Workbook

Sheet All
A2: L.P. | C2: IMIĘ NAZWISKO | D2: V/M | E2: V/M | Q2: TS | R2: TS | AD2: Ind | AE2: Ind
B3: kat | E3: MP | G3: PP1 | I3: PP2 | K3: PP3 | M3: PP4 | O3: PP5 | R3: MP | T3: PP1 | V3: PP2 | X3: PP3 | Z3: PP4 | AB3: PP5 | AE3: MP | AG3: PP1 | AI3: PP2 | AK3: PP3 | AM3: PP4 | AO3: PP5
E4: 1 | F4: 2 | G4: 1 | H4: 2 | I4: 1 | J4: 2 | K4: 1 | L4: 2 | M4: 1 | N4: 2 | O4: 1 | P4: 2 | R4: 1 | S4: 2 | T4: 1 | U4: 2 | V4: 1 | W4: 2 | X4: 1 | Y4: 2 | Z4: 1 | AA4: 2 | AB4: 1 | AC4: 2 | AE4: 1 | AF4: 2 | AG4: 1 | AH4: 2 | AI4: 1 | AJ4: 2 | AK4: 1 | AL4: 2 | AM4: 1 | AN4: 2 | AO4: 1 | AP4: 2
A5: =ROW()-4 -> 1 | B5: 1 | C5: SĘKOWSKI Maciej | D5: =SUM(E5:P5) -> 11.52 | E5: =_xlfn.XLOOKUP($C5,'MP (1)'!$B$6:$B$100,'MP (1)'!$E$6:$E$100,"") -> 1 | F5: =_xlfn.XLOOKUP($C5,'MP (2)'!$B$6:$B$100,'MP (2)'!$E$6:$E$100,"") -> 1 | G5: =_xlfn.XLOOKUP($C5,'PP1 (1)'!$B$6:$B$99,'PP1 (1)'!$E$6:$E$99,"") -> 1 | H5: =_xlfn.XLOOKUP($C5,'PP1 (2)'!$B$6:$B$98,'PP1 (2)'!$E$6:$E$98,"") -> 0.86 | I5: =_xlfn.XLOOKUP($C5,'PP2 (1)'!$B$6:$B$106,'PP2 (1)'!$E$6:$E$106,"") -> 0.83 | J5: =_xlfn.XLOOKUP($C5,'PP2 (2)'!$B$6:$B$100,'PP2 (2)'!$E$6:$E$100,"") -> 1 | K5: =_xlfn.XLOOKUP($C5,'PP3 (1)'!$B$5:$B$106,'PP3 (1)'!$E$5:$E$106,"") -> 0.83 | L5: =_xlfn.XLOOKUP($C5,'PP3 (2)'!$B$5:$B$108,'PP3 (2)'!$E$5:$E$108,"") -> 1 | M5: =_xlfn.XLOOKUP($C5,'PP4 (1)'!$B$6:$B$100,'PP4 (1)'!$E$6:$E$100,"") -> 1 | N5: =_xlfn.XLOOKUP($C5,'PP4 (2)'!$B$6:$B$100,'PP4 (2)'!$E$6:$E$100,"") -> 1 | O5: =_xlfn.XLOOKUP($C5,'PP5 (1)'!$B$6:$B$100,'PP5 (1)'!$E$6:$E$100,"") -> 1 | P5: =_xlfn.XLOOKUP($C5,'PP5 (2)'!$B$6:$B$100,'PP5 (2)'!$E$6:$E$100,"") -> 1 | Q5: =SUM(R5:AC5) -> 364 | R5: =_xlfn.XLOOKUP($C5,'MP (1)'!$B$6:$B$100,'MP (1)'!$F$6:$F$100,"") -> 35 | S5: =_xlfn.XLOOKUP($C5,'MP (2)'!$B$6:$B$100,'MP (2)'!$F$6:$F$100,"") -> 35 | T5: =_xlfn.XLOOKUP($C5,'PP1 (1)'!$B$6:$B$99,'PP1 (1)'!$F$6:$F$99,"") -> 35 | U5: =_xlfn.XLOOKUP($C5,'PP1 (2)'!$B$6:$B$98,'PP1 (2)'!$F$6:$F$98,"") -> 33 | V5: =_xlfn.XLOOKUP($C5,'PP2 (1)'!$B$6:$B$106,'PP2 (1)'!$F$6:$F$106,"") -> 29 | W5: =_xlfn.XLOOKUP($C5,'PP2 (2)'!$B$6:$B$100,'PP2 (2)'!$F$6:$F$100,"") -> 29 | X5: =_xlfn.XLOOKUP($C5,'PP3 (1)'!$B$5:$B$106,'PP3 (1)'!$F$5:$F$106,"") -> 28 | Y5: =_xlfn.XLOOKUP($C5,'PP3 (2)'!$B$5:$B$108,'PP3 (2)'!$F$5:$F$108,"") -> 25 | Z5: =_xlfn.XLOOKUP($C5,'PP4 (1)'!$B$6:$B$100,'PP4 (1)'!$F$6:$F$100,"") -> 30 | AA5: =_xlfn.XLOOKUP($C5,'PP4 (2)'!$B$6:$B$100,'PP4 (2)'!$F$6:$F$100,"") -> 30 | AB5: =_xlfn.XLOOKUP($C5,'PP5 (1)'!$B$6:$B$100,'PP5 (1)'!$F$6:$F$100,"") -> 25 | AC5: =_xlfn.XLOOKUP($C5,'PP5 (2)'!$B$6:$B$100,'PP5 (2)'!$F$6:$F$100,"") -> 30 | AD5: =SUM(AE5:AP5) -> 255 | AE5: =_xlfn.XLOOKUP($C5,'MP (1)'!$B$6:$B$100,'MP (1)'!$H$6:$H$100,"") -> 30 | AF5: =_xlfn.XLOOKUP($C5,'MP (2)'!$B$6:$B$100,'MP (2)'!$H$6:$H$100,"") -> 23 | AG5: =_xlfn.XLOOKUP($C5,'PP1 (1)'!$B$6:$B$99,'PP1 (1)'!$H$6:$H$99,"") -> 17 | AH5: =_xlfn.XLOOKUP($C5,'PP1 (2)'!$B$6:$B$98,'PP1 (2)'!$H$6:$H$98,"") -> 17 | AI5: =_xlfn.XLOOKUP($C5,'PP2 (1)'!$B$6:$B$106,'PP2 (1)'!$H$6:$H$106,"") -> 16 | AJ5: =_xlfn.XLOOKUP($C5,'PP2 (2)'!$B$6:$B$100,'PP2 (2)'!$H$6:$H$100,"") -> 23 | AK5: =_xlfn.XLOOKUP($C5,'PP3 (1)'!$B$5:$B$106,'PP3 (1)'!$H$5:$H$106,"") -> 14 | AL5: =_xlfn.XLOOKUP($C5,'PP3 (2)'!$B$5:$B$108,'PP3 (2)'!$H$5:$H$108,"") -> 21 | AM5: =_xlfn.XLOOKUP($C5,'PP4 (1)'!$B$6:$B$100,'PP4 (1)'!$H$6:$H$100,"") -> 22 | AN5: =_xlfn.XLOOKUP($C5,'PP4 (2)'!$B$6:$B$100,'PP4 (2)'!$H$6:$H$100,"") -> 27 | AO5: =_xlfn.XLOOKUP($C5,'PP5 (1)'!$B$6:$B$100,'PP5 (1)'!$H$6:$H$100,"") -> 23 | AP5: =_xlfn.XLOOKUP($C5,'PP5 (2)'!$B$6:$B$100,'PP5 (2)'!$H$6:$H$100,"") -> 22
A6: =ROW()-4 -> 2 | B6: 1 | C6: GROMADA Roland | D6: =SUM(E6:P6) -> 10.45 | E6: =_xlfn.XLOOKUP($C6,'MP (1)'!$B$6:$B$100,'MP (1)'!$E$6:$E$100,"") -> 1 | F6: =_xlfn.XLOOKUP($C6,'MP (2)'!$B$6:$B$100,'MP (2)'!$E$6:$E$100,"") -> 0.86 | G6: =_xlfn.XLOOKUP($C6,'PP1 (1)'!$B$6:$B$99,'PP1 (1)'!$E$6:$E$99,"") -> 0.86 | H6: =_xlfn.XLOOKUP($C6,'PP1 (2)'!$B$6:$B$98,'PP1 (2)'!$E$6:$E$98,"") -> 0.67 | I6: =_xlfn.XLOOKUP($C6,'PP2 (1)'!$B$6:$B$106,'PP2 (1)'!$E$6:$E$106,"") -> 0.83 | J6: =_xlfn.XLOOKUP($C6,'PP2 (2)'!$B$6:$B$100,'PP2 (2)'!$E$6:$E$100,"") -> 0.83 | K6: =_xlfn.XLOOKUP($C6,'PP3 (1)'!$B$5:$B$106,'PP3 (1)'!$E$5:$E$106,"") -> 0.8 | L6: =_xlfn.XLOOKUP($C6,'PP3 (2)'!$B$5:$B$108,'PP3 (2)'!$E$5:$E$108,"") -> 1 | M6: =_xlfn.XLOOKUP($C6,'PP4 (1)'!$B$6:$B$100,'PP4 (1)'!$E$6:$E$100,"") -> 1 | N6: =_xlfn.XLOOKUP($C6,'PP4 (2)'!$B$6:$B$100,'PP4 (2)'!$E$6:$E$100,"") -> 1 | O6: =_xlfn.XLOOKUP($C6,'PP5 (1)'!$B$6:$B$100,'PP5 (1)'!$E$6:$E$100,"") -> 0.6 | P6: =_xlfn.XLOOKUP($C6,'PP5 (2)'!$B$6:$B$100,'PP5 (2)'!$E$6:$E$100,"") -> 1 | Q6: =SUM(R6:AC6) -> 323 | R6: =_xlfn.XLOOKUP($C6,'MP (1)'!$B$6:$B$100,'MP (1)'!$F$6:$F$100,"") -> 30 | S6: =_xlfn.XLOOKUP($C6,'MP (2)'!$B$6:$B$100,'MP (2)'!$F$6:$F$100,"") -> 30 | T6: =_xlfn.XLOOKUP($C6,'PP1 (1)'!$B$6:$B$99,'PP1 (1)'!$F$6:$F$99,"") -> 31 | U6: =_xlfn.XLOOKUP($C6,'PP1 (2)'!$B$6:$B$98,'PP1 (2)'!$F$6:$F$98,"") -> 26 | V6: =_xlfn.XLOOKUP($C6,'PP2 (1)'!$B$6:$B$106,'PP2 (1)'!$F$6:$F$106,"") -> 26 | W6: =_xlfn.XLOOKUP($C6,'PP2 (2)'!$B$6:$B$100,'PP2 (2)'!$F$6:$F$100,"") -> 25 | X6: =_xlfn.XLOOKUP($C6,'PP3 (1)'!$B$5:$B$106,'PP3 (1)'!$F$5:$F$106,"") -> 22 | Y6: =_xlfn.XLOOKUP($C6,'PP3 (2)'!$B$5:$B$108,'PP3 (2)'!$F$5:$F$108,"") -> 27 | Z6: =_xlfn.XLOOKUP($C6,'PP4 (1)'!$B$6:$B$100,'PP4 (1)'!$F$6:$F$100,"") -> 30 | AA6: =_xlfn.XLOOKUP($C6,'PP4 (2)'!$B$6:$B$100,'PP4 (2)'!$F$6:$F$100,"") -> 30 | AB6: =_xlfn.XLOOKUP($C6,'PP5 (1)'!$B$6:$B$100,'PP5 (1)'!$F$6:$F$100,"") -> 21 | AC6: =_xlfn.XLOOKUP($C6,'PP5 (2)'!$B$6:$B$100,'PP5 (2)'!$F$6:$F$100,"") -> 25 | AD6: =SUM(AE6:AP6) -> 172 | AE6: =_xlfn.XLOOKUP($C6,'MP (1)'!$B$6:$B$100,'MP (1)'!$H$6:$H$100,"") -> 22 | AF6: =_xlfn.XLOOKUP($C6,'MP (2)'!$B$6:$B$100,'MP (2)'!$H$6:$H$100,"") -> 18 | AG6: =_xlfn.XLOOKUP($C6,'PP1 (1)'!$B$6:$B$99,'PP1 (1)'!$H$6:$H$99,"") -> 16 | AH6: =_xlfn.XLOOKUP($C6,'PP1 (2)'!$B$6:$B$98,'PP1 (2)'!$H$6:$H$98,"") -> 7 | AI6: =_xlfn.XLOOKUP($C6,'PP2 (1)'!$B$6:$B$106,'PP2 (1)'!$H$6:$H$106,"") -> 13 | AJ6: =_xlfn.XLOOKUP($C6,'PP2 (2)'!$B$6:$B$100,'PP2 (2)'!$H$6:$H$100,"") -> 11 | AK6: =_xlfn.XLOOKUP($C6,'PP3 (1)'!$B$5:$B$106,'PP3 (1)'!$H$5:$H$106,"") -> 8 | AL6: =_xlfn.XLOOKUP($C6,'PP3 (2)'!$B$5:$B$108,'PP3 (2)'!$H$5:$H$108,"") -> 19 | AM6: =_xlfn.XLOOKUP($C6,'PP4 (1)'!$B$6:$B$100,'PP4 (1)'!$H$6:$H$100,"") -> 20 | AN6: =_xlfn.XLOOKUP($C6,'PP4 (2)'!$B$6:$B$100,'PP4 (2)'!$H$6:$H$100,"") -> 25 | AO6: =_xlfn.XLOOKUP($C6,'PP5 (1)'!$B$6:$B$100,'PP5 (1)'!$H$6:$H$100,"") -> 6 | AP6: =_xlfn.XLOOKUP($C6,'PP5 (2)'!$B$6:$B$100,'PP5 (2)'!$H$6:$H$100,"") -> 7
A7: =ROW()-4 -> 3 | B7: 2 | C7: ZIELIŃSKI Dariusz | D7: =SUM(E7:P7) -> 9.15 | E7: =_xlfn.XLOOKUP($C7,'MP (1)'!$B$6:$B$100,'MP (1)'!$E$6:$E$100,"") -> 1 | F7: =_xlfn.XLOOKUP($C7,'MP (2)'!$B$6:$B$100,'MP (2)'!$E$6:$E$100,"") -> 0.83 | G7: =_xlfn.XLOOKUP($C7,'PP1 (1)'!$B$6:$B$99,'PP1 (1)'!$E$6:$E$99,"") -> 1 | H7: =_xlfn.XLOOKUP($C7,'PP1 (2)'!$B$6:$B$98,'PP1 (2)'!$E$6:$E$98,"") -> 0.83 | I7: =_xlfn.XLOOKUP($C7,'PP2 (1)'!$B$6:$B$106,'PP2 (1)'!$E$6:$E$106,"") -> 0.83 | J7: =_xlfn.XLOOKUP($C7,'PP2 (2)'!$B$6:$B$100,'PP2 (2)'!$E$6:$E$100,"") -> 1 | K7: =_xlfn.XLOOKUP($C7,'PP3 (1)'!$B$5:$B$106,'PP3 (1)'!$E$5:$E$106,"") -> 0.83 | L7: =_xlfn.XLOOKUP($C7,'PP3 (2)'!$B$5:$B$108,'PP3 (2)'!$E$5:$E$108,"") -> 1 | M7: =_xlfn.XLOOKUP($C7,'PP4 (1)'!$B$6:$B$100,'PP4 (1)'!$E$6:$E$100,"") -> 0.83 | N7: =_xlfn.XLOOKUP($C7,'PP4 (2)'!$B$6:$B$100,'PP4 (2)'!$E$6:$E$100,"") -> 1 | O7: =_xlfn.XLOOKUP($C7,'PP5 (1)'!$B$6:$B$100,'PP5 (1)'!$E$6:$E$100,"") | P7: =_xlfn.XLOOKUP($C7,'PP5 (2)'!$B$6:$B$100,'PP5 (2)'!$E$6:$E$100,"") | Q7: =SUM(R7:AC7) -> 287 | R7: =_xlfn.XLOOKUP($C7,'MP (1)'!$B$6:$B$100,'MP (1)'!$F$6:$F$100,"") -> 33 | S7: =_xlfn.XLOOKUP($C7,'MP (2)'!$B$6:$B$100,'MP (2)'!$F$6:$F$100,"") -> 28 | T7: =_xlfn.XLOOKUP($C7,'PP1 (1)'!$B$6:$B$99,'PP1 (1)'!$F$6:$F$99,"") -> 30 | U7: =_xlfn.XLOOKUP($C7,'PP1 (2)'!$B$6:$B$98,'PP1 (2)'!$F$6:$F$98,"") -> 26 | V7: =_xlfn.XLOOKUP($C7,'PP2 (1)'!$B$6:$B$106,'PP2 (1)'!$F$6:$F$106,"") -> 29 | W7: =_xlfn.XLOOKUP($C7,'PP2 (2)'!$B$6:$B$100,'PP2 (2)'!$F$6:$F$100,"") -> 30 | X7: =_xlfn.XLOOKUP($C7,'PP3 (1)'!$B$5:$B$106,'PP3 (1)'!$F$5:$F$106,"") -> 29 | Y7: =_xlfn.XLOOKUP($C7,'PP3 (2)'!$B$5:$B$108,'PP3 (2)'!$F$5:$F$108,"") -> 30 | Z7: =_xlfn.XLOOKUP($C7,'PP4 (1)'!$B$6:$B$100,'PP4 (1)'!$F$6:$F$100,"") -> 27 | AA7: =_xlfn.XLOOKUP($C7,'PP4 (2)'!$B$6:$B$100,'PP4 (2)'!$F$6:$F$100,"") -> 25 | AB7: =_xlfn.XLOOKUP($C7,'PP5 (1)'!$B$6:$B$100,'PP5 (1)'!$F$6:$F$100,"") | AC7: =_xlfn.XLOOKUP($C7,'PP5 (2)'!$B$6:$B$100,'PP5 (2)'!$F$6:$F$100,"") | AD7: =SUM(AE7:AP7) -> 171 | AE7: =_xlfn.XLOOKUP($C7,'MP (1)'!$B$6:$B$100,'MP (1)'!$H$6:$H$100,"") -> 19 | AF7: =_xlfn.XLOOKUP($C7,'MP (2)'!$B$6:$B$100,'MP (2)'!$H$6:$H$100,"") -> 14 | AG7: =_xlfn.XLOOKUP($C7,'PP1 (1)'!$B$6:$B$99,'PP1 (1)'!$H$6:$H$99,"") -> 16 | AH7: =_xlfn.XLOOKUP($C7,'PP1 (2)'!$B$6:$B$98,'PP1 (2)'!$H$6:$H$98,"") -> 15 | AI7: =_xlfn.XLOOKUP($C7,'PP2 (1)'!$B$6:$B$106,'PP2 (1)'!$H$6:$H$106,"") -> 16 | AJ7: =_xlfn.XLOOKUP($C7,'PP2 (2)'!$B$6:$B$100,'PP2 (2)'!$H$6:$H$100,"") -> 18 | AK7: =_xlfn.XLOOKUP($C7,'PP3 (1)'!$B$5:$B$106,'PP3 (1)'!$H$5:$H$106,"") -> 18 | AL7: =_xlfn.XLOOKUP($C7,'PP3 (2)'!$B$5:$B$108,'PP3 (2)'!$H$5:$H$108,"") -> 21 | AM7: =_xlfn.XLOOKUP($C7,'PP4 (1)'!$B$6:$B$100,'PP4 (1)'!$H$6:$H$100,"") -> 16 | AN7: =_xlfn.XLOOKUP($C7,'PP4 (2)'!$B$6:$B$100,'PP4 (2)'!$H$6:$H$100,"") -> 18 | AO7: =_xlfn.XLOOKUP($C7,'PP5 (1)'!$B$6:$B$100,'PP5 (1)'!$H$6:$H$100,"") | AP7: =_xlfn.XLOOKUP($C7,'PP5 (2)'!$B$6:$B$100,'PP5 (2)'!$H$6:$H$100,"")
A8: =ROW()-4 -> 4 | B8: 1 | C8: KORONA Przemysław | D8: =SUM(E8:P8) -> 8.86 | E8: =_xlfn.XLOOKUP($C8,'MP (1)'!$B$6:$B$100,'MP (1)'!$E$6:$E$100,"") -> 0.86 | F8: =_xlfn.XLOOKUP($C8,'MP (2)'!$B$6:$B$100,'MP (2)'!$E$6:$E$100,"") -> 0.83 | G8: =_xlfn.XLOOKUP($C8,'PP1 (1)'!$B$6:$B$99,'PP1 (1)'!$E$6:$E$99,"") -> 1 | H8: =_xlfn.XLOOKUP($C8,'PP1 (2)'!$B$6:$B$98,'PP1 (2)'!$E$6:$E$98,"") -> 1 | I8: =_xlfn.XLOOKUP($C8,'PP2 (1)'!$B$6:$B$106,'PP2 (1)'!$E$6:$E$106,"") -> 1 | J8: =_xlfn.XLOOKUP($C8,'PP2 (2)'!$B$6:$B$100,'PP2 (2)'!$E$6:$E$100,"") -> 1 | K8: =_xlfn.XLOOKUP($C8,'PP3 (1)'!$B$5:$B$106,'PP3 (1)'!$E$5:$E$106,"") -> 0.83 | L8: =_xlfn.XLOOKUP($C8,'PP3 (2)'!$B$5:$B$108,'PP3 (2)'!$E$5:$E$108,"") -> 1 | M8: =_xlfn.XLOOKUP($C8,'PP4 (1)'!$B$6:$B$100,'PP4 (1)'!$E$6:$E$100,"") -> 0.67 | N8: =_xlfn.XLOOKUP($C8,'PP4 (2)'!$B$6:$B$100,'PP4 (2)'!$E$6:$E$100,"") -> 0.67 | O8: =_xlfn.XLOOKUP($C8,'PP5 (1)'!$B$6:$B$100,'PP5 (1)'!$E$6:$E$100,"") | P8: =_xlfn.XLOOKUP($C8,'PP5 (2)'!$B$6:$B$100,'PP5 (2)'!$E$6:$E$100,"") | Q8: =SUM(R8:AC8) -> 294 | R8: =_xlfn.XLOOKUP($C8,'MP (1)'!$B$6:$B$100,'MP (1)'!$F$6:$F$100,"") -> 31 | S8: =_xlfn.XLOOKUP($C8,'MP (2)'!$B$6:$B$100,'MP (2)'!$F$6:$F$100,"") -> 26 | T8: =_xlfn.XLOOKUP($C8,'PP1 (1)'!$B$6:$B$99,'PP1 (1)'!$F$6:$F$99,"") -> 35 | U8: =_xlfn.XLOOKUP($C8,'PP1 (2)'!$B$6:$B$98,'PP1 (2)'!$F$6:$F$98,"") -> 33 | V8: =_xlfn.XLOOKUP($C8,'PP2 (1)'!$B$6:$B$106,'PP2 (1)'!$F$6:$F$106,"") -> 30 | W8: =_xlfn.XLOOKUP($C8,'PP2 (2)'!$B$6:$B$100,'PP2 (2)'!$F$6:$F$100,"") -> 30 | X8: =_xlfn.XLOOKUP($C8,'PP3 (1)'!$B$5:$B$106,'PP3 (1)'!$F$5:$F$106,"") -> 28 | Y8: =_xlfn.XLOOKUP($C8,'PP3 (2)'!$B$5:$B$108,'PP3 (2)'!$F$5:$F$108,"") -> 30 | Z8: =_xlfn.XLOOKUP($C8,'PP4 (1)'!$B$6:$B$100,'PP4 (1)'!$F$6:$F$100,"") -> 25 | AA8: =_xlfn.XLOOKUP($C8,'PP4 (2)'!$B$6:$B$100,'PP4 (2)'!$F$6:$F$100,"") -> 26 | AB8: =_xlfn.XLOOKUP($C8,'PP5 (1)'!$B$6:$B$100,'PP5 (1)'!$F$6:$F$100,"") | AC8: =_xlfn.XLOOKUP($C8,'PP5 (2)'!$B$6:$B$100,'PP5 (2)'!$F$6:$F$100,"") | AD8: =SUM(AE8:AP8) -> 170 | AE8: =_xlfn.XLOOKUP($C8,'MP (1)'!$B$6:$B$100,'MP (1)'!$H$6:$H$100,"") -> 17 | AF8: =_xlfn.XLOOKUP($C8,'MP (2)'!$B$6:$B$100,'MP (2)'!$H$6:$H$100,"") -> 13 | AG8: =_xlfn.XLOOKUP($C8,'PP1 (1)'!$B$6:$B$99,'PP1 (1)'!$H$6:$H$99,"") -> 19 | AH8: =_xlfn.XLOOKUP($C8,'PP1 (2)'!$B$6:$B$98,'PP1 (2)'!$H$6:$H$98,"") -> 19 | AI8: =_xlfn.XLOOKUP($C8,'PP2 (1)'!$B$6:$B$106,'PP2 (1)'!$H$6:$H$106,"") -> 18 | AJ8: =_xlfn.XLOOKUP($C8,'PP2 (2)'!$B$6:$B$100,'PP2 (2)'!$H$6:$H$100,"") -> 20 | AK8: =_xlfn.XLOOKUP($C8,'PP3 (1)'!$B$5:$B$106,'PP3 (1)'!$H$5:$H$106,"") -> 18 | AL8: =_xlfn.XLOOKUP($C8,'PP3 (2)'!$B$5:$B$108,'PP3 (2)'!$H$5:$H$108,"") -> 23 | AM8: =_xlfn.XLOOKUP($C8,'PP4 (1)'!$B$6:$B$100,'PP4 (1)'!$H$6:$H$100,"") -> 10 | AN8: =_xlfn.XLOOKUP($C8,'PP4 (2)'!$B$6:$B$100,'PP4 (2)'!$H$6:$H$100,"") -> 13 | AO8: =_xlfn.XLOOKUP($C8,'PP5 (1)'!$B$6:$B$100,'PP5 (1)'!$H$6:$H$100,"") | AP8: =_xlfn.XLOOKUP($C8,'PP5 (2)'!$B$6:$B$100,'PP5 (2)'!$H$6:$H$100,"")
A9: =ROW()-4 -> 5 | B9: 3 | C9: DRAPELLA Maciej | D9: =SUM(E9:P9) -> 8.45 | E9: =_xlfn.XLOOKUP($C9,'MP (1)'!$B$6:$B$100,'MP (1)'!$E$6:$E$100,"") -> 0.83 | F9: =_xlfn.XLOOKUP($C9,'MP (2)'!$B$6:$B$100,'MP (2)'!$E$6:$E$100,"") -> 0.83 | G9: =_xlfn.XLOOKUP($C9,'PP1 (1)'!$B$6:$B$99,'PP1 (1)'!$E$6:$E$99,"") -> 1 | H9: =_xlfn.XLOOKUP($C9,'PP1 (2)'!$B$6:$B$98,'PP1 (2)'!$E$6:$E$98,"") -> 0.86 | I9: =_xlfn.XLOOKUP($C9,'PP2 (1)'!$B$6:$B$106,'PP2 (1)'!$E$6:$E$106,"") -> 0.83 | J9: =_xlfn.XLOOKUP($C9,'PP2 (2)'!$B$6:$B$100,'PP2 (2)'!$E$6:$E$100,"") -> 1 | K9: =_xlfn.XLOOKUP($C9,'PP3 (1)'!$B$5:$B$106,'PP3 (1)'!$E$5:$E$106,"") -> 0.83 | L9: =_xlfn.XLOOKUP($C9,'PP3 (2)'!$B$5:$B$108,'PP3 (2)'!$E$5:$E$108,"") -> 0.8 | M9: =_xlfn.XLOOKUP($C9,'PP4 (1)'!$B$6:$B$100,'PP4 (1)'!$E$6:$E$100,"") -> 0.8 | N9: =_xlfn.XLOOKUP($C9,'PP4 (2)'!$B$6:$B$100,'PP4 (2)'!$E$6:$E$100,"") -> 0.67 | O9: =_xlfn.XLOOKUP($C9,'PP5 (1)'!$B$6:$B$100,'PP5 (1)'!$E$6:$E$100,"") | P9: =_xlfn.XLOOKUP($C9,'PP5 (2)'!$B$6:$B$100,'PP5 (2)'!$E$6:$E$100,"") | Q9: =SUM(R9:AC9) -> 267 | R9: =_xlfn.XLOOKUP($C9,'MP (1)'!$B$6:$B$100,'MP (1)'!$F$6:$F$100,"") -> 27 | S9: =_xlfn.XLOOKUP($C9,'MP (2)'!$B$6:$B$100,'MP (2)'!$F$6:$F$100,"") -> 25 | T9: =_xlfn.XLOOKUP($C9,'PP1 (1)'!$B$6:$B$99,'PP1 (1)'!$F$6:$F$99,"") -> 30 | U9: =_xlfn.XLOOKUP($C9,'PP1 (2)'!$B$6:$B$98,'PP1 (2)'!$F$6:$F$98,"") -> 34 | V9: =_xlfn.XLOOKUP($C9,'PP2 (1)'!$B$6:$B$106,'PP2 (1)'!$F$6:$F$106,"") -> 24 | W9: =_xlfn.XLOOKUP($C9,'PP2 (2)'!$B$6:$B$100,'PP2 (2)'!$F$6:$F$100,"") -> 30 | X9: =_xlfn.XLOOKUP($C9,'PP3 (1)'!$B$5:$B$106,'PP3 (1)'!$F$5:$F$106,"") -> 26 | Y9: =_xlfn.XLOOKUP($C9,'PP3 (2)'!$B$5:$B$108,'PP3 (2)'!$F$5:$F$108,"") -> 22 | Z9: =_xlfn.XLOOKUP($C9,'PP4 (1)'!$B$6:$B$100,'PP4 (1)'!$F$6:$F$100,"") -> 21 | AA9: =_xlfn.XLOOKUP($C9,'PP4 (2)'!$B$6:$B$100,'PP4 (2)'!$F$6:$F$100,"") -> 28 | AB9: =_xlfn.XLOOKUP($C9,'PP5 (1)'!$B$6:$B$100,'PP5 (1)'!$F$6:$F$100,"") | AC9: =_xlfn.XLOOKUP($C9,'PP5 (2)'!$B$6:$B$100,'PP5 (2)'!$F$6:$F$100,"") | AD9: =SUM(AE9:AP9) -> 133 | AE9: =_xlfn.XLOOKUP($C9,'MP (1)'!$B$6:$B$100,'MP (1)'!$H$6:$H$100,"") -> 11 | AF9: =_xlfn.XLOOKUP($C9,'MP (2)'!$B$6:$B$100,'MP (2)'!$H$6:$H$100,"") -> 11 | AG9: =_xlfn.XLOOKUP($C9,'PP1 (1)'!$B$6:$B$99,'PP1 (1)'!$H$6:$H$99,"") -> 17 | AH9: =_xlfn.XLOOKUP($C9,'PP1 (2)'!$B$6:$B$98,'PP1 (2)'!$H$6:$H$98,"") -> 21 | AI9: =_xlfn.XLOOKUP($C9,'PP2 (1)'!$B$6:$B$106,'PP2 (1)'!$H$6:$H$106,"") -> 13 | AJ9: =_xlfn.XLOOKUP($C9,'PP2 (2)'!$B$6:$B$100,'PP2 (2)'!$H$6:$H$100,"") -> 17 | AK9: =_xlfn.XLOOKUP($C9,'PP3 (1)'!$B$5:$B$106,'PP3 (1)'!$H$5:$H$106,"") -> 8 | AL9: =_xlfn.XLOOKUP($C9,'PP3 (2)'!$B$5:$B$108,'PP3 (2)'!$H$5:$H$108,"") -> 10 | AM9: =_xlfn.XLOOKUP($C9,'PP4 (1)'!$B$6:$B$100,'PP4 (1)'!$H$6:$H$100,"") -> 9 | AN9: =_xlfn.XLOOKUP($C9,'PP4 (2)'!$B$6:$B$100,'PP4 (2)'!$H$6:$H$100,"") -> 16 | AO9: =_xlfn.XLOOKUP($C9,'PP5 (1)'!$B$6:$B$100,'PP5 (1)'!$H$6:$H$100,"") | AP9: =_xlfn.XLOOKUP($C9,'PP5 (2)'!$B$6:$B$100,'PP5 (2)'!$H$6:$H$100,"")
A10: =ROW()-4 -> 6 | B10: 3 | C10: KRZEMIŃSKI Mariusz | D10: =SUM(E10:P10) -> 8.25 | E10: =_xlfn.XLOOKUP($C10,'MP (1)'!$B$6:$B$100,'MP (1)'!$E$6:$E$100,"") -> 0.83 | F10: =_xlfn.XLOOKUP($C10,'MP (2)'!$B$6:$B$100,'MP (2)'!$E$6:$E$100,"") -> 1 | G10: =_xlfn.XLOOKUP($C10,'PP1 (1)'!$B$6:$B$99,'PP1 (1)'!$E$6:$E$99,"") -> 0.71 | H10: =_xlfn.XLOOKUP($C10,'PP1 (2)'!$B$6:$B$98,'PP1 (2)'!$E$6:$E$98,"") -> 0.71 | I10: =_xlfn.XLOOKUP($C10,'PP2 (1)'!$B$6:$B$106,'PP2 (1)'!$E$6:$E$106,"") -> 0.67 | J10: =_xlfn.XLOOKUP($C10,'PP2 (2)'!$B$6:$B$100,'PP2 (2)'!$E$6:$E$100,"") -> 0.83 | K10: =_xlfn.XLOOKUP($C10,'PP3 (1)'!$B$5:$B$106,'PP3 (1)'!$E$5:$E$106,"") -> 1 | L10: =_xlfn.XLOOKUP($C10,'PP3 (2)'!$B$5:$B$108,'PP3 (2)'!$E$5:$E$108,"") -> 0.83 | M10: =_xlfn.XLOOKUP($C10,'PP4 (1)'!$B$6:$B$100,'PP4 (1)'!$E$6:$E$100,"") -> 0.67 | N10: =_xlfn.XLOOKUP($C10,'PP4 (2)'!$B$6:$B$100,'PP4 (2)'!$E$6:$E$100,"") -> 1 | O10: =_xlfn.XLOOKUP($C10,'PP5 (1)'!$B$6:$B$100,'PP5 (1)'!$E$6:$E$100,"") | P10: =_xlfn.XLOOKUP($C10,'PP5 (2)'!$B$6:$B$100,'PP5 (2)'!$E$6:$E$100,"") | Q10: =SUM(R10:AC10) -> 273 | R10: =_xlfn.XLOOKUP($C10,'MP (1)'!$B$6:$B$100,'MP (1)'!$F$6:$F$100,"") -> 23 | S10: =_xlfn.XLOOKUP($C10,'MP (2)'!$B$6:$B$100,'MP (2)'!$F$6:$F$100,"") -> 29 | T10: =_xlfn.XLOOKUP($C10,'PP1 (1)'!$B$6:$B$99,'PP1 (1)'!$F$6:$F$99,"") -> 31 | U10: =_xlfn.XLOOKUP($C10,'PP1 (2)'!$B$6:$B$98,'PP1 (2)'!$F$6:$F$98,"") -> 30 | V10: =_xlfn.XLOOKUP($C10,'PP2 (1)'!$B$6:$B$106,'PP2 (1)'!$F$6:$F$106,"") -> 23 | W10: =_xlfn.XLOOKUP($C10,'PP2 (2)'!$B$6:$B$100,'PP2 (2)'!$F$6:$F$100,"") -> 27 | X10: =_xlfn.XLOOKUP($C10,'PP3 (1)'!$B$5:$B$106,'PP3 (1)'!$F$5:$F$106,"") -> 30 | Y10: =_xlfn.XLOOKUP($C10,'PP3 (2)'!$B$5:$B$108,'PP3 (2)'!$F$5:$F$108,"") -> 25 | Z10: =_xlfn.XLOOKUP($C10,'PP4 (1)'!$B$6:$B$100,'PP4 (1)'!$F$6:$F$100,"") -> 25 | AA10: =_xlfn.XLOOKUP($C10,'PP4 (2)'!$B$6:$B$100,'PP4 (2)'!$F$6:$F$100,"") -> 30 | AB10: =_xlfn.XLOOKUP($C10,'PP5 (1)'!$B$6:$B$100,'PP5 (1)'!$F$6:$F$100,"") | AC10: =_xlfn.XLOOKUP($C10,'PP5 (2)'!$B$6:$B$100,'PP5 (2)'!$F$6:$F$100,"") | AD10: =SUM(AE10:AP10) -> 129 | AE10: =_xlfn.XLOOKUP($C10,'MP (1)'!$B$6:$B$100,'MP (1)'!$H$6:$H$100,"") -> 9 | AF10: =_xlfn.XLOOKUP($C10,'MP (2)'!$B$6:$B$100,'MP (2)'!$H$6:$H$100,"") -> 19 | AG10: =_xlfn.XLOOKUP($C10,'PP1 (1)'!$B$6:$B$99,'PP1 (1)'!$H$6:$H$99,"") -> 11 | AH10: =_xlfn.XLOOKUP($C10,'PP1 (2)'!$B$6:$B$98,'PP1 (2)'!$H$6:$H$98,"") -> 12 | AI10: =_xlfn.XLOOKUP($C10,'PP2 (1)'!$B$6:$B$106,'PP2 (1)'!$H$6:$H$106,"") -> 6 | AJ10: =_xlfn.XLOOKUP($C10,'PP2 (2)'!$B$6:$B$100,'PP2 (2)'!$H$6:$H$100,"") -> 15 | AK10: =_xlfn.XLOOKUP($C10,'PP3 (1)'!$B$5:$B$106,'PP3 (1)'!$H$5:$H$106,"") -> 17 | AL10: =_xlfn.XLOOKUP($C10,'PP3 (2)'!$B$5:$B$108,'PP3 (2)'!$H$5:$H$108,"") -> 12 | AM10: =_xlfn.XLOOKUP($C10,'PP4 (1)'!$B$6:$B$100,'PP4 (1)'!$H$6:$H$100,"") -> 9 | AN10: =_xlfn.XLOOKUP($C10,'PP4 (2)'!$B$6:$B$100,'PP4 (2)'!$H$6:$H$100,"") -> 19 | AO10: =_xlfn.XLOOKUP($C10,'PP5 (1)'!$B$6:$B$100,'PP5 (1)'!$H$6:$H$100,"") | AP10: =_xlfn.XLOOKUP($C10,'PP5 (2)'!$B$6:$B$100,'PP5 (2)'!$H$6:$H$100,"")
A11: =ROW()-4 -> 7 | B11: 1 | C11: BOBUSIA Jarosław | D11: =SUM(E11:P11) -> 8.24 | E11: =_xlfn.XLOOKUP($C11,'MP (1)'!$B$6:$B$100,'MP (1)'!$E$6:$E$100,"") -> 1 | F11: =_xlfn.XLOOKUP($C11,'MP (2)'!$B$6:$B$100,'MP (2)'!$E$6:$E$100,"") -> 0.83 | G11: =_xlfn.XLOOKUP($C11,'PP1 (1)'!$B$6:$B$99,'PP1 (1)'!$E$6:$E$99,"") -> 0.71 | H11: =_xlfn.XLOOKUP($C11,'PP1 (2)'!$B$6:$B$98,'PP1 (2)'!$E$6:$E$98,"") -> 0.57 | I11: =_xlfn.XLOOKUP($C11,'PP2 (1)'!$B$6:$B$106,'PP2 (1)'!$E$6:$E$106,"") -> 1 | J11: =_xlfn.XLOOKUP($C11,'PP2 (2)'!$B$6:$B$100,'PP2 (2)'!$E$6:$E$100,"") -> 1 | K11: =_xlfn.XLOOKUP($C11,'PP3 (1)'!$B$5:$B$106,'PP3 (1)'!$E$5:$E$106,"") -> 0.5 | L11: =_xlfn.XLOOKUP($C11,'PP3 (2)'!$B$5:$B$108,'PP3 (2)'!$E$5:$E$108,"") -> 0.8 | M11: =_xlfn.XLOOKUP($C11,'PP4 (1)'!$B$6:$B$100,'PP4 (1)'!$E$6:$E$100,"") -> 1 | N11: =_xlfn.XLOOKUP($C11,'PP4 (2)'!$B$6:$B$100,'PP4 (2)'!$E$6:$E$100,"") -> 0.83 | O11: =_xlfn.XLOOKUP($C11,'PP5 (1)'!$B$6:$B$100,'PP5 (1)'!$E$6:$E$100,"") | P11: =_xlfn.XLOOKUP($C11,'PP5 (2)'!$B$6:$B$100,'PP5 (2)'!$E$6:$E$100,"") | Q11: =SUM(R11:AC11) -> 275 | R11: =_xlfn.XLOOKUP($C11,'MP (1)'!$B$6:$B$100,'MP (1)'!$F$6:$F$100,"") -> 29 | S11: =_xlfn.XLOOKUP($C11,'MP (2)'!$B$6:$B$100,'MP (2)'!$F$6:$F$100,"") -> 27 | T11: =_xlfn.XLOOKUP($C11,'PP1 (1)'!$B$6:$B$99,'PP1 (1)'!$F$6:$F$99,"") -> 31 | U11: =_xlfn.XLOOKUP($C11,'PP1 (2)'!$B$6:$B$98,'PP1 (2)'!$F$6:$F$98,"") -> 27 | V11: =_xlfn.XLOOKUP($C11,'PP2 (1)'!$B$6:$B$106,'PP2 (1)'!$F$6:$F$106,"") -> 30 | W11: =_xlfn.XLOOKUP($C11,'PP2 (2)'!$B$6:$B$100,'PP2 (2)'!$F$6:$F$100,"") -> 30 | X11: =_xlfn.XLOOKUP($C11,'PP3 (1)'!$B$5:$B$106,'PP3 (1)'!$F$5:$F$106,"") -> 21 | Y11: =_xlfn.XLOOKUP($C11,'PP3 (2)'!$B$5:$B$108,'PP3 (2)'!$F$5:$F$108,"") -> 22 | Z11: =_xlfn.XLOOKUP($C11,'PP4 (1)'!$B$6:$B$100,'PP4 (1)'!$F$6:$F$100,"") -> 30 | AA11: =_xlfn.XLOOKUP($C11,'PP4 (2)'!$B$6:$B$100,'PP4 (2)'!$F$6:$F$100,"") -> 28 | AB11: =_xlfn.XLOOKUP($C11,'PP5 (1)'!$B$6:$B$100,'PP5 (1)'!$F$6:$F$100,"") | AC11: =_xlfn.XLOOKUP($C11,'PP5 (2)'!$B$6:$B$100,'PP5 (2)'!$F$6:$F$100,"") | AD11: =SUM(AE11:AP11) -> 120 | AE11: =_xlfn.XLOOKUP($C11,'MP (1)'!$B$6:$B$100,'MP (1)'!$H$6:$H$100,"") -> 13 | AF11: =_xlfn.XLOOKUP($C11,'MP (2)'!$B$6:$B$100,'MP (2)'!$H$6:$H$100,"") -> 10 | AG11: =_xlfn.XLOOKUP($C11,'PP1 (1)'!$B$6:$B$99,'PP1 (1)'!$H$6:$H$99,"") -> 11 | AH11: =_xlfn.XLOOKUP($C11,'PP1 (2)'!$B$6:$B$98,'PP1 (2)'!$H$6:$H$98,"") -> 0 | AI11: =_xlfn.XLOOKUP($C11,'PP2 (1)'!$B$6:$B$106,'PP2 (1)'!$H$6:$H$106,"") -> 20 | AJ11: =_xlfn.XLOOKUP($C11,'PP2 (2)'!$B$6:$B$100,'PP2 (2)'!$H$6:$H$100,"") -> 18 | AK11: =_xlfn.XLOOKUP($C11,'PP3 (1)'!$B$5:$B$106,'PP3 (1)'!$H$5:$H$106,"") -> 1 | AL11: =_xlfn.XLOOKUP($C11,'PP3 (2)'!$B$5:$B$108,'PP3 (2)'!$H$5:$H$108,"") -> 11 | AM11: =_xlfn.XLOOKUP($C11,'PP4 (1)'!$B$6:$B$100,'PP4 (1)'!$H$6:$H$100,"") -> 24 | AN11: =_xlfn.XLOOKUP($C11,'PP4 (2)'!$B$6:$B$100,'PP4 (2)'!$H$6:$H$100,"") -> 12 | AO11: =_xlfn.XLOOKUP($C11,'PP5 (1)'!$B$6:$B$100,'PP5 (1)'!$H$6:$H$100,"") | AP11: =_xlfn.XLOOKUP($C11,'PP5 (2)'!$B$6:$B$100,'PP5 (2)'!$H$6:$H$100,"")
A12: =ROW()-4 -> 8 | B12: 3 | C12: KOSTRZEWA Ireneusz | D12: =SUM(E12:P12) -> 8.18 | E12: =_xlfn.XLOOKUP($C12,'MP (1)'!$B$6:$B$100,'MP (1)'!$E$6:$E$100,"") -> 0.67 | F12: =_xlfn.XLOOKUP($C12,'MP (2)'!$B$6:$B$100,'MP (2)'!$E$6:$E$100,"") -> 0.86 | G12: =_xlfn.XLOOKUP($C12,'PP1 (1)'!$B$6:$B$99,'PP1 (1)'!$E$6:$E$99,"") -> 0.86 | H12: =_xlfn.XLOOKUP($C12,'PP1 (2)'!$B$6:$B$98,'PP1 (2)'!$E$6:$E$98,"") -> 0.83 | I12: =_xlfn.XLOOKUP($C12,'PP2 (1)'!$B$6:$B$106,'PP2 (1)'!$E$6:$E$106,"") -> 1 | J12: =_xlfn.XLOOKUP($C12,'PP2 (2)'!$B$6:$B$100,'PP2 (2)'!$E$6:$E$100,"") -> 0.83 | K12: =_xlfn.XLOOKUP($C12,'PP3 (1)'!$B$5:$B$106,'PP3 (1)'!$E$5:$E$106,"") -> 0.83 | L12: =_xlfn.XLOOKUP($C12,'PP3 (2)'!$B$5:$B$108,'PP3 (2)'!$E$5:$E$108,"") -> 0.8 | M12: =_xlfn.XLOOKUP($C12,'PP4 (1)'!$B$6:$B$100,'PP4 (1)'!$E$6:$E$100,"") | N12: =_xlfn.XLOOKUP($C12,'PP4 (2)'!$B$6:$B$100,'PP4 (2)'!$E$6:$E$100,"") | O12: =_xlfn.XLOOKUP($C12,'PP5 (1)'!$B$6:$B$100,'PP5 (1)'!$E$6:$E$100,"") -> 0.67 | P12: =_xlfn.XLOOKUP($C12,'PP5 (2)'!$B$6:$B$100,'PP5 (2)'!$E$6:$E$100,"") -> 0.83 | Q12: =SUM(R12:AC12) -> 279 | R12: =_xlfn.XLOOKUP($C12,'MP (1)'!$B$6:$B$100,'MP (1)'!$F$6:$F$100,"") -> 20 | S12: =_xlfn.XLOOKUP($C12,'MP (2)'!$B$6:$B$100,'MP (2)'!$F$6:$F$100,"") -> 34 | T12: =_xlfn.XLOOKUP($C12,'PP1 (1)'!$B$6:$B$99,'PP1 (1)'!$F$6:$F$99,"") -> 32 | U12: =_xlfn.XLOOKUP($C12,'PP1 (2)'!$B$6:$B$98,'PP1 (2)'!$F$6:$F$98,"") -> 28 | V12: =_xlfn.XLOOKUP($C12,'PP2 (1)'!$B$6:$B$106,'PP2 (1)'!$F$6:$F$106,"") -> 30 | W12: =_xlfn.XLOOKUP($C12,'PP2 (2)'!$B$6:$B$100,'PP2 (2)'!$F$6:$F$100,"") -> 29 | X12: =_xlfn.XLOOKUP($C12,'PP3 (1)'!$B$5:$B$106,'PP3 (1)'!$F$5:$F$106,"") -> 29 | Y12: =_xlfn.XLOOKUP($C12,'PP3 (2)'!$B$5:$B$108,'PP3 (2)'!$F$5:$F$108,"") -> 24 | Z12: =_xlfn.XLOOKUP($C12,'PP4 (1)'!$B$6:$B$100,'PP4 (1)'!$F$6:$F$100,"") | AA12: =_xlfn.XLOOKUP($C12,'PP4 (2)'!$B$6:$B$100,'PP4 (2)'!$F$6:$F$100,"") | AB12: =_xlfn.XLOOKUP($C12,'PP5 (1)'!$B$6:$B$100,'PP5 (1)'!$F$6:$F$100,"") -> 26 | AC12: =_xlfn.XLOOKUP($C12,'PP5 (2)'!$B$6:$B$100,'PP5 (2)'!$F$6:$F$100,"") -> 27 | AD12: =SUM(AE12:AP12) -> 151 | AE12: =_xlfn.XLOOKUP($C12,'MP (1)'!$B$6:$B$100,'MP (1)'!$H$6:$H$100,"") -> 10 | AF12: =_xlfn.XLOOKUP($C12,'MP (2)'!$B$6:$B$100,'MP (2)'!$H$6:$H$100,"") -> 18 | AG12: =_xlfn.XLOOKUP($C12,'PP1 (1)'!$B$6:$B$99,'PP1 (1)'!$H$6:$H$99,"") -> 17 | AH12: =_xlfn.XLOOKUP($C12,'PP1 (2)'!$B$6:$B$98,'PP1 (2)'!$H$6:$H$98,"") -> 18 | AI12: =_xlfn.XLOOKUP($C12,'PP2 (1)'!$B$6:$B$106,'PP2 (1)'!$H$6:$H$106,"") -> 15 | AJ12: =_xlfn.XLOOKUP($C12,'PP2 (2)'!$B$6:$B$100,'PP2 (2)'!$H$6:$H$100,"") -> 23 | AK12: =_xlfn.XLOOKUP($C12,'PP3 (1)'!$B$5:$B$106,'PP3 (1)'!$H$5:$H$106,"") -> 15 | AL12: =_xlfn.XLOOKUP($C12,'PP3 (2)'!$B$5:$B$108,'PP3 (2)'!$H$5:$H$108,"") -> 14 | AM12: =_xlfn.XLOOKUP($C12,'PP4 (1)'!$B$6:$B$100,'PP4 (1)'!$H$6:$H$100,"") | AN12: =_xlfn.XLOOKUP($C12,'PP4 (2)'!$B$6:$B$100,'PP4 (2)'!$H$6:$H$100,"") | AO12: =_xlfn.XLOOKUP($C12,'PP5 (1)'!$B$6:$B$100,'PP5 (1)'!$H$6:$H$100,"") -> 7 | AP12: =_xlfn.XLOOKUP($C12,'PP5 (2)'!$B$6:$B$100,'PP5 (2)'!$H$6:$H$100,"") -> 14
A13: =ROW()-4 -> 9 | B13: 3 | C13: AUGUSTOWSKI Waldemar | D13: =SUM(E13:P13) -> 8.04 | E13: =_xlfn.XLOOKUP($C13,'MP (1)'!$B$6:$B$100,'MP (1)'!$E$6:$E$100,"") -> 0.5 | F13: =_xlfn.XLOOKUP($C13,'MP (2)'!$B$6:$B$100,'MP (2)'!$E$6:$E$100,"") -> 0.67 | G13: =_xlfn.XLOOKUP($C13,'PP1 (1)'!$B$6:$B$99,'PP1 (1)'!$E$6:$E$99,"") -> 0.83 | H13: =_xlfn.XLOOKUP($C13,'PP1 (2)'!$B$6:$B$98,'PP1 (2)'!$E$6:$E$98,"") -> 0.57 | I13: =_xlfn.XLOOKUP($C13,'PP2 (1)'!$B$6:$B$106,'PP2 (1)'!$E$6:$E$106,"") -> 0.67 | J13: =_xlfn.XLOOKUP($C13,'PP2 (2)'!$B$6:$B$100,'PP2 (2)'!$E$6:$E$100,"") -> 0.67 | K13: =_xlfn.XLOOKUP($C13,'PP3 (1)'!$B$5:$B$106,'PP3 (1)'!$E$5:$E$106,"") -> 0.4 | L13: =_xlfn.XLOOKUP($C13,'PP3 (2)'!$B$5:$B$108,'PP3 (2)'!$E$5:$E$108,"") -> 0.5 | M13: =_xlfn.XLOOKUP($C13,'PP4 (1)'!$B$6:$B$100,'PP4 (1)'!$E$6:$E$100,"") -> 1 | N13: =_xlfn.XLOOKUP($C13,'PP4 (2)'!$B$6:$B$100,'PP4 (2)'!$E$6:$E$100,"") -> 0.6 | O13: =_xlfn.XLOOKUP($C13,'PP5 (1)'!$B$6:$B$100,'PP5 (1)'!$E$6:$E$100,"") -> 0.83 | P13: =_xlfn.XLOOKUP($C13,'PP5 (2)'!$B$6:$B$100,'PP5 (2)'!$E$6:$E$100,"") -> 0.8 | Q13: =SUM(R13:AC13) -> 287 | R13: =_xlfn.XLOOKUP($C13,'MP (1)'!$B$6:$B$100,'MP (1)'!$F$6:$F$100,"") -> 22 | S13: =_xlfn.XLOOKUP($C13,'MP (2)'!$B$6:$B$100,'MP (2)'!$F$6:$F$100,"") -> 25 | T13: =_xlfn.XLOOKUP($C13,'PP1 (1)'!$B$6:$B$99,'PP1 (1)'!$F$6:$F$99,"") -> 27 | U13: =_xlfn.XLOOKUP($C13,'PP1 (2)'!$B$6:$B$98,'PP1 (2)'!$F$6:$F$98,"") -> 30 | V13: =_xlfn.XLOOKUP($C13,'PP2 (1)'!$B$6:$B$106,'PP2 (1)'!$F$6:$F$106,"") -> 24 | W13: =_xlfn.XLOOKUP($C13,'PP2 (2)'!$B$6:$B$100,'PP2 (2)'!$F$6:$F$100,"") -> 23 | X13: =_xlfn.XLOOKUP($C13,'PP3 (1)'!$B$5:$B$106,'PP3 (1)'!$F$5:$F$106,"") -> 19 | Y13: =_xlfn.XLOOKUP($C13,'PP3 (2)'!$B$5:$B$108,'PP3 (2)'!$F$5:$F$108,"") -> 25 | Z13: =_xlfn.XLOOKUP($C13,'PP4 (1)'!$B$6:$B$100,'PP4 (1)'!$F$6:$F$100,"") -> 23 | AA13: =_xlfn.XLOOKUP($C13,'PP4 (2)'!$B$6:$B$100,'PP4 (2)'!$F$6:$F$100,"") -> 19 | AB13: =_xlfn.XLOOKUP($C13,'PP5 (1)'!$B$6:$B$100,'PP5 (1)'!$F$6:$F$100,"") -> 27 | AC13: =_xlfn.XLOOKUP($C13,'PP5 (2)'!$B$6:$B$100,'PP5 (2)'!$F$6:$F$100,"") -> 23 | AD13: =SUM(AE13:AP13) -> 89 | AE13: =_xlfn.XLOOKUP($C13,'MP (1)'!$B$6:$B$100,'MP (1)'!$H$6:$H$100,"") -> 5 | AF13: =_xlfn.XLOOKUP($C13,'MP (2)'!$B$6:$B$100,'MP (2)'!$H$6:$H$100,"") -> 7 | AG13: =_xlfn.XLOOKUP($C13,'PP1 (1)'!$B$6:$B$99,'PP1 (1)'!$H$6:$H$99,"") -> 7 | AH13: =_xlfn.XLOOKUP($C13,'PP1 (2)'!$B$6:$B$98,'PP1 (2)'!$H$6:$H$98,"") -> 5 | AI13: =_xlfn.XLOOKUP($C13,'PP2 (1)'!$B$6:$B$106,'PP2 (1)'!$H$6:$H$106,"") -> 8 | AJ13: =_xlfn.XLOOKUP($C13,'PP2 (2)'!$B$6:$B$100,'PP2 (2)'!$H$6:$H$100,"") -> 6 | AK13: =_xlfn.XLOOKUP($C13,'PP3 (1)'!$B$5:$B$106,'PP3 (1)'!$H$5:$H$106,"") -> 2 | AL13: =_xlfn.XLOOKUP($C13,'PP3 (2)'!$B$5:$B$108,'PP3 (2)'!$H$5:$H$108,"") -> 4 | AM13: =_xlfn.XLOOKUP($C13,'PP4 (1)'!$B$6:$B$100,'PP4 (1)'!$H$6:$H$100,"") -> 15 | AN13: =_xlfn.XLOOKUP($C13,'PP4 (2)'!$B$6:$B$100,'PP4 (2)'!$H$6:$H$100,"") -> 4 | AO13: =_xlfn.XLOOKUP($C13,'PP5 (1)'!$B$6:$B$100,'PP5 (1)'!$H$6:$H$100,"") -> 14 | AP13: =_xlfn.XLOOKUP($C13,'PP5 (2)'!$B$6:$B$100,'PP5 (2)'!$H$6:$H$100,"") -> 12
A14: =ROW()-4 -> 10 | B14: 2 | C14: ATANASSOW Aleksander | D14: =SUM(E14:P14) -> 7.16 | E14: =_xlfn.XLOOKUP($C14,'MP (1)'!$B$6:$B$100,'MP (1)'!$E$6:$E$100,"") | F14: =_xlfn.XLOOKUP($C14,'MP (2)'!$B$6:$B$100,'MP (2)'!$E$6:$E$100,"") | G14: =_xlfn.XLOOKUP($C14,'PP1 (1)'!$B$6:$B$99,'PP1 (1)'!$E$6:$E$99,"") -> 0.83 | H14: =_xlfn.XLOOKUP($C14,'PP1 (2)'!$B$6:$B$98,'PP1 (2)'!$E$6:$E$98,"") -> 1 | I14: =_xlfn.XLOOKUP($C14,'PP2 (1)'!$B$6:$B$106,'PP2 (1)'!$E$6:$E$106,"") -> 0.83 | J14: =_xlfn.XLOOKUP($C14,'PP2 (2)'!$B$6:$B$100,'PP2 (2)'!$E$6:$E$100,"") -> 1 | K14: =_xlfn.XLOOKUP($C14,'PP3 (1)'!$B$5:$B$106,'PP3 (1)'!$E$5:$E$106,"") -> 0.83 | L14: =_xlfn.XLOOKUP($C14,'PP3 (2)'!$B$5:$B$108,'PP3 (2)'!$E$5:$E$108,"") -> 0.67 | M14: =_xlfn.XLOOKUP($C14,'PP4 (1)'!$B$6:$B$100,'PP4 (1)'!$E$6:$E$100,"") -> 1 | N14: =_xlfn.XLOOKUP($C14,'PP4 (2)'!$B$6:$B$100,'PP4 (2)'!$E$6:$E$100,"") -> 1 | O14: =_xlfn.XLOOKUP($C14,'PP5 (1)'!$B$6:$B$100,'PP5 (1)'!$E$6:$E$100,"") | P14: =_xlfn.XLOOKUP($C14,'PP5 (2)'!$B$6:$B$100,'PP5 (2)'!$E$6:$E$100,"") | Q14: =SUM(R14:AC14) -> 218 | R14: =_xlfn.XLOOKUP($C14,'MP (1)'!$B$6:$B$100,'MP (1)'!$F$6:$F$100,"") | S14: =_xlfn.XLOOKUP($C14,'MP (2)'!$B$6:$B$100,'MP (2)'!$F$6:$F$100,"") | T14: =_xlfn.XLOOKUP($C14,'PP1 (1)'!$B$6:$B$99,'PP1 (1)'!$F$6:$F$99,"") -> 27 | U14: =_xlfn.XLOOKUP($C14,'PP1 (2)'!$B$6:$B$98,'PP1 (2)'!$F$6:$F$98,"") -> 27 | V14: =_xlfn.XLOOKUP($C14,'PP2 (1)'!$B$6:$B$106,'PP2 (1)'!$F$6:$F$106,"") -> 26 | W14: =_xlfn.XLOOKUP($C14,'PP2 (2)'!$B$6:$B$100,'PP2 (2)'!$F$6:$F$100,"") -> 30 | X14: =_xlfn.XLOOKUP($C14,'PP3 (1)'!$B$5:$B$106,'PP3 (1)'!$F$5:$F$106,"") -> 29 | Y14: =_xlfn.XLOOKUP($C14,'PP3 (2)'!$B$5:$B$108,'PP3 (2)'!$F$5:$F$108,"") -> 24 | Z14: =_xlfn.XLOOKUP($C14,'PP4 (1)'!$B$6:$B$100,'PP4 (1)'!$F$6:$F$100,"") -> 30 | AA14: =_xlfn.XLOOKUP($C14,'PP4 (2)'!$B$6:$B$100,'PP4 (2)'!$F$6:$F$100,"") -> 25 | AB14: =_xlfn.XLOOKUP($C14,'PP5 (1)'!$B$6:$B$100,'PP5 (1)'!$F$6:$F$100,"") | AC14: =_xlfn.XLOOKUP($C14,'PP5 (2)'!$B$6:$B$100,'PP5 (2)'!$F$6:$F$100,"") | AD14: =SUM(AE14:AP14) -> 126 | AE14: =_xlfn.XLOOKUP($C14,'MP (1)'!$B$6:$B$100,'MP (1)'!$H$6:$H$100,"") | AF14: =_xlfn.XLOOKUP($C14,'MP (2)'!$B$6:$B$100,'MP (2)'!$H$6:$H$100,"") | AG14: =_xlfn.XLOOKUP($C14,'PP1 (1)'!$B$6:$B$99,'PP1 (1)'!$H$6:$H$99,"") -> 14 | AH14: =_xlfn.XLOOKUP($C14,'PP1 (2)'!$B$6:$B$98,'PP1 (2)'!$H$6:$H$98,"") -> 15 | AI14: =_xlfn.XLOOKUP($C14,'PP2 (1)'!$B$6:$B$106,'PP2 (1)'!$H$6:$H$106,"") -> 16 | AJ14: =_xlfn.XLOOKUP($C14,'PP2 (2)'!$B$6:$B$100,'PP2 (2)'!$H$6:$H$100,"") -> 20 | AK14: =_xlfn.XLOOKUP($C14,'PP3 (1)'!$B$5:$B$106,'PP3 (1)'!$H$5:$H$106,"") -> 16 | AL14: =_xlfn.XLOOKUP($C14,'PP3 (2)'!$B$5:$B$108,'PP3 (2)'!$H$5:$H$108,"") -> 14 | AM14: =_xlfn.XLOOKUP($C14,'PP4 (1)'!$B$6:$B$100,'PP4 (1)'!$H$6:$H$100,"") -> 15 | AN14: =_xlfn.XLOOKUP($C14,'PP4 (2)'!$B$6:$B$100,'PP4 (2)'!$H$6:$H$100,"") -> 16 | AO14: =_xlfn.XLOOKUP($C14,'PP5 (1)'!$B$6:$B$100,'PP5 (1)'!$H$6:$H$100,"") | AP14: =_xlfn.XLOOKUP($C14,'PP5 (2)'!$B$6:$B$100,'PP5 (2)'!$H$6:$H$100,"")
A15: =ROW()-4 -> 11 | B15: 0 | C15: WALCZEWSKI Konrad | D15: =SUM(E15:P15) -> 6.93 | E15: =_xlfn.XLOOKUP($C15,'MP (1)'!$B$6:$B$100,'MP (1)'!$E$6:$E$100,"") -> 0.57 | F15: =_xlfn.XLOOKUP($C15,'MP (2)'!$B$6:$B$100,'MP (2)'!$E$6:$E$100,"") -> 0.5 | G15: =_xlfn.XLOOKUP($C15,'PP1 (1)'!$B$6:$B$99,'PP1 (1)'!$E$6:$E$99,"") -> 0.33 | H15: =_xlfn.XLOOKUP($C15,'PP1 (2)'!$B$6:$B$98,'PP1 (2)'!$E$6:$E$98,"") -> 0.5 | I15: =_xlfn.XLOOKUP($C15,'PP2 (1)'!$B$6:$B$106,'PP2 (1)'!$E$6:$E$106,"") -> 0.83 | J15: =_xlfn.XLOOKUP($C15,'PP2 (2)'!$B$6:$B$100,'PP2 (2)'!$E$6:$E$100,"") -> 0.67 | K15: =_xlfn.XLOOKUP($C15,'PP3 (1)'!$B$5:$B$106,'PP3 (1)'!$E$5:$E$106,"") -> 0.83 | L15: =_xlfn.XLOOKUP($C15,'PP3 (2)'!$B$5:$B$108,'PP3 (2)'!$E$5:$E$108,"") -> 0.6 | M15: =_xlfn.XLOOKUP($C15,'PP4 (1)'!$B$6:$B$100,'PP4 (1)'!$E$6:$E$100,"") -> 0.5 | N15: =_xlfn.XLOOKUP($C15,'PP4 (2)'!$B$6:$B$100,'PP4 (2)'!$E$6:$E$100,"") -> 0.4 | O15: =_xlfn.XLOOKUP($C15,'PP5 (1)'!$B$6:$B$100,'PP5 (1)'!$E$6:$E$100,"") -> 0.8 | P15: =_xlfn.XLOOKUP($C15,'PP5 (2)'!$B$6:$B$100,'PP5 (2)'!$E$6:$E$100,"") -> 0.4 | Q15: =SUM(R15:AC15) -> 277 | R15: =_xlfn.XLOOKUP($C15,'MP (1)'!$B$6:$B$100,'MP (1)'!$F$6:$F$100,"") -> 26 | S15: =_xlfn.XLOOKUP($C15,'MP (2)'!$B$6:$B$100,'MP (2)'!$F$6:$F$100,"") -> 19 | T15: =_xlfn.XLOOKUP($C15,'PP1 (1)'!$B$6:$B$99,'PP1 (1)'!$F$6:$F$99,"") -> 24 | U15: =_xlfn.XLOOKUP($C15,'PP1 (2)'!$B$6:$B$98,'PP1 (2)'!$F$6:$F$98,"") -> 23 | V15: =_xlfn.XLOOKUP($C15,'PP2 (1)'!$B$6:$B$106,'PP2 (1)'!$F$6:$F$106,"") -> 28 | W15: =_xlfn.XLOOKUP($C15,'PP2 (2)'!$B$6:$B$100,'PP2 (2)'!$F$6:$F$100,"") -> 24 | X15: =_xlfn.XLOOKUP($C15,'PP3 (1)'!$B$5:$B$106,'PP3 (1)'!$F$5:$F$106,"") -> 29 | Y15: =_xlfn.XLOOKUP($C15,'PP3 (2)'!$B$5:$B$108,'PP3 (2)'!$F$5:$F$108,"") -> 19 | Z15: =_xlfn.XLOOKUP($C15,'PP4 (1)'!$B$6:$B$100,'PP4 (1)'!$F$6:$F$100,"") -> 23 | AA15: =_xlfn.XLOOKUP($C15,'PP4 (2)'!$B$6:$B$100,'PP4 (2)'!$F$6:$F$100,"") -> 22 | AB15: =_xlfn.XLOOKUP($C15,'PP5 (1)'!$B$6:$B$100,'PP5 (1)'!$F$6:$F$100,"") -> 21 | AC15: =_xlfn.XLOOKUP($C15,'PP5 (2)'!$B$6:$B$100,'PP5 (2)'!$F$6:$F$100,"") -> 19 | AD15: =SUM(AE15:AP15) -> 34 | AE15: =_xlfn.XLOOKUP($C15,'MP (1)'!$B$6:$B$100,'MP (1)'!$H$6:$H$100,"") -> -2 | AF15: =_xlfn.XLOOKUP($C15,'MP (2)'!$B$6:$B$100,'MP (2)'!$H$6:$H$100,"") -> -3 | AG15: =_xlfn.XLOOKUP($C15,'PP1 (1)'!$B$6:$B$99,'PP1 (1)'!$H$6:$H$99,"") -> -1 | AH15: =_xlfn.XLOOKUP($C15,'PP1 (2)'!$B$6:$B$98,'PP1 (2)'!$H$6:$H$98,"") -> 1 | AI15: =_xlfn.XLOOKUP($C15,'PP2 (1)'!$B$6:$B$106,'PP2 (1)'!$H$6:$H$106,"") -> 11 | AJ15: =_xlfn.XLOOKUP($C15,'PP2 (2)'!$B$6:$B$100,'PP2 (2)'!$H$6:$H$100,"") -> 4 | AK15: =_xlfn.XLOOKUP($C15,'PP3 (1)'!$B$5:$B$106,'PP3 (1)'!$H$5:$H$106,"") -> 12 | AL15: =_xlfn.XLOOKUP($C15,'PP3 (2)'!$B$5:$B$108,'PP3 (2)'!$H$5:$H$108,"") -> -1 | AM15: =_xlfn.XLOOKUP($C15,'PP4 (1)'!$B$6:$B$100,'PP4 (1)'!$H$6:$H$100,"") -> 2 | AN15: =_xlfn.XLOOKUP($C15,'PP4 (2)'!$B$6:$B$100,'PP4 (2)'!$H$6:$H$100,"") -> 3 | AO15: =_xlfn.XLOOKUP($C15,'PP5 (1)'!$B$6:$B$100,'PP5 (1)'!$H$6:$H$100,"") -> 10 | AP15: =_xlfn.XLOOKUP($C15,'PP5 (2)'!$B$6:$B$100,'PP5 (2)'!$H$6:$H$100,"") -> -2
A16: =ROW()-4 -> 12 | B16: 0 | C16: DZIUBIŃSKI Mateusz | D16: =SUM(E16:P16) -> 6.91 | E16: =_xlfn.XLOOKUP($C16,'MP (1)'!$B$6:$B$100,'MP (1)'!$E$6:$E$100,"") -> 0.5 | F16: =_xlfn.XLOOKUP($C16,'MP (2)'!$B$6:$B$100,'MP (2)'!$E$6:$E$100,"") -> 0.43 | G16: =_xlfn.XLOOKUP($C16,'PP1 (1)'!$B$6:$B$99,'PP1 (1)'!$E$6:$E$99,"") -> 0.67 | H16: =_xlfn.XLOOKUP($C16,'PP1 (2)'!$B$6:$B$98,'PP1 (2)'!$E$6:$E$98,"") -> 0.71 | I16: =_xlfn.XLOOKUP($C16,'PP2 (1)'!$B$6:$B$106,'PP2 (1)'!$E$6:$E$106,"") -> 0.33 | J16: =_xlfn.XLOOKUP($C16,'PP2 (2)'!$B$6:$B$100,'PP2 (2)'!$E$6:$E$100,"") -> 0.67 | K16: =_xlfn.XLOOKUP($C16,'PP3 (1)'!$B$5:$B$106,'PP3 (1)'!$E$5:$E$106,"") -> 0.4 | L16: =_xlfn.XLOOKUP($C16,'PP3 (2)'!$B$5:$B$108,'PP3 (2)'!$E$5:$E$108,"") -> 0.67 | M16: =_xlfn.XLOOKUP($C16,'PP4 (1)'!$B$6:$B$100,'PP4 (1)'!$E$6:$E$100,"") -> 0.8 | N16: =_xlfn.XLOOKUP($C16,'PP4 (2)'!$B$6:$B$100,'PP4 (2)'!$E$6:$E$100,"") -> 0.33 | O16: =_xlfn.XLOOKUP($C16,'PP5 (1)'!$B$6:$B$100,'PP5 (1)'!$E$6:$E$100,"") -> 0.8 | P16: =_xlfn.XLOOKUP($C16,'PP5 (2)'!$B$6:$B$100,'PP5 (2)'!$E$6:$E$100,"") -> 0.6 | Q16: =SUM(R16:AC16) -> 273 | R16: =_xlfn.XLOOKUP($C16,'MP (1)'!$B$6:$B$100,'MP (1)'!$F$6:$F$100,"") -> 25 | S16: =_xlfn.XLOOKUP($C16,'MP (2)'!$B$6:$B$100,'MP (2)'!$F$6:$F$100,"") -> 23 | T16: =_xlfn.XLOOKUP($C16,'PP1 (1)'!$B$6:$B$99,'PP1 (1)'!$F$6:$F$99,"") -> 26 | U16: =_xlfn.XLOOKUP($C16,'PP1 (2)'!$B$6:$B$98,'PP1 (2)'!$F$6:$F$98,"") -> 32 | V16: =_xlfn.XLOOKUP($C16,'PP2 (1)'!$B$6:$B$106,'PP2 (1)'!$F$6:$F$106,"") -> 19 | W16: =_xlfn.XLOOKUP($C16,'PP2 (2)'!$B$6:$B$100,'PP2 (2)'!$F$6:$F$100,"") -> 22 | X16: =_xlfn.XLOOKUP($C16,'PP3 (1)'!$B$5:$B$106,'PP3 (1)'!$F$5:$F$106,"") -> 15 | Y16: =_xlfn.XLOOKUP($C16,'PP3 (2)'!$B$5:$B$108,'PP3 (2)'!$F$5:$F$108,"") -> 26 | Z16: =_xlfn.XLOOKUP($C16,'PP4 (1)'!$B$6:$B$100,'PP4 (1)'!$F$6:$F$100,"") -> 21 | AA16: =_xlfn.XLOOKUP($C16,'PP4 (2)'!$B$6:$B$100,'PP4 (2)'!$F$6:$F$100,"") -> 23 | AB16: =_xlfn.XLOOKUP($C16,'PP5 (1)'!$B$6:$B$100,'PP5 (1)'!$F$6:$F$100,"") -> 21 | AC16: =_xlfn.XLOOKUP($C16,'PP5 (2)'!$B$6:$B$100,'PP5 (2)'!$F$6:$F$100,"") -> 20 | AD16: =SUM(AE16:AP16) -> 34 | AE16: =_xlfn.XLOOKUP($C16,'MP (1)'!$B$6:$B$100,'MP (1)'!$H$6:$H$100,"") -> 1 | AF16: =_xlfn.XLOOKUP($C16,'MP (2)'!$B$6:$B$100,'MP (2)'!$H$6:$H$100,"") -> -4 | AG16: =_xlfn.XLOOKUP($C16,'PP1 (1)'!$B$6:$B$99,'PP1 (1)'!$H$6:$H$99,"") -> 4 | AH16: =_xlfn.XLOOKUP($C16,'PP1 (2)'!$B$6:$B$98,'PP1 (2)'!$H$6:$H$98,"") -> 8 | AI16: =_xlfn.XLOOKUP($C16,'PP2 (1)'!$B$6:$B$106,'PP2 (1)'!$H$6:$H$106,"") -> -8 | AJ16: =_xlfn.XLOOKUP($C16,'PP2 (2)'!$B$6:$B$100,'PP2 (2)'!$H$6:$H$100,"") -> 1 | AK16: =_xlfn.XLOOKUP($C16,'PP3 (1)'!$B$5:$B$106,'PP3 (1)'!$H$5:$H$106,"") -> 0 | AL16: =_xlfn.XLOOKUP($C16,'PP3 (2)'!$B$5:$B$108,'PP3 (2)'!$H$5:$H$108,"") -> 12 | AM16: =_xlfn.XLOOKUP($C16,'PP4 (1)'!$B$6:$B$100,'PP4 (1)'!$H$6:$H$100,"") -> 10 | AN16: =_xlfn.XLOOKUP($C16,'PP4 (2)'!$B$6:$B$100,'PP4 (2)'!$H$6:$H$100,"") -> -1 | AO16: =_xlfn.XLOOKUP($C16,'PP5 (1)'!$B$6:$B$100,'PP5 (1)'!$H$6:$H$100,"") -> 9 | AP16: =_xlfn.XLOOKUP($C16,'PP5 (2)'!$B$6:$B$100,'PP5 (2)'!$H$6:$H$100,"") -> 2
... A20: =ROW()-4 -> 16 | B20: 2 | C20: ŻUKOWSKI Wojciech | D20: =SUM(E20:P20) -> 5.67 | E20: =_xlfn.XLOOKUP($C20,'MP (1)'!$B$6:$B$100,'MP (1)'!$E$6:$E$100,"") -> 0.67 | F20: =_xlfn.XLOOKUP($C20,'MP (2)'!$B$6:$B$100,'MP (2)'!$E$6:$E$100,"") -> 0.57 | G20: =_xlfn.XLOOKUP($C20,'PP1 (1)'!$B$6:$B$99,'PP1 (1)'!$E$6:$E$99,"") -> 0.5 | H20: =_xlfn.XLOOKUP($C20,'PP1 (2)'!$B$6:$B$98,'PP1 (2)'!$E$6:$E$98,"") -> 0.33 | I20: =_xlfn.XLOOKUP($C20,'PP2 (1)'!$B$6:$B$106,'PP2 (1)'!$E$6:$E$106,"") -> 0.33 | J20: =_xlfn.XLOOKUP($C20,'PP2 (2)'!$B$6:$B$100,'PP2 (2)'!$E$6:$E$100,"") -> 0.67 | K20: =_xlfn.XLOOKUP($C20,'PP3 (1)'!$B$5:$B$106,'PP3 (1)'!$E$5:$E$106,"") -> 0.6 | L20: =_xlfn.XLOOKUP($C20,'PP3 (2)'!$B$5:$B$108,'PP3 (2)'!$E$5:$E$108,"") -> 0.8 | M20: =_xlfn.XLOOKUP($C20,'PP4 (1)'!$B$6:$B$100,'PP4 (1)'!$E$6:$E$100,"") | N20: =_xlfn.XLOOKUP($C20,'PP4 (2)'!$B$6:$B$100,'PP4 (2)'!$E$6:$E$100,"") | O20: =_xlfn.XLOOKUP($C20,'PP5 (1)'!$B$6:$B$100,'PP5 (1)'!$E$6:$E$100,"") -> 0.6 | P20: =_xlfn.XLOOKUP($C20,'PP5 (2)'!$B$6:$B$100,'PP5 (2)'!$E$6:$E$100,"") -> 0.6 | Q20: =SUM(R20:AC20) -> 224 | R20: =_xlfn.XLOOKUP($C20,'MP (1)'!$B$6:$B$100,'MP (1)'!$F$6:$F$100,"") -> 26 | S20: =_xlfn.XLOOKUP($C20,'MP (2)'!$B$6:$B$100,'MP (2)'!$F$6:$F$100,"") -> 28 | T20: =_xlfn.XLOOKUP($C20,'PP1 (1)'!$B$6:$B$99,'PP1 (1)'!$F$6:$F$99,"") -> 26 | U20: =_xlfn.XLOOKUP($C20,'PP1 (2)'!$B$6:$B$98,'PP1 (2)'!$F$6:$F$98,"") -> 22 | V20: =_xlfn.XLOOKUP($C20,'PP2 (1)'!$B$6:$B$106,'PP2 (1)'!$F$6:$F$106,"") -> 19 | W20: =_xlfn.XLOOKUP($C20,'PP2 (2)'!$B$6:$B$100,'PP2 (2)'!$F$6:$F$100,"") -> 22 | X20: =_xlfn.XLOOKUP($C20,'PP3 (1)'!$B$5:$B$106,'PP3 (1)'!$F$5:$F$106,"") -> 20 | Y20: =_xlfn.XLOOKUP($C20,'PP3 (2)'!$B$5:$B$108,'PP3 (2)'!$F$5:$F$108,"") -> 21 | Z20: =_xlfn.XLOOKUP($C20,'PP4 (1)'!$B$6:$B$100,'PP4 (1)'!$F$6:$F$100,"") | AA20: =_xlfn.XLOOKUP($C20,'PP4 (2)'!$B$6:$B$100,'PP4 (2)'!$F$6:$F$100,"") | AB20: =_xlfn.XLOOKUP($C20,'PP5 (1)'!$B$6:$B$100,'PP5 (1)'!$F$6:$F$100,"") -> 18 | AC20: =_xlfn.XLOOKUP($C20,'PP5 (2)'!$B$6:$B$100,'PP5 (2)'!$F$6:$F$100,"") -> 22 | AD20: =SUM(AE20:AP20) -> 29 | AE20: =_xlfn.XLOOKUP($C20,'MP (1)'!$B$6:$B$100,'MP (1)'!$H$6:$H$100,"") -> 8 | AF20: =_xlfn.XLOOKUP($C20,'MP (2)'!$B$6:$B$100,'MP (2)'!$H$6:$H$100,"") -> 6 | AG20: =_xlfn.XLOOKUP($C20,'PP1 (1)'!$B$6:$B$99,'PP1 (1)'!$H$6:$H$99,"") -> 4 | AH20: =_xlfn.XLOOKUP($C20,'PP1 (2)'!$B$6:$B$98,'PP1 (2)'!$H$6:$H$98,"") -> -6 | AI20: =_xlfn.XLOOKUP($C20,'PP2 (1)'!$B$6:$B$106,'PP2 (1)'!$H$6:$H$106,"") -> -4 | AJ20: =_xlfn.XLOOKUP($C20,'PP2 (2)'!$B$6:$B$100,'PP2 (2)'!$H$6:$H$100,"") -> 2 | AK20: =_xlfn.XLOOKUP($C20,'PP3 (1)'!$B$5:$B$106,'PP3 (1)'!$H$5:$H$106,"") -> 4 | AL20: =_xlfn.XLOOKUP($C20,'PP3 (2)'!$B$5:$B$108,'PP3 (2)'!$H$5:$H$108,"") -> 5 | AM20: =_xlfn.XLOOKUP($C20,'PP4 (1)'!$B$6:$B$100,'PP4 (1)'!$H$6:$H$100,"") | AN20: =_xlfn.XLOOKUP($C20,'PP4 (2)'!$B$6:$B$100,'PP4 (2)'!$H$6:$H$100,"") | AO20: =_xlfn.XLOOKUP($C20,'PP5 (1)'!$B$6:$B$100,'PP5 (1)'!$H$6:$H$100,"") -> 3 | AP20: =_xlfn.XLOOKUP($C20,'PP5 (2)'!$B$6:$B$100,'PP5 (2)'!$H$6:$H$100,"") -> 7
A21: =ROW()-4 -> 17 | B21: 1k | C21: KAMIŃSKA Gabriela | D21: =SUM(E21:P21) -> 5.61 | E21: =_xlfn.XLOOKUP($C21,'MP (1)'!$B$6:$B$100,'MP (1)'!$E$6:$E$100,"") -> 0.57 | F21: =_xlfn.XLOOKUP($C21,'MP (2)'!$B$6:$B$100,'MP (2)'!$E$6:$E$100,"") -> 0.67 | G21: =_xlfn.XLOOKUP($C21,'PP1 (1)'!$B$6:$B$99,'PP1 (1)'!$E$6:$E$99,"") -> 0.67 | H21: =_xlfn.XLOOKUP($C21,'PP1 (2)'!$B$6:$B$98,'PP1 (2)'!$E$6:$E$98,"") -> 0.43 | I21: =_xlfn.XLOOKUP($C21,'PP2 (1)'!$B$6:$B$106,'PP2 (1)'!$E$6:$E$106,"") -> 0.83 | J21: =_xlfn.XLOOKUP($C21,'PP2 (2)'!$B$6:$B$100,'PP2 (2)'!$E$6:$E$100,"") -> 0.67 | K21: =_xlfn.XLOOKUP($C21,'PP3 (1)'!$B$5:$B$106,'PP3 (1)'!$E$5:$E$106,"") -> 0.67 | L21: =_xlfn.XLOOKUP($C21,'PP3 (2)'!$B$5:$B$108,'PP3 (2)'!$E$5:$E$108,"") -> 0 | M21: =_xlfn.XLOOKUP($C21,'PP4 (1)'!$B$6:$B$100,'PP4 (1)'!$E$6:$E$100,"") -> 0.5 | N21: =_xlfn.XLOOKUP($C21,'PP4 (2)'!$B$6:$B$100,'PP4 (2)'!$E$6:$E$100,"") -> 0.6 | O21: =_xlfn.XLOOKUP($C21,'PP5 (1)'!$B$6:$B$100,'PP5 (1)'!$E$6:$E$100,"") | P21: =_xlfn.XLOOKUP($C21,'PP5 (2)'!$B$6:$B$100,'PP5 (2)'!$E$6:$E$100,"") | Q21: =SUM(R21:AC21) -> 250 | R21: =_xlfn.XLOOKUP($C21,'MP (1)'!$B$6:$B$100,'MP (1)'!$F$6:$F$100,"") -> 28 | S21: =_xlfn.XLOOKUP($C21,'MP (2)'!$B$6:$B$100,'MP (2)'!$F$6:$F$100,"") -> 26 | T21: =_xlfn.XLOOKUP($C21,'PP1 (1)'!$B$6:$B$99,'PP1 (1)'!$F$6:$F$99,"") -> 25 | U21: =_xlfn.XLOOKUP($C21,'PP1 (2)'!$B$6:$B$98,'PP1 (2)'!$F$6:$F$98,"") -> 30 | V21: =_xlfn.XLOOKUP($C21,'PP2 (1)'!$B$6:$B$106,'PP2 (1)'!$F$6:$F$106,"") -> 28 | W21: =_xlfn.XLOOKUP($C21,'PP2 (2)'!$B$6:$B$100,'PP2 (2)'!$F$6:$F$100,"") -> 27 | X21: =_xlfn.XLOOKUP($C21,'PP3 (1)'!$B$5:$B$106,'PP3 (1)'!$F$5:$F$106,"") -> 23 | Y21: =_xlfn.XLOOKUP($C21,'PP3 (2)'!$B$5:$B$108,'PP3 (2)'!$F$5:$F$108,"") -> 21 | Z21: =_xlfn.XLOOKUP($C21,'PP4 (1)'!$B$6:$B$100,'PP4 (1)'!$F$6:$F$100,"") -> 19 | AA21: =_xlfn.XLOOKUP($C21,'PP4 (2)'!$B$6:$B$100,'PP4 (2)'!$F$6:$F$100,"") -> 23 | AB21: =_xlfn.XLOOKUP($C21,'PP5 (1)'!$B$6:$B$100,'PP5 (1)'!$F$6:$F$100,"") | AC21: =_xlfn.XLOOKUP($C21,'PP5 (2)'!$B$6:$B$100,'PP5 (2)'!$F$6:$F$100,"") | AD21: =SUM(AE21:AP21) -> 37 | AE21: =_xlfn.XLOOKUP($C21,'MP (1)'!$B$6:$B$100,'MP (1)'!$H$6:$H$100,"") -> 3 | AF21: =_xlfn.XLOOKUP($C21,'MP (2)'!$B$6:$B$100,'MP (2)'!$H$6:$H$100,"") -> 9 | AG21: =_xlfn.XLOOKUP($C21,'PP1 (1)'!$B$6:$B$99,'PP1 (1)'!$H$6:$H$99,"") -> 5 | AH21: =_xlfn.XLOOKUP($C21,'PP1 (2)'!$B$6:$B$98,'PP1 (2)'!$H$6:$H$98,"") -> 4 | AI21: =_xlfn.XLOOKUP($C21,'PP2 (1)'!$B$6:$B$106,'PP2 (1)'!$H$6:$H$106,"") -> 8 | AJ21: =_xlfn.XLOOKUP($C21,'PP2 (2)'!$B$6:$B$100,'PP2 (2)'!$H$6:$H$100,"") -> 8 | AK21: =_xlfn.XLOOKUP($C21,'PP3 (1)'!$B$5:$B$106,'PP3 (1)'!$H$5:$H$106,"") -> 6 | AL21: =_xlfn.XLOOKUP($C21,'PP3 (2)'!$B$5:$B$108,'PP3 (2)'!$H$5:$H$108,"") -> -9 | AM21: =_xlfn.XLOOKUP($C21,'PP4 (1)'!$B$6:$B$100,'PP4 (1)'!$H$6:$H$100,"") -> 0 | AN21: =_xlfn.XLOOKUP($C21,'PP4 (2)'!$B$6:$B$100,'PP4 (2)'!$H$6:$H$100,"") -> 3 | AO21: =_xlfn.XLOOKUP($C21,'PP5 (1)'!$B$6:$B$100,'PP5 (1)'!$H$6:$H$100,"") | AP21: =_xlfn.XLOOKUP($C21,'PP5 (2)'!$B$6:$B$100,'PP5 (2)'!$H$6:$H$100,"")
A22: =ROW()-4 -> 18 | B22: 1 | C22: MALINOWSKI Piotr | D22: =SUM(E22:P22) -> 5.61 | E22: =_xlfn.XLOOKUP($C22,'MP (1)'!$B$6:$B$100,'MP (1)'!$E$6:$E$100,"") -> 0.57 | F22: =_xlfn.XLOOKUP($C22,'MP (2)'!$B$6:$B$100,'MP (2)'!$E$6:$E$100,"") -> 0.33 | G22: =_xlfn.XLOOKUP($C22,'PP1 (1)'!$B$6:$B$99,'PP1 (1)'!$E$6:$E$99,"") -> 0.43 | H22: =_xlfn.XLOOKUP($C22,'PP1 (2)'!$B$6:$B$98,'PP1 (2)'!$E$6:$E$98,"") -> 0.71 | I22: =_xlfn.XLOOKUP($C22,'PP2 (1)'!$B$6:$B$106,'PP2 (1)'!$E$6:$E$106,"") | J22: =_xlfn.XLOOKUP($C22,'PP2 (2)'!$B$6:$B$100,'PP2 (2)'!$E$6:$E$100,"") | K22: =_xlfn.XLOOKUP($C22,'PP3 (1)'!$B$5:$B$106,'PP3 (1)'!$E$5:$E$106,"") -> 0.67 | L22: =_xlfn.XLOOKUP($C22,'PP3 (2)'!$B$5:$B$108,'PP3 (2)'!$E$5:$E$108,"") -> 0.5 | M22: =_xlfn.XLOOKUP($C22,'PP4 (1)'!$B$6:$B$100,'PP4 (1)'!$E$6:$E$100,"") -> 0.83 | N22: =_xlfn.XLOOKUP($C22,'PP4 (2)'!$B$6:$B$100,'PP4 (2)'!$E$6:$E$100,"") -> 0.4 | O22: =_xlfn.XLOOKUP($C22,'PP5 (1)'!$B$6:$B$100,'PP5 (1)'!$E$6:$E$100,"") -> 0.67 | P22: =_xlfn.XLOOKUP($C22,'PP5 (2)'!$B$6:$B$100,'PP5 (2)'!$E$6:$E$100,"") -> 0.5 | Q22: =SUM(R22:AC22) -> 239 | R22: =_xlfn.XLOOKUP($C22,'MP (1)'!$B$6:$B$100,'MP (1)'!$F$6:$F$100,"") -> 26 | S22: =_xlfn.XLOOKUP($C22,'MP (2)'!$B$6:$B$100,'MP (2)'!$F$6:$F$100,"") -> 20 | T22: =_xlfn.XLOOKUP($C22,'PP1 (1)'!$B$6:$B$99,'PP1 (1)'!$F$6:$F$99,"") -> 25 | U22: =_xlfn.XLOOKUP($C22,'PP1 (2)'!$B$6:$B$98,'PP1 (2)'!$F$6:$F$98,"") -> 32 | V22: =_xlfn.XLOOKUP($C22,'PP2 (1)'!$B$6:$B$106,'PP2 (1)'!$F$6:$F$106,"") | W22: =_xlfn.XLOOKUP($C22,'PP2 (2)'!$B$6:$B$100,'PP2 (2)'!$F$6:$F$100,"") | X22: =_xlfn.XLOOKUP($C22,'PP3 (1)'!$B$5:$B$106,'PP3 (1)'!$F$5:$F$106,"") -> 25 | Y22: =_xlfn.XLOOKUP($C22,'PP3 (2)'!$B$5:$B$108,'PP3 (2)'!$F$5:$F$108,"") -> 19 | Z22: =_xlfn.XLOOKUP($C22,'PP4 (1)'!$B$6:$B$100,'PP4 (1)'!$F$6:$F$100,"") -> 26 | AA22: =_xlfn.XLOOKUP($C22,'PP4 (2)'!$B$6:$B$100,'PP4 (2)'!$F$6:$F$100,"") -> 19 | AB22: =_xlfn.XLOOKUP($C22,'PP5 (1)'!$B$6:$B$100,'PP5 (1)'!$F$6:$F$100,"") -> 24 | AC22: =_xlfn.XLOOKUP($C22,'PP5 (2)'!$B$6:$B$100,'PP5 (2)'!$F$6:$F$100,"") -> 23 | AD22: =SUM(AE22:AP22) -> 13 | AE22: =_xlfn.XLOOKUP($C22,'MP (1)'!$B$6:$B$100,'MP (1)'!$H$6:$H$100,"") -> 4 | AF22: =_xlfn.XLOOKUP($C22,'MP (2)'!$B$6:$B$100,'MP (2)'!$H$6:$H$100,"") -> -2 | AG22: =_xlfn.XLOOKUP($C22,'PP1 (1)'!$B$6:$B$99,'PP1 (1)'!$H$6:$H$99,"") -> -6 | AH22: =_xlfn.XLOOKUP($C22,'PP1 (2)'!$B$6:$B$98,'PP1 (2)'!$H$6:$H$98,"") -> 10 | AI22: =_xlfn.XLOOKUP($C22,'PP2 (1)'!$B$6:$B$106,'PP2 (1)'!$H$6:$H$106,"") | AJ22: =_xlfn.XLOOKUP($C22,'PP2 (2)'!$B$6:$B$100,'PP2 (2)'!$H$6:$H$100,"") | AK22: =_xlfn.XLOOKUP($C22,'PP3 (1)'!$B$5:$B$106,'PP3 (1)'!$H$5:$H$106,"") -> 4 | AL22: =_xlfn.XLOOKUP($C22,'PP3 (2)'!$B$5:$B$108,'PP3 (2)'!$H$5:$H$108,"") -> -8 | AM22: =_xlfn.XLOOKUP($C22,'PP4 (1)'!$B$6:$B$100,'PP4 (1)'!$H$6:$H$100,"") -> 9 | AN22: =_xlfn.XLOOKUP($C22,'PP4 (2)'!$B$6:$B$100,'PP4 (2)'!$H$6:$H$100,"") -> -4 | AO22: =_xlfn.XLOOKUP($C22,'PP5 (1)'!$B$6:$B$100,'PP5 (1)'!$H$6:$H$100,"") -> 6 | AP22: =_xlfn.XLOOKUP($C22,'PP5 (2)'!$B$6:$B$100,'PP5 (2)'!$H$6:$H$100,"") -> 0
A23: =ROW()-4 -> 19 | B23: 2 | C23: JASZCZAK Piotr | D23: =SUM(E23:P23) -> 5.37 | E23: =_xlfn.XLOOKUP($C23,'MP (1)'!$B$6:$B$100,'MP (1)'!$E$6:$E$100,"") | F23: =_xlfn.XLOOKUP($C23,'MP (2)'!$B$6:$B$100,'MP (2)'!$E$6:$E$100,"") | G23: =_xlfn.XLOOKUP($C23,'PP1 (1)'!$B$6:$B$99,'PP1 (1)'!$E$6:$E$99,"") -> 0.57 | H23: =_xlfn.XLOOKUP($C23,'PP1 (2)'!$B$6:$B$98,'PP1 (2)'!$E$6:$E$98,"") -> 0.83 | I23: =_xlfn.XLOOKUP($C23,'PP2 (1)'!$B$6:$B$106,'PP2 (1)'!$E$6:$E$106,"") -> 0.67 | J23: =_xlfn.XLOOKUP($C23,'PP2 (2)'!$B$6:$B$100,'PP2 (2)'!$E$6:$E$100,"") -> 0.5 | K23: =_xlfn.XLOOKUP($C23,'PP3 (1)'!$B$5:$B$106,'PP3 (1)'!$E$5:$E$106,"") -> 0.6 | L23: =_xlfn.XLOOKUP($C23,'PP3 (2)'!$B$5:$B$108,'PP3 (2)'!$E$5:$E$108,"") -> 0.4 | M23: =_xlfn.XLOOKUP($C23,'PP4 (1)'!$B$6:$B$100,'PP4 (1)'!$E$6:$E$100,"") -> 1 | N23: =_xlfn.XLOOKUP($C23,'PP4 (2)'!$B$6:$B$100,'PP4 (2)'!$E$6:$E$100,"") -> 0.8 | O23: =_xlfn.XLOOKUP($C23,'PP5 (1)'!$B$6:$B$100,'PP5 (1)'!$E$6:$E$100,"") | P23: =_xlfn.XLOOKUP($C23,'PP5 (2)'!$B$6:$B$100,'PP5 (2)'!$E$6:$E$100,"") | Q23: =SUM(R23:AC23) -> 185 | R23: =_xlfn.XLOOKUP($C23,'MP (1)'!$B$6:$B$100,'MP (1)'!$F$6:$F$100,"") | S23: =_xlfn.XLOOKUP($C23,'MP (2)'!$B$6:$B$100,'MP (2)'!$F$6:$F$100,"") | T23: =_xlfn.XLOOKUP($C23,'PP1 (1)'!$B$6:$B$99,'PP1 (1)'!$F$6:$F$99,"") -> 28 | U23: =_xlfn.XLOOKUP($C23,'PP1 (2)'!$B$6:$B$98,'PP1 (2)'!$F$6:$F$98,"") -> 27 | V23: =_xlfn.XLOOKUP($C23,'PP2 (1)'!$B$6:$B$106,'PP2 (1)'!$F$6:$F$106,"") -> 22 | W23: =_xlfn.XLOOKUP($C23,'PP2 (2)'!$B$6:$B$100,'PP2 (2)'!$F$6:$F$100,"") -> 27 | X23: =_xlfn.XLOOKUP($C23,'PP3 (1)'!$B$5:$B$106,'PP3 (1)'!$F$5:$F$106,"") -> 19 | Y23: =_xlfn.XLOOKUP($C23,'PP3 (2)'!$B$5:$B$108,'PP3 (2)'!$F$5:$F$108,"") -> 19 | Z23: =_xlfn.XLOOKUP($C23,'PP4 (1)'!$B$6:$B$100,'PP4 (1)'!$F$6:$F$100,"") -> 23 | AA23: =_xlfn.XLOOKUP($C23,'PP4 (2)'!$B$6:$B$100,'PP4 (2)'!$F$6:$F$100,"") -> 20 | AB23: =_xlfn.XLOOKUP($C23,'PP5 (1)'!$B$6:$B$100,'PP5 (1)'!$F$6:$F$100,"") | AC23: =_xlfn.XLOOKUP($C23,'PP5 (2)'!$B$6:$B$100,'PP5 (2)'!$F$6:$F$100,"") | AD23: =SUM(AE23:AP23) -> 54 | AE23: =_xlfn.XLOOKUP($C23,'MP (1)'!$B$6:$B$100,'MP (1)'!$H$6:$H$100,"") | AF23: =_xlfn.XLOOKUP($C23,'MP (2)'!$B$6:$B$100,'MP (2)'!$H$6:$H$100,"") | AG23: =_xlfn.XLOOKUP($C23,'PP1 (1)'!$B$6:$B$99,'PP1 (1)'!$H$6:$H$99,"") -> 3 | AH23: =_xlfn.XLOOKUP($C23,'PP1 (2)'!$B$6:$B$98,'PP1 (2)'!$H$6:$H$98,"") -> 18 | AI23: =_xlfn.XLOOKUP($C23,'PP2 (1)'!$B$6:$B$106,'PP2 (1)'!$H$6:$H$106,"") -> 5 | AJ23: =_xlfn.XLOOKUP($C23,'PP2 (2)'!$B$6:$B$100,'PP2 (2)'!$H$6:$H$100,"") -> 5 | AK23: =_xlfn.XLOOKUP($C23,'PP3 (1)'!$B$5:$B$106,'PP3 (1)'!$H$5:$H$106,"") -> 2 | AL23: =_xlfn.XLOOKUP($C23,'PP3 (2)'!$B$5:$B$108,'PP3 (2)'!$H$5:$H$108,"") -> 0 | AM23: =_xlfn.XLOOKUP($C23,'PP4 (1)'!$B$6:$B$100,'PP4 (1)'!$H$6:$H$100,"") -> 14 | AN23: =_xlfn.XLOOKUP($C23,'PP4 (2)'!$B$6:$B$100,'PP4 (2)'!$H$6:$H$100,"") -> 7 | AO23: =_xlfn.XLOOKUP($C23,'PP5 (1)'!$B$6:$B$100,'PP5 (1)'!$H$6:$H$100,"") | AP23: =_xlfn.XLOOKUP($C23,'PP5 (2)'!$B$6:$B$100,'PP5 (2)'!$H$6:$H$100,"")
A24: =ROW()-4 -> 20 | B24: 2k | C24: WASILCZUK Beata | D24: =SUM(E24:P24) -> 5.09 | E24: =_xlfn.XLOOKUP($C24,'MP (1)'!$B$6:$B$100,'MP (1)'!$E$6:$E$100,"") -> 0.43 | F24: =_xlfn.XLOOKUP($C24,'MP (2)'!$B$6:$B$100,'MP (2)'!$E$6:$E$100,"") -> 0.57 | G24: =_xlfn.XLOOKUP($C24,'PP1 (1)'!$B$6:$B$99,'PP1 (1)'!$E$6:$E$99,"") -> 0.29 | H24: =_xlfn.XLOOKUP($C24,'PP1 (2)'!$B$6:$B$98,'PP1 (2)'!$E$6:$E$98,"") -> 0.17 | I24: =_xlfn.XLOOKUP($C24,'PP2 (1)'!$B$6:$B$106,'PP2 (1)'!$E$6:$E$106,"") -> 0.5 | J24: =_xlfn.XLOOKUP($C24,'PP2 (2)'!$B$6:$B$100,'PP2 (2)'!$E$6:$E$100,"") -> 0.5 | K24: =_xlfn.XLOOKUP($C24,'PP3 (1)'!$B$5:$B$106,'PP3 (1)'!$E$5:$E$106,"") -> 0.8 | L24: =_xlfn.XLOOKUP($C24,'PP3 (2)'!$B$5:$B$108,'PP3 (2)'!$E$5:$E$108,"") -> 0.5 | M24: =_xlfn.XLOOKUP($C24,'PP4 (1)'!$B$6:$B$100,'PP4 (1)'!$E$6:$E$100,"") -> 0.5 | N24: =_xlfn.XLOOKUP($C24,'PP4 (2)'!$B$6:$B$100,'PP4 (2)'!$E$6:$E$100,"") -> 0.83 | O24: =_xlfn.XLOOKUP($C24,'PP5 (1)'!$B$6:$B$100,'PP5 (1)'!$E$6:$E$100,"") | P24: =_xlfn.XLOOKUP($C24,'PP5 (2)'!$B$6:$B$100,'PP5 (2)'!$E$6:$E$100,"") | Q24: =SUM(R24:AC24) -> 231 | R24: =_xlfn.XLOOKUP($C24,'MP (1)'!$B$6:$B$100,'MP (1)'!$F$6:$F$100,"") -> 29 | S24: =_xlfn.XLOOKUP($C24,'MP (2)'!$B$6:$B$100,'MP (2)'!$F$6:$F$100,"") -> 28 | T24: =_xlfn.XLOOKUP($C24,'PP1 (1)'!$B$6:$B$99,'PP1 (1)'!$F$6:$F$99,"") -> 26 | U24: =_xlfn.XLOOKUP($C24,'PP1 (2)'!$B$6:$B$98,'PP1 (2)'!$F$6:$F$98,"") -> 15 | V24: =_xlfn.XLOOKUP($C24,'PP2 (1)'!$B$6:$B$106,'PP2 (1)'!$F$6:$F$106,"") -> 17 | W24: =_xlfn.XLOOKUP($C24,'PP2 (2)'!$B$6:$B$100,'PP2 (2)'!$F$6:$F$100,"") -> 22 | X24: =_xlfn.XLOOKUP($C24,'PP3 (1)'!$B$5:$B$106,'PP3 (1)'!$F$5:$F$106,"") -> 19 | Y24: =_xlfn.XLOOKUP($C24,'PP3 (2)'!$B$5:$B$108,'PP3 (2)'!$F$5:$F$108,"") -> 24 | Z24: =_xlfn.XLOOKUP($C24,'PP4 (1)'!$B$6:$B$100,'PP4 (1)'!$F$6:$F$100,"") -> 24 | AA24: =_xlfn.XLOOKUP($C24,'PP4 (2)'!$B$6:$B$100,'PP4 (2)'!$F$6:$F$100,"") -> 27 | AB24: =_xlfn.XLOOKUP($C24,'PP5 (1)'!$B$6:$B$100,'PP5 (1)'!$F$6:$F$100,"") | AC24: =_xlfn.XLOOKUP($C24,'PP5 (2)'!$B$6:$B$100,'PP5 (2)'!$F$6:$F$100,"") | AD24: =SUM(AE24:AP24) -> 2 | AE24: =_xlfn.XLOOKUP($C24,'MP (1)'!$B$6:$B$100,'MP (1)'!$H$6:$H$100,"") -> 3 | AF24: =_xlfn.XLOOKUP($C24,'MP (2)'!$B$6:$B$100,'MP (2)'!$H$6:$H$100,"") -> 1 | AG24: =_xlfn.XLOOKUP($C24,'PP1 (1)'!$B$6:$B$99,'PP1 (1)'!$H$6:$H$99,"") -> -2 | AH24: =_xlfn.XLOOKUP($C24,'PP1 (2)'!$B$6:$B$98,'PP1 (2)'!$H$6:$H$98,"") -> -11 | AI24: =_xlfn.XLOOKUP($C24,'PP2 (1)'!$B$6:$B$106,'PP2 (1)'!$H$6:$H$106,"") -> -4 | AJ24: =_xlfn.XLOOKUP($C24,'PP2 (2)'!$B$6:$B$100,'PP2 (2)'!$H$6:$H$100,"") -> -3 | AK24: =_xlfn.XLOOKUP($C24,'PP3 (1)'!$B$5:$B$106,'PP3 (1)'!$H$5:$H$106,"") -> 7 | AL24: =_xlfn.XLOOKUP($C24,'PP3 (2)'!$B$5:$B$108,'PP3 (2)'!$H$5:$H$108,"") -> 2 | AM24: =_xlfn.XLOOKUP($C24,'PP4 (1)'!$B$6:$B$100,'PP4 (1)'!$H$6:$H$100,"") -> 4 | AN24: =_xlfn.XLOOKUP($C24,'PP4 (2)'!$B$6:$B$100,'PP4 (2)'!$H$6:$H$100,"") -> 5 | AO24: =_xlfn.XLOOKUP($C24,'PP5 (1)'!$B$6:$B$100,'PP5 (1)'!$H$6:$H$100,"") | AP24: =_xlfn.XLOOKUP($C24,'PP5 (2)'!$B$6:$B$100,'PP5 (2)'!$H$6:$H$100,"")
A25: =ROW()-4 -> 21 | B25: 1 | C25: STOCKI Piotr | D25: =SUM(E25:P25) -> 4.81 | E25: =_xlfn.XLOOKUP($C25,'MP (1)'!$B$6:$B$100,'MP (1)'!$E$6:$E$100,"") | F25: =_xlfn.XLOOKUP($C25,'MP (2)'!$B$6:$B$100,'MP (2)'!$E$6:$E$100,"") | G25: =_xlfn.XLOOKUP($C25,'PP1 (1)'!$B$6:$B$99,'PP1 (1)'!$E$6:$E$99,"") -> 0.43 | H25: =_xlfn.XLOOKUP($C25,'PP1 (2)'!$B$6:$B$98,'PP1 (2)'!$E$6:$E$98,"") -> 0.71 | I25: =_xlfn.XLOOKUP($C25,'PP2 (1)'!$B$6:$B$106,'PP2 (1)'!$E$6:$E$106,"") -> 1 | J25: =_xlfn.XLOOKUP($C25,'PP2 (2)'!$B$6:$B$100,'PP2 (2)'!$E$6:$E$100,"") -> 1 | K25: =_xlfn.XLOOKUP($C25,'PP3 (1)'!$B$5:$B$106,'PP3 (1)'!$E$5:$E$106,"") -> 0.67 | L25: =_xlfn.XLOOKUP($C25,'PP3 (2)'!$B$5:$B$108,'PP3 (2)'!$E$5:$E$108,"") -> 1 | M25: =_xlfn.XLOOKUP($C25,'PP4 (1)'!$B$6:$B$100,'PP4 (1)'!$E$6:$E$100,"") | N25: =_xlfn.XLOOKUP($C25,'PP4 (2)'!$B$6:$B$100,'PP4 (2)'!$E$6:$E$100,"") | O25: =_xlfn.XLOOKUP($C25,'PP5 (1)'!$B$6:$B$100,'PP5 (1)'!$E$6:$E$100,"") | P25: =_xlfn.XLOOKUP($C25,'PP5 (2)'!$B$6:$B$100,'PP5 (2)'!$E$6:$E$100,"") | Q25: =SUM(R25:AC25) -> 170 | R25: =_xlfn.XLOOKUP($C25,'MP (1)'!$B$6:$B$100,'MP (1)'!$F$6:$F$100,"") | S25: =_xlfn.XLOOKUP($C25,'MP (2)'!$B$6:$B$100,'MP (2)'!$F$6:$F$100,"") | T25: =_xlfn.XLOOKUP($C25,'PP1 (1)'!$B$6:$B$99,'PP1 (1)'!$F$6:$F$99,"") -> 24 | U25: =_xlfn.XLOOKUP($C25,'PP1 (2)'!$B$6:$B$98,'PP1 (2)'!$F$6:$F$98,"") -> 31 | V25: =_xlfn.XLOOKUP($C25,'PP2 (1)'!$B$6:$B$106,'PP2 (1)'!$F$6:$F$106,"") -> 30 | W25: =_xlfn.XLOOKUP($C25,'PP2 (2)'!$B$6:$B$100,'PP2 (2)'!$F$6:$F$100,"") -> 30 | X25: =_xlfn.XLOOKUP($C25,'PP3 (1)'!$B$5:$B$106,'PP3 (1)'!$F$5:$F$106,"") -> 25 | Y25: =_xlfn.XLOOKUP($C25,'PP3 (2)'!$B$5:$B$108,'PP3 (2)'!$F$5:$F$108,"") -> 30 | Z25: =_xlfn.XLOOKUP($C25,'PP4 (1)'!$B$6:$B$100,'PP4 (1)'!$F$6:$F$100,"") | AA25: =_xlfn.XLOOKUP($C25,'PP4 (2)'!$B$6:$B$100,'PP4 (2)'!$F$6:$F$100,"") | AB25: =_xlfn.XLOOKUP($C25,'PP5 (1)'!$B$6:$B$100,'PP5 (1)'!$F$6:$F$100,"") | AC25: =_xlfn.XLOOKUP($C25,'PP5 (2)'!$B$6:$B$100,'PP5 (2)'!$F$6:$F$100,"") | AD25: =SUM(AE25:AP25) -> 72 | AE25: =_xlfn.XLOOKUP($C25,'MP (1)'!$B$6:$B$100,'MP (1)'!$H$6:$H$100,"") | AF25: =_xlfn.XLOOKUP($C25,'MP (2)'!$B$6:$B$100,'MP (2)'!$H$6:$H$100,"") | AG25: =_xlfn.XLOOKUP($C25,'PP1 (1)'!$B$6:$B$99,'PP1 (1)'!$H$6:$H$99,"") -> -1 | AH25: =_xlfn.XLOOKUP($C25,'PP1 (2)'!$B$6:$B$98,'PP1 (2)'!$H$6:$H$98,"") -> 14 | AI25: =_xlfn.XLOOKUP($C25,'PP2 (1)'!$B$6:$B$106,'PP2 (1)'!$H$6:$H$106,"") -> 15 | AJ25: =_xlfn.XLOOKUP($C25,'PP2 (2)'!$B$6:$B$100,'PP2 (2)'!$H$6:$H$100,"") -> 20 | AK25: =_xlfn.XLOOKUP($C25,'PP3 (1)'!$B$5:$B$106,'PP3 (1)'!$H$5:$H$106,"") -> 4 | AL25: =_xlfn.XLOOKUP($C25,'PP3 (2)'!$B$5:$B$108,'PP3 (2)'!$H$5:$H$108,"") -> 20 | AM25: =_xlfn.XLOOKUP($C25,'PP4 (1)'!$B$6:$B$100,'PP4 (1)'!$H$6:$H$100,"") | AN25: =_xlfn.XLOOKUP($C25,'PP4 (2)'!$B$6:$B$100,'PP4 (2)'!$H$6:$H$100,"") | AO25: =_xlfn.XLOOKUP($C25,'PP5 (1)'!$B$6:$B$100,'PP5 (1)'!$H$6:$H$100,"") | AP25: =_xlfn.XLOOKUP($C25,'PP5 (2)'!$B$6:$B$100,'PP5 (2)'!$H$6:$H$100,"")
A26: =ROW()-4 -> 22 | B26: 0 | C26: JASIELCZUK Igor | D26: =SUM(E26:P26) -> 4.63 | E26: =_xlfn.XLOOKUP($C26,'MP (1)'!$B$6:$B$100,'MP (1)'!$E$6:$E$100,"") -> 0.86 | F26: =_xlfn.XLOOKUP($C26,'MP (2)'!$B$6:$B$100,'MP (2)'!$E$6:$E$100,"") -> 1 | G26: =_xlfn.XLOOKUP($C26,'PP1 (1)'!$B$6:$B$99,'PP1 (1)'!$E$6:$E$99,"") | H26: =_xlfn.XLOOKUP($C26,'PP1 (2)'!$B$6:$B$98,'PP1 (2)'!$E$6:$E$98,"") | I26: =_xlfn.XLOOKUP($C26,'PP2 (1)'!$B$6:$B$106,'PP2 (1)'!$E$6:$E$106,"") -> 0.83 | J26: =_xlfn.XLOOKUP($C26,'PP2 (2)'!$B$6:$B$100,'PP2 (2)'!$E$6:$E$100,"") -> 0.67 | K26: =_xlfn.XLOOKUP($C26,'PP3 (1)'!$B$5:$B$106,'PP3 (1)'!$E$5:$E$106,"") -> 0.67 | L26: =_xlfn.XLOOKUP($C26,'PP3 (2)'!$B$5:$B$108,'PP3 (2)'!$E$5:$E$108,"") -> 0.6 | M26: =_xlfn.XLOOKUP($C26,'PP4 (1)'!$B$6:$B$100,'PP4 (1)'!$E$6:$E$100,"") | N26: =_xlfn.XLOOKUP($C26,'PP4 (2)'!$B$6:$B$100,'PP4 (2)'!$E$6:$E$100,"") | O26: =_xlfn.XLOOKUP($C26,'PP5 (1)'!$B$6:$B$100,'PP5 (1)'!$E$6:$E$100,"") | P26: =_xlfn.XLOOKUP($C26,'PP5 (2)'!$B$6:$B$100,'PP5 (2)'!$E$6:$E$100,"") | Q26: =SUM(R26:AC26) -> 155 | R26: =_xlfn.XLOOKUP($C26,'MP (1)'!$B$6:$B$100,'MP (1)'!$F$6:$F$100,"") -> 31 | S26: =_xlfn.XLOOKUP($C26,'MP (2)'!$B$6:$B$100,'MP (2)'!$F$6:$F$100,"") -> 28 | T26: =_xlfn.XLOOKUP($C26,'PP1 (1)'!$B$6:$B$99,'PP1 (1)'!$F$6:$F$99,"") | U26: =_xlfn.XLOOKUP($C26,'PP1 (2)'!$B$6:$B$98,'PP1 (2)'!$F$6:$F$98,"") | V26: =_xlfn.XLOOKUP($C26,'PP2 (1)'!$B$6:$B$106,'PP2 (1)'!$F$6:$F$106,"") -> 27 | W26: =_xlfn.XLOOKUP($C26,'PP2 (2)'!$B$6:$B$100,'PP2 (2)'!$F$6:$F$100,"") -> 23 | X26: =_xlfn.XLOOKUP($C26,'PP3 (1)'!$B$5:$B$106,'PP3 (1)'!$F$5:$F$106,"") -> 27 | Y26: =_xlfn.XLOOKUP($C26,'PP3 (2)'!$B$5:$B$108,'PP3 (2)'!$F$5:$F$108,"") -> 19 | Z26: =_xlfn.XLOOKUP($C26,'PP4 (1)'!$B$6:$B$100,'PP4 (1)'!$F$6:$F$100,"") | AA26: =_xlfn.XLOOKUP($C26,'PP4 (2)'!$B$6:$B$100,'PP4 (2)'!$F$6:$F$100,"") | AB26: =_xlfn.XLOOKUP($C26,'PP5 (1)'!$B$6:$B$100,'PP5 (1)'!$F$6:$F$100,"") | AC26: =_xlfn.XLOOKUP($C26,'PP5 (2)'!$B$6:$B$100,'PP5 (2)'!$F$6:$F$100,"") | AD26: =SUM(AE26:AP26) -> 65 | AE26: =_xlfn.XLOOKUP($C26,'MP (1)'!$B$6:$B$100,'MP (1)'!$H$6:$H$100,"") -> 15 | AF26: =_xlfn.XLOOKUP($C26,'MP (2)'!$B$6:$B$100,'MP (2)'!$H$6:$H$100,"") -> 17 | AG26: =_xlfn.XLOOKUP($C26,'PP1 (1)'!$B$6:$B$99,'PP1 (1)'!$H$6:$H$99,"") | AH26: =_xlfn.XLOOKUP($C26,'PP1 (2)'!$B$6:$B$98,'PP1 (2)'!$H$6:$H$98,"") | AI26: =_xlfn.XLOOKUP($C26,'PP2 (1)'!$B$6:$B$106,'PP2 (1)'!$H$6:$H$106,"") -> 11 | AJ26: =_xlfn.XLOOKUP($C26,'PP2 (2)'!$B$6:$B$100,'PP2 (2)'!$H$6:$H$100,"") -> 6 | AK26: =_xlfn.XLOOKUP($C26,'PP3 (1)'!$B$5:$B$106,'PP3 (1)'!$H$5:$H$106,"") -> 12 | AL26: =_xlfn.XLOOKUP($C26,'PP3 (2)'!$B$5:$B$108,'PP3 (2)'!$H$5:$H$108,"") -> 4 | AM26: =_xlfn.XLOOKUP($C26,'PP4 (1)'!$B$6:$B$100,'PP4 (1)'!$H$6:$H$100,"") | AN26: =_xlfn.XLOOKUP($C26,'PP4 (2)'!$B$6:$B$100,'PP4 (2)'!$H$6:$H$100,"") | AO26: =_xlfn.XLOOKUP($C26,'PP5 (1)'!$B$6:$B$100,'PP5 (1)'!$H$6:$H$100,"") | AP26: =_xlfn.XLOOKUP($C26,'PP5 (2)'!$B$6:$B$100,'PP5 (2)'!$H$6:$H$100,"")
