Workbook

Sheet KlasyfikacjaGP
B2: Dołączył/a do kategorii w tym roku | D2: Ranking Grand Prix Pucharu Polski Weteranów (PPW) sezon 2023 - 2024 | X2: Na sumę punktów w rankingu skłąda się 6 najlepszych wyników (z 8 możliwych) w turniejach GP PPW oraz wynik z Mistrzostw Polski Weteranów.
D3: Kat. 2
A4: L.P. | B4: NAZWISKO Imię | C4: KLUB | D4: PUNKTY | E4: I GP | G4: II GP | I4: III GP | K4: IV GP | M4: V GP | O4: VI GP | Q4: VII GP | S4: VIII GP | U4: MPW
E5: M | F5: P | G5: M | H5: P | I5: M | J5: P | K5: M | L5: P | M5: M | N5: P | O5: M | P5: P | Q5: M | R5: P | S5: M | T5: P | U5: M | V5: P
A6: =ROW()-5 -> 1 | B6: ATANASSOW Aleksander | D6: =SUM(F6,H6,J6,L6,N6,P6,R6,T6,V6)-SUM(SMALL((F6,H6,J6,L6,N6,P6,R6,T6),1),SMALL((F6,H6,J6,L6,N6,P6,R6,T6),2)) -> 762.83585 | E6: =_xlfn.XLOOKUP($B6,'GP1'!$C$6:$C$101,'GP1'!$B$6:$B$101,"") -> 1 | F6: =_xlfn.XLOOKUP(E6,'GP1'!$B$6:$B$55,'GP1'!$A$6:$A$55,0) -> 110.01582 | G6: =_xlfn.XLOOKUP($B6,'GP2'!$C$6:$C$101,'GP2'!$B$6:$B$101,"") -> 1 | H6: =_xlfn.XLOOKUP(G6,'GP2'!$B$6:$B$55,'GP2'!$A$6:$A$55,0) -> 110.01582 | I6: =_xlfn.XLOOKUP($B6,'GP3'!$C$6:$C$101,'GP3'!$B$6:$B$101,"") -> 1 | J6: =_xlfn.XLOOKUP(I6,'GP3'!$B$6:$B$55,'GP3'!$A$6:$A$55,0) -> 108.72075 | K6: =_xlfn.XLOOKUP($B6,'GP4'!$C$6:$C$101,'GP4'!$B$6:$B$101,"") -> 1 | L6: =_xlfn.XLOOKUP(K6,'GP4'!$B$6:$B$55,'GP4'!$A$6:$A$55,0) -> 110.01582 | M6: =_xlfn.XLOOKUP($B6,'GP5'!$C$6:$C$101,'GP5'!$B$6:$B$101,"") | N6: =_xlfn.XLOOKUP(M6,'GP5'!$B$6:$B$55,'GP5'!$A$6:$A$55,0) -> 0 | O6: =_xlfn.XLOOKUP($B6,'GP6'!$C$6:$C$101,'GP6'!$B$6:$B$101,"") -> 2 | P6: =_xlfn.XLOOKUP(O6,'GP6'!$B$6:$B$55,'GP6'!$A$6:$A$55,0) -> 80.068367 | Q6: =_xlfn.XLOOKUP($B6,'GP7'!$C$6:$C$101,'GP7'!$B$6:$B$101,"") -> 1 | R6: =_xlfn.XLOOKUP(Q6,'GP7'!$B$6:$B$55,'GP7'!$A$6:$A$55,0) -> 110.60486 | S6: =_xlfn.XLOOKUP($B6,'GP8'!$C$6:$C$101,'GP8'!$B$6:$B$101,"") -> 5 | T6: =_xlfn.XLOOKUP(S6,'GP8'!$B$6:$B$55,'GP8'!$A$6:$A$55,0) -> 24.108149 | U6: =_xlfn.XLOOKUP(B6,MPW!C$6:C$101,MPW!B$6:B$101,"") -> 1 | V6: =_xlfn.XLOOKUP(U6,MPW!B$6:B$55,MPW!A$6:A$55,0) -> 133.39441
A7: =ROW()-5 -> 2 | B7: ZIELIŃSKI Dariusz | D7: =SUM(F7,H7,J7,L7,N7,P7,R7,T7,V7)-SUM(SMALL((F7,H7,J7,L7,N7,P7,R7,T7),1),SMALL((F7,H7,J7,L7,N7,P7,R7,T7),2)) -> 520.21168 | E7: =_xlfn.XLOOKUP($B7,'GP1'!$C$6:$C$101,'GP1'!$B$6:$B$101,"") -> 2 | F7: =_xlfn.XLOOKUP(E7,'GP1'!$B$6:$B$55,'GP1'!$A$6:$A$55,0) -> 79.179704 | G7: =_xlfn.XLOOKUP($B7,'GP2'!$C$6:$C$101,'GP2'!$B$6:$B$101,"") -> 2 | H7: =_xlfn.XLOOKUP(G7,'GP2'!$B$6:$B$55,'GP2'!$A$6:$A$55,0) -> 79.179704 | I7: =_xlfn.XLOOKUP($B7,'GP3'!$C$6:$C$101,'GP3'!$B$6:$B$101,"") -> 3 | J7: =_xlfn.XLOOKUP(I7,'GP3'!$B$6:$B$55,'GP3'!$A$6:$A$55,0) -> 51.740251 | K7: =_xlfn.XLOOKUP($B7,'GP4'!$C$6:$C$101,'GP4'!$B$6:$B$101,"") -> 4 | L7: =_xlfn.XLOOKUP(K7,'GP4'!$B$6:$B$55,'GP4'!$A$6:$A$55,0) -> 41.671647 | M7: =_xlfn.XLOOKUP($B7,'GP5'!$C$6:$C$101,'GP5'!$B$6:$B$101,"") | N7: =_xlfn.XLOOKUP(M7,'GP5'!$B$6:$B$55,'GP5'!$A$6:$A$55,0) -> 0 | O7: =_xlfn.XLOOKUP($B7,'GP6'!$C$6:$C$101,'GP6'!$B$6:$B$101,"") -> 1 | P7: =_xlfn.XLOOKUP(O7,'GP6'!$B$6:$B$55,'GP6'!$A$6:$A$55,0) -> 110.60486 | Q7: =_xlfn.XLOOKUP($B7,'GP7'!$C$6:$C$101,'GP7'!$B$6:$B$101,"") -> 3 | R7: =_xlfn.XLOOKUP(Q7,'GP7'!$B$6:$B$55,'GP7'!$A$6:$A$55,0) -> 55.204694 | S7: =_xlfn.XLOOKUP($B7,'GP8'!$C$6:$C$101,'GP8'!$B$6:$B$101,"") -> 2 | T7: =_xlfn.XLOOKUP(S7,'GP8'!$B$6:$B$55,'GP8'!$A$6:$A$55,0) -> 77.022724 | U7: =_xlfn.XLOOKUP(B7,MPW!C$6:C$101,MPW!B$6:B$101,"") -> 3 | V7: =_xlfn.XLOOKUP(U7,MPW!B$6:B$55,MPW!A$6:A$55,0) -> 67.279745
A8: =ROW()-5 -> 3 | B8: JENDRYŚ Marek | D8: =SUM(F8,H8,J8,L8,N8,P8,R8,T8,V8)-SUM(SMALL((F8,H8,J8,L8,N8,P8,R8,T8),1),SMALL((F8,H8,J8,L8,N8,P8,R8,T8),2)) -> 445.87477 | E8: =_xlfn.XLOOKUP($B8,'GP1'!$C$6:$C$101,'GP1'!$B$6:$B$101,"") | F8: =_xlfn.XLOOKUP(E8,'GP1'!$B$6:$B$55,'GP1'!$A$6:$A$55,0) -> 0 | G8: =_xlfn.XLOOKUP($B8,'GP2'!$C$6:$C$101,'GP2'!$B$6:$B$101,"") | H8: =_xlfn.XLOOKUP(G8,'GP2'!$B$6:$B$55,'GP2'!$A$6:$A$55,0) -> 0 | I8: =_xlfn.XLOOKUP($B8,'GP3'!$C$6:$C$101,'GP3'!$B$6:$B$101,"") -> 2k1 | J8: =_xlfn.XLOOKUP(I8,'GP3'!$B$6:$B$55,'GP3'!$A$6:$A$55,0) -> 80.866339 | K8: =_xlfn.XLOOKUP($B8,'GP4'!$C$6:$C$101,'GP4'!$B$6:$B$101,"") -> 2 | L8: =_xlfn.XLOOKUP(K8,'GP4'!$B$6:$B$55,'GP4'!$A$6:$A$55,0) -> 79.179704 | M8: =_xlfn.XLOOKUP($B8,'GP5'!$C$6:$C$101,'GP5'!$B$6:$B$101,"") | N8: =_xlfn.XLOOKUP(M8,'GP5'!$B$6:$B$55,'GP5'!$A$6:$A$55,0) -> 0 | O8: =_xlfn.XLOOKUP($B8,'GP6'!$C$6:$C$101,'GP6'!$B$6:$B$101,"") | P8: =_xlfn.XLOOKUP(O8,'GP6'!$B$6:$B$55,'GP6'!$A$6:$A$55,0) -> 0 | Q8: =_xlfn.XLOOKUP($B8,'GP7'!$C$6:$C$101,'GP7'!$B$6:$B$101,"") -> 2 | R8: =_xlfn.XLOOKUP(Q8,'GP7'!$B$6:$B$55,'GP7'!$A$6:$A$55,0) -> 80.068367 | S8: =_xlfn.XLOOKUP($B8,'GP8'!$C$6:$C$101,'GP8'!$B$6:$B$101,"") -> 1 | T8: =_xlfn.XLOOKUP(S8,'GP8'!$B$6:$B$55,'GP8'!$A$6:$A$55,0) -> 108.72075 | U8: =_xlfn.XLOOKUP(B8,MPW!C$6:C$101,MPW!B$6:B$101,"") -> 2 | V8: =_xlfn.XLOOKUP(U8,MPW!B$6:B$55,MPW!A$6:A$55,0) -> 97.039606
A9: =ROW()-5 -> 4 | B9: KOSTRZEWA Ireneusz | D9: =SUM(F9,H9,J9,L9,N9,P9,R9,T9,V9)-SUM(SMALL((F9,H9,J9,L9,N9,P9,R9,T9),1),SMALL((F9,H9,J9,L9,N9,P9,R9,T9),2)) -> 430.55245 | E9: =_xlfn.XLOOKUP($B9,'GP1'!$C$6:$C$101,'GP1'!$B$6:$B$101,"") -> 3 | F9: =_xlfn.XLOOKUP(E9,'GP1'!$B$6:$B$55,'GP1'!$A$6:$A$55,0) -> 54.222252 | G9: =_xlfn.XLOOKUP($B9,'GP2'!$C$6:$C$101,'GP2'!$B$6:$B$101,"") -> 3 | H9: =_xlfn.XLOOKUP(G9,'GP2'!$B$6:$B$55,'GP2'!$A$6:$A$55,0) -> 54.222252 | I9: =_xlfn.XLOOKUP($B9,'GP3'!$C$6:$C$101,'GP3'!$B$6:$B$101,"") -> 4 | J9: =_xlfn.XLOOKUP(I9,'GP3'!$B$6:$B$55,'GP3'!$A$6:$A$55,0) -> 39.084442 | K9: =_xlfn.XLOOKUP($B9,'GP4'!$C$6:$C$101,'GP4'!$B$6:$B$101,"") -> 3 | L9: =_xlfn.XLOOKUP(K9,'GP4'!$B$6:$B$55,'GP4'!$A$6:$A$55,0) -> 54.222252 | M9: =_xlfn.XLOOKUP($B9,'GP5'!$C$6:$C$101,'GP5'!$B$6:$B$101,"") -> 1 | N9: =_xlfn.XLOOKUP(M9,'GP5'!$B$6:$B$55,'GP5'!$A$6:$A$55,0) -> 108.72075 | O9: =_xlfn.XLOOKUP($B9,'GP6'!$C$6:$C$101,'GP6'!$B$6:$B$101,"") -> 3 | P9: =_xlfn.XLOOKUP(O9,'GP6'!$B$6:$B$55,'GP6'!$A$6:$A$55,0) -> 55.204694 | Q9: =_xlfn.XLOOKUP($B9,'GP7'!$C$6:$C$101,'GP7'!$B$6:$B$101,"") -> 4 | R9: =_xlfn.XLOOKUP(Q9,'GP7'!$B$6:$B$55,'GP7'!$A$6:$A$55,0) -> 42.663591 | S9: =_xlfn.XLOOKUP($B9,'GP8'!$C$6:$C$101,'GP8'!$B$6:$B$101,"") -> 3 | T9: =_xlfn.XLOOKUP(S9,'GP8'!$B$6:$B$55,'GP8'!$A$6:$A$55,0) -> 51.740251 | U9: =_xlfn.XLOOKUP(B9,MPW!C$6:C$101,MPW!B$6:B$101,"") -> 4 | V9: =_xlfn.XLOOKUP(U9,MPW!B$6:B$55,MPW!A$6:A$55,0) -> 52.219993
A10: =ROW()-5 -> 5 | B10: HAŚKO Sergiusz | D10: =SUM(F10,H10,J10,L10,N10,P10,R10,T10,V10)-SUM(SMALL((F10,H10,J10,L10,N10,P10,R10,T10),1),SMALL((F10,H10,J10,L10,N10,P10,R10,T10),2)) -> 264.44886 | E10: =_xlfn.XLOOKUP($B10,'GP1'!$C$6:$C$101,'GP1'!$B$6:$B$101,"") | F10: =_xlfn.XLOOKUP(E10,'GP1'!$B$6:$B$55,'GP1'!$A$6:$A$55,0) -> 0 | G10: =_xlfn.XLOOKUP($B10,'GP2'!$C$6:$C$101,'GP2'!$B$6:$B$101,"") -> 6k1 | H10: =_xlfn.XLOOKUP(G10,'GP2'!$B$6:$B$55,'GP2'!$A$6:$A$55,0) -> 21.870589 | I10: =_xlfn.XLOOKUP($B10,'GP3'!$C$6:$C$101,'GP3'!$B$6:$B$101,"") -> 6k1 | J10: =_xlfn.XLOOKUP(I10,'GP3'!$B$6:$B$55,'GP3'!$A$6:$A$55,0) -> 25.770781 | K10: =_xlfn.XLOOKUP($B10,'GP4'!$C$6:$C$101,'GP4'!$B$6:$B$101,"") -> 5 | L10: =_xlfn.XLOOKUP(K10,'GP4'!$B$6:$B$55,'GP4'!$A$6:$A$55,0) -> 27.111801 | M10: =_xlfn.XLOOKUP($B10,'GP5'!$C$6:$C$101,'GP5'!$B$6:$B$101,"") -> 2 | N10: =_xlfn.XLOOKUP(M10,'GP5'!$B$6:$B$55,'GP5'!$A$6:$A$55,0) -> 77.022724 | O10: =_xlfn.XLOOKUP($B10,'GP6'!$C$6:$C$101,'GP6'!$B$6:$B$101,"") -> 4 | P10: =_xlfn.XLOOKUP(O10,'GP6'!$B$6:$B$55,'GP6'!$A$6:$A$55,0) -> 42.663591 | Q10: =_xlfn.XLOOKUP($B10,'GP7'!$C$6:$C$101,'GP7'!$B$6:$B$101,"") | R10: =_xlfn.XLOOKUP(Q10,'GP7'!$B$6:$B$55,'GP7'!$A$6:$A$55,0) -> 0 | S10: =_xlfn.XLOOKUP($B10,'GP8'!$C$6:$C$101,'GP8'!$B$6:$B$101,"") -> 4 | T10: =_xlfn.XLOOKUP(S10,'GP8'!$B$6:$B$55,'GP8'!$A$6:$A$55,0) -> 39.084442 | U10: =_xlfn.XLOOKUP(B10,MPW!C$6:C$101,MPW!B$6:B$101,"") -> 6 | V10: =_xlfn.XLOOKUP(U10,MPW!B$6:B$55,MPW!A$6:A$55,0) -> 30.924937
A11: =ROW()-5 -> 6 | B11: WOJTAS Bogdan | D11: =SUM(F11,H11,J11,L11,N11,P11,R11,T11,V11)-SUM(SMALL((F11,H11,J11,L11,N11,P11,R11,T11),1),SMALL((F11,H11,J11,L11,N11,P11,R11,T11),2)) -> 135.06885 | E11: =_xlfn.XLOOKUP($B11,'GP1'!$C$6:$C$101,'GP1'!$B$6:$B$101,"") -> 8 | F11: =_xlfn.XLOOKUP(E11,'GP1'!$B$6:$B$55,'GP1'!$A$6:$A$55,0) -> 17.507471 | G11: =_xlfn.XLOOKUP($B11,'GP2'!$C$6:$C$101,'GP2'!$B$6:$B$101,"") | H11: =_xlfn.XLOOKUP(G11,'GP2'!$B$6:$B$55,'GP2'!$A$6:$A$55,0) -> 0 | I11: =_xlfn.XLOOKUP($B11,'GP3'!$C$6:$C$101,'GP3'!$B$6:$B$101,"") -> 6 | J11: =_xlfn.XLOOKUP(I11,'GP3'!$B$6:$B$55,'GP3'!$A$6:$A$55,0) -> 20.042221 | K11: =_xlfn.XLOOKUP($B11,'GP4'!$C$6:$C$101,'GP4'!$B$6:$B$101,"") -> 7 | L11: =_xlfn.XLOOKUP(K11,'GP4'!$B$6:$B$55,'GP4'!$A$6:$A$55,0) -> 20.236129 | M11: =_xlfn.XLOOKUP($B11,'GP5'!$C$6:$C$101,'GP5'!$B$6:$B$101,"") | N11: =_xlfn.XLOOKUP(M11,'GP5'!$B$6:$B$55,'GP5'!$A$6:$A$55,0) -> 0 | O11: =_xlfn.XLOOKUP($B11,'GP6'!$C$6:$C$101,'GP6'!$B$6:$B$101,"") -> 5 | P11: =_xlfn.XLOOKUP(O11,'GP6'!$B$6:$B$55,'GP6'!$A$6:$A$55,0) -> 28.263412 | Q11: =_xlfn.XLOOKUP($B11,'GP7'!$C$6:$C$101,'GP7'!$B$6:$B$101,"") -> 7 | R11: =_xlfn.XLOOKUP(Q11,'GP7'!$B$6:$B$55,'GP7'!$A$6:$A$55,0) -> 21.628499 | S11: =_xlfn.XLOOKUP($B11,'GP8'!$C$6:$C$101,'GP8'!$B$6:$B$101,"") | T11: =_xlfn.XLOOKUP(S11,'GP8'!$B$6:$B$55,'GP8'!$A$6:$A$55,0) -> 0 | U11: =_xlfn.XLOOKUP(B11,MPW!C$6:C$101,MPW!B$6:B$101,"") -> 7 | V11: =_xlfn.XLOOKUP(U11,MPW!B$6:B$55,MPW!A$6:A$55,0) -> 27.391121
A12: =ROW()-5 -> 7 | B12: SKOCZEK Artur | D12: =SUM(F12,H12,J12,L12,N12,P12,R12,T12,V12)-SUM(SMALL((F12,H12,J12,L12,N12,P12,R12,T12),1),SMALL((F12,H12,J12,L12,N12,P12,R12,T12),2)) -> 133.47706 | E12: =_xlfn.XLOOKUP($B12,'GP1'!$C$6:$C$101,'GP1'!$B$6:$B$101,"") -> 5 | F12: =_xlfn.XLOOKUP(E12,'GP1'!$B$6:$B$55,'GP1'!$A$6:$A$55,0) -> 27.111801 | G12: =_xlfn.XLOOKUP($B12,'GP2'!$C$6:$C$101,'GP2'!$B$6:$B$101,"") -> 7 | H12: =_xlfn.XLOOKUP(G12,'GP2'!$B$6:$B$55,'GP2'!$A$6:$A$55,0) -> 20.236129 | I12: =_xlfn.XLOOKUP($B12,'GP3'!$C$6:$C$101,'GP3'!$B$6:$B$101,"") -> 7 | J12: =_xlfn.XLOOKUP(I12,'GP3'!$B$6:$B$55,'GP3'!$A$6:$A$55,0) -> 16.604528 | K12: =_xlfn.XLOOKUP($B12,'GP4'!$C$6:$C$101,'GP4'!$B$6:$B$101,"") -> 6 | L12: =_xlfn.XLOOKUP(K12,'GP4'!$B$6:$B$55,'GP4'!$A$6:$A$55,0) -> 23.386135 | M12: =_xlfn.XLOOKUP($B12,'GP5'!$C$6:$C$101,'GP5'!$B$6:$B$101,"") -> 5 | N12: =_xlfn.XLOOKUP(M12,'GP5'!$B$6:$B$55,'GP5'!$A$6:$A$55,0) -> 24.108149 | O12: =_xlfn.XLOOKUP($B12,'GP6'!$C$6:$C$101,'GP6'!$B$6:$B$101,"") | P12: =_xlfn.XLOOKUP(O12,'GP6'!$B$6:$B$55,'GP6'!$A$6:$A$55,0) -> 0 | Q12: =_xlfn.XLOOKUP($B12,'GP7'!$C$6:$C$101,'GP7'!$B$6:$B$101,"") -> 8 | R12: =_xlfn.XLOOKUP(Q12,'GP7'!$B$6:$B$55,'GP7'!$A$6:$A$55,0) -> 18.995387 | S12: =_xlfn.XLOOKUP($B12,'GP8'!$C$6:$C$101,'GP8'!$B$6:$B$101,"") -> 7 | T12: =_xlfn.XLOOKUP(S12,'GP8'!$B$6:$B$55,'GP8'!$A$6:$A$55,0) -> 16.604528 | U12: =_xlfn.XLOOKUP(B12,MPW!C$6:C$101,MPW!B$6:B$101,"") -> 12 | V12: =_xlfn.XLOOKUP(U12,MPW!B$6:B$55,MPW!A$6:A$55,0) -> 3.0349334
A13: =ROW()-5 -> 8 | B13: BURLIKOWSKI Bartosz | D13: =SUM(F13,H13,J13,L13,N13,P13,R13,T13,V13)-SUM(SMALL((F13,H13,J13,L13,N13,P13,R13,T13),1),SMALL((F13,H13,J13,L13,N13,P13,R13,T13),2)) -> 118.0801 | E13: =_xlfn.XLOOKUP($B13,'GP1'!$C$6:$C$101,'GP1'!$B$6:$B$101,"") -> 4 | F13: =_xlfn.XLOOKUP(E13,'GP1'!$B$6:$B$55,'GP1'!$A$6:$A$55,0) -> 41.671647 | G13: =_xlfn.XLOOKUP($B13,'GP2'!$C$6:$C$101,'GP2'!$B$6:$B$101,"") | H13: =_xlfn.XLOOKUP(G13,'GP2'!$B$6:$B$55,'GP2'!$A$6:$A$55,0) -> 0 | I13: =_xlfn.XLOOKUP($B13,'GP3'!$C$6:$C$101,'GP3'!$B$6:$B$101,"") | J13: =_xlfn.XLOOKUP(I13,'GP3'!$B$6:$B$55,'GP3'!$A$6:$A$55,0) -> 0 | K13: =_xlfn.XLOOKUP($B13,'GP4'!$C$6:$C$101,'GP4'!$B$6:$B$101,"") | L13: =_xlfn.XLOOKUP(K13,'GP4'!$B$6:$B$55,'GP4'!$A$6:$A$55,0) -> 0 | M13: =_xlfn.XLOOKUP($B13,'GP5'!$C$6:$C$101,'GP5'!$B$6:$B$101,"") -> 3 | N13: =_xlfn.XLOOKUP(M13,'GP5'!$B$6:$B$55,'GP5'!$A$6:$A$55,0) -> 51.740251 | O13: =_xlfn.XLOOKUP($B13,'GP6'!$C$6:$C$101,'GP6'!$B$6:$B$101,"") -> 6 | P13: =_xlfn.XLOOKUP(O13,'GP6'!$B$6:$B$55,'GP6'!$A$6:$A$55,0) -> 24.668204 | Q13: =_xlfn.XLOOKUP($B13,'GP7'!$C$6:$C$101,'GP7'!$B$6:$B$101,"") | R13: =_xlfn.XLOOKUP(Q13,'GP7'!$B$6:$B$55,'GP7'!$A$6:$A$55,0) -> 0 | S13: =_xlfn.XLOOKUP($B13,'GP8'!$C$6:$C$101,'GP8'!$B$6:$B$101,"") | T13: =_xlfn.XLOOKUP(S13,'GP8'!$B$6:$B$55,'GP8'!$A$6:$A$55,0) -> 0 | U13: =_xlfn.XLOOKUP(B13,MPW!C$6:C$101,MPW!B$6:B$101,"") | V13: =_xlfn.XLOOKUP(U13,MPW!B$6:B$55,MPW!A$6:A$55,0)
A14: =ROW()-5 -> 9 | B14: KOTERSKI Paweł | D14: =SUM(F14,H14,J14,L14,N14,P14,R14,T14,V14)-SUM(SMALL((F14,H14,J14,L14,N14,P14,R14,T14),1),SMALL((F14,H14,J14,L14,N14,P14,R14,T14),2)) -> 99.757395 | E14: =_xlfn.XLOOKUP($B14,'GP1'!$C$6:$C$101,'GP1'!$B$6:$B$101,"") -> 7 | F14: =_xlfn.XLOOKUP(E14,'GP1'!$B$6:$B$55,'GP1'!$A$6:$A$55,0) -> 20.236129 | G14: =_xlfn.XLOOKUP($B14,'GP2'!$C$6:$C$101,'GP2'!$B$6:$B$101,"") -> 5 | H14: =_xlfn.XLOOKUP(G14,'GP2'!$B$6:$B$55,'GP2'!$A$6:$A$55,0) -> 27.111801 | I14: =_xlfn.XLOOKUP($B14,'GP3'!$C$6:$C$101,'GP3'!$B$6:$B$101,"") -> 5 | J14: =_xlfn.XLOOKUP(I14,'GP3'!$B$6:$B$55,'GP3'!$A$6:$A$55,0) -> 24.108149 | K14: =_xlfn.XLOOKUP($B14,'GP4'!$C$6:$C$101,'GP4'!$B$6:$B$101,"") | L14: =_xlfn.XLOOKUP(K14,'GP4'!$B$6:$B$55,'GP4'!$A$6:$A$55,0) -> 0 | M14: =_xlfn.XLOOKUP($B14,'GP5'!$C$6:$C$101,'GP5'!$B$6:$B$101,"") | N14: =_xlfn.XLOOKUP(M14,'GP5'!$B$6:$B$55,'GP5'!$A$6:$A$55,0) -> 0 | O14: =_xlfn.XLOOKUP($B14,'GP6'!$C$6:$C$101,'GP6'!$B$6:$B$101,"") -> 7 | P14: =_xlfn.XLOOKUP(O14,'GP6'!$B$6:$B$55,'GP6'!$A$6:$A$55,0) -> 21.628499 | Q14: =_xlfn.XLOOKUP($B14,'GP7'!$C$6:$C$101,'GP7'!$B$6:$B$101,"") -> 9 | R14: =_xlfn.XLOOKUP(Q14,'GP7'!$B$6:$B$55,'GP7'!$A$6:$A$55,0) -> 6.6728173 | S14: =_xlfn.XLOOKUP($B14,'GP8'!$C$6:$C$101,'GP8'!$B$6:$B$101,"") | T14: =_xlfn.XLOOKUP(S14,'GP8'!$B$6:$B$55,'GP8'!$A$6:$A$55,0) -> 0 | U14: =_xlfn.XLOOKUP(B14,MPW!C$6:C$101,MPW!B$6:B$101,"") | V14: =_xlfn.XLOOKUP(U14,MPW!B$6:B$55,MPW!A$6:A$55,0)
A15: =ROW()-5 -> 10 | B15: WIERZBICKI Jacek | D15: =SUM(F15,H15,J15,L15,N15,P15,R15,T15,V15)-SUM(SMALL((F15,H15,J15,L15,N15,P15,R15,T15),1),SMALL((F15,H15,J15,L15,N15,P15,R15,T15),2)) -> 91.394857 | E15: =_xlfn.XLOOKUP($B15,'GP1'!$C$6:$C$101,'GP1'!$B$6:$B$101,"") -> 10 | F15: =_xlfn.XLOOKUP(E15,'GP1'!$B$6:$B$55,'GP1'!$A$6:$A$55,0) -> 2.9476242 | G15: =_xlfn.XLOOKUP($B15,'GP2'!$C$6:$C$101,'GP2'!$B$6:$B$101,"") -> 9 | H15: =_xlfn.XLOOKUP(G15,'GP2'!$B$6:$B$55,'GP2'!$A$6:$A$55,0) -> 5.1006228 | I15: =_xlfn.XLOOKUP($B15,'GP3'!$C$6:$C$101,'GP3'!$B$6:$B$101,"") -> 8 | J15: =_xlfn.XLOOKUP(I15,'GP3'!$B$6:$B$55,'GP3'!$A$6:$A$55,0) -> 13.626663 | K15: =_xlfn.XLOOKUP($B15,'GP4'!$C$6:$C$101,'GP4'!$B$6:$B$101,"") -> 8 | L15: =_xlfn.XLOOKUP(K15,'GP4'!$B$6:$B$55,'GP4'!$A$6:$A$55,0) -> 17.507471 | M15: =_xlfn.XLOOKUP($B15,'GP5'!$C$6:$C$101,'GP5'!$B$6:$B$101,"") -> 7 | N15: =_xlfn.XLOOKUP(M15,'GP5'!$B$6:$B$55,'GP5'!$A$6:$A$55,0) -> 16.604528 | O15: =_xlfn.XLOOKUP($B15,'GP6'!$C$6:$C$101,'GP6'!$B$6:$B$101,"") -> 9 | P15: =_xlfn.XLOOKUP(O15,'GP6'!$B$6:$B$55,'GP6'!$A$6:$A$55,0) -> 6.6728173 | Q15: =_xlfn.XLOOKUP($B15,'GP7'!$C$6:$C$101,'GP7'!$B$6:$B$101,"") -> 6 | R15: =_xlfn.XLOOKUP(Q15,'GP7'!$B$6:$B$55,'GP7'!$A$6:$A$55,0) -> 24.668204 | S15: =_xlfn.XLOOKUP($B15,'GP8'!$C$6:$C$101,'GP8'!$B$6:$B$101,"") -> 9 | T15: =_xlfn.XLOOKUP(S15,'GP8'!$B$6:$B$55,'GP8'!$A$6:$A$55,0) -> 1 | U15: =_xlfn.XLOOKUP(B15,MPW!C$6:C$101,MPW!B$6:B$101,"") -> 10 | V15: =_xlfn.XLOOKUP(U15,MPW!B$6:B$55,MPW!A$6:A$55,0) -> 7.214551
A16: =ROW()-5 -> 11 | B16: JASZCZAK Piotr | D16: =SUM(F16,H16,J16,L16,N16,P16,R16,T16,V16)-SUM(SMALL((F16,H16,J16,L16,N16,P16,R16,T16),1),SMALL((F16,H16,J16,L16,N16,P16,R16,T16),2)) -> 90.733989 | E16: =_xlfn.XLOOKUP($B16,'GP1'!$C$6:$C$101,'GP1'!$B$6:$B$101,"") -> 6 | F16: =_xlfn.XLOOKUP(E16,'GP1'!$B$6:$B$55,'GP1'!$A$6:$A$55,0) -> 23.386135 | G16: =_xlfn.XLOOKUP($B16,'GP2'!$C$6:$C$101,'GP2'!$B$6:$B$101,"") | H16: =_xlfn.XLOOKUP(G16,'GP2'!$B$6:$B$55,'GP2'!$A$6:$A$55,0) -> 0 | I16: =_xlfn.XLOOKUP($B16,'GP3'!$C$6:$C$101,'GP3'!$B$6:$B$101,"") | J16: =_xlfn.XLOOKUP(I16,'GP3'!$B$6:$B$55,'GP3'!$A$6:$A$55,0) -> 0 | K16: =_xlfn.XLOOKUP($B16,'GP4'!$C$6:$C$101,'GP4'!$B$6:$B$101,"") | L16: =_xlfn.XLOOKUP(K16,'GP4'!$B$6:$B$55,'GP4'!$A$6:$A$55,0) -> 0 | M16: =_xlfn.XLOOKUP($B16,'GP5'!$C$6:$C$101,'GP5'!$B$6:$B$101,"") -> 4 | N16: =_xlfn.XLOOKUP(M16,'GP5'!$B$6:$B$55,'GP5'!$A$6:$A$55,0) -> 39.084442 | O16: =_xlfn.XLOOKUP($B16,'GP6'!$C$6:$C$101,'GP6'!$B$6:$B$101,"") | P16: =_xlfn.XLOOKUP(O16,'GP6'!$B$6:$B$55,'GP6'!$A$6:$A$55,0) -> 0 | Q16: =_xlfn.XLOOKUP($B16,'GP7'!$C$6:$C$101,'GP7'!$B$6:$B$101,"") -> 5 | R16: =_xlfn.XLOOKUP(Q16,'GP7'!$B$6:$B$55,'GP7'!$A$6:$A$55,0) -> 28.263412 | S16: =_xlfn.XLOOKUP($B16,'GP8'!$C$6:$C$101,'GP8'!$B$6:$B$101,"") | T16: =_xlfn.XLOOKUP(S16,'GP8'!$B$6:$B$55,'GP8'!$A$6:$A$55,0) -> 0 | U16: =_xlfn.XLOOKUP(B16,MPW!C$6:C$101,MPW!B$6:B$101,"") | V16: =_xlfn.XLOOKUP(U16,MPW!B$6:B$55,MPW!A$6:A$55,0)
A17: =ROW()-5 -> 12 | B17: DUDEK Mariusz | D17: =SUM(F17,H17,J17,L17,N17,P17,R17,T17,V17)-SUM(SMALL((F17,H17,J17,L17,N17,P17,R17,T17),1),SMALL((F17,H17,J17,L17,N17,P17,R17,T17),2)) -> 71.575512 | E17: =_xlfn.XLOOKUP($B17,'GP1'!$C$6:$C$101,'GP1'!$B$6:$B$101,"") | F17: =_xlfn.XLOOKUP(E17,'GP1'!$B$6:$B$55,'GP1'!$A$6:$A$55,0) -> 0 | G17: =_xlfn.XLOOKUP($B17,'GP2'!$C$6:$C$101,'GP2'!$B$6:$B$101,"") -> 8 | H17: =_xlfn.XLOOKUP(G17,'GP2'!$B$6:$B$55,'GP2'!$A$6:$A$55,0) -> 17.507471 | I17: =_xlfn.XLOOKUP($B17,'GP3'!$C$6:$C$101,'GP3'!$B$6:$B$101,"") | J17: =_xlfn.XLOOKUP(I17,'GP3'!$B$6:$B$55,'GP3'!$A$6:$A$55,0) -> 0 | K17: =_xlfn.XLOOKUP($B17,'GP4'!$C$6:$C$101,'GP4'!$B$6:$B$101,"") -> 9 | L17: =_xlfn.XLOOKUP(K17,'GP4'!$B$6:$B$55,'GP4'!$A$6:$A$55,0) -> 5.1006228 | M17: =_xlfn.XLOOKUP($B17,'GP5'!$C$6:$C$101,'GP5'!$B$6:$B$101,"") -> 6 | N17: =_xlfn.XLOOKUP(M17,'GP5'!$B$6:$B$55,'GP5'!$A$6:$A$55,0) -> 20.042221 | O17: =_xlfn.XLOOKUP($B17,'GP6'!$C$6:$C$101,'GP6'!$B$6:$B$101,"") -> 10 | P17: =_xlfn.XLOOKUP(O17,'GP6'!$B$6:$B$55,'GP6'!$A$6:$A$55,0) -> 4.595208 | Q17: =_xlfn.XLOOKUP($B17,'GP7'!$C$6:$C$101,'GP7'!$B$6:$B$101,"") | R17: =_xlfn.XLOOKUP(Q17,'GP7'!$B$6:$B$55,'GP7'!$A$6:$A$55,0) -> 0 | S17: =_xlfn.XLOOKUP($B17,'GP8'!$C$6:$C$101,'GP8'!$B$6:$B$101,"") | T17: =_xlfn.XLOOKUP(S17,'GP8'!$B$6:$B$55,'GP8'!$A$6:$A$55,0) -> 0 | U17: =_xlfn.XLOOKUP(B17,MPW!C$6:C$101,MPW!B$6:B$101,"") -> 8 | V17: =_xlfn.XLOOKUP(U17,MPW!B$6:B$55,MPW!A$6:A$55,0) -> 24.32999
... A28: =ROW()-5 -> 23 | B28: WRONA Grzegorz | D28: =SUM(F28,H28,J28,L28,N28,P28,R28,T28,V28)-SUM(SMALL((F28,H28,J28,L28,N28,P28,R28,T28),1),SMALL((F28,H28,J28,L28,N28,P28,R28,T28),2)) -> 1 | E28: =_xlfn.XLOOKUP($B28,'GP1'!$C$6:$C$101,'GP1'!$B$6:$B$101,"") | F28: =_xlfn.XLOOKUP(E28,'GP1'!$B$6:$B$55,'GP1'!$A$6:$A$55,0) -> 0 | G28: =_xlfn.XLOOKUP($B28,'GP2'!$C$6:$C$101,'GP2'!$B$6:$B$101,"") | H28: =_xlfn.XLOOKUP(G28,'GP2'!$B$6:$B$55,'GP2'!$A$6:$A$55,0) -> 0 | I28: =_xlfn.XLOOKUP($B28,'GP3'!$C$6:$C$101,'GP3'!$B$6:$B$101,"") | J28: =_xlfn.XLOOKUP(I28,'GP3'!$B$6:$B$55,'GP3'!$A$6:$A$55,0) -> 0 | K28: =_xlfn.XLOOKUP($B28,'GP4'!$C$6:$C$101,'GP4'!$B$6:$B$101,"") | L28: =_xlfn.XLOOKUP(K28,'GP4'!$B$6:$B$55,'GP4'!$A$6:$A$55,0) -> 0 | M28: =_xlfn.XLOOKUP($B28,'GP5'!$C$6:$C$101,'GP5'!$B$6:$B$101,"") | N28: =_xlfn.XLOOKUP(M28,'GP5'!$B$6:$B$55,'GP5'!$A$6:$A$55,0) -> 0 | O28: =_xlfn.XLOOKUP($B28,'GP6'!$C$6:$C$101,'GP6'!$B$6:$B$101,"") -> 12 | P28: =_xlfn.XLOOKUP(O28,'GP6'!$B$6:$B$55,'GP6'!$A$6:$A$55,0) -> 1 | Q28: =_xlfn.XLOOKUP($B28,'GP7'!$C$6:$C$101,'GP7'!$B$6:$B$101,"") | R28: =_xlfn.XLOOKUP(Q28,'GP7'!$B$6:$B$55,'GP7'!$A$6:$A$55,0) -> 0 | S28: =_xlfn.XLOOKUP($B28,'GP8'!$C$6:$C$101,'GP8'!$B$6:$B$101,"") | T28: =_xlfn.XLOOKUP(S28,'GP8'!$B$6:$B$55,'GP8'!$A$6:$A$55,0) -> 0 | U28: =_xlfn.XLOOKUP(B28,MPW!C$6:C$101,MPW!B$6:B$101,"") | V28: =_xlfn.XLOOKUP(U28,MPW!B$6:B$55,MPW!A$6:A$55,0)
A29: =ROW()-5 -> 24 | D29: =SUM(F29,H29,J29,L29,N29,P29,R29,T29,V29)-SUM(SMALL((F29,H29,J29,L29,N29,P29,R29,T29),1),SMALL((F29,H29,J29,L29,N29,P29,R29,T29),2)) -> 0 | E29: =_xlfn.XLOOKUP($B29,'GP1'!$C$6:$C$101,'GP1'!$B$6:$B$101,"") | F29: =_xlfn.XLOOKUP(E29,'GP1'!$B$6:$B$55,'GP1'!$A$6:$A$55,0) -> 0 | G29: =_xlfn.XLOOKUP($B29,'GP2'!$C$6:$C$101,'GP2'!$B$6:$B$101,"") | H29: =_xlfn.XLOOKUP(G29,'GP2'!$B$6:$B$55,'GP2'!$A$6:$A$55,0) -> 0 | I29: =_xlfn.XLOOKUP($B29,'GP3'!$C$6:$C$101,'GP3'!$B$6:$B$101,"") | J29: =_xlfn.XLOOKUP(I29,'GP3'!$B$6:$B$55,'GP3'!$A$6:$A$55,0) -> 0 | K29: =_xlfn.XLOOKUP($B29,'GP4'!$C$6:$C$101,'GP4'!$B$6:$B$101,"") | L29: =_xlfn.XLOOKUP(K29,'GP4'!$B$6:$B$55,'GP4'!$A$6:$A$55,0) -> 0 | M29: =_xlfn.XLOOKUP($B29,'GP5'!$C$6:$C$101,'GP5'!$B$6:$B$101,"") | N29: =_xlfn.XLOOKUP(M29,'GP5'!$B$6:$B$55,'GP5'!$A$6:$A$55,0) -> 0 | O29: =_xlfn.XLOOKUP($B29,'GP6'!$C$6:$C$101,'GP6'!$B$6:$B$101,"") | P29: =_xlfn.XLOOKUP(O29,'GP6'!$B$6:$B$55,'GP6'!$A$6:$A$55,0) -> 0 | Q29: =_xlfn.XLOOKUP($B29,'GP7'!$C$6:$C$101,'GP7'!$B$6:$B$101,"") | R29: =_xlfn.XLOOKUP(Q29,'GP7'!$B$6:$B$55,'GP7'!$A$6:$A$55,0) -> 0 | S29: =_xlfn.XLOOKUP($B29,'GP8'!$C$6:$C$101,'GP8'!$B$6:$B$101,"") | T29: =_xlfn.XLOOKUP(S29,'GP8'!$B$6:$B$55,'GP8'!$A$6:$A$55,0) -> 0 | U29: =_xlfn.XLOOKUP(B29,MPW!C$6:C$101,MPW!B$6:B$101,"") | V29: =_xlfn.XLOOKUP(U29,MPW!B$6:B$55,MPW!A$6:A$55,0)

Sheet GP1
H1: Liczba uczestników: | I1: GP Punkty | J1: Bonus za rundę | K1: Mnożnik za podium
B2: miejsce: | C2: PABIANICE | H2: 11 | I2: 50 | J2: 10 | K2: =3*H2^(1/3) -> 6.6719403
B3: data: | C3: 44940
A5: Punkty | B5: Miejsce Place | C5: Nazwisko Imię Name | D5: Klub Club(s) | E5: Okręg Division | F5: Państwo Country | H5: Miejsce | I5: Punkty za miejsce | J5: liczba wygranych walk pucharowych | K5: bonus z rundy pucharowej | L5: punkty za podium | M5: Suma
A6: =M6 -> 110.01582 | B6: =IF(H6>$H$2,"",(ROW()-5)) -> 1 | C6: ATANASSOW Aleksander | D6: KS CRACOVIA 1906. | F6: POL | H6: 1 | I6: =IF(H2=1,50,IF(H6<$H$2+1,($I$2-($I$2-1)*(LOG(H6)/LOG($H$2))),"")) -> 50 | J6: =INT(LOG($H$2,2))-ROUNDUP(LOG(H6,2),0)+IF(OR($H$2=1,$H$2=2,$H$2=4,$H$2=8,$H$2=16,$H$2=32,$H$2=64,$H$2=128,$H$2=256),0,1) -> 4 | K6: =J6*$J$2 -> 40 | L6: =3*K2 -> 20.015821 | M6: =IF(I6<>"",K6+I6+L6,0) -> 110.01582
A7: =M7 -> 79.179704 | B7: =IF(H7>$H$2,"",(ROW()-5)) -> 2 | C7: ZIELIŃSKI Dariusz | D7: PIAST GLIWICE | F7: POL | H7: 2 | I7: =IF(H7<$H$2+1,($I$2-($I$2-1)*(LOG(H7)/LOG($H$2))),"") -> 35.835824 | J7: =INT(LOG($H$2,2))-ROUNDUP(LOG(H7,2),0)+IF(OR($H$2=1,$H$2=2,$H$2=4,$H$2=8,$H$2=16,$H$2=32,$H$2=64,$H$2=128,$H$2=256),0,1) -> 3 | K7: =J7*$J$2 -> 30 | L7: =2*K2 -> 13.343881 | M7: =IF(I7<>"",K7+I7+L7,0) -> 79.179704
A8: =M8 -> 54.222252 | B8: =IF(H8>$H$2,"",(ROW()-5)) -> 3 | C8: KOSTRZEWA Ireneusz | D8: KSz WARSZAWIANKA | F8: POL | H8: 3 | I8: =IF(H8<$H$2+1,($I$2-($I$2-1)*(LOG(H8)/LOG($H$2))),"") -> 27.550311 | J8: =INT(LOG($H$2,2))-ROUNDUP(LOG(H8,2),0)+IF(OR($H$2=1,$H$2=2,$H$2=4,$H$2=8,$H$2=16,$H$2=32,$H$2=64,$H$2=128,$H$2=256),0,1) -> 2 | K8: =J8*$J$2 -> 20 | L8: =K2 -> 6.6719403 | M8: =IF(I8<>"",K8+I8+L8,0) -> 54.222252
A9: =M9 -> 41.671647 | B9: =IF(H9>$H$2,"",(ROW()-5)) -> 4 | C9: BURLIKOWSKI Bartosz | D9: AZS AWF WARSZAWA | F9: POL | H9: 4 | I9: =IF(H9<$H$2+1,($I$2-($I$2-1)*(LOG(H9)/LOG($H$2))),"") -> 21.671647 | J9: =INT(LOG($H$2,2))-ROUNDUP(LOG(H9,2),0)+IF(OR($H$2=1,$H$2=2,$H$2=4,$H$2=8,$H$2=16,$H$2=32,$H$2=64,$H$2=128,$H$2=256),0,1) -> 2 | K9: =J9*$J$2 -> 20 | M9: =IF(I9<>"",K9+I9+L9,0) -> 41.671647
A10: =M10 -> 27.111801 | B10: =IF(H10>$H$2,"",(ROW()-5)) -> 5 | C10: SKOCZEK Artur | D10: KSz WARSZAWIANKA | F10: POL | H10: 5 | I10: =IF(H10<$H$2+1,($I$2-($I$2-1)*(LOG(H10)/LOG($H$2))),"") -> 17.111801 | J10: =INT(LOG($H$2,2))-ROUNDUP(LOG(H10,2),0)+IF(OR($H$2=1,$H$2=2,$H$2=4,$H$2=8,$H$2=16,$H$2=32,$H$2=64,$H$2=128,$H$2=256),0,1) -> 1 | K10: =J10*$J$2 -> 10 | M10: =IF(I10<>"",K10+I10+L10,0) -> 27.111801
A11: =M11 -> 23.386135 | B11: =IF(H11>$H$2,"",(ROW()-5)) -> 6 | C11: JASZCZAK Piotr | D11: KS SZPADA ŁÓDŹ | F11: POL | H11: 6 | I11: =IF(H11<$H$2+1,($I$2-($I$2-1)*(LOG(H11)/LOG($H$2))),"") -> 13.386135 | J11: =INT(LOG($H$2,2))-ROUNDUP(LOG(H11,2),0)+IF(OR($H$2=1,$H$2=2,$H$2=4,$H$2=8,$H$2=16,$H$2=32,$H$2=64,$H$2=128,$H$2=256),0,1) -> 1 | K11: =J11*$J$2 -> 10 | M11: =IF(I11<>"",K11+I11+L11,0) -> 23.386135
A12: =M12 -> 20.236129 | B12: =IF(H12>$H$2,"",(ROW()-5)) -> 7 | C12: KOTERSKI Paweł | D12: AZS WRATISLAVIA WROCŁAW | F12: POL | H12: 7 | I12: =IF(H12<$H$2+1,($I$2-($I$2-1)*(LOG(H12)/LOG($H$2))),"") -> 10.236129 | J12: =INT(LOG($H$2,2))-ROUNDUP(LOG(H12,2),0)+IF(OR($H$2=1,$H$2=2,$H$2=4,$H$2=8,$H$2=16,$H$2=32,$H$2=64,$H$2=128,$H$2=256),0,1) -> 1 | K12: =J12*$J$2 -> 10 | M12: =IF(I12<>"",K12+I12+L12,0) -> 20.236129
A13: =M13 -> 17.507471 | B13: =IF(H13>$H$2,"",(ROW()-5)) -> 8 | C13: WOJTAS Bogdan | D13: KKS KRAKÓW | H13: 8 | I13: =IF(H13<$H$2+1,($I$2-($I$2-1)*(LOG(H13)/LOG($H$2))),"") -> 7.5074705 | J13: =INT(LOG($H$2,2))-ROUNDUP(LOG(H13,2),0)+IF(OR($H$2=1,$H$2=2,$H$2=4,$H$2=8,$H$2=16,$H$2=32,$H$2=64,$H$2=128,$H$2=256),0,1) -> 1 | K13: =J13*$J$2 -> 10 | M13: =IF(I13<>"",K13+I13+L13,0) -> 17.507471
A14: =M14 -> 5.1006228 | B14: =IF(H14>$H$2,"",(ROW()-5)) -> 9 | C14: GRZYWACZ Mirosław | D14: KKS KRAKÓW | H14: 9 | I14: =IF(H14<$H$2+1,($I$2-($I$2-1)*(LOG(H14)/LOG($H$2))),"") -> 5.1006228 | J14: =INT(LOG($H$2,2))-ROUNDUP(LOG(H14,2),0)+IF(OR($H$2=1,$H$2=2,$H$2=4,$H$2=8,$H$2=16,$H$2=32,$H$2=64,$H$2=128,$H$2=256),0,1) -> 0 | K14: =J14*$J$2 -> 0 | M14: =IF(I14<>"",K14+I14+L14,0) -> 5.1006228
A15: =M15 -> 2.9476242 | B15: =IF(H15>$H$2,"",(ROW()-5)) -> 10 | C15: WIERZBICKI Jacek | D15: AZS KU POLITECHNIKI OPOLSKIEJ | H15: 10 | I15: =IF(H15<$H$2+1,($I$2-($I$2-1)*(LOG(H15)/LOG($H$2))),"") -> 2.9476242 | J15: =INT(LOG($H$2,2))-ROUNDUP(LOG(H15,2),0)+IF(OR($H$2=1,$H$2=2,$H$2=4,$H$2=8,$H$2=16,$H$2=32,$H$2=64,$H$2=128,$H$2=256),0,1) -> 0 | K15: =J15*$J$2 -> 0 | M15: =IF(I15<>"",K15+I15+L15,0) -> 2.9476242
A16: =M16 -> 1 | B16: =IF(H16>$H$2,"",(ROW()-5)) -> 11 | C16: PARDUS Borys | D16: AKADEMIA SZERMIERKI W-WA | H16: 11 | I16: =IF(H16<$H$2+1,($I$2-($I$2-1)*(LOG(H16)/LOG($H$2))),"") -> 1 | J16: =INT(LOG($H$2,2))-ROUNDUP(LOG(H16,2),0)+IF(OR($H$2=1,$H$2=2,$H$2=4,$H$2=8,$H$2=16,$H$2=32,$H$2=64,$H$2=128,$H$2=256),0,1) -> 0 | K16: =J16*$J$2 -> 0 | M16: =IF(I16<>"",K16+I16+L16,0) -> 1
A17: =M17 -> 0 | B17: =IF(H17>$H$2,"",(ROW()-5)) | H17: 12 | I17: =IF(H17<$H$2+1,($I$2-($I$2-1)*(LOG(H17)/LOG($H$2))),"") | J17: =INT(LOG($H$2,2))-ROUNDUP(LOG(H17,2),0)+IF(OR($H$2=1,$H$2=2,$H$2=4,$H$2=8,$H$2=16,$H$2=32,$H$2=64,$H$2=128,$H$2=256),0,1) -> 0 | K17: =J17*$J$2 -> 0 | M17: =IF(I17<>"",K17+I17+L17,0) -> 0
A18: =M18 -> 0 | B18: =IF(H18>$H$2,"",(ROW()-5)) | H18: 13 | I18: =IF(H18<$H$2+1,($I$2-($I$2-1)*(LOG(H18)/LOG($H$2))),"") | J18: =INT(LOG($H$2,2))-ROUNDUP(LOG(H18,2),0)+IF(OR($H$2=1,$H$2=2,$H$2=4,$H$2=8,$H$2=16,$H$2=32,$H$2=64,$H$2=128,$H$2=256),0,1) -> 0 | K18: =J18*$J$2 -> 0 | M18: =IF(I18<>"",K18+I18+L18,0) -> 0
A19: =M19 -> 0 | B19: =IF(H19>$H$2,"",(ROW()-5)) | H19: 14 | I19: =IF(H19<$H$2+1,($I$2-($I$2-1)*(LOG(H19)/LOG($H$2))),"") | J19: =INT(LOG($H$2,2))-ROUNDUP(LOG(H19,2),0)+IF(OR($H$2=1,$H$2=2,$H$2=4,$H$2=8,$H$2=16,$H$2=32,$H$2=64,$H$2=128,$H$2=256),0,1) -> 0 | K19: =J19*$J$2 -> 0 | M19: =IF(I19<>"",K19+I19+L19,0) -> 0
A20: =M20 -> 0 | B20: =IF(H20>$H$2,"",(ROW()-5)) | H20: 15 | I20: =IF(H20<$H$2+1,($I$2-($I$2-1)*(LOG(H20)/LOG($H$2))),"") | J20: =INT(LOG($H$2,2))-ROUNDUP(LOG(H20,2),0)+IF(OR($H$2=1,$H$2=2,$H$2=4,$H$2=8,$H$2=16,$H$2=32,$H$2=64,$H$2=128,$H$2=256),0,1) -> 0 | K20: =J20*$J$2 -> 0 | M20: =IF(I20<>"",K20+I20+L20,0) -> 0
A21: =M21 -> 0 | B21: =IF(H21>$H$2,"",(ROW()-5)) | H21: 16 | I21: =IF(H21<$H$2+1,($I$2-($I$2-1)*(LOG(H21)/LOG($H$2))),"") | J21: =INT(LOG($H$2,2))-ROUNDUP(LOG(H21,2),0)+IF(OR($H$2=1,$H$2=2,$H$2=4,$H$2=8,$H$2=16,$H$2=32,$H$2=64,$H$2=128,$H$2=256),0,1) -> 0 | K21: =J21*$J$2 -> 0 | M21: =IF(I21<>"",K21+I21+L21,0) -> 0
A22: =M22 -> 0 | B22: =IF(H22>$H$2,"",(ROW()-5)) | H22: 17 | I22: =IF(H22<$H$2+1,($I$2-($I$2-1)*(LOG(H22)/LOG($H$2))),"") | J22: =INT(LOG($H$2,2))-ROUNDUP(LOG(H22,2),0)+IF(OR($H$2=1,$H$2=2,$H$2=4,$H$2=8,$H$2=16,$H$2=32,$H$2=64,$H$2=128,$H$2=256),0,1) -> -1 | K22: =J22*$J$2 -> -10 | M22: =IF(I22<>"",K22+I22+L22,0) -> 0
A23: =M23 -> 0 | B23: =IF(H23>$H$2,"",(ROW()-5)) | H23: 18 | I23: =IF(H23<$H$2+1,($I$2-($I$2-1)*(LOG(H23)/LOG($H$2))),"") | J23: =INT(LOG($H$2,2))-ROUNDUP(LOG(H23,2),0)+IF(OR($H$2=1,$H$2=2,$H$2=4,$H$2=8,$H$2=16,$H$2=32,$H$2=64,$H$2=128,$H$2=256),0,1) -> -1 | K23: =J23*$J$2 -> -10 | M23: =IF(I23<>"",K23+I23+L23,0) -> 0
A24: =M24 -> 0 | B24: =IF(H24>$H$2,"",(ROW()-5)) | H24: 19 | I24: =IF(H24<$H$2+1,($I$2-($I$2-1)*(LOG(H24)/LOG($H$2))),"") | J24: =INT(LOG($H$2,2))-ROUNDUP(LOG(H24,2),0)+IF(OR($H$2=1,$H$2=2,$H$2=4,$H$2=8,$H$2=16,$H$2=32,$H$2=64,$H$2=128,$H$2=256),0,1) -> -1 | K24: =J24*$J$2 -> -10 | M24: =IF(I24<>"",K24+I24+L24,0) -> 0
A25: =M25 -> 0 | B25: =IF(H25>$H$2,"",(ROW()-5)) | H25: 20 | I25: =IF(H25<$H$2+1,($I$2-($I$2-1)*(LOG(H25)/LOG($H$2))),"") | J25: =INT(LOG($H$2,2))-ROUNDUP(LOG(H25,2),0)+IF(OR($H$2=1,$H$2=2,$H$2=4,$H$2=8,$H$2=16,$H$2=32,$H$2=64,$H$2=128,$H$2=256),0,1) -> -1 | K25: =J25*$J$2 -> -10 | M25: =IF(I25<>"",K25+I25+L25,0) -> 0
A26: =M26 -> 0 | B26: =IF(H26>$H$2,"",(ROW()-5)) | H26: 21 | I26: =IF(H26<$H$2+1,($I$2-($I$2-1)*(LOG(H26)/LOG($H$2))),"") | J26: =INT(LOG($H$2,2))-ROUNDUP(LOG(H26,2),0)+IF(OR($H$2=1,$H$2=2,$H$2=4,$H$2=8,$H$2=16,$H$2=32,$H$2=64,$H$2=128,$H$2=256),0,1) -> -1 | K26: =J26*$J$2 -> -10 | M26: =IF(I26<>"",K26+I26+L26,0) -> 0
A27: =M27 -> 0 | B27: =IF(H27>$H$2,"",(ROW()-5)) | H27: 22 | I27: =IF(H27<$H$2+1,($I$2-($I$2-1)*(LOG(H27)/LOG($H$2))),"") | J27: =INT(LOG($H$2,2))-ROUNDUP(LOG(H27,2),0)+IF(OR($H$2=1,$H$2=2,$H$2=4,$H$2=8,$H$2=16,$H$2=32,$H$2=64,$H$2=128,$H$2=256),0,1) -> -1 | K27: =J27*$J$2 -> -10 | M27: =IF(I27<>"",K27+I27+L27,0) -> 0
A28: =M28 -> 0 | B28: =IF(H28>$H$2,"",(ROW()-5)) | H28: 23 | I28: =IF(H28<$H$2+1,($I$2-($I$2-1)*(LOG(H28)/LOG($H$2))),"") | J28: =INT(LOG($H$2,2))-ROUNDUP(LOG(H28,2),0)+IF(OR($H$2=1,$H$2=2,$H$2=4,$H$2=8,$H$2=16,$H$2=32,$H$2=64,$H$2=128,$H$2=256),0,1) -> -1 | K28: =J28*$J$2 -> -10 | M28: =IF(I28<>"",K28+I28+L28,0) -> 0
... A37: =M37 -> 0 | B37: =IF(H37>$H$2,"",(ROW()-5)) | H37: 32 | I37: =IF(H37<$H$2+1,($I$2-($I$2-1)*(LOG(H37)/LOG($H$2))),"") | J37: =INT(LOG($H$2,2))-ROUNDUP(LOG(H37,2),0)+IF(OR($H$2=1,$H$2=2,$H$2=4,$H$2=8,$H$2=16,$H$2=32,$H$2=64,$H$2=128,$H$2=256),0,1) -> -1 | K37: =J37*$J$2 -> -10 | M37: =IF(I37<>"",K37+I37+L37,0) -> 0
B38: =IF(H38>$H$2,"",(ROW()-5)) | H38: 33 | I38: =IF(H38<$H$2+1,($I$2-($I$2-1)*(LOG(H38)/LOG($H$2))),"") | J38: =INT(LOG($H$2,2))-ROUNDUP(LOG(H38,2),0)+IF(OR($H$2=1,$H$2=2,$H$2=4,$H$2=8,$H$2=16,$H$2=32,$H$2=64,$H$2=128,$H$2=256),0,1) -> -2 | K38: =J38*$J$2 -> -20 | M38: =IF(I38<>"",K38+I38+L38,0) -> 0
B39: =IF(H39>$H$2,"",(ROW()-5)) | H39: 34 | I39: =IF(H39<$H$2+1,($I$2-($I$2-1)*(LOG(H39)/LOG($H$2))),"") | J39: =INT(LOG($H$2,2))-ROUNDUP(LOG(H39,2),0)+IF(OR($H$2=1,$H$2=2,$H$2=4,$H$2=8,$H$2=16,$H$2=32,$H$2=64,$H$2=128,$H$2=256),0,1) -> -2 | K39: =J39*$J$2 -> -20 | M39: =IF(I39<>"",K39+I39+L39,0) -> 0
B40: =IF(H40>$H$2,"",(ROW()-5)) | H40: 35 | I40: =IF(H40<$H$2+1,($I$2-($I$2-1)*(LOG(H40)/LOG($H$2))),"") | J40: =INT(LOG($H$2,2))-ROUNDUP(LOG(H40,2),0)+IF(OR($H$2=1,$H$2=2,$H$2=4,$H$2=8,$H$2=16,$H$2=32,$H$2=64,$H$2=128,$H$2=256),0,1) -> -2 | K40: =J40*$J$2 -> -20 | M40: =IF(I40<>"",K40+I40+L40,0) -> 0
B41: =IF(H41>$H$2,"",(ROW()-5)) | H41: 36 | I41: =IF(H41<$H$2+1,($I$2-($I$2-1)*(LOG(H41)/LOG($H$2))),"") | J41: =INT(LOG($H$2,2))-ROUNDUP(LOG(H41,2),0)+IF(OR($H$2=1,$H$2=2,$H$2=4,$H$2=8,$H$2=16,$H$2=32,$H$2=64,$H$2=128,$H$2=256),0,1) -> -2 | K41: =J41*$J$2 -> -20 | M41: =IF(I41<>"",K41+I41+L41,0) -> 0
B42: =IF(H42>$H$2,"",(ROW()-5)) | H42: 37 | I42: =IF(H42<$H$2+1,($I$2-($I$2-1)*(LOG(H42)/LOG($H$2))),"") | J42: =INT(LOG($H$2,2))-ROUNDUP(LOG(H42,2),0)+IF(OR($H$2=1,$H$2=2,$H$2=4,$H$2=8,$H$2=16,$H$2=32,$H$2=64,$H$2=128,$H$2=256),0,1) -> -2 | K42: =J42*$J$2 -> -20 | M42: =IF(I42<>"",K42+I42+L42,0) -> 0
B43: =IF(H43>$H$2,"",(ROW()-5)) | H43: 38 | I43: =IF(H43<$H$2+1,($I$2-($I$2-1)*(LOG(H43)/LOG($H$2))),"") | J43: =INT(LOG($H$2,2))-ROUNDUP(LOG(H43,2),0)+IF(OR($H$2=1,$H$2=2,$H$2=4,$H$2=8,$H$2=16,$H$2=32,$H$2=64,$H$2=128,$H$2=256),0,1) -> -2 | K43: =J43*$J$2 -> -20 | M43: =IF(I43<>"",K43+I43+L43,0) -> 0
B44: =IF(H44>$H$2,"",(ROW()-5)) | H44: 39 | I44: =IF(H44<$H$2+1,($I$2-($I$2-1)*(LOG(H44)/LOG($H$2))),"") | J44: =INT(LOG($H$2,2))-ROUNDUP(LOG(H44,2),0)+IF(OR($H$2=1,$H$2=2,$H$2=4,$H$2=8,$H$2=16,$H$2=32,$H$2=64,$H$2=128,$H$2=256),0,1) -> -2 | K44: =J44*$J$2 -> -20 | M44: =IF(I44<>"",K44+I44+L44,0) -> 0
B45: =IF(H45>$H$2,"",(ROW()-5)) | H45: 40 | I45: =IF(H45<$H$2+1,($I$2-($I$2-1)*(LOG(H45)/LOG($H$2))),"") | J45: =INT(LOG($H$2,2))-ROUNDUP(LOG(H45,2),0)+IF(OR($H$2=1,$H$2=2,$H$2=4,$H$2=8,$H$2=16,$H$2=32,$H$2=64,$H$2=128,$H$2=256),0,1) -> -2 | K45: =J45*$J$2 -> -20 | M45: =IF(I45<>"",K45+I45+L45,0) -> 0
B46: =IF(H46>$H$2,"",(ROW()-5)) | H46: 41 | I46: =IF(H46<$H$2+1,($I$2-($I$2-1)*(LOG(H46)/LOG($H$2))),"") | J46: =INT(LOG($H$2,2))-ROUNDUP(LOG(H46,2),0)+IF(OR($H$2=1,$H$2=2,$H$2=4,$H$2=8,$H$2=16,$H$2=32,$H$2=64,$H$2=128,$H$2=256),0,1) -> -2 | K46: =J46*$J$2 -> -20 | M46: =IF(I46<>"",K46+I46+L46,0) -> 0
B47: =IF(H47>$H$2,"",(ROW()-5)) | H47: 42 | I47: =IF(H47<$H$2+1,($I$2-($I$2-1)*(LOG(H47)/LOG($H$2))),"") | J47: =INT(LOG($H$2,2))-ROUNDUP(LOG(H47,2),0)+IF(OR($H$2=1,$H$2=2,$H$2=4,$H$2=8,$H$2=16,$H$2=32,$H$2=64,$H$2=128,$H$2=256),0,1) -> -2 | K47: =J47*$J$2 -> -20 | M47: =IF(I47<>"",K47+I47+L47,0) -> 0
B48: =IF(H48>$H$2,"",(ROW()-5)) | H48: 43 | I48: =IF(H48<$H$2+1,($I$2-($I$2-1)*(LOG(H48)/LOG($H$2))),"") | J48: =INT(LOG($H$2,2))-ROUNDUP(LOG(H48,2),0)+IF(OR($H$2=1,$H$2=2,$H$2=4,$H$2=8,$H$2=16,$H$2=32,$H$2=64,$H$2=128,$H$2=256),0,1) -> -2 | K48: =J48*$J$2 -> -20 | M48: =IF(I48<>"",K48+I48+L48,0) -> 0
B49: =IF(H49>$H$2,"",(ROW()-5)) | H49: 44 | I49: =IF(H49<$H$2+1,($I$2-($I$2-1)*(LOG(H49)/LOG($H$2))),"") | J49: =INT(LOG($H$2,2))-ROUNDUP(LOG(H49,2),0)+IF(OR($H$2=1,$H$2=2,$H$2=4,$H$2=8,$H$2=16,$H$2=32,$H$2=64,$H$2=128,$H$2=256),0,1) -> -2 | K49: =J49*$J$2 -> -20 | M49: =IF(I49<>"",K49+I49+L49,0) -> 0
...

Sheet GP2
H1: Liczba uczestników: | I1: GP Punkty | J1: Bonus za rundę | K1: Mnożnik za podium
B2: miejsce: | C2: TORUŃ | H2: 11 | I2: 50 | J2: 10 | K2: =3*H2^(1/3) -> 6.6719403
B3: data: | C3: 45019
A5: Punkty | B5: Miejsce Place | C5: Nazwisko Imię Name | D5: Klub Club(s) | E5: Okręg Division | F5: Państwo Country | H5: Miejsce | I5: Punkty za miejsce | J5: liczba wygranych walk pucharowych | K5: bonus z rundy pucharowej | L5: punkty za podium | M5: Suma
A6: =M6 -> 110.01582 | B6: 1 | C6: ATANASSOW Aleksander | D6: KS CRACOVIA 1906. | H6: 1 | I6: =IF(H2=1,50,IF(H6<$H$2+1,($I$2-($I$2-1)*(LOG(H6)/LOG($H$2))),"")) -> 50 | J6: =INT(LOG($H$2,2))-ROUNDUP(LOG(H6,2),0)+IF(OR($H$2=1,$H$2=2,$H$2=4,$H$2=8,$H$2=16,$H$2=32,$H$2=64,$H$2=128,$H$2=256),0,1) -> 4 | K6: =J6*$J$2 -> 40 | L6: =3*K2 -> 20.015821 | M6: =IF(I6<>"",K6+I6+L6,0) -> 110.01582
A7: =M7 -> 79.179704 | B7: 2 | C7: ZIELIŃSKI Dariusz | D7: PIAST GLIWICE | H7: 2 | I7: =IF(H7<$H$2+1,($I$2-($I$2-1)*(LOG(H7)/LOG($H$2))),"") -> 35.835824 | J7: =INT(LOG($H$2,2))-ROUNDUP(LOG(H7,2),0)+IF(OR($H$2=1,$H$2=2,$H$2=4,$H$2=8,$H$2=16,$H$2=32,$H$2=64,$H$2=128,$H$2=256),0,1) -> 3 | K7: =J7*$J$2 -> 30 | L7: =2*K2 -> 13.343881 | M7: =IF(I7<>"",K7+I7+L7,0) -> 79.179704
A8: =M8 -> 54.222252 | B8: 3 | C8: KOSTRZEWA Ireneusz | D8: KSz WARSZAWIANKA | H8: 3 | I8: =IF(H8<$H$2+1,($I$2-($I$2-1)*(LOG(H8)/LOG($H$2))),"") -> 27.550311 | J8: =INT(LOG($H$2,2))-ROUNDUP(LOG(H8,2),0)+IF(OR($H$2=1,$H$2=2,$H$2=4,$H$2=8,$H$2=16,$H$2=32,$H$2=64,$H$2=128,$H$2=256),0,1) -> 2 | K8: =J8*$J$2 -> 20 | L8: =K2 -> 6.6719403 | M8: =IF(I8<>"",K8+I8+L8,0) -> 54.222252
A9: =M9 -> 41.671647 | B9: 4 | C9: GĄSIOROWSKI Maciej | D9: Alex Toruń | H9: 4 | I9: =IF(H9<$H$2+1,($I$2-($I$2-1)*(LOG(H9)/LOG($H$2))),"") -> 21.671647 | J9: =INT(LOG($H$2,2))-ROUNDUP(LOG(H9,2),0)+IF(OR($H$2=1,$H$2=2,$H$2=4,$H$2=8,$H$2=16,$H$2=32,$H$2=64,$H$2=128,$H$2=256),0,1) -> 2 | K9: =J9*$J$2 -> 20 | M9: =IF(I9<>"",K9+I9+L9,0) -> 41.671647
A10: =M10 -> 27.111801 | B10: 5 | C10: KOTERSKI Paweł | D10: AZS WRATISLAVIA WROCŁAW | H10: 5 | I10: =IF(H10<$H$2+1,($I$2-($I$2-1)*(LOG(H10)/LOG($H$2))),"") -> 17.111801 | J10: =INT(LOG($H$2,2))-ROUNDUP(LOG(H10,2),0)+IF(OR($H$2=1,$H$2=2,$H$2=4,$H$2=8,$H$2=16,$H$2=32,$H$2=64,$H$2=128,$H$2=256),0,1) -> 1 | K10: =J10*$J$2 -> 10 | M10: =IF(I10<>"",K10+I10+L10,0) -> 27.111801
A11: =M11 -> 23.386135 | B11: 6 | C11: DRAPELLA Maciej | D11: KS AZS AWFIS GDAŃSK. | H11: 6 | I11: =IF(H11<$H$2+1,($I$2-($I$2-1)*(LOG(H11)/LOG($H$2))),"") -> 13.386135 | J11: =INT(LOG($H$2,2))-ROUNDUP(LOG(H11,2),0)+IF(OR($H$2=1,$H$2=2,$H$2=4,$H$2=8,$H$2=16,$H$2=32,$H$2=64,$H$2=128,$H$2=256),0,1) -> 1 | K11: =J11*$J$2 -> 10 | M11: =IF(I11<>"",K11+I11+L11,0) -> 23.386135
A12: =M12 -> 20.236129 | B12: 7 | C12: SKOCZEK Artur | D12: KSz WARSZAWIANKA | H12: 7 | I12: =IF(H12<$H$2+1,($I$2-($I$2-1)*(LOG(H12)/LOG($H$2))),"") -> 10.236129 | J12: =INT(LOG($H$2,2))-ROUNDUP(LOG(H12,2),0)+IF(OR($H$2=1,$H$2=2,$H$2=4,$H$2=8,$H$2=16,$H$2=32,$H$2=64,$H$2=128,$H$2=256),0,1) -> 1 | K12: =J12*$J$2 -> 10 | M12: =IF(I12<>"",K12+I12+L12,0) -> 20.236129
A13: =M13 -> 17.507471 | B13: 8 | C13: DUDEK Mariusz | D13: Feniks Nowy Dwór Mazowiecki | H13: 8 | I13: =IF(H13<$H$2+1,($I$2-($I$2-1)*(LOG(H13)/LOG($H$2))),"") -> 7.5074705 | J13: =INT(LOG($H$2,2))-ROUNDUP(LOG(H13,2),0)+IF(OR($H$2=1,$H$2=2,$H$2=4,$H$2=8,$H$2=16,$H$2=32,$H$2=64,$H$2=128,$H$2=256),0,1) -> 1 | K13: =J13*$J$2 -> 10 | M13: =IF(I13<>"",K13+I13+L13,0) -> 17.507471
A14: =M14 -> 5.1006228 | B14: 9 | C14: WIERZBICKI Jacek | D14: AZS KU POLITECHNIKI OPOLSKIEJ | H14: 9 | I14: =IF(H14<$H$2+1,($I$2-($I$2-1)*(LOG(H14)/LOG($H$2))),"") -> 5.1006228 | J14: =INT(LOG($H$2,2))-ROUNDUP(LOG(H14,2),0)+IF(OR($H$2=1,$H$2=2,$H$2=4,$H$2=8,$H$2=16,$H$2=32,$H$2=64,$H$2=128,$H$2=256),0,1) -> 0 | K14: =J14*$J$2 -> 0 | M14: =IF(I14<>"",K14+I14+L14,0) -> 5.1006228
A15: =M15 -> 2.9476242 | B15: 10 | C15: PARDUS Borys | D15: AKADEMIA SZERMIERKI W-WA | H15: 10 | I15: =IF(H15<$H$2+1,($I$2-($I$2-1)*(LOG(H15)/LOG($H$2))),"") -> 2.9476242 | J15: =INT(LOG($H$2,2))-ROUNDUP(LOG(H15,2),0)+IF(OR($H$2=1,$H$2=2,$H$2=4,$H$2=8,$H$2=16,$H$2=32,$H$2=64,$H$2=128,$H$2=256),0,1) -> 0 | K15: =J15*$J$2 -> 0 | M15: =IF(I15<>"",K15+I15+L15,0) -> 2.9476242
A16: =M16 -> 1 | B16: 11 | C16: KASZTELOWICZ Piotr | D16: Alex Toruń | H16: 11 | I16: =IF(H16<$H$2+1,($I$2-($I$2-1)*(LOG(H16)/LOG($H$2))),"") -> 1 | J16: =INT(LOG($H$2,2))-ROUNDUP(LOG(H16,2),0)+IF(OR($H$2=1,$H$2=2,$H$2=4,$H$2=8,$H$2=16,$H$2=32,$H$2=64,$H$2=128,$H$2=256),0,1) -> 0 | K16: =J16*$J$2 -> 0 | M16: =IF(I16<>"",K16+I16+L16,0) -> 1
A17: =M17 -> 0 | B17: =IF(H17>$H$2,"",(ROW()-5)) | H17: 12 | I17: =IF(H17<$H$2+1,($I$2-($I$2-1)*(LOG(H17)/LOG($H$2))),"") | J17: =INT(LOG($H$2,2))-ROUNDUP(LOG(H17,2),0)+IF(OR($H$2=1,$H$2=2,$H$2=4,$H$2=8,$H$2=16,$H$2=32,$H$2=64,$H$2=128,$H$2=256),0,1) -> 0 | K17: =J17*$J$2 -> 0 | M17: =IF(I17<>"",K17+I17+L17,0) -> 0
A18: =M18 -> 0 | B18: =IF(H18>$H$2,"",(ROW()-5)) | H18: 13 | I18: =IF(H18<$H$2+1,($I$2-($I$2-1)*(LOG(H18)/LOG($H$2))),"") | J18: =INT(LOG($H$2,2))-ROUNDUP(LOG(H18,2),0)+IF(OR($H$2=1,$H$2=2,$H$2=4,$H$2=8,$H$2=16,$H$2=32,$H$2=64,$H$2=128,$H$2=256),0,1) -> 0 | K18: =J18*$J$2 -> 0 | M18: =IF(I18<>"",K18+I18+L18,0) -> 0
A19: 21.870589 | B19: 6k1 | C19: HAŚKO Sergiusz | D19: BYTOMSKIE TOWARZYSTWO SZERMIERCZE | H19: 14 | I19: =IF(H19<$H$2+1,($I$2-($I$2-1)*(LOG(H19)/LOG($H$2))),"") | J19: =INT(LOG($H$2,2))-ROUNDUP(LOG(H19,2),0)+IF(OR($H$2=1,$H$2=2,$H$2=4,$H$2=8,$H$2=16,$H$2=32,$H$2=64,$H$2=128,$H$2=256),0,1) -> 0 | K19: =J19*$J$2 -> 0 | M19: =IF(I19<>"",K19+I19+L19,0) -> 0
A20: =M20 -> 0 | B20: =IF(H20>$H$2,"",(ROW()-5)) | H20: 15 | I20: =IF(H20<$H$2+1,($I$2-($I$2-1)*(LOG(H20)/LOG($H$2))),"") | J20: =INT(LOG($H$2,2))-ROUNDUP(LOG(H20,2),0)+IF(OR($H$2=1,$H$2=2,$H$2=4,$H$2=8,$H$2=16,$H$2=32,$H$2=64,$H$2=128,$H$2=256),0,1) -> 0 | K20: =J20*$J$2 -> 0 | M20: =IF(I20<>"",K20+I20+L20,0) -> 0
A21: =M21 -> 0 | B21: =IF(H21>$H$2,"",(ROW()-5)) | H21: 16 | I21: =IF(H21<$H$2+1,($I$2-($I$2-1)*(LOG(H21)/LOG($H$2))),"") | J21: =INT(LOG($H$2,2))-ROUNDUP(LOG(H21,2),0)+IF(OR($H$2=1,$H$2=2,$H$2=4,$H$2=8,$H$2=16,$H$2=32,$H$2=64,$H$2=128,$H$2=256),0,1) -> 0 | K21: =J21*$J$2 -> 0 | M21: =IF(I21<>"",K21+I21+L21,0) -> 0
A22: =M22 -> 0 | B22: =IF(H22>$H$2,"",(ROW()-5)) | H22: 17 | I22: =IF(H22<$H$2+1,($I$2-($I$2-1)*(LOG(H22)/LOG($H$2))),"") | J22: =INT(LOG($H$2,2))-ROUNDUP(LOG(H22,2),0)+IF(OR($H$2=1,$H$2=2,$H$2=4,$H$2=8,$H$2=16,$H$2=32,$H$2=64,$H$2=128,$H$2=256),0,1) -> -1 | K22: =J22*$J$2 -> -10 | M22: =IF(I22<>"",K22+I22+L22,0) -> 0
A23: =M23 -> 0 | B23: =IF(H23>$H$2,"",(ROW()-5)) | H23: 18 | I23: =IF(H23<$H$2+1,($I$2-($I$2-1)*(LOG(H23)/LOG($H$2))),"") | J23: =INT(LOG($H$2,2))-ROUNDUP(LOG(H23,2),0)+IF(OR($H$2=1,$H$2=2,$H$2=4,$H$2=8,$H$2=16,$H$2=32,$H$2=64,$H$2=128,$H$2=256),0,1) -> -1 | K23: =J23*$J$2 -> -10 | M23: =IF(I23<>"",K23+I23+L23,0) -> 0
A24: =M24 -> 0 | B24: =IF(H24>$H$2,"",(ROW()-5)) | H24: 19 | I24: =IF(H24<$H$2+1,($I$2-($I$2-1)*(LOG(H24)/LOG($H$2))),"") | J24: =INT(LOG($H$2,2))-ROUNDUP(LOG(H24,2),0)+IF(OR($H$2=1,$H$2=2,$H$2=4,$H$2=8,$H$2=16,$H$2=32,$H$2=64,$H$2=128,$H$2=256),0,1) -> -1 | K24: =J24*$J$2 -> -10 | M24: =IF(I24<>"",K24+I24+L24,0) -> 0
A25: =M25 -> 0 | B25: =IF(H25>$H$2,"",(ROW()-5)) | H25: 20 | I25: =IF(H25<$H$2+1,($I$2-($I$2-1)*(LOG(H25)/LOG($H$2))),"") | J25: =INT(LOG($H$2,2))-ROUNDUP(LOG(H25,2),0)+IF(OR($H$2=1,$H$2=2,$H$2=4,$H$2=8,$H$2=16,$H$2=32,$H$2=64,$H$2=128,$H$2=256),0,1) -> -1 | K25: =J25*$J$2 -> -10 | M25: =IF(I25<>"",K25+I25+L25,0) -> 0
A26: =M26 -> 0 | B26: =IF(H26>$H$2,"",(ROW()-5)) | H26: 21 | I26: =IF(H26<$H$2+1,($I$2-($I$2-1)*(LOG(H26)/LOG($H$2))),"") | J26: =INT(LOG($H$2,2))-ROUNDUP(LOG(H26,2),0)+IF(OR($H$2=1,$H$2=2,$H$2=4,$H$2=8,$H$2=16,$H$2=32,$H$2=64,$H$2=128,$H$2=256),0,1) -> -1 | K26: =J26*$J$2 -> -10 | M26: =IF(I26<>"",K26+I26+L26,0) -> 0
A27: =M27 -> 0 | B27: =IF(H27>$H$2,"",(ROW()-5)) | H27: 22 | I27: =IF(H27<$H$2+1,($I$2-($I$2-1)*(LOG(H27)/LOG($H$2))),"") | J27: =INT(LOG($H$2,2))-ROUNDUP(LOG(H27,2),0)+IF(OR($H$2=1,$H$2=2,$H$2=4,$H$2=8,$H$2=16,$H$2=32,$H$2=64,$H$2=128,$H$2=256),0,1) -> -1 | K27: =J27*$J$2 -> -10 | M27: =IF(I27<>"",K27+I27+L27,0) -> 0
A28: =M28 -> 0 | B28: =IF(H28>$H$2,"",(ROW()-5)) | H28: 23 | I28: =IF(H28<$H$2+1,($I$2-($I$2-1)*(LOG(H28)/LOG($H$2))),"") | J28: =INT(LOG($H$2,2))-ROUNDUP(LOG(H28,2),0)+IF(OR($H$2=1,$H$2=2,$H$2=4,$H$2=8,$H$2=16,$H$2=32,$H$2=64,$H$2=128,$H$2=256),0,1) -> -1 | K28: =J28*$J$2 -> -10 | M28: =IF(I28<>"",K28+I28+L28,0) -> 0
A29: =M29 -> 0 | B29: =IF(H29>$H$2,"",(ROW()-5)) | H29: 24 | I29: =IF(H29<$H$2+1,($I$2-($I$2-1)*(LOG(H29)/LOG($H$2))),"") | J29: =INT(LOG($H$2,2))-ROUNDUP(LOG(H29,2),0)+IF(OR($H$2=1,$H$2=2,$H$2=4,$H$2=8,$H$2=16,$H$2=32,$H$2=64,$H$2=128,$H$2=256),0,1) -> -1 | K29: =J29*$J$2 -> -10 | M29: =IF(I29<>"",K29+I29+L29,0) -> 0
A30: =M30 -> 0 | B30: =IF(H30>$H$2,"",(ROW()-5)) | H30: 25 | I30: =IF(H30<$H$2+1,($I$2-($I$2-1)*(LOG(H30)/LOG($H$2))),"") | J30: =INT(LOG($H$2,2))-ROUNDUP(LOG(H30,2),0)+IF(OR($H$2=1,$H$2=2,$H$2=4,$H$2=8,$H$2=16,$H$2=32,$H$2=64,$H$2=128,$H$2=256),0,1) -> -1 | K30: =J30*$J$2 -> -10 | M30: =IF(I30<>"",K30+I30+L30,0) -> 0
A31: =M31 -> 0 | B31: =IF(H31>$H$2,"",(ROW()-5)) | H31: 26 | I31: =IF(H31<$H$2+1,($I$2-($I$2-1)*(LOG(H31)/LOG($H$2))),"") | J31: =INT(LOG($H$2,2))-ROUNDUP(LOG(H31,2),0)+IF(OR($H$2=1,$H$2=2,$H$2=4,$H$2=8,$H$2=16,$H$2=32,$H$2=64,$H$2=128,$H$2=256),0,1) -> -1 | K31: =J31*$J$2 -> -10 | M31: =IF(I31<>"",K31+I31+L31,0) -> 0
... A37: =M37 -> 0 | B37: =IF(H37>$H$2,"",(ROW()-5)) | H37: 32 | I37: =IF(H37<$H$2+1,($I$2-($I$2-1)*(LOG(H37)/LOG($H$2))),"") | J37: =INT(LOG($H$2,2))-ROUNDUP(LOG(H37,2),0)+IF(OR($H$2=1,$H$2=2,$H$2=4,$H$2=8,$H$2=16,$H$2=32,$H$2=64,$H$2=128,$H$2=256),0,1) -> -1 | K37: =J37*$J$2 -> -10 | M37: =IF(I37<>"",K37+I37+L37,0) -> 0
B38: =IF(H38>$H$2,"",(ROW()-5)) | H38: 33 | I38: =IF(H38<$H$2+1,($I$2-($I$2-1)*(LOG(H38)/LOG($H$2))),"") | J38: =INT(LOG($H$2,2))-ROUNDUP(LOG(H38,2),0)+IF(OR($H$2=1,$H$2=2,$H$2=4,$H$2=8,$H$2=16,$H$2=32,$H$2=64,$H$2=128,$H$2=256),0,1) -> -2 | K38: =J38*$J$2 -> -20 | M38: =IF(I38<>"",K38+I38+L38,0) -> 0
B39: =IF(H39>$H$2,"",(ROW()-5)) | H39: 34 | I39: =IF(H39<$H$2+1,($I$2-($I$2-1)*(LOG(H39)/LOG($H$2))),"") | J39: =INT(LOG($H$2,2))-ROUNDUP(LOG(H39,2),0)+IF(OR($H$2=1,$H$2=2,$H$2=4,$H$2=8,$H$2=16,$H$2=32,$H$2=64,$H$2=128,$H$2=256),0,1) -> -2 | K39: =J39*$J$2 -> -20 | M39: =IF(I39<>"",K39+I39+L39,0) -> 0
B40: =IF(H40>$H$2,"",(ROW()-5)) | H40: 35 | I40: =IF(H40<$H$2+1,($I$2-($I$2-1)*(LOG(H40)/LOG($H$2))),"") | J40: =INT(LOG($H$2,2))-ROUNDUP(LOG(H40,2),0)+IF(OR($H$2=1,$H$2=2,$H$2=4,$H$2=8,$H$2=16,$H$2=32,$H$2=64,$H$2=128,$H$2=256),0,1) -> -2 | K40: =J40*$J$2 -> -20 | M40: =IF(I40<>"",K40+I40+L40,0) -> 0
B41: =IF(H41>$H$2,"",(ROW()-5)) | H41: 36 | I41: =IF(H41<$H$2+1,($I$2-($I$2-1)*(LOG(H41)/LOG($H$2))),"") | J41: =INT(LOG($H$2,2))-ROUNDUP(LOG(H41,2),0)+IF(OR($H$2=1,$H$2=2,$H$2=4,$H$2=8,$H$2=16,$H$2=32,$H$2=64,$H$2=128,$H$2=256),0,1) -> -2 | K41: =J41*$J$2 -> -20 | M41: =IF(I41<>"",K41+I41+L41,0) -> 0
B42: =IF(H42>$H$2,"",(ROW()-5)) | H42: 37 | I42: =IF(H42<$H$2+1,($I$2-($I$2-1)*(LOG(H42)/LOG($H$2))),"") | J42: =INT(LOG($H$2,2))-ROUNDUP(LOG(H42,2),0)+IF(OR($H$2=1,$H$2=2,$H$2=4,$H$2=8,$H$2=16,$H$2=32,$H$2=64,$H$2=128,$H$2=256),0,1) -> -2 | K42: =J42*$J$2 -> -20 | M42: =IF(I42<>"",K42+I42+L42,0) -> 0
B43: =IF(H43>$H$2,"",(ROW()-5)) | H43: 38 | I43: =IF(H43<$H$2+1,($I$2-($I$2-1)*(LOG(H43)/LOG($H$2))),"") | J43: =INT(LOG($H$2,2))-ROUNDUP(LOG(H43,2),0)+IF(OR($H$2=1,$H$2=2,$H$2=4,$H$2=8,$H$2=16,$H$2=32,$H$2=64,$H$2=128,$H$2=256),0,1) -> -2 | K43: =J43*$J$2 -> -20 | M43: =IF(I43<>"",K43+I43+L43,0) -> 0
B44: =IF(H44>$H$2,"",(ROW()-5)) | H44: 39 | I44: =IF(H44<$H$2+1,($I$2-($I$2-1)*(LOG(H44)/LOG($H$2))),"") | J44: =INT(LOG($H$2,2))-ROUNDUP(LOG(H44,2),0)+IF(OR($H$2=1,$H$2=2,$H$2=4,$H$2=8,$H$2=16,$H$2=32,$H$2=64,$H$2=128,$H$2=256),0,1) -> -2 | K44: =J44*$J$2 -> -20 | M44: =IF(I44<>"",K44+I44+L44,0) -> 0
B45: =IF(H45>$H$2,"",(ROW()-5)) | H45: 40 | I45: =IF(H45<$H$2+1,($I$2-($I$2-1)*(LOG(H45)/LOG($H$2))),"") | J45: =INT(LOG($H$2,2))-ROUNDUP(LOG(H45,2),0)+IF(OR($H$2=1,$H$2=2,$H$2=4,$H$2=8,$H$2=16,$H$2=32,$H$2=64,$H$2=128,$H$2=256),0,1) -> -2 | K45: =J45*$J$2 -> -20 | M45: =IF(I45<>"",K45+I45+L45,0) -> 0
B46: =IF(H46>$H$2,"",(ROW()-5)) | H46: 41 | I46: =IF(H46<$H$2+1,($I$2-($I$2-1)*(LOG(H46)/LOG($H$2))),"") | J46: =INT(LOG($H$2,2))-ROUNDUP(LOG(H46,2),0)+IF(OR($H$2=1,$H$2=2,$H$2=4,$H$2=8,$H$2=16,$H$2=32,$H$2=64,$H$2=128,$H$2=256),0,1) -> -2 | K46: =J46*$J$2 -> -20 | M46: =IF(I46<>"",K46+I46+L46,0) -> 0
...

Sheet GP3
H1: Liczba uczestników: | I1: GP Punkty | J1: Bonus za rundę | K1: Mnożnik za podium
B2: miejsce: | C2: NIEPOŁOMICE | H2: 9 | I2: 50 | J2: 10 | K2: =3*H2^(1/3) -> 6.2402515
B3: data: | C3: 45094
A5: Punkty | B5: Miejsce Place | C5: Nazwisko Imię Name | D5: Klub Club(s) | E5: Okręg Division | F5: Państwo Country | H5: Miejsce | I5: Punkty za miejsce | J5: liczba wygranych walk pucharowych | K5: bonus z rundy pucharowej | L5: punkty za podium | M5: Suma
A6: =M6 -> 108.72075 | B6: 1 | C6: ATANASSOW Aleksander | D6: KS AGH Kraków | F6: POL | H6: 1 | I6: =IF(H2=1,50,IF(H6<$H$2+1,($I$2-($I$2-1)*(LOG(H6)/LOG($H$2))),"")) -> 50 | J6: =INT(LOG($H$2,2))-ROUNDUP(LOG(H6,2),0)+IF(OR($H$2=1,$H$2=2,$H$2=4,$H$2=8,$H$2=16,$H$2=32,$H$2=64,$H$2=128,$H$2=256),0,1) -> 4 | K6: =J6*$J$2 -> 40 | L6: =3*K2 -> 18.720754 | M6: =IF(I6<>"",K6+I6+L6,0) -> 108.72075
A7: =M7 -> 77.022724 | B7: 2 | C7: DRAPELLA Maciej | D7: KS AZS AWFIS GDAŃSK. | F7: POL | H7: 2 | I7: =IF(H7<$H$2+1,($I$2-($I$2-1)*(LOG(H7)/LOG($H$2))),"") -> 34.542221 | J7: =INT(LOG($H$2,2))-ROUNDUP(LOG(H7,2),0)+IF(OR($H$2=1,$H$2=2,$H$2=4,$H$2=8,$H$2=16,$H$2=32,$H$2=64,$H$2=128,$H$2=256),0,1) -> 3 | K7: =J7*$J$2 -> 30 | L7: =2*K2 -> 12.480503 | M7: =IF(I7<>"",K7+I7+L7,0) -> 77.022724
A8: =M8 -> 51.740251 | B8: 3 | C8: ZIELIŃSKI Dariusz | D8: PIAST GLIWICE | F8: POL | H8: 3 | I8: =IF(H8<$H$2+1,($I$2-($I$2-1)*(LOG(H8)/LOG($H$2))),"") -> 25.5 | J8: =INT(LOG($H$2,2))-ROUNDUP(LOG(H8,2),0)+IF(OR($H$2=1,$H$2=2,$H$2=4,$H$2=8,$H$2=16,$H$2=32,$H$2=64,$H$2=128,$H$2=256),0,1) -> 2 | K8: =J8*$J$2 -> 20 | L8: =K2 -> 6.2402515 | M8: =IF(I8<>"",K8+I8+L8,0) -> 51.740251
A9: =M9 -> 39.084442 | B9: 4 | C9: KOSTRZEWA Ireneusz | D9: KSz WARSZAWIANKA | F9: POL | H9: 4 | I9: =IF(H9<$H$2+1,($I$2-($I$2-1)*(LOG(H9)/LOG($H$2))),"") -> 19.084442 | J9: =INT(LOG($H$2,2))-ROUNDUP(LOG(H9,2),0)+IF(OR($H$2=1,$H$2=2,$H$2=4,$H$2=8,$H$2=16,$H$2=32,$H$2=64,$H$2=128,$H$2=256),0,1) -> 2 | K9: =J9*$J$2 -> 20 | M9: =IF(I9<>"",K9+I9+L9,0) -> 39.084442
A10: =M10 -> 24.108149 | B10: 5 | C10: KOTERSKI Paweł | D10: AZS WRATISLAVIA WROCŁAW | F10: POL | H10: 5 | I10: =IF(H10<$H$2+1,($I$2-($I$2-1)*(LOG(H10)/LOG($H$2))),"") -> 14.108149 | J10: =INT(LOG($H$2,2))-ROUNDUP(LOG(H10,2),0)+IF(OR($H$2=1,$H$2=2,$H$2=4,$H$2=8,$H$2=16,$H$2=32,$H$2=64,$H$2=128,$H$2=256),0,1) -> 1 | K10: =J10*$J$2 -> 10 | M10: =IF(I10<>"",K10+I10+L10,0) -> 24.108149
A11: =M11 -> 20.042221 | B11: 6 | C11: WOJTAS Bogdan | D11: KKS KRAKÓW | F11: POL | H11: 6 | I11: =IF(H11<$H$2+1,($I$2-($I$2-1)*(LOG(H11)/LOG($H$2))),"") -> 10.042221 | J11: =INT(LOG($H$2,2))-ROUNDUP(LOG(H11,2),0)+IF(OR($H$2=1,$H$2=2,$H$2=4,$H$2=8,$H$2=16,$H$2=32,$H$2=64,$H$2=128,$H$2=256),0,1) -> 1 | K11: =J11*$J$2 -> 10 | M11: =IF(I11<>"",K11+I11+L11,0) -> 20.042221
A12: =M12 -> 16.604528 | B12: 7 | C12: SKOCZEK Artur | D12: KSz WARSZAWIANKA | F12: POL | H12: 7 | I12: =IF(H12<$H$2+1,($I$2-($I$2-1)*(LOG(H12)/LOG($H$2))),"") -> 6.6045281 | J12: =INT(LOG($H$2,2))-ROUNDUP(LOG(H12,2),0)+IF(OR($H$2=1,$H$2=2,$H$2=4,$H$2=8,$H$2=16,$H$2=32,$H$2=64,$H$2=128,$H$2=256),0,1) -> 1 | K12: =J12*$J$2 -> 10 | M12: =IF(I12<>"",K12+I12+L12,0) -> 16.604528
A13: =M13 -> 13.626663 | B13: 8 | C13: WIERZBICKI Jacek | D13: AZS KU POLITECHNIKI OPOLSKIEJ | F13: POL | H13: 8 | I13: =IF(H13<$H$2+1,($I$2-($I$2-1)*(LOG(H13)/LOG($H$2))),"") -> 3.6266631 | J13: =INT(LOG($H$2,2))-ROUNDUP(LOG(H13,2),0)+IF(OR($H$2=1,$H$2=2,$H$2=4,$H$2=8,$H$2=16,$H$2=32,$H$2=64,$H$2=128,$H$2=256),0,1) -> 1 | K13: =J13*$J$2 -> 10 | M13: =IF(I13<>"",K13+I13+L13,0) -> 13.626663
A14: =M14 -> 1 | B14: 9 | C14: PARDUS Borys | D14: AKADEMIA SZERMIERKI W-WA | F14: POL | H14: 9 | I14: =IF(H14<$H$2+1,($I$2-($I$2-1)*(LOG(H14)/LOG($H$2))),"") -> 1 | J14: =INT(LOG($H$2,2))-ROUNDUP(LOG(H14,2),0)+IF(OR($H$2=1,$H$2=2,$H$2=4,$H$2=8,$H$2=16,$H$2=32,$H$2=64,$H$2=128,$H$2=256),0,1) -> 0 | K14: =J14*$J$2 -> 0 | M14: =IF(I14<>"",K14+I14+L14,0) -> 1
A15: =M15 -> 0 | B15: =IF(H15>$H$2,"",(ROW()-5)) | H15: 10 | I15: =IF(H15<$H$2+1,($I$2-($I$2-1)*(LOG(H15)/LOG($H$2))),"") | J15: =INT(LOG($H$2,2))-ROUNDUP(LOG(H15,2),0)+IF(OR($H$2=1,$H$2=2,$H$2=4,$H$2=8,$H$2=16,$H$2=32,$H$2=64,$H$2=128,$H$2=256),0,1) -> 0 | K15: =J15*$J$2 -> 0 | M15: =IF(I15<>"",K15+I15+L15,0) -> 0
A16: 80.866339 | B16: 2k1 | C16: JENDRYŚ Marek | H16: 11 | I16: =IF(H16<$H$2+1,($I$2-($I$2-1)*(LOG(H16)/LOG($H$2))),"") | J16: =INT(LOG($H$2,2))-ROUNDUP(LOG(H16,2),0)+IF(OR($H$2=1,$H$2=2,$H$2=4,$H$2=8,$H$2=16,$H$2=32,$H$2=64,$H$2=128,$H$2=256),0,1) -> 0 | K16: =J16*$J$2 -> 0 | M16: =IF(I16<>"",K16+I16+L16,0) -> 0
A17: 25.770781 | B17: 6k1 | C17: HAŚKO Sergiusz | D17: BYTOMSKIE TOWARZYSTWO SZERMIERCZE | F17: POL | H17: 12 | I17: =IF(H17<$H$2+1,($I$2-($I$2-1)*(LOG(H17)/LOG($H$2))),"") | J17: =INT(LOG($H$2,2))-ROUNDUP(LOG(H17,2),0)+IF(OR($H$2=1,$H$2=2,$H$2=4,$H$2=8,$H$2=16,$H$2=32,$H$2=64,$H$2=128,$H$2=256),0,1) -> 0 | K17: =J17*$J$2 -> 0 | M17: =IF(I17<>"",K17+I17+L17,0) -> 0
A18: =M18 -> 0 | B18: =IF(H18>$H$2,"",(ROW()-5)) | H18: 13 | I18: =IF(H18<$H$2+1,($I$2-($I$2-1)*(LOG(H18)/LOG($H$2))),"") | J18: =INT(LOG($H$2,2))-ROUNDUP(LOG(H18,2),0)+IF(OR($H$2=1,$H$2=2,$H$2=4,$H$2=8,$H$2=16,$H$2=32,$H$2=64,$H$2=128,$H$2=256),0,1) -> 0 | K18: =J18*$J$2 -> 0 | M18: =IF(I18<>"",K18+I18+L18,0) -> 0
A19: =M19 -> 0 | B19: =IF(H19>$H$2,"",(ROW()-5)) | H19: 14 | I19: =IF(H19<$H$2+1,($I$2-($I$2-1)*(LOG(H19)/LOG($H$2))),"") | J19: =INT(LOG($H$2,2))-ROUNDUP(LOG(H19,2),0)+IF(OR($H$2=1,$H$2=2,$H$2=4,$H$2=8,$H$2=16,$H$2=32,$H$2=64,$H$2=128,$H$2=256),0,1) -> 0 | K19: =J19*$J$2 -> 0 | M19: =IF(I19<>"",K19+I19+L19,0) -> 0
A20: =M20 -> 0 | B20: =IF(H20>$H$2,"",(ROW()-5)) | H20: 15 | I20: =IF(H20<$H$2+1,($I$2-($I$2-1)*(LOG(H20)/LOG($H$2))),"") | J20: =INT(LOG($H$2,2))-ROUNDUP(LOG(H20,2),0)+IF(OR($H$2=1,$H$2=2,$H$2=4,$H$2=8,$H$2=16,$H$2=32,$H$2=64,$H$2=128,$H$2=256),0,1) -> 0 | K20: =J20*$J$2 -> 0 | M20: =IF(I20<>"",K20+I20+L20,0) -> 0
A21: =M21 -> 0 | B21: =IF(H21>$H$2,"",(ROW()-5)) | H21: 16 | I21: =IF(H21<$H$2+1,($I$2-($I$2-1)*(LOG(H21)/LOG($H$2))),"") | J21: =INT(LOG($H$2,2))-ROUNDUP(LOG(H21,2),0)+IF(OR($H$2=1,$H$2=2,$H$2=4,$H$2=8,$H$2=16,$H$2=32,$H$2=64,$H$2=128,$H$2=256),0,1) -> 0 | K21: =J21*$J$2 -> 0 | M21: =IF(I21<>"",K21+I21+L21,0) -> 0
A22: =M22 -> 0 | B22: =IF(H22>$H$2,"",(ROW()-5)) | H22: 17 | I22: =IF(H22<$H$2+1,($I$2-($I$2-1)*(LOG(H22)/LOG($H$2))),"") | J22: =INT(LOG($H$2,2))-ROUNDUP(LOG(H22,2),0)+IF(OR($H$2=1,$H$2=2,$H$2=4,$H$2=8,$H$2=16,$H$2=32,$H$2=64,$H$2=128,$H$2=256),0,1) -> -1 | K22: =J22*$J$2 -> -10 | M22: =IF(I22<>"",K22+I22+L22,0) -> 0
A23: =M23 -> 0 | B23: =IF(H23>$H$2,"",(ROW()-5)) | H23: 18 | I23: =IF(H23<$H$2+1,($I$2-($I$2-1)*(LOG(H23)/LOG($H$2))),"") | J23: =INT(LOG($H$2,2))-ROUNDUP(LOG(H23,2),0)+IF(OR($H$2=1,$H$2=2,$H$2=4,$H$2=8,$H$2=16,$H$2=32,$H$2=64,$H$2=128,$H$2=256),0,1) -> -1 | K23: =J23*$J$2 -> -10 | M23: =IF(I23<>"",K23+I23+L23,0) -> 0
A24: =M24 -> 0 | B24: =IF(H24>$H$2,"",(ROW()-5)) | H24: 19 | I24: =IF(H24<$H$2+1,($I$2-($I$2-1)*(LOG(H24)/LOG($H$2))),"") | J24: =INT(LOG($H$2,2))-ROUNDUP(LOG(H24,2),0)+IF(OR($H$2=1,$H$2=2,$H$2=4,$H$2=8,$H$2=16,$H$2=32,$H$2=64,$H$2=128,$H$2=256),0,1) -> -1 | K24: =J24*$J$2 -> -10 | M24: =IF(I24<>"",K24+I24+L24,0) -> 0
A25: =M25 -> 0 | B25: =IF(H25>$H$2,"",(ROW()-5)) | H25: 20 | I25: =IF(H25<$H$2+1,($I$2-($I$2-1)*(LOG(H25)/LOG($H$2))),"") | J25: =INT(LOG($H$2,2))-ROUNDUP(LOG(H25,2),0)+IF(OR($H$2=1,$H$2=2,$H$2=4,$H$2=8,$H$2=16,$H$2=32,$H$2=64,$H$2=128,$H$2=256),0,1) -> -1 | K25: =J25*$J$2 -> -10 | M25: =IF(I25<>"",K25+I25+L25,0) -> 0
A26: =M26 -> 0 | B26: =IF(H26>$H$2,"",(ROW()-5)) | H26: 21 | I26: =IF(H26<$H$2+1,($I$2-($I$2-1)*(LOG(H26)/LOG($H$2))),"") | J26: =INT(LOG($H$2,2))-ROUNDUP(LOG(H26,2),0)+IF(OR($H$2=1,$H$2=2,$H$2=4,$H$2=8,$H$2=16,$H$2=32,$H$2=64,$H$2=128,$H$2=256),0,1) -> -1 | K26: =J26*$J$2 -> -10 | M26: =IF(I26<>"",K26+I26+L26,0) -> 0
A27: =M27 -> 0 | B27: =IF(H27>$H$2,"",(ROW()-5)) | H27: 22 | I27: =IF(H27<$H$2+1,($I$2-($I$2-1)*(LOG(H27)/LOG($H$2))),"") | J27: =INT(LOG($H$2,2))-ROUNDUP(LOG(H27,2),0)+IF(OR($H$2=1,$H$2=2,$H$2=4,$H$2=8,$H$2=16,$H$2=32,$H$2=64,$H$2=128,$H$2=256),0,1) -> -1 | K27: =J27*$J$2 -> -10 | M27: =IF(I27<>"",K27+I27+L27,0) -> 0
A28: =M28 -> 0 | B28: =IF(H28>$H$2,"",(ROW()-5)) | H28: 23 | I28: =IF(H28<$H$2+1,($I$2-($I$2-1)*(LOG(H28)/LOG($H$2))),"") | J28: =INT(LOG($H$2,2))-ROUNDUP(LOG(H28,2),0)+IF(OR($H$2=1,$H$2=2,$H$2=4,$H$2=8,$H$2=16,$H$2=32,$H$2=64,$H$2=128,$H$2=256),0,1) -> -1 | K28: =J28*$J$2 -> -10 | M28: =IF(I28<>"",K28+I28+L28,0) -> 0
A29: =M29 -> 0 | B29: =IF(H29>$H$2,"",(ROW()-5)) | H29: 24 | I29: =IF(H29<$H$2+1,($I$2-($I$2-1)*(LOG(H29)/LOG($H$2))),"") | J29: =INT(LOG($H$2,2))-ROUNDUP(LOG(H29,2),0)+IF(OR($H$2=1,$H$2=2,$H$2=4,$H$2=8,$H$2=16,$H$2=32,$H$2=64,$H$2=128,$H$2=256),0,1) -> -1 | K29: =J29*$J$2 -> -10 | M29: =IF(I29<>"",K29+I29+L29,0) -> 0
... A37: =M37 -> 0 | B37: =IF(H37>$H$2,"",(ROW()-5)) | H37: 32 | I37: =IF(H37<$H$2+1,($I$2-($I$2-1)*(LOG(H37)/LOG($H$2))),"") | J37: =INT(LOG($H$2,2))-ROUNDUP(LOG(H37,2),0)+IF(OR($H$2=1,$H$2=2,$H$2=4,$H$2=8,$H$2=16,$H$2=32,$H$2=64,$H$2=128,$H$2=256),0,1) -> -1 | K37: =J37*$J$2 -> -10 | M37: =IF(I37<>"",K37+I37+L37,0) -> 0
B38: =IF(H38>$H$2,"",(ROW()-5)) | H38: 33 | I38: =IF(H38<$H$2+1,($I$2-($I$2-1)*(LOG(H38)/LOG($H$2))),"") | J38: =INT(LOG($H$2,2))-ROUNDUP(LOG(H38,2),0)+IF(OR($H$2=1,$H$2=2,$H$2=4,$H$2=8,$H$2=16,$H$2=32,$H$2=64,$H$2=128,$H$2=256),0,1) -> -2 | K38: =J38*$J$2 -> -20 | M38: =IF(I38<>"",K38+I38+L38,0) -> 0
B39: =IF(H39>$H$2,"",(ROW()-5)) | H39: 34 | I39: =IF(H39<$H$2+1,($I$2-($I$2-1)*(LOG(H39)/LOG($H$2))),"") | J39: =INT(LOG($H$2,2))-ROUNDUP(LOG(H39,2),0)+IF(OR($H$2=1,$H$2=2,$H$2=4,$H$2=8,$H$2=16,$H$2=32,$H$2=64,$H$2=128,$H$2=256),0,1) -> -2 | K39: =J39*$J$2 -> -20 | M39: =IF(I39<>"",K39+I39+L39,0) -> 0
B40: =IF(H40>$H$2,"",(ROW()-5)) | H40: 35 | I40: =IF(H40<$H$2+1,($I$2-($I$2-1)*(LOG(H40)/LOG($H$2))),"") | J40: =INT(LOG($H$2,2))-ROUNDUP(LOG(H40,2),0)+IF(OR($H$2=1,$H$2=2,$H$2=4,$H$2=8,$H$2=16,$H$2=32,$H$2=64,$H$2=128,$H$2=256),0,1) -> -2 | K40: =J40*$J$2 -> -20 | M40: =IF(I40<>"",K40+I40+L40,0) -> 0
B41: =IF(H41>$H$2,"",(ROW()-5)) | H41: 36 | I41: =IF(H41<$H$2+1,($I$2-($I$2-1)*(LOG(H41)/LOG($H$2))),"") | J41: =INT(LOG($H$2,2))-ROUNDUP(LOG(H41,2),0)+IF(OR($H$2=1,$H$2=2,$H$2=4,$H$2=8,$H$2=16,$H$2=32,$H$2=64,$H$2=128,$H$2=256),0,1) -> -2 | K41: =J41*$J$2 -> -20 | M41: =IF(I41<>"",K41+I41+L41,0) -> 0
B42: =IF(H42>$H$2,"",(ROW()-5)) | H42: 37 | I42: =IF(H42<$H$2+1,($I$2-($I$2-1)*(LOG(H42)/LOG($H$2))),"") | J42: =INT(LOG($H$2,2))-ROUNDUP(LOG(H42,2),0)+IF(OR($H$2=1,$H$2=2,$H$2=4,$H$2=8,$H$2=16,$H$2=32,$H$2=64,$H$2=128,$H$2=256),0,1) -> -2 | K42: =J42*$J$2 -> -20 | M42: =IF(I42<>"",K42+I42+L42,0) -> 0
B43: =IF(H43>$H$2,"",(ROW()-5)) | H43: 38 | I43: =IF(H43<$H$2+1,($I$2-($I$2-1)*(LOG(H43)/LOG($H$2))),"") | J43: =INT(LOG($H$2,2))-ROUNDUP(LOG(H43,2),0)+IF(OR($H$2=1,$H$2=2,$H$2=4,$H$2=8,$H$2=16,$H$2=32,$H$2=64,$H$2=128,$H$2=256),0,1) -> -2 | K43: =J43*$J$2 -> -20 | M43: =IF(I43<>"",K43+I43+L43,0) -> 0
B44: =IF(H44>$H$2,"",(ROW()-5)) | H44: 39 | I44: =IF(H44<$H$2+1,($I$2-($I$2-1)*(LOG(H44)/LOG($H$2))),"") | J44: =INT(LOG($H$2,2))-ROUNDUP(LOG(H44,2),0)+IF(OR($H$2=1,$H$2=2,$H$2=4,$H$2=8,$H$2=16,$H$2=32,$H$2=64,$H$2=128,$H$2=256),0,1) -> -2 | K44: =J44*$J$2 -> -20 | M44: =IF(I44<>"",K44+I44+L44,0) -> 0
B45: =IF(H45>$H$2,"",(ROW()-5)) | H45: 40 | I45: =IF(H45<$H$2+1,($I$2-($I$2-1)*(LOG(H45)/LOG($H$2))),"") | J45: =INT(LOG($H$2,2))-ROUNDUP(LOG(H45,2),0)+IF(OR($H$2=1,$H$2=2,$H$2=4,$H$2=8,$H$2=16,$H$2=32,$H$2=64,$H$2=128,$H$2=256),0,1) -> -2 | K45: =J45*$J$2 -> -20 | M45: =IF(I45<>"",K45+I45+L45,0) -> 0
B46: =IF(H46>$H$2,"",(ROW()-5)) | H46: 41 | I46: =IF(H46<$H$2+1,($I$2-($I$2-1)*(LOG(H46)/LOG($H$2))),"") | J46: =INT(LOG($H$2,2))-ROUNDUP(LOG(H46,2),0)+IF(OR($H$2=1,$H$2=2,$H$2=4,$H$2=8,$H$2=16,$H$2=32,$H$2=64,$H$2=128,$H$2=256),0,1) -> -2 | K46: =J46*$J$2 -> -20 | M46: =IF(I46<>"",K46+I46+L46,0) -> 0
B47: =IF(H47>$H$2,"",(ROW()-5)) | H47: 42 | I47: =IF(H47<$H$2+1,($I$2-($I$2-1)*(LOG(H47)/LOG($H$2))),"") | J47: =INT(LOG($H$2,2))-ROUNDUP(LOG(H47,2),0)+IF(OR($H$2=1,$H$2=2,$H$2=4,$H$2=8,$H$2=16,$H$2=32,$H$2=64,$H$2=128,$H$2=256),0,1) -> -2 | K47: =J47*$J$2 -> -20 | M47: =IF(I47<>"",K47+I47+L47,0) -> 0
B48: =IF(H48>$H$2,"",(ROW()-5)) | H48: 43 | I48: =IF(H48<$H$2+1,($I$2-($I$2-1)*(LOG(H48)/LOG($H$2))),"") | J48: =INT(LOG($H$2,2))-ROUNDUP(LOG(H48,2),0)+IF(OR($H$2=1,$H$2=2,$H$2=4,$H$2=8,$H$2=16,$H$2=32,$H$2=64,$H$2=128,$H$2=256),0,1) -> -2 | K48: =J48*$J$2 -> -20 | M48: =IF(I48<>"",K48+I48+L48,0) -> 0
...

Sheet GP4
H1: Liczba uczestników: | I1: GP Punkty | J1: Bonus za rundę | K1: Mnożnik za podium
B2: miejsce: | C2: OPOLE | H2: 11 | I2: 50 | J2: 10 | K2: =3*H2^(1/3) -> 6.6719403
B3: data: | C3: 23-24.10.2023
A5: Punkty | B5: Miejsce Place | C5: Nazwisko Imię Name | D5: Klub Club(s) | E5: Okręg Division | F5: Państwo Country | H5: Miejsce | I5: Punkty za miejsce | J5: liczba wygranych walk pucharowych | K5: bonus z rundy pucharowej | L5: punkty za podium | M5: Suma
A6: =M6 -> 110.01582 | B6: =IF(H6>$H$2,"",(ROW()-5)) -> 1 | C6: ATANASSOW Aleksander | D6: KS AGH Kraków | F6: POL | H6: 1 | I6: =IF(H2=1,50,IF(H6<$H$2+1,($I$2-($I$2-1)*(LOG(H6)/LOG($H$2))),"")) -> 50 | J6: =INT(LOG($H$2,2))-ROUNDUP(LOG(H6,2),0)+IF(OR($H$2=1,$H$2=2,$H$2=4,$H$2=8,$H$2=16,$H$2=32,$H$2=64,$H$2=128,$H$2=256),0,1) -> 4 | K6: =J6*$J$2 -> 40 | L6: =3*K2 -> 20.015821 | M6: =IF(I6<>"",K6+I6+L6,0) -> 110.01582
A7: =M7 -> 79.179704 | B7: =IF(H7>$H$2,"",(ROW()-5)) -> 2 | C7: JENDRYŚ Marek | D7: ST. POLSKICH WETERANÓW SZERMIERKI | F7: POL | H7: 2 | I7: =IF(H7<$H$2+1,($I$2-($I$2-1)*(LOG(H7)/LOG($H$2))),"") -> 35.835824 | J7: =INT(LOG($H$2,2))-ROUNDUP(LOG(H7,2),0)+IF(OR($H$2=1,$H$2=2,$H$2=4,$H$2=8,$H$2=16,$H$2=32,$H$2=64,$H$2=128,$H$2=256),0,1) -> 3 | K7: =J7*$J$2 -> 30 | L7: =2*K2 -> 13.343881 | M7: =IF(I7<>"",K7+I7+L7,0) -> 79.179704
