Workbook

Sheet KlasyfikacjaGP
B2: Dołączył/a do kategorii w tym roku | D2: Klsyfikacja Grand Prix Pucharu Polski Weteranów (PPW) za 2022 rok | S2: Na sumę punktów w rankingu skłądają się 4 najlepsze wyniki (z 5 możliwych) w turniejach GP PPW oraz wynik z Mistrzostw Polski Weteranów.
D3: Kat. 2 | E3: (rok ur. 1963-1972)
A4: L.P. | B4: NAZWISKO Imię | C4: KLUB | D4: PUNKTY | E4: I GP | G4: II GP | I4: III GP | K4: IV GP | M4: V GP | O4: MPW
E5: M | F5: P | G5: M | H5: P | I5: M | J5: P | K5: M | L5: P | M5: M | N5: P | O5: M | P5: P | Q5: best
A6: =ROW()-5 -> 1 | B6: ATANASSOW Aleksander | D6: =SUM(F6,H6,J6,L6,N6,P6)-MIN(F6,H6,J6,L6,N6) -> 412.741 | E6: =_xlfn.XLOOKUP($B6,'GP1'!$C$6:$C$101,'GP1'!$B$6:$B$101,"") -> 1 | F6: =_xlfn.XLOOKUP(E6,'GP1'!$B$6:$B$55,'GP1'!$A$6:$A$55,0) -> 97.216381 | G6: =_xlfn.XLOOKUP($B6,'GP2'!$C$6:$C$101,'GP2'!$B$6:$B$101,"") -> 1 | H6: =_xlfn.XLOOKUP(G6,'GP2'!$B$6:$B$55,'GP2'!$A$6:$A$55,0) -> 97.216381 | I6: =_xlfn.XLOOKUP($B6,'GP3'!$C$6:$C$101,'GP3'!$B$6:$B$101,"") -> 1 | J6: =_xlfn.XLOOKUP(I6,'GP3'!$B$6:$B$55,'GP3'!$A$6:$A$55,0) -> 98 | K6: =_xlfn.XLOOKUP($B6,'GP4'!$C$6:$C$101,'GP4'!$B$6:$B$101,"") -> 1 | L6: =_xlfn.XLOOKUP(K6,'GP4'!$B$6:$B$55,'GP4'!$A$6:$A$55,0) -> 98 | M6: =_xlfn.XLOOKUP($B6,'GP5'!$C$6:$C$101,'GP5'!$B$6:$B$101,"") | N6: =_xlfn.XLOOKUP(M6,'GP5'!$B$6:$B$55,'GP5'!$A$6:$A$55,0) -> 0 | O6: =_xlfn.XLOOKUP(B6,MPW!C$6:C$101,MPW!B$6:B$101,"") -> 7 | P6: =_xlfn.XLOOKUP(O6,MPW!B$6:B$55,MPW!A$6:A$55,0) -> 22.308235 | Q6: =MAX(F6,H6,J6,L6,N6,P6) -> 98
A7: =ROW()-5 -> 2 | B7: ZIELIŃSKI Dariusz | D7: =SUM(F7,H7,J7,L7,N7,P7)-MIN(F7,H7,J7,L7,N7) -> 364.69928 | E7: =_xlfn.XLOOKUP($B7,'GP1'!$C$6:$C$101,'GP1'!$B$6:$B$101,"") -> 2 | F7: =_xlfn.XLOOKUP(E7,'GP1'!$B$6:$B$55,'GP1'!$A$6:$A$55,0) -> 64.023435 | G7: =_xlfn.XLOOKUP($B7,'GP2'!$C$6:$C$101,'GP2'!$B$6:$B$101,"") -> 3 | H7: =_xlfn.XLOOKUP(G7,'GP2'!$B$6:$B$55,'GP2'!$A$6:$A$55,0) -> 38.074617 | I7: =_xlfn.XLOOKUP($B7,'GP3'!$C$6:$C$101,'GP3'!$B$6:$B$101,"") -> 2 | J7: =_xlfn.XLOOKUP(I7,'GP3'!$B$6:$B$55,'GP3'!$A$6:$A$55,0) -> 65.666667 | K7: =_xlfn.XLOOKUP($B7,'GP4'!$C$6:$C$101,'GP4'!$B$6:$B$101,"") -> 2 | L7: =_xlfn.XLOOKUP(K7,'GP4'!$B$6:$B$55,'GP4'!$A$6:$A$55,0) -> 65.666667 | M7: =_xlfn.XLOOKUP($B7,'GP5'!$C$6:$C$101,'GP5'!$B$6:$B$101,"") | N7: =_xlfn.XLOOKUP(M7,'GP5'!$B$6:$B$55,'GP5'!$A$6:$A$55,0) -> 0 | O7: =_xlfn.XLOOKUP(B7,MPW!C$6:C$101,MPW!B$6:B$101,"") -> 1 | P7: =_xlfn.XLOOKUP(O7,MPW!B$6:B$55,MPW!A$6:A$55,0) -> 131.26789 | Q7: =MAX(F7,H7,J7,L7,N7,P7) -> 131.26789
A8: =ROW()-5 -> 3 | B8: KOSTRZEWA Ireneusz | D8: =SUM(F8,H8,J8,L8,N8,P8)-MIN(F8,H8,J8,L8,N8) -> 237.20224 | E8: =_xlfn.XLOOKUP($B8,'GP1'!$C$6:$C$101,'GP1'!$B$6:$B$101,"") -> 3 | F8: =_xlfn.XLOOKUP(E8,'GP1'!$B$6:$B$55,'GP1'!$A$6:$A$55,0) -> 38.074617 | G8: =_xlfn.XLOOKUP($B8,'GP2'!$C$6:$C$101,'GP2'!$B$6:$B$101,"") -> 4 | H8: =_xlfn.XLOOKUP(G8,'GP2'!$B$6:$B$55,'GP2'!$A$6:$A$55,0) -> 25.091696 | I8: =_xlfn.XLOOKUP($B8,'GP3'!$C$6:$C$101,'GP3'!$B$6:$B$101,"") -> 3 | J8: =_xlfn.XLOOKUP(I8,'GP3'!$B$6:$B$55,'GP3'!$A$6:$A$55,0) -> 40.112279 | K8: =_xlfn.XLOOKUP($B8,'GP4'!$C$6:$C$101,'GP4'!$B$6:$B$101,"") -> 3 | L8: =_xlfn.XLOOKUP(K8,'GP4'!$B$6:$B$55,'GP4'!$A$6:$A$55,0) -> 40.112279 | M8: =_xlfn.XLOOKUP($B8,'GP5'!$C$6:$C$101,'GP5'!$B$6:$B$101,"") | N8: =_xlfn.XLOOKUP(M8,'GP5'!$B$6:$B$55,'GP5'!$A$6:$A$55,0) -> 0 | O8: =_xlfn.XLOOKUP(B8,MPW!C$6:C$101,MPW!B$6:B$101,"") -> 2 | P8: =_xlfn.XLOOKUP(O8,MPW!B$6:B$55,MPW!A$6:A$55,0) -> 93.811366 | Q8: =MAX(F8,H8,J8,L8,N8,P8) -> 93.811366
A9: =ROW()-5 -> 4 | B9: WOJTAS Bogdan | D9: =SUM(F9,H9,J9,L9,N9,P9)-MIN(F9,H9,J9,L9,N9) -> 215.39525 | E9: =_xlfn.XLOOKUP($B9,'GP1'!$C$6:$C$101,'GP1'!$B$6:$B$101,"") -> 4 | F9: =_xlfn.XLOOKUP(E9,'GP1'!$B$6:$B$55,'GP1'!$A$6:$A$55,0) -> 25.091696 | G9: =_xlfn.XLOOKUP($B9,'GP2'!$C$6:$C$101,'GP2'!$B$6:$B$101,"") | H9: =_xlfn.XLOOKUP(G9,'GP2'!$B$6:$B$55,'GP2'!$A$6:$A$55,0) -> 0 | I9: =_xlfn.XLOOKUP($B9,'GP3'!$C$6:$C$101,'GP3'!$B$6:$B$101,"") -> 4 | J9: =_xlfn.XLOOKUP(I9,'GP3'!$B$6:$B$55,'GP3'!$A$6:$A$55,0) -> 27.333333 | K9: =_xlfn.XLOOKUP($B9,'GP4'!$C$6:$C$101,'GP4'!$B$6:$B$101,"") -> 3 | L9: =_xlfn.XLOOKUP(K9,'GP4'!$B$6:$B$55,'GP4'!$A$6:$A$55,0) -> 40.112279 | M9: =_xlfn.XLOOKUP($B9,'GP5'!$C$6:$C$101,'GP5'!$B$6:$B$101,"") -> 2 | N9: =_xlfn.XLOOKUP(M9,'GP5'!$B$6:$B$55,'GP5'!$A$6:$A$55,0) -> 59.156704 | O9: =_xlfn.XLOOKUP(B9,MPW!C$6:C$101,MPW!B$6:B$101,"") -> 3 | P9: =_xlfn.XLOOKUP(O9,MPW!B$6:B$55,MPW!A$6:A$55,0) -> 63.701235 | Q9: =MAX(F9,H9,J9,L9,N9,P9) -> 63.701235
A10: =ROW()-5 -> 5 | B10: KOTERSKI Paweł | D10: =SUM(F10,H10,J10,L10,N10,P10)-MIN(F10,H10,J10,L10,N10) -> 212.89376 | E10: =_xlfn.XLOOKUP($B10,'GP1'!$C$6:$C$101,'GP1'!$B$6:$B$101,"") -> 6 | F10: =_xlfn.XLOOKUP(E10,'GP1'!$B$6:$B$55,'GP1'!$A$6:$A$55,0) -> 4.8816712 | G10: =_xlfn.XLOOKUP($B10,'GP2'!$C$6:$C$101,'GP2'!$B$6:$B$101,"") -> 2 | H10: =_xlfn.XLOOKUP(G10,'GP2'!$B$6:$B$55,'GP2'!$A$6:$A$55,0) -> 64.023435 | I10: =_xlfn.XLOOKUP($B10,'GP3'!$C$6:$C$101,'GP3'!$B$6:$B$101,"") | J10: =_xlfn.XLOOKUP(I10,'GP3'!$B$6:$B$55,'GP3'!$A$6:$A$55,0) -> 0 | K10: =_xlfn.XLOOKUP($B10,'GP4'!$C$6:$C$101,'GP4'!$B$6:$B$101,"") | L10: =_xlfn.XLOOKUP(K10,'GP4'!$B$6:$B$55,'GP4'!$A$6:$A$55,0) -> 0 | M10: =_xlfn.XLOOKUP($B10,'GP5'!$C$6:$C$101,'GP5'!$B$6:$B$101,"") -> 1 | N10: =_xlfn.XLOOKUP(M10,'GP5'!$B$6:$B$55,'GP5'!$A$6:$A$55,0) -> 95.389784 | O10: =_xlfn.XLOOKUP(B10,MPW!C$6:C$101,MPW!B$6:B$101,"") -> 4 | P10: =_xlfn.XLOOKUP(O10,MPW!B$6:B$55,MPW!A$6:A$55,0) -> 48.598873 | Q10: =MAX(F10,H10,J10,L10,N10,P10) -> 95.389784
A11: =ROW()-5 -> 6 | B11: DRAPELLA Maciej | D11: =SUM(F11,H11,J11,L11,N11,P11)-MIN(F11,H11,J11,L11,N11) -> 61.921166 | E11: =_xlfn.XLOOKUP($B11,'GP1'!$C$6:$C$101,'GP1'!$B$6:$B$101,"") -> 5 | F11: =_xlfn.XLOOKUP(E11,'GP1'!$B$6:$B$55,'GP1'!$A$6:$A$55,0) -> 9.4727137 | G11: =_xlfn.XLOOKUP($B11,'GP2'!$C$6:$C$101,'GP2'!$B$6:$B$101,"") -> 5 | H11: =_xlfn.XLOOKUP(G11,'GP2'!$B$6:$B$55,'GP2'!$A$6:$A$55,0) -> 9.4727137 | I11: =_xlfn.XLOOKUP($B11,'GP3'!$C$6:$C$101,'GP3'!$B$6:$B$101,"") -> 5 | J11: =_xlfn.XLOOKUP(I11,'GP3'!$B$6:$B$55,'GP3'!$A$6:$A$55,0) -> 12.075174 | K11: =_xlfn.XLOOKUP($B11,'GP4'!$C$6:$C$101,'GP4'!$B$6:$B$101,"") | L11: =_xlfn.XLOOKUP(K11,'GP4'!$B$6:$B$55,'GP4'!$A$6:$A$55,0) -> 0 | M11: =_xlfn.XLOOKUP($B11,'GP5'!$C$6:$C$101,'GP5'!$B$6:$B$101,"") | N11: =_xlfn.XLOOKUP(M11,'GP5'!$B$6:$B$55,'GP5'!$A$6:$A$55,0) -> 0 | O11: =_xlfn.XLOOKUP(B11,MPW!C$6:C$101,MPW!B$6:B$101,"") -> 5 | P11: =_xlfn.XLOOKUP(O11,MPW!B$6:B$55,MPW!A$6:A$55,0) -> 30.900564 | Q11: =MAX(F11,H11,J11,L11,N11,P11) -> 30.900564
A12: =ROW()-5 -> 7 | B12: GRZYWACZ Mirosław | D12: =SUM(F12,H12,J12,L12,N12,P12)-MIN(F12,H12,J12,L12,N12) -> 57.926931 | E12: =_xlfn.XLOOKUP($B12,'GP1'!$C$6:$C$101,'GP1'!$B$6:$B$101,"") | F12: =_xlfn.XLOOKUP(E12,'GP1'!$B$6:$B$55,'GP1'!$A$6:$A$55,0) -> 0 | G12: =_xlfn.XLOOKUP($B12,'GP2'!$C$6:$C$101,'GP2'!$B$6:$B$101,"") | H12: =_xlfn.XLOOKUP(G12,'GP2'!$B$6:$B$55,'GP2'!$A$6:$A$55,0) -> 0 | I12: =_xlfn.XLOOKUP($B12,'GP3'!$C$6:$C$101,'GP3'!$B$6:$B$101,"") | J12: =_xlfn.XLOOKUP(I12,'GP3'!$B$6:$B$55,'GP3'!$A$6:$A$55,0) -> 0 | K12: =_xlfn.XLOOKUP($B12,'GP4'!$C$6:$C$101,'GP4'!$B$6:$B$101,"") | L12: =_xlfn.XLOOKUP(K12,'GP4'!$B$6:$B$55,'GP4'!$A$6:$A$55,0) -> 0 | M12: =_xlfn.XLOOKUP($B12,'GP5'!$C$6:$C$101,'GP5'!$B$6:$B$101,"") -> 3 | N12: =_xlfn.XLOOKUP(M12,'GP5'!$B$6:$B$55,'GP5'!$A$6:$A$55,0) -> 31.682224 | O12: =_xlfn.XLOOKUP(B12,MPW!C$6:C$101,MPW!B$6:B$101,"") -> 6 | P12: =_xlfn.XLOOKUP(O12,MPW!B$6:B$55,MPW!A$6:A$55,0) -> 26.244706 | Q12: =MAX(F12,H12,J12,L12,N12,P12) -> 31.682224
A13: =ROW()-5 -> 8 | B13: SKOCZEK Artur | D13: =SUM(F13,H13,J13,L13,N13,P13)-MIN(F13,H13,J13,L13,N13) -> 37.242129 | E13: =_xlfn.XLOOKUP($B13,'GP1'!$C$6:$C$101,'GP1'!$B$6:$B$101,"") | F13: =_xlfn.XLOOKUP(E13,'GP1'!$B$6:$B$55,'GP1'!$A$6:$A$55,0) -> 0 | G13: =_xlfn.XLOOKUP($B13,'GP2'!$C$6:$C$101,'GP2'!$B$6:$B$101,"") | H13: =_xlfn.XLOOKUP(G13,'GP2'!$B$6:$B$55,'GP2'!$A$6:$A$55,0) -> 0 | I13: =_xlfn.XLOOKUP($B13,'GP3'!$C$6:$C$101,'GP3'!$B$6:$B$101,"") -> 6 | J13: =_xlfn.XLOOKUP(I13,'GP3'!$B$6:$B$55,'GP3'!$A$6:$A$55,0) -> 7.7789458 | K13: =_xlfn.XLOOKUP($B13,'GP4'!$C$6:$C$101,'GP4'!$B$6:$B$101,"") -> 6 | L13: =_xlfn.XLOOKUP(K13,'GP4'!$B$6:$B$55,'GP4'!$A$6:$A$55,0) -> 7.7789458 | M13: =_xlfn.XLOOKUP($B13,'GP5'!$C$6:$C$101,'GP5'!$B$6:$B$101,"") -> 4 | N13: =_xlfn.XLOOKUP(M13,'GP5'!$B$6:$B$55,'GP5'!$A$6:$A$55,0) -> 17.793697 | O13: =_xlfn.XLOOKUP(B13,MPW!C$6:C$101,MPW!B$6:B$101,"") -> 9 | P13: =_xlfn.XLOOKUP(O13,MPW!B$6:B$55,MPW!A$6:A$55,0) -> 3.8905404 | Q13: =MAX(F13,H13,J13,L13,N13,P13) -> 17.793697
A14: =ROW()-5 -> 9 | B14: WIERZBICKI Jacek | D14: =SUM(F14,H14,J14,L14,N14,P14)-MIN(F14,H14,J14,L14,N14) -> 26.044845 | E14: =_xlfn.XLOOKUP($B14,'GP1'!$C$6:$C$101,'GP1'!$B$6:$B$101,"") -> 7 | F14: =_xlfn.XLOOKUP(E14,'GP1'!$B$6:$B$55,'GP1'!$A$6:$A$55,0) -> 1 | G14: =_xlfn.XLOOKUP($B14,'GP2'!$C$6:$C$101,'GP2'!$B$6:$B$101,"") -> 7 | H14: =_xlfn.XLOOKUP(G14,'GP2'!$B$6:$B$55,'GP2'!$A$6:$A$55,0) -> 1 | I14: =_xlfn.XLOOKUP($B14,'GP3'!$C$6:$C$101,'GP3'!$B$6:$B$101,"") -> 8 | J14: =_xlfn.XLOOKUP(I14,'GP3'!$B$6:$B$55,'GP3'!$A$6:$A$55,0) -> 1 | K14: =_xlfn.XLOOKUP($B14,'GP4'!$C$6:$C$101,'GP4'!$B$6:$B$101,"") -> 7 | L14: =_xlfn.XLOOKUP(K14,'GP4'!$B$6:$B$55,'GP4'!$A$6:$A$55,0) -> 4.1465363 | M14: =_xlfn.XLOOKUP($B14,'GP5'!$C$6:$C$101,'GP5'!$B$6:$B$101,"") | N14: =_xlfn.XLOOKUP(M14,'GP5'!$B$6:$B$55,'GP5'!$A$6:$A$55,0) -> 0 | O14: =_xlfn.XLOOKUP(B14,MPW!C$6:C$101,MPW!B$6:B$101,"") -> 8 | P14: =_xlfn.XLOOKUP(O14,MPW!B$6:B$55,MPW!A$6:A$55,0) -> 18.898309 | Q14: =MAX(F14,H14,J14,L14,N14,P14) -> 18.898309
A15: =ROW()-5 -> 10 | B15: TYKHYI Volodymyr | D15: =SUM(F15,H15,J15,L15,N15,P15)-MIN(F15,H15,J15,L15,N15) -> 12.075174 | E15: =_xlfn.XLOOKUP($B15,'GP1'!$C$6:$C$101,'GP1'!$B$6:$B$101,"") | F15: =_xlfn.XLOOKUP(E15,'GP1'!$B$6:$B$55,'GP1'!$A$6:$A$55,0) -> 0 | G15: =_xlfn.XLOOKUP($B15,'GP2'!$C$6:$C$101,'GP2'!$B$6:$B$101,"") | H15: =_xlfn.XLOOKUP(G15,'GP2'!$B$6:$B$55,'GP2'!$A$6:$A$55,0) -> 0 | I15: =_xlfn.XLOOKUP($B15,'GP3'!$C$6:$C$101,'GP3'!$B$6:$B$101,"") | J15: =_xlfn.XLOOKUP(I15,'GP3'!$B$6:$B$55,'GP3'!$A$6:$A$55,0) -> 0 | K15: =_xlfn.XLOOKUP($B15,'GP4'!$C$6:$C$101,'GP4'!$B$6:$B$101,"") -> 5 | L15: =_xlfn.XLOOKUP(K15,'GP4'!$B$6:$B$55,'GP4'!$A$6:$A$55,0) -> 12.075174 | M15: =_xlfn.XLOOKUP($B15,'GP5'!$C$6:$C$101,'GP5'!$B$6:$B$101,"") | N15: =_xlfn.XLOOKUP(M15,'GP5'!$B$6:$B$55,'GP5'!$A$6:$A$55,0) -> 0 | O15: =_xlfn.XLOOKUP(B15,MPW!C$6:C$101,MPW!B$6:B$101,"") | P15: =_xlfn.XLOOKUP(O15,MPW!B$6:B$55,MPW!A$6:A$55,0) | Q15: =MAX(F15,H15,J15,L15,N15,P15) -> 12.075174
A16: =ROW()-5 -> 11 | B16: PARDUS Borys | D16: =SUM(F16,H16,J16,L16,N16,P16)-MIN(F16,H16,J16,L16,N16) -> 7.3465363 | E16: =_xlfn.XLOOKUP($B16,'GP1'!$C$6:$C$101,'GP1'!$B$6:$B$101,"") | F16: =_xlfn.XLOOKUP(E16,'GP1'!$B$6:$B$55,'GP1'!$A$6:$A$55,0) -> 0 | G16: =_xlfn.XLOOKUP($B16,'GP2'!$C$6:$C$101,'GP2'!$B$6:$B$101,"") | H16: =_xlfn.XLOOKUP(G16,'GP2'!$B$6:$B$55,'GP2'!$A$6:$A$55,0) -> 0 | I16: =_xlfn.XLOOKUP($B16,'GP3'!$C$6:$C$101,'GP3'!$B$6:$B$101,"") -> 7 | J16: =_xlfn.XLOOKUP(I16,'GP3'!$B$6:$B$55,'GP3'!$A$6:$A$55,0) -> 4.1465363 | K16: =_xlfn.XLOOKUP($B16,'GP4'!$C$6:$C$101,'GP4'!$B$6:$B$101,"") -> 8 | L16: =_xlfn.XLOOKUP(K16,'GP4'!$B$6:$B$55,'GP4'!$A$6:$A$55,0) -> 1 | M16: =_xlfn.XLOOKUP($B16,'GP5'!$C$6:$C$101,'GP5'!$B$6:$B$101,"") -> 5 | N16: =_xlfn.XLOOKUP(M16,'GP5'!$B$6:$B$55,'GP5'!$A$6:$A$55,0) -> 1 | O16: =_xlfn.XLOOKUP(B16,MPW!C$6:C$101,MPW!B$6:B$101,"") -> 10 | P16: =_xlfn.XLOOKUP(O16,MPW!B$6:B$55,MPW!A$6:A$55,0) -> 1.2 | Q16: =MAX(F16,H16,J16,L16,N16,P16) -> 4.1465363
A17: =ROW()-5 -> 12 | B17: NIKALAICHUK Aliaksandr | D17: =SUM(F17,H17,J17,L17,N17,P17)-MIN(F17,H17,J17,L17,N17) -> 4.8816712 | E17: =_xlfn.XLOOKUP($B17,'GP1'!$C$6:$C$101,'GP1'!$B$6:$B$101,"") | F17: =_xlfn.XLOOKUP(E17,'GP1'!$B$6:$B$55,'GP1'!$A$6:$A$55,0) -> 0 | G17: =_xlfn.XLOOKUP($B17,'GP2'!$C$6:$C$101,'GP2'!$B$6:$B$101,"") -> 6 | H17: =_xlfn.XLOOKUP(G17,'GP2'!$B$6:$B$55,'GP2'!$A$6:$A$55,0) -> 4.8816712 | I17: =_xlfn.XLOOKUP($B17,'GP3'!$C$6:$C$101,'GP3'!$B$6:$B$101,"") | J17: =_xlfn.XLOOKUP(I17,'GP3'!$B$6:$B$55,'GP3'!$A$6:$A$55,0) -> 0 | K17: =_xlfn.XLOOKUP($B17,'GP4'!$C$6:$C$101,'GP4'!$B$6:$B$101,"") | L17: =_xlfn.XLOOKUP(K17,'GP4'!$B$6:$B$55,'GP4'!$A$6:$A$55,0) -> 0 | M17: =_xlfn.XLOOKUP($B17,'GP5'!$C$6:$C$101,'GP5'!$B$6:$B$101,"") | N17: =_xlfn.XLOOKUP(M17,'GP5'!$B$6:$B$55,'GP5'!$A$6:$A$55,0) -> 0 | O17: =_xlfn.XLOOKUP(B17,MPW!C$6:C$101,MPW!B$6:B$101,"") | P17: =_xlfn.XLOOKUP(O17,MPW!B$6:B$55,MPW!A$6:A$55,0) | Q17: =MAX(F17,H17,J17,L17,N17,P17) -> 4.8816712
A18: =ROW()-5 -> 13 | D18: =SUM(F18,H18,J18,L18,N18,P18)-MIN(F18,H18,J18,L18,N18) -> 0 | E18: =_xlfn.XLOOKUP($B18,'GP1'!$C$6:$C$101,'GP1'!$B$6:$B$101,"") | F18: =_xlfn.XLOOKUP(E18,'GP1'!$B$6:$B$55,'GP1'!$A$6:$A$55,0) -> 0 | G18: =_xlfn.XLOOKUP($B18,'GP2'!$C$6:$C$101,'GP2'!$B$6:$B$101,"") | H18: =_xlfn.XLOOKUP(G18,'GP2'!$B$6:$B$55,'GP2'!$A$6:$A$55,0) -> 0 | I18: =_xlfn.XLOOKUP($B18,'GP3'!$C$6:$C$101,'GP3'!$B$6:$B$101,"") | J18: =_xlfn.XLOOKUP(I18,'GP3'!$B$6:$B$55,'GP3'!$A$6:$A$55,0) -> 0 | K18: =_xlfn.XLOOKUP($B18,'GP4'!$C$6:$C$101,'GP4'!$B$6:$B$101,"") | L18: =_xlfn.XLOOKUP(K18,'GP4'!$B$6:$B$55,'GP4'!$A$6:$A$55,0) -> 0 | M18: =_xlfn.XLOOKUP($B18,'GP5'!$C$6:$C$101,'GP5'!$B$6:$B$101,"") | N18: =_xlfn.XLOOKUP(M18,'GP5'!$B$6:$B$55,'GP5'!$A$6:$A$55,0) -> 0 | O18: =_xlfn.XLOOKUP(B18,MPW!C$6:C$101,MPW!B$6:B$101,"") | P18: =_xlfn.XLOOKUP(O18,MPW!B$6:B$55,MPW!A$6:A$55,0) | Q18: =MAX(F18,H18,J18,L18,N18,P18) -> 0
A19: =ROW()-5 -> 14 | D19: =SUM(F19,H19,J19,L19,N19,P19)-MIN(F19,H19,J19,L19,N19) -> 0 | E19: =_xlfn.XLOOKUP($B19,'GP1'!$C$6:$C$101,'GP1'!$B$6:$B$101,"") | F19: =_xlfn.XLOOKUP(E19,'GP1'!$B$6:$B$55,'GP1'!$A$6:$A$55,0) -> 0 | G19: =_xlfn.XLOOKUP($B19,'GP2'!$C$6:$C$101,'GP2'!$B$6:$B$101,"") | H19: =_xlfn.XLOOKUP(G19,'GP2'!$B$6:$B$55,'GP2'!$A$6:$A$55,0) -> 0 | I19: =_xlfn.XLOOKUP($B19,'GP3'!$C$6:$C$101,'GP3'!$B$6:$B$101,"") | J19: =_xlfn.XLOOKUP(I19,'GP3'!$B$6:$B$55,'GP3'!$A$6:$A$55,0) -> 0 | K19: =_xlfn.XLOOKUP($B19,'GP4'!$C$6:$C$101,'GP4'!$B$6:$B$101,"") | L19: =_xlfn.XLOOKUP(K19,'GP4'!$B$6:$B$55,'GP4'!$A$6:$A$55,0) -> 0 | M19: =_xlfn.XLOOKUP($B19,'GP5'!$C$6:$C$101,'GP5'!$B$6:$B$101,"") | N19: =_xlfn.XLOOKUP(M19,'GP5'!$B$6:$B$55,'GP5'!$A$6:$A$55,0) -> 0 | O19: =_xlfn.XLOOKUP(B19,MPW!C$6:C$101,MPW!B$6:B$101,"") | P19: =_xlfn.XLOOKUP(O19,MPW!B$6:B$55,MPW!A$6:A$55,0) | Q19: =MAX(F19,H19,J19,L19,N19,P19) -> 0
A20: =ROW()-5 -> 15 | D20: =SUM(F20,H20,J20,L20,N20,P20)-MIN(F20,H20,J20,L20,N20) -> 0 | E20: =_xlfn.XLOOKUP($B20,'GP1'!$C$6:$C$101,'GP1'!$B$6:$B$101,"") | F20: =_xlfn.XLOOKUP(E20,'GP1'!$B$6:$B$55,'GP1'!$A$6:$A$55,0) -> 0 | G20: =_xlfn.XLOOKUP($B20,'GP2'!$C$6:$C$101,'GP2'!$B$6:$B$101,"") | H20: =_xlfn.XLOOKUP(G20,'GP2'!$B$6:$B$55,'GP2'!$A$6:$A$55,0) -> 0 | I20: =_xlfn.XLOOKUP($B20,'GP3'!$C$6:$C$101,'GP3'!$B$6:$B$101,"") | J20: =_xlfn.XLOOKUP(I20,'GP3'!$B$6:$B$55,'GP3'!$A$6:$A$55,0) -> 0 | K20: =_xlfn.XLOOKUP($B20,'GP4'!$C$6:$C$101,'GP4'!$B$6:$B$101,"") | L20: =_xlfn.XLOOKUP(K20,'GP4'!$B$6:$B$55,'GP4'!$A$6:$A$55,0) -> 0 | M20: =_xlfn.XLOOKUP($B20,'GP5'!$C$6:$C$101,'GP5'!$B$6:$B$101,"") | N20: =_xlfn.XLOOKUP(M20,'GP5'!$B$6:$B$55,'GP5'!$A$6:$A$55,0) -> 0 | O20: =_xlfn.XLOOKUP(B20,MPW!C$6:C$101,MPW!B$6:B$101,"") | P20: =_xlfn.XLOOKUP(O20,MPW!B$6:B$55,MPW!A$6:A$55,0) | Q20: =MAX(F20,H20,J20,L20,N20,P20) -> 0
A21: =ROW()-5 -> 16 | D21: =SUM(F21,H21,J21,L21,N21,P21)-MIN(F21,H21,J21,L21,N21) -> 0 | E21: =_xlfn.XLOOKUP($B21,'GP1'!$C$6:$C$101,'GP1'!$B$6:$B$101,"") | F21: =_xlfn.XLOOKUP(E21,'GP1'!$B$6:$B$55,'GP1'!$A$6:$A$55,0) -> 0 | G21: =_xlfn.XLOOKUP($B21,'GP2'!$C$6:$C$101,'GP2'!$B$6:$B$101,"") | H21: =_xlfn.XLOOKUP(G21,'GP2'!$B$6:$B$55,'GP2'!$A$6:$A$55,0) -> 0 | I21: =_xlfn.XLOOKUP($B21,'GP3'!$C$6:$C$101,'GP3'!$B$6:$B$101,"") | J21: =_xlfn.XLOOKUP(I21,'GP3'!$B$6:$B$55,'GP3'!$A$6:$A$55,0) -> 0 | K21: =_xlfn.XLOOKUP($B21,'GP4'!$C$6:$C$101,'GP4'!$B$6:$B$101,"") | L21: =_xlfn.XLOOKUP(K21,'GP4'!$B$6:$B$55,'GP4'!$A$6:$A$55,0) -> 0 | M21: =_xlfn.XLOOKUP($B21,'GP5'!$C$6:$C$101,'GP5'!$B$6:$B$101,"") | N21: =_xlfn.XLOOKUP(M21,'GP5'!$B$6:$B$55,'GP5'!$A$6:$A$55,0) -> 0 | O21: =_xlfn.XLOOKUP(B21,MPW!C$6:C$101,MPW!B$6:B$101,"") | P21: =_xlfn.XLOOKUP(O21,MPW!B$6:B$55,MPW!A$6:A$55,0) | Q21: =MAX(F21,H21,J21,L21,N21,P21) -> 0
A22: =ROW()-5 -> 17 | D22: =SUM(F22,H22,J22,L22,N22,P22)-MIN(F22,H22,J22,L22,N22) -> 0 | E22: =_xlfn.XLOOKUP($B22,'GP1'!$C$6:$C$101,'GP1'!$B$6:$B$101,"") | F22: =_xlfn.XLOOKUP(E22,'GP1'!$B$6:$B$55,'GP1'!$A$6:$A$55,0) -> 0 | G22: =_xlfn.XLOOKUP($B22,'GP2'!$C$6:$C$101,'GP2'!$B$6:$B$101,"") | H22: =_xlfn.XLOOKUP(G22,'GP2'!$B$6:$B$55,'GP2'!$A$6:$A$55,0) -> 0 | I22: =_xlfn.XLOOKUP($B22,'GP3'!$C$6:$C$101,'GP3'!$B$6:$B$101,"") | J22: =_xlfn.XLOOKUP(I22,'GP3'!$B$6:$B$55,'GP3'!$A$6:$A$55,0) -> 0 | K22: =_xlfn.XLOOKUP($B22,'GP4'!$C$6:$C$101,'GP4'!$B$6:$B$101,"") | L22: =_xlfn.XLOOKUP(K22,'GP4'!$B$6:$B$55,'GP4'!$A$6:$A$55,0) -> 0 | M22: =_xlfn.XLOOKUP($B22,'GP5'!$C$6:$C$101,'GP5'!$B$6:$B$101,"") | N22: =_xlfn.XLOOKUP(M22,'GP5'!$B$6:$B$55,'GP5'!$A$6:$A$55,0) -> 0 | O22: =_xlfn.XLOOKUP(B22,MPW!C$6:C$101,MPW!B$6:B$101,"") | P22: =_xlfn.XLOOKUP(O22,MPW!B$6:B$55,MPW!A$6:A$55,0) | Q22: =MAX(F22,H22,J22,L22,N22,P22) -> 0
A23: =ROW()-5 -> 18 | D23: =SUM(F23,H23,J23,L23,N23,P23)-MIN(F23,H23,J23,L23,N23) -> 0 | E23: =_xlfn.XLOOKUP($B23,'GP1'!$C$6:$C$101,'GP1'!$B$6:$B$101,"") | F23: =_xlfn.XLOOKUP(E23,'GP1'!$B$6:$B$55,'GP1'!$A$6:$A$55,0) -> 0 | G23: =_xlfn.XLOOKUP($B23,'GP2'!$C$6:$C$101,'GP2'!$B$6:$B$101,"") | H23: =_xlfn.XLOOKUP(G23,'GP2'!$B$6:$B$55,'GP2'!$A$6:$A$55,0) -> 0 | I23: =_xlfn.XLOOKUP($B23,'GP3'!$C$6:$C$101,'GP3'!$B$6:$B$101,"") | J23: =_xlfn.XLOOKUP(I23,'GP3'!$B$6:$B$55,'GP3'!$A$6:$A$55,0) -> 0 | K23: =_xlfn.XLOOKUP($B23,'GP4'!$C$6:$C$101,'GP4'!$B$6:$B$101,"") | L23: =_xlfn.XLOOKUP(K23,'GP4'!$B$6:$B$55,'GP4'!$A$6:$A$55,0) -> 0 | M23: =_xlfn.XLOOKUP($B23,'GP5'!$C$6:$C$101,'GP5'!$B$6:$B$101,"") | N23: =_xlfn.XLOOKUP(M23,'GP5'!$B$6:$B$55,'GP5'!$A$6:$A$55,0) -> 0 | O23: =_xlfn.XLOOKUP(B23,MPW!C$6:C$101,MPW!B$6:B$101,"") | P23: =_xlfn.XLOOKUP(O23,MPW!B$6:B$55,MPW!A$6:A$55,0) | Q23: =MAX(F23,H23,J23,L23,N23,P23) -> 0

Sheet GP1
H1: Liczba uczestników: | I1: GP Punkty | J1: Bonus za rundę | K1: Mnożnik za podium
B2: miejsce: | C2: LESZNO | H2: 7 | I2: 50 | J2: 10 | K2: =3*H2^(1/3) -> 5.7387935
B3: data: | C3: 44611
A5: Punkty | B5: Miejsce Place | C5: Nazwisko Imię Name | D5: Klub Club(s) | E5: Okręg Division | F5: Państwo Country | H5: Miejsce | I5: Punkty za miejsce | J5: liczba wygranych walk pucharowych | K5: bonus z rundy pucharowej | L5: punkty za podium | M5: Suma
A6: =M6 -> 97.216381 | B6: =IF(H6>$H$2,"",(ROW()-5)) -> 1 | C6: ATANASSOW Aleksander | F6: POL | H6: 1 | I6: =IF(H6<$H$2+1,($I$2-($I$2-1)*(LOG(H6)/LOG($H$2))),"") -> 50 | J6: =INT(LOG($H$2,2))-ROUNDUP(LOG(H6,2),0)+IF(OR($H$2=1,$H$2=2,$H$2=4,$H$2=8,$H$2=16,$H$2=32,$H$2=64,$H$2=128,$H$2=256),0,1) -> 3 | K6: =J6*$J$2 -> 30 | L6: =3*K2 -> 17.216381 | M6: =IF(I6<>"",K6+I6+L6,0) -> 97.216381
A7: =M7 -> 64.023435 | B7: =IF(H7>$H$2,"",(ROW()-5)) -> 2 | C7: ZIELIŃSKI Dariusz | F7: POL | H7: 2 | I7: =IF(H7<$H$2+1,($I$2-($I$2-1)*(LOG(H7)/LOG($H$2))),"") -> 32.545848 | J7: =INT(LOG($H$2,2))-ROUNDUP(LOG(H7,2),0)+IF(OR($H$2=1,$H$2=2,$H$2=4,$H$2=8,$H$2=16,$H$2=32,$H$2=64,$H$2=128,$H$2=256),0,1) -> 2 | K7: =J7*$J$2 -> 20 | L7: =2*K2 -> 11.477587 | M7: =IF(I7<>"",K7+I7+L7,0) -> 64.023435
A8: =M8 -> 38.074617 | B8: =IF(H8>$H$2,"",(ROW()-5)) -> 3 | C8: KOSTRZEWA Ireneusz | F8: POL | H8: 3 | I8: =IF(H8<$H$2+1,($I$2-($I$2-1)*(LOG(H8)/LOG($H$2))),"") -> 22.335823 | J8: =INT(LOG($H$2,2))-ROUNDUP(LOG(H8,2),0)+IF(OR($H$2=1,$H$2=2,$H$2=4,$H$2=8,$H$2=16,$H$2=32,$H$2=64,$H$2=128,$H$2=256),0,1) -> 1 | K8: =J8*$J$2 -> 10 | L8: =K2 -> 5.7387935 | M8: =IF(I8<>"",K8+I8+L8,0) -> 38.074617
A9: =M9 -> 25.091696 | B9: =IF(H9>$H$2,"",(ROW()-5)) -> 4 | C9: WOJTAS Bogdan | F9: POL | H9: 4 | I9: =IF(H9<$H$2+1,($I$2-($I$2-1)*(LOG(H9)/LOG($H$2))),"") -> 15.091696 | J9: =INT(LOG($H$2,2))-ROUNDUP(LOG(H9,2),0)+IF(OR($H$2=1,$H$2=2,$H$2=4,$H$2=8,$H$2=16,$H$2=32,$H$2=64,$H$2=128,$H$2=256),0,1) -> 1 | K9: =J9*$J$2 -> 10 | M9: =IF(I9<>"",K9+I9+L9,0) -> 25.091696
A10: =M10 -> 9.4727137 | B10: =IF(H10>$H$2,"",(ROW()-5)) -> 5 | C10: DRAPELLA Maciej | F10: POL | H10: 5 | I10: =IF(H10<$H$2+1,($I$2-($I$2-1)*(LOG(H10)/LOG($H$2))),"") -> 9.4727137 | J10: =INT(LOG($H$2,2))-ROUNDUP(LOG(H10,2),0)+IF(OR($H$2=1,$H$2=2,$H$2=4,$H$2=8,$H$2=16,$H$2=32,$H$2=64,$H$2=128,$H$2=256),0,1) -> 0 | K10: =J10*$J$2 -> 0 | M10: =IF(I10<>"",K10+I10+L10,0) -> 9.4727137
A11: =M11 -> 4.8816712 | B11: =IF(H11>$H$2,"",(ROW()-5)) -> 6 | C11: KOTERSKI Paweł | F11: POL | H11: 6 | I11: =IF(H11<$H$2+1,($I$2-($I$2-1)*(LOG(H11)/LOG($H$2))),"") -> 4.8816712 | J11: =INT(LOG($H$2,2))-ROUNDUP(LOG(H11,2),0)+IF(OR($H$2=1,$H$2=2,$H$2=4,$H$2=8,$H$2=16,$H$2=32,$H$2=64,$H$2=128,$H$2=256),0,1) -> 0 | K11: =J11*$J$2 -> 0 | M11: =IF(I11<>"",K11+I11+L11,0) -> 4.8816712
A12: =M12 -> 1 | B12: =IF(H12>$H$2,"",(ROW()-5)) -> 7 | C12: WIERZBICKI Jacek | F12: POL | H12: 7 | I12: =IF(H12<$H$2+1,($I$2-($I$2-1)*(LOG(H12)/LOG($H$2))),"") -> 1 | J12: =INT(LOG($H$2,2))-ROUNDUP(LOG(H12,2),0)+IF(OR($H$2=1,$H$2=2,$H$2=4,$H$2=8,$H$2=16,$H$2=32,$H$2=64,$H$2=128,$H$2=256),0,1) -> 0 | K12: =J12*$J$2 -> 0 | M12: =IF(I12<>"",K12+I12+L12,0) -> 1
A13: =M13 -> 0 | B13: =IF(H13>$H$2,"",(ROW()-5)) | H13: 8 | I13: =IF(H13<$H$2+1,($I$2-($I$2-1)*(LOG(H13)/LOG($H$2))),"") | J13: =INT(LOG($H$2,2))-ROUNDUP(LOG(H13,2),0)+IF(OR($H$2=1,$H$2=2,$H$2=4,$H$2=8,$H$2=16,$H$2=32,$H$2=64,$H$2=128,$H$2=256),0,1) -> 0 | K13: =J13*$J$2 -> 0 | M13: =IF(I13<>"",K13+I13+L13,0) -> 0
A14: =M14 -> 0 | B14: =IF(H14>$H$2,"",(ROW()-5)) | H14: 9 | I14: =IF(H14<$H$2+1,($I$2-($I$2-1)*(LOG(H14)/LOG($H$2))),"") | J14: =INT(LOG($H$2,2))-ROUNDUP(LOG(H14,2),0)+IF(OR($H$2=1,$H$2=2,$H$2=4,$H$2=8,$H$2=16,$H$2=32,$H$2=64,$H$2=128,$H$2=256),0,1) -> -1 | K14: =J14*$J$2 -> -10 | M14: =IF(I14<>"",K14+I14+L14,0) -> 0
A15: =M15 -> 0 | B15: =IF(H15>$H$2,"",(ROW()-5)) | H15: 10 | I15: =IF(H15<$H$2+1,($I$2-($I$2-1)*(LOG(H15)/LOG($H$2))),"") | J15: =INT(LOG($H$2,2))-ROUNDUP(LOG(H15,2),0)+IF(OR($H$2=1,$H$2=2,$H$2=4,$H$2=8,$H$2=16,$H$2=32,$H$2=64,$H$2=128,$H$2=256),0,1) -> -1 | K15: =J15*$J$2 -> -10 | M15: =IF(I15<>"",K15+I15+L15,0) -> 0
A16: =M16 -> 0 | B16: =IF(H16>$H$2,"",(ROW()-5)) | H16: 11 | I16: =IF(H16<$H$2+1,($I$2-($I$2-1)*(LOG(H16)/LOG($H$2))),"") | J16: =INT(LOG($H$2,2))-ROUNDUP(LOG(H16,2),0)+IF(OR($H$2=1,$H$2=2,$H$2=4,$H$2=8,$H$2=16,$H$2=32,$H$2=64,$H$2=128,$H$2=256),0,1) -> -1 | K16: =J16*$J$2 -> -10 | M16: =IF(I16<>"",K16+I16+L16,0) -> 0
A17: =M17 -> 0 | B17: =IF(H17>$H$2,"",(ROW()-5)) | H17: 12 | I17: =IF(H17<$H$2+1,($I$2-($I$2-1)*(LOG(H17)/LOG($H$2))),"") | J17: =INT(LOG($H$2,2))-ROUNDUP(LOG(H17,2),0)+IF(OR($H$2=1,$H$2=2,$H$2=4,$H$2=8,$H$2=16,$H$2=32,$H$2=64,$H$2=128,$H$2=256),0,1) -> -1 | K17: =J17*$J$2 -> -10 | M17: =IF(I17<>"",K17+I17+L17,0) -> 0
A18: =M18 -> 0 | B18: =IF(H18>$H$2,"",(ROW()-5)) | H18: 13 | I18: =IF(H18<$H$2+1,($I$2-($I$2-1)*(LOG(H18)/LOG($H$2))),"") | J18: =INT(LOG($H$2,2))-ROUNDUP(LOG(H18,2),0)+IF(OR($H$2=1,$H$2=2,$H$2=4,$H$2=8,$H$2=16,$H$2=32,$H$2=64,$H$2=128,$H$2=256),0,1) -> -1 | K18: =J18*$J$2 -> -10 | M18: =IF(I18<>"",K18+I18+L18,0) -> 0
A19: =M19 -> 0 | B19: =IF(H19>$H$2,"",(ROW()-5)) | H19: 14 | I19: =IF(H19<$H$2+1,($I$2-($I$2-1)*(LOG(H19)/LOG($H$2))),"") | J19: =INT(LOG($H$2,2))-ROUNDUP(LOG(H19,2),0)+IF(OR($H$2=1,$H$2=2,$H$2=4,$H$2=8,$H$2=16,$H$2=32,$H$2=64,$H$2=128,$H$2=256),0,1) -> -1 | K19: =J19*$J$2 -> -10 | M19: =IF(I19<>"",K19+I19+L19,0) -> 0
A20: =M20 -> 0 | B20: =IF(H20>$H$2,"",(ROW()-5)) | H20: 15 | I20: =IF(H20<$H$2+1,($I$2-($I$2-1)*(LOG(H20)/LOG($H$2))),"") | J20: =INT(LOG($H$2,2))-ROUNDUP(LOG(H20,2),0)+IF(OR($H$2=1,$H$2=2,$H$2=4,$H$2=8,$H$2=16,$H$2=32,$H$2=64,$H$2=128,$H$2=256),0,1) -> -1 | K20: =J20*$J$2 -> -10 | M20: =IF(I20<>"",K20+I20+L20,0) -> 0
A21: =M21 -> 0 | B21: =IF(H21>$H$2,"",(ROW()-5)) | H21: 16 | I21: =IF(H21<$H$2+1,($I$2-($I$2-1)*(LOG(H21)/LOG($H$2))),"") | J21: =INT(LOG($H$2,2))-ROUNDUP(LOG(H21,2),0)+IF(OR($H$2=1,$H$2=2,$H$2=4,$H$2=8,$H$2=16,$H$2=32,$H$2=64,$H$2=128,$H$2=256),0,1) -> -1 | K21: =J21*$J$2 -> -10 | M21: =IF(I21<>"",K21+I21+L21,0) -> 0
A22: =M22 -> 0 | B22: =IF(H22>$H$2,"",(ROW()-5)) | H22: 17 | I22: =IF(H22<$H$2+1,($I$2-($I$2-1)*(LOG(H22)/LOG($H$2))),"") | J22: =INT(LOG($H$2,2))-ROUNDUP(LOG(H22,2),0)+IF(OR($H$2=1,$H$2=2,$H$2=4,$H$2=8,$H$2=16,$H$2=32,$H$2=64,$H$2=128,$H$2=256),0,1) -> -2 | K22: =J22*$J$2 -> -20 | M22: =IF(I22<>"",K22+I22+L22,0) -> 0
A23: =M23 -> 0 | B23: =IF(H23>$H$2,"",(ROW()-5)) | H23: 18 | I23: =IF(H23<$H$2+1,($I$2-($I$2-1)*(LOG(H23)/LOG($H$2))),"") | J23: =INT(LOG($H$2,2))-ROUNDUP(LOG(H23,2),0)+IF(OR($H$2=1,$H$2=2,$H$2=4,$H$2=8,$H$2=16,$H$2=32,$H$2=64,$H$2=128,$H$2=256),0,1) -> -2 | K23: =J23*$J$2 -> -20 | M23: =IF(I23<>"",K23+I23+L23,0) -> 0
A24: =M24 -> 0 | B24: =IF(H24>$H$2,"",(ROW()-5)) | H24: 19 | I24: =IF(H24<$H$2+1,($I$2-($I$2-1)*(LOG(H24)/LOG($H$2))),"") | J24: =INT(LOG($H$2,2))-ROUNDUP(LOG(H24,2),0)+IF(OR($H$2=1,$H$2=2,$H$2=4,$H$2=8,$H$2=16,$H$2=32,$H$2=64,$H$2=128,$H$2=256),0,1) -> -2 | K24: =J24*$J$2 -> -20 | M24: =IF(I24<>"",K24+I24+L24,0) -> 0
... A37: =M37 -> 0 | B37: =IF(H37>$H$2,"",(ROW()-5)) | H37: 32 | I37: =IF(H37<$H$2+1,($I$2-($I$2-1)*(LOG(H37)/LOG($H$2))),"") | J37: =INT(LOG($H$2,2))-ROUNDUP(LOG(H37,2),0)+IF(OR($H$2=1,$H$2=2,$H$2=4,$H$2=8,$H$2=16,$H$2=32,$H$2=64,$H$2=128,$H$2=256),0,1) -> -2 | K37: =J37*$J$2 -> -20 | M37: =IF(I37<>"",K37+I37+L37,0) -> 0
B38: =IF(H38>$H$2,"",(ROW()-5)) | H38: 33 | I38: =IF(H38<$H$2+1,($I$2-($I$2-1)*(LOG(H38)/LOG($H$2))),"") | J38: =INT(LOG($H$2,2))-ROUNDUP(LOG(H38,2),0)+IF(OR($H$2=1,$H$2=2,$H$2=4,$H$2=8,$H$2=16,$H$2=32,$H$2=64,$H$2=128,$H$2=256),0,1) -> -3 | K38: =J38*$J$2 -> -30 | M38: =IF(I38<>"",K38+I38+L38,0) -> 0
B39: =IF(H39>$H$2,"",(ROW()-5)) | H39: 34 | I39: =IF(H39<$H$2+1,($I$2-($I$2-1)*(LOG(H39)/LOG($H$2))),"") | J39: =INT(LOG($H$2,2))-ROUNDUP(LOG(H39,2),0)+IF(OR($H$2=1,$H$2=2,$H$2=4,$H$2=8,$H$2=16,$H$2=32,$H$2=64,$H$2=128,$H$2=256),0,1) -> -3 | K39: =J39*$J$2 -> -30 | M39: =IF(I39<>"",K39+I39+L39,0) -> 0
B40: =IF(H40>$H$2,"",(ROW()-5)) | H40: 35 | I40: =IF(H40<$H$2+1,($I$2-($I$2-1)*(LOG(H40)/LOG($H$2))),"") | J40: =INT(LOG($H$2,2))-ROUNDUP(LOG(H40,2),0)+IF(OR($H$2=1,$H$2=2,$H$2=4,$H$2=8,$H$2=16,$H$2=32,$H$2=64,$H$2=128,$H$2=256),0,1) -> -3 | K40: =J40*$J$2 -> -30 | M40: =IF(I40<>"",K40+I40+L40,0) -> 0
B41: =IF(H41>$H$2,"",(ROW()-5)) | H41: 36 | I41: =IF(H41<$H$2+1,($I$2-($I$2-1)*(LOG(H41)/LOG($H$2))),"") | J41: =INT(LOG($H$2,2))-ROUNDUP(LOG(H41,2),0)+IF(OR($H$2=1,$H$2=2,$H$2=4,$H$2=8,$H$2=16,$H$2=32,$H$2=64,$H$2=128,$H$2=256),0,1) -> -3 | K41: =J41*$J$2 -> -30 | M41: =IF(I41<>"",K41+I41+L41,0) -> 0
B42: =IF(H42>$H$2,"",(ROW()-5)) | H42: 37 | I42: =IF(H42<$H$2+1,($I$2-($I$2-1)*(LOG(H42)/LOG($H$2))),"") | J42: =INT(LOG($H$2,2))-ROUNDUP(LOG(H42,2),0)+IF(OR($H$2=1,$H$2=2,$H$2=4,$H$2=8,$H$2=16,$H$2=32,$H$2=64,$H$2=128,$H$2=256),0,1) -> -3 | K42: =J42*$J$2 -> -30 | M42: =IF(I42<>"",K42+I42+L42,0) -> 0
B43: =IF(H43>$H$2,"",(ROW()-5)) | H43: 38 | I43: =IF(H43<$H$2+1,($I$2-($I$2-1)*(LOG(H43)/LOG($H$2))),"") | J43: =INT(LOG($H$2,2))-ROUNDUP(LOG(H43,2),0)+IF(OR($H$2=1,$H$2=2,$H$2=4,$H$2=8,$H$2=16,$H$2=32,$H$2=64,$H$2=128,$H$2=256),0,1) -> -3 | K43: =J43*$J$2 -> -30 | M43: =IF(I43<>"",K43+I43+L43,0) -> 0
B44: =IF(H44>$H$2,"",(ROW()-5)) | H44: 39 | I44: =IF(H44<$H$2+1,($I$2-($I$2-1)*(LOG(H44)/LOG($H$2))),"") | J44: =INT(LOG($H$2,2))-ROUNDUP(LOG(H44,2),0)+IF(OR($H$2=1,$H$2=2,$H$2=4,$H$2=8,$H$2=16,$H$2=32,$H$2=64,$H$2=128,$H$2=256),0,1) -> -3 | K44: =J44*$J$2 -> -30 | M44: =IF(I44<>"",K44+I44+L44,0) -> 0
B45: =IF(H45>$H$2,"",(ROW()-5)) | H45: 40 | I45: =IF(H45<$H$2+1,($I$2-($I$2-1)*(LOG(H45)/LOG($H$2))),"") | J45: =INT(LOG($H$2,2))-ROUNDUP(LOG(H45,2),0)+IF(OR($H$2=1,$H$2=2,$H$2=4,$H$2=8,$H$2=16,$H$2=32,$H$2=64,$H$2=128,$H$2=256),0,1) -> -3 | K45: =J45*$J$2 -> -30 | M45: =IF(I45<>"",K45+I45+L45,0) -> 0
B46: =IF(H46>$H$2,"",(ROW()-5)) | H46: 41 | I46: =IF(H46<$H$2+1,($I$2-($I$2-1)*(LOG(H46)/LOG($H$2))),"") | J46: =INT(LOG($H$2,2))-ROUNDUP(LOG(H46,2),0)+IF(OR($H$2=1,$H$2=2,$H$2=4,$H$2=8,$H$2=16,$H$2=32,$H$2=64,$H$2=128,$H$2=256),0,1) -> -3 | K46: =J46*$J$2 -> -30 | M46: =IF(I46<>"",K46+I46+L46,0) -> 0
B47: =IF(H47>$H$2,"",(ROW()-5)) | H47: 42 | I47: =IF(H47<$H$2+1,($I$2-($I$2-1)*(LOG(H47)/LOG($H$2))),"") | J47: =INT(LOG($H$2,2))-ROUNDUP(LOG(H47,2),0)+IF(OR($H$2=1,$H$2=2,$H$2=4,$H$2=8,$H$2=16,$H$2=32,$H$2=64,$H$2=128,$H$2=256),0,1) -> -3 | K47: =J47*$J$2 -> -30 | M47: =IF(I47<>"",K47+I47+L47,0) -> 0
B48: =IF(H48>$H$2,"",(ROW()-5)) | H48: 43 | I48: =IF(H48<$H$2+1,($I$2-($I$2-1)*(LOG(H48)/LOG($H$2))),"") | J48: =INT(LOG($H$2,2))-ROUNDUP(LOG(H48,2),0)+IF(OR($H$2=1,$H$2=2,$H$2=4,$H$2=8,$H$2=16,$H$2=32,$H$2=64,$H$2=128,$H$2=256),0,1) -> -3 | K48: =J48*$J$2 -> -30 | M48: =IF(I48<>"",K48+I48+L48,0) -> 0
B49: =IF(H49>$H$2,"",(ROW()-5)) | H49: 44 | I49: =IF(H49<$H$2+1,($I$2-($I$2-1)*(LOG(H49)/LOG($H$2))),"") | J49: =INT(LOG($H$2,2))-ROUNDUP(LOG(H49,2),0)+IF(OR($H$2=1,$H$2=2,$H$2=4,$H$2=8,$H$2=16,$H$2=32,$H$2=64,$H$2=128,$H$2=256),0,1) -> -3 | K49: =J49*$J$2 -> -30 | M49: =IF(I49<>"",K49+I49+L49,0) -> 0
... B65: =IF(H65>$H$2,"",(ROW()-5)) | H65: 60 | I65: =IF(H65<$H$2+1,($I$2-($I$2-1)*(LOG(H65)/LOG($H$2))),"") | J65: =INT(LOG($H$2,2))-ROUNDUP(LOG(H65,2),0)+IF(OR($H$2=1,$H$2=2,$H$2=4,$H$2=8,$H$2=16,$H$2=32,$H$2=64,$H$2=128,$H$2=256),0,1) -> -3 | K65: =J65*$J$2 -> -30 | M65: =IF(I65<>"",K65+I65+L65,0) -> 0
H66: 61 | I66: =IF(H66<$H$2+1,($I$2-($I$2-1)*(LOG(H66)/LOG($H$2))),"") | J66: =INT(LOG($H$2,2))-ROUNDUP(LOG(H66,2),0)+IF(OR($H$2=1,$H$2=2,$H$2=4,$H$2=8,$H$2=16,$H$2=32,$H$2=64,$H$2=128,$H$2=256),0,1) -> -3 | K66: =J66*$J$2 -> -30 | M66: =IF(I66<>"",K66+I66+L66,0) -> 0
H67: 62 | I67: =IF(H67<$H$2+1,($I$2-($I$2-1)*(LOG(H67)/LOG($H$2))),"") | J67: =INT(LOG($H$2,2))-ROUNDUP(LOG(H67,2),0)+IF(OR($H$2=1,$H$2=2,$H$2=4,$H$2=8,$H$2=16,$H$2=32,$H$2=64,$H$2=128,$H$2=256),0,1) -> -3 | K67: =J67*$J$2 -> -30 | M67: =IF(I67<>"",K67+I67+L67,0) -> 0
H68: 63 | I68: =IF(H68<$H$2+1,($I$2-($I$2-1)*(LOG(H68)/LOG($H$2))),"") | J68: =INT(LOG($H$2,2))-ROUNDUP(LOG(H68,2),0)+IF(OR($H$2=1,$H$2=2,$H$2=4,$H$2=8,$H$2=16,$H$2=32,$H$2=64,$H$2=128,$H$2=256),0,1) -> -3 | K68: =J68*$J$2 -> -30 | M68: =IF(I68<>"",K68+I68+L68,0) -> 0
...

Sheet GP2
H1: Liczba uczestników: | I1: GP Punkty | J1: Bonus za rundę | K1: Mnożnik za podium
B2: miejsce: | C2: WISŁA | H2: 7 | I2: 50 | J2: 10 | K2: =3*H2^(1/3) -> 5.7387935
B3: data: | C3: 44898
A5: Punkty | B5: Miejsce Place | C5: Nazwisko Imię Name | D5: Klub Club(s) | E5: Okręg Division | F5: Państwo Country | H5: Miejsce | I5: Punkty za miejsce | J5: liczba wygranych walk pucharowych | K5: bonus z rundy pucharowej | L5: punkty za podium | M5: Suma
A6: =M6 -> 97.216381 | B6: =IF(H6>$H$2,"",(ROW()-5)) -> 1 | C6: ATANASSOW Aleksander | D6: AZS AGH KRAKÓW | H6: 1 | I6: =IF(H6<$H$2+1,($I$2-($I$2-1)*(LOG(H6)/LOG($H$2))),"") -> 50 | J6: =INT(LOG($H$2,2))-ROUNDUP(LOG(H6,2),0)+IF(OR($H$2=1,$H$2=2,$H$2=4,$H$2=8,$H$2=16,$H$2=32,$H$2=64,$H$2=128,$H$2=256),0,1) -> 3 | K6: =J6*$J$2 -> 30 | L6: =3*K2 -> 17.216381 | M6: =IF(I6<>"",K6+I6+L6,0) -> 97.216381
A7: =M7 -> 64.023435 | B7: =IF(H7>$H$2,"",(ROW()-5)) -> 2 | C7: KOTERSKI Paweł | D7: AZS WRATISLAVIA WROCLAW | H7: 2 | I7: =IF(H7<$H$2+1,($I$2-($I$2-1)*(LOG(H7)/LOG($H$2))),"") -> 32.545848 | J7: =INT(LOG($H$2,2))-ROUNDUP(LOG(H7,2),0)+IF(OR($H$2=1,$H$2=2,$H$2=4,$H$2=8,$H$2=16,$H$2=32,$H$2=64,$H$2=128,$H$2=256),0,1) -> 2 | K7: =J7*$J$2 -> 20 | L7: =2*K2 -> 11.477587 | M7: =IF(I7<>"",K7+I7+L7,0) -> 64.023435
A8: =M8 -> 38.074617 | B8: =IF(H8>$H$2,"",(ROW()-5)) -> 3 | C8: ZIELIŃSKI Dariusz | D8: PIAST GLIWICE | H8: 3 | I8: =IF(H8<$H$2+1,($I$2-($I$2-1)*(LOG(H8)/LOG($H$2))),"") -> 22.335823 | J8: =INT(LOG($H$2,2))-ROUNDUP(LOG(H8,2),0)+IF(OR($H$2=1,$H$2=2,$H$2=4,$H$2=8,$H$2=16,$H$2=32,$H$2=64,$H$2=128,$H$2=256),0,1) -> 1 | K8: =J8*$J$2 -> 10 | L8: =K2 -> 5.7387935 | M8: =IF(I8<>"",K8+I8+L8,0) -> 38.074617
A9: =M9 -> 25.091696 | B9: =IF(H9>$H$2,"",(ROW()-5)) -> 4 | C9: KOSTRZEWA Ireneusz | D9: KSz WARSZAWIANKA | H9: 4 | I9: =IF(H9<$H$2+1,($I$2-($I$2-1)*(LOG(H9)/LOG($H$2))),"") -> 15.091696 | J9: =INT(LOG($H$2,2))-ROUNDUP(LOG(H9,2),0)+IF(OR($H$2=1,$H$2=2,$H$2=4,$H$2=8,$H$2=16,$H$2=32,$H$2=64,$H$2=128,$H$2=256),0,1) -> 1 | K9: =J9*$J$2 -> 10 | M9: =IF(I9<>"",K9+I9+L9,0) -> 25.091696
A10: =M10 -> 9.4727137 | B10: =IF(H10>$H$2,"",(ROW()-5)) -> 5 | C10: DRAPELLA Maciej | D10: KS AZS AWFIS GDANSK | H10: 5 | I10: =IF(H10<$H$2+1,($I$2-($I$2-1)*(LOG(H10)/LOG($H$2))),"") -> 9.4727137 | J10: =INT(LOG($H$2,2))-ROUNDUP(LOG(H10,2),0)+IF(OR($H$2=1,$H$2=2,$H$2=4,$H$2=8,$H$2=16,$H$2=32,$H$2=64,$H$2=128,$H$2=256),0,1) -> 0 | K10: =J10*$J$2 -> 0 | M10: =IF(I10<>"",K10+I10+L10,0) -> 9.4727137
A11: =M11 -> 4.8816712 | B11: =IF(H11>$H$2,"",(ROW()-5)) -> 6 | C11: NIKALAICHUK Aliaksandr | D11: AZS AWF KRAKÓW | H11: 6 | I11: =IF(H11<$H$2+1,($I$2-($I$2-1)*(LOG(H11)/LOG($H$2))),"") -> 4.8816712 | J11: =INT(LOG($H$2,2))-ROUNDUP(LOG(H11,2),0)+IF(OR($H$2=1,$H$2=2,$H$2=4,$H$2=8,$H$2=16,$H$2=32,$H$2=64,$H$2=128,$H$2=256),0,1) -> 0 | K11: =J11*$J$2 -> 0 | M11: =IF(I11<>"",K11+I11+L11,0) -> 4.8816712
A12: =M12 -> 1 | B12: =IF(H12>$H$2,"",(ROW()-5)) -> 7 | C12: WIERZBICKI Jacek | D12: AZS POLITECHNIKA OPOLSKA | H12: 7 | I12: =IF(H12<$H$2+1,($I$2-($I$2-1)*(LOG(H12)/LOG($H$2))),"") -> 1 | J12: =INT(LOG($H$2,2))-ROUNDUP(LOG(H12,2),0)+IF(OR($H$2=1,$H$2=2,$H$2=4,$H$2=8,$H$2=16,$H$2=32,$H$2=64,$H$2=128,$H$2=256),0,1) -> 0 | K12: =J12*$J$2 -> 0 | M12: =IF(I12<>"",K12+I12+L12,0) -> 1
A13: =M13 -> 0 | B13: =IF(H13>$H$2,"",(ROW()-5)) | H13: 8 | I13: =IF(H13<$H$2+1,($I$2-($I$2-1)*(LOG(H13)/LOG($H$2))),"") | J13: =INT(LOG($H$2,2))-ROUNDUP(LOG(H13,2),0)+IF(OR($H$2=1,$H$2=2,$H$2=4,$H$2=8,$H$2=16,$H$2=32,$H$2=64,$H$2=128,$H$2=256),0,1) -> 0 | K13: =J13*$J$2 -> 0 | M13: =IF(I13<>"",K13+I13+L13,0) -> 0
A14: =M14 -> 0 | B14: =IF(H14>$H$2,"",(ROW()-5)) | H14: 9 | I14: =IF(H14<$H$2+1,($I$2-($I$2-1)*(LOG(H14)/LOG($H$2))),"") | J14: =INT(LOG($H$2,2))-ROUNDUP(LOG(H14,2),0)+IF(OR($H$2=1,$H$2=2,$H$2=4,$H$2=8,$H$2=16,$H$2=32,$H$2=64,$H$2=128,$H$2=256),0,1) -> -1 | K14: =J14*$J$2 -> -10 | M14: =IF(I14<>"",K14+I14+L14,0) -> 0
A15: =M15 -> 0 | B15: =IF(H15>$H$2,"",(ROW()-5)) | H15: 10 | I15: =IF(H15<$H$2+1,($I$2-($I$2-1)*(LOG(H15)/LOG($H$2))),"") | J15: =INT(LOG($H$2,2))-ROUNDUP(LOG(H15,2),0)+IF(OR($H$2=1,$H$2=2,$H$2=4,$H$2=8,$H$2=16,$H$2=32,$H$2=64,$H$2=128,$H$2=256),0,1) -> -1 | K15: =J15*$J$2 -> -10 | M15: =IF(I15<>"",K15+I15+L15,0) -> 0
A16: =M16 -> 0 | B16: =IF(H16>$H$2,"",(ROW()-5)) | H16: 11 | I16: =IF(H16<$H$2+1,($I$2-($I$2-1)*(LOG(H16)/LOG($H$2))),"") | J16: =INT(LOG($H$2,2))-ROUNDUP(LOG(H16,2),0)+IF(OR($H$2=1,$H$2=2,$H$2=4,$H$2=8,$H$2=16,$H$2=32,$H$2=64,$H$2=128,$H$2=256),0,1) -> -1 | K16: =J16*$J$2 -> -10 | M16: =IF(I16<>"",K16+I16+L16,0) -> 0
A17: =M17 -> 0 | B17: =IF(H17>$H$2,"",(ROW()-5)) | H17: 12 | I17: =IF(H17<$H$2+1,($I$2-($I$2-1)*(LOG(H17)/LOG($H$2))),"") | J17: =INT(LOG($H$2,2))-ROUNDUP(LOG(H17,2),0)+IF(OR($H$2=1,$H$2=2,$H$2=4,$H$2=8,$H$2=16,$H$2=32,$H$2=64,$H$2=128,$H$2=256),0,1) -> -1 | K17: =J17*$J$2 -> -10 | M17: =IF(I17<>"",K17+I17+L17,0) -> 0
A18: =M18 -> 0 | B18: =IF(H18>$H$2,"",(ROW()-5)) | H18: 13 | I18: =IF(H18<$H$2+1,($I$2-($I$2-1)*(LOG(H18)/LOG($H$2))),"") | J18: =INT(LOG($H$2,2))-ROUNDUP(LOG(H18,2),0)+IF(OR($H$2=1,$H$2=2,$H$2=4,$H$2=8,$H$2=16,$H$2=32,$H$2=64,$H$2=128,$H$2=256),0,1) -> -1 | K18: =J18*$J$2 -> -10 | M18: =IF(I18<>"",K18+I18+L18,0) -> 0
A19: =M19 -> 0 | B19: =IF(H19>$H$2,"",(ROW()-5)) | H19: 14 | I19: =IF(H19<$H$2+1,($I$2-($I$2-1)*(LOG(H19)/LOG($H$2))),"") | J19: =INT(LOG($H$2,2))-ROUNDUP(LOG(H19,2),0)+IF(OR($H$2=1,$H$2=2,$H$2=4,$H$2=8,$H$2=16,$H$2=32,$H$2=64,$H$2=128,$H$2=256),0,1) -> -1 | K19: =J19*$J$2 -> -10 | M19: =IF(I19<>"",K19+I19+L19,0) -> 0
A20: =M20 -> 0 | B20: =IF(H20>$H$2,"",(ROW()-5)) | H20: 15 | I20: =IF(H20<$H$2+1,($I$2-($I$2-1)*(LOG(H20)/LOG($H$2))),"") | J20: =INT(LOG($H$2,2))-ROUNDUP(LOG(H20,2),0)+IF(OR($H$2=1,$H$2=2,$H$2=4,$H$2=8,$H$2=16,$H$2=32,$H$2=64,$H$2=128,$H$2=256),0,1) -> -1 | K20: =J20*$J$2 -> -10 | M20: =IF(I20<>"",K20+I20+L20,0) -> 0
A21: =M21 -> 0 | B21: =IF(H21>$H$2,"",(ROW()-5)) | H21: 16 | I21: =IF(H21<$H$2+1,($I$2-($I$2-1)*(LOG(H21)/LOG($H$2))),"") | J21: =INT(LOG($H$2,2))-ROUNDUP(LOG(H21,2),0)+IF(OR($H$2=1,$H$2=2,$H$2=4,$H$2=8,$H$2=16,$H$2=32,$H$2=64,$H$2=128,$H$2=256),0,1) -> -1 | K21: =J21*$J$2 -> -10 | M21: =IF(I21<>"",K21+I21+L21,0) -> 0
A22: =M22 -> 0 | B22: =IF(H22>$H$2,"",(ROW()-5)) | H22: 17 | I22: =IF(H22<$H$2+1,($I$2-($I$2-1)*(LOG(H22)/LOG($H$2))),"") | J22: =INT(LOG($H$2,2))-ROUNDUP(LOG(H22,2),0)+IF(OR($H$2=1,$H$2=2,$H$2=4,$H$2=8,$H$2=16,$H$2=32,$H$2=64,$H$2=128,$H$2=256),0,1) -> -2 | K22: =J22*$J$2 -> -20 | M22: =IF(I22<>"",K22+I22+L22,0) -> 0
A23: =M23 -> 0 | B23: =IF(H23>$H$2,"",(ROW()-5)) | H23: 18 | I23: =IF(H23<$H$2+1,($I$2-($I$2-1)*(LOG(H23)/LOG($H$2))),"") | J23: =INT(LOG($H$2,2))-ROUNDUP(LOG(H23,2),0)+IF(OR($H$2=1,$H$2=2,$H$2=4,$H$2=8,$H$2=16,$H$2=32,$H$2=64,$H$2=128,$H$2=256),0,1) -> -2 | K23: =J23*$J$2 -> -20 | M23: =IF(I23<>"",K23+I23+L23,0) -> 0
A24: =M24 -> 0 | B24: =IF(H24>$H$2,"",(ROW()-5)) | H24: 19 | I24: =IF(H24<$H$2+1,($I$2-($I$2-1)*(LOG(H24)/LOG($H$2))),"") | J24: =INT(LOG($H$2,2))-ROUNDUP(LOG(H24,2),0)+IF(OR($H$2=1,$H$2=2,$H$2=4,$H$2=8,$H$2=16,$H$2=32,$H$2=64,$H$2=128,$H$2=256),0,1) -> -2 | K24: =J24*$J$2 -> -20 | M24: =IF(I24<>"",K24+I24+L24,0) -> 0
... A37: =M37 -> 0 | B37: =IF(H37>$H$2,"",(ROW()-5)) | H37: 32 | I37: =IF(H37<$H$2+1,($I$2-($I$2-1)*(LOG(H37)/LOG($H$2))),"") | J37: =INT(LOG($H$2,2))-ROUNDUP(LOG(H37,2),0)+IF(OR($H$2=1,$H$2=2,$H$2=4,$H$2=8,$H$2=16,$H$2=32,$H$2=64,$H$2=128,$H$2=256),0,1) -> -2 | K37: =J37*$J$2 -> -20 | M37: =IF(I37<>"",K37+I37+L37,0) -> 0
B38: =IF(H38>$H$2,"",(ROW()-5)) | H38: 33 | I38: =IF(H38<$H$2+1,($I$2-($I$2-1)*(LOG(H38)/LOG($H$2))),"") | J38: =INT(LOG($H$2,2))-ROUNDUP(LOG(H38,2),0)+IF(OR($H$2=1,$H$2=2,$H$2=4,$H$2=8,$H$2=16,$H$2=32,$H$2=64,$H$2=128,$H$2=256),0,1) -> -3 | K38: =J38*$J$2 -> -30 | M38: =IF(I38<>"",K38+I38+L38,0) -> 0
B39: =IF(H39>$H$2,"",(ROW()-5)) | H39: 34 | I39: =IF(H39<$H$2+1,($I$2-($I$2-1)*(LOG(H39)/LOG($H$2))),"") | J39: =INT(LOG($H$2,2))-ROUNDUP(LOG(H39,2),0)+IF(OR($H$2=1,$H$2=2,$H$2=4,$H$2=8,$H$2=16,$H$2=32,$H$2=64,$H$2=128,$H$2=256),0,1) -> -3 | K39: =J39*$J$2 -> -30 | M39: =IF(I39<>"",K39+I39+L39,0) -> 0
B40: =IF(H40>$H$2,"",(ROW()-5)) | H40: 35 | I40: =IF(H40<$H$2+1,($I$2-($I$2-1)*(LOG(H40)/LOG($H$2))),"") | J40: =INT(LOG($H$2,2))-ROUNDUP(LOG(H40,2),0)+IF(OR($H$2=1,$H$2=2,$H$2=4,$H$2=8,$H$2=16,$H$2=32,$H$2=64,$H$2=128,$H$2=256),0,1) -> -3 | K40: =J40*$J$2 -> -30 | M40: =IF(I40<>"",K40+I40+L40,0) -> 0
B41: =IF(H41>$H$2,"",(ROW()-5)) | H41: 36 | I41: =IF(H41<$H$2+1,($I$2-($I$2-1)*(LOG(H41)/LOG($H$2))),"") | J41: =INT(LOG($H$2,2))-ROUNDUP(LOG(H41,2),0)+IF(OR($H$2=1,$H$2=2,$H$2=4,$H$2=8,$H$2=16,$H$2=32,$H$2=64,$H$2=128,$H$2=256),0,1) -> -3 | K41: =J41*$J$2 -> -30 | M41: =IF(I41<>"",K41+I41+L41,0) -> 0
B42: =IF(H42>$H$2,"",(ROW()-5)) | H42: 37 | I42: =IF(H42<$H$2+1,($I$2-($I$2-1)*(LOG(H42)/LOG($H$2))),"") | J42: =INT(LOG($H$2,2))-ROUNDUP(LOG(H42,2),0)+IF(OR($H$2=1,$H$2=2,$H$2=4,$H$2=8,$H$2=16,$H$2=32,$H$2=64,$H$2=128,$H$2=256),0,1) -> -3 | K42: =J42*$J$2 -> -30 | M42: =IF(I42<>"",K42+I42+L42,0) -> 0
B43: =IF(H43>$H$2,"",(ROW()-5)) | H43: 38 | I43: =IF(H43<$H$2+1,($I$2-($I$2-1)*(LOG(H43)/LOG($H$2))),"") | J43: =INT(LOG($H$2,2))-ROUNDUP(LOG(H43,2),0)+IF(OR($H$2=1,$H$2=2,$H$2=4,$H$2=8,$H$2=16,$H$2=32,$H$2=64,$H$2=128,$H$2=256),0,1) -> -3 | K43: =J43*$J$2 -> -30 | M43: =IF(I43<>"",K43+I43+L43,0) -> 0
B44: =IF(H44>$H$2,"",(ROW()-5)) | H44: 39 | I44: =IF(H44<$H$2+1,($I$2-($I$2-1)*(LOG(H44)/LOG($H$2))),"") | J44: =INT(LOG($H$2,2))-ROUNDUP(LOG(H44,2),0)+IF(OR($H$2=1,$H$2=2,$H$2=4,$H$2=8,$H$2=16,$H$2=32,$H$2=64,$H$2=128,$H$2=256),0,1) -> -3 | K44: =J44*$J$2 -> -30 | M44: =IF(I44<>"",K44+I44+L44,0) -> 0
B45: =IF(H45>$H$2,"",(ROW()-5)) | H45: 40 | I45: =IF(H45<$H$2+1,($I$2-($I$2-1)*(LOG(H45)/LOG($H$2))),"") | J45: =INT(LOG($H$2,2))-ROUNDUP(LOG(H45,2),0)+IF(OR($H$2=1,$H$2=2,$H$2=4,$H$2=8,$H$2=16,$H$2=32,$H$2=64,$H$2=128,$H$2=256),0,1) -> -3 | K45: =J45*$J$2 -> -30 | M45: =IF(I45<>"",K45+I45+L45,0) -> 0
B46: =IF(H46>$H$2,"",(ROW()-5)) | H46: 41 | I46: =IF(H46<$H$2+1,($I$2-($I$2-1)*(LOG(H46)/LOG($H$2))),"") | J46: =INT(LOG($H$2,2))-ROUNDUP(LOG(H46,2),0)+IF(OR($H$2=1,$H$2=2,$H$2=4,$H$2=8,$H$2=16,$H$2=32,$H$2=64,$H$2=128,$H$2=256),0,1) -> -3 | K46: =J46*$J$2 -> -30 | M46: =IF(I46<>"",K46+I46+L46,0) -> 0
B47: =IF(H47>$H$2,"",(ROW()-5)) | H47: 42 | I47: =IF(H47<$H$2+1,($I$2-($I$2-1)*(LOG(H47)/LOG($H$2))),"") | J47: =INT(LOG($H$2,2))-ROUNDUP(LOG(H47,2),0)+IF(OR($H$2=1,$H$2=2,$H$2=4,$H$2=8,$H$2=16,$H$2=32,$H$2=64,$H$2=128,$H$2=256),0,1) -> -3 | K47: =J47*$J$2 -> -30 | M47: =IF(I47<>"",K47+I47+L47,0) -> 0
B48: =IF(H48>$H$2,"",(ROW()-5)) | H48: 43 | I48: =IF(H48<$H$2+1,($I$2-($I$2-1)*(LOG(H48)/LOG($H$2))),"") | J48: =INT(LOG($H$2,2))-ROUNDUP(LOG(H48,2),0)+IF(OR($H$2=1,$H$2=2,$H$2=4,$H$2=8,$H$2=16,$H$2=32,$H$2=64,$H$2=128,$H$2=256),0,1) -> -3 | K48: =J48*$J$2 -> -30 | M48: =IF(I48<>"",K48+I48+L48,0) -> 0
B49: =IF(H49>$H$2,"",(ROW()-5)) | H49: 44 | I49: =IF(H49<$H$2+1,($I$2-($I$2-1)*(LOG(H49)/LOG($H$2))),"") | J49: =INT(LOG($H$2,2))-ROUNDUP(LOG(H49,2),0)+IF(OR($H$2=1,$H$2=2,$H$2=4,$H$2=8,$H$2=16,$H$2=32,$H$2=64,$H$2=128,$H$2=256),0,1) -> -3 | K49: =J49*$J$2 -> -30 | M49: =IF(I49<>"",K49+I49+L49,0) -> 0
... B65: =IF(H65>$H$2,"",(ROW()-5)) | H65: 60 | I65: =IF(H65<$H$2+1,($I$2-($I$2-1)*(LOG(H65)/LOG($H$2))),"") | J65: =INT(LOG($H$2,2))-ROUNDUP(LOG(H65,2),0)+IF(OR($H$2=1,$H$2=2,$H$2=4,$H$2=8,$H$2=16,$H$2=32,$H$2=64,$H$2=128,$H$2=256),0,1) -> -3 | K65: =J65*$J$2 -> -30 | M65: =IF(I65<>"",K65+I65+L65,0) -> 0
H66: 61 | I66: =IF(H66<$H$2+1,($I$2-($I$2-1)*(LOG(H66)/LOG($H$2))),"") | J66: =INT(LOG($H$2,2))-ROUNDUP(LOG(H66,2),0)+IF(OR($H$2=1,$H$2=2,$H$2=4,$H$2=8,$H$2=16,$H$2=32,$H$2=64,$H$2=128,$H$2=256),0,1) -> -3 | K66: =J66*$J$2 -> -30 | M66: =IF(I66<>"",K66+I66+L66,0) -> 0
H67: 62 | I67: =IF(H67<$H$2+1,($I$2-($I$2-1)*(LOG(H67)/LOG($H$2))),"") | J67: =INT(LOG($H$2,2))-ROUNDUP(LOG(H67,2),0)+IF(OR($H$2=1,$H$2=2,$H$2=4,$H$2=8,$H$2=16,$H$2=32,$H$2=64,$H$2=128,$H$2=256),0,1) -> -3 | K67: =J67*$J$2 -> -30 | M67: =IF(I67<>"",K67+I67+L67,0) -> 0
H68: 63 | I68: =IF(H68<$H$2+1,($I$2-($I$2-1)*(LOG(H68)/LOG($H$2))),"") | J68: =INT(LOG($H$2,2))-ROUNDUP(LOG(H68,2),0)+IF(OR($H$2=1,$H$2=2,$H$2=4,$H$2=8,$H$2=16,$H$2=32,$H$2=64,$H$2=128,$H$2=256),0,1) -> -3 | K68: =J68*$J$2 -> -30 | M68: =IF(I68<>"",K68+I68+L68,0) -> 0
...

Sheet GP3
H1: Liczba uczestników: | I1: GP Punkty | J1: Bonus za rundę | K1: Mnożnik za podium
B2: miejsce: | C2: NIEPOŁOMICE | H2: 8 | I2: 50 | J2: 10 | K2: =3*H2^(1/3) -> 6
B3: data: | C3: 18/06/2022
A5: Punkty | B5: Miejsce Place | C5: Nazwisko Imię Name | D5: Klub Club(s) | E5: Okręg Division | F5: Państwo Country | H5: Miejsce | I5: Punkty za miejsce | J5: liczba wygranych walk pucharowych | K5: bonus z rundy pucharowej | L5: punkty za podium | M5: Suma
A6: =M6 -> 98 | B6: 1 | C6: ATANASSOW Aleksander | D6: KS CRACOVIA 1906. | E6: POL | H6: 1 | I6: =IF(H6<$H$2+1,($I$2-($I$2-1)*(LOG(H6)/LOG($H$2))),"") -> 50 | J6: =INT(LOG($H$2,2))-ROUNDUP(LOG(H6,2),0)+IF(OR($H$2=1,$H$2=2,$H$2=4,$H$2=8,$H$2=16,$H$2=32,$H$2=64,$H$2=128,$H$2=256),0,1) -> 3 | K6: =J6*$J$2 -> 30 | L6: =3*K2 -> 18 | M6: =IF(I6<>"",K6+I6+L6,0) -> 98
A7: =M7 -> 65.666667 | B7: 2 | C7: ZIELIŃSKI Dariusz | D7: PIAST GLIWICE | E7: POL | H7: 2 | I7: =IF(H7<$H$2+1,($I$2-($I$2-1)*(LOG(H7)/LOG($H$2))),"") -> 33.666667 | J7: =INT(LOG($H$2,2))-ROUNDUP(LOG(H7,2),0)+IF(OR($H$2=1,$H$2=2,$H$2=4,$H$2=8,$H$2=16,$H$2=32,$H$2=64,$H$2=128,$H$2=256),0,1) -> 2 | K7: =J7*$J$2 -> 20 | L7: =2*K2 -> 12 | M7: =IF(I7<>"",K7+I7+L7,0) -> 65.666667
A8: =M8 -> 40.112279 | B8: 3 | C8: KOSTRZEWA Ireneusz | D8: KSz WARSZAWIANKA | E8: POL | H8: 3 | I8: =IF(H8<$H$2+1,($I$2-($I$2-1)*(LOG(H8)/LOG($H$2))),"") -> 24.112279 | J8: =INT(LOG($H$2,2))-ROUNDUP(LOG(H8,2),0)+IF(OR($H$2=1,$H$2=2,$H$2=4,$H$2=8,$H$2=16,$H$2=32,$H$2=64,$H$2=128,$H$2=256),0,1) -> 1 | K8: =J8*$J$2 -> 10 | L8: =K2 -> 6 | M8: =IF(I8<>"",K8+I8+L8,0) -> 40.112279
A9: =M9 -> 27.333333 | B9: 4 | C9: WOJTAS Bogdan | E9: POL | H9: 4 | I9: =IF(H9<$H$2+1,($I$2-($I$2-1)*(LOG(H9)/LOG($H$2))),"") -> 17.333333 | J9: =INT(LOG($H$2,2))-ROUNDUP(LOG(H9,2),0)+IF(OR($H$2=1,$H$2=2,$H$2=4,$H$2=8,$H$2=16,$H$2=32,$H$2=64,$H$2=128,$H$2=256),0,1) -> 1 | K9: =J9*$J$2 -> 10 | M9: =IF(I9<>"",K9+I9+L9,0) -> 27.333333
A10: =M10 -> 12.075174 | B10: 5 | C10: DRAPELLA Maciej | D10: KS AZS AWFIS GDAŃSK. | E10: POL | H10: 5 | I10: =IF(H10<$H$2+1,($I$2-($I$2-1)*(LOG(H10)/LOG($H$2))),"") -> 12.075174 | J10: =INT(LOG($H$2,2))-ROUNDUP(LOG(H10,2),0)+IF(OR($H$2=1,$H$2=2,$H$2=4,$H$2=8,$H$2=16,$H$2=32,$H$2=64,$H$2=128,$H$2=256),0,1) -> 0 | K10: =J10*$J$2 -> 0 | M10: =IF(I10<>"",K10+I10+L10,0) -> 12.075174
A11: =M11 -> 7.7789458 | B11: 6 | C11: SKOCZEK Artur | E11: POL | H11: 6 | I11: =IF(H11<$H$2+1,($I$2-($I$2-1)*(LOG(H11)/LOG($H$2))),"") -> 7.7789458 | J11: =INT(LOG($H$2,2))-ROUNDUP(LOG(H11,2),0)+IF(OR($H$2=1,$H$2=2,$H$2=4,$H$2=8,$H$2=16,$H$2=32,$H$2=64,$H$2=128,$H$2=256),0,1) -> 0 | K11: =J11*$J$2 -> 0 | M11: =IF(I11<>"",K11+I11+L11,0) -> 7.7789458
A12: =M12 -> 4.1465363 | B12: 7 | C12: PARDUS Borys | D12: AKADEMIA SZERMIERKI W-WA | E12: POL | H12: 7 | I12: =IF(H12<$H$2+1,($I$2-($I$2-1)*(LOG(H12)/LOG($H$2))),"") -> 4.1465363 | J12: =INT(LOG($H$2,2))-ROUNDUP(LOG(H12,2),0)+IF(OR($H$2=1,$H$2=2,$H$2=4,$H$2=8,$H$2=16,$H$2=32,$H$2=64,$H$2=128,$H$2=256),0,1) -> 0 | K12: =J12*$J$2 -> 0 | M12: =IF(I12<>"",K12+I12+L12,0) -> 4.1465363
A13: =M13 -> 1 | B13: 8 | C13: WIERZBICKI Jacek | D13: AZS KU POLITECHNIKI OPOLSKIEJ | E13: POL | H13: 8 | I13: =IF(H13<$H$2+1,($I$2-($I$2-1)*(LOG(H13)/LOG($H$2))),"") -> 1 | J13: =INT(LOG($H$2,2))-ROUNDUP(LOG(H13,2),0)+IF(OR($H$2=1,$H$2=2,$H$2=4,$H$2=8,$H$2=16,$H$2=32,$H$2=64,$H$2=128,$H$2=256),0,1) -> 0 | K13: =J13*$J$2 -> 0 | M13: =IF(I13<>"",K13+I13+L13,0) -> 1
A14: =M14 -> 0 | B14: =IF(H14>$H$2,"",(ROW()-5)) | H14: 9 | I14: =IF(H14<$H$2+1,($I$2-($I$2-1)*(LOG(H14)/LOG($H$2))),"") | J14: =INT(LOG($H$2,2))-ROUNDUP(LOG(H14,2),0)+IF(OR($H$2=1,$H$2=2,$H$2=4,$H$2=8,$H$2=16,$H$2=32,$H$2=64,$H$2=128,$H$2=256),0,1) -> -1 | K14: =J14*$J$2 -> -10 | M14: =IF(I14<>"",K14+I14+L14,0) -> 0
A15: =M15 -> 0 | B15: =IF(H15>$H$2,"",(ROW()-5)) | H15: 10 | I15: =IF(H15<$H$2+1,($I$2-($I$2-1)*(LOG(H15)/LOG($H$2))),"") | J15: =INT(LOG($H$2,2))-ROUNDUP(LOG(H15,2),0)+IF(OR($H$2=1,$H$2=2,$H$2=4,$H$2=8,$H$2=16,$H$2=32,$H$2=64,$H$2=128,$H$2=256),0,1) -> -1 | K15: =J15*$J$2 -> -10 | M15: =IF(I15<>"",K15+I15+L15,0) -> 0
A16: =M16 -> 0 | B16: =IF(H16>$H$2,"",(ROW()-5)) | H16: 11 | I16: =IF(H16<$H$2+1,($I$2-($I$2-1)*(LOG(H16)/LOG($H$2))),"") | J16: =INT(LOG($H$2,2))-ROUNDUP(LOG(H16,2),0)+IF(OR($H$2=1,$H$2=2,$H$2=4,$H$2=8,$H$2=16,$H$2=32,$H$2=64,$H$2=128,$H$2=256),0,1) -> -1 | K16: =J16*$J$2 -> -10 | M16: =IF(I16<>"",K16+I16+L16,0) -> 0
A17: =M17 -> 0 | B17: =IF(H17>$H$2,"",(ROW()-5)) | H17: 12 | I17: =IF(H17<$H$2+1,($I$2-($I$2-1)*(LOG(H17)/LOG($H$2))),"") | J17: =INT(LOG($H$2,2))-ROUNDUP(LOG(H17,2),0)+IF(OR($H$2=1,$H$2=2,$H$2=4,$H$2=8,$H$2=16,$H$2=32,$H$2=64,$H$2=128,$H$2=256),0,1) -> -1 | K17: =J17*$J$2 -> -10 | M17: =IF(I17<>"",K17+I17+L17,0) -> 0
A18: =M18 -> 0 | B18: =IF(H18>$H$2,"",(ROW()-5)) | H18: 13 | I18: =IF(H18<$H$2+1,($I$2-($I$2-1)*(LOG(H18)/LOG($H$2))),"") | J18: =INT(LOG($H$2,2))-ROUNDUP(LOG(H18,2),0)+IF(OR($H$2=1,$H$2=2,$H$2=4,$H$2=8,$H$2=16,$H$2=32,$H$2=64,$H$2=128,$H$2=256),0,1) -> -1 | K18: =J18*$J$2 -> -10 | M18: =IF(I18<>"",K18+I18+L18,0) -> 0
A19: =M19 -> 0 | B19: =IF(H19>$H$2,"",(ROW()-5)) | H19: 14 | I19: =IF(H19<$H$2+1,($I$2-($I$2-1)*(LOG(H19)/LOG($H$2))),"") | J19: =INT(LOG($H$2,2))-ROUNDUP(LOG(H19,2),0)+IF(OR($H$2=1,$H$2=2,$H$2=4,$H$2=8,$H$2=16,$H$2=32,$H$2=64,$H$2=128,$H$2=256),0,1) -> -1 | K19: =J19*$J$2 -> -10 | M19: =IF(I19<>"",K19+I19+L19,0) -> 0
A20: =M20 -> 0 | B20: =IF(H20>$H$2,"",(ROW()-5)) | H20: 15 | I20: =IF(H20<$H$2+1,($I$2-($I$2-1)*(LOG(H20)/LOG($H$2))),"") | J20: =INT(LOG($H$2,2))-ROUNDUP(LOG(H20,2),0)+IF(OR($H$2=1,$H$2=2,$H$2=4,$H$2=8,$H$2=16,$H$2=32,$H$2=64,$H$2=128,$H$2=256),0,1) -> -1 | K20: =J20*$J$2 -> -10 | M20: =IF(I20<>"",K20+I20+L20,0) -> 0
A21: =M21 -> 0 | B21: =IF(H21>$H$2,"",(ROW()-5)) | H21: 16 | I21: =IF(H21<$H$2+1,($I$2-($I$2-1)*(LOG(H21)/LOG($H$2))),"") | J21: =INT(LOG($H$2,2))-ROUNDUP(LOG(H21,2),0)+IF(OR($H$2=1,$H$2=2,$H$2=4,$H$2=8,$H$2=16,$H$2=32,$H$2=64,$H$2=128,$H$2=256),0,1) -> -1 | K21: =J21*$J$2 -> -10 | M21: =IF(I21<>"",K21+I21+L21,0) -> 0
A22: =M22 -> 0 | B22: =IF(H22>$H$2,"",(ROW()-5)) | H22: 17 | I22: =IF(H22<$H$2+1,($I$2-($I$2-1)*(LOG(H22)/LOG($H$2))),"") | J22: =INT(LOG($H$2,2))-ROUNDUP(LOG(H22,2),0)+IF(OR($H$2=1,$H$2=2,$H$2=4,$H$2=8,$H$2=16,$H$2=32,$H$2=64,$H$2=128,$H$2=256),0,1) -> -2 | K22: =J22*$J$2 -> -20 | M22: =IF(I22<>"",K22+I22+L22,0) -> 0
A23: =M23 -> 0 | B23: =IF(H23>$H$2,"",(ROW()-5)) | H23: 18 | I23: =IF(H23<$H$2+1,($I$2-($I$2-1)*(LOG(H23)/LOG($H$2))),"") | J23: =INT(LOG($H$2,2))-ROUNDUP(LOG(H23,2),0)+IF(OR($H$2=1,$H$2=2,$H$2=4,$H$2=8,$H$2=16,$H$2=32,$H$2=64,$H$2=128,$H$2=256),0,1) -> -2 | K23: =J23*$J$2 -> -20 | M23: =IF(I23<>"",K23+I23+L23,0) -> 0
A24: =M24 -> 0 | B24: =IF(H24>$H$2,"",(ROW()-5)) | H24: 19 | I24: =IF(H24<$H$2+1,($I$2-($I$2-1)*(LOG(H24)/LOG($H$2))),"") | J24: =INT(LOG($H$2,2))-ROUNDUP(LOG(H24,2),0)+IF(OR($H$2=1,$H$2=2,$H$2=4,$H$2=8,$H$2=16,$H$2=32,$H$2=64,$H$2=128,$H$2=256),0,1) -> -2 | K24: =J24*$J$2 -> -20 | M24: =IF(I24<>"",K24+I24+L24,0) -> 0
A25: =M25 -> 0 | B25: =IF(H25>$H$2,"",(ROW()-5)) | H25: 20 | I25: =IF(H25<$H$2+1,($I$2-($I$2-1)*(LOG(H25)/LOG($H$2))),"") | J25: =INT(LOG($H$2,2))-ROUNDUP(LOG(H25,2),0)+IF(OR($H$2=1,$H$2=2,$H$2=4,$H$2=8,$H$2=16,$H$2=32,$H$2=64,$H$2=128,$H$2=256),0,1) -> -2 | K25: =J25*$J$2 -> -20 | M25: =IF(I25<>"",K25+I25+L25,0) -> 0
... A37: =M37 -> 0 | B37: =IF(H37>$H$2,"",(ROW()-5)) | H37: 32 | I37: =IF(H37<$H$2+1,($I$2-($I$2-1)*(LOG(H37)/LOG($H$2))),"") | J37: =INT(LOG($H$2,2))-ROUNDUP(LOG(H37,2),0)+IF(OR($H$2=1,$H$2=2,$H$2=4,$H$2=8,$H$2=16,$H$2=32,$H$2=64,$H$2=128,$H$2=256),0,1) -> -2 | K37: =J37*$J$2 -> -20 | M37: =IF(I37<>"",K37+I37+L37,0) -> 0
B38: =IF(H38>$H$2,"",(ROW()-5)) | H38: 33 | I38: =IF(H38<$H$2+1,($I$2-($I$2-1)*(LOG(H38)/LOG($H$2))),"") | J38: =INT(LOG($H$2,2))-ROUNDUP(LOG(H38,2),0)+IF(OR($H$2=1,$H$2=2,$H$2=4,$H$2=8,$H$2=16,$H$2=32,$H$2=64,$H$2=128,$H$2=256),0,1) -> -3 | K38: =J38*$J$2 -> -30 | M38: =IF(I38<>"",K38+I38+L38,0) -> 0
B39: =IF(H39>$H$2,"",(ROW()-5)) | H39: 34 | I39: =IF(H39<$H$2+1,($I$2-($I$2-1)*(LOG(H39)/LOG($H$2))),"") | J39: =INT(LOG($H$2,2))-ROUNDUP(LOG(H39,2),0)+IF(OR($H$2=1,$H$2=2,$H$2=4,$H$2=8,$H$2=16,$H$2=32,$H$2=64,$H$2=128,$H$2=256),0,1) -> -3 | K39: =J39*$J$2 -> -30 | M39: =IF(I39<>"",K39+I39+L39,0) -> 0
B40: =IF(H40>$H$2,"",(ROW()-5)) | H40: 35 | I40: =IF(H40<$H$2+1,($I$2-($I$2-1)*(LOG(H40)/LOG($H$2))),"") | J40: =INT(LOG($H$2,2))-ROUNDUP(LOG(H40,2),0)+IF(OR($H$2=1,$H$2=2,$H$2=4,$H$2=8,$H$2=16,$H$2=32,$H$2=64,$H$2=128,$H$2=256),0,1) -> -3 | K40: =J40*$J$2 -> -30 | M40: =IF(I40<>"",K40+I40+L40,0) -> 0
B41: =IF(H41>$H$2,"",(ROW()-5)) | H41: 36 | I41: =IF(H41<$H$2+1,($I$2-($I$2-1)*(LOG(H41)/LOG($H$2))),"") | J41: =INT(LOG($H$2,2))-ROUNDUP(LOG(H41,2),0)+IF(OR($H$2=1,$H$2=2,$H$2=4,$H$2=8,$H$2=16,$H$2=32,$H$2=64,$H$2=128,$H$2=256),0,1) -> -3 | K41: =J41*$J$2 -> -30 | M41: =IF(I41<>"",K41+I41+L41,0) -> 0
B42: =IF(H42>$H$2,"",(ROW()-5)) | H42: 37 | I42: =IF(H42<$H$2+1,($I$2-($I$2-1)*(LOG(H42)/LOG($H$2))),"") | J42: =INT(LOG($H$2,2))-ROUNDUP(LOG(H42,2),0)+IF(OR($H$2=1,$H$2=2,$H$2=4,$H$2=8,$H$2=16,$H$2=32,$H$2=64,$H$2=128,$H$2=256),0,1) -> -3 | K42: =J42*$J$2 -> -30 | M42: =IF(I42<>"",K42+I42+L42,0) -> 0
B43: =IF(H43>$H$2,"",(ROW()-5)) | H43: 38 | I43: =IF(H43<$H$2+1,($I$2-($I$2-1)*(LOG(H43)/LOG($H$2))),"") | J43: =INT(LOG($H$2,2))-ROUNDUP(LOG(H43,2),0)+IF(OR($H$2=1,$H$2=2,$H$2=4,$H$2=8,$H$2=16,$H$2=32,$H$2=64,$H$2=128,$H$2=256),0,1) -> -3 | K43: =J43*$J$2 -> -30 | M43: =IF(I43<>"",K43+I43+L43,0) -> 0
B44: =IF(H44>$H$2,"",(ROW()-5)) | H44: 39 | I44: =IF(H44<$H$2+1,($I$2-($I$2-1)*(LOG(H44)/LOG($H$2))),"") | J44: =INT(LOG($H$2,2))-ROUNDUP(LOG(H44,2),0)+IF(OR($H$2=1,$H$2=2,$H$2=4,$H$2=8,$H$2=16,$H$2=32,$H$2=64,$H$2=128,$H$2=256),0,1) -> -3 | K44: =J44*$J$2 -> -30 | M44: =IF(I44<>"",K44+I44+L44,0) -> 0
B45: =IF(H45>$H$2,"",(ROW()-5)) | H45: 40 | I45: =IF(H45<$H$2+1,($I$2-($I$2-1)*(LOG(H45)/LOG($H$2))),"") | J45: =INT(LOG($H$2,2))-ROUNDUP(LOG(H45,2),0)+IF(OR($H$2=1,$H$2=2,$H$2=4,$H$2=8,$H$2=16,$H$2=32,$H$2=64,$H$2=128,$H$2=256),0,1) -> -3 | K45: =J45*$J$2 -> -30 | M45: =IF(I45<>"",K45+I45+L45,0) -> 0
B46: =IF(H46>$H$2,"",(ROW()-5)) | H46: 41 | I46: =IF(H46<$H$2+1,($I$2-($I$2-1)*(LOG(H46)/LOG($H$2))),"") | J46: =INT(LOG($H$2,2))-ROUNDUP(LOG(H46,2),0)+IF(OR($H$2=1,$H$2=2,$H$2=4,$H$2=8,$H$2=16,$H$2=32,$H$2=64,$H$2=128,$H$2=256),0,1) -> -3 | K46: =J46*$J$2 -> -30 | M46: =IF(I46<>"",K46+I46+L46,0) -> 0
B47: =IF(H47>$H$2,"",(ROW()-5)) | H47: 42 | I47: =IF(H47<$H$2+1,($I$2-($I$2-1)*(LOG(H47)/LOG($H$2))),"") | J47: =INT(LOG($H$2,2))-ROUNDUP(LOG(H47,2),0)+IF(OR($H$2=1,$H$2=2,$H$2=4,$H$2=8,$H$2=16,$H$2=32,$H$2=64,$H$2=128,$H$2=256),0,1) -> -3 | K47: =J47*$J$2 -> -30 | M47: =IF(I47<>"",K47+I47+L47,0) -> 0
B48: =IF(H48>$H$2,"",(ROW()-5)) | H48: 43 | I48: =IF(H48<$H$2+1,($I$2-($I$2-1)*(LOG(H48)/LOG($H$2))),"") | J48: =INT(LOG($H$2,2))-ROUNDUP(LOG(H48,2),0)+IF(OR($H$2=1,$H$2=2,$H$2=4,$H$2=8,$H$2=16,$H$2=32,$H$2=64,$H$2=128,$H$2=256),0,1) -> -3 | K48: =J48*$J$2 -> -30 | M48: =IF(I48<>"",K48+I48+L48,0) -> 0
B49: =IF(H49>$H$2,"",(ROW()-5)) | H49: 44 | I49: =IF(H49<$H$2+1,($I$2-($I$2-1)*(LOG(H49)/LOG($H$2))),"") | J49: =INT(LOG($H$2,2))-ROUNDUP(LOG(H49,2),0)+IF(OR($H$2=1,$H$2=2,$H$2=4,$H$2=8,$H$2=16,$H$2=32,$H$2=64,$H$2=128,$H$2=256),0,1) -> -3 | K49: =J49*$J$2 -> -30 | M49: =IF(I49<>"",K49+I49+L49,0) -> 0
... B65: =IF(H65>$H$2,"",(ROW()-5)) | H65: 60 | I65: =IF(H65<$H$2+1,($I$2-($I$2-1)*(LOG(H65)/LOG($H$2))),"") | J65: =INT(LOG($H$2,2))-ROUNDUP(LOG(H65,2),0)+IF(OR($H$2=1,$H$2=2,$H$2=4,$H$2=8,$H$2=16,$H$2=32,$H$2=64,$H$2=128,$H$2=256),0,1) -> -3 | K65: =J65*$J$2 -> -30 | M65: =IF(I65<>"",K65+I65+L65,0) -> 0
H66: 61 | I66: =IF(H66<$H$2+1,($I$2-($I$2-1)*(LOG(H66)/LOG($H$2))),"") | J66: =INT(LOG($H$2,2))-ROUNDUP(LOG(H66,2),0)+IF(OR($H$2=1,$H$2=2,$H$2=4,$H$2=8,$H$2=16,$H$2=32,$H$2=64,$H$2=128,$H$2=256),0,1) -> -3 | K66: =J66*$J$2 -> -30 | M66: =IF(I66<>"",K66+I66+L66,0) -> 0
H67: 62 | I67: =IF(H67<$H$2+1,($I$2-($I$2-1)*(LOG(H67)/LOG($H$2))),"") | J67: =INT(LOG($H$2,2))-ROUNDUP(LOG(H67,2),0)+IF(OR($H$2=1,$H$2=2,$H$2=4,$H$2=8,$H$2=16,$H$2=32,$H$2=64,$H$2=128,$H$2=256),0,1) -> -3 | K67: =J67*$J$2 -> -30 | M67: =IF(I67<>"",K67+I67+L67,0) -> 0
...

Sheet GP4
H1: Liczba uczestników: | I1: GP Punkty | J1: Bonus za rundę | K1: Mnożnik za podium
B2: miejsce: | C2: KATOWICE | H2: 8 | I2: 50 | J2: 10 | K2: =3*H2^(1/3) -> 6
B3: data: | C3: 22-23.10.2022
A5: Punkty | B5: Miejsce Place | C5: Nazwisko Imię Name | D5: Klub Club(s) | E5: Okręg Division | F5: Państwo Country | H5: Miejsce | I5: Punkty za miejsce | J5: liczba wygranych walk pucharowych | K5: bonus z rundy pucharowej | L5: punkty za podium | M5: Suma
A6: =M6 -> 98 | B6: =IF(H6>$H$2,"",(ROW()-5)) -> 1 | C6: ATANASSOW Aleksander | D6: AZS AGH | F6: POL | H6: 1 | I6: =IF(H6<$H$2+1,($I$2-($I$2-1)*(LOG(H6)/LOG($H$2))),"") -> 50 | J6: =INT(LOG($H$2,2))-ROUNDUP(LOG(H6,2),0)+IF(OR($H$2=1,$H$2=2,$H$2=4,$H$2=8,$H$2=16,$H$2=32,$H$2=64,$H$2=128,$H$2=256),0,1) -> 3 | K6: =J6*$J$2 -> 30 | L6: =3*K2 -> 18 | M6: =IF(I6<>"",K6+I6+L6,0) -> 98
A7: =M7 -> 65.666667 | B7: =IF(H7>$H$2,"",(ROW()-5)) -> 2 | C7: ZIELIŃSKI Dariusz | D7: PIAST GLIWICE | F7: POL | H7: 2 | I7: =IF(H7<$H$2+1,($I$2-($I$2-1)*(LOG(H7)/LOG($H$2))),"") -> 33.666667 | J7: =INT(LOG($H$2,2))-ROUNDUP(LOG(H7,2),0)+IF(OR($H$2=1,$H$2=2,$H$2=4,$H$2=8,$H$2=16,$H$2=32,$H$2=64,$H$2=128,$H$2=256),0,1) -> 2 | K7: =J7*$J$2 -> 20 | L7: =2*K2 -> 12 | M7: =IF(I7<>"",K7+I7+L7,0) -> 65.666667
A8: =M8 -> 40.112279 | B8: =IF(H8>$H$2,"",(ROW()-5)) -> 3 | C8: KOSTRZEWA Ireneusz | D8: KSz WARSZAWIANKA | F8: POL | H8: 3 | I8: =IF(H8<$H$2+1,($I$2-($I$2-1)*(LOG(H8)/LOG($H$2))),"") -> 24.112279 | J8: =INT(LOG($H$2,2))-ROUNDUP(LOG(H8,2),0)+IF(OR($H$2=1,$H$2=2,$H$2=4,$H$2=8,$H$2=16,$H$2=32,$H$2=64,$H$2=128,$H$2=256),0,1) -> 1 | K8: =J8*$J$2 -> 10 | L8: =K2 -> 6 | M8: =IF(I8<>"",K8+I8+L8,0) -> 40.112279
A9: =M9 -> 40.112279 | B9: 3 | C9: WOJTAS Bogdan | F9: POL | H9: 3 | I9: =IF(H9<$H$2+1,($I$2-($I$2-1)*(LOG(H9)/LOG($H$2))),"") -> 24.112279 | J9: =INT(LOG($H$2,2))-ROUNDUP(LOG(H9,2),0)+IF(OR($H$2=1,$H$2=2,$H$2=4,$H$2=8,$H$2=16,$H$2=32,$H$2=64,$H$2=128,$H$2=256),0,1) -> 1 | K9: =J9*$J$2 -> 10 | L9: =K2 -> 6 | M9: =IF(I9<>"",K9+I9+L9,0) -> 40.112279
A10: =M10 -> 12.075174 | B10: =IF(H10>$H$2,"",(ROW()-5)) -> 5 | C10: TYKHYI Volodymyr | D10: UKRAINA | F10: UKR | H10: 5 | I10: =IF(H10<$H$2+1,($I$2-($I$2-1)*(LOG(H10)/LOG($H$2))),"") -> 12.075174 | J10: =INT(LOG($H$2,2))-ROUNDUP(LOG(H10,2),0)+IF(OR($H$2=1,$H$2=2,$H$2=4,$H$2=8,$H$2=16,$H$2=32,$H$2=64,$H$2=128,$H$2=256),0,1) -> 0 | K10: =J10*$J$2 -> 0 | M10: =IF(I10<>"",K10+I10+L10,0) -> 12.075174
A11: =M11 -> 7.7789458 | B11: =IF(H11>$H$2,"",(ROW()-5)) -> 6 | C11: SKOCZEK Artur | F11: POL | H11: 6 | I11: =IF(H11<$H$2+1,($I$2-($I$2-1)*(LOG(H11)/LOG($H$2))),"") -> 7.7789458 | J11: =INT(LOG($H$2,2))-ROUNDUP(LOG(H11,2),0)+IF(OR($H$2=1,$H$2=2,$H$2=4,$H$2=8,$H$2=16,$H$2=32,$H$2=64,$H$2=128,$H$2=256),0,1) -> 0 | K11: =J11*$J$2 -> 0 | M11: =IF(I11<>"",K11+I11+L11,0) -> 7.7789458
A12: =M12 -> 4.1465363 | B12: =IF(H12>$H$2,"",(ROW()-5)) -> 7 | C12: WIERZBICKI Jacek | D12: AZS KU POLITECHNIKI OPOLSKIEJ | F12: POL | H12: 7 | I12: =IF(H12<$H$2+1,($I$2-($I$2-1)*(LOG(H12)/LOG($H$2))),"") -> 4.1465363 | J12: =INT(LOG($H$2,2))-ROUNDUP(LOG(H12,2),0)+IF(OR($H$2=1,$H$2=2,$H$2=4,$H$2=8,$H$2=16,$H$2=32,$H$2=64,$H$2=128,$H$2=256),0,1) -> 0 | K12: =J12*$J$2 -> 0 | M12: =IF(I12<>"",K12+I12+L12,0) -> 4.1465363
A13: =M13 -> 1 | B13: =IF(H13>$H$2,"",(ROW()-5)) -> 8 | C13: PARDUS Borys | D13: AKADEMIA SZERMIERKI W-WA | F13: POL | H13: 8 | I13: =IF(H13<$H$2+1,($I$2-($I$2-1)*(LOG(H13)/LOG($H$2))),"") -> 1 | J13: =INT(LOG($H$2,2))-ROUNDUP(LOG(H13,2),0)+IF(OR($H$2=1,$H$2=2,$H$2=4,$H$2=8,$H$2=16,$H$2=32,$H$2=64,$H$2=128,$H$2=256),0,1) -> 0 | K13: =J13*$J$2 -> 0 | M13: =IF(I13<>"",K13+I13+L13,0) -> 1
A14: =M14 -> 0 | B14: =IF(H14>$H$2,"",(ROW()-5)) | H14: 9 | I14: =IF(H14<$H$2+1,($I$2-($I$2-1)*(LOG(H14)/LOG($H$2))),"") | J14: =INT(LOG($H$2,2))-ROUNDUP(LOG(H14,2),0)+IF(OR($H$2=1,$H$2=2,$H$2=4,$H$2=8,$H$2=16,$H$2=32,$H$2=64,$H$2=128,$H$2=256),0,1) -> -1 | K14: =J14*$J$2 -> -10 | M14: =IF(I14<>"",K14+I14+L14,0) -> 0
A15: =M15 -> 0 | B15: =IF(H15>$H$2,"",(ROW()-5)) | H15: 10 | I15: =IF(H15<$H$2+1,($I$2-($I$2-1)*(LOG(H15)/LOG($H$2))),"") | J15: =INT(LOG($H$2,2))-ROUNDUP(LOG(H15,2),0)+IF(OR($H$2=1,$H$2=2,$H$2=4,$H$2=8,$H$2=16,$H$2=32,$H$2=64,$H$2=128,$H$2=256),0,1) -> -1 | K15: =J15*$J$2 -> -10 | M15: =IF(I15<>"",K15+I15+L15,0) -> 0
A16: =M16 -> 0 | B16: =IF(H16>$H$2,"",(ROW()-5)) | H16: 11 | I16: =IF(H16<$H$2+1,($I$2-($I$2-1)*(LOG(H16)/LOG($H$2))),"") | J16: =INT(LOG($H$2,2))-ROUNDUP(LOG(H16,2),0)+IF(OR($H$2=1,$H$2=2,$H$2=4,$H$2=8,$H$2=16,$H$2=32,$H$2=64,$H$2=128,$H$2=256),0,1) -> -1 | K16: =J16*$J$2 -> -10 | M16: =IF(I16<>"",K16+I16+L16,0) -> 0
A17: =M17 -> 0 | B17: =IF(H17>$H$2,"",(ROW()-5)) | H17: 12 | I17: =IF(H17<$H$2+1,($I$2-($I$2-1)*(LOG(H17)/LOG($H$2))),"") | J17: =INT(LOG($H$2,2))-ROUNDUP(LOG(H17,2),0)+IF(OR($H$2=1,$H$2=2,$H$2=4,$H$2=8,$H$2=16,$H$2=32,$H$2=64,$H$2=128,$H$2=256),0,1) -> -1 | K17: =J17*$J$2 -> -10 | M17: =IF(I17<>"",K17+I17+L17,0) -> 0
A18: =M18 -> 0 | B18: =IF(H18>$H$2,"",(ROW()-5)) | H18: 13 | I18: =IF(H18<$H$2+1,($I$2-($I$2-1)*(LOG(H18)/LOG($H$2))),"") | J18: =INT(LOG($H$2,2))-ROUNDUP(LOG(H18,2),0)+IF(OR($H$2=1,$H$2=2,$H$2=4,$H$2=8,$H$2=16,$H$2=32,$H$2=64,$H$2=128,$H$2=256),0,1) -> -1 | K18: =J18*$J$2 -> -10 | M18: =IF(I18<>"",K18+I18+L18,0) -> 0
A19: =M19 -> 0 | B19: =IF(H19>$H$2,"",(ROW()-5)) | H19: 14 | I19: =IF(H19<$H$2+1,($I$2-($I$2-1)*(LOG(H19)/LOG($H$2))),"") | J19: =INT(LOG($H$2,2))-ROUNDUP(LOG(H19,2),0)+IF(OR($H$2=1,$H$2=2,$H$2=4,$H$2=8,$H$2=16,$H$2=32,$H$2=64,$H$2=128,$H$2=256),0,1) -> -1 | K19: =J19*$J$2 -> -10 | M19: =IF(I19<>"",K19+I19+L19,0) -> 0
A20: =M20 -> 0 | B20: =IF(H20>$H$2,"",(ROW()-5)) | H20: 15 | I20: =IF(H20<$H$2+1,($I$2-($I$2-1)*(LOG(H20)/LOG($H$2))),"") | J20: =INT(LOG($H$2,2))-ROUNDUP(LOG(H20,2),0)+IF(OR($H$2=1,$H$2=2,$H$2=4,$H$2=8,$H$2=16,$H$2=32,$H$2=64,$H$2=128,$H$2=256),0,1) -> -1 | K20: =J20*$J$2 -> -10 | M20: =IF(I20<>"",K20+I20+L20,0) -> 0
