Workbook

Sheet All
A2: L.P. | B2: kat | C2: IMIĘ NAZWISKO | D2: V/M | E2: V/M | Q2: TS | R2: TS | AD2: Ind | AE2: Ind | AR2: ma mniej niż 30 lat
E3: MP | G3: GP1 | I3: GP2 | K3: GP3 | M3: GP4 | O3: GP5 | R3: MP | T3: GP1 | V3: GP2 | X3: GP3 | Z3: GP4 | AB3: GP5 | AE3: MP | AG3: GP1 | AI3: GP2 | AK3: GP3 | AM3: GP4 | AO3: GP5 | AR3: odeszła/odszedł w tym roku
E4: 1 | F4: 2 | G4: 1 | H4: 2 | I4: 1 | J4: 2 | K4: 1 | L4: 2 | M4: 1 | N4: 2 | O4: 1 | P4: 2 | R4: 1 | S4: 2 | T4: 1 | U4: 2 | V4: 1 | W4: 2 | X4: 1 | Y4: 2 | Z4: 1 | AA4: 2 | AB4: 1 | AC4: 2 | AE4: 1 | AF4: 2 | AG4: 1 | AH4: 2 | AI4: 1 | AJ4: 2 | AK4: 1 | AL4: 2 | AM4: 1 | AN4: 2 | AO4: 1 | AP4: 2
A5: =ROW()-4 -> 1 | B5: 1 | C5: GANSZCZYK Marcin | D5: =SUM(E5:P5) -> 11.38 | E5: =_xlfn.XLOOKUP($C5,'MP (1)'!$B$6:$B$100,'MP (1)'!$E$6:$E$100,"") -> 1 | F5: =_xlfn.XLOOKUP($C5,'MP (2)'!$B$6:$B$100,'MP (2)'!$E$6:$E$100,"") -> 1 | G5: =_xlfn.XLOOKUP($C5,'GP1 (1)'!$B$6:$B$100,'GP1 (1)'!$E$6:$E$100,"") -> 0.83 | H5: =_xlfn.XLOOKUP($C5,'GP1 (2)'!$B$6:$B$100,'GP1 (2)'!$E$6:$E$100,"") -> 1 | I5: =_xlfn.XLOOKUP($C5,'GP2 (1)'!$B$6:$B$107,'GP2 (1)'!$E$6:$E$107,"") -> 1 | J5: =_xlfn.XLOOKUP($C5,'GP2 (2)'!$B$6:$B$99,'GP2 (2)'!$E$6:$E$99,"") -> 1 | K5: =_xlfn.XLOOKUP($C5,'GP3 (1)'!$B$6:$B$100,'GP3 (1)'!$E$6:$E$100,"") -> 1 | L5: =_xlfn.XLOOKUP($C5,'GP3 (2)'!$B$6:$B$100,'GP3 (2)'!$E$6:$E$100,"") -> 1 | M5: =_xlfn.XLOOKUP($C5,'GP4 (1)'!$B$6:$B$86,'GP4 (1)'!$E$6:$E$86,"") -> 1 | N5: =_xlfn.XLOOKUP($C5,'GP4 (2)'!$B$6:$B$100,'GP4 (2)'!$E$6:$E$100,"") -> 0.8 | O5: =_xlfn.XLOOKUP($C5,'GP5 (1)'!$B$6:$B$100,'GP5 (1)'!$E$6:$E$100,"") -> 1 | P5: =_xlfn.XLOOKUP($C5,'GP5 (2)'!$B$6:$B$100,'GP5 (2)'!$E$6:$E$100,"") -> 0.75 | Q5: =SUM(R5:AC5) -> 284 | R5: =_xlfn.XLOOKUP($C5,'MP (1)'!$B$6:$B$100,'MP (1)'!$F$6:$F$100,"") -> 30 | S5: =_xlfn.XLOOKUP($C5,'MP (2)'!$B$6:$B$100,'MP (2)'!$F$6:$F$100,"") -> 30 | T5: =_xlfn.XLOOKUP($C5,'GP1 (1)'!$B$6:$B$100,'GP1 (1)'!$F$6:$F$100,"") -> 29 | U5: =_xlfn.XLOOKUP($C5,'GP1 (2)'!$B$6:$B$100,'GP1 (2)'!$F$6:$F$100,"") -> 25 | V5: =_xlfn.XLOOKUP($C5,'GP2 (1)'!$B$8:$B$107,'GP2 (1)'!$F$8:$F$107,"") | W5: =_xlfn.XLOOKUP($C5,'GP2 (2)'!$B$6:$B$99,'GP2 (2)'!$F$6:$F$99,"") -> 30 | X5: =_xlfn.XLOOKUP($C5,'GP3 (1)'!$B$6:$B$100,'GP3 (1)'!$F$6:$F$100,"") -> 25 | Y5: =_xlfn.XLOOKUP($C5,'GP3 (2)'!$B$6:$B$100,'GP3 (2)'!$F$6:$F$100,"") -> 30 | Z5: =_xlfn.XLOOKUP($C5,'GP4 (1)'!$B$6:$B$86,'GP4 (1)'!$F$6:$F$86,"") -> 25 | AA5: =_xlfn.XLOOKUP($C5,'GP4 (2)'!$B$6:$B$100,'GP4 (2)'!$F$6:$F$100,"") -> 22 | AB5: =_xlfn.XLOOKUP($C5,'GP5 (1)'!$B$6:$B$100,'GP5 (1)'!$F$6:$F$100,"") -> 20 | AC5: =_xlfn.XLOOKUP($C5,'GP5 (2)'!$B$6:$B$100,'GP5 (2)'!$F$6:$F$100,"") -> 18 | AD5: =SUM(AE5:AO5) -> 177 | AE5: =_xlfn.XLOOKUP($C5,'MP (1)'!$B$6:$B$100,'MP (1)'!$H$6:$H$100,"") -> 21 | AF5: =_xlfn.XLOOKUP($C5,'MP (2)'!$B$6:$B$100,'MP (2)'!$H$6:$H$100,"") -> 27 | AG5: =_xlfn.XLOOKUP($C5,'GP1 (1)'!$B$6:$B$100,'GP1 (1)'!$H$6:$H$100,"") -> 15 | AH5: =_xlfn.XLOOKUP($C5,'GP1 (2)'!$B$6:$B$100,'GP1 (2)'!$H$6:$H$100,"") -> 18 | AI5: =_xlfn.XLOOKUP($C5,'GP2 (1)'!$B$8:$B$107,'GP2 (1)'!$H$8:$H$107,"") | AJ5: =_xlfn.XLOOKUP($C5,'GP2 (2)'!$B$6:$B$99,'GP2 (2)'!$H$6:$H$99,"") -> 23 | AK5: =_xlfn.XLOOKUP($C5,'GP3 (1)'!$B$6:$B$100,'GP3 (1)'!$H$6:$H$100,"") -> 17 | AL5: =_xlfn.XLOOKUP($C5,'GP3 (2)'!$B$6:$B$100,'GP3 (2)'!$H$6:$H$100,"") -> 17 | AM5: =_xlfn.XLOOKUP($C5,'GP4 (1)'!$B$6:$B$86,'GP4 (1)'!$H$6:$H$86,"") -> 16 | AN5: =_xlfn.XLOOKUP($C5,'GP4 (2)'!$B$6:$B$100,'GP4 (2)'!$H$6:$H$100,"") -> 7 | AO5: =_xlfn.XLOOKUP($C5,'GP5 (1)'!$B$6:$B$100,'GP5 (1)'!$H$6:$H$100,"") -> 16 | AP5: =_xlfn.XLOOKUP($C5,'GP5 (2)'!$B$6:$B$100,'GP5 (2)'!$H$6:$H$100,"") -> 11
A6: =ROW()-4 -> 2 | B6: 2 | C6: GAJDA Leszek | D6: =SUM(E6:P6) -> 10.86 | E6: =_xlfn.XLOOKUP($C6,'MP (1)'!$B$6:$B$100,'MP (1)'!$E$6:$E$100,"") -> 1 | F6: =_xlfn.XLOOKUP($C6,'MP (2)'!$B$6:$B$100,'MP (2)'!$E$6:$E$100,"") -> 1 | G6: =_xlfn.XLOOKUP($C6,'GP1 (1)'!$B$6:$B$100,'GP1 (1)'!$E$6:$E$100,"") -> 0.83 | H6: =_xlfn.XLOOKUP($C6,'GP1 (2)'!$B$6:$B$100,'GP1 (2)'!$E$6:$E$100,"") -> 0.4 | I6: =_xlfn.XLOOKUP($C6,'GP2 (1)'!$B$6:$B$107,'GP2 (1)'!$E$6:$E$107,"") -> 1 | J6: =_xlfn.XLOOKUP($C6,'GP2 (2)'!$B$6:$B$99,'GP2 (2)'!$E$6:$E$99,"") -> 0.8 | K6: =_xlfn.XLOOKUP($C6,'GP3 (1)'!$B$6:$B$100,'GP3 (1)'!$E$6:$E$100,"") -> 1 | L6: =_xlfn.XLOOKUP($C6,'GP3 (2)'!$B$6:$B$100,'GP3 (2)'!$E$6:$E$100,"") -> 0.83 | M6: =_xlfn.XLOOKUP($C6,'GP4 (1)'!$B$6:$B$86,'GP4 (1)'!$E$6:$E$86,"") -> 1 | N6: =_xlfn.XLOOKUP($C6,'GP4 (2)'!$B$6:$B$100,'GP4 (2)'!$E$6:$E$100,"") -> 1 | O6: =_xlfn.XLOOKUP($C6,'GP5 (1)'!$B$6:$B$100,'GP5 (1)'!$E$6:$E$100,"") -> 1 | P6: =_xlfn.XLOOKUP($C6,'GP5 (2)'!$B$6:$B$100,'GP5 (2)'!$E$6:$E$100,"") -> 1 | Q6: =SUM(R6:AC6) -> 277 | R6: =_xlfn.XLOOKUP($C6,'MP (1)'!$B$6:$B$100,'MP (1)'!$F$6:$F$100,"") -> 30 | S6: =_xlfn.XLOOKUP($C6,'MP (2)'!$B$6:$B$100,'MP (2)'!$F$6:$F$100,"") -> 30 | T6: =_xlfn.XLOOKUP($C6,'GP1 (1)'!$B$6:$B$100,'GP1 (1)'!$F$6:$F$100,"") -> 28 | U6: =_xlfn.XLOOKUP($C6,'GP1 (2)'!$B$6:$B$100,'GP1 (2)'!$F$6:$F$100,"") -> 21 | V6: =_xlfn.XLOOKUP($C6,'GP2 (1)'!$B$8:$B$107,'GP2 (1)'!$F$8:$F$107,"") | W6: =_xlfn.XLOOKUP($C6,'GP2 (2)'!$B$6:$B$99,'GP2 (2)'!$F$6:$F$99,"") -> 24 | X6: =_xlfn.XLOOKUP($C6,'GP3 (1)'!$B$6:$B$100,'GP3 (1)'!$F$6:$F$100,"") -> 25 | Y6: =_xlfn.XLOOKUP($C6,'GP3 (2)'!$B$6:$B$100,'GP3 (2)'!$F$6:$F$100,"") -> 29 | Z6: =_xlfn.XLOOKUP($C6,'GP4 (1)'!$B$6:$B$86,'GP4 (1)'!$F$6:$F$86,"") -> 25 | AA6: =_xlfn.XLOOKUP($C6,'GP4 (2)'!$B$6:$B$100,'GP4 (2)'!$F$6:$F$100,"") -> 25 | AB6: =_xlfn.XLOOKUP($C6,'GP5 (1)'!$B$6:$B$100,'GP5 (1)'!$F$6:$F$100,"") -> 20 | AC6: =_xlfn.XLOOKUP($C6,'GP5 (2)'!$B$6:$B$100,'GP5 (2)'!$F$6:$F$100,"") -> 20 | AD6: =SUM(AE6:AO6) -> 149 | AE6: =_xlfn.XLOOKUP($C6,'MP (1)'!$B$6:$B$100,'MP (1)'!$H$6:$H$100,"") -> 19 | AF6: =_xlfn.XLOOKUP($C6,'MP (2)'!$B$6:$B$100,'MP (2)'!$H$6:$H$100,"") -> 17 | AG6: =_xlfn.XLOOKUP($C6,'GP1 (1)'!$B$6:$B$100,'GP1 (1)'!$H$6:$H$100,"") -> 14 | AH6: =_xlfn.XLOOKUP($C6,'GP1 (2)'!$B$6:$B$100,'GP1 (2)'!$H$6:$H$100,"") -> 1 | AI6: =_xlfn.XLOOKUP($C6,'GP2 (1)'!$B$8:$B$107,'GP2 (1)'!$H$8:$H$107,"") | AJ6: =_xlfn.XLOOKUP($C6,'GP2 (2)'!$B$6:$B$99,'GP2 (2)'!$H$6:$H$99,"") -> 10 | AK6: =_xlfn.XLOOKUP($C6,'GP3 (1)'!$B$6:$B$100,'GP3 (1)'!$H$6:$H$100,"") -> 23 | AL6: =_xlfn.XLOOKUP($C6,'GP3 (2)'!$B$6:$B$100,'GP3 (2)'!$H$6:$H$100,"") -> 20 | AM6: =_xlfn.XLOOKUP($C6,'GP4 (1)'!$B$6:$B$86,'GP4 (1)'!$H$6:$H$86,"") -> 14 | AN6: =_xlfn.XLOOKUP($C6,'GP4 (2)'!$B$6:$B$100,'GP4 (2)'!$H$6:$H$100,"") -> 14 | AO6: =_xlfn.XLOOKUP($C6,'GP5 (1)'!$B$6:$B$100,'GP5 (1)'!$H$6:$H$100,"") -> 17 | AP6: =_xlfn.XLOOKUP($C6,'GP5 (2)'!$B$6:$B$100,'GP5 (2)'!$H$6:$H$100,"") -> 13
A7: =ROW()-4 -> 3 | B7: 2 | C7: NOWICKI Robert | D7: =SUM(E7:P7) -> 10.45 | E7: =_xlfn.XLOOKUP($C7,'MP (1)'!$B$6:$B$100,'MP (1)'!$E$6:$E$100,"") -> 0.83 | F7: =_xlfn.XLOOKUP($C7,'MP (2)'!$B$6:$B$100,'MP (2)'!$E$6:$E$100,"") -> 0.8 | G7: =_xlfn.XLOOKUP($C7,'GP1 (1)'!$B$6:$B$100,'GP1 (1)'!$E$6:$E$100,"") -> 1 | H7: =_xlfn.XLOOKUP($C7,'GP1 (2)'!$B$6:$B$100,'GP1 (2)'!$E$6:$E$100,"") -> 0.6 | I7: =_xlfn.XLOOKUP($C7,'GP2 (1)'!$B$6:$B$107,'GP2 (1)'!$E$6:$E$107,"") -> 1 | J7: =_xlfn.XLOOKUP($C7,'GP2 (2)'!$B$6:$B$99,'GP2 (2)'!$E$6:$E$99,"") -> 1 | K7: =_xlfn.XLOOKUP($C7,'GP3 (1)'!$B$6:$B$100,'GP3 (1)'!$E$6:$E$100,"") -> 1 | L7: =_xlfn.XLOOKUP($C7,'GP3 (2)'!$B$6:$B$100,'GP3 (2)'!$E$6:$E$100,"") -> 1 | M7: =_xlfn.XLOOKUP($C7,'GP4 (1)'!$B$6:$B$86,'GP4 (1)'!$E$6:$E$86,"") -> 0.67 | N7: =_xlfn.XLOOKUP($C7,'GP4 (2)'!$B$6:$B$100,'GP4 (2)'!$E$6:$E$100,"") -> 0.8 | O7: =_xlfn.XLOOKUP($C7,'GP5 (1)'!$B$6:$B$100,'GP5 (1)'!$E$6:$E$100,"") -> 0.75 | P7: =_xlfn.XLOOKUP($C7,'GP5 (2)'!$B$6:$B$100,'GP5 (2)'!$E$6:$E$100,"") -> 1 | Q7: =SUM(R7:AC7) -> 288 | R7: =_xlfn.XLOOKUP($C7,'MP (1)'!$B$6:$B$100,'MP (1)'!$F$6:$F$100,"") -> 29 | S7: =_xlfn.XLOOKUP($C7,'MP (2)'!$B$6:$B$100,'MP (2)'!$F$6:$F$100,"") -> 23 | T7: =_xlfn.XLOOKUP($C7,'GP1 (1)'!$B$6:$B$100,'GP1 (1)'!$F$6:$F$100,"") -> 25 | U7: =_xlfn.XLOOKUP($C7,'GP1 (2)'!$B$6:$B$100,'GP1 (2)'!$F$6:$F$100,"") -> 23 | V7: =_xlfn.XLOOKUP($C7,'GP2 (1)'!$B$8:$B$107,'GP2 (1)'!$F$8:$F$107,"") -> 25 | W7: =_xlfn.XLOOKUP($C7,'GP2 (2)'!$B$6:$B$99,'GP2 (2)'!$F$6:$F$99,"") -> 25 | X7: =_xlfn.XLOOKUP($C7,'GP3 (1)'!$B$6:$B$100,'GP3 (1)'!$F$6:$F$100,"") -> 20 | Y7: =_xlfn.XLOOKUP($C7,'GP3 (2)'!$B$6:$B$100,'GP3 (2)'!$F$6:$F$100,"") -> 30 | Z7: =_xlfn.XLOOKUP($C7,'GP4 (1)'!$B$6:$B$86,'GP4 (1)'!$F$6:$F$86,"") -> 28 | AA7: =_xlfn.XLOOKUP($C7,'GP4 (2)'!$B$6:$B$100,'GP4 (2)'!$F$6:$F$100,"") -> 23 | AB7: =_xlfn.XLOOKUP($C7,'GP5 (1)'!$B$6:$B$100,'GP5 (1)'!$F$6:$F$100,"") -> 17 | AC7: =_xlfn.XLOOKUP($C7,'GP5 (2)'!$B$6:$B$100,'GP5 (2)'!$F$6:$F$100,"") -> 20 | AD7: =SUM(AE7:AO7) -> 153 | AE7: =_xlfn.XLOOKUP($C7,'MP (1)'!$B$6:$B$100,'MP (1)'!$H$6:$H$100,"") -> 18 | AF7: =_xlfn.XLOOKUP($C7,'MP (2)'!$B$6:$B$100,'MP (2)'!$H$6:$H$100,"") -> 12 | AG7: =_xlfn.XLOOKUP($C7,'GP1 (1)'!$B$6:$B$100,'GP1 (1)'!$H$6:$H$100,"") -> 16 | AH7: =_xlfn.XLOOKUP($C7,'GP1 (2)'!$B$6:$B$100,'GP1 (2)'!$H$6:$H$100,"") -> 8 | AI7: =_xlfn.XLOOKUP($C7,'GP2 (1)'!$B$8:$B$107,'GP2 (1)'!$H$8:$H$107,"") -> 15 | AJ7: =_xlfn.XLOOKUP($C7,'GP2 (2)'!$B$6:$B$99,'GP2 (2)'!$H$6:$H$99,"") -> 15 | AK7: =_xlfn.XLOOKUP($C7,'GP3 (1)'!$B$6:$B$100,'GP3 (1)'!$H$6:$H$100,"") -> 14 | AL7: =_xlfn.XLOOKUP($C7,'GP3 (2)'!$B$6:$B$100,'GP3 (2)'!$H$6:$H$100,"") -> 22 | AM7: =_xlfn.XLOOKUP($C7,'GP4 (1)'!$B$6:$B$86,'GP4 (1)'!$H$6:$H$86,"") -> 12 | AN7: =_xlfn.XLOOKUP($C7,'GP4 (2)'!$B$6:$B$100,'GP4 (2)'!$H$6:$H$100,"") -> 13 | AO7: =_xlfn.XLOOKUP($C7,'GP5 (1)'!$B$6:$B$100,'GP5 (1)'!$H$6:$H$100,"") -> 8 | AP7: =_xlfn.XLOOKUP($C7,'GP5 (2)'!$B$6:$B$100,'GP5 (2)'!$H$6:$H$100,"") -> 11
A8: =ROW()-4 -> 4 | B8: 2 | C8: MAZIK Aleksander | D8: =SUM(E8:P8) -> 8.75 | E8: =_xlfn.XLOOKUP($C8,'MP (1)'!$B$6:$B$100,'MP (1)'!$E$6:$E$100,"") -> 0.8 | F8: =_xlfn.XLOOKUP($C8,'MP (2)'!$B$6:$B$100,'MP (2)'!$E$6:$E$100,"") -> 0.8 | G8: =_xlfn.XLOOKUP($C8,'GP1 (1)'!$B$6:$B$100,'GP1 (1)'!$E$6:$E$100,"") -> 0.83 | H8: =_xlfn.XLOOKUP($C8,'GP1 (2)'!$B$6:$B$100,'GP1 (2)'!$E$6:$E$100,"") -> 0.8 | I8: =_xlfn.XLOOKUP($C8,'GP2 (1)'!$B$6:$B$107,'GP2 (1)'!$E$6:$E$107,"") -> 0.4 | J8: =_xlfn.XLOOKUP($C8,'GP2 (2)'!$B$6:$B$99,'GP2 (2)'!$E$6:$E$99,"") -> 0.8 | K8: =_xlfn.XLOOKUP($C8,'GP3 (1)'!$B$6:$B$100,'GP3 (1)'!$E$6:$E$100,"") -> 0.75 | L8: =_xlfn.XLOOKUP($C8,'GP3 (2)'!$B$6:$B$100,'GP3 (2)'!$E$6:$E$100,"") -> 0.67 | M8: =_xlfn.XLOOKUP($C8,'GP4 (1)'!$B$6:$B$86,'GP4 (1)'!$E$6:$E$86,"") -> 0.8 | N8: =_xlfn.XLOOKUP($C8,'GP4 (2)'!$B$6:$B$100,'GP4 (2)'!$E$6:$E$100,"") -> 0.6 | O8: =_xlfn.XLOOKUP($C8,'GP5 (1)'!$B$6:$B$100,'GP5 (1)'!$E$6:$E$100,"") -> 0.75 | P8: =_xlfn.XLOOKUP($C8,'GP5 (2)'!$B$6:$B$100,'GP5 (2)'!$E$6:$E$100,"") -> 0.75 | Q8: =SUM(R8:AC8) -> 253 | R8: =_xlfn.XLOOKUP($C8,'MP (1)'!$B$6:$B$100,'MP (1)'!$F$6:$F$100,"") -> 22 | S8: =_xlfn.XLOOKUP($C8,'MP (2)'!$B$6:$B$100,'MP (2)'!$F$6:$F$100,"") -> 22 | T8: =_xlfn.XLOOKUP($C8,'GP1 (1)'!$B$6:$B$100,'GP1 (1)'!$F$6:$F$100,"") -> 29 | U8: =_xlfn.XLOOKUP($C8,'GP1 (2)'!$B$6:$B$100,'GP1 (2)'!$F$6:$F$100,"") -> 24 | V8: =_xlfn.XLOOKUP($C8,'GP2 (1)'!$B$8:$B$107,'GP2 (1)'!$F$8:$F$107,"") -> 20 | W8: =_xlfn.XLOOKUP($C8,'GP2 (2)'!$B$6:$B$99,'GP2 (2)'!$F$6:$F$99,"") -> 22 | X8: =_xlfn.XLOOKUP($C8,'GP3 (1)'!$B$6:$B$100,'GP3 (1)'!$F$6:$F$100,"") -> 16 | Y8: =_xlfn.XLOOKUP($C8,'GP3 (2)'!$B$6:$B$100,'GP3 (2)'!$F$6:$F$100,"") -> 21 | Z8: =_xlfn.XLOOKUP($C8,'GP4 (1)'!$B$6:$B$86,'GP4 (1)'!$F$6:$F$86,"") -> 21 | AA8: =_xlfn.XLOOKUP($C8,'GP4 (2)'!$B$6:$B$100,'GP4 (2)'!$F$6:$F$100,"") -> 21 | AB8: =_xlfn.XLOOKUP($C8,'GP5 (1)'!$B$6:$B$100,'GP5 (1)'!$F$6:$F$100,"") -> 17 | AC8: =_xlfn.XLOOKUP($C8,'GP5 (2)'!$B$6:$B$100,'GP5 (2)'!$F$6:$F$100,"") -> 18 | AD8: =SUM(AE8:AO8) -> 68 | AE8: =_xlfn.XLOOKUP($C8,'MP (1)'!$B$6:$B$100,'MP (1)'!$H$6:$H$100,"") -> 14 | AF8: =_xlfn.XLOOKUP($C8,'MP (2)'!$B$6:$B$100,'MP (2)'!$H$6:$H$100,"") -> 6 | AG8: =_xlfn.XLOOKUP($C8,'GP1 (1)'!$B$6:$B$100,'GP1 (1)'!$H$6:$H$100,"") -> 11 | AH8: =_xlfn.XLOOKUP($C8,'GP1 (2)'!$B$6:$B$100,'GP1 (2)'!$H$6:$H$100,"") -> 6 | AI8: =_xlfn.XLOOKUP($C8,'GP2 (1)'!$B$8:$B$107,'GP2 (1)'!$H$8:$H$107,"") -> 3 | AJ8: =_xlfn.XLOOKUP($C8,'GP2 (2)'!$B$6:$B$99,'GP2 (2)'!$H$6:$H$99,"") -> 7 | AK8: =_xlfn.XLOOKUP($C8,'GP3 (1)'!$B$6:$B$100,'GP3 (1)'!$H$6:$H$100,"") -> 5 | AL8: =_xlfn.XLOOKUP($C8,'GP3 (2)'!$B$6:$B$100,'GP3 (2)'!$H$6:$H$100,"") -> 3 | AM8: =_xlfn.XLOOKUP($C8,'GP4 (1)'!$B$6:$B$86,'GP4 (1)'!$H$6:$H$86,"") -> 2 | AN8: =_xlfn.XLOOKUP($C8,'GP4 (2)'!$B$6:$B$100,'GP4 (2)'!$H$6:$H$100,"") -> 5 | AO8: =_xlfn.XLOOKUP($C8,'GP5 (1)'!$B$6:$B$100,'GP5 (1)'!$H$6:$H$100,"") -> 6 | AP8: =_xlfn.XLOOKUP($C8,'GP5 (2)'!$B$6:$B$100,'GP5 (2)'!$H$6:$H$100,"") -> 9
A9: =ROW()-4 -> 5 | B9: 1 | C9: KOSIŃSKI Łukasz | D9: =SUM(E9:P9) -> 8.56 | E9: =_xlfn.XLOOKUP($C9,'MP (1)'!$B$6:$B$100,'MP (1)'!$E$6:$E$100,"") -> 0.83 | F9: =_xlfn.XLOOKUP($C9,'MP (2)'!$B$6:$B$100,'MP (2)'!$E$6:$E$100,"") -> 1 | G9: =_xlfn.XLOOKUP($C9,'GP1 (1)'!$B$6:$B$100,'GP1 (1)'!$E$6:$E$100,"") -> 1 | H9: =_xlfn.XLOOKUP($C9,'GP1 (2)'!$B$6:$B$100,'GP1 (2)'!$E$6:$E$100,"") -> 1 | I9: =_xlfn.XLOOKUP($C9,'GP2 (1)'!$B$6:$B$107,'GP2 (1)'!$E$6:$E$107,"") -> 0.8 | J9: =_xlfn.XLOOKUP($C9,'GP2 (2)'!$B$6:$B$99,'GP2 (2)'!$E$6:$E$99,"") -> 0.6 | K9: =_xlfn.XLOOKUP($C9,'GP3 (1)'!$B$6:$B$100,'GP3 (1)'!$E$6:$E$100,"") -> 0.5 | L9: =_xlfn.XLOOKUP($C9,'GP3 (2)'!$B$6:$B$100,'GP3 (2)'!$E$6:$E$100,"") -> 0.83 | M9: =_xlfn.XLOOKUP($C9,'GP4 (1)'!$B$6:$B$86,'GP4 (1)'!$E$6:$E$86,"") -> 1 | N9: =_xlfn.XLOOKUP($C9,'GP4 (2)'!$B$6:$B$100,'GP4 (2)'!$E$6:$E$100,"") -> 1 | O9: =_xlfn.XLOOKUP($C9,'GP5 (1)'!$B$6:$B$100,'GP5 (1)'!$E$6:$E$100,"") | P9: =_xlfn.XLOOKUP($C9,'GP5 (2)'!$B$6:$B$100,'GP5 (2)'!$E$6:$E$100,"") | Q9: =SUM(R9:AC9) -> 251 | R9: =_xlfn.XLOOKUP($C9,'MP (1)'!$B$6:$B$100,'MP (1)'!$F$6:$F$100,"") -> 28 | S9: =_xlfn.XLOOKUP($C9,'MP (2)'!$B$6:$B$100,'MP (2)'!$F$6:$F$100,"") -> 25 | T9: =_xlfn.XLOOKUP($C9,'GP1 (1)'!$B$6:$B$100,'GP1 (1)'!$F$6:$F$100,"") -> 30 | U9: =_xlfn.XLOOKUP($C9,'GP1 (2)'!$B$6:$B$100,'GP1 (2)'!$F$6:$F$100,"") -> 30 | V9: =_xlfn.XLOOKUP($C9,'GP2 (1)'!$B$8:$B$107,'GP2 (1)'!$F$8:$F$107,"") -> 24 | W9: =_xlfn.XLOOKUP($C9,'GP2 (2)'!$B$6:$B$99,'GP2 (2)'!$F$6:$F$99,"") -> 23 | X9: =_xlfn.XLOOKUP($C9,'GP3 (1)'!$B$6:$B$100,'GP3 (1)'!$F$6:$F$100,"") -> 14 | Y9: =_xlfn.XLOOKUP($C9,'GP3 (2)'!$B$6:$B$100,'GP3 (2)'!$F$6:$F$100,"") -> 27 | Z9: =_xlfn.XLOOKUP($C9,'GP4 (1)'!$B$6:$B$86,'GP4 (1)'!$F$6:$F$86,"") -> 25 | AA9: =_xlfn.XLOOKUP($C9,'GP4 (2)'!$B$6:$B$100,'GP4 (2)'!$F$6:$F$100,"") -> 25 | AB9: =_xlfn.XLOOKUP($C9,'GP5 (1)'!$B$6:$B$100,'GP5 (1)'!$F$6:$F$100,"") | AC9: =_xlfn.XLOOKUP($C9,'GP5 (2)'!$B$6:$B$100,'GP5 (2)'!$F$6:$F$100,"") | AD9: =SUM(AE9:AO9) -> 155 | AE9: =_xlfn.XLOOKUP($C9,'MP (1)'!$B$6:$B$100,'MP (1)'!$H$6:$H$100,"") -> 14 | AF9: =_xlfn.XLOOKUP($C9,'MP (2)'!$B$6:$B$100,'MP (2)'!$H$6:$H$100,"") -> 20 | AG9: =_xlfn.XLOOKUP($C9,'GP1 (1)'!$B$6:$B$100,'GP1 (1)'!$H$6:$H$100,"") -> 18 | AH9: =_xlfn.XLOOKUP($C9,'GP1 (2)'!$B$6:$B$100,'GP1 (2)'!$H$6:$H$100,"") -> 20 | AI9: =_xlfn.XLOOKUP($C9,'GP2 (1)'!$B$8:$B$107,'GP2 (1)'!$H$8:$H$107,"") -> 11 | AJ9: =_xlfn.XLOOKUP($C9,'GP2 (2)'!$B$6:$B$99,'GP2 (2)'!$H$6:$H$99,"") -> 8 | AK9: =_xlfn.XLOOKUP($C9,'GP3 (1)'!$B$6:$B$100,'GP3 (1)'!$H$6:$H$100,"") -> 2 | AL9: =_xlfn.XLOOKUP($C9,'GP3 (2)'!$B$6:$B$100,'GP3 (2)'!$H$6:$H$100,"") -> 20 | AM9: =_xlfn.XLOOKUP($C9,'GP4 (1)'!$B$6:$B$86,'GP4 (1)'!$H$6:$H$86,"") -> 23 | AN9: =_xlfn.XLOOKUP($C9,'GP4 (2)'!$B$6:$B$100,'GP4 (2)'!$H$6:$H$100,"") -> 19 | AO9: =_xlfn.XLOOKUP($C9,'GP5 (1)'!$B$6:$B$100,'GP5 (1)'!$H$6:$H$100,"") | AP9: =_xlfn.XLOOKUP($C9,'GP5 (2)'!$B$6:$B$100,'GP5 (2)'!$H$6:$H$100,"")
A10: =ROW()-4 -> 6 | B10: 1 | C10: KROCHMALSKI Jakub | D10: =SUM(E10:P10) -> 7.8 | E10: =_xlfn.XLOOKUP($C10,'MP (1)'!$B$6:$B$100,'MP (1)'!$E$6:$E$100,"") -> 0.8 | F10: =_xlfn.XLOOKUP($C10,'MP (2)'!$B$6:$B$100,'MP (2)'!$E$6:$E$100,"") -> 1 | G10: =_xlfn.XLOOKUP($C10,'GP1 (1)'!$B$6:$B$100,'GP1 (1)'!$E$6:$E$100,"") -> 1 | H10: =_xlfn.XLOOKUP($C10,'GP1 (2)'!$B$6:$B$100,'GP1 (2)'!$E$6:$E$100,"") -> 1 | I10: =_xlfn.XLOOKUP($C10,'GP2 (1)'!$B$6:$B$107,'GP2 (1)'!$E$6:$E$107,"") -> 1 | J10: =_xlfn.XLOOKUP($C10,'GP2 (2)'!$B$6:$B$99,'GP2 (2)'!$E$6:$E$99,"") -> 1 | K10: =_xlfn.XLOOKUP($C10,'GP3 (1)'!$B$6:$B$100,'GP3 (1)'!$E$6:$E$100,"") | L10: =_xlfn.XLOOKUP($C10,'GP3 (2)'!$B$6:$B$100,'GP3 (2)'!$E$6:$E$100,"") | M10: =_xlfn.XLOOKUP($C10,'GP4 (1)'!$B$6:$B$86,'GP4 (1)'!$E$6:$E$86,"") -> 1 | N10: =_xlfn.XLOOKUP($C10,'GP4 (2)'!$B$6:$B$100,'GP4 (2)'!$E$6:$E$100,"") -> 1 | O10: =_xlfn.XLOOKUP($C10,'GP5 (1)'!$B$6:$B$100,'GP5 (1)'!$E$6:$E$100,"") | P10: =_xlfn.XLOOKUP($C10,'GP5 (2)'!$B$6:$B$100,'GP5 (2)'!$E$6:$E$100,"") | Q10: =SUM(R10:AC10) -> 204 | R10: =_xlfn.XLOOKUP($C10,'MP (1)'!$B$6:$B$100,'MP (1)'!$F$6:$F$100,"") -> 24 | S10: =_xlfn.XLOOKUP($C10,'MP (2)'!$B$6:$B$100,'MP (2)'!$F$6:$F$100,"") -> 25 | T10: =_xlfn.XLOOKUP($C10,'GP1 (1)'!$B$6:$B$100,'GP1 (1)'!$F$6:$F$100,"") -> 25 | U10: =_xlfn.XLOOKUP($C10,'GP1 (2)'!$B$6:$B$100,'GP1 (2)'!$F$6:$F$100,"") -> 30 | V10: =_xlfn.XLOOKUP($C10,'GP2 (1)'!$B$8:$B$107,'GP2 (1)'!$F$8:$F$107,"") -> 25 | W10: =_xlfn.XLOOKUP($C10,'GP2 (2)'!$B$6:$B$99,'GP2 (2)'!$F$6:$F$99,"") -> 25 | X10: =_xlfn.XLOOKUP($C10,'GP3 (1)'!$B$6:$B$100,'GP3 (1)'!$F$6:$F$100,"") | Y10: =_xlfn.XLOOKUP($C10,'GP3 (2)'!$B$6:$B$100,'GP3 (2)'!$F$6:$F$100,"") | Z10: =_xlfn.XLOOKUP($C10,'GP4 (1)'!$B$6:$B$86,'GP4 (1)'!$F$6:$F$86,"") -> 25 | AA10: =_xlfn.XLOOKUP($C10,'GP4 (2)'!$B$6:$B$100,'GP4 (2)'!$F$6:$F$100,"") -> 25 | AB10: =_xlfn.XLOOKUP($C10,'GP5 (1)'!$B$6:$B$100,'GP5 (1)'!$F$6:$F$100,"") | AC10: =_xlfn.XLOOKUP($C10,'GP5 (2)'!$B$6:$B$100,'GP5 (2)'!$F$6:$F$100,"") | AD10: =SUM(AE10:AO10) -> 149 | AE10: =_xlfn.XLOOKUP($C10,'MP (1)'!$B$6:$B$100,'MP (1)'!$H$6:$H$100,"") -> 14 | AF10: =_xlfn.XLOOKUP($C10,'MP (2)'!$B$6:$B$100,'MP (2)'!$H$6:$H$100,"") -> 21 | AG10: =_xlfn.XLOOKUP($C10,'GP1 (1)'!$B$6:$B$100,'GP1 (1)'!$H$6:$H$100,"") -> 21 | AH10: =_xlfn.XLOOKUP($C10,'GP1 (2)'!$B$6:$B$100,'GP1 (2)'!$H$6:$H$100,"") -> 24 | AI10: =_xlfn.XLOOKUP($C10,'GP2 (1)'!$B$8:$B$107,'GP2 (1)'!$H$8:$H$107,"") -> 12 | AJ10: =_xlfn.XLOOKUP($C10,'GP2 (2)'!$B$6:$B$99,'GP2 (2)'!$H$6:$H$99,"") -> 19 | AK10: =_xlfn.XLOOKUP($C10,'GP3 (1)'!$B$6:$B$100,'GP3 (1)'!$H$6:$H$100,"") | AL10: =_xlfn.XLOOKUP($C10,'GP3 (2)'!$B$6:$B$100,'GP3 (2)'!$H$6:$H$100,"") | AM10: =_xlfn.XLOOKUP($C10,'GP4 (1)'!$B$6:$B$86,'GP4 (1)'!$H$6:$H$86,"") -> 23 | AN10: =_xlfn.XLOOKUP($C10,'GP4 (2)'!$B$6:$B$100,'GP4 (2)'!$H$6:$H$100,"") -> 15 | AO10: =_xlfn.XLOOKUP($C10,'GP5 (1)'!$B$6:$B$100,'GP5 (1)'!$H$6:$H$100,"") | AP10: =_xlfn.XLOOKUP($C10,'GP5 (2)'!$B$6:$B$100,'GP5 (2)'!$H$6:$H$100,"")
A11: =ROW()-4 -> 7 | B11: 1 | C11: ZAWROTNIAK Przemysław | D11: =SUM(E11:P11) -> 6.85 | E11: =_xlfn.XLOOKUP($C11,'MP (1)'!$B$6:$B$100,'MP (1)'!$E$6:$E$100,"") -> 1 | F11: =_xlfn.XLOOKUP($C11,'MP (2)'!$B$6:$B$100,'MP (2)'!$E$6:$E$100,"") -> 1 | G11: =_xlfn.XLOOKUP($C11,'GP1 (1)'!$B$6:$B$100,'GP1 (1)'!$E$6:$E$100,"") -> 0.8 | H11: =_xlfn.XLOOKUP($C11,'GP1 (2)'!$B$6:$B$100,'GP1 (2)'!$E$6:$E$100,"") -> 0.83 | I11: =_xlfn.XLOOKUP($C11,'GP2 (1)'!$B$6:$B$107,'GP2 (1)'!$E$6:$E$107,"") | J11: =_xlfn.XLOOKUP($C11,'GP2 (2)'!$B$6:$B$99,'GP2 (2)'!$E$6:$E$99,"") | K11: =_xlfn.XLOOKUP($C11,'GP3 (1)'!$B$6:$B$100,'GP3 (1)'!$E$6:$E$100,"") -> 0.75 | L11: =_xlfn.XLOOKUP($C11,'GP3 (2)'!$B$6:$B$100,'GP3 (2)'!$E$6:$E$100,"") -> 1 | M11: =_xlfn.XLOOKUP($C11,'GP4 (1)'!$B$6:$B$86,'GP4 (1)'!$E$6:$E$86,"") -> 0.67 | N11: =_xlfn.XLOOKUP($C11,'GP4 (2)'!$B$6:$B$100,'GP4 (2)'!$E$6:$E$100,"") -> 0.8 | O11: =_xlfn.XLOOKUP($C11,'GP5 (1)'!$B$6:$B$100,'GP5 (1)'!$E$6:$E$100,"") | P11: =_xlfn.XLOOKUP($C11,'GP5 (2)'!$B$6:$B$100,'GP5 (2)'!$E$6:$E$100,"") | Q11: =SUM(R11:AC11) -> 190 | R11: =_xlfn.XLOOKUP($C11,'MP (1)'!$B$6:$B$100,'MP (1)'!$F$6:$F$100,"") -> 25 | S11: =_xlfn.XLOOKUP($C11,'MP (2)'!$B$6:$B$100,'MP (2)'!$F$6:$F$100,"") -> 25 | T11: =_xlfn.XLOOKUP($C11,'GP1 (1)'!$B$6:$B$100,'GP1 (1)'!$F$6:$F$100,"") -> 21 | U11: =_xlfn.XLOOKUP($C11,'GP1 (2)'!$B$6:$B$100,'GP1 (2)'!$F$6:$F$100,"") -> 26 | V11: =_xlfn.XLOOKUP($C11,'GP2 (1)'!$B$8:$B$107,'GP2 (1)'!$F$8:$F$107,"") | W11: =_xlfn.XLOOKUP($C11,'GP2 (2)'!$B$6:$B$99,'GP2 (2)'!$F$6:$F$99,"") | X11: =_xlfn.XLOOKUP($C11,'GP3 (1)'!$B$6:$B$100,'GP3 (1)'!$F$6:$F$100,"") -> 18 | Y11: =_xlfn.XLOOKUP($C11,'GP3 (2)'!$B$6:$B$100,'GP3 (2)'!$F$6:$F$100,"") -> 30 | Z11: =_xlfn.XLOOKUP($C11,'GP4 (1)'!$B$6:$B$86,'GP4 (1)'!$F$6:$F$86,"") -> 24 | AA11: =_xlfn.XLOOKUP($C11,'GP4 (2)'!$B$6:$B$100,'GP4 (2)'!$F$6:$F$100,"") -> 21 | AB11: =_xlfn.XLOOKUP($C11,'GP5 (1)'!$B$6:$B$100,'GP5 (1)'!$F$6:$F$100,"") | AC11: =_xlfn.XLOOKUP($C11,'GP5 (2)'!$B$6:$B$100,'GP5 (2)'!$F$6:$F$100,"") | AD11: =SUM(AE11:AO11) -> 96 | AE11: =_xlfn.XLOOKUP($C11,'MP (1)'!$B$6:$B$100,'MP (1)'!$H$6:$H$100,"") -> 16 | AF11: =_xlfn.XLOOKUP($C11,'MP (2)'!$B$6:$B$100,'MP (2)'!$H$6:$H$100,"") -> 16 | AG11: =_xlfn.XLOOKUP($C11,'GP1 (1)'!$B$6:$B$100,'GP1 (1)'!$H$6:$H$100,"") -> 6 | AH11: =_xlfn.XLOOKUP($C11,'GP1 (2)'!$B$6:$B$100,'GP1 (2)'!$H$6:$H$100,"") -> 15 | AI11: =_xlfn.XLOOKUP($C11,'GP2 (1)'!$B$8:$B$107,'GP2 (1)'!$H$8:$H$107,"") | AJ11: =_xlfn.XLOOKUP($C11,'GP2 (2)'!$B$6:$B$99,'GP2 (2)'!$H$6:$H$99,"") | AK11: =_xlfn.XLOOKUP($C11,'GP3 (1)'!$B$6:$B$100,'GP3 (1)'!$H$6:$H$100,"") -> 7 | AL11: =_xlfn.XLOOKUP($C11,'GP3 (2)'!$B$6:$B$100,'GP3 (2)'!$H$6:$H$100,"") -> 23 | AM11: =_xlfn.XLOOKUP($C11,'GP4 (1)'!$B$6:$B$86,'GP4 (1)'!$H$6:$H$86,"") -> 4 | AN11: =_xlfn.XLOOKUP($C11,'GP4 (2)'!$B$6:$B$100,'GP4 (2)'!$H$6:$H$100,"") -> 9 | AO11: =_xlfn.XLOOKUP($C11,'GP5 (1)'!$B$6:$B$100,'GP5 (1)'!$H$6:$H$100,"") | AP11: =_xlfn.XLOOKUP($C11,'GP5 (2)'!$B$6:$B$100,'GP5 (2)'!$H$6:$H$100,"")
A12: =ROW()-4 -> 8 | B12: 0 | C12: SAJEWICZ Izabela | D12: =SUM(E12:P12) -> 6.63 | E12: =_xlfn.XLOOKUP($C12,'MP (1)'!$B$6:$B$100,'MP (1)'!$E$6:$E$100,"") -> 0.4 | F12: =_xlfn.XLOOKUP($C12,'MP (2)'!$B$6:$B$100,'MP (2)'!$E$6:$E$100,"") -> 1 | G12: =_xlfn.XLOOKUP($C12,'GP1 (1)'!$B$6:$B$100,'GP1 (1)'!$E$6:$E$100,"") | H12: =_xlfn.XLOOKUP($C12,'GP1 (2)'!$B$6:$B$100,'GP1 (2)'!$E$6:$E$100,"") | I12: =_xlfn.XLOOKUP($C12,'GP2 (1)'!$B$6:$B$107,'GP2 (1)'!$E$6:$E$107,"") -> 1 | J12: =_xlfn.XLOOKUP($C12,'GP2 (2)'!$B$6:$B$99,'GP2 (2)'!$E$6:$E$99,"") -> 1 | K12: =_xlfn.XLOOKUP($C12,'GP3 (1)'!$B$6:$B$100,'GP3 (1)'!$E$6:$E$100,"") -> 0.8 | L12: =_xlfn.XLOOKUP($C12,'GP3 (2)'!$B$6:$B$100,'GP3 (2)'!$E$6:$E$100,"") -> 0.83 | M12: =_xlfn.XLOOKUP($C12,'GP4 (1)'!$B$6:$B$86,'GP4 (1)'!$E$6:$E$86,"") -> 0.8 | N12: =_xlfn.XLOOKUP($C12,'GP4 (2)'!$B$6:$B$100,'GP4 (2)'!$E$6:$E$100,"") -> 0.8 | O12: =_xlfn.XLOOKUP($C12,'GP5 (1)'!$B$6:$B$100,'GP5 (1)'!$E$6:$E$100,"") | P12: =_xlfn.XLOOKUP($C12,'GP5 (2)'!$B$6:$B$100,'GP5 (2)'!$E$6:$E$100,"") | Q12: =SUM(R12:AC12) -> 190 | R12: =_xlfn.XLOOKUP($C12,'MP (1)'!$B$6:$B$100,'MP (1)'!$F$6:$F$100,"") -> 18 | S12: =_xlfn.XLOOKUP($C12,'MP (2)'!$B$6:$B$100,'MP (2)'!$F$6:$F$100,"") -> 25 | T12: =_xlfn.XLOOKUP($C12,'GP1 (1)'!$B$6:$B$100,'GP1 (1)'!$F$6:$F$100,"") | U12: =_xlfn.XLOOKUP($C12,'GP1 (2)'!$B$6:$B$100,'GP1 (2)'!$F$6:$F$100,"") | V12: =_xlfn.XLOOKUP($C12,'GP2 (1)'!$B$8:$B$107,'GP2 (1)'!$F$8:$F$107,"") -> 25 | W12: =_xlfn.XLOOKUP($C12,'GP2 (2)'!$B$6:$B$99,'GP2 (2)'!$F$6:$F$99,"") -> 25 | X12: =_xlfn.XLOOKUP($C12,'GP3 (1)'!$B$6:$B$100,'GP3 (1)'!$F$6:$F$100,"") -> 22 | Y12: =_xlfn.XLOOKUP($C12,'GP3 (2)'!$B$6:$B$100,'GP3 (2)'!$F$6:$F$100,"") -> 28 | Z12: =_xlfn.XLOOKUP($C12,'GP4 (1)'!$B$6:$B$86,'GP4 (1)'!$F$6:$F$86,"") -> 24 | AA12: =_xlfn.XLOOKUP($C12,'GP4 (2)'!$B$6:$B$100,'GP4 (2)'!$F$6:$F$100,"") -> 23 | AB12: =_xlfn.XLOOKUP($C12,'GP5 (1)'!$B$6:$B$100,'GP5 (1)'!$F$6:$F$100,"") | AC12: =_xlfn.XLOOKUP($C12,'GP5 (2)'!$B$6:$B$100,'GP5 (2)'!$F$6:$F$100,"") | AD12: =SUM(AE12:AO12) -> 94 | AE12: =_xlfn.XLOOKUP($C12,'MP (1)'!$B$6:$B$100,'MP (1)'!$H$6:$H$100,"") -> -1 | AF12: =_xlfn.XLOOKUP($C12,'MP (2)'!$B$6:$B$100,'MP (2)'!$H$6:$H$100,"") -> 16 | AG12: =_xlfn.XLOOKUP($C12,'GP1 (1)'!$B$6:$B$100,'GP1 (1)'!$H$6:$H$100,"") | AH12: =_xlfn.XLOOKUP($C12,'GP1 (2)'!$B$6:$B$100,'GP1 (2)'!$H$6:$H$100,"") | AI12: =_xlfn.XLOOKUP($C12,'GP2 (1)'!$B$8:$B$107,'GP2 (1)'!$H$8:$H$107,"") -> 16 | AJ12: =_xlfn.XLOOKUP($C12,'GP2 (2)'!$B$6:$B$99,'GP2 (2)'!$H$6:$H$99,"") -> 17 | AK12: =_xlfn.XLOOKUP($C12,'GP3 (1)'!$B$6:$B$100,'GP3 (1)'!$H$6:$H$100,"") -> 11 | AL12: =_xlfn.XLOOKUP($C12,'GP3 (2)'!$B$6:$B$100,'GP3 (2)'!$H$6:$H$100,"") -> 7 | AM12: =_xlfn.XLOOKUP($C12,'GP4 (1)'!$B$6:$B$86,'GP4 (1)'!$H$6:$H$86,"") -> 13 | AN12: =_xlfn.XLOOKUP($C12,'GP4 (2)'!$B$6:$B$100,'GP4 (2)'!$H$6:$H$100,"") -> 15 | AO12: =_xlfn.XLOOKUP($C12,'GP5 (1)'!$B$6:$B$100,'GP5 (1)'!$H$6:$H$100,"") | AP12: =_xlfn.XLOOKUP($C12,'GP5 (2)'!$B$6:$B$100,'GP5 (2)'!$H$6:$H$100,"")
A13: =ROW()-4 -> 9 | B13: 2 | C13: RUDY Andrzej | D13: =SUM(E13:P13) -> 6.1 | E13: =_xlfn.XLOOKUP($C13,'MP (1)'!$B$6:$B$100,'MP (1)'!$E$6:$E$100,"") -> 0.6 | F13: =_xlfn.XLOOKUP($C13,'MP (2)'!$B$6:$B$100,'MP (2)'!$E$6:$E$100,"") -> 0.8 | G13: =_xlfn.XLOOKUP($C13,'GP1 (1)'!$B$6:$B$100,'GP1 (1)'!$E$6:$E$100,"") | H13: =_xlfn.XLOOKUP($C13,'GP1 (2)'!$B$6:$B$100,'GP1 (2)'!$E$6:$E$100,"") | I13: =_xlfn.XLOOKUP($C13,'GP2 (1)'!$B$6:$B$107,'GP2 (1)'!$E$6:$E$107,"") -> 0.8 | J13: =_xlfn.XLOOKUP($C13,'GP2 (2)'!$B$6:$B$99,'GP2 (2)'!$E$6:$E$99,"") -> 0.8 | K13: =_xlfn.XLOOKUP($C13,'GP3 (1)'!$B$6:$B$100,'GP3 (1)'!$E$6:$E$100,"") | L13: =_xlfn.XLOOKUP($C13,'GP3 (2)'!$B$6:$B$100,'GP3 (2)'!$E$6:$E$100,"") | M13: =_xlfn.XLOOKUP($C13,'GP4 (1)'!$B$6:$B$86,'GP4 (1)'!$E$6:$E$86,"") -> 0.8 | N13: =_xlfn.XLOOKUP($C13,'GP4 (2)'!$B$6:$B$100,'GP4 (2)'!$E$6:$E$100,"") -> 0.8 | O13: =_xlfn.XLOOKUP($C13,'GP5 (1)'!$B$6:$B$100,'GP5 (1)'!$E$6:$E$100,"") -> 0.75 | P13: =_xlfn.XLOOKUP($C13,'GP5 (2)'!$B$6:$B$100,'GP5 (2)'!$E$6:$E$100,"") -> 0.75 | Q13: =SUM(R13:AC13) -> 173 | R13: =_xlfn.XLOOKUP($C13,'MP (1)'!$B$6:$B$100,'MP (1)'!$F$6:$F$100,"") -> 23 | S13: =_xlfn.XLOOKUP($C13,'MP (2)'!$B$6:$B$100,'MP (2)'!$F$6:$F$100,"") -> 22 | T13: =_xlfn.XLOOKUP($C13,'GP1 (1)'!$B$6:$B$100,'GP1 (1)'!$F$6:$F$100,"") | U13: =_xlfn.XLOOKUP($C13,'GP1 (2)'!$B$6:$B$100,'GP1 (2)'!$F$6:$F$100,"") | V13: =_xlfn.XLOOKUP($C13,'GP2 (1)'!$B$8:$B$107,'GP2 (1)'!$F$8:$F$107,"") -> 22 | W13: =_xlfn.XLOOKUP($C13,'GP2 (2)'!$B$6:$B$99,'GP2 (2)'!$F$6:$F$99,"") -> 24 | X13: =_xlfn.XLOOKUP($C13,'GP3 (1)'!$B$6:$B$100,'GP3 (1)'!$F$6:$F$100,"") | Y13: =_xlfn.XLOOKUP($C13,'GP3 (2)'!$B$6:$B$100,'GP3 (2)'!$F$6:$F$100,"") | Z13: =_xlfn.XLOOKUP($C13,'GP4 (1)'!$B$6:$B$86,'GP4 (1)'!$F$6:$F$86,"") -> 24 | AA13: =_xlfn.XLOOKUP($C13,'GP4 (2)'!$B$6:$B$100,'GP4 (2)'!$F$6:$F$100,"") -> 24 | AB13: =_xlfn.XLOOKUP($C13,'GP5 (1)'!$B$6:$B$100,'GP5 (1)'!$F$6:$F$100,"") -> 18 | AC13: =_xlfn.XLOOKUP($C13,'GP5 (2)'!$B$6:$B$100,'GP5 (2)'!$F$6:$F$100,"") -> 16 | AD13: =SUM(AE13:AO13) -> 57 | AE13: =_xlfn.XLOOKUP($C13,'MP (1)'!$B$6:$B$100,'MP (1)'!$H$6:$H$100,"") -> 7 | AF13: =_xlfn.XLOOKUP($C13,'MP (2)'!$B$6:$B$100,'MP (2)'!$H$6:$H$100,"") -> 11 | AG13: =_xlfn.XLOOKUP($C13,'GP1 (1)'!$B$6:$B$100,'GP1 (1)'!$H$6:$H$100,"") | AH13: =_xlfn.XLOOKUP($C13,'GP1 (2)'!$B$6:$B$100,'GP1 (2)'!$H$6:$H$100,"") | AI13: =_xlfn.XLOOKUP($C13,'GP2 (1)'!$B$8:$B$107,'GP2 (1)'!$H$8:$H$107,"") -> 6 | AJ13: =_xlfn.XLOOKUP($C13,'GP2 (2)'!$B$6:$B$99,'GP2 (2)'!$H$6:$H$99,"") -> 6 | AK13: =_xlfn.XLOOKUP($C13,'GP3 (1)'!$B$6:$B$100,'GP3 (1)'!$H$6:$H$100,"") | AL13: =_xlfn.XLOOKUP($C13,'GP3 (2)'!$B$6:$B$100,'GP3 (2)'!$H$6:$H$100,"") | AM13: =_xlfn.XLOOKUP($C13,'GP4 (1)'!$B$6:$B$86,'GP4 (1)'!$H$6:$H$86,"") -> 13 | AN13: =_xlfn.XLOOKUP($C13,'GP4 (2)'!$B$6:$B$100,'GP4 (2)'!$H$6:$H$100,"") -> 9 | AO13: =_xlfn.XLOOKUP($C13,'GP5 (1)'!$B$6:$B$100,'GP5 (1)'!$H$6:$H$100,"") -> 5 | AP13: =_xlfn.XLOOKUP($C13,'GP5 (2)'!$B$6:$B$100,'GP5 (2)'!$H$6:$H$100,"") -> 6
A14: =ROW()-4 -> 10 | B14: 2 | C14: GAJDA Zbigniew | D14: =SUM(E14:P14) -> 5.77 | E14: =_xlfn.XLOOKUP($C14,'MP (1)'!$B$6:$B$100,'MP (1)'!$E$6:$E$100,"") -> 0.8 | F14: =_xlfn.XLOOKUP($C14,'MP (2)'!$B$6:$B$100,'MP (2)'!$E$6:$E$100,"") -> 0.6 | G14: =_xlfn.XLOOKUP($C14,'GP1 (1)'!$B$6:$B$100,'GP1 (1)'!$E$6:$E$100,"") -> 0.6 | H14: =_xlfn.XLOOKUP($C14,'GP1 (2)'!$B$6:$B$100,'GP1 (2)'!$E$6:$E$100,"") -> 0.67 | I14: =_xlfn.XLOOKUP($C14,'GP2 (1)'!$B$6:$B$107,'GP2 (1)'!$E$6:$E$107,"") | J14: =_xlfn.XLOOKUP($C14,'GP2 (2)'!$B$6:$B$99,'GP2 (2)'!$E$6:$E$99,"") | K14: =_xlfn.XLOOKUP($C14,'GP3 (1)'!$B$6:$B$100,'GP3 (1)'!$E$6:$E$100,"") | L14: =_xlfn.XLOOKUP($C14,'GP3 (2)'!$B$6:$B$100,'GP3 (2)'!$E$6:$E$100,"") | M14: =_xlfn.XLOOKUP($C14,'GP4 (1)'!$B$6:$B$86,'GP4 (1)'!$E$6:$E$86,"") -> 0.8 | N14: =_xlfn.XLOOKUP($C14,'GP4 (2)'!$B$6:$B$100,'GP4 (2)'!$E$6:$E$100,"") -> 0.8 | O14: =_xlfn.XLOOKUP($C14,'GP5 (1)'!$B$6:$B$100,'GP5 (1)'!$E$6:$E$100,"") -> 0.75 | P14: =_xlfn.XLOOKUP($C14,'GP5 (2)'!$B$6:$B$100,'GP5 (2)'!$E$6:$E$100,"") -> 0.75 | Q14: =SUM(R14:AC14) -> 169 | R14: =_xlfn.XLOOKUP($C14,'MP (1)'!$B$6:$B$100,'MP (1)'!$F$6:$F$100,"") -> 23 | S14: =_xlfn.XLOOKUP($C14,'MP (2)'!$B$6:$B$100,'MP (2)'!$F$6:$F$100,"") -> 17 | T14: =_xlfn.XLOOKUP($C14,'GP1 (1)'!$B$6:$B$100,'GP1 (1)'!$F$6:$F$100,"") -> 20 | U14: =_xlfn.XLOOKUP($C14,'GP1 (2)'!$B$6:$B$100,'GP1 (2)'!$F$6:$F$100,"") -> 27 | V14: =_xlfn.XLOOKUP($C14,'GP2 (1)'!$B$8:$B$107,'GP2 (1)'!$F$8:$F$107,"") | W14: =_xlfn.XLOOKUP($C14,'GP2 (2)'!$B$6:$B$99,'GP2 (2)'!$F$6:$F$99,"") | X14: =_xlfn.XLOOKUP($C14,'GP3 (1)'!$B$6:$B$100,'GP3 (1)'!$F$6:$F$100,"") | Y14: =_xlfn.XLOOKUP($C14,'GP3 (2)'!$B$6:$B$100,'GP3 (2)'!$F$6:$F$100,"") | Z14: =_xlfn.XLOOKUP($C14,'GP4 (1)'!$B$6:$B$86,'GP4 (1)'!$F$6:$F$86,"") -> 24 | AA14: =_xlfn.XLOOKUP($C14,'GP4 (2)'!$B$6:$B$100,'GP4 (2)'!$F$6:$F$100,"") -> 23 | AB14: =_xlfn.XLOOKUP($C14,'GP5 (1)'!$B$6:$B$100,'GP5 (1)'!$F$6:$F$100,"") -> 17 | AC14: =_xlfn.XLOOKUP($C14,'GP5 (2)'!$B$6:$B$100,'GP5 (2)'!$F$6:$F$100,"") -> 18 | AD14: =SUM(AE14:AO14) -> 61 | AE14: =_xlfn.XLOOKUP($C14,'MP (1)'!$B$6:$B$100,'MP (1)'!$H$6:$H$100,"") -> 10 | AF14: =_xlfn.XLOOKUP($C14,'MP (2)'!$B$6:$B$100,'MP (2)'!$H$6:$H$100,"") -> 2 | AG14: =_xlfn.XLOOKUP($C14,'GP1 (1)'!$B$6:$B$100,'GP1 (1)'!$H$6:$H$100,"") -> 3 | AH14: =_xlfn.XLOOKUP($C14,'GP1 (2)'!$B$6:$B$100,'GP1 (2)'!$H$6:$H$100,"") -> 12 | AI14: =_xlfn.XLOOKUP($C14,'GP2 (1)'!$B$8:$B$107,'GP2 (1)'!$H$8:$H$107,"") | AJ14: =_xlfn.XLOOKUP($C14,'GP2 (2)'!$B$6:$B$99,'GP2 (2)'!$H$6:$H$99,"") | AK14: =_xlfn.XLOOKUP($C14,'GP3 (1)'!$B$6:$B$100,'GP3 (1)'!$H$6:$H$100,"") | AL14: =_xlfn.XLOOKUP($C14,'GP3 (2)'!$B$6:$B$100,'GP3 (2)'!$H$6:$H$100,"") | AM14: =_xlfn.XLOOKUP($C14,'GP4 (1)'!$B$6:$B$86,'GP4 (1)'!$H$6:$H$86,"") -> 14 | AN14: =_xlfn.XLOOKUP($C14,'GP4 (2)'!$B$6:$B$100,'GP4 (2)'!$H$6:$H$100,"") -> 9 | AO14: =_xlfn.XLOOKUP($C14,'GP5 (1)'!$B$6:$B$100,'GP5 (1)'!$H$6:$H$100,"") -> 11 | AP14: =_xlfn.XLOOKUP($C14,'GP5 (2)'!$B$6:$B$100,'GP5 (2)'!$H$6:$H$100,"") -> 12
A15: =ROW()-4 -> 11 | B15: 2 | C15: WINGROWICZ Mariusz | D15: =SUM(E15:P15) -> 5.53 | E15: =_xlfn.XLOOKUP($C15,'MP (1)'!$B$6:$B$100,'MP (1)'!$E$6:$E$100,"") -> 0.67 | F15: =_xlfn.XLOOKUP($C15,'MP (2)'!$B$6:$B$100,'MP (2)'!$E$6:$E$100,"") -> 0.83 | G15: =_xlfn.XLOOKUP($C15,'GP1 (1)'!$B$6:$B$100,'GP1 (1)'!$E$6:$E$100,"") -> 0.33 | H15: =_xlfn.XLOOKUP($C15,'GP1 (2)'!$B$6:$B$100,'GP1 (2)'!$E$6:$E$100,"") -> 0.5 | I15: =_xlfn.XLOOKUP($C15,'GP2 (1)'!$B$6:$B$107,'GP2 (1)'!$E$6:$E$107,"") -> 0.8 | J15: =_xlfn.XLOOKUP($C15,'GP2 (2)'!$B$6:$B$99,'GP2 (2)'!$E$6:$E$99,"") -> 0.8 | K15: =_xlfn.XLOOKUP($C15,'GP3 (1)'!$B$6:$B$100,'GP3 (1)'!$E$6:$E$100,"") | L15: =_xlfn.XLOOKUP($C15,'GP3 (2)'!$B$6:$B$100,'GP3 (2)'!$E$6:$E$100,"") | M15: =_xlfn.XLOOKUP($C15,'GP4 (1)'!$B$6:$B$86,'GP4 (1)'!$E$6:$E$86,"") -> 0.8 | N15: =_xlfn.XLOOKUP($C15,'GP4 (2)'!$B$6:$B$100,'GP4 (2)'!$E$6:$E$100,"") -> 0.8 | O15: =_xlfn.XLOOKUP($C15,'GP5 (1)'!$B$6:$B$100,'GP5 (1)'!$E$6:$E$100,"") | P15: =_xlfn.XLOOKUP($C15,'GP5 (2)'!$B$6:$B$100,'GP5 (2)'!$E$6:$E$100,"") | Q15: =SUM(R15:AC15) -> 177 | R15: =_xlfn.XLOOKUP($C15,'MP (1)'!$B$6:$B$100,'MP (1)'!$F$6:$F$100,"") -> 27 | S15: =_xlfn.XLOOKUP($C15,'MP (2)'!$B$6:$B$100,'MP (2)'!$F$6:$F$100,"") -> 27 | T15: =_xlfn.XLOOKUP($C15,'GP1 (1)'!$B$6:$B$100,'GP1 (1)'!$F$6:$F$100,"") -> 16 | U15: =_xlfn.XLOOKUP($C15,'GP1 (2)'!$B$6:$B$100,'GP1 (2)'!$F$6:$F$100,"") -> 20 | V15: =_xlfn.XLOOKUP($C15,'GP2 (1)'!$B$8:$B$107,'GP2 (1)'!$F$8:$F$107,"") -> 24 | W15: =_xlfn.XLOOKUP($C15,'GP2 (2)'!$B$6:$B$99,'GP2 (2)'!$F$6:$F$99,"") -> 21 | X15: =_xlfn.XLOOKUP($C15,'GP3 (1)'!$B$6:$B$100,'GP3 (1)'!$F$6:$F$100,"") | Y15: =_xlfn.XLOOKUP($C15,'GP3 (2)'!$B$6:$B$100,'GP3 (2)'!$F$6:$F$100,"") | Z15: =_xlfn.XLOOKUP($C15,'GP4 (1)'!$B$6:$B$86,'GP4 (1)'!$F$6:$F$86,"") -> 20 | AA15: =_xlfn.XLOOKUP($C15,'GP4 (2)'!$B$6:$B$100,'GP4 (2)'!$F$6:$F$100,"") -> 22 | AB15: =_xlfn.XLOOKUP($C15,'GP5 (1)'!$B$6:$B$100,'GP5 (1)'!$F$6:$F$100,"") | AC15: =_xlfn.XLOOKUP($C15,'GP5 (2)'!$B$6:$B$100,'GP5 (2)'!$F$6:$F$100,"") | AD15: =SUM(AE15:AO15) -> 61 | AE15: =_xlfn.XLOOKUP($C15,'MP (1)'!$B$6:$B$100,'MP (1)'!$H$6:$H$100,"") -> 11 | AF15: =_xlfn.XLOOKUP($C15,'MP (2)'!$B$6:$B$100,'MP (2)'!$H$6:$H$100,"") -> 16 | AG15: =_xlfn.XLOOKUP($C15,'GP1 (1)'!$B$6:$B$100,'GP1 (1)'!$H$6:$H$100,"") -> -6 | AH15: =_xlfn.XLOOKUP($C15,'GP1 (2)'!$B$6:$B$100,'GP1 (2)'!$H$6:$H$100,"") -> 1 | AI15: =_xlfn.XLOOKUP($C15,'GP2 (1)'!$B$8:$B$107,'GP2 (1)'!$H$8:$H$107,"") -> 15 | AJ15: =_xlfn.XLOOKUP($C15,'GP2 (2)'!$B$6:$B$99,'GP2 (2)'!$H$6:$H$99,"") -> 9 | AK15: =_xlfn.XLOOKUP($C15,'GP3 (1)'!$B$6:$B$100,'GP3 (1)'!$H$6:$H$100,"") | AL15: =_xlfn.XLOOKUP($C15,'GP3 (2)'!$B$6:$B$100,'GP3 (2)'!$H$6:$H$100,"") | AM15: =_xlfn.XLOOKUP($C15,'GP4 (1)'!$B$6:$B$86,'GP4 (1)'!$H$6:$H$86,"") -> 7 | AN15: =_xlfn.XLOOKUP($C15,'GP4 (2)'!$B$6:$B$100,'GP4 (2)'!$H$6:$H$100,"") -> 8 | AO15: =_xlfn.XLOOKUP($C15,'GP5 (1)'!$B$6:$B$100,'GP5 (1)'!$H$6:$H$100,"") | AP15: =_xlfn.XLOOKUP($C15,'GP5 (2)'!$B$6:$B$100,'GP5 (2)'!$H$6:$H$100,"")
A16: =ROW()-4 -> 12 | B16: 2 | C16: KACZMAREK Paweł | D16: =SUM(E16:P16) -> 5.2 | E16: =_xlfn.XLOOKUP($C16,'MP (1)'!$B$6:$B$100,'MP (1)'!$E$6:$E$100,"") -> 0.33 | F16: =_xlfn.XLOOKUP($C16,'MP (2)'!$B$6:$B$100,'MP (2)'!$E$6:$E$100,"") -> 0.33 | G16: =_xlfn.XLOOKUP($C16,'GP1 (1)'!$B$6:$B$100,'GP1 (1)'!$E$6:$E$100,"") -> 0.67 | H16: =_xlfn.XLOOKUP($C16,'GP1 (2)'!$B$6:$B$100,'GP1 (2)'!$E$6:$E$100,"") -> 0.5 | I16: =_xlfn.XLOOKUP($C16,'GP2 (1)'!$B$8:$B$107,'GP2 (1)'!$E$8:$E$107,"") -> 0.4 | J16: =_xlfn.XLOOKUP($C16,'GP2 (2)'!$B$6:$B$99,'GP2 (2)'!$E$6:$E$99,"") -> 0.2 | K16: =_xlfn.XLOOKUP($C16,'GP3 (1)'!$B$6:$B$100,'GP3 (1)'!$E$6:$E$100,"") -> 0.6 | L16: =_xlfn.XLOOKUP($C16,'GP3 (2)'!$B$6:$B$100,'GP3 (2)'!$E$6:$E$100,"") -> 0.67 | M16: =_xlfn.XLOOKUP($C16,'GP4 (1)'!$B$6:$B$86,'GP4 (1)'!$E$6:$E$86,"") | N16: =_xlfn.XLOOKUP($C16,'GP4 (2)'!$B$6:$B$100,'GP4 (2)'!$E$6:$E$100,"") | O16: =_xlfn.XLOOKUP($C16,'GP5 (1)'!$B$6:$B$100,'GP5 (1)'!$E$6:$E$100,"") -> 0.75 | P16: =_xlfn.XLOOKUP($C16,'GP5 (2)'!$B$6:$B$100,'GP5 (2)'!$E$6:$E$100,"") -> 0.75 | Q16: =SUM(R16:AC16) -> 194 | R16: =_xlfn.XLOOKUP($C16,'MP (1)'!$B$6:$B$100,'MP (1)'!$F$6:$F$100,"") -> 17 | S16: =_xlfn.XLOOKUP($C16,'MP (2)'!$B$6:$B$100,'MP (2)'!$F$6:$F$100,"") -> 19 | T16: =_xlfn.XLOOKUP($C16,'GP1 (1)'!$B$6:$B$100,'GP1 (1)'!$F$6:$F$100,"") -> 27 | U16: =_xlfn.XLOOKUP($C16,'GP1 (2)'!$B$6:$B$100,'GP1 (2)'!$F$6:$F$100,"") -> 22 | V16: =_xlfn.XLOOKUP($C16,'GP2 (1)'!$B$8:$B$107,'GP2 (1)'!$F$8:$F$107,"") -> 18 | W16: =_xlfn.XLOOKUP($C16,'GP2 (2)'!$B$6:$B$99,'GP2 (2)'!$F$6:$F$99,"") -> 11 | X16: =_xlfn.XLOOKUP($C16,'GP3 (1)'!$B$6:$B$100,'GP3 (1)'!$F$6:$F$100,"") -> 21 | Y16: =_xlfn.XLOOKUP($C16,'GP3 (2)'!$B$6:$B$100,'GP3 (2)'!$F$6:$F$100,"") -> 23 | Z16: =_xlfn.XLOOKUP($C16,'GP4 (1)'!$B$6:$B$86,'GP4 (1)'!$F$6:$F$86,"") | AA16: =_xlfn.XLOOKUP($C16,'GP4 (2)'!$B$6:$B$100,'GP4 (2)'!$F$6:$F$100,"") | AB16: =_xlfn.XLOOKUP($C16,'GP5 (1)'!$B$6:$B$100,'GP5 (1)'!$F$6:$F$100,"") -> 18 | AC16: =_xlfn.XLOOKUP($C16,'GP5 (2)'!$B$6:$B$100,'GP5 (2)'!$F$6:$F$100,"") -> 18 | AD16: =SUM(AE16:AO16) -> 2 | AE16: =_xlfn.XLOOKUP($C16,'MP (1)'!$B$6:$B$100,'MP (1)'!$H$6:$H$100,"") -> -5 | AF16: =_xlfn.XLOOKUP($C16,'MP (2)'!$B$6:$B$100,'MP (2)'!$H$6:$H$100,"") -> -5 | AG16: =_xlfn.XLOOKUP($C16,'GP1 (1)'!$B$6:$B$100,'GP1 (1)'!$H$6:$H$100,"") -> 7 | AH16: =_xlfn.XLOOKUP($C16,'GP1 (2)'!$B$6:$B$100,'GP1 (2)'!$H$6:$H$100,"") -> -2 | AI16: =_xlfn.XLOOKUP($C16,'GP2 (1)'!$B$8:$B$107,'GP2 (1)'!$H$8:$H$107,"") -> -2 | AJ16: =_xlfn.XLOOKUP($C16,'GP2 (2)'!$B$6:$B$99,'GP2 (2)'!$H$6:$H$99,"") -> -10 | AK16: =_xlfn.XLOOKUP($C16,'GP3 (1)'!$B$6:$B$100,'GP3 (1)'!$H$6:$H$100,"") -> 6 | AL16: =_xlfn.XLOOKUP($C16,'GP3 (2)'!$B$6:$B$100,'GP3 (2)'!$H$6:$H$100,"") -> 6 | AM16: =_xlfn.XLOOKUP($C16,'GP4 (1)'!$B$6:$B$86,'GP4 (1)'!$H$6:$H$86,"") | AN16: =_xlfn.XLOOKUP($C16,'GP4 (2)'!$B$6:$B$100,'GP4 (2)'!$H$6:$H$100,"") | AO16: =_xlfn.XLOOKUP($C16,'GP5 (1)'!$B$6:$B$100,'GP5 (1)'!$H$6:$H$100,"") -> 7 | AP16: =_xlfn.XLOOKUP($C16,'GP5 (2)'!$B$6:$B$100,'GP5 (2)'!$H$6:$H$100,"") -> 6
A17: =ROW()-4 -> 13 | B17: 3 | C17: OSSOWSKI Wojciech | D17: =SUM(E17:P17) -> 5.07 | E17: =_xlfn.XLOOKUP($C17,'MP (1)'!$B$6:$B$100,'MP (1)'!$E$6:$E$100,"") -> 0.5 | F17: =_xlfn.XLOOKUP($C17,'MP (2)'!$B$6:$B$100,'MP (2)'!$E$6:$E$100,"") -> 0.4 | G17: =_xlfn.XLOOKUP($C17,'GP1 (1)'!$B$6:$B$100,'GP1 (1)'!$E$6:$E$100,"") -> 0.5 | H17: =_xlfn.XLOOKUP($C17,'GP1 (2)'!$B$6:$B$100,'GP1 (2)'!$E$6:$E$100,"") -> 0.6 | I17: =_xlfn.XLOOKUP($C17,'GP2 (1)'!$B$6:$B$107,'GP2 (1)'!$E$6:$E$107,"") -> 0.5 | J17: =_xlfn.XLOOKUP($C17,'GP2 (2)'!$B$6:$B$99,'GP2 (2)'!$E$6:$E$99,"") -> 0.2 | K17: =_xlfn.XLOOKUP($C17,'GP3 (1)'!$B$6:$B$100,'GP3 (1)'!$E$6:$E$100,"") -> 0.6 | L17: =_xlfn.XLOOKUP($C17,'GP3 (2)'!$B$6:$B$100,'GP3 (2)'!$E$6:$E$100,"") -> 0.5 | M17: =_xlfn.XLOOKUP($C17,'GP4 (1)'!$B$6:$B$86,'GP4 (1)'!$E$6:$E$86,"") -> 0.67 | N17: =_xlfn.XLOOKUP($C17,'GP4 (2)'!$B$6:$B$100,'GP4 (2)'!$E$6:$E$100,"") -> 0.6 | O17: =_xlfn.XLOOKUP($C17,'GP5 (1)'!$B$6:$B$100,'GP5 (1)'!$E$6:$E$100,"") | P17: =_xlfn.XLOOKUP($C17,'GP5 (2)'!$B$6:$B$100,'GP5 (2)'!$E$6:$E$100,"") | Q17: =SUM(R17:AC17) -> 194 | R17: =_xlfn.XLOOKUP($C17,'MP (1)'!$B$6:$B$100,'MP (1)'!$F$6:$F$100,"") -> 21 | S17: =_xlfn.XLOOKUP($C17,'MP (2)'!$B$6:$B$100,'MP (2)'!$F$6:$F$100,"") -> 15 | T17: =_xlfn.XLOOKUP($C17,'GP1 (1)'!$B$6:$B$100,'GP1 (1)'!$F$6:$F$100,"") -> 22 | U17: =_xlfn.XLOOKUP($C17,'GP1 (2)'!$B$6:$B$100,'GP1 (2)'!$F$6:$F$100,"") -> 18 | V17: =_xlfn.XLOOKUP($C17,'GP2 (1)'!$B$8:$B$107,'GP2 (1)'!$F$8:$F$107,"") -> 20 | W17: =_xlfn.XLOOKUP($C17,'GP2 (2)'!$B$6:$B$99,'GP2 (2)'!$F$6:$F$99,"") -> 17 | X17: =_xlfn.XLOOKUP($C17,'GP3 (1)'!$B$6:$B$100,'GP3 (1)'!$F$6:$F$100,"") -> 18 | Y17: =_xlfn.XLOOKUP($C17,'GP3 (2)'!$B$6:$B$100,'GP3 (2)'!$F$6:$F$100,"") -> 17 | Z17: =_xlfn.XLOOKUP($C17,'GP4 (1)'!$B$6:$B$86,'GP4 (1)'!$F$6:$F$86,"") -> 28 | AA17: =_xlfn.XLOOKUP($C17,'GP4 (2)'!$B$6:$B$100,'GP4 (2)'!$F$6:$F$100,"") -> 18 | AB17: =_xlfn.XLOOKUP($C17,'GP5 (1)'!$B$6:$B$100,'GP5 (1)'!$F$6:$F$100,"") | AC17: =_xlfn.XLOOKUP($C17,'GP5 (2)'!$B$6:$B$100,'GP5 (2)'!$F$6:$F$100,"") | AD17: =SUM(AE17:AO17) -> 2 | AE17: =_xlfn.XLOOKUP($C17,'MP (1)'!$B$6:$B$100,'MP (1)'!$H$6:$H$100,"") -> 2 | AF17: =_xlfn.XLOOKUP($C17,'MP (2)'!$B$6:$B$100,'MP (2)'!$H$6:$H$100,"") -> -1 | AG17: =_xlfn.XLOOKUP($C17,'GP1 (1)'!$B$6:$B$100,'GP1 (1)'!$H$6:$H$100,"") -> 2 | AH17: =_xlfn.XLOOKUP($C17,'GP1 (2)'!$B$6:$B$100,'GP1 (2)'!$H$6:$H$100,"") -> -1 | AI17: =_xlfn.XLOOKUP($C17,'GP2 (1)'!$B$8:$B$107,'GP2 (1)'!$H$8:$H$107,"") -> 1 | AJ17: =_xlfn.XLOOKUP($C17,'GP2 (2)'!$B$6:$B$99,'GP2 (2)'!$H$6:$H$99,"") -> -4 | AK17: =_xlfn.XLOOKUP($C17,'GP3 (1)'!$B$6:$B$100,'GP3 (1)'!$H$6:$H$100,"") -> 1 | AL17: =_xlfn.XLOOKUP($C17,'GP3 (2)'!$B$6:$B$100,'GP3 (2)'!$H$6:$H$100,"") -> -4 | AM17: =_xlfn.XLOOKUP($C17,'GP4 (1)'!$B$6:$B$86,'GP4 (1)'!$H$6:$H$86,"") -> 7 | AN17: =_xlfn.XLOOKUP($C17,'GP4 (2)'!$B$6:$B$100,'GP4 (2)'!$H$6:$H$100,"") -> -1 | AO17: =_xlfn.XLOOKUP($C17,'GP5 (1)'!$B$6:$B$100,'GP5 (1)'!$H$6:$H$100,"") | AP17: =_xlfn.XLOOKUP($C17,'GP5 (2)'!$B$6:$B$100,'GP5 (2)'!$H$6:$H$100,"")
A18: =ROW()-4 -> 14 | B18: 3 | C18: JAROSZEK Zbigniew | D18: =SUM(E18:P18) -> 4.71 | E18: =_xlfn.XLOOKUP($C18,'MP (1)'!$B$6:$B$100,'MP (1)'!$E$6:$E$100,"") -> 0.4 | F18: =_xlfn.XLOOKUP($C18,'MP (2)'!$B$6:$B$100,'MP (2)'!$E$6:$E$100,"") -> 0.4 | G18: =_xlfn.XLOOKUP($C18,'GP1 (1)'!$B$6:$B$100,'GP1 (1)'!$E$6:$E$100,"") -> 0.6 | H18: =_xlfn.XLOOKUP($C18,'GP1 (2)'!$B$6:$B$100,'GP1 (2)'!$E$6:$E$100,"") -> 0.33 | I18: =_xlfn.XLOOKUP($C18,'GP2 (1)'!$B$6:$B$107,'GP2 (1)'!$E$6:$E$107,"") -> 0.83 | J18: =_xlfn.XLOOKUP($C18,'GP2 (2)'!$B$6:$B$99,'GP2 (2)'!$E$6:$E$99,"") -> 0.6 | K18: =_xlfn.XLOOKUP($C18,'GP3 (1)'!$B$6:$B$100,'GP3 (1)'!$E$6:$E$100,"") | L18: =_xlfn.XLOOKUP($C18,'GP3 (2)'!$B$6:$B$100,'GP3 (2)'!$E$6:$E$100,"") | M18: =_xlfn.XLOOKUP($C18,'GP4 (1)'!$B$6:$B$86,'GP4 (1)'!$E$6:$E$86,"") -> 0.4 | N18: =_xlfn.XLOOKUP($C18,'GP4 (2)'!$B$6:$B$100,'GP4 (2)'!$E$6:$E$100,"") -> 0.4 | O18: =_xlfn.XLOOKUP($C18,'GP5 (1)'!$B$6:$B$100,'GP5 (1)'!$E$6:$E$100,"") -> 0.25 | P18: =_xlfn.XLOOKUP($C18,'GP5 (2)'!$B$6:$B$100,'GP5 (2)'!$E$6:$E$100,"") -> 0.5 | Q18: =SUM(R18:AC18) -> 173 | R18: =_xlfn.XLOOKUP($C18,'MP (1)'!$B$6:$B$100,'MP (1)'!$F$6:$F$100,"") -> 16 | S18: =_xlfn.XLOOKUP($C18,'MP (2)'!$B$6:$B$100,'MP (2)'!$F$6:$F$100,"") -> 13 | T18: =_xlfn.XLOOKUP($C18,'GP1 (1)'!$B$6:$B$100,'GP1 (1)'!$F$6:$F$100,"") -> 19 | U18: =_xlfn.XLOOKUP($C18,'GP1 (2)'!$B$6:$B$100,'GP1 (2)'!$F$6:$F$100,"") -> 17 | V18: =_xlfn.XLOOKUP($C18,'GP2 (1)'!$B$8:$B$107,'GP2 (1)'!$F$8:$F$107,"") -> 28 | W18: =_xlfn.XLOOKUP($C18,'GP2 (2)'!$B$6:$B$99,'GP2 (2)'!$F$6:$F$99,"") -> 20 | X18: =_xlfn.XLOOKUP($C18,'GP3 (1)'!$B$6:$B$100,'GP3 (1)'!$F$6:$F$100,"") | Y18: =_xlfn.XLOOKUP($C18,'GP3 (2)'!$B$6:$B$100,'GP3 (2)'!$F$6:$F$100,"") | Z18: =_xlfn.XLOOKUP($C18,'GP4 (1)'!$B$6:$B$86,'GP4 (1)'!$F$6:$F$86,"") -> 15 | AA18: =_xlfn.XLOOKUP($C18,'GP4 (2)'!$B$6:$B$100,'GP4 (2)'!$F$6:$F$100,"") -> 16 | AB18: =_xlfn.XLOOKUP($C18,'GP5 (1)'!$B$6:$B$100,'GP5 (1)'!$F$6:$F$100,"") -> 14 | AC18: =_xlfn.XLOOKUP($C18,'GP5 (2)'!$B$6:$B$100,'GP5 (2)'!$F$6:$F$100,"") -> 15 | AD18: =SUM(AE18:AO18) -> -11 | AE18: =_xlfn.XLOOKUP($C18,'MP (1)'!$B$6:$B$100,'MP (1)'!$H$6:$H$100,"") -> -4 | AF18: =_xlfn.XLOOKUP($C18,'MP (2)'!$B$6:$B$100,'MP (2)'!$H$6:$H$100,"") -> -5 | AG18: =_xlfn.XLOOKUP($C18,'GP1 (1)'!$B$6:$B$100,'GP1 (1)'!$H$6:$H$100,"") -> 3 | AH18: =_xlfn.XLOOKUP($C18,'GP1 (2)'!$B$6:$B$100,'GP1 (2)'!$H$6:$H$100,"") -> -8 | AI18: =_xlfn.XLOOKUP($C18,'GP2 (1)'!$B$8:$B$107,'GP2 (1)'!$H$8:$H$107,"") -> 11 | AJ18: =_xlfn.XLOOKUP($C18,'GP2 (2)'!$B$6:$B$99,'GP2 (2)'!$H$6:$H$99,"") -> 1 | AK18: =_xlfn.XLOOKUP($C18,'GP3 (1)'!$B$6:$B$100,'GP3 (1)'!$H$6:$H$100,"") | AL18: =_xlfn.XLOOKUP($C18,'GP3 (2)'!$B$6:$B$100,'GP3 (2)'!$H$6:$H$100,"") | AM18: =_xlfn.XLOOKUP($C18,'GP4 (1)'!$B$6:$B$86,'GP4 (1)'!$H$6:$H$86,"") -> -4 | AN18: =_xlfn.XLOOKUP($C18,'GP4 (2)'!$B$6:$B$100,'GP4 (2)'!$H$6:$H$100,"") -> -2 | AO18: =_xlfn.XLOOKUP($C18,'GP5 (1)'!$B$6:$B$100,'GP5 (1)'!$H$6:$H$100,"") -> -3 | AP18: =_xlfn.XLOOKUP($C18,'GP5 (2)'!$B$6:$B$100,'GP5 (2)'!$H$6:$H$100,"") -> -2
A19: =ROW()-4 -> 15 | B19: 0 | C19: GRACZYK Bogdan | D19: =SUM(E19:P19) -> 4.5 | E19: =_xlfn.XLOOKUP($C19,'MP (1)'!$B$6:$B$100,'MP (1)'!$E$6:$E$100,"") -> 0.67 | F19: =_xlfn.XLOOKUP($C19,'MP (2)'!$B$6:$B$100,'MP (2)'!$E$6:$E$100,"") -> 0.67 | G19: =_xlfn.XLOOKUP($C19,'GP1 (1)'!$B$6:$B$100,'GP1 (1)'!$E$6:$E$100,"") -> 0.33 | H19: =_xlfn.XLOOKUP($C19,'GP1 (2)'!$B$6:$B$100,'GP1 (2)'!$E$6:$E$100,"") -> 0.83 | I19: =_xlfn.XLOOKUP($C19,'GP2 (1)'!$B$8:$B$107,'GP2 (1)'!$E$8:$E$107,"") -> 0.6 | J19: =_xlfn.XLOOKUP($C19,'GP2 (2)'!$B$6:$B$99,'GP2 (2)'!$E$6:$E$99,"") -> 0.2 | K19: =_xlfn.XLOOKUP($C19,'GP3 (1)'!$B$6:$B$100,'GP3 (1)'!$E$6:$E$100,"") | L19: =_xlfn.XLOOKUP($C19,'GP3 (2)'!$B$6:$B$100,'GP3 (2)'!$E$6:$E$100,"") | M19: =_xlfn.XLOOKUP($C19,'GP4 (1)'!$B$6:$B$86,'GP4 (1)'!$E$6:$E$86,"") -> 0.6 | N19: =_xlfn.XLOOKUP($C19,'GP4 (2)'!$B$6:$B$100,'GP4 (2)'!$E$6:$E$100,"") -> 0.6 | O19: =_xlfn.XLOOKUP($C19,'GP5 (1)'!$B$6:$B$100,'GP5 (1)'!$E$6:$E$100,"") | P19: =_xlfn.XLOOKUP($C19,'GP5 (2)'!$B$6:$B$100,'GP5 (2)'!$E$6:$E$100,"") | Q19: =SUM(R19:AC19) -> 166 | R19: =_xlfn.XLOOKUP($C19,'MP (1)'!$B$6:$B$100,'MP (1)'!$F$6:$F$100,"") -> 23 | S19: =_xlfn.XLOOKUP($C19,'MP (2)'!$B$6:$B$100,'MP (2)'!$F$6:$F$100,"") -> 25 | T19: =_xlfn.XLOOKUP($C19,'GP1 (1)'!$B$6:$B$100,'GP1 (1)'!$F$6:$F$100,"") -> 20 | U19: =_xlfn.XLOOKUP($C19,'GP1 (2)'!$B$6:$B$100,'GP1 (2)'!$F$6:$F$100,"") -> 25 | V19: =_xlfn.XLOOKUP($C19,'GP2 (1)'!$B$8:$B$107,'GP2 (1)'!$F$8:$F$107,"") -> 17 | W19: =_xlfn.XLOOKUP($C19,'GP2 (2)'!$B$6:$B$99,'GP2 (2)'!$F$6:$F$99,"") -> 18 | X19: =_xlfn.XLOOKUP($C19,'GP3 (1)'!$B$6:$B$100,'GP3 (1)'!$F$6:$F$100,"") | Y19: =_xlfn.XLOOKUP($C19,'GP3 (2)'!$B$6:$B$100,'GP3 (2)'!$F$6:$F$100,"") | Z19: =_xlfn.XLOOKUP($C19,'GP4 (1)'!$B$6:$B$86,'GP4 (1)'!$F$6:$F$86,"") -> 19 | AA19: =_xlfn.XLOOKUP($C19,'GP4 (2)'!$B$6:$B$100,'GP4 (2)'!$F$6:$F$100,"") -> 19 | AB19: =_xlfn.XLOOKUP($C19,'GP5 (1)'!$B$6:$B$100,'GP5 (1)'!$F$6:$F$100,"") | AC19: =_xlfn.XLOOKUP($C19,'GP5 (2)'!$B$6:$B$100,'GP5 (2)'!$F$6:$F$100,"") | AD19: =SUM(AE19:AO19) -> 22 | AE19: =_xlfn.XLOOKUP($C19,'MP (1)'!$B$6:$B$100,'MP (1)'!$H$6:$H$100,"") -> 2 | AF19: =_xlfn.XLOOKUP($C19,'MP (2)'!$B$6:$B$100,'MP (2)'!$H$6:$H$100,"") -> 6 | AG19: =_xlfn.XLOOKUP($C19,'GP1 (1)'!$B$6:$B$100,'GP1 (1)'!$H$6:$H$100,"") -> -4 | AH19: =_xlfn.XLOOKUP($C19,'GP1 (2)'!$B$6:$B$100,'GP1 (2)'!$H$6:$H$100,"") -> 12 | AI19: =_xlfn.XLOOKUP($C19,'GP2 (1)'!$B$8:$B$107,'GP2 (1)'!$H$8:$H$107,"") -> 2 | AJ19: =_xlfn.XLOOKUP($C19,'GP2 (2)'!$B$6:$B$99,'GP2 (2)'!$H$6:$H$99,"") -> -6 | AK19: =_xlfn.XLOOKUP($C19,'GP3 (1)'!$B$6:$B$100,'GP3 (1)'!$H$6:$H$100,"") | AL19: =_xlfn.XLOOKUP($C19,'GP3 (2)'!$B$6:$B$100,'GP3 (2)'!$H$6:$H$100,"") | AM19: =_xlfn.XLOOKUP($C19,'GP4 (1)'!$B$6:$B$86,'GP4 (1)'!$H$6:$H$86,"") -> 4 | AN19: =_xlfn.XLOOKUP($C19,'GP4 (2)'!$B$6:$B$100,'GP4 (2)'!$H$6:$H$100,"") -> 6 | AO19: =_xlfn.XLOOKUP($C19,'GP5 (1)'!$B$6:$B$100,'GP5 (1)'!$H$6:$H$100,"") | AP19: =_xlfn.XLOOKUP($C19,'GP5 (2)'!$B$6:$B$100,'GP5 (2)'!$H$6:$H$100,"")
A20: =ROW()-4 -> 16 | B20: 0 | C20: GĘZIKIEWICZ Marcin | D20: =SUM(E20:P20) -> 4.46 | E20: =_xlfn.XLOOKUP($C20,'MP (1)'!$B$6:$B$100,'MP (1)'!$E$6:$E$100,"") -> 0.8 | F20: =_xlfn.XLOOKUP($C20,'MP (2)'!$B$6:$B$100,'MP (2)'!$E$6:$E$100,"") -> 0.83 | G20: =_xlfn.XLOOKUP($C20,'GP1 (1)'!$B$6:$B$100,'GP1 (1)'!$E$6:$E$100,"") -> 0.6 | H20: =_xlfn.XLOOKUP($C20,'GP1 (2)'!$B$6:$B$100,'GP1 (2)'!$E$6:$E$100,"") -> 0.8 | I20: =_xlfn.XLOOKUP($C20,'GP2 (1)'!$B$6:$B$107,'GP2 (1)'!$E$6:$E$107,"") -> 0.6 | J20: =_xlfn.XLOOKUP($C20,'GP2 (2)'!$B$6:$B$99,'GP2 (2)'!$E$6:$E$99,"") -> 0.83 | K20: =_xlfn.XLOOKUP($C20,'GP3 (1)'!$B$6:$B$100,'GP3 (1)'!$E$6:$E$100,"") | L20: =_xlfn.XLOOKUP($C20,'GP3 (2)'!$B$6:$B$100,'GP3 (2)'!$E$6:$E$100,"") | M20: =_xlfn.XLOOKUP($C20,'GP4 (1)'!$B$6:$B$86,'GP4 (1)'!$E$6:$E$86,"") | N20: =_xlfn.XLOOKUP($C20,'GP4 (2)'!$B$6:$B$100,'GP4 (2)'!$E$6:$E$100,"") | O20: =_xlfn.XLOOKUP($C20,'GP5 (1)'!$B$6:$B$100,'GP5 (1)'!$E$6:$E$100,"") | P20: =_xlfn.XLOOKUP($C20,'GP5 (2)'!$B$6:$B$100,'GP5 (2)'!$E$6:$E$100,"") | Q20: =SUM(R20:AC20) -> 143 | R20: =_xlfn.XLOOKUP($C20,'MP (1)'!$B$6:$B$100,'MP (1)'!$F$6:$F$100,"") -> 24 | S20: =_xlfn.XLOOKUP($C20,'MP (2)'!$B$6:$B$100,'MP (2)'!$F$6:$F$100,"") -> 28 | T20: =_xlfn.XLOOKUP($C20,'GP1 (1)'!$B$6:$B$100,'GP1 (1)'!$F$6:$F$100,"") -> 20 | U20: =_xlfn.XLOOKUP($C20,'GP1 (2)'!$B$6:$B$100,'GP1 (2)'!$F$6:$F$100,"") -> 23 | V20: =_xlfn.XLOOKUP($C20,'GP2 (1)'!$B$8:$B$107,'GP2 (1)'!$F$8:$F$107,"") -> 20 | W20: =_xlfn.XLOOKUP($C20,'GP2 (2)'!$B$6:$B$99,'GP2 (2)'!$F$6:$F$99,"") -> 28 | X20: =_xlfn.XLOOKUP($C20,'GP3 (1)'!$B$6:$B$100,'GP3 (1)'!$F$6:$F$100,"") | Y20: =_xlfn.XLOOKUP($C20,'GP3 (2)'!$B$6:$B$100,'GP3 (2)'!$F$6:$F$100,"") | Z20: =_xlfn.XLOOKUP($C20,'GP4 (1)'!$B$6:$B$86,'GP4 (1)'!$F$6:$F$86,"") | AA20: =_xlfn.XLOOKUP($C20,'GP4 (2)'!$B$6:$B$100,'GP4 (2)'!$F$6:$F$100,"") | AB20: =_xlfn.XLOOKUP($C20,'GP5 (1)'!$B$6:$B$100,'GP5 (1)'!$F$6:$F$100,"") | AC20: =_xlfn.XLOOKUP($C20,'GP5 (2)'!$B$6:$B$100,'GP5 (2)'!$F$6:$F$100,"") | AD20: =SUM(AE20:AO20) -> 54 | AE20: =_xlfn.XLOOKUP($C20,'MP (1)'!$B$6:$B$100,'MP (1)'!$H$6:$H$100,"") -> 10 | AF20: =_xlfn.XLOOKUP($C20,'MP (2)'!$B$6:$B$100,'MP (2)'!$H$6:$H$100,"") -> 17 | AG20: =_xlfn.XLOOKUP($C20,'GP1 (1)'!$B$6:$B$100,'GP1 (1)'!$H$6:$H$100,"") -> 1 | AH20: =_xlfn.XLOOKUP($C20,'GP1 (2)'!$B$6:$B$100,'GP1 (2)'!$H$6:$H$100,"") -> 6 | AI20: =_xlfn.XLOOKUP($C20,'GP2 (1)'!$B$8:$B$107,'GP2 (1)'!$H$8:$H$107,"") -> 2 | AJ20: =_xlfn.XLOOKUP($C20,'GP2 (2)'!$B$6:$B$99,'GP2 (2)'!$H$6:$H$99,"") -> 18 | AK20: =_xlfn.XLOOKUP($C20,'GP3 (1)'!$B$6:$B$100,'GP3 (1)'!$H$6:$H$100,"") | AL20: =_xlfn.XLOOKUP($C20,'GP3 (2)'!$B$6:$B$100,'GP3 (2)'!$H$6:$H$100,"") | AM20: =_xlfn.XLOOKUP($C20,'GP4 (1)'!$B$6:$B$86,'GP4 (1)'!$H$6:$H$86,"") | AN20: =_xlfn.XLOOKUP($C20,'GP4 (2)'!$B$6:$B$100,'GP4 (2)'!$H$6:$H$100,"") | AO20: =_xlfn.XLOOKUP($C20,'GP5 (1)'!$B$6:$B$100,'GP5 (1)'!$H$6:$H$100,"") | AP20: =_xlfn.XLOOKUP($C20,'GP5 (2)'!$B$6:$B$100,'GP5 (2)'!$H$6:$H$100,"")
A21: =ROW()-4 -> 17 | B21: 0 | C21: SZEPIETOWSKI Rafał | D21: =SUM(E21:P21) -> 4.03 | E21: =_xlfn.XLOOKUP($C21,'MP (1)'!$B$6:$B$100,'MP (1)'!$E$6:$E$100,"") -> 0.83 | F21: =_xlfn.XLOOKUP($C21,'MP (2)'!$B$6:$B$100,'MP (2)'!$E$6:$E$100,"") -> 0.8 | G21: =_xlfn.XLOOKUP($C21,'GP1 (1)'!$B$6:$B$100,'GP1 (1)'!$E$6:$E$100,"") -> 0.2 | H21: =_xlfn.XLOOKUP($C21,'GP1 (2)'!$B$6:$B$100,'GP1 (2)'!$E$6:$E$100,"") -> 0.4 | I21: =_xlfn.XLOOKUP($C21,'GP2 (1)'!$B$8:$B$107,'GP2 (1)'!$E$8:$E$107,"") -> 0.4 | J21: =_xlfn.XLOOKUP($C21,'GP2 (2)'!$B$6:$B$99,'GP2 (2)'!$E$6:$E$99,"") -> 0.5 | K21: =_xlfn.XLOOKUP($C21,'GP3 (1)'!$B$6:$B$100,'GP3 (1)'!$E$6:$E$100,"") -> 0.4 | L21: =_xlfn.XLOOKUP($C21,'GP3 (2)'!$B$6:$B$100,'GP3 (2)'!$E$6:$E$100,"") -> 0.5 | M21: =_xlfn.XLOOKUP($C21,'GP4 (1)'!$B$6:$B$86,'GP4 (1)'!$E$6:$E$86,"") | N21: =_xlfn.XLOOKUP($C21,'GP4 (2)'!$B$6:$B$100,'GP4 (2)'!$E$6:$E$100,"") | O21: =_xlfn.XLOOKUP($C21,'GP5 (1)'!$B$6:$B$100,'GP5 (1)'!$E$6:$E$100,"") | P21: =_xlfn.XLOOKUP($C21,'GP5 (2)'!$B$6:$B$100,'GP5 (2)'!$E$6:$E$100,"") | Q21: =SUM(R21:AC21) -> 154 | R21: =_xlfn.XLOOKUP($C21,'MP (1)'!$B$6:$B$100,'MP (1)'!$F$6:$F$100,"") -> 26 | S21: =_xlfn.XLOOKUP($C21,'MP (2)'!$B$6:$B$100,'MP (2)'!$F$6:$F$100,"") -> 21 | T21: =_xlfn.XLOOKUP($C21,'GP1 (1)'!$B$6:$B$100,'GP1 (1)'!$F$6:$F$100,"") -> 16 | U21: =_xlfn.XLOOKUP($C21,'GP1 (2)'!$B$6:$B$100,'GP1 (2)'!$F$6:$F$100,"") -> 17 | V21: =_xlfn.XLOOKUP($C21,'GP2 (1)'!$B$8:$B$107,'GP2 (1)'!$F$8:$F$107,"") -> 16 | W21: =_xlfn.XLOOKUP($C21,'GP2 (2)'!$B$6:$B$99,'GP2 (2)'!$F$6:$F$99,"") -> 19 | X21: =_xlfn.XLOOKUP($C21,'GP3 (1)'!$B$6:$B$100,'GP3 (1)'!$F$6:$F$100,"") -> 15 | Y21: =_xlfn.XLOOKUP($C21,'GP3 (2)'!$B$6:$B$100,'GP3 (2)'!$F$6:$F$100,"") -> 24 | Z21: =_xlfn.XLOOKUP($C21,'GP4 (1)'!$B$6:$B$86,'GP4 (1)'!$F$6:$F$86,"") | AA21: =_xlfn.XLOOKUP($C21,'GP4 (2)'!$B$6:$B$100,'GP4 (2)'!$F$6:$F$100,"") | AB21: =_xlfn.XLOOKUP($C21,'GP5 (1)'!$B$6:$B$100,'GP5 (1)'!$F$6:$F$100,"") | AC21: =_xlfn.XLOOKUP($C21,'GP5 (2)'!$B$6:$B$100,'GP5 (2)'!$F$6:$F$100,"") | AD21: =SUM(AE21:AO21) -> 16 | AE21: =_xlfn.XLOOKUP($C21,'MP (1)'!$B$6:$B$100,'MP (1)'!$H$6:$H$100,"") -> 14 | AF21: =_xlfn.XLOOKUP($C21,'MP (2)'!$B$6:$B$100,'MP (2)'!$H$6:$H$100,"") -> 12 | AG21: =_xlfn.XLOOKUP($C21,'GP1 (1)'!$B$6:$B$100,'GP1 (1)'!$H$6:$H$100,"") -> -7 | AH21: =_xlfn.XLOOKUP($C21,'GP1 (2)'!$B$6:$B$100,'GP1 (2)'!$H$6:$H$100,"") -> -1 | AI21: =_xlfn.XLOOKUP($C21,'GP2 (1)'!$B$8:$B$107,'GP2 (1)'!$H$8:$H$107,"") -> -5 | AJ21: =_xlfn.XLOOKUP($C21,'GP2 (2)'!$B$6:$B$99,'GP2 (2)'!$H$6:$H$99,"") -> 0 | AK21: =_xlfn.XLOOKUP($C21,'GP3 (1)'!$B$6:$B$100,'GP3 (1)'!$H$6:$H$100,"") -> -2 | AL21: =_xlfn.XLOOKUP($C21,'GP3 (2)'!$B$6:$B$100,'GP3 (2)'!$H$6:$H$100,"") -> 5 | AM21: =_xlfn.XLOOKUP($C21,'GP4 (1)'!$B$6:$B$86,'GP4 (1)'!$H$6:$H$86,"") | AN21: =_xlfn.XLOOKUP($C21,'GP4 (2)'!$B$6:$B$100,'GP4 (2)'!$H$6:$H$100,"") | AO21: =_xlfn.XLOOKUP($C21,'GP5 (1)'!$B$6:$B$100,'GP5 (1)'!$H$6:$H$100,"") | AP21: =_xlfn.XLOOKUP($C21,'GP5 (2)'!$B$6:$B$100,'GP5 (2)'!$H$6:$H$100,"")
A22: =ROW()-4 -> 18 | B22: 1 | C22: SZYMAŃSKI Adam | D22: =SUM(E22:P22) -> 3.4 | E22: =_xlfn.XLOOKUP($C22,'MP (1)'!$B$6:$B$100,'MP (1)'!$E$6:$E$100,"") -> 0.6 | F22: =_xlfn.XLOOKUP($C22,'MP (2)'!$B$6:$B$100,'MP (2)'!$E$6:$E$100,"") -> 0.2 | G22: =_xlfn.XLOOKUP($C22,'GP1 (1)'!$B$6:$B$100,'GP1 (1)'!$E$6:$E$100,"") -> 0 | H22: =_xlfn.XLOOKUP($C22,'GP1 (2)'!$B$6:$B$100,'GP1 (2)'!$E$6:$E$100,"") -> 0.17 | I22: =_xlfn.XLOOKUP($C22,'GP2 (1)'!$B$6:$B$107,'GP2 (1)'!$E$6:$E$107,"") -> 0.6 | J22: =_xlfn.XLOOKUP($C22,'GP2 (2)'!$B$6:$B$99,'GP2 (2)'!$E$6:$E$99,"") -> 0.4 | K22: =_xlfn.XLOOKUP($C22,'GP3 (1)'!$B$6:$B$100,'GP3 (1)'!$E$6:$E$100,"") -> 0.5 | L22: =_xlfn.XLOOKUP($C22,'GP3 (2)'!$B$6:$B$100,'GP3 (2)'!$E$6:$E$100,"") -> 0.33 | M22: =_xlfn.XLOOKUP($C22,'GP4 (1)'!$B$6:$B$86,'GP4 (1)'!$E$6:$E$86,"") -> 0.2 | N22: =_xlfn.XLOOKUP($C22,'GP4 (2)'!$B$6:$B$100,'GP4 (2)'!$E$6:$E$100,"") -> 0.4 | O22: =_xlfn.XLOOKUP($C22,'GP5 (1)'!$B$6:$B$100,'GP5 (1)'!$E$6:$E$100,"") | P22: =_xlfn.XLOOKUP($C22,'GP5 (2)'!$B$6:$B$100,'GP5 (2)'!$E$6:$E$100,"") | Q22: =SUM(R22:AC22) -> 162 | R22: =_xlfn.XLOOKUP($C22,'MP (1)'!$B$6:$B$100,'MP (1)'!$F$6:$F$100,"") -> 15 | S22: =_xlfn.XLOOKUP($C22,'MP (2)'!$B$6:$B$100,'MP (2)'!$F$6:$F$100,"") -> 13 | T22: =_xlfn.XLOOKUP($C22,'GP1 (1)'!$B$6:$B$100,'GP1 (1)'!$F$6:$F$100,"") -> 12 | U22: =_xlfn.XLOOKUP($C22,'GP1 (2)'!$B$6:$B$100,'GP1 (2)'!$F$6:$F$100,"") -> 16 | V22: =_xlfn.XLOOKUP($C22,'GP2 (1)'!$B$8:$B$107,'GP2 (1)'!$F$8:$F$107,"") -> 19 | W22: =_xlfn.XLOOKUP($C22,'GP2 (2)'!$B$6:$B$99,'GP2 (2)'!$F$6:$F$99,"") -> 17 | X22: =_xlfn.XLOOKUP($C22,'GP3 (1)'!$B$6:$B$100,'GP3 (1)'!$F$6:$F$100,"") -> 16 | Y22: =_xlfn.XLOOKUP($C22,'GP3 (2)'!$B$6:$B$100,'GP3 (2)'!$F$6:$F$100,"") -> 18 | Z22: =_xlfn.XLOOKUP($C22,'GP4 (1)'!$B$6:$B$86,'GP4 (1)'!$F$6:$F$86,"") -> 16 | AA22: =_xlfn.XLOOKUP($C22,'GP4 (2)'!$B$6:$B$100,'GP4 (2)'!$F$6:$F$100,"") -> 20 | AB22: =_xlfn.XLOOKUP($C22,'GP5 (1)'!$B$6:$B$100,'GP5 (1)'!$F$6:$F$100,"") | AC22: =_xlfn.XLOOKUP($C22,'GP5 (2)'!$B$6:$B$100,'GP5 (2)'!$F$6:$F$100,"") | AD22: =SUM(AE22:AO22) -> -43 | AE22: =_xlfn.XLOOKUP($C22,'MP (1)'!$B$6:$B$100,'MP (1)'!$H$6:$H$100,"") -> -2 | AF22: =_xlfn.XLOOKUP($C22,'MP (2)'!$B$6:$B$100,'MP (2)'!$H$6:$H$100,"") -> -10 | AG22: =_xlfn.XLOOKUP($C22,'GP1 (1)'!$B$6:$B$100,'GP1 (1)'!$H$6:$H$100,"") -> -13 | AH22: =_xlfn.XLOOKUP($C22,'GP1 (2)'!$B$6:$B$100,'GP1 (2)'!$H$6:$H$100,"") -> -11 | AI22: =_xlfn.XLOOKUP($C22,'GP2 (1)'!$B$8:$B$107,'GP2 (1)'!$H$8:$H$107,"") -> 1 | AJ22: =_xlfn.XLOOKUP($C22,'GP2 (2)'!$B$6:$B$99,'GP2 (2)'!$H$6:$H$99,"") -> 0 | AK22: =_xlfn.XLOOKUP($C22,'GP3 (1)'!$B$6:$B$100,'GP3 (1)'!$H$6:$H$100,"") -> 1 | AL22: =_xlfn.XLOOKUP($C22,'GP3 (2)'!$B$6:$B$100,'GP3 (2)'!$H$6:$H$100,"") -> -7 | AM22: =_xlfn.XLOOKUP($C22,'GP4 (1)'!$B$6:$B$86,'GP4 (1)'!$H$6:$H$86,"") -> -7 | AN22: =_xlfn.XLOOKUP($C22,'GP4 (2)'!$B$6:$B$100,'GP4 (2)'!$H$6:$H$100,"") -> 5 | AO22: =_xlfn.XLOOKUP($C22,'GP5 (1)'!$B$6:$B$100,'GP5 (1)'!$H$6:$H$100,"") | AP22: =_xlfn.XLOOKUP($C22,'GP5 (2)'!$B$6:$B$100,'GP5 (2)'!$H$6:$H$100,"")
A23: =ROW()-4 -> 19 | B23: 4 | C23: PRĘGOWSKI Jerzy | D23: =SUM(E23:P23) -> 2.75 | E23: =_xlfn.XLOOKUP($C23,'MP (1)'!$B$6:$B$100,'MP (1)'!$E$6:$E$100,"") -> 0.33 | F23: =_xlfn.XLOOKUP($C23,'MP (2)'!$B$6:$B$100,'MP (2)'!$E$6:$E$100,"") -> 0.4 | G23: =_xlfn.XLOOKUP($C23,'GP1 (1)'!$B$6:$B$100,'GP1 (1)'!$E$6:$E$100,"") | H23: =_xlfn.XLOOKUP($C23,'GP1 (2)'!$B$6:$B$100,'GP1 (2)'!$E$6:$E$100,"") | I23: =_xlfn.XLOOKUP($C23,'GP2 (1)'!$B$6:$B$107,'GP2 (1)'!$E$6:$E$107,"") -> 0.4 | J23: =_xlfn.XLOOKUP($C23,'GP2 (2)'!$B$6:$B$99,'GP2 (2)'!$E$6:$E$99,"") -> 0.2 | K23: =_xlfn.XLOOKUP($C23,'GP3 (1)'!$B$6:$B$100,'GP3 (1)'!$E$6:$E$100,"") -> 0.25 | L23: =_xlfn.XLOOKUP($C23,'GP3 (2)'!$B$6:$B$100,'GP3 (2)'!$E$6:$E$100,"") -> 0.17 | M23: =_xlfn.XLOOKUP($C23,'GP4 (1)'!$B$6:$B$86,'GP4 (1)'!$E$6:$E$86,"") -> 0.6 | N23: =_xlfn.XLOOKUP($C23,'GP4 (2)'!$B$6:$B$100,'GP4 (2)'!$E$6:$E$100,"") -> 0.4 | O23: =_xlfn.XLOOKUP($C23,'GP5 (1)'!$B$6:$B$100,'GP5 (1)'!$E$6:$E$100,"") | P23: =_xlfn.XLOOKUP($C23,'GP5 (2)'!$B$6:$B$100,'GP5 (2)'!$E$6:$E$100,"") | Q23: =SUM(R23:AC23) -> 116 | R23: =_xlfn.XLOOKUP($C23,'MP (1)'!$B$6:$B$100,'MP (1)'!$F$6:$F$100,"") -> 19 | S23: =_xlfn.XLOOKUP($C23,'MP (2)'!$B$6:$B$100,'MP (2)'!$F$6:$F$100,"") -> 16 | T23: =_xlfn.XLOOKUP($C23,'GP1 (1)'!$B$6:$B$100,'GP1 (1)'!$F$6:$F$100,"") | U23: =_xlfn.XLOOKUP($C23,'GP1 (2)'!$B$6:$B$100,'GP1 (2)'!$F$6:$F$100,"") | V23: =_xlfn.XLOOKUP($C23,'GP2 (1)'!$B$8:$B$107,'GP2 (1)'!$F$8:$F$107,"") -> 17 | W23: =_xlfn.XLOOKUP($C23,'GP2 (2)'!$B$6:$B$99,'GP2 (2)'!$F$6:$F$99,"") -> 14 | X23: =_xlfn.XLOOKUP($C23,'GP3 (1)'!$B$6:$B$100,'GP3 (1)'!$F$6:$F$100,"") -> 11 | Y23: =_xlfn.XLOOKUP($C23,'GP3 (2)'!$B$6:$B$100,'GP3 (2)'!$F$6:$F$100,"") -> 10 | Z23: =_xlfn.XLOOKUP($C23,'GP4 (1)'!$B$6:$B$86,'GP4 (1)'!$F$6:$F$86,"") -> 18 | AA23: =_xlfn.XLOOKUP($C23,'GP4 (2)'!$B$6:$B$100,'GP4 (2)'!$F$6:$F$100,"") -> 11 | AB23: =_xlfn.XLOOKUP($C23,'GP5 (1)'!$B$6:$B$100,'GP5 (1)'!$F$6:$F$100,"") | AC23: =_xlfn.XLOOKUP($C23,'GP5 (2)'!$B$6:$B$100,'GP5 (2)'!$F$6:$F$100,"") | AD23: =SUM(AE23:AO23) -> -51 | AE23: =_xlfn.XLOOKUP($C23,'MP (1)'!$B$6:$B$100,'MP (1)'!$H$6:$H$100,"") -> -8 | AF23: =_xlfn.XLOOKUP($C23,'MP (2)'!$B$6:$B$100,'MP (2)'!$H$6:$H$100,"") -> -4 | AG23: =_xlfn.XLOOKUP($C23,'GP1 (1)'!$B$6:$B$100,'GP1 (1)'!$H$6:$H$100,"") | AH23: =_xlfn.XLOOKUP($C23,'GP1 (2)'!$B$6:$B$100,'GP1 (2)'!$H$6:$H$100,"") | AI23: =_xlfn.XLOOKUP($C23,'GP2 (1)'!$B$8:$B$107,'GP2 (1)'!$H$8:$H$107,"") -> -2 | AJ23: =_xlfn.XLOOKUP($C23,'GP2 (2)'!$B$6:$B$99,'GP2 (2)'!$H$6:$H$99,"") -> -9 | AK23: =_xlfn.XLOOKUP($C23,'GP3 (1)'!$B$6:$B$100,'GP3 (1)'!$H$6:$H$100,"") -> -4 | AL23: =_xlfn.XLOOKUP($C23,'GP3 (2)'!$B$6:$B$100,'GP3 (2)'!$H$6:$H$100,"") -> -17 | AM23: =_xlfn.XLOOKUP($C23,'GP4 (1)'!$B$6:$B$86,'GP4 (1)'!$H$6:$H$86,"") -> 0 | AN23: =_xlfn.XLOOKUP($C23,'GP4 (2)'!$B$6:$B$100,'GP4 (2)'!$H$6:$H$100,"") -> -7 | AO23: =_xlfn.XLOOKUP($C23,'GP5 (1)'!$B$6:$B$100,'GP5 (1)'!$H$6:$H$100,"") | AP23: =_xlfn.XLOOKUP($C23,'GP5 (2)'!$B$6:$B$100,'GP5 (2)'!$H$6:$H$100,"")
