Workbook

Sheet Ranking
B2: Dołączył/a do kategorii w tym roku | D2: Ranking Pucharu Polski Weteranów (PP) sezon 2025-2026 | R2: Na sumę punktów w rankingu skłąda się 4 najlePSzych wyników (z 5 możliwych) w turniejach PP Weteranów oraz wynik z Mistrzostw Polski Weteranów.
D3: Kat. 2
A4: L.P. | B4: NAZWISKO Imię | C4: KLUB | D4: PUNKTY | E4: I PP | G4: II PP | I4: III PP | K4: IV PP | M4: V PP | O4: MPW
E5: M | F5: P | G5: M | H5: P | I5: M | J5: P | K5: M | L5: P | M5: M | N5: P | O5: M | P5: P
A6: =ROW()-5 -> 1 | B6: ZIELIŃSKI Dariusz | D6: =SUM(F6,H6,J6,L6,N6,P6)-MIN(F6,H6,J6,L6,N6) -> 322.50804 | E6: =_xlfn.XLOOKUP($B6,'PP1'!$C$6:$C$150,'PP1'!$B$6:$B$150,"") -> 1 | F6: =_xlfn.XLOOKUP(E6,'PP1'!$B$6:$B$150,'PP1'!$A$6:$A$150,0) -> 98 | G6: =_xlfn.XLOOKUP($B6,'PP2'!$C$6:$C$150,'PP2'!$B$6:$B$150,"") | H6: =_xlfn.XLOOKUP(G6,'PP2'!$B$6:$B$150,'PP2'!$A$6:$A$150,0) -> 0 | I6: =_xlfn.XLOOKUP($B6,'PP3'!$C$6:$C$150,'PP3'!$B$6:$B$150,"") -> 5 | J6: =_xlfn.XLOOKUP(I6,'PP3'!$B$6:$B$150,'PP3'!$A$6:$A$150,0) -> 43.216474 | K6: =_xlfn.XLOOKUP($B6,'PP4'!$C$6:$C$150,'PP4'!$B$6:$B$150,"") -> 2 | L6: =_xlfn.XLOOKUP(K6,'PP4'!$B$6:$B$150,'PP4'!$A$6:$A$150,0) -> 65.666667 | M6: =_xlfn.XLOOKUP($B6,'PP5'!$C$6:$C$150,'PP5'!$B$6:$B$150,"") | N6: =_xlfn.XLOOKUP(M6,'PP5'!$B$6:$B$150,'PP5'!$A$6:$A$150,0) -> 0 | O6: =_xlfn.XLOOKUP(B6,MPW!C$6:C$150,MPW!B$6:B$150,"") -> 1 | P6: =_xlfn.XLOOKUP(O6,MPW!B$6:B$150,MPW!A$6:A$150,0) -> 115.6249
A7: =ROW()-5 -> 2 | B7: ATANASSOW Aleksander | D7: =SUM(F7,H7,J7,L7,N7,P7)-MIN(F7,H7,J7,L7,N7) -> 287.68228 | E7: =_xlfn.XLOOKUP($B7,'PP1'!$C$6:$C$150,'PP1'!$B$6:$B$150,"") -> 2 | F7: =_xlfn.XLOOKUP(E7,'PP1'!$B$6:$B$150,'PP1'!$A$6:$A$150,0) -> 65.666667 | G7: =_xlfn.XLOOKUP($B7,'PP2'!$C$6:$C$150,'PP2'!$B$6:$B$150,"") | H7: =_xlfn.XLOOKUP(G7,'PP2'!$B$6:$B$150,'PP2'!$A$6:$A$150,0) -> 0 | I7: =_xlfn.XLOOKUP($B7,'PP3'!$C$6:$C$150,'PP3'!$B$6:$B$150,"") -> 1 | J7: =_xlfn.XLOOKUP(I7,'PP3'!$B$6:$B$150,'PP3'!$A$6:$A$150,0) -> 124.01561 | K7: =_xlfn.XLOOKUP($B7,'PP4'!$C$6:$C$150,'PP4'!$B$6:$B$150,"") -> 1 | L7: =_xlfn.XLOOKUP(K7,'PP4'!$B$6:$B$150,'PP4'!$A$6:$A$150,0) -> 98 | M7: =_xlfn.XLOOKUP($B7,'PP5'!$C$6:$C$150,'PP5'!$B$6:$B$150,"") | N7: =_xlfn.XLOOKUP(M7,'PP5'!$B$6:$B$150,'PP5'!$A$6:$A$150,0) -> 0 | O7: =_xlfn.XLOOKUP(B7,MPW!C$6:C$150,MPW!B$6:B$150,"") | P7: =_xlfn.XLOOKUP(O7,MPW!B$6:B$150,MPW!A$6:A$150,0) -> 0
A8: =ROW()-5 -> 3 | B8: KORONA Przemysław | D8: =SUM(F8,H8,J8,L8,N8,P8)-MIN(F8,H8,J8,L8,N8) -> 239.66527 | E8: =_xlfn.XLOOKUP($B8,'PP1'!$C$6:$C$150,'PP1'!$B$6:$B$150,"") -> 4 | F8: =_xlfn.XLOOKUP(E8,'PP1'!$B$6:$B$150,'PP1'!$A$6:$A$150,0) -> 27.333333 | G8: =_xlfn.XLOOKUP($B8,'PP2'!$C$6:$C$150,'PP2'!$B$6:$B$150,"") -> 1 | H8: =_xlfn.XLOOKUP(G8,'PP2'!$B$6:$B$150,'PP2'!$A$6:$A$150,0) -> 98 | I8: =_xlfn.XLOOKUP($B8,'PP3'!$C$6:$C$150,'PP3'!$B$6:$B$150,"") -> 3 | J8: =_xlfn.XLOOKUP(I8,'PP3'!$B$6:$B$150,'PP3'!$A$6:$A$150,0) -> 69.722604 | K8: =_xlfn.XLOOKUP($B8,'PP4'!$C$6:$C$150,'PP4'!$B$6:$B$150,"") -> 5k1 | L8: =_xlfn.XLOOKUP(K8,'PP4'!$B$6:$B$150,'PP4'!$A$6:$A$150,0) -> 12.075174 | M8: =_xlfn.XLOOKUP($B8,'PP5'!$C$6:$C$150,'PP5'!$B$6:$B$150,"") | N8: =_xlfn.XLOOKUP(M8,'PP5'!$B$6:$B$150,'PP5'!$A$6:$A$150,0) -> 0 | O8: =_xlfn.XLOOKUP(B8,MPW!C$6:C$150,MPW!B$6:B$150,"") -> 5k1 | P8: =_xlfn.XLOOKUP(O8,MPW!B$6:B$150,MPW!A$6:A$150,0) -> 32.534161
A9: =ROW()-5 -> 4 | B9: JENDRYŚ Marek | D9: =SUM(F9,H9,J9,L9,N9,P9)-MIN(F9,H9,J9,L9,N9) -> 208.92398 | E9: =_xlfn.XLOOKUP($B9,'PP1'!$C$6:$C$150,'PP1'!$B$6:$B$150,"") -> 3 | F9: =_xlfn.XLOOKUP(E9,'PP1'!$B$6:$B$150,'PP1'!$A$6:$A$150,0) -> 40.112279 | G9: =_xlfn.XLOOKUP($B9,'PP2'!$C$6:$C$150,'PP2'!$B$6:$B$150,"") | H9: =_xlfn.XLOOKUP(G9,'PP2'!$B$6:$B$150,'PP2'!$A$6:$A$150,0) -> 0 | I9: =_xlfn.XLOOKUP($B9,'PP3'!$C$6:$C$150,'PP3'!$B$6:$B$150,"") -> 2 | J9: =_xlfn.XLOOKUP(I9,'PP3'!$B$6:$B$150,'PP3'!$A$6:$A$150,0) -> 94.475373 | K9: =_xlfn.XLOOKUP($B9,'PP4'!$C$6:$C$150,'PP4'!$B$6:$B$150,"") | L9: =_xlfn.XLOOKUP(K9,'PP4'!$B$6:$B$150,'PP4'!$A$6:$A$150,0) -> 0 | M9: =_xlfn.XLOOKUP($B9,'PP5'!$C$6:$C$150,'PP5'!$B$6:$B$150,"") | N9: =_xlfn.XLOOKUP(M9,'PP5'!$B$6:$B$150,'PP5'!$A$6:$A$150,0) -> 0 | O9: =_xlfn.XLOOKUP(B9,MPW!C$6:C$150,MPW!B$6:B$150,"") -> 2 | P9: =_xlfn.XLOOKUP(O9,MPW!B$6:B$150,MPW!A$6:A$150,0) -> 74.336323
A10: =ROW()-5 -> 5 | B10: DROBIŃSKI Leszek | D10: =SUM(F10,H10,J10,L10,N10,P10)-MIN(F10,H10,J10,L10,N10) -> 185.46325 | E10: =_xlfn.XLOOKUP($B10,'PP1'!$C$6:$C$150,'PP1'!$B$6:$B$150,"") -> 5 | F10: =_xlfn.XLOOKUP(E10,'PP1'!$B$6:$B$150,'PP1'!$A$6:$A$150,0) -> 12.075174 | G10: =_xlfn.XLOOKUP($B10,'PP2'!$C$6:$C$150,'PP2'!$B$6:$B$150,"") -> 2 | H10: =_xlfn.XLOOKUP(G10,'PP2'!$B$6:$B$150,'PP2'!$A$6:$A$150,0) -> 65.666667 | I10: =_xlfn.XLOOKUP($B10,'PP3'!$C$6:$C$150,'PP3'!$B$6:$B$150,"") -> 9 | J10: =_xlfn.XLOOKUP(I10,'PP3'!$B$6:$B$150,'PP3'!$A$6:$A$150,0) -> 23.434799 | K10: =_xlfn.XLOOKUP($B10,'PP4'!$C$6:$C$150,'PP4'!$B$6:$B$150,"") | L10: =_xlfn.XLOOKUP(K10,'PP4'!$B$6:$B$150,'PP4'!$A$6:$A$150,0) -> 0 | M10: =_xlfn.XLOOKUP($B10,'PP5'!$C$6:$C$150,'PP5'!$B$6:$B$150,"") -> 1 | N10: =_xlfn.XLOOKUP(M10,'PP5'!$B$6:$B$150,'PP5'!$A$6:$A$150,0) -> 84.286609 | O10: =_xlfn.XLOOKUP(B10,MPW!C$6:C$150,MPW!B$6:B$150,"") | P10: =_xlfn.XLOOKUP(O10,MPW!B$6:B$150,MPW!A$6:A$150,0) -> 0
A11: =ROW()-5 -> 6 | B11: WASIOŁKA Sebastian | D11: =SUM(F11,H11,J11,L11,N11,P11)-MIN(F11,H11,J11,L11,N11) -> 156.96258 | E11: =_xlfn.XLOOKUP($B11,'PP1'!$C$6:$C$150,'PP1'!$B$6:$B$150,"") | F11: =_xlfn.XLOOKUP(E11,'PP1'!$B$6:$B$150,'PP1'!$A$6:$A$150,0) -> 0 | G11: =_xlfn.XLOOKUP($B11,'PP2'!$C$6:$C$150,'PP2'!$B$6:$B$150,"") | H11: =_xlfn.XLOOKUP(G11,'PP2'!$B$6:$B$150,'PP2'!$A$6:$A$150,0) -> 0 | I11: =_xlfn.XLOOKUP($B11,'PP3'!$C$6:$C$150,'PP3'!$B$6:$B$150,"") | J11: =_xlfn.XLOOKUP(I11,'PP3'!$B$6:$B$150,'PP3'!$A$6:$A$150,0) -> 0 | K11: =_xlfn.XLOOKUP($B11,'PP4'!$C$6:$C$150,'PP4'!$B$6:$B$150,"") | L11: =_xlfn.XLOOKUP(K11,'PP4'!$B$6:$B$150,'PP4'!$A$6:$A$150,0) -> 0 | M11: =_xlfn.XLOOKUP($B11,'PP5'!$C$6:$C$150,'PP5'!$B$6:$B$150,"") -> 2k1 | N11: =_xlfn.XLOOKUP(M11,'PP5'!$B$6:$B$150,'PP5'!$A$6:$A$150,0) -> 61.946936 | O11: =_xlfn.XLOOKUP(B11,MPW!C$6:C$150,MPW!B$6:B$150,"") -> 2k1 | P11: =_xlfn.XLOOKUP(O11,MPW!B$6:B$150,MPW!A$6:A$150,0) -> 95.015645
A12: =ROW()-5 -> 7 | B12: ŻUKOWSKI Wojciech | D12: =SUM(F12,H12,J12,L12,N12,P12)-MIN(F12,H12,J12,L12,N12) -> 133.32423 | E12: =_xlfn.XLOOKUP($B12,'PP1'!$C$6:$C$150,'PP1'!$B$6:$B$150,"") | F12: =_xlfn.XLOOKUP(E12,'PP1'!$B$6:$B$150,'PP1'!$A$6:$A$150,0) -> 0 | G12: =_xlfn.XLOOKUP($B12,'PP2'!$C$6:$C$150,'PP2'!$B$6:$B$150,"") -> 3 | H12: =_xlfn.XLOOKUP(G12,'PP2'!$B$6:$B$150,'PP2'!$A$6:$A$150,0) -> 40.112279 | I12: =_xlfn.XLOOKUP($B12,'PP3'!$C$6:$C$150,'PP3'!$B$6:$B$150,"") -> 10 | J12: =_xlfn.XLOOKUP(I12,'PP3'!$B$6:$B$150,'PP3'!$A$6:$A$150,0) -> 21.681437 | K12: =_xlfn.XLOOKUP($B12,'PP4'!$C$6:$C$150,'PP4'!$B$6:$B$150,"") | L12: =_xlfn.XLOOKUP(K12,'PP4'!$B$6:$B$150,'PP4'!$A$6:$A$150,0) -> 0 | M12: =_xlfn.XLOOKUP($B12,'PP5'!$C$6:$C$150,'PP5'!$B$6:$B$150,"") -> 2 | N12: =_xlfn.XLOOKUP(M12,'PP5'!$B$6:$B$150,'PP5'!$A$6:$A$150,0) -> 45.024406 | O12: =_xlfn.XLOOKUP(B12,MPW!C$6:C$150,MPW!B$6:B$150,"") -> 4 | P12: =_xlfn.XLOOKUP(O12,MPW!B$6:B$150,MPW!A$6:A$150,0) -> 26.50611
A13: =ROW()-5 -> 8 | B13: PILUTKIEWICZ Igor | D13: =SUM(F13,H13,J13,L13,N13,P13)-MIN(F13,H13,J13,L13,N13) -> 91.437791 | E13: =_xlfn.XLOOKUP($B13,'PP1'!$C$6:$C$150,'PP1'!$B$6:$B$150,"") | F13: =_xlfn.XLOOKUP(E13,'PP1'!$B$6:$B$150,'PP1'!$A$6:$A$150,0) -> 0 | G13: =_xlfn.XLOOKUP($B13,'PP2'!$C$6:$C$150,'PP2'!$B$6:$B$150,"") | H13: =_xlfn.XLOOKUP(G13,'PP2'!$B$6:$B$150,'PP2'!$A$6:$A$150,0) -> 0 | I13: =_xlfn.XLOOKUP($B13,'PP3'!$C$6:$C$150,'PP3'!$B$6:$B$150,"") -> 8 | J13: =_xlfn.XLOOKUP(I13,'PP3'!$B$6:$B$150,'PP3'!$A$6:$A$150,0) -> 35.39489 | K13: =_xlfn.XLOOKUP($B13,'PP4'!$C$6:$C$150,'PP4'!$B$6:$B$150,"") -> 3 | L13: =_xlfn.XLOOKUP(K13,'PP4'!$B$6:$B$150,'PP4'!$A$6:$A$150,0) -> 40.112279 | M13: =_xlfn.XLOOKUP($B13,'PP5'!$C$6:$C$150,'PP5'!$B$6:$B$150,"") -> 3 | N13: =_xlfn.XLOOKUP(M13,'PP5'!$B$6:$B$150,'PP5'!$A$6:$A$150,0) -> 15.930622 | O13: =_xlfn.XLOOKUP(B13,MPW!C$6:C$150,MPW!B$6:B$150,"") | P13: =_xlfn.XLOOKUP(O13,MPW!B$6:B$150,MPW!A$6:A$150,0) -> 0
A14: =ROW()-5 -> 9 | B14: JASZCZAK Piotr | D14: =SUM(F14,H14,J14,L14,N14,P14)-MIN(F14,H14,J14,L14,N14) -> 67.515696 | E14: =_xlfn.XLOOKUP($B14,'PP1'!$C$6:$C$150,'PP1'!$B$6:$B$150,"") | F14: =_xlfn.XLOOKUP(E14,'PP1'!$B$6:$B$150,'PP1'!$A$6:$A$150,0) -> 0 | G14: =_xlfn.XLOOKUP($B14,'PP2'!$C$6:$C$150,'PP2'!$B$6:$B$150,"") | H14: =_xlfn.XLOOKUP(G14,'PP2'!$B$6:$B$150,'PP2'!$A$6:$A$150,0) -> 0 | I14: =_xlfn.XLOOKUP($B14,'PP3'!$C$6:$C$150,'PP3'!$B$6:$B$150,"") -> 6 | J14: =_xlfn.XLOOKUP(I14,'PP3'!$B$6:$B$150,'PP3'!$A$6:$A$150,0) -> 40.182363 | K14: =_xlfn.XLOOKUP($B14,'PP4'!$C$6:$C$150,'PP4'!$B$6:$B$150,"") -> 4 | L14: =_xlfn.XLOOKUP(K14,'PP4'!$B$6:$B$150,'PP4'!$A$6:$A$150,0) -> 27.333333 | M14: =_xlfn.XLOOKUP($B14,'PP5'!$C$6:$C$150,'PP5'!$B$6:$B$150,"") | N14: =_xlfn.XLOOKUP(M14,'PP5'!$B$6:$B$150,'PP5'!$A$6:$A$150,0) -> 0 | O14: =_xlfn.XLOOKUP(B14,MPW!C$6:C$150,MPW!B$6:B$150,"") | P14: =_xlfn.XLOOKUP(O14,MPW!B$6:B$150,MPW!A$6:A$150,0) -> 0
A15: =ROW()-5 -> 10 | B15: LEAHEY John | D15: =SUM(F15,H15,J15,L15,N15,P15)-MIN(F15,H15,J15,L15,N15) -> 56.929926 | E15: =_xlfn.XLOOKUP($B15,'PP1'!$C$6:$C$150,'PP1'!$B$6:$B$150,"") | F15: =_xlfn.XLOOKUP(E15,'PP1'!$B$6:$B$150,'PP1'!$A$6:$A$150,0) -> 0 | G15: =_xlfn.XLOOKUP($B15,'PP2'!$C$6:$C$150,'PP2'!$B$6:$B$150,"") | H15: =_xlfn.XLOOKUP(G15,'PP2'!$B$6:$B$150,'PP2'!$A$6:$A$150,0) -> 0 | I15: =_xlfn.XLOOKUP($B15,'PP3'!$C$6:$C$150,'PP3'!$B$6:$B$150,"") -> 4 | J15: =_xlfn.XLOOKUP(I15,'PP3'!$B$6:$B$150,'PP3'!$A$6:$A$150,0) -> 56.929926 | K15: =_xlfn.XLOOKUP($B15,'PP4'!$C$6:$C$150,'PP4'!$B$6:$B$150,"") | L15: =_xlfn.XLOOKUP(K15,'PP4'!$B$6:$B$150,'PP4'!$A$6:$A$150,0) -> 0 | M15: =_xlfn.XLOOKUP($B15,'PP5'!$C$6:$C$150,'PP5'!$B$6:$B$150,"") | N15: =_xlfn.XLOOKUP(M15,'PP5'!$B$6:$B$150,'PP5'!$A$6:$A$150,0) -> 0 | O15: =_xlfn.XLOOKUP(B15,MPW!C$6:C$150,MPW!B$6:B$150,"") | P15: =_xlfn.XLOOKUP(O15,MPW!B$6:B$150,MPW!A$6:A$150,0) -> 0
A16: =ROW()-5 -> 11 | B16: WOJTAS Bogusław | D16: =SUM(F16,H16,J16,L16,N16,P16)-MIN(F16,H16,J16,L16,N16) -> 42.488579 | E16: =_xlfn.XLOOKUP($B16,'PP1'!$C$6:$C$150,'PP1'!$B$6:$B$150,"") | F16: =_xlfn.XLOOKUP(E16,'PP1'!$B$6:$B$150,'PP1'!$A$6:$A$150,0) -> 0 | G16: =_xlfn.XLOOKUP($B16,'PP2'!$C$6:$C$150,'PP2'!$B$6:$B$150,"") | H16: =_xlfn.XLOOKUP(G16,'PP2'!$B$6:$B$150,'PP2'!$A$6:$A$150,0) -> 0 | I16: =_xlfn.XLOOKUP($B16,'PP3'!$C$6:$C$150,'PP3'!$B$6:$B$150,"") | J16: =_xlfn.XLOOKUP(I16,'PP3'!$B$6:$B$150,'PP3'!$A$6:$A$150,0) -> 0 | K16: =_xlfn.XLOOKUP($B16,'PP4'!$C$6:$C$150,'PP4'!$B$6:$B$150,"") | L16: =_xlfn.XLOOKUP(K16,'PP4'!$B$6:$B$150,'PP4'!$A$6:$A$150,0) -> 0 | M16: =_xlfn.XLOOKUP($B16,'PP5'!$C$6:$C$150,'PP5'!$B$6:$B$150,"") | N16: =_xlfn.XLOOKUP(M16,'PP5'!$B$6:$B$150,'PP5'!$A$6:$A$150,0) -> 0 | O16: =_xlfn.XLOOKUP(B16,MPW!C$6:C$150,MPW!B$6:B$150,"") -> 3 | P16: =_xlfn.XLOOKUP(O16,MPW!B$6:B$150,MPW!A$6:A$150,0) -> 42.488579
A17: =ROW()-5 -> 12 | B17: OLSZEWSKI Mikołaj | D17: =SUM(F17,H17,J17,L17,N17,P17)-MIN(F17,H17,J17,L17,N17) -> 37.617058 | E17: =_xlfn.XLOOKUP($B17,'PP1'!$C$6:$C$150,'PP1'!$B$6:$B$150,"") | F17: =_xlfn.XLOOKUP(E17,'PP1'!$B$6:$B$150,'PP1'!$A$6:$A$150,0) -> 0 | G17: =_xlfn.XLOOKUP($B17,'PP2'!$C$6:$C$150,'PP2'!$B$6:$B$150,"") | H17: =_xlfn.XLOOKUP(G17,'PP2'!$B$6:$B$150,'PP2'!$A$6:$A$150,0) -> 0 | I17: =_xlfn.XLOOKUP($B17,'PP3'!$C$6:$C$150,'PP3'!$B$6:$B$150,"") -> 7 | J17: =_xlfn.XLOOKUP(I17,'PP3'!$B$6:$B$150,'PP3'!$A$6:$A$150,0) -> 37.617058 | K17: =_xlfn.XLOOKUP($B17,'PP4'!$C$6:$C$150,'PP4'!$B$6:$B$150,"") | L17: =_xlfn.XLOOKUP(K17,'PP4'!$B$6:$B$150,'PP4'!$A$6:$A$150,0) -> 0 | M17: =_xlfn.XLOOKUP($B17,'PP5'!$C$6:$C$150,'PP5'!$B$6:$B$150,"") | N17: =_xlfn.XLOOKUP(M17,'PP5'!$B$6:$B$150,'PP5'!$A$6:$A$150,0) -> 0 | O17: =_xlfn.XLOOKUP(B17,MPW!C$6:C$150,MPW!B$6:B$150,"") | P17: =_xlfn.XLOOKUP(O17,MPW!B$6:B$150,MPW!A$6:A$150,0) -> 0
... A29: =ROW()-5 -> 24 | B29: GOLD Oleg | D29: =SUM(F29,H29,J29,L29,N29,P29)-MIN(F29,H29,J29,L29,N29) -> 1 | E29: =_xlfn.XLOOKUP($B29,'PP1'!$C$6:$C$150,'PP1'!$B$6:$B$150,"") | F29: =_xlfn.XLOOKUP(E29,'PP1'!$B$6:$B$150,'PP1'!$A$6:$A$150,0) -> 0 | G29: =_xlfn.XLOOKUP($B29,'PP2'!$C$6:$C$150,'PP2'!$B$6:$B$150,"") | H29: =_xlfn.XLOOKUP(G29,'PP2'!$B$6:$B$150,'PP2'!$A$6:$A$150,0) -> 0 | I29: =_xlfn.XLOOKUP($B29,'PP3'!$C$6:$C$150,'PP3'!$B$6:$B$150,"") -> 19 | J29: =_xlfn.XLOOKUP(I29,'PP3'!$B$6:$B$150,'PP3'!$A$6:$A$150,0) -> 1 | K29: =_xlfn.XLOOKUP($B29,'PP4'!$C$6:$C$150,'PP4'!$B$6:$B$150,"") | L29: =_xlfn.XLOOKUP(K29,'PP4'!$B$6:$B$150,'PP4'!$A$6:$A$150,0) -> 0 | M29: =_xlfn.XLOOKUP($B29,'PP5'!$C$6:$C$150,'PP5'!$B$6:$B$150,"") | N29: =_xlfn.XLOOKUP(M29,'PP5'!$B$6:$B$150,'PP5'!$A$6:$A$150,0) -> 0 | O29: =_xlfn.XLOOKUP(B29,MPW!C$6:C$150,MPW!B$6:B$150,"") | P29: =_xlfn.XLOOKUP(O29,MPW!B$6:B$150,MPW!A$6:A$150,0) -> 0
A30: =ROW()-5 -> 25 | D30: =SUM(F30,H30,J30,L30,N30,P30)-MIN(F30,H30,J30,L30,N30) -> 0 | E30: =_xlfn.XLOOKUP($B30,'PP1'!$C$6:$C$150,'PP1'!$B$6:$B$150,"") | F30: =_xlfn.XLOOKUP(E30,'PP1'!$B$6:$B$150,'PP1'!$A$6:$A$150,0) -> 0 | G30: =_xlfn.XLOOKUP($B30,'PP2'!$C$6:$C$150,'PP2'!$B$6:$B$150,"") | H30: =_xlfn.XLOOKUP(G30,'PP2'!$B$6:$B$150,'PP2'!$A$6:$A$150,0) -> 0 | I30: =_xlfn.XLOOKUP($B30,'PP3'!$C$6:$C$150,'PP3'!$B$6:$B$150,"") | J30: =_xlfn.XLOOKUP(I30,'PP3'!$B$6:$B$150,'PP3'!$A$6:$A$150,0) -> 0 | K30: =_xlfn.XLOOKUP($B30,'PP4'!$C$6:$C$150,'PP4'!$B$6:$B$150,"") | L30: =_xlfn.XLOOKUP(K30,'PP4'!$B$6:$B$150,'PP4'!$A$6:$A$150,0) -> 0 | M30: =_xlfn.XLOOKUP($B30,'PP5'!$C$6:$C$150,'PP5'!$B$6:$B$150,"") | N30: =_xlfn.XLOOKUP(M30,'PP5'!$B$6:$B$150,'PP5'!$A$6:$A$150,0) -> 0 | O30: =_xlfn.XLOOKUP(B30,MPW!C$6:C$150,MPW!B$6:B$150,"") | P30: =_xlfn.XLOOKUP(O30,MPW!B$6:B$150,MPW!A$6:A$150,0) -> 0
A31: =ROW()-5 -> 26 | D31: =SUM(F31,H31,J31,L31,N31,P31)-MIN(F31,H31,J31,L31,N31) -> 0 | E31: =_xlfn.XLOOKUP($B31,'PP1'!$C$6:$C$150,'PP1'!$B$6:$B$150,"") | F31: =_xlfn.XLOOKUP(E31,'PP1'!$B$6:$B$150,'PP1'!$A$6:$A$150,0) -> 0 | G31: =_xlfn.XLOOKUP($B31,'PP2'!$C$6:$C$150,'PP2'!$B$6:$B$150,"") | H31: =_xlfn.XLOOKUP(G31,'PP2'!$B$6:$B$150,'PP2'!$A$6:$A$150,0) -> 0 | I31: =_xlfn.XLOOKUP($B31,'PP3'!$C$6:$C$150,'PP3'!$B$6:$B$150,"") | J31: =_xlfn.XLOOKUP(I31,'PP3'!$B$6:$B$150,'PP3'!$A$6:$A$150,0) -> 0 | K31: =_xlfn.XLOOKUP($B31,'PP4'!$C$6:$C$150,'PP4'!$B$6:$B$150,"") | L31: =_xlfn.XLOOKUP(K31,'PP4'!$B$6:$B$150,'PP4'!$A$6:$A$150,0) -> 0 | M31: =_xlfn.XLOOKUP($B31,'PP5'!$C$6:$C$150,'PP5'!$B$6:$B$150,"") | N31: =_xlfn.XLOOKUP(M31,'PP5'!$B$6:$B$150,'PP5'!$A$6:$A$150,0) -> 0 | O31: =_xlfn.XLOOKUP(B31,MPW!C$6:C$150,MPW!B$6:B$150,"") | P31: =_xlfn.XLOOKUP(O31,MPW!B$6:B$150,MPW!A$6:A$150,0) -> 0
A32: =ROW()-5 -> 27 | D32: =SUM(F32,H32,J32,L32,N32,P32)-MIN(F32,H32,J32,L32,N32) -> 0 | E32: =_xlfn.XLOOKUP($B32,'PP1'!$C$6:$C$150,'PP1'!$B$6:$B$150,"") | F32: =_xlfn.XLOOKUP(E32,'PP1'!$B$6:$B$150,'PP1'!$A$6:$A$150,0) -> 0 | G32: =_xlfn.XLOOKUP($B32,'PP2'!$C$6:$C$150,'PP2'!$B$6:$B$150,"") | H32: =_xlfn.XLOOKUP(G32,'PP2'!$B$6:$B$150,'PP2'!$A$6:$A$150,0) -> 0 | I32: =_xlfn.XLOOKUP($B32,'PP3'!$C$6:$C$150,'PP3'!$B$6:$B$150,"") | J32: =_xlfn.XLOOKUP(I32,'PP3'!$B$6:$B$150,'PP3'!$A$6:$A$150,0) -> 0 | K32: =_xlfn.XLOOKUP($B32,'PP4'!$C$6:$C$150,'PP4'!$B$6:$B$150,"") | L32: =_xlfn.XLOOKUP(K32,'PP4'!$B$6:$B$150,'PP4'!$A$6:$A$150,0) -> 0 | M32: =_xlfn.XLOOKUP($B32,'PP5'!$C$6:$C$150,'PP5'!$B$6:$B$150,"") | N32: =_xlfn.XLOOKUP(M32,'PP5'!$B$6:$B$150,'PP5'!$A$6:$A$150,0) -> 0 | O32: =_xlfn.XLOOKUP(B32,MPW!C$6:C$150,MPW!B$6:B$150,"") | P32: =_xlfn.XLOOKUP(O32,MPW!B$6:B$150,MPW!A$6:A$150,0) -> 0

Sheet PP1
H1: Liczba uczestników: | I1: GP Punkty | J1: Bonus za rundę | K1: Mnożnik za podium
B2: miejsce: | C2: OPOLE | H2: 8 | I2: 50 | J2: 10 | K2: =3*H2^(1/3) -> 6
B3: data: | C3: 28.09.2025
A5: Punkty | B5: Miejsce Place | C5: Nazwisko Imię Name | D5: Klub Club(s) | E5: Okręg Division | F5: Państwo Country | H5: Miejsce | I5: Punkty za miejsce | J5: liczba wygranych walk pucharowych | K5: bonus z rundy pucharowej | L5: punkty za podium | M5: Suma
A6: =M6 -> 98 | B6: =IF(H6>$H$2,"",(ROW()-5)) -> 1 | C6: ZIELIŃSKI Dariusz | H6: 1 | I6: =IF(H2=1,50,IF(H6<$H$2+1,($I$2-($I$2-1)*(LOG(H6)/LOG($H$2))),"")) -> 50 | J6: =INT(LOG($H$2,2))-ROUNDUP(LOG(H6,2),0)+IF(OR($H$2=1,$H$2=2,$H$2=4,$H$2=8,$H$2=16,$H$2=32,$H$2=64,$H$2=128,$H$2=256),0,1) -> 3 | K6: =J6*$J$2 -> 30 | L6: =3*K2 -> 18 | M6: =IF(I6<>"",K6+I6+L6,0) -> 98
A7: =M7 -> 65.666667 | B7: =IF(H7>$H$2,"",(ROW()-5)) -> 2 | C7: ATANASSOW Aleksander | H7: 2 | I7: =IF(H7<$H$2+1,($I$2-($I$2-1)*(LOG(H7)/LOG($H$2))),"") -> 33.666667 | J7: =INT(LOG($H$2,2))-ROUNDUP(LOG(H7,2),0)+IF(OR($H$2=1,$H$2=2,$H$2=4,$H$2=8,$H$2=16,$H$2=32,$H$2=64,$H$2=128,$H$2=256),0,1) -> 2 | K7: =J7*$J$2 -> 20 | L7: =2*K2 -> 12 | M7: =IF(I7<>"",K7+I7+L7,0) -> 65.666667
A8: =M8 -> 40.112279 | B8: =IF(H8>$H$2,"",(ROW()-5)) -> 3 | C8: JENDRYŚ Marek | H8: 3 | I8: =IF(H8<$H$2+1,($I$2-($I$2-1)*(LOG(H8)/LOG($H$2))),"") -> 24.112279 | J8: =INT(LOG($H$2,2))-ROUNDUP(LOG(H8,2),0)+IF(OR($H$2=1,$H$2=2,$H$2=4,$H$2=8,$H$2=16,$H$2=32,$H$2=64,$H$2=128,$H$2=256),0,1) -> 1 | K8: =J8*$J$2 -> 10 | L8: =K2 -> 6 | M8: =IF(I8<>"",K8+I8+L8,0) -> 40.112279
A9: =M9 -> 27.333333 | B9: =IF(H9>$H$2,"",(ROW()-5)) -> 4 | C9: KORONA Przemysław | H9: 4 | I9: =IF(H9<$H$2+1,($I$2-($I$2-1)*(LOG(H9)/LOG($H$2))),"") -> 17.333333 | J9: =INT(LOG($H$2,2))-ROUNDUP(LOG(H9,2),0)+IF(OR($H$2=1,$H$2=2,$H$2=4,$H$2=8,$H$2=16,$H$2=32,$H$2=64,$H$2=128,$H$2=256),0,1) -> 1 | K9: =J9*$J$2 -> 10 | M9: =IF(I9<>"",K9+I9+L9,0) -> 27.333333
A10: =M10 -> 12.075174 | B10: =IF(H10>$H$2,"",(ROW()-5)) -> 5 | C10: DROBIŃSKI Leszek | H10: 5 | I10: =IF(H10<$H$2+1,($I$2-($I$2-1)*(LOG(H10)/LOG($H$2))),"") -> 12.075174 | J10: =INT(LOG($H$2,2))-ROUNDUP(LOG(H10,2),0)+IF(OR($H$2=1,$H$2=2,$H$2=4,$H$2=8,$H$2=16,$H$2=32,$H$2=64,$H$2=128,$H$2=256),0,1) -> 0 | K10: =J10*$J$2 -> 0 | M10: =IF(I10<>"",K10+I10+L10,0) -> 12.075174
A11: =M11 -> 7.7789458 | B11: =IF(H11>$H$2,"",(ROW()-5)) -> 6 | C11: PARDUS Borys | H11: 6 | I11: =IF(H11<$H$2+1,($I$2-($I$2-1)*(LOG(H11)/LOG($H$2))),"") -> 7.7789458 | J11: =INT(LOG($H$2,2))-ROUNDUP(LOG(H11,2),0)+IF(OR($H$2=1,$H$2=2,$H$2=4,$H$2=8,$H$2=16,$H$2=32,$H$2=64,$H$2=128,$H$2=256),0,1) -> 0 | K11: =J11*$J$2 -> 0 | M11: =IF(I11<>"",K11+I11+L11,0) -> 7.7789458
A12: =M12 -> 4.1465363 | B12: =IF(H12>$H$2,"",(ROW()-5)) -> 7 | C12: WIERZBICKI Jacek | H12: 7 | I12: =IF(H12<$H$2+1,($I$2-($I$2-1)*(LOG(H12)/LOG($H$2))),"") -> 4.1465363 | J12: =INT(LOG($H$2,2))-ROUNDUP(LOG(H12,2),0)+IF(OR($H$2=1,$H$2=2,$H$2=4,$H$2=8,$H$2=16,$H$2=32,$H$2=64,$H$2=128,$H$2=256),0,1) -> 0 | K12: =J12*$J$2 -> 0 | M12: =IF(I12<>"",K12+I12+L12,0) -> 4.1465363
A13: =M13 -> 1 | B13: =IF(H13>$H$2,"",(ROW()-5)) -> 8 | C13: HEŁKA Jacek | H13: 8 | I13: =IF(H13<$H$2+1,($I$2-($I$2-1)*(LOG(H13)/LOG($H$2))),"") -> 1 | J13: =INT(LOG($H$2,2))-ROUNDUP(LOG(H13,2),0)+IF(OR($H$2=1,$H$2=2,$H$2=4,$H$2=8,$H$2=16,$H$2=32,$H$2=64,$H$2=128,$H$2=256),0,1) -> 0 | K13: =J13*$J$2 -> 0 | M13: =IF(I13<>"",K13+I13+L13,0) -> 1
A14: =M14 -> 0 | B14: =IF(H14>$H$2,"",(ROW()-5)) | H14: 9 | I14: =IF(H14<$H$2+1,($I$2-($I$2-1)*(LOG(H14)/LOG($H$2))),"") | J14: =INT(LOG($H$2,2))-ROUNDUP(LOG(H14,2),0)+IF(OR($H$2=1,$H$2=2,$H$2=4,$H$2=8,$H$2=16,$H$2=32,$H$2=64,$H$2=128,$H$2=256),0,1) -> -1 | K14: =J14*$J$2 -> -10 | M14: =IF(I14<>"",K14+I14+L14,0) -> 0
A15: =M15 -> 0 | B15: =IF(H15>$H$2,"",(ROW()-5)) | H15: 10 | I15: =IF(H15<$H$2+1,($I$2-($I$2-1)*(LOG(H15)/LOG($H$2))),"") | J15: =INT(LOG($H$2,2))-ROUNDUP(LOG(H15,2),0)+IF(OR($H$2=1,$H$2=2,$H$2=4,$H$2=8,$H$2=16,$H$2=32,$H$2=64,$H$2=128,$H$2=256),0,1) -> -1 | K15: =J15*$J$2 -> -10 | M15: =IF(I15<>"",K15+I15+L15,0) -> 0
A16: =M16 -> 0 | B16: =IF(H16>$H$2,"",(ROW()-5)) | H16: 11 | I16: =IF(H16<$H$2+1,($I$2-($I$2-1)*(LOG(H16)/LOG($H$2))),"") | J16: =INT(LOG($H$2,2))-ROUNDUP(LOG(H16,2),0)+IF(OR($H$2=1,$H$2=2,$H$2=4,$H$2=8,$H$2=16,$H$2=32,$H$2=64,$H$2=128,$H$2=256),0,1) -> -1 | K16: =J16*$J$2 -> -10 | M16: =IF(I16<>"",K16+I16+L16,0) -> 0
A17: =M17 -> 0 | B17: =IF(H17>$H$2,"",(ROW()-5)) | H17: 12 | I17: =IF(H17<$H$2+1,($I$2-($I$2-1)*(LOG(H17)/LOG($H$2))),"") | J17: =INT(LOG($H$2,2))-ROUNDUP(LOG(H17,2),0)+IF(OR($H$2=1,$H$2=2,$H$2=4,$H$2=8,$H$2=16,$H$2=32,$H$2=64,$H$2=128,$H$2=256),0,1) -> -1 | K17: =J17*$J$2 -> -10 | M17: =IF(I17<>"",K17+I17+L17,0) -> 0
A18: =M18 -> 0 | B18: =IF(H18>$H$2,"",(ROW()-5)) | H18: 13 | I18: =IF(H18<$H$2+1,($I$2-($I$2-1)*(LOG(H18)/LOG($H$2))),"") | J18: =INT(LOG($H$2,2))-ROUNDUP(LOG(H18,2),0)+IF(OR($H$2=1,$H$2=2,$H$2=4,$H$2=8,$H$2=16,$H$2=32,$H$2=64,$H$2=128,$H$2=256),0,1) -> -1 | K18: =J18*$J$2 -> -10 | M18: =IF(I18<>"",K18+I18+L18,0) -> 0
A19: =M19 -> 0 | B19: =IF(H19>$H$2,"",(ROW()-5)) | H19: 14 | I19: =IF(H19<$H$2+1,($I$2-($I$2-1)*(LOG(H19)/LOG($H$2))),"") | J19: =INT(LOG($H$2,2))-ROUNDUP(LOG(H19,2),0)+IF(OR($H$2=1,$H$2=2,$H$2=4,$H$2=8,$H$2=16,$H$2=32,$H$2=64,$H$2=128,$H$2=256),0,1) -> -1 | K19: =J19*$J$2 -> -10 | M19: =IF(I19<>"",K19+I19+L19,0) -> 0
A20: =M20 -> 0 | B20: =IF(H20>$H$2,"",(ROW()-5)) | H20: 15 | I20: =IF(H20<$H$2+1,($I$2-($I$2-1)*(LOG(H20)/LOG($H$2))),"") | J20: =INT(LOG($H$2,2))-ROUNDUP(LOG(H20,2),0)+IF(OR($H$2=1,$H$2=2,$H$2=4,$H$2=8,$H$2=16,$H$2=32,$H$2=64,$H$2=128,$H$2=256),0,1) -> -1 | K20: =J20*$J$2 -> -10 | M20: =IF(I20<>"",K20+I20+L20,0) -> 0
A21: =M21 -> 0 | B21: =IF(H21>$H$2,"",(ROW()-5)) | H21: 16 | I21: =IF(H21<$H$2+1,($I$2-($I$2-1)*(LOG(H21)/LOG($H$2))),"") | J21: =INT(LOG($H$2,2))-ROUNDUP(LOG(H21,2),0)+IF(OR($H$2=1,$H$2=2,$H$2=4,$H$2=8,$H$2=16,$H$2=32,$H$2=64,$H$2=128,$H$2=256),0,1) -> -1 | K21: =J21*$J$2 -> -10 | M21: =IF(I21<>"",K21+I21+L21,0) -> 0
A22: =M22 -> 0 | B22: =IF(H22>$H$2,"",(ROW()-5)) | H22: 17 | I22: =IF(H22<$H$2+1,($I$2-($I$2-1)*(LOG(H22)/LOG($H$2))),"") | J22: =INT(LOG($H$2,2))-ROUNDUP(LOG(H22,2),0)+IF(OR($H$2=1,$H$2=2,$H$2=4,$H$2=8,$H$2=16,$H$2=32,$H$2=64,$H$2=128,$H$2=256),0,1) -> -2 | K22: =J22*$J$2 -> -20 | M22: =IF(I22<>"",K22+I22+L22,0) -> 0
A23: =M23 -> 0 | B23: =IF(H23>$H$2,"",(ROW()-5)) | H23: 18 | I23: =IF(H23<$H$2+1,($I$2-($I$2-1)*(LOG(H23)/LOG($H$2))),"") | J23: =INT(LOG($H$2,2))-ROUNDUP(LOG(H23,2),0)+IF(OR($H$2=1,$H$2=2,$H$2=4,$H$2=8,$H$2=16,$H$2=32,$H$2=64,$H$2=128,$H$2=256),0,1) -> -2 | K23: =J23*$J$2 -> -20 | M23: =IF(I23<>"",K23+I23+L23,0) -> 0
A24: =M24 -> 0 | B24: =IF(H24>$H$2,"",(ROW()-5)) | H24: 19 | I24: =IF(H24<$H$2+1,($I$2-($I$2-1)*(LOG(H24)/LOG($H$2))),"") | J24: =INT(LOG($H$2,2))-ROUNDUP(LOG(H24,2),0)+IF(OR($H$2=1,$H$2=2,$H$2=4,$H$2=8,$H$2=16,$H$2=32,$H$2=64,$H$2=128,$H$2=256),0,1) -> -2 | K24: =J24*$J$2 -> -20 | M24: =IF(I24<>"",K24+I24+L24,0) -> 0
A25: =M25 -> 0 | B25: =IF(H25>$H$2,"",(ROW()-5)) | H25: 20 | I25: =IF(H25<$H$2+1,($I$2-($I$2-1)*(LOG(H25)/LOG($H$2))),"") | J25: =INT(LOG($H$2,2))-ROUNDUP(LOG(H25,2),0)+IF(OR($H$2=1,$H$2=2,$H$2=4,$H$2=8,$H$2=16,$H$2=32,$H$2=64,$H$2=128,$H$2=256),0,1) -> -2 | K25: =J25*$J$2 -> -20 | M25: =IF(I25<>"",K25+I25+L25,0) -> 0
... A37: =M37 -> 0 | B37: =IF(H37>$H$2,"",(ROW()-5)) | H37: 32 | I37: =IF(H37<$H$2+1,($I$2-($I$2-1)*(LOG(H37)/LOG($H$2))),"") | J37: =INT(LOG($H$2,2))-ROUNDUP(LOG(H37,2),0)+IF(OR($H$2=1,$H$2=2,$H$2=4,$H$2=8,$H$2=16,$H$2=32,$H$2=64,$H$2=128,$H$2=256),0,1) -> -2 | K37: =J37*$J$2 -> -20 | M37: =IF(I37<>"",K37+I37+L37,0) -> 0
B38: =IF(H38>$H$2,"",(ROW()-5)) | H38: 33 | I38: =IF(H38<$H$2+1,($I$2-($I$2-1)*(LOG(H38)/LOG($H$2))),"") | J38: =INT(LOG($H$2,2))-ROUNDUP(LOG(H38,2),0)+IF(OR($H$2=1,$H$2=2,$H$2=4,$H$2=8,$H$2=16,$H$2=32,$H$2=64,$H$2=128,$H$2=256),0,1) -> -3 | K38: =J38*$J$2 -> -30 | M38: =IF(I38<>"",K38+I38+L38,0) -> 0
B39: =IF(H39>$H$2,"",(ROW()-5)) | H39: 34 | I39: =IF(H39<$H$2+1,($I$2-($I$2-1)*(LOG(H39)/LOG($H$2))),"") | J39: =INT(LOG($H$2,2))-ROUNDUP(LOG(H39,2),0)+IF(OR($H$2=1,$H$2=2,$H$2=4,$H$2=8,$H$2=16,$H$2=32,$H$2=64,$H$2=128,$H$2=256),0,1) -> -3 | K39: =J39*$J$2 -> -30 | M39: =IF(I39<>"",K39+I39+L39,0) -> 0
B40: =IF(H40>$H$2,"",(ROW()-5)) | H40: 35 | I40: =IF(H40<$H$2+1,($I$2-($I$2-1)*(LOG(H40)/LOG($H$2))),"") | J40: =INT(LOG($H$2,2))-ROUNDUP(LOG(H40,2),0)+IF(OR($H$2=1,$H$2=2,$H$2=4,$H$2=8,$H$2=16,$H$2=32,$H$2=64,$H$2=128,$H$2=256),0,1) -> -3 | K40: =J40*$J$2 -> -30 | M40: =IF(I40<>"",K40+I40+L40,0) -> 0
B41: =IF(H41>$H$2,"",(ROW()-5)) | H41: 36 | I41: =IF(H41<$H$2+1,($I$2-($I$2-1)*(LOG(H41)/LOG($H$2))),"") | J41: =INT(LOG($H$2,2))-ROUNDUP(LOG(H41,2),0)+IF(OR($H$2=1,$H$2=2,$H$2=4,$H$2=8,$H$2=16,$H$2=32,$H$2=64,$H$2=128,$H$2=256),0,1) -> -3 | K41: =J41*$J$2 -> -30 | M41: =IF(I41<>"",K41+I41+L41,0) -> 0
B42: =IF(H42>$H$2,"",(ROW()-5)) | H42: 37 | I42: =IF(H42<$H$2+1,($I$2-($I$2-1)*(LOG(H42)/LOG($H$2))),"") | J42: =INT(LOG($H$2,2))-ROUNDUP(LOG(H42,2),0)+IF(OR($H$2=1,$H$2=2,$H$2=4,$H$2=8,$H$2=16,$H$2=32,$H$2=64,$H$2=128,$H$2=256),0,1) -> -3 | K42: =J42*$J$2 -> -30 | M42: =IF(I42<>"",K42+I42+L42,0) -> 0
B43: =IF(H43>$H$2,"",(ROW()-5)) | H43: 38 | I43: =IF(H43<$H$2+1,($I$2-($I$2-1)*(LOG(H43)/LOG($H$2))),"") | J43: =INT(LOG($H$2,2))-ROUNDUP(LOG(H43,2),0)+IF(OR($H$2=1,$H$2=2,$H$2=4,$H$2=8,$H$2=16,$H$2=32,$H$2=64,$H$2=128,$H$2=256),0,1) -> -3 | K43: =J43*$J$2 -> -30 | M43: =IF(I43<>"",K43+I43+L43,0) -> 0
B44: =IF(H44>$H$2,"",(ROW()-5)) | H44: 39 | I44: =IF(H44<$H$2+1,($I$2-($I$2-1)*(LOG(H44)/LOG($H$2))),"") | J44: =INT(LOG($H$2,2))-ROUNDUP(LOG(H44,2),0)+IF(OR($H$2=1,$H$2=2,$H$2=4,$H$2=8,$H$2=16,$H$2=32,$H$2=64,$H$2=128,$H$2=256),0,1) -> -3 | K44: =J44*$J$2 -> -30 | M44: =IF(I44<>"",K44+I44+L44,0) -> 0
B45: =IF(H45>$H$2,"",(ROW()-5)) | H45: 40 | I45: =IF(H45<$H$2+1,($I$2-($I$2-1)*(LOG(H45)/LOG($H$2))),"") | J45: =INT(LOG($H$2,2))-ROUNDUP(LOG(H45,2),0)+IF(OR($H$2=1,$H$2=2,$H$2=4,$H$2=8,$H$2=16,$H$2=32,$H$2=64,$H$2=128,$H$2=256),0,1) -> -3 | K45: =J45*$J$2 -> -30 | M45: =IF(I45<>"",K45+I45+L45,0) -> 0
B46: =IF(H46>$H$2,"",(ROW()-5)) | H46: 41 | I46: =IF(H46<$H$2+1,($I$2-($I$2-1)*(LOG(H46)/LOG($H$2))),"") | J46: =INT(LOG($H$2,2))-ROUNDUP(LOG(H46,2),0)+IF(OR($H$2=1,$H$2=2,$H$2=4,$H$2=8,$H$2=16,$H$2=32,$H$2=64,$H$2=128,$H$2=256),0,1) -> -3 | K46: =J46*$J$2 -> -30 | M46: =IF(I46<>"",K46+I46+L46,0) -> 0
B47: =IF(H47>$H$2,"",(ROW()-5)) | H47: 42 | I47: =IF(H47<$H$2+1,($I$2-($I$2-1)*(LOG(H47)/LOG($H$2))),"") | J47: =INT(LOG($H$2,2))-ROUNDUP(LOG(H47,2),0)+IF(OR($H$2=1,$H$2=2,$H$2=4,$H$2=8,$H$2=16,$H$2=32,$H$2=64,$H$2=128,$H$2=256),0,1) -> -3 | K47: =J47*$J$2 -> -30 | M47: =IF(I47<>"",K47+I47+L47,0) -> 0
B48: =IF(H48>$H$2,"",(ROW()-5)) | H48: 43 | I48: =IF(H48<$H$2+1,($I$2-($I$2-1)*(LOG(H48)/LOG($H$2))),"") | J48: =INT(LOG($H$2,2))-ROUNDUP(LOG(H48,2),0)+IF(OR($H$2=1,$H$2=2,$H$2=4,$H$2=8,$H$2=16,$H$2=32,$H$2=64,$H$2=128,$H$2=256),0,1) -> -3 | K48: =J48*$J$2 -> -30 | M48: =IF(I48<>"",K48+I48+L48,0) -> 0
B49: =IF(H49>$H$2,"",(ROW()-5)) | H49: 44 | I49: =IF(H49<$H$2+1,($I$2-($I$2-1)*(LOG(H49)/LOG($H$2))),"") | J49: =INT(LOG($H$2,2))-ROUNDUP(LOG(H49,2),0)+IF(OR($H$2=1,$H$2=2,$H$2=4,$H$2=8,$H$2=16,$H$2=32,$H$2=64,$H$2=128,$H$2=256),0,1) -> -3 | K49: =J49*$J$2 -> -30 | M49: =IF(I49<>"",K49+I49+L49,0) -> 0
... B65: =IF(H65>$H$2,"",(ROW()-5)) | H65: 60 | I65: =IF(H65<$H$2+1,($I$2-($I$2-1)*(LOG(H65)/LOG($H$2))),"") | J65: =INT(LOG($H$2,2))-ROUNDUP(LOG(H65,2),0)+IF(OR($H$2=1,$H$2=2,$H$2=4,$H$2=8,$H$2=16,$H$2=32,$H$2=64,$H$2=128,$H$2=256),0,1) -> -3 | K65: =J65*$J$2 -> -30 | M65: =IF(I65<>"",K65+I65+L65,0) -> 0
H66: 61 | I66: =IF(H66<$H$2+1,($I$2-($I$2-1)*(LOG(H66)/LOG($H$2))),"") | J66: =INT(LOG($H$2,2))-ROUNDUP(LOG(H66,2),0)+IF(OR($H$2=1,$H$2=2,$H$2=4,$H$2=8,$H$2=16,$H$2=32,$H$2=64,$H$2=128,$H$2=256),0,1) -> -3 | K66: =J66*$J$2 -> -30 | M66: =IF(I66<>"",K66+I66+L66,0) -> 0
H67: 62 | I67: =IF(H67<$H$2+1,($I$2-($I$2-1)*(LOG(H67)/LOG($H$2))),"") | J67: =INT(LOG($H$2,2))-ROUNDUP(LOG(H67,2),0)+IF(OR($H$2=1,$H$2=2,$H$2=4,$H$2=8,$H$2=16,$H$2=32,$H$2=64,$H$2=128,$H$2=256),0,1) -> -3 | K67: =J67*$J$2 -> -30 | M67: =IF(I67<>"",K67+I67+L67,0) -> 0
...

Sheet PP2
B1: miejsce: | C1: II Puchar Weteranów Poznań | H1: Liczba uczestników: | I1: GP Punkty | J1: Bonus za rundę | K1: Mnożnik za podium
A2: LINK | B2: turniej: | C2: SZPADA MĘŻCZYZN 2 WETERANI | H2: 8 | I2: 50 | J2: 10 | K2: =3*H2^(1/3) -> 6
A3: B | B3: data: | C3: Sunday, October 26, 2025 1:00 PM
C4: httPS://www.fencingtimelive.com/events/results/download/0387CC20A25B4EBA9BDAFAB148E8C12B
A5: Punkty | B5: Miejsce Place | C5: Nazwisko Imię Name | D5: Klub Club(s) | E5: Okręg Division | F5: Państwo Country | H5: Miejsce | I5: Punkty za miejsce | J5: liczba wygranych walk pucharowych | K5: bonus z rundy pucharowej | L5: punkty za podium | M5: Suma
A6: =M6 -> 98 | B6: =IF(H6>$H$2,"",(ROW()-5)) -> 1 | C6: KORONA Przemysław | D6: AZS AWF WARSZAWA | H6: 1 | I6: =IF(H2=1,50,IF(H6<$H$2+1,($I$2-($I$2-1)*(LOG(H6)/LOG($H$2))),"")) -> 50 | J6: =INT(LOG($H$2,2))-ROUNDUP(LOG(H6,2),0)+IF(OR($H$2=1,$H$2=2,$H$2=4,$H$2=8,$H$2=16,$H$2=32,$H$2=64,$H$2=128,$H$2=256),0,1) -> 3 | K6: =J6*$J$2 -> 30 | L6: =3*K2 -> 18 | M6: =IF(I6<>"",K6+I6+L6,0) -> 98
A7: =M7 -> 65.666667 | B7: =IF(H7>$H$2,"",(ROW()-5)) -> 2 | C7: DROBIŃSKI Leszek | D7: WARTA-MUSZKIETEROWIE POZNAŃ | H7: 2 | I7: =IF(H7<$H$2+1,($I$2-($I$2-1)*(LOG(H7)/LOG($H$2))),"") -> 33.666667 | J7: =INT(LOG($H$2,2))-ROUNDUP(LOG(H7,2),0)+IF(OR($H$2=1,$H$2=2,$H$2=4,$H$2=8,$H$2=16,$H$2=32,$H$2=64,$H$2=128,$H$2=256),0,1) -> 2 | K7: =J7*$J$2 -> 20 | L7: =2*K2 -> 12 | M7: =IF(I7<>"",K7+I7+L7,0) -> 65.666667
A8: =M8 -> 40.112279 | B8: =IF(H8>$H$2,"",(ROW()-5)) -> 3 | C8: ŻUKOWSKI Wojciech | D8: STOWARZYSZENIE POLSKICH WETERANÓW SZERMIERKI | H8: 3 | I8: =IF(H8<$H$2+1,($I$2-($I$2-1)*(LOG(H8)/LOG($H$2))),"") -> 24.112279 | J8: =INT(LOG($H$2,2))-ROUNDUP(LOG(H8,2),0)+IF(OR($H$2=1,$H$2=2,$H$2=4,$H$2=8,$H$2=16,$H$2=32,$H$2=64,$H$2=128,$H$2=256),0,1) -> 1 | K8: =J8*$J$2 -> 10 | L8: =K2 -> 6 | M8: =IF(I8<>"",K8+I8+L8,0) -> 40.112279
A9: =M9 -> 27.333333 | B9: =IF(H9>$H$2,"",(ROW()-5)) -> 4 | C9: STANIEWICZ Witold | D9: WARTA-MUSZKIETEROWIE POZNAŃ | H9: 4 | I9: =IF(H9<$H$2+1,($I$2-($I$2-1)*(LOG(H9)/LOG($H$2))),"") -> 17.333333 | J9: =INT(LOG($H$2,2))-ROUNDUP(LOG(H9,2),0)+IF(OR($H$2=1,$H$2=2,$H$2=4,$H$2=8,$H$2=16,$H$2=32,$H$2=64,$H$2=128,$H$2=256),0,1) -> 1 | K9: =J9*$J$2 -> 10 | M9: =IF(I9<>"",K9+I9+L9,0) -> 27.333333
A10: =M10 -> 12.075174 | B10: =IF(H10>$H$2,"",(ROW()-5)) -> 5 | C10: WIERZBICKI Jacek | D10: AZS KU POLITECHNIKI OPOLSKIEJ | H10: 5 | I10: =IF(H10<$H$2+1,($I$2-($I$2-1)*(LOG(H10)/LOG($H$2))),"") -> 12.075174 | J10: =INT(LOG($H$2,2))-ROUNDUP(LOG(H10,2),0)+IF(OR($H$2=1,$H$2=2,$H$2=4,$H$2=8,$H$2=16,$H$2=32,$H$2=64,$H$2=128,$H$2=256),0,1) -> 0 | K10: =J10*$J$2 -> 0 | M10: =IF(I10<>"",K10+I10+L10,0) -> 12.075174
A11: =M11 -> 7.7789458 | B11: =IF(H11>$H$2,"",(ROW()-5)) -> 6 | C11: PARDUS Borys | D11: K.S. SZERMIERZ ŁOMIANKI | H11: 6 | I11: =IF(H11<$H$2+1,($I$2-($I$2-1)*(LOG(H11)/LOG($H$2))),"") -> 7.7789458 | J11: =INT(LOG($H$2,2))-ROUNDUP(LOG(H11,2),0)+IF(OR($H$2=1,$H$2=2,$H$2=4,$H$2=8,$H$2=16,$H$2=32,$H$2=64,$H$2=128,$H$2=256),0,1) -> 0 | K11: =J11*$J$2 -> 0 | M11: =IF(I11<>"",K11+I11+L11,0) -> 7.7789458
A12: =M12 -> 4.1465363 | B12: =IF(H12>$H$2,"",(ROW()-5)) -> 7 | C12: HEŁKA Jacek | D12: Tomasz Motyka Team AZS Wratislavia | H12: 7 | I12: =IF(H12<$H$2+1,($I$2-($I$2-1)*(LOG(H12)/LOG($H$2))),"") -> 4.1465363 | J12: =INT(LOG($H$2,2))-ROUNDUP(LOG(H12,2),0)+IF(OR($H$2=1,$H$2=2,$H$2=4,$H$2=8,$H$2=16,$H$2=32,$H$2=64,$H$2=128,$H$2=256),0,1) -> 0 | K12: =J12*$J$2 -> 0 | M12: =IF(I12<>"",K12+I12+L12,0) -> 4.1465363
A13: =M13 -> 1 | B13: =IF(H13>$H$2,"",(ROW()-5)) -> 8 | C13: TOMCZAK Ireneusz | D13: ŚA WARTA ŚREM | H13: 8 | I13: =IF(H13<$H$2+1,($I$2-($I$2-1)*(LOG(H13)/LOG($H$2))),"") -> 1 | J13: =INT(LOG($H$2,2))-ROUNDUP(LOG(H13,2),0)+IF(OR($H$2=1,$H$2=2,$H$2=4,$H$2=8,$H$2=16,$H$2=32,$H$2=64,$H$2=128,$H$2=256),0,1) -> 0 | K13: =J13*$J$2 -> 0 | M13: =IF(I13<>"",K13+I13+L13,0) -> 1
A14: =M14 -> 0 | B14: =IF(H14>$H$2,"",(ROW()-5)) | H14: 9 | I14: =IF(H14<$H$2+1,($I$2-($I$2-1)*(LOG(H14)/LOG($H$2))),"") | J14: =INT(LOG($H$2,2))-ROUNDUP(LOG(H14,2),0)+IF(OR($H$2=1,$H$2=2,$H$2=4,$H$2=8,$H$2=16,$H$2=32,$H$2=64,$H$2=128,$H$2=256),0,1) -> -1 | K14: =J14*$J$2 -> -10 | M14: =IF(I14<>"",K14+I14+L14,0) -> 0
A15: =M15 -> 0 | B15: =IF(H15>$H$2,"",(ROW()-5)) | H15: 10 | I15: =IF(H15<$H$2+1,($I$2-($I$2-1)*(LOG(H15)/LOG($H$2))),"") | J15: =INT(LOG($H$2,2))-ROUNDUP(LOG(H15,2),0)+IF(OR($H$2=1,$H$2=2,$H$2=4,$H$2=8,$H$2=16,$H$2=32,$H$2=64,$H$2=128,$H$2=256),0,1) -> -1 | K15: =J15*$J$2 -> -10 | M15: =IF(I15<>"",K15+I15+L15,0) -> 0
A16: =M16 -> 0 | B16: =IF(H16>$H$2,"",(ROW()-5)) | H16: 11 | I16: =IF(H16<$H$2+1,($I$2-($I$2-1)*(LOG(H16)/LOG($H$2))),"") | J16: =INT(LOG($H$2,2))-ROUNDUP(LOG(H16,2),0)+IF(OR($H$2=1,$H$2=2,$H$2=4,$H$2=8,$H$2=16,$H$2=32,$H$2=64,$H$2=128,$H$2=256),0,1) -> -1 | K16: =J16*$J$2 -> -10 | M16: =IF(I16<>"",K16+I16+L16,0) -> 0
A17: =M17 -> 0 | B17: =IF(H17>$H$2,"",(ROW()-5)) | H17: 12 | I17: =IF(H17<$H$2+1,($I$2-($I$2-1)*(LOG(H17)/LOG($H$2))),"") | J17: =INT(LOG($H$2,2))-ROUNDUP(LOG(H17,2),0)+IF(OR($H$2=1,$H$2=2,$H$2=4,$H$2=8,$H$2=16,$H$2=32,$H$2=64,$H$2=128,$H$2=256),0,1) -> -1 | K17: =J17*$J$2 -> -10 | M17: =IF(I17<>"",K17+I17+L17,0) -> 0
A18: =M18 -> 0 | B18: =IF(H18>$H$2,"",(ROW()-5)) | H18: 13 | I18: =IF(H18<$H$2+1,($I$2-($I$2-1)*(LOG(H18)/LOG($H$2))),"") | J18: =INT(LOG($H$2,2))-ROUNDUP(LOG(H18,2),0)+IF(OR($H$2=1,$H$2=2,$H$2=4,$H$2=8,$H$2=16,$H$2=32,$H$2=64,$H$2=128,$H$2=256),0,1) -> -1 | K18: =J18*$J$2 -> -10 | M18: =IF(I18<>"",K18+I18+L18,0) -> 0
A19: =M19 -> 0 | B19: =IF(H19>$H$2,"",(ROW()-5)) | H19: 14 | I19: =IF(H19<$H$2+1,($I$2-($I$2-1)*(LOG(H19)/LOG($H$2))),"") | J19: =INT(LOG($H$2,2))-ROUNDUP(LOG(H19,2),0)+IF(OR($H$2=1,$H$2=2,$H$2=4,$H$2=8,$H$2=16,$H$2=32,$H$2=64,$H$2=128,$H$2=256),0,1) -> -1 | K19: =J19*$J$2 -> -10 | M19: =IF(I19<>"",K19+I19+L19,0) -> 0
A20: =M20 -> 0 | B20: =IF(H20>$H$2,"",(ROW()-5)) | H20: 15 | I20: =IF(H20<$H$2+1,($I$2-($I$2-1)*(LOG(H20)/LOG($H$2))),"") | J20: =INT(LOG($H$2,2))-ROUNDUP(LOG(H20,2),0)+IF(OR($H$2=1,$H$2=2,$H$2=4,$H$2=8,$H$2=16,$H$2=32,$H$2=64,$H$2=128,$H$2=256),0,1) -> -1 | K20: =J20*$J$2 -> -10 | M20: =IF(I20<>"",K20+I20+L20,0) -> 0
A21: =M21 -> 0 | B21: =IF(H21>$H$2,"",(ROW()-5)) | H21: 16 | I21: =IF(H21<$H$2+1,($I$2-($I$2-1)*(LOG(H21)/LOG($H$2))),"") | J21: =INT(LOG($H$2,2))-ROUNDUP(LOG(H21,2),0)+IF(OR($H$2=1,$H$2=2,$H$2=4,$H$2=8,$H$2=16,$H$2=32,$H$2=64,$H$2=128,$H$2=256),0,1) -> -1 | K21: =J21*$J$2 -> -10 | M21: =IF(I21<>"",K21+I21+L21,0) -> 0
A22: =M22 -> 0 | B22: =IF(H22>$H$2,"",(ROW()-5)) | H22: 17 | I22: =IF(H22<$H$2+1,($I$2-($I$2-1)*(LOG(H22)/LOG($H$2))),"") | J22: =INT(LOG($H$2,2))-ROUNDUP(LOG(H22,2),0)+IF(OR($H$2=1,$H$2=2,$H$2=4,$H$2=8,$H$2=16,$H$2=32,$H$2=64,$H$2=128,$H$2=256),0,1) -> -2 | K22: =J22*$J$2 -> -20 | M22: =IF(I22<>"",K22+I22+L22,0) -> 0
A23: =M23 -> 0 | B23: =IF(H23>$H$2,"",(ROW()-5)) | H23: 18 | I23: =IF(H23<$H$2+1,($I$2-($I$2-1)*(LOG(H23)/LOG($H$2))),"") | J23: =INT(LOG($H$2,2))-ROUNDUP(LOG(H23,2),0)+IF(OR($H$2=1,$H$2=2,$H$2=4,$H$2=8,$H$2=16,$H$2=32,$H$2=64,$H$2=128,$H$2=256),0,1) -> -2 | K23: =J23*$J$2 -> -20 | M23: =IF(I23<>"",K23+I23+L23,0) -> 0
A24: =M24 -> 0 | B24: =IF(H24>$H$2,"",(ROW()-5)) | H24: 19 | I24: =IF(H24<$H$2+1,($I$2-($I$2-1)*(LOG(H24)/LOG($H$2))),"") | J24: =INT(LOG($H$2,2))-ROUNDUP(LOG(H24,2),0)+IF(OR($H$2=1,$H$2=2,$H$2=4,$H$2=8,$H$2=16,$H$2=32,$H$2=64,$H$2=128,$H$2=256),0,1) -> -2 | K24: =J24*$J$2 -> -20 | M24: =IF(I24<>"",K24+I24+L24,0) -> 0
A25: =M25 -> 0 | B25: =IF(H25>$H$2,"",(ROW()-5)) | H25: 20 | I25: =IF(H25<$H$2+1,($I$2-($I$2-1)*(LOG(H25)/LOG($H$2))),"") | J25: =INT(LOG($H$2,2))-ROUNDUP(LOG(H25,2),0)+IF(OR($H$2=1,$H$2=2,$H$2=4,$H$2=8,$H$2=16,$H$2=32,$H$2=64,$H$2=128,$H$2=256),0,1) -> -2 | K25: =J25*$J$2 -> -20 | M25: =IF(I25<>"",K25+I25+L25,0) -> 0
... A269: =M269 -> 0 | B269: =IF(H269>$H$2,"",(ROW()-5)) | H269: 264 | I269: =IF(H269<$H$2+1,($I$2-($I$2-1)*(LOG(H269)/LOG($H$2))),"") | J269: =INT(LOG($H$2,2))-ROUNDUP(LOG(H269,2),0)+IF(OR($H$2=1,$H$2=2,$H$2=4,$H$2=8,$H$2=16,$H$2=32,$H$2=64,$H$2=128,$H$2=256),0,1) -> -6 | K269: =J269*$J$2 -> -60 | M269: =IF(I269<>"",K269+I269+L269,0) -> 0
H270: 265 | I270: =IF(H270<$H$2+1,($I$2-($I$2-1)*(LOG(H270)/LOG($H$2))),"") | J270: =INT(LOG($H$2,2))-ROUNDUP(LOG(H270,2),0)+IF(OR($H$2=1,$H$2=2,$H$2=4,$H$2=8,$H$2=16,$H$2=32,$H$2=64,$H$2=128,$H$2=256),0,1) -> -6 | K270: =J270*$J$2 -> -60 | M270: =IF(I270<>"",K270+I270+L270,0) -> 0
H271: 266 | I271: =IF(H271<$H$2+1,($I$2-($I$2-1)*(LOG(H271)/LOG($H$2))),"") | J271: =INT(LOG($H$2,2))-ROUNDUP(LOG(H271,2),0)+IF(OR($H$2=1,$H$2=2,$H$2=4,$H$2=8,$H$2=16,$H$2=32,$H$2=64,$H$2=128,$H$2=256),0,1) -> -6 | K271: =J271*$J$2 -> -60 | M271: =IF(I271<>"",K271+I271+L271,0) -> 0
H272: 267 | I272: =IF(H272<$H$2+1,($I$2-($I$2-1)*(LOG(H272)/LOG($H$2))),"") | J272: =INT(LOG($H$2,2))-ROUNDUP(LOG(H272,2),0)+IF(OR($H$2=1,$H$2=2,$H$2=4,$H$2=8,$H$2=16,$H$2=32,$H$2=64,$H$2=128,$H$2=256),0,1) -> -6 | K272: =J272*$J$2 -> -60 | M272: =IF(I272<>"",K272+I272+L272,0) -> 0
H273: 268 | I273: =IF(H273<$H$2+1,($I$2-($I$2-1)*(LOG(H273)/LOG($H$2))),"") | J273: =INT(LOG($H$2,2))-ROUNDUP(LOG(H273,2),0)+IF(OR($H$2=1,$H$2=2,$H$2=4,$H$2=8,$H$2=16,$H$2=32,$H$2=64,$H$2=128,$H$2=256),0,1) -> -6 | K273: =J273*$J$2 -> -60 | M273: =IF(I273<>"",K273+I273+L273,0) -> 0
H274: 269 | I274: =IF(H274<$H$2+1,($I$2-($I$2-1)*(LOG(H274)/LOG($H$2))),"") | J274: =INT(LOG($H$2,2))-ROUNDUP(LOG(H274,2),0)+IF(OR($H$2=1,$H$2=2,$H$2=4,$H$2=8,$H$2=16,$H$2=32,$H$2=64,$H$2=128,$H$2=256),0,1) -> -6 | K274: =J274*$J$2 -> -60 | M274: =IF(I274<>"",K274+I274+L274,0) -> 0
H275: 270 | I275: =IF(H275<$H$2+1,($I$2-($I$2-1)*(LOG(H275)/LOG($H$2))),"") | J275: =INT(LOG($H$2,2))-ROUNDUP(LOG(H275,2),0)+IF(OR($H$2=1,$H$2=2,$H$2=4,$H$2=8,$H$2=16,$H$2=32,$H$2=64,$H$2=128,$H$2=256),0,1) -> -6 | K275: =J275*$J$2 -> -60 | M275: =IF(I275<>"",K275+I275+L275,0) -> 0
H276: 271 | I276: =IF(H276<$H$2+1,($I$2-($I$2-1)*(LOG(H276)/LOG($H$2))),"") | J276: =INT(LOG($H$2,2))-ROUNDUP(LOG(H276,2),0)+IF(OR($H$2=1,$H$2=2,$H$2=4,$H$2=8,$H$2=16,$H$2=32,$H$2=64,$H$2=128,$H$2=256),0,1) -> -6 | K276: =J276*$J$2 -> -60 | M276: =IF(I276<>"",K276+I276+L276,0) -> 0
H277: 272 | I277: =IF(H277<$H$2+1,($I$2-($I$2-1)*(LOG(H277)/LOG($H$2))),"") | J277: =INT(LOG($H$2,2))-ROUNDUP(LOG(H277,2),0)+IF(OR($H$2=1,$H$2=2,$H$2=4,$H$2=8,$H$2=16,$H$2=32,$H$2=64,$H$2=128,$H$2=256),0,1) -> -6 | K277: =J277*$J$2 -> -60 | M277: =IF(I277<>"",K277+I277+L277,0) -> 0
H278: 273 | I278: =IF(H278<$H$2+1,($I$2-($I$2-1)*(LOG(H278)/LOG($H$2))),"") | J278: =INT(LOG($H$2,2))-ROUNDUP(LOG(H278,2),0)+IF(OR($H$2=1,$H$2=2,$H$2=4,$H$2=8,$H$2=16,$H$2=32,$H$2=64,$H$2=128,$H$2=256),0,1) -> -6 | K278: =J278*$J$2 -> -60 | M278: =IF(I278<>"",K278+I278+L278,0) -> 0
H279: 274 | I279: =IF(H279<$H$2+1,($I$2-($I$2-1)*(LOG(H279)/LOG($H$2))),"") | J279: =INT(LOG($H$2,2))-ROUNDUP(LOG(H279,2),0)+IF(OR($H$2=1,$H$2=2,$H$2=4,$H$2=8,$H$2=16,$H$2=32,$H$2=64,$H$2=128,$H$2=256),0,1) -> -6 | K279: =J279*$J$2 -> -60 | M279: =IF(I279<>"",K279+I279+L279,0) -> 0
H280: 275 | I280: =IF(H280<$H$2+1,($I$2-($I$2-1)*(LOG(H280)/LOG($H$2))),"") | J280: =INT(LOG($H$2,2))-ROUNDUP(LOG(H280,2),0)+IF(OR($H$2=1,$H$2=2,$H$2=4,$H$2=8,$H$2=16,$H$2=32,$H$2=64,$H$2=128,$H$2=256),0,1) -> -6 | K280: =J280*$J$2 -> -60 | M280: =IF(I280<>"",K280+I280+L280,0) -> 0
H281: 276 | I281: =IF(H281<$H$2+1,($I$2-($I$2-1)*(LOG(H281)/LOG($H$2))),"") | J281: =INT(LOG($H$2,2))-ROUNDUP(LOG(H281,2),0)+IF(OR($H$2=1,$H$2=2,$H$2=4,$H$2=8,$H$2=16,$H$2=32,$H$2=64,$H$2=128,$H$2=256),0,1) -> -6 | K281: =J281*$J$2 -> -60 | M281: =IF(I281<>"",K281+I281+L281,0) -> 0
... H305: 300 | I305: =IF(H305<$H$2+1,($I$2-($I$2-1)*(LOG(H305)/LOG($H$2))),"") | J305: =INT(LOG($H$2,2))-ROUNDUP(LOG(H305,2),0)+IF(OR($H$2=1,$H$2=2,$H$2=4,$H$2=8,$H$2=16,$H$2=32,$H$2=64,$H$2=128,$H$2=256),0,1) -> -6 | K305: =J305*$J$2 -> -60 | M305: =IF(I305<>"",K305+I305+L305,0) -> 0
J306: =INT(LOG($H$2,2))-ROUNDUP(LOG(H306,2),0)+IF(OR($H$2=1,$H$2=2,$H$2=4,$H$2=8,$H$2=16,$H$2=32,$H$2=64,$H$2=128,$H$2=256),0,1) -> #NUM!
...

Sheet PP3
B1: miejsce: | C1: Warsaw Epee Open | H1: Liczba uczestników: | I1: GP Punkty | J1: Bonus za rundę | K1: Mnożnik za podium
A2: LINK | B2: turniej: | C2: Szpada Mężczyzn kat. 2 | H2: 19 | I2: 50 | J2: 10 | K2: =3*H2^(1/3) -> 8.0052049
A3: b | B3: data: | C3: Saturday, December 13, 2025 5:00 PM
C4: https://www.fencingtimelive.com/events/results/download/2034F718AC554C8D89A639B0EC0984DD
A5: Punkty | B5: Miejsce Place | C5: Nazwisko Imię Name | D5: Klub Club(s) | E5: Okręg Division | F5: Państwo Country | H5: Miejsce | I5: Punkty za miejsce | J5: liczba wygranych walk pucharowych | K5: bonus z rundy pucharowej | L5: punkty za podium | M5: Suma
A6: =M6 -> 124.01561 | B6: =IF(H6>$H$2,"",(ROW()-5)) -> 1 | C6: ATANASSOW Aleksander | D6: KS AGH Kraków | F6: POL | H6: 1 | I6: =IF(H2=1,50,IF(H6<$H$2+1,($I$2-($I$2-1)*(LOG(H6)/LOG($H$2))),"")) -> 50 | J6: =INT(LOG($H$2,2))-ROUNDUP(LOG(H6,2),0)+IF(OR($H$2=1,$H$2=2,$H$2=4,$H$2=8,$H$2=16,$H$2=32,$H$2=64,$H$2=128,$H$2=256),0,1) -> 5 | K6: =J6*$J$2 -> 50 | L6: =3*K2 -> 24.015615 | M6: =IF(I6<>"",K6+I6+L6,0) -> 124.01561
A7: =M7 -> 94.475373 | B7: =IF(H7>$H$2,"",(ROW()-5)) -> 2 | C7: JENDRYŚ Marek | D7: PIAST GLIWICE | F7: POL | H7: 2 | I7: =IF(H7<$H$2+1,($I$2-($I$2-1)*(LOG(H7)/LOG($H$2))),"") -> 38.464963 | J7: =INT(LOG($H$2,2))-ROUNDUP(LOG(H7,2),0)+IF(OR($H$2=1,$H$2=2,$H$2=4,$H$2=8,$H$2=16,$H$2=32,$H$2=64,$H$2=128,$H$2=256),0,1) -> 4 | K7: =J7*$J$2 -> 40 | L7: =2*K2 -> 16.01041 | M7: =IF(I7<>"",K7+I7+L7,0) -> 94.475373
A8: =M8 -> 69.722604 | B8: =IF(H8>$H$2,"",(ROW()-5)) -> 3 | C8: KORONA Przemysław | D8: AZS AWF WARSZAWA | F8: POL | H8: 3 | I8: =IF(H8<$H$2+1,($I$2-($I$2-1)*(LOG(H8)/LOG($H$2))),"") -> 31.717399 | J8: =INT(LOG($H$2,2))-ROUNDUP(LOG(H8,2),0)+IF(OR($H$2=1,$H$2=2,$H$2=4,$H$2=8,$H$2=16,$H$2=32,$H$2=64,$H$2=128,$H$2=256),0,1) -> 3 | K8: =J8*$J$2 -> 30 | L8: =K2 -> 8.0052049 | M8: =IF(I8<>"",K8+I8+L8,0) -> 69.722604
A9: =M9 -> 56.929926 | B9: =IF(H9>$H$2,"",(ROW()-5)) -> 4 | C9: LEAHEY John | D9: Malvern Hills | F9: GBR | H9: 4 | I9: =IF(H9<$H$2+1,($I$2-($I$2-1)*(LOG(H9)/LOG($H$2))),"") -> 26.929926 | J9: =INT(LOG($H$2,2))-ROUNDUP(LOG(H9,2),0)+IF(OR($H$2=1,$H$2=2,$H$2=4,$H$2=8,$H$2=16,$H$2=32,$H$2=64,$H$2=128,$H$2=256),0,1) -> 3 | K9: =J9*$J$2 -> 30 | M9: =IF(I9<>"",K9+I9+L9,0) -> 56.929926
A10: =M10 -> 43.216474 | B10: =IF(H10>$H$2,"",(ROW()-5)) -> 5 | C10: ZIELIŃSKI Dariusz | D10: ST. POLSKICH WETERANÓW SZERMIERKI | F10: POL | H10: 5 | I10: =IF(H10<$H$2+1,($I$2-($I$2-1)*(LOG(H10)/LOG($H$2))),"") -> 23.216474 | J10: =INT(LOG($H$2,2))-ROUNDUP(LOG(H10,2),0)+IF(OR($H$2=1,$H$2=2,$H$2=4,$H$2=8,$H$2=16,$H$2=32,$H$2=64,$H$2=128,$H$2=256),0,1) -> 2 | K10: =J10*$J$2 -> 20 | M10: =IF(I10<>"",K10+I10+L10,0) -> 43.216474
A11: =M11 -> 40.182363 | B11: =IF(H11>$H$2,"",(ROW()-5)) -> 6 | C11: JASZCZAK Piotr | D11: K.S. SZERMIERZ ŁOMIANKI | F11: POL | H11: 6 | I11: =IF(H11<$H$2+1,($I$2-($I$2-1)*(LOG(H11)/LOG($H$2))),"") -> 20.182363 | J11: =INT(LOG($H$2,2))-ROUNDUP(LOG(H11,2),0)+IF(OR($H$2=1,$H$2=2,$H$2=4,$H$2=8,$H$2=16,$H$2=32,$H$2=64,$H$2=128,$H$2=256),0,1) -> 2 | K11: =J11*$J$2 -> 20 | M11: =IF(I11<>"",K11+I11+L11,0) -> 40.182363
A12: =M12 -> 37.617058 | B12: =IF(H12>$H$2,"",(ROW()-5)) -> 7 | C12: OLSZEWSKI Mikołaj | D12: KSz WARSZAWIANKA | F12: POL | H12: 7 | I12: =IF(H12<$H$2+1,($I$2-($I$2-1)*(LOG(H12)/LOG($H$2))),"") -> 17.617058 | J12: =INT(LOG($H$2,2))-ROUNDUP(LOG(H12,2),0)+IF(OR($H$2=1,$H$2=2,$H$2=4,$H$2=8,$H$2=16,$H$2=32,$H$2=64,$H$2=128,$H$2=256),0,1) -> 2 | K12: =J12*$J$2 -> 20 | M12: =IF(I12<>"",K12+I12+L12,0) -> 37.617058
A13: =M13 -> 35.39489 | B13: =IF(H13>$H$2,"",(ROW()-5)) -> 8 | C13: PILUTKIEWICZ Igor | D13: KSz WARSZAWIANKA | F13: POL | H13: 8 | I13: =IF(H13<$H$2+1,($I$2-($I$2-1)*(LOG(H13)/LOG($H$2))),"") -> 15.39489 | J13: =INT(LOG($H$2,2))-ROUNDUP(LOG(H13,2),0)+IF(OR($H$2=1,$H$2=2,$H$2=4,$H$2=8,$H$2=16,$H$2=32,$H$2=64,$H$2=128,$H$2=256),0,1) -> 2 | K13: =J13*$J$2 -> 20 | M13: =IF(I13<>"",K13+I13+L13,0) -> 35.39489
A14: =M14 -> 23.434799 | B14: =IF(H14>$H$2,"",(ROW()-5)) -> 9 | C14: DROBIŃSKI Leszek | D14: WARTA-MUSZKIETEROWIE POZNAŃ | F14: POL | H14: 9 | I14: =IF(H14<$H$2+1,($I$2-($I$2-1)*(LOG(H14)/LOG($H$2))),"") -> 13.434799 | J14: =INT(LOG($H$2,2))-ROUNDUP(LOG(H14,2),0)+IF(OR($H$2=1,$H$2=2,$H$2=4,$H$2=8,$H$2=16,$H$2=32,$H$2=64,$H$2=128,$H$2=256),0,1) -> 1 | K14: =J14*$J$2 -> 10 | M14: =IF(I14<>"",K14+I14+L14,0) -> 23.434799
A15: =M15 -> 21.681437 | B15: =IF(H15>$H$2,"",(ROW()-5)) -> 10 | C15: ŻUKOWSKI Wojciech | D15: Szczecińska Szkoła Szermiecza | F15: POL | H15: 10 | I15: =IF(H15<$H$2+1,($I$2-($I$2-1)*(LOG(H15)/LOG($H$2))),"") -> 11.681437 | J15: =INT(LOG($H$2,2))-ROUNDUP(LOG(H15,2),0)+IF(OR($H$2=1,$H$2=2,$H$2=4,$H$2=8,$H$2=16,$H$2=32,$H$2=64,$H$2=128,$H$2=256),0,1) -> 1 | K15: =J15*$J$2 -> 10 | M15: =IF(I15<>"",K15+I15+L15,0) -> 21.681437
A16: =M16 -> 20.095329 | B16: =IF(H16>$H$2,"",(ROW()-5)) -> 11 | C16: GERTSMAN Alex | D16: Maccabi Harish Fencing Club | F16: ISR | H16: 11 | I16: =IF(H16<$H$2+1,($I$2-($I$2-1)*(LOG(H16)/LOG($H$2))),"") -> 10.095329 | J16: =INT(LOG($H$2,2))-ROUNDUP(LOG(H16,2),0)+IF(OR($H$2=1,$H$2=2,$H$2=4,$H$2=8,$H$2=16,$H$2=32,$H$2=64,$H$2=128,$H$2=256),0,1) -> 1 | K16: =J16*$J$2 -> 10 | M16: =IF(I16<>"",K16+I16+L16,0) -> 20.095329
A17: =M17 -> 18.647326 | B17: =IF(H17>$H$2,"",(ROW()-5)) -> 12 | C17: SKOCZEK Artur | D17: NAUKA SZERMIERKI | F17: POL | H17: 12 | I17: =IF(H17<$H$2+1,($I$2-($I$2-1)*(LOG(H17)/LOG($H$2))),"") -> 8.6473258 | J17: =INT(LOG($H$2,2))-ROUNDUP(LOG(H17,2),0)+IF(OR($H$2=1,$H$2=2,$H$2=4,$H$2=8,$H$2=16,$H$2=32,$H$2=64,$H$2=128,$H$2=256),0,1) -> 1 | K17: =J17*$J$2 -> 10 | M17: =IF(I17<>"",K17+I17+L17,0) -> 18.647326
A18: =M18 -> 17.315292 | B18: =IF(H18>$H$2,"",(ROW()-5)) -> 13 | C18: ODOLAK Jarosław | D18: AKADEMIA SZERMIERKI W-WA | F18: POL | H18: 13 | I18: =IF(H18<$H$2+1,($I$2-($I$2-1)*(LOG(H18)/LOG($H$2))),"") -> 7.3152918 | J18: =INT(LOG($H$2,2))-ROUNDUP(LOG(H18,2),0)+IF(OR($H$2=1,$H$2=2,$H$2=4,$H$2=8,$H$2=16,$H$2=32,$H$2=64,$H$2=128,$H$2=256),0,1) -> 1 | K18: =J18*$J$2 -> 10 | M18: =IF(I18<>"",K18+I18+L18,0) -> 17.315292
A19: =M19 -> 16.082021 | B19: =IF(H19>$H$2,"",(ROW()-5)) -> 14 | C19: TOMCZAK Ireneusz | D19: Śremska Akademia Szermierki | F19: POL | H19: 14 | I19: =IF(H19<$H$2+1,($I$2-($I$2-1)*(LOG(H19)/LOG($H$2))),"") -> 6.082021 | J19: =INT(LOG($H$2,2))-ROUNDUP(LOG(H19,2),0)+IF(OR($H$2=1,$H$2=2,$H$2=4,$H$2=8,$H$2=16,$H$2=32,$H$2=64,$H$2=128,$H$2=256),0,1) -> 1 | K19: =J19*$J$2 -> 10 | M19: =IF(I19<>"",K19+I19+L19,0) -> 16.082021
A20: =M20 -> 14.933873 | B20: =IF(H20>$H$2,"",(ROW()-5)) -> 15 | C20: SERWATKA Marek | D20: MKS ZORZA ŁOMŻA | F20: POL | H20: 15 | I20: =IF(H20<$H$2+1,($I$2-($I$2-1)*(LOG(H20)/LOG($H$2))),"") -> 4.9338734 | J20: =INT(LOG($H$2,2))-ROUNDUP(LOG(H20,2),0)+IF(OR($H$2=1,$H$2=2,$H$2=4,$H$2=8,$H$2=16,$H$2=32,$H$2=64,$H$2=128,$H$2=256),0,1) -> 1 | K20: =J20*$J$2 -> 10 | M20: =IF(I20<>"",K20+I20+L20,0) -> 14.933873
... A24: =M24 -> 1 | B24: =IF(H24>$H$2,"",(ROW()-5)) -> 19 | C24: GOLD Oleg | D24: Maccabi Harish Fencing Club | F24: ISR | H24: 19 | I24: =IF(H24<$H$2+1,($I$2-($I$2-1)*(LOG(H24)/LOG($H$2))),"") -> 1 | J24: =INT(LOG($H$2,2))-ROUNDUP(LOG(H24,2),0)+IF(OR($H$2=1,$H$2=2,$H$2=4,$H$2=8,$H$2=16,$H$2=32,$H$2=64,$H$2=128,$H$2=256),0,1) -> 0 | K24: =J24*$J$2 -> 0 | M24: =IF(I24<>"",K24+I24+L24,0) -> 1
A25: =M25 -> 0 | B25: =IF(H25>$H$2,"",(ROW()-5)) | H25: 20 | I25: =IF(H25<$H$2+1,($I$2-($I$2-1)*(LOG(H25)/LOG($H$2))),"") | J25: =INT(LOG($H$2,2))-ROUNDUP(LOG(H25,2),0)+IF(OR($H$2=1,$H$2=2,$H$2=4,$H$2=8,$H$2=16,$H$2=32,$H$2=64,$H$2=128,$H$2=256),0,1) -> 0 | K25: =J25*$J$2 -> 0 | M25: =IF(I25<>"",K25+I25+L25,0) -> 0
A26: =M26 -> 0 | B26: =IF(H26>$H$2,"",(ROW()-5)) | H26: 21 | I26: =IF(H26<$H$2+1,($I$2-($I$2-1)*(LOG(H26)/LOG($H$2))),"") | J26: =INT(LOG($H$2,2))-ROUNDUP(LOG(H26,2),0)+IF(OR($H$2=1,$H$2=2,$H$2=4,$H$2=8,$H$2=16,$H$2=32,$H$2=64,$H$2=128,$H$2=256),0,1) -> 0 | K26: =J26*$J$2 -> 0 | M26: =IF(I26<>"",K26+I26+L26,0) -> 0
A27: =M27 -> 0 | B27: =IF(H27>$H$2,"",(ROW()-5)) | H27: 22 | I27: =IF(H27<$H$2+1,($I$2-($I$2-1)*(LOG(H27)/LOG($H$2))),"") | J27: =INT(LOG($H$2,2))-ROUNDUP(LOG(H27,2),0)+IF(OR($H$2=1,$H$2=2,$H$2=4,$H$2=8,$H$2=16,$H$2=32,$H$2=64,$H$2=128,$H$2=256),0,1) -> 0 | K27: =J27*$J$2 -> 0 | M27: =IF(I27<>"",K27+I27+L27,0) -> 0
A28: =M28 -> 0 | B28: =IF(H28>$H$2,"",(ROW()-5)) | H28: 23 | I28: =IF(H28<$H$2+1,($I$2-($I$2-1)*(LOG(H28)/LOG($H$2))),"") | J28: =INT(LOG($H$2,2))-ROUNDUP(LOG(H28,2),0)+IF(OR($H$2=1,$H$2=2,$H$2=4,$H$2=8,$H$2=16,$H$2=32,$H$2=64,$H$2=128,$H$2=256),0,1) -> 0 | K28: =J28*$J$2 -> 0 | M28: =IF(I28<>"",K28+I28+L28,0) -> 0
A29: =M29 -> 0 | B29: =IF(H29>$H$2,"",(ROW()-5)) | H29: 24 | I29: =IF(H29<$H$2+1,($I$2-($I$2-1)*(LOG(H29)/LOG($H$2))),"") | J29: =INT(LOG($H$2,2))-ROUNDUP(LOG(H29,2),0)+IF(OR($H$2=1,$H$2=2,$H$2=4,$H$2=8,$H$2=16,$H$2=32,$H$2=64,$H$2=128,$H$2=256),0,1) -> 0 | K29: =J29*$J$2 -> 0 | M29: =IF(I29<>"",K29+I29+L29,0) -> 0
A30: =M30 -> 0 | B30: =IF(H30>$H$2,"",(ROW()-5)) | H30: 25 | I30: =IF(H30<$H$2+1,($I$2-($I$2-1)*(LOG(H30)/LOG($H$2))),"") | J30: =INT(LOG($H$2,2))-ROUNDUP(LOG(H30,2),0)+IF(OR($H$2=1,$H$2=2,$H$2=4,$H$2=8,$H$2=16,$H$2=32,$H$2=64,$H$2=128,$H$2=256),0,1) -> 0 | K30: =J30*$J$2 -> 0 | M30: =IF(I30<>"",K30+I30+L30,0) -> 0
A31: =M31 -> 0 | B31: =IF(H31>$H$2,"",(ROW()-5)) | H31: 26 | I31: =IF(H31<$H$2+1,($I$2-($I$2-1)*(LOG(H31)/LOG($H$2))),"") | J31: =INT(LOG($H$2,2))-ROUNDUP(LOG(H31,2),0)+IF(OR($H$2=1,$H$2=2,$H$2=4,$H$2=8,$H$2=16,$H$2=32,$H$2=64,$H$2=128,$H$2=256),0,1) -> 0 | K31: =J31*$J$2 -> 0 | M31: =IF(I31<>"",K31+I31+L31,0) -> 0
A32: =M32 -> 0 | B32: =IF(H32>$H$2,"",(ROW()-5)) | H32: 27 | I32: =IF(H32<$H$2+1,($I$2-($I$2-1)*(LOG(H32)/LOG($H$2))),"") | J32: =INT(LOG($H$2,2))-ROUNDUP(LOG(H32,2),0)+IF(OR($H$2=1,$H$2=2,$H$2=4,$H$2=8,$H$2=16,$H$2=32,$H$2=64,$H$2=128,$H$2=256),0,1) -> 0 | K32: =J32*$J$2 -> 0 | M32: =IF(I32<>"",K32+I32+L32,0) -> 0
A33: =M33 -> 0 | B33: =IF(H33>$H$2,"",(ROW()-5)) | H33: 28 | I33: =IF(H33<$H$2+1,($I$2-($I$2-1)*(LOG(H33)/LOG($H$2))),"") | J33: =INT(LOG($H$2,2))-ROUNDUP(LOG(H33,2),0)+IF(OR($H$2=1,$H$2=2,$H$2=4,$H$2=8,$H$2=16,$H$2=32,$H$2=64,$H$2=128,$H$2=256),0,1) -> 0 | K33: =J33*$J$2 -> 0 | M33: =IF(I33<>"",K33+I33+L33,0) -> 0
A34: =M34 -> 0 | B34: =IF(H34>$H$2,"",(ROW()-5)) | H34: 29 | I34: =IF(H34<$H$2+1,($I$2-($I$2-1)*(LOG(H34)/LOG($H$2))),"") | J34: =INT(LOG($H$2,2))-ROUNDUP(LOG(H34,2),0)+IF(OR($H$2=1,$H$2=2,$H$2=4,$H$2=8,$H$2=16,$H$2=32,$H$2=64,$H$2=128,$H$2=256),0,1) -> 0 | K34: =J34*$J$2 -> 0 | M34: =IF(I34<>"",K34+I34+L34,0) -> 0
A35: =M35 -> 0 | B35: =IF(H35>$H$2,"",(ROW()-5)) | H35: 30 | I35: =IF(H35<$H$2+1,($I$2-($I$2-1)*(LOG(H35)/LOG($H$2))),"") | J35: =INT(LOG($H$2,2))-ROUNDUP(LOG(H35,2),0)+IF(OR($H$2=1,$H$2=2,$H$2=4,$H$2=8,$H$2=16,$H$2=32,$H$2=64,$H$2=128,$H$2=256),0,1) -> 0 | K35: =J35*$J$2 -> 0 | M35: =IF(I35<>"",K35+I35+L35,0) -> 0
A36: =M36 -> 0 | B36: =IF(H36>$H$2,"",(ROW()-5)) | H36: 31 | I36: =IF(H36<$H$2+1,($I$2-($I$2-1)*(LOG(H36)/LOG($H$2))),"") | J36: =INT(LOG($H$2,2))-ROUNDUP(LOG(H36,2),0)+IF(OR($H$2=1,$H$2=2,$H$2=4,$H$2=8,$H$2=16,$H$2=32,$H$2=64,$H$2=128,$H$2=256),0,1) -> 0 | K36: =J36*$J$2 -> 0 | M36: =IF(I36<>"",K36+I36+L36,0) -> 0
... A269: =M269 -> 0 | B269: =IF(H269>$H$2,"",(ROW()-5)) | H269: 264 | I269: =IF(H269<$H$2+1,($I$2-($I$2-1)*(LOG(H269)/LOG($H$2))),"") | J269: =INT(LOG($H$2,2))-ROUNDUP(LOG(H269,2),0)+IF(OR($H$2=1,$H$2=2,$H$2=4,$H$2=8,$H$2=16,$H$2=32,$H$2=64,$H$2=128,$H$2=256),0,1) -> -4 | K269: =J269*$J$2 -> -40 | M269: =IF(I269<>"",K269+I269+L269,0) -> 0
H270: 265 | I270: =IF(H270<$H$2+1,($I$2-($I$2-1)*(LOG(H270)/LOG($H$2))),"") | J270: =INT(LOG($H$2,2))-ROUNDUP(LOG(H270,2),0)+IF(OR($H$2=1,$H$2=2,$H$2=4,$H$2=8,$H$2=16,$H$2=32,$H$2=64,$H$2=128,$H$2=256),0,1) -> -4 | K270: =J270*$J$2 -> -40 | M270: =IF(I270<>"",K270+I270+L270,0) -> 0
H271: 266 | I271: =IF(H271<$H$2+1,($I$2-($I$2-1)*(LOG(H271)/LOG($H$2))),"") | J271: =INT(LOG($H$2,2))-ROUNDUP(LOG(H271,2),0)+IF(OR($H$2=1,$H$2=2,$H$2=4,$H$2=8,$H$2=16,$H$2=32,$H$2=64,$H$2=128,$H$2=256),0,1) -> -4 | K271: =J271*$J$2 -> -40 | M271: =IF(I271<>"",K271+I271+L271,0) -> 0
H272: 267 | I272: =IF(H272<$H$2+1,($I$2-($I$2-1)*(LOG(H272)/LOG($H$2))),"") | J272: =INT(LOG($H$2,2))-ROUNDUP(LOG(H272,2),0)+IF(OR($H$2=1,$H$2=2,$H$2=4,$H$2=8,$H$2=16,$H$2=32,$H$2=64,$H$2=128,$H$2=256),0,1) -> -4 | K272: =J272*$J$2 -> -40 | M272: =IF(I272<>"",K272+I272+L272,0) -> 0
H273: 268 | I273: =IF(H273<$H$2+1,($I$2-($I$2-1)*(LOG(H273)/LOG($H$2))),"") | J273: =INT(LOG($H$2,2))-ROUNDUP(LOG(H273,2),0)+IF(OR($H$2=1,$H$2=2,$H$2=4,$H$2=8,$H$2=16,$H$2=32,$H$2=64,$H$2=128,$H$2=256),0,1) -> -4 | K273: =J273*$J$2 -> -40 | M273: =IF(I273<>"",K273+I273+L273,0) -> 0
H274: 269 | I274: =IF(H274<$H$2+1,($I$2-($I$2-1)*(LOG(H274)/LOG($H$2))),"") | J274: =INT(LOG($H$2,2))-ROUNDUP(LOG(H274,2),0)+IF(OR($H$2=1,$H$2=2,$H$2=4,$H$2=8,$H$2=16,$H$2=32,$H$2=64,$H$2=128,$H$2=256),0,1) -> -4 | K274: =J274*$J$2 -> -40 | M274: =IF(I274<>"",K274+I274+L274,0) -> 0
H275: 270 | I275: =IF(H275<$H$2+1,($I$2-($I$2-1)*(LOG(H275)/LOG($H$2))),"") | J275: =INT(LOG($H$2,2))-ROUNDUP(LOG(H275,2),0)+IF(OR($H$2=1,$H$2=2,$H$2=4,$H$2=8,$H$2=16,$H$2=32,$H$2=64,$H$2=128,$H$2=256),0,1) -> -4 | K275: =J275*$J$2 -> -40 | M275: =IF(I275<>"",K275+I275+L275,0) -> 0
...

Sheet PP4
H1: Liczba uczestników: | I1: GP Punkty | J1: Bonus za rundę | K1: Mnożnik za podium
B2: miejsce: | C2: WARSZAWA | H2: 8 | I2: 50 | J2: 10 | K2: =3*H2^(1/3) -> 6
B3: data: | C3: 22.02.2025
A5: Punkty | B5: Miejsce Place | C5: Nazwisko Imię Name | D5: Klub Club(s) | E5: Okręg Division | F5: Państwo Country | H5: Miejsce | I5: Punkty za miejsce | J5: awans do kolejnej rundy pucharowej | K5: bonus za rundy pucharowe | L5: punkty za podium | M5: Suma
A6: =M6 -> 98 | B6: =IF(H6>$H$2,"",(ROW()-5)) -> 1 | C6: ATANASSOW Aleksander | D6: KS AGH Kraków | E6: POL | H6: 1 | I6: =IF(H2=1,50,IF(H6<$H$2+1,($I$2-($I$2-1)*(LOG(H6)/LOG($H$2))),"")) -> 50 | J6: =INT(LOG($H$2,2))-ROUNDUP(LOG(H6,2),0)+IF(OR($H$2=1,$H$2=2,$H$2=4,$H$2=8,$H$2=16,$H$2=32,$H$2=64,$H$2=128,$H$2=256),0,1) -> 3 | K6: =J6*$J$2 -> 30 | L6: =3*K2 -> 18 | M6: =IF(I6<>"",K6+I6+L6,0) -> 98
A7: =M7 -> 65.666667 | B7: =IF(H7>$H$2,"",(ROW()-5)) -> 2 | C7: ZIELIŃSKI Dariusz | D7: PIAST GLIWICE | E7: POL | H7: 2 | I7: =IF(H7<$H$2+1,($I$2-($I$2-1)*(LOG(H7)/LOG($H$2))),"") -> 33.666667 | J7: =INT(LOG($H$2,2))-ROUNDUP(LOG(H7,2),0)+IF(OR($H$2=1,$H$2=2,$H$2=4,$H$2=8,$H$2=16,$H$2=32,$H$2=64,$H$2=128,$H$2=256),0,1) -> 2 | K7: =J7*$J$2 -> 20 | L7: =2*K2 -> 12 | M7: =IF(I7<>"",K7+I7+L7,0) -> 65.666667
A8: =M8 -> 40.112279 | B8: =IF(H8>$H$2,"",(ROW()-5)) -> 3 | C8: PILUTKIEWICZ Igor | D8: KSz WARSZAWIANKA | E8: POL | H8: 3 | I8: =IF(H8<$H$2+1,($I$2-($I$2-1)*(LOG(H8)/LOG($H$2))),"") -> 24.112279 | J8: =INT(LOG($H$2,2))-ROUNDUP(LOG(H8,2),0)+IF(OR($H$2=1,$H$2=2,$H$2=4,$H$2=8,$H$2=16,$H$2=32,$H$2=64,$H$2=128,$H$2=256),0,1) -> 1 | K8: =J8*$J$2 -> 10 | L8: =K2 -> 6 | M8: =IF(I8<>"",K8+I8+L8,0) -> 40.112279
A9: =M9 -> 27.333333 | B9: =IF(H9>$H$2,"",(ROW()-5)) -> 4 | C9: JASZCZAK Piotr | D9: K.S. SZERMIERZ ŁOMIANKI | E9: POL | H9: 4 | I9: =IF(H9<$H$2+1,($I$2-($I$2-1)*(LOG(H9)/LOG($H$2))),"") -> 17.333333 | J9: =INT(LOG($H$2,2))-ROUNDUP(LOG(H9,2),0)+IF(OR($H$2=1,$H$2=2,$H$2=4,$H$2=8,$H$2=16,$H$2=32,$H$2=64,$H$2=128,$H$2=256),0,1) -> 1 | K9: =J9*$J$2 -> 10 | M9: =IF(I9<>"",K9+I9+L9,0) -> 27.333333 | AH9: x | AI9: 23
A10: =M10 -> 12.075174 | B10: =IF(H10>$H$2,"",(ROW()-5)) -> 5 | C10: PARDUS Borys | D10: K.S. SZERMIERZ ŁOMIANKI | E10: POL | H10: 5 | I10: =IF(H10<$H$2+1,($I$2-($I$2-1)*(LOG(H10)/LOG($H$2))),"") -> 12.075174 | J10: =INT(LOG($H$2,2))-ROUNDUP(LOG(H10,2),0)+IF(OR($H$2=1,$H$2=2,$H$2=4,$H$2=8,$H$2=16,$H$2=32,$H$2=64,$H$2=128,$H$2=256),0,1) -> 0 | K10: =J10*$J$2 -> 0 | M10: =IF(I10<>"",K10+I10+L10,0) -> 12.075174 | AH10: N | AI10: 45
A11: =M11 -> 7.7789458 | B11: =IF(H11>$H$2,"",(ROW()-5)) -> 6 | C11: ODOLAK Jarosław | D11: AKADEMIA SZERMIERKI W-WA | E11: POL | H11: 6 | I11: =IF(H11<$H$2+1,($I$2-($I$2-1)*(LOG(H11)/LOG($H$2))),"") -> 7.7789458 | J11: =INT(LOG($H$2,2))-ROUNDUP(LOG(H11,2),0)+IF(OR($H$2=1,$H$2=2,$H$2=4,$H$2=8,$H$2=16,$H$2=32,$H$2=64,$H$2=128,$H$2=256),0,1) -> 0 | K11: =J11*$J$2 -> 0 | M11: =IF(I11<>"",K11+I11+L11,0) -> 7.7789458 | AH11: MP | AI11: 50
A12: =M12 -> 4.1465363 | B12: =IF(H12>$H$2,"",(ROW()-5)) -> 7 | C12: SKOCZEK Artur | D12: NAUKA SZERMIERKI | E12: POL | H12: 7 | I12: =IF(H12<$H$2+1,($I$2-($I$2-1)*(LOG(H12)/LOG($H$2))),"") -> 4.1465363 | J12: =INT(LOG($H$2,2))-ROUNDUP(LOG(H12,2),0)+IF(OR($H$2=1,$H$2=2,$H$2=4,$H$2=8,$H$2=16,$H$2=32,$H$2=64,$H$2=128,$H$2=256),0,1) -> 0 | K12: =J12*$J$2 -> 0 | M12: =IF(I12<>"",K12+I12+L12,0) -> 4.1465363 | AH12: MP-1 | AI12: =AI11-1 -> 49
A13: =M13 -> 1 | B13: =IF(H13>$H$2,"",(ROW()-5)) -> 8 | C13: WIERZBICKI JACEK | D13: AZS KU POLITECHNIKI OPOLSKIEJ | E13: POL | H13: 8 | I13: =IF(H13<$H$2+1,($I$2-($I$2-1)*(LOG(H13)/LOG($H$2))),"") -> 1 | J13: =INT(LOG($H$2,2))-ROUNDUP(LOG(H13,2),0)+IF(OR($H$2=1,$H$2=2,$H$2=4,$H$2=8,$H$2=16,$H$2=32,$H$2=64,$H$2=128,$H$2=256),0,1) -> 0 | K13: =J13*$J$2 -> 0 | M13: =IF(I13<>"",K13+I13+L13,0) -> 1 | AH13: log(x) | AI13: =LOG(AI9) -> 1.3617278
A14: =M14 -> 0 | B14: =IF(H14>$H$2,"",(ROW()-5)) | H14: 9 | I14: =IF(H14<$H$2+1,($I$2-($I$2-1)*(LOG(H14)/LOG($H$2))),"") | J14: =INT(LOG($H$2,2))-ROUNDUP(LOG(H14,2),0)+IF(OR($H$2=1,$H$2=2,$H$2=4,$H$2=8,$H$2=16,$H$2=32,$H$2=64,$H$2=128,$H$2=256),0,1) -> -1 | K14: =J14*$J$2 -> -10 | M14: =IF(I14<>"",K14+I14+L14,0) -> 0 | AH14: Log(N) | AI14: =LOG(AI10) -> 1.6532125
A15: =M15 -> 0 | B15: =IF(H15>$H$2,"",(ROW()-5)) | H15: 10 | I15: =IF(H15<$H$2+1,($I$2-($I$2-1)*(LOG(H15)/LOG($H$2))),"") | J15: =INT(LOG($H$2,2))-ROUNDUP(LOG(H15,2),0)+IF(OR($H$2=1,$H$2=2,$H$2=4,$H$2=8,$H$2=16,$H$2=32,$H$2=64,$H$2=128,$H$2=256),0,1) -> -1 | K15: =J15*$J$2 -> -10 | M15: =IF(I15<>"",K15+I15+L15,0) -> 0
A16: 12.075174 | B16: 5k1 | C16: KORONA Przemysław | H16: 11 | I16: =IF(H16<$H$2+1,($I$2-($I$2-1)*(LOG(H16)/LOG($H$2))),"") | J16: =INT(LOG($H$2,2))-ROUNDUP(LOG(H16,2),0)+IF(OR($H$2=1,$H$2=2,$H$2=4,$H$2=8,$H$2=16,$H$2=32,$H$2=64,$H$2=128,$H$2=256),0,1) -> -1 | K16: =J16*$J$2 -> -10 | M16: =IF(I16<>"",K16+I16+L16,0) -> 0 | AH16: MP - (MP-1)*LOG(x)/LOG(N) | AI16: =AI11-AI12*AI13/AI14 -> 9.6393909 | AJ16: points
A17: 7.7789458 | B17: 6k1 | C17: KOBIERSKI Krzysztof | H17: 12 | I17: =IF(H17<$H$2+1,($I$2-($I$2-1)*(LOG(H17)/LOG($H$2))),"") | J17: =INT(LOG($H$2,2))-ROUNDUP(LOG(H17,2),0)+IF(OR($H$2=1,$H$2=2,$H$2=4,$H$2=8,$H$2=16,$H$2=32,$H$2=64,$H$2=128,$H$2=256),0,1) -> -1 | K17: =J17*$J$2 -> -10 | M17: =IF(I17<>"",K17+I17+L17,0) -> 0
A18: =M18 -> 0 | B18: =IF(H18>$H$2,"",(ROW()-5)) | H18: 13 | I18: =IF(H18<$H$2+1,($I$2-($I$2-1)*(LOG(H18)/LOG($H$2))),"") | J18: =INT(LOG($H$2,2))-ROUNDUP(LOG(H18,2),0)+IF(OR($H$2=1,$H$2=2,$H$2=4,$H$2=8,$H$2=16,$H$2=32,$H$2=64,$H$2=128,$H$2=256),0,1) -> -1 | K18: =J18*$J$2 -> -10 | M18: =IF(I18<>"",K18+I18+L18,0) -> 0
A19: =M19 -> 0 | B19: =IF(H19>$H$2,"",(ROW()-5)) | H19: 14 | I19: =IF(H19<$H$2+1,($I$2-($I$2-1)*(LOG(H19)/LOG($H$2))),"") | J19: =INT(LOG($H$2,2))-ROUNDUP(LOG(H19,2),0)+IF(OR($H$2=1,$H$2=2,$H$2=4,$H$2=8,$H$2=16,$H$2=32,$H$2=64,$H$2=128,$H$2=256),0,1) -> -1 | K19: =J19*$J$2 -> -10 | M19: =IF(I19<>"",K19+I19+L19,0) -> 0
A20: =M20 -> 0 | B20: =IF(H20>$H$2,"",(ROW()-5)) | H20: 15 | I20: =IF(H20<$H$2+1,($I$2-($I$2-1)*(LOG(H20)/LOG($H$2))),"") | J20: =INT(LOG($H$2,2))-ROUNDUP(LOG(H20,2),0)+IF(OR($H$2=1,$H$2=2,$H$2=4,$H$2=8,$H$2=16,$H$2=32,$H$2=64,$H$2=128,$H$2=256),0,1) -> -1 | K20: =J20*$J$2 -> -10 | M20: =IF(I20<>"",K20+I20+L20,0) -> 0
A21: =M21 -> 0 | B21: =IF(H21>$H$2,"",(ROW()-5)) | H21: 16 | I21: =IF(H21<$H$2+1,($I$2-($I$2-1)*(LOG(H21)/LOG($H$2))),"") | J21: =INT(LOG($H$2,2))-ROUNDUP(LOG(H21,2),0)+IF(OR($H$2=1,$H$2=2,$H$2=4,$H$2=8,$H$2=16,$H$2=32,$H$2=64,$H$2=128,$H$2=256),0,1) -> -1 | K21: =J21*$J$2 -> -10 | M21: =IF(I21<>"",K21+I21+L21,0) -> 0
A22: =M22 -> 0 | B22: =IF(H22>$H$2,"",(ROW()-5)) | H22: 17 | I22: =IF(H22<$H$2+1,($I$2-($I$2-1)*(LOG(H22)/LOG($H$2))),"") | J22: =INT(LOG($H$2,2))-ROUNDUP(LOG(H22,2),0)+IF(OR($H$2=1,$H$2=2,$H$2=4,$H$2=8,$H$2=16,$H$2=32,$H$2=64,$H$2=128,$H$2=256),0,1) -> -2 | K22: =J22*$J$2 -> -20 | M22: =IF(I22<>"",K22+I22+L22,0) -> 0
A23: =M23 -> 0 | B23: =IF(H23>$H$2,"",(ROW()-5)) | H23: 18 | I23: =IF(H23<$H$2+1,($I$2-($I$2-1)*(LOG(H23)/LOG($H$2))),"") | J23: =INT(LOG($H$2,2))-ROUNDUP(LOG(H23,2),0)+IF(OR($H$2=1,$H$2=2,$H$2=4,$H$2=8,$H$2=16,$H$2=32,$H$2=64,$H$2=128,$H$2=256),0,1) -> -2 | K23: =J23*$J$2 -> -20 | M23: =IF(I23<>"",K23+I23+L23,0) -> 0
A24: =M24 -> 0 | B24: =IF(H24>$H$2,"",(ROW()-5)) | H24: 19 | I24: =IF(H24<$H$2+1,($I$2-($I$2-1)*(LOG(H24)/LOG($H$2))),"") | J24: =INT(LOG($H$2,2))-ROUNDUP(LOG(H24,2),0)+IF(OR($H$2=1,$H$2=2,$H$2=4,$H$2=8,$H$2=16,$H$2=32,$H$2=64,$H$2=128,$H$2=256),0,1) -> -2 | K24: =J24*$J$2 -> -20 | M24: =IF(I24<>"",K24+I24+L24,0) -> 0
