Workbook

Sheet All
A1: L.P. | C1: IMIĘ NAZWISKO | D1: PUNKTY | F1: ma mniej niż 30 lat
F2: odeszła/odszedł w tym roku
A3: =ROW()-2 -> 1 | B3: 1 | C3: TK | D3: =_xlfn.XLOOKUP(C3,Kobiety!$B$3:$B$96,Kobiety!C$3:C$96,_xlfn.XLOOKUP(C3,Mężczyźni!$C$3:$C$62,Mężczyźni!D$3:D$62,"")) -> 59
A4: =ROW()-2 -> 2 | B4: 1 | C4: GANSZCZYK Marcin | D4: =_xlfn.XLOOKUP(C4,Kobiety!$B$3:$B$96,Kobiety!C$3:C$96,_xlfn.XLOOKUP(C4,Mężczyźni!$C$3:$C$62,Mężczyźni!D$3:D$62,"")) -> 56
A5: =ROW()-2 -> 3 | B5: 0 | C5: KOSIŃSKI Łukasz | D5: =_xlfn.XLOOKUP(C5,Kobiety!$B$3:$B$96,Kobiety!C$3:C$96,_xlfn.XLOOKUP(C5,Mężczyźni!$C$3:$C$62,Mężczyźni!D$3:D$62,"")) -> 55
A6: =ROW()-2 -> 4 | B6: 2 | C6: GAJDA Leszek | D6: =_xlfn.XLOOKUP(C6,Kobiety!$B$3:$B$96,Kobiety!C$3:C$96,_xlfn.XLOOKUP(C6,Mężczyźni!$C$3:$C$62,Mężczyźni!D$3:D$62,"")) -> 40
A7: =ROW()-2 -> 5 | B7: 3 | C7: OSSOWSKI Wojciech | D7: =_xlfn.XLOOKUP(C7,Kobiety!$B$3:$B$96,Kobiety!C$3:C$96,_xlfn.XLOOKUP(C7,Mężczyźni!$C$3:$C$62,Mężczyźni!D$3:D$62,"")) -> 37
A8: =ROW()-2 -> 6 | B8: 2 | C8: MAZIK Aleksander | D8: =_xlfn.XLOOKUP(C8,Kobiety!$B$3:$B$96,Kobiety!C$3:C$96,_xlfn.XLOOKUP(C8,Mężczyźni!$C$3:$C$62,Mężczyźni!D$3:D$62,"")) -> 34
A9: =ROW()-2 -> 7 | B9: 1 | C9: WINGROWICZ Mariusz | D9: =_xlfn.XLOOKUP(C9,Kobiety!$B$3:$B$96,Kobiety!C$3:C$96,_xlfn.XLOOKUP(C9,Mężczyźni!$C$3:$C$62,Mężczyźni!D$3:D$62,"")) -> 32
A10: =ROW()-2 -> 8 | B10: 2 | C10: NOWICKI Robert | D10: =_xlfn.XLOOKUP(C10,Kobiety!$B$3:$B$96,Kobiety!C$3:C$96,_xlfn.XLOOKUP(C10,Mężczyźni!$C$3:$C$62,Mężczyźni!D$3:D$62,"")) -> 31
A11: =ROW()-2 -> 9 | B11: 2 | C11: GAJDA Zbigniew | D11: =_xlfn.XLOOKUP(C11,Kobiety!$B$3:$B$96,Kobiety!C$3:C$96,_xlfn.XLOOKUP(C11,Mężczyźni!$C$3:$C$62,Mężczyźni!D$3:D$62,"")) -> 30
A12: =ROW()-2 -> 10 | B12: 1 | C12: RUDY Andrzej | D12: =_xlfn.XLOOKUP(C12,Kobiety!$B$3:$B$96,Kobiety!C$3:C$96,_xlfn.XLOOKUP(C12,Mężczyźni!$C$3:$C$62,Mężczyźni!D$3:D$62,"")) -> 29
A13: =ROW()-2 -> 11 | B13: 0 | C13: MICHALSKI Philip | D13: =_xlfn.XLOOKUP(C13,Kobiety!$B$3:$B$96,Kobiety!C$3:C$96,_xlfn.XLOOKUP(C13,Mężczyźni!$C$3:$C$62,Mężczyźni!D$3:D$62,"")) -> 25
A14: =ROW()-2 -> 12 | B14: 0 | C14: CHOJNACKI Tomasz | D14: =_xlfn.XLOOKUP(C14,Kobiety!$B$3:$B$96,Kobiety!C$3:C$96,_xlfn.XLOOKUP(C14,Mężczyźni!$C$3:$C$62,Mężczyźni!D$3:D$62,"")) -> 24
... A19: =ROW()-2 -> 17 | B19: 2 | C19: MUTWIL Marcin | D19: =_xlfn.XLOOKUP(C19,Kobiety!$B$3:$B$96,Kobiety!C$3:C$96,_xlfn.XLOOKUP(C19,Mężczyźni!$C$3:$C$62,Mężczyźni!D$3:D$62,"")) -> 23
A20: =ROW()-2 -> 18 | B20: k | C20: LASKOWSKA Patrycja | D20: =_xlfn.XLOOKUP(C20,Kobiety!$B$3:$B$96,Kobiety!C$3:C$96,_xlfn.XLOOKUP(C20,Mężczyźni!$C$3:$C$62,Mężczyźni!D$3:D$62,"")) -> 21
A21: =ROW()-2 -> 19 | B21: 0 | C21: WIŚNIEWSKI Bernard | D21: =_xlfn.XLOOKUP(C21,Kobiety!$B$3:$B$96,Kobiety!C$3:C$96,_xlfn.XLOOKUP(C21,Mężczyźni!$C$3:$C$62,Mężczyźni!D$3:D$62,"")) -> 19
A22: =ROW()-2 -> 20 | B22: 3 | C22: KONWIŃSKI Grzegorz | D22: =_xlfn.XLOOKUP(C22,Kobiety!$B$3:$B$96,Kobiety!C$3:C$96,_xlfn.XLOOKUP(C22,Mężczyźni!$C$3:$C$62,Mężczyźni!D$3:D$62,"")) -> 16
A23: =ROW()-2 -> 21 | B23: 1 | C23: BAZAK Jacek | D23: =_xlfn.XLOOKUP(C23,Kobiety!$B$3:$B$96,Kobiety!C$3:C$96,_xlfn.XLOOKUP(C23,Mężczyźni!$C$3:$C$62,Mężczyźni!D$3:D$62,"")) -> 15
A24: =ROW()-2 -> 22 | B24: k | C24: FUHRMANN Ulrike | D24: =_xlfn.XLOOKUP(C24,Kobiety!$B$3:$B$96,Kobiety!C$3:C$96,_xlfn.XLOOKUP(C24,Mężczyźni!$C$3:$C$62,Mężczyźni!D$3:D$62,"")) -> 15
A25: =ROW()-2 -> 23 | B25: 0 | C25: GĘZIKIEWICZ Marcin | D25: =_xlfn.XLOOKUP(C25,Kobiety!$B$3:$B$96,Kobiety!C$3:C$96,_xlfn.XLOOKUP(C25,Mężczyźni!$C$3:$C$62,Mężczyźni!D$3:D$62,"")) -> 15
A26: =ROW()-2 -> 24 | B26: k | C26: DANILCZUK Julita | D26: =_xlfn.XLOOKUP(C26,Kobiety!$B$3:$B$96,Kobiety!C$3:C$96,_xlfn.XLOOKUP(C26,Mężczyźni!$C$3:$C$62,Mężczyźni!D$3:D$62,"")) -> 14
A27: =ROW()-2 -> 25 | B27: k | C27: KĘDZIORA Agata | D27: =_xlfn.XLOOKUP(C27,Kobiety!$B$3:$B$96,Kobiety!C$3:C$96,_xlfn.XLOOKUP(C27,Mężczyźni!$C$3:$C$62,Mężczyźni!D$3:D$62,"")) -> 14
A28: =ROW()-2 -> 26 | B28: k | C28: SAJEWICZ Izabela | D28: =_xlfn.XLOOKUP(C28,Kobiety!$B$3:$B$96,Kobiety!C$3:C$96,_xlfn.XLOOKUP(C28,Mężczyźni!$C$3:$C$62,Mężczyźni!D$3:D$62,"")) -> 13
A29: =ROW()-2 -> 27 | B29: 2 | C29: JAROSZEK Zbigniew | D29: =_xlfn.XLOOKUP(C29,Kobiety!$B$3:$B$96,Kobiety!C$3:C$96,_xlfn.XLOOKUP(C29,Mężczyźni!$C$3:$C$62,Mężczyźni!D$3:D$62,"")) -> 11
A30: =ROW()-2 -> 28 | B30: k | C30: OWCZAREK Ewelina | D30: =_xlfn.XLOOKUP(C30,Kobiety!$B$3:$B$96,Kobiety!C$3:C$96,_xlfn.XLOOKUP(C30,Mężczyźni!$C$3:$C$62,Mężczyźni!D$3:D$62,"")) -> 11
A31: =ROW()-2 -> 29 | B31: 0 | C31: WOŁOSZYN Nikodem | D31: =_xlfn.XLOOKUP(C31,Kobiety!$B$3:$B$96,Kobiety!C$3:C$96,_xlfn.XLOOKUP(C31,Mężczyźni!$C$3:$C$62,Mężczyźni!D$3:D$62,"")) -> 11
A32: =ROW()-2 -> 30 | B32: 2 | C32: TRZENSIOK Bernard | D32: =_xlfn.XLOOKUP(C32,Kobiety!$B$3:$B$96,Kobiety!C$3:C$96,_xlfn.XLOOKUP(C32,Mężczyźni!$C$3:$C$62,Mężczyźni!D$3:D$62,"")) -> 10
A33: =ROW()-2 -> 31 | B33: k | C33: BROMBEREK Angelika | D33: =_xlfn.XLOOKUP(C33,Kobiety!$B$3:$B$96,Kobiety!C$3:C$96,_xlfn.XLOOKUP(C33,Mężczyźni!$C$3:$C$62,Mężczyźni!D$3:D$62,"")) -> 9
A34: =ROW()-2 -> 32 | B34: 3 | C34: KOSIŃSKI Jerzy | D34: =_xlfn.XLOOKUP(C34,Kobiety!$B$3:$B$96,Kobiety!C$3:C$96,_xlfn.XLOOKUP(C34,Mężczyźni!$C$3:$C$62,Mężczyźni!D$3:D$62,"")) -> 9
A35: =ROW()-2 -> 33 | B35: 0 | C35: MIKOŁAJCZUK Norbert | D35: =_xlfn.XLOOKUP(C35,Kobiety!$B$3:$B$96,Kobiety!C$3:C$96,_xlfn.XLOOKUP(C35,Mężczyźni!$C$3:$C$62,Mężczyźni!D$3:D$62,"")) -> 9
A36: =ROW()-2 -> 34 | B36: 0 | C36: TRISCRONIA Anton | D36: =_xlfn.XLOOKUP(C36,Kobiety!$B$3:$B$96,Kobiety!C$3:C$96,_xlfn.XLOOKUP(C36,Mężczyźni!$C$3:$C$62,Mężczyźni!D$3:D$62,"")) -> 9
A37: =ROW()-2 -> 35 | B37: 3 | C37: KIERSZNICKI Ryszard | D37: =_xlfn.XLOOKUP(C37,Kobiety!$B$3:$B$96,Kobiety!C$3:C$96,_xlfn.XLOOKUP(C37,Mężczyźni!$C$3:$C$62,Mężczyźni!D$3:D$62,"")) -> 6
A38: =ROW()-2 -> 36 | B38: 1 | C38: KOŁUCKI Michał | D38: =_xlfn.XLOOKUP(C38,Kobiety!$B$3:$B$96,Kobiety!C$3:C$96,_xlfn.XLOOKUP(C38,Mężczyźni!$C$3:$C$62,Mężczyźni!D$3:D$62,"")) -> 6
A39: =ROW()-2 -> 37 | B39: 1 | C39: MARASEK Tomasz | D39: =_xlfn.XLOOKUP(C39,Kobiety!$B$3:$B$96,Kobiety!C$3:C$96,_xlfn.XLOOKUP(C39,Mężczyźni!$C$3:$C$62,Mężczyźni!D$3:D$62,"")) -> 6
A40: =ROW()-2 -> 38 | B40: 1 | C40: ZAWROTNIAK Przemysław | D40: =_xlfn.XLOOKUP(C40,Kobiety!$B$3:$B$96,Kobiety!C$3:C$96,_xlfn.XLOOKUP(C40,Mężczyźni!$C$3:$C$62,Mężczyźni!D$3:D$62,"")) -> 6
A41: =ROW()-2 -> 39 | B41: 3 | C41: ADAMCZEWSKI Wojciech | D41: =_xlfn.XLOOKUP(C41,Kobiety!$B$3:$B$96,Kobiety!C$3:C$96,_xlfn.XLOOKUP(C41,Mężczyźni!$C$3:$C$62,Mężczyźni!D$3:D$62,"")) -> 5
A42: =ROW()-2 -> 40 | B42: 1 | C42: SZYMAŃSKI Adam | D42: =_xlfn.XLOOKUP(C42,Kobiety!$B$3:$B$96,Kobiety!C$3:C$96,_xlfn.XLOOKUP(C42,Mężczyźni!$C$3:$C$62,Mężczyźni!D$3:D$62,"")) -> 5
A43: =ROW()-2 -> 41 | B43: k | C43: BALIUNOVA Iryna | D43: =_xlfn.XLOOKUP(C43,Kobiety!$B$3:$B$96,Kobiety!C$3:C$96,_xlfn.XLOOKUP(C43,Mężczyźni!$C$3:$C$62,Mężczyźni!D$3:D$62,"")) -> 4
A44: =ROW()-2 -> 42 | C44: GAJDA Krzysztof | D44: =_xlfn.XLOOKUP(C44,Kobiety!$B$3:$B$96,Kobiety!C$3:C$96,_xlfn.XLOOKUP(C44,Mężczyźni!$C$3:$C$62,Mężczyźni!D$3:D$62,"")) -> 4
...

Sheet Kobiety
A1: L.P. | B1: IMIĘ NAZWISKO | C1: PUNKTY | D1: MPW | F1: GP I | H1: GP II | J1: GP III | L1: GP IV | N1: GP V | Q1: ma mniej niż 30 lat
D2: I | E2: II | F2: I | G2: II | H2: I | I2: II | J2: I | K2: II | L2: I | M2: II | N2: I | O2: II | Q2: odeszła w tym roku
A3: =ROW()-2 -> 1 | B3: LASKOWSKA Patrycja | C3: =SUM(D3:O3) -> 21 | H3: 4 | I3: 2 | J3: 1 | K3: 3 | L3: 2 | M3: 1 | N3: 4 | O3: 4
A4: =ROW()-2 -> 2 | B4: FUHRMANN Ulrike | C4: =SUM(D4:O4) -> 15 | D4: 0 | E4: 1 | F4: 2 | G4: 3 | H4: 0 | I4: 1 | J4: 0 | K4: 2 | L4: 2 | M4: 2 | N4: 1 | O4: 1
A5: =ROW()-2 -> 3 | B5: DANILCZUK Julita | C5: =SUM(D5:O5) -> 14 | H5: 3 | I5: 1 | L5: 3 | M5: 2 | N5: 2 | O5: 3
A6: =ROW()-2 -> 4 | B6: KĘDZIORA Agata | C6: =SUM(D6:O6) -> 14 | F6: 2 | G6: 3 | H6: 4 | I6: 5
A7: =ROW()-2 -> 5 | B7: SAJEWICZ Izabela | C7: =SUM(D7:O7) -> 13 | H7: 4 | I7: 3 | L7: 2 | M7: 4
A8: =ROW()-2 -> 6 | B8: OWCZAREK Ewelina | C8: =SUM(D8:O8) -> 11 | F8: 3 | G8: 3 | H8: 2 | I8: 3
A9: =ROW()-2 -> 7 | B9: BROMBEREK Angelika | C9: =SUM(D9:O9) -> 9 | F9: 3 | G9: 3 | L9: 3
A10: =ROW()-2 -> 8 | B10: BALIUNOVA Iryna | C10: =SUM(D10:O10) -> 4 | H10: 2 | I10: 2
A11: =ROW()-2 -> 9 | B11: JAŃCZYK Marta | C11: =SUM(D11:O11) -> 3 | H11: 2 | I11: 1
A12: =ROW()-2 -> 10 | B12: MARTIN Madalina | C12: =SUM(D12:O12) -> 2 | N12: 1 | O12: 1
A13: =ROW()-2 -> 11 | B13: GAWROŃSKA Marta | C13: =SUM(D13:O13) -> 2 | H13: 1 | I13: 1
A14: =ROW()-2 -> 12 | B14: MILCZAREK Renata | C14: =SUM(D14:O14) -> 1 | J14: 0 | K14: 0 | L14: 0 | M14: 0 | N14: 1 | O14: 0
A15: =ROW()-2 -> 13 | B15: SOSNOWSKA Aniela | C15: =SUM(D15:O15) -> 1 | F15: 1 | G15: 0 | H15: 0 | I15: 0
A16: =ROW()-2 -> 14 | B16: SZYMCZYK Wiktoria | C16: =SUM(D16:O16) -> 1 | N16: 0 | O16: 1
A17: =ROW()-2 -> 15 | B17: CZERNIK Paulina | C17: =SUM(D17:O17) -> 0 | N17: 0 | O17: 0
A18: =ROW()-2 -> 16 | B18: DEDU Bianca | C18: =SUM(D18:O18) -> 0 | N18: 0 | O18: 0
A19: =ROW()-2 -> 17 | B19: TRECIŃSKA Oliwia | C19: =SUM(D19:O19) -> 0 | N19: 0 | O19: 0
A20: =ROW()-2 -> 18 | C20: =SUM(D20:O20) -> 0
A21: =ROW()-2 -> 19 | C21: =SUM(D21:O21) -> 0
A22: =ROW()-2 -> 20 | C22: =SUM(D22:O22) -> 0
A23: =ROW()-2 -> 21 | C23: =SUM(D23:O23) -> 0
A24: =ROW()-2 -> 22 | C24: =SUM(D24:O24) -> 0
A25: =ROW()-2 -> 23 | C25: =SUM(D25:O25) -> 0
A26: =ROW()-2 -> 24 | C26: =SUM(D26:O26) -> 0

Sheet Mężczyźni
A1: L.P. | C1: IMIĘ NAZWISKO | D1: PUNKTY | E1: MPW | G1: GP I | I1: GP II | K1: GP III | M1: GP IV | O1: GP V | R1: ma mniej niż 30 lat
E2: I | F2: II | G2: I | H2: II | I2: I | J2: II | K2: I | L2: II | M2: I | N2: II | O2: I | P2: II | R2: Odszedł w tym roku
A3: =ROW()-2 -> 1 | B3: 1 | C3: TK | D3: =SUM(E3:P3) -> 59 | E3: 5 | F3: 5 | G3: 5 | H3: 4 | I3: 5 | J3: 5 | K3: 6 | L3: 6 | M3: 5 | N3: 4 | O3: 4 | P3: 5
A4: =ROW()-2 -> 2 | B4: 1 | C4: GANSZCZYK Marcin | D4: =SUM(E4:P4) -> 56 | E4: 5 | F4: 5 | G4: 5 | H4: 5 | I4: 5 | J4: 5 | K4: 4 | L4: 4 | M4: 5 | N4: 5 | O4: 4 | P4: 4
A5: =ROW()-2 -> 3 | B5: 0 | C5: KOSIŃSKI Łukasz | D5: =SUM(E5:P5) -> 55 | E5: 5 | F5: 2 | G5: 5 | H5: 5 | I5: 4 | J5: 5 | K5: 5 | L5: 5 | M5: 5 | N5: 5 | O5: 4 | P5: 5
A6: =ROW()-2 -> 4 | B6: 2 | C6: GAJDA Leszek | D6: =SUM(E6:P6) -> 40 | E6: 3 | F6: 4 | G6: 2 | H6: 4 | I6: 3 | J6: 4 | K6: 2 | L6: 4 | M6: 3 | N6: 2 | O6: 4 | P6: 5
A7: =ROW()-2 -> 5 | B7: 3 | C7: OSSOWSKI Wojciech | D7: =SUM(E7:P7) -> 37 | E7: 4 | F7: 2 | G7: 1 | H7: 3 | I7: 4 | J7: 4 | K7: 3 | L7: 2 | M7: 3 | N7: 3 | O7: 5 | P7: 3
A8: =ROW()-2 -> 6 | B8: 2 | C8: MAZIK Aleksander | D8: =SUM(E8:P8) -> 34 | E8: 2 | F8: 4 | G8: 3 | H8: 3 | I8: 3 | J8: 3 | K8: 3 | L8: 2 | M8: 2 | N8: 1 | O8: 4 | P8: 4
A9: =ROW()-2 -> 7 | B9: 1 | C9: WINGROWICZ Mariusz | D9: =SUM(E9:P9) -> 32 | E9: 4 | F9: 4 | I9: 3 | J9: 3 | K9: 3 | L9: 3 | M9: 2 | N9: 4 | O9: 4 | P9: 2
A10: =ROW()-2 -> 8 | B10: 2 | C10: NOWICKI Robert | D10: =SUM(E10:P10) -> 31 | E10: 3 | F10: 3 | K10: 5 | L10: 5 | M10: 3 | N10: 3 | O10: 5 | P10: 4
A11: =ROW()-2 -> 9 | B11: 2 | C11: GAJDA Zbigniew | D11: =SUM(E11:P11) -> 30 | G11: 2 | H11: 4 | I11: 4 | J11: 4 | K11: 4 | L11: 3 | M11: 3 | N11: 1 | O11: 2 | P11: 3
A12: =ROW()-2 -> 10 | B12: 1 | C12: RUDY Andrzej | D12: =SUM(E12:P12) -> 29 | E12: 3 | F12: 3 | G12: 1 | H12: 2 | I12: 5 | J12: 3 | K12: 3 | L12: 3 | M12: 2 | N12: 4
A13: =ROW()-2 -> 11 | B13: 0 | C13: MICHALSKI Philip | D13: =SUM(E13:P13) -> 25 | I13: 3 | J13: 5 | K13: 5 | L13: 5 | O13: 4 | P13: 3
A14: =ROW()-2 -> 12 | B14: 0 | C14: CHOJNACKI Tomasz | D14: =SUM(E14:P14) -> 24 | E14: 1 | F14: 2 | G14: 4 | H14: 3 | K14: 3 | L14: 1 | M14: 2 | N14: 2 | O14: 3 | P14: 3
A15: =ROW()-2 -> 13 | B15: 1 | C15: KROCHMALSKI Jakub | D15: =SUM(E15:P15) -> 24 | E15: 3 | F15: 4 | M15: 4 | N15: 4 | O15: 5 | P15: 4
A16: =ROW()-2 -> 14 | B16: 0 | C16: PRZYSTAJKO Daniel | D16: =SUM(E16:P16) -> 24 | G16: 3 | H16: 3 | I16: 5 | J16: 4 | O16: 4 | P16: 5
A17: =ROW()-2 -> 15 | B17: 2 | C17: ZABŁOCKI Michał | D17: =SUM(E17:P17) -> 24 | E17: 4 | F17: 5 | K17: 4 | L17: 4 | M17: 4 | N17: 3
A18: =ROW()-2 -> 16 | B18: 4 | C18: MAINKA Andrzej | D18: =SUM(E18:P18) -> 23 | E18: 2 | F18: 2 | G18: 3 | H18: 1 | I18: 1 | J18: 1 | K18: 2 | L18: 1 | M18: 3 | N18: 2 | O18: 3 | P18: 2
A19: =ROW()-2 -> 17 | B19: 2 | C19: MUTWIL Marcin | D19: =SUM(E19:P19) -> 23 | G19: 3 | H19: 5 | I19: 5 | J19: 4 | M19: 3 | N19: 3
A20: =ROW()-2 -> 18 | B20: 0 | C20: WIŚNIEWSKI Bernard | D20: =SUM(E20:P20) -> 19 | E20: 2 | F20: 2 | K20: 1 | L20: 3 | M20: 3 | N20: 2 | O20: 3 | P20: 3
A21: =ROW()-2 -> 19 | B21: 3 | C21: KONWIŃSKI Grzegorz | D21: =SUM(E21:P21) -> 16 | E21: 0 | F21: 2 | G21: 5 | H21: 1 | I21: 0 | J21: 1 | K21: 2 | L21: 0 | O21: 2 | P21: 3
A22: =ROW()-2 -> 20 | B22: 1 | C22: BAZAK Jacek | D22: =SUM(E22:P22) -> 15 | G22: 4 | H22: 5 | I22: 2 | J22: 4
A23: =ROW()-2 -> 21 | B23: 0 | C23: GĘZIKIEWICZ Marcin | D23: =SUM(E23:P23) -> 15 | K23: 4 | L23: 5 | O23: 3 | P23: 3
A24: =ROW()-2 -> 22 | B24: 2 | C24: JAROSZEK Zbigniew | D24: =SUM(E24:P24) -> 11 | I24: 4 | J24: 3 | M24: 1 | N24: 3
A25: =ROW()-2 -> 23 | B25: 0 | C25: WOŁOSZYN Nikodem | D25: =SUM(E25:P25) -> 11 | I25: 2 | J25: 3 | O25: 2 | P25: 4
A26: =ROW()-2 -> 24 | B26: 2 | C26: TRZENSIOK Bernard | D26: =SUM(E26:P26) -> 10 | I26: 3 | J26: 2 | K26: 1 | L26: 3 | M26: 0 | N26: 1
A27: =ROW()-2 -> 25 | B27: 3 | C27: KOSIŃSKI Jerzy | D27: =SUM(E27:P27) -> 9 | G27: 2 | H27: 2 | I27: 3 | J27: 2
A28: =ROW()-2 -> 26 | B28: 0 | C28: MIKOŁAJCZUK Norbert | D28: =SUM(E28:P28) -> 9 | I28: 1 | J28: 1 | M28: 1 | N28: 1 | O28: 3 | P28: 2
A29: =ROW()-2 -> 27 | B29: 0 | C29: TRISCRONIA Anton | D29: =SUM(E29:P29) -> 9 | M29: 2 | N29: 2 | O29: 2 | P29: 3
A30: =ROW()-2 -> 28 | B30: 3 | C30: KIERSZNICKI Ryszard | D30: =SUM(E30:P30) -> 6 | E30: 1 | F30: 0 | G30: 2 | H30: 2 | I30: 0 | J30: 0 | K30: 1 | L30: 0 | M30: 0 | N30: 0
A31: =ROW()-2 -> 29 | B31: 1 | C31: KOŁUCKI Michał | D31: =SUM(E31:P31) -> 6 | E31: 3 | F31: 3
A32: =ROW()-2 -> 30 | B32: 1 | C32: MARASEK Tomasz | D32: =SUM(E32:P32) -> 6 | E32: 1 | F32: 1 | O32: 2 | P32: 2
A33: =ROW()-2 -> 31 | B33: 1 | C33: ZAWROTNIAK Przemysław | D33: =SUM(E33:P33) -> 6 | M33: 3 | N33: 3
A34: =ROW()-2 -> 32 | B34: 3 | C34: ADAMCZEWSKI Wojciech | D34: =SUM(E34:P34) -> 5 | E34: 0 | F34: 0 | I34: 0 | J34: 1 | O34: 3 | P34: 1
A35: =ROW()-2 -> 33 | B35: 1 | C35: SZYMAŃSKI Adam | D35: =SUM(E35:P35) -> 5 | K35: 2 | L35: 1 | M35: 2 | N35: 0
A36: =ROW()-2 -> 34 | B36: 0 | C36: GAJDA Krzysztof | D36: =SUM(E36:P36) -> 4 | I36: 0 | J36: 1 | K36: 2 | L36: 1
A37: =ROW()-2 -> 35 | B37: 0 | C37: JAMROCHA Maciej | D37: =SUM(E37:P37) -> 4 | O37: 0 | P37: 4
A38: =ROW()-2 -> 36 | B38: 3 | C38: JUSZKIEWICZ Piotr | D38: =SUM(E38:P38) -> 4 | E38: 1 | F38: 0 | G38: 0 | H38: 0 | K38: 0 | L38: 0 | M38: 0 | N38: 0 | O38: 2 | P38: 1
A39: =ROW()-2 -> 37 | B39: 0 | C39: ZAPAŚNIK Janusz | D39: =SUM(E39:P39) -> 4 | I39: 1 | J39: 3
A40: =ROW()-2 -> 38 | B40: 0 | C40: KIRCUN Jan | D40: =SUM(E40:P40) -> 3 | M40: 2 | N40: 1
...
