Workbook

Sheet All
A2: L,P, | B2: IMIĘ NAZWISKO | C2: V/M | D2: V/M | V2: TS | W2: TS | AO2: Ind | AP2: Ind
D3: MP | F3: GP1 | H3: GP2 | J3: GP3 | L3: GP4 | N3: GP5 | P3: GP6 | R3: GP7 | T3: GP8 | W3: MP | Y3: GP1 | AA3: GP2 | AC3: GP3 | AE3: GP4 | AG3: GP5 | AI3: GP6 | AK3: GP7 | AM3: GP8 | AP3: MP | AR3: GP1 | AT3: GP2 | AV3: GP3 | AX3: GP4 | AZ3: GP5 | BB3: GP6 | BD3: GP7 | BF3: GP8
D4: 1 | E4: 2 | F4: 1 | G4: 2 | H4: 1 | I4: 2 | J4: 1 | K4: 2 | L4: 1 | M4: 2 | N4: 1 | O4: 2 | P4: 1 | Q4: 2 | R4: 1 | S4: 2 | T4: 1 | U4: 2 | W4: 1 | X4: 2 | Y4: 1 | Z4: 2 | AA4: 1 | AB4: 2 | AC4: 1 | AD4: 2 | AE4: 1 | AF4: 2 | AG4: 1 | AH4: 2 | AI4: 1 | AJ4: 2 | AK4: 1 | AL4: 2 | AM4: 1 | AN4: 2 | AP4: 1 | AQ4: 2 | AR4: 1 | AS4: 2 | AT4: 1 | AU4: 2 | AV4: 1 | AW4: 2 | AX4: 1 | AY4: 2 | AZ4: 1 | BA4: 2 | BB4: 1 | BC4: 2 | BD4: 1 | BE4: 2 | BF4: 1 | BG4: 2
A5: =ROW()-4 -> 1 | B5: BAZAK Jacek | C5: =SUM(D5:U5) -> 9.45 | D5: =_xlfn.XLOOKUP($B5,'MP (1)'!$B$6:$B$99,'MP (1)'!$E$6:$E$99,"") -> 1 | E5: =_xlfn.XLOOKUP($B5,'MP (2)'!$B$6:$B$100,'MP (2)'!$E$6:$E$100,"") -> 1 | F5: =_xlfn.XLOOKUP($B5,'GP1 (1)'!$B$6:$B$100,'GP1 (1)'!$E$6:$E$100,"") -> 1 | G5: =_xlfn.XLOOKUP($B5,'GP1 (2)'!$B$6:$B$100,'GP1 (2)'!$E$6:$E$100,"") -> 0.8 | H5: =_xlfn.XLOOKUP($B5,'GP2 (1)'!$B$6:$B$101,'GP2 (1)'!$E$6:$E$101,"") -> 0.8 | I5: =_xlfn.XLOOKUP($B5,'GP2 (2)'!$B$6:$B$100,'GP2 (2)'!$E$6:$E$100,"") -> 0.6 | J5: =_xlfn.XLOOKUP($B5,'GP3 (1)'!$B$6:$B$100,'GP3 (1)'!$E$6:$E$100,"") | K5: =_xlfn.XLOOKUP($B5,'GP3 (2)'!$B$6:$B$100,'GP3 (2)'!$E$6:$E$100,"") | L5: =_xlfn.XLOOKUP($B5,'GP4 (1)'!$B$6:$B$66,'GP4 (1)'!$E$6:$E$66,"") -> 0.8 | M5: =_xlfn.XLOOKUP($B5,'GP4 (2)'!$B$6:$B$100,'GP4 (2)'!$E$6:$E$100,"") -> 0.8 | N5: =_xlfn.XLOOKUP($B5,'GP5 (1)'!$B$6:$B$99,'GP5 (1)'!$E$6:$E$99,"") -> 0.4 | O5: =_xlfn.XLOOKUP($B5,'GP5 (2)'!$B$6:$B$99,'GP5 (2)'!$E$6:$E$99,"") -> 0.75 | P5: =_xlfn.XLOOKUP($B5,'GP6 (1)'!$B$5:$B$99,'GP6 (1)'!$E$5:$E$99,"") | Q5: =_xlfn.XLOOKUP($B5,'GP6 (2)'!$B$5:$B$99,'GP6 (2)'!$E$5:$E$99,"") | R5: =_xlfn.XLOOKUP($B5,'GP7 (1)'!$B$6:$B$100,'GP7 (1)'!$E$6:$E$100,"") -> 0.80 | S5: =_xlfn.XLOOKUP($B5,'GP7 (2)'!$B$6:$B$100,'GP7 (2)'!$E$6:$E$100,"") -> 0.75 | T5: =_xlfn.XLOOKUP($B5,'GP8 (1)'!$B$6:$B$100,'GP8 (1)'!$E$6:$E$100,"") -> 0.80 | U5: =_xlfn.XLOOKUP($B5,'GP8 (2)'!$B$6:$B$100,'GP8 (2)'!$E$6:$E$100,"") -> 0.75 | V5: =SUM(W5:AN5) -> 311 | W5: =_xlfn.XLOOKUP($B5,'MP (1)'!$B$6:$B$99,'MP (1)'!$F$6:$F$99,"") -> 28 | X5: =_xlfn.XLOOKUP($B5,'MP (2)'!$B$6:$B$100,'MP (2)'!$F$6:$F$100,"") -> 30 | Y5: =_xlfn.XLOOKUP($B5,'GP1 (1)'!$B$6:$B$100,'GP1 (1)'!$F$6:$F$100,"") -> 30 | Z5: =_xlfn.XLOOKUP($B5,'GP1 (2)'!$B$6:$B$100,'GP1 (2)'!$F$6:$F$100,"") -> 21 | AA5: =_xlfn.XLOOKUP($B5,'GP2 (1)'!$B$6:$B$101,'GP2 (1)'!$F$6:$F$101,"") -> 22 | AB5: =_xlfn.XLOOKUP($B5,'GP2 (2)'!$B$6:$B$100,'GP2 (2)'!$F$6:$F$100,"") -> 20 | AC5: =_xlfn.XLOOKUP($B5,'GP3 (1)'!$B$6:$B$100,'GP3 (1)'!$F$6:$F$100,"") | AD5: =_xlfn.XLOOKUP($B5,'GP3 (2)'!$B$6:$B$100,'GP3 (2)'!$F$6:$F$100,"") | AE5: =_xlfn.XLOOKUP($B5,'GP4 (1)'!$B$6:$B$66,'GP4 (1)'!$F$6:$F$66,"") -> 23 | AF5: =_xlfn.XLOOKUP($B5,'GP4 (2)'!$B$6:$B$100,'GP4 (2)'!$F$6:$F$100,"") -> 23 | AG5: =_xlfn.XLOOKUP($B5,'GP5 (1)'!$B$6:$B$99,'GP5 (1)'!$F$6:$F$99,"") -> 18 | AH5: =_xlfn.XLOOKUP($B5,'GP5 (2)'!$B$6:$B$99,'GP5 (2)'!$F$6:$F$99,"") -> 16 | AI5: =_xlfn.XLOOKUP($B5,'GP6 (1)'!$B$5:$B$99,'GP6 (1)'!$F$5:$F$99,"") | AJ5: =_xlfn.XLOOKUP($B5,'GP6 (2)'!$B$5:$B$99,'GP6 (2)'!$F$5:$F$99,"") | AK5: =_xlfn.XLOOKUP($B5,'GP7 (1)'!$B$6:$B$100,'GP7 (1)'!$F$6:$F$100,"") -> 22 | AL5: =_xlfn.XLOOKUP($B5,'GP7 (2)'!$B$6:$B$100,'GP7 (2)'!$F$6:$F$100,"") -> 18 | AM5: =_xlfn.XLOOKUP($B5,'GP8 (1)'!$B$6:$B$100,'GP8 (1)'!$F$6:$F$100,"") -> 24 | AN5: =_xlfn.XLOOKUP($B5,'GP8 (2)'!$B$6:$B$100,'GP8 (2)'!$F$6:$F$100,"") -> 16 | AO5: =SUM(AP5:BG5) -> 165 | AP5: =_xlfn.XLOOKUP($B5,'MP (1)'!$B$6:$B$99,'MP (1)'!$H$6:$H$99,"") -> 21 | AQ5: =_xlfn.XLOOKUP($B5,'MP (2)'!$B$6:$B$100,'MP (2)'!$H$6:$H$100,"") -> 23 | AR5: =_xlfn.XLOOKUP($B5,'GP1 (1)'!$B$6:$B$100,'GP1 (1)'!$H$6:$H$100,"") -> 25 | AS5: =_xlfn.XLOOKUP($B5,'GP1 (2)'!$B$6:$B$100,'GP1 (2)'!$H$6:$H$100,"") -> 10 | AT5: =_xlfn.XLOOKUP($B5,'GP2 (1)'!$B$6:$B$101,'GP2 (1)'!$H$6:$H$101,"") -> 13 | AU5: =_xlfn.XLOOKUP($B5,'GP2 (2)'!$B$6:$B$100,'GP2 (2)'!$H$6:$H$100,"") -> 4 | AV5: =_xlfn.XLOOKUP($B5,'GP3 (1)'!$B$6:$B$100,'GP3 (1)'!$H$6:$H$100,"") | AW5: =_xlfn.XLOOKUP($B5,'GP3 (2)'!$B$6:$B$100,'GP3 (2)'!$H$6:$H$100,"") | AX5: =_xlfn.XLOOKUP($B5,'GP4 (1)'!$B$6:$B$66,'GP4 (1)'!$H$6:$H$66,"") -> 17 | AY5: =_xlfn.XLOOKUP($B5,'GP4 (2)'!$B$6:$B$100,'GP4 (2)'!$H$6:$H$100,"") -> 14 | AZ5: =_xlfn.XLOOKUP($B5,'GP5 (1)'!$B$6:$B$99,'GP5 (1)'!$H$6:$H$99,"") -> 1 | BA5: =_xlfn.XLOOKUP($B5,'GP5 (2)'!$B$6:$B$99,'GP5 (2)'!$H$6:$H$99,"") -> 3 | BB5: =_xlfn.XLOOKUP($B5,'GP6 (1)'!$B$5:$B$99,'GP6 (1)'!$H$5:$H$99,"") | BC5: =_xlfn.XLOOKUP($B5,'GP6 (2)'!$B$5:$B$99,'GP6 (2)'!$H$5:$H$99,"") | BD5: =_xlfn.XLOOKUP($B5,'GP7 (1)'!$B$6:$B$100,'GP7 (1)'!$H$6:$H$100,"") -> 5 | BE5: =_xlfn.XLOOKUP($B5,'GP7 (2)'!$B$6:$B$100,'GP7 (2)'!$H$6:$H$100,"") -> 7 | BF5: =_xlfn.XLOOKUP($B5,'GP8 (1)'!$B$6:$B$100,'GP8 (1)'!$H$6:$H$100,"") -> 15 | BG5: =_xlfn.XLOOKUP($B5,'GP8 (2)'!$B$6:$B$100,'GP8 (2)'!$H$6:$H$100,"") -> 7
A6: =ROW()-4 -> 2 | B6: MALINOWSKI Piotr | C6: =SUM(D6:U6) -> 9.4 | D6: =_xlfn.XLOOKUP($B6,'MP (1)'!$B$6:$B$99,'MP (1)'!$E$6:$E$99,"") -> 0.6 | E6: =_xlfn.XLOOKUP($B6,'MP (2)'!$B$6:$B$100,'MP (2)'!$E$6:$E$100,"") -> 0.8 | F6: =_xlfn.XLOOKUP($B6,'GP1 (1)'!$B$6:$B$100,'GP1 (1)'!$E$6:$E$100,"") | G6: =_xlfn.XLOOKUP($B6,'GP1 (2)'!$B$6:$B$100,'GP1 (2)'!$E$6:$E$100,"") | H6: =_xlfn.XLOOKUP($B6,'GP2 (1)'!$B$6:$B$101,'GP2 (1)'!$E$6:$E$101,"") -> 1 | I6: =_xlfn.XLOOKUP($B6,'GP2 (2)'!$B$6:$B$100,'GP2 (2)'!$E$6:$E$100,"") -> 0.8 | J6: =_xlfn.XLOOKUP($B6,'GP3 (1)'!$B$6:$B$100,'GP3 (1)'!$E$6:$E$100,"") -> 0.6 | K6: =_xlfn.XLOOKUP($B6,'GP3 (2)'!$B$6:$B$100,'GP3 (2)'!$E$6:$E$100,"") -> 1.00 | L6: =_xlfn.XLOOKUP($B6,'GP4 (1)'!$B$6:$B$66,'GP4 (1)'!$E$6:$E$66,"") -> 1 | M6: =_xlfn.XLOOKUP($B6,'GP4 (2)'!$B$6:$B$100,'GP4 (2)'!$E$6:$E$100,"") -> 1 | N6: =_xlfn.XLOOKUP($B6,'GP5 (1)'!$B$6:$B$99,'GP5 (1)'!$E$6:$E$99,"") -> 1 | O6: =_xlfn.XLOOKUP($B6,'GP5 (2)'!$B$6:$B$99,'GP5 (2)'!$E$6:$E$99,"") -> 0.6 | P6: =_xlfn.XLOOKUP($B6,'GP6 (1)'!$B$5:$B$99,'GP6 (1)'!$E$5:$E$99,"") -> 0.75 | Q6: =_xlfn.XLOOKUP($B6,'GP6 (2)'!$B$5:$B$99,'GP6 (2)'!$E$5:$E$99,"") -> 0.75 | R6: =_xlfn.XLOOKUP($B6,'GP7 (1)'!$B$6:$B$100,'GP7 (1)'!$E$6:$E$100,"") -> 0.60 | S6: =_xlfn.XLOOKUP($B6,'GP7 (2)'!$B$6:$B$100,'GP7 (2)'!$E$6:$E$100,"") -> 1 | T6: =_xlfn.XLOOKUP($B6,'GP8 (1)'!$B$6:$B$100,'GP8 (1)'!$E$6:$E$100,"") -> 0.75 | U6: =_xlfn.XLOOKUP($B6,'GP8 (2)'!$B$6:$B$100,'GP8 (2)'!$E$6:$E$100,"") -> 1 | V6: =SUM(W6:AN6) -> 360 | W6: =_xlfn.XLOOKUP($B6,'MP (1)'!$B$6:$B$99,'MP (1)'!$F$6:$F$99,"") -> 23 | X6: =_xlfn.XLOOKUP($B6,'MP (2)'!$B$6:$B$100,'MP (2)'!$F$6:$F$100,"") -> 24 | Y6: =_xlfn.XLOOKUP($B6,'GP1 (1)'!$B$6:$B$100,'GP1 (1)'!$F$6:$F$100,"") | Z6: =_xlfn.XLOOKUP($B6,'GP1 (2)'!$B$6:$B$100,'GP1 (2)'!$F$6:$F$100,"") | AA6: =_xlfn.XLOOKUP($B6,'GP2 (1)'!$B$6:$B$101,'GP2 (1)'!$F$6:$F$101,"") -> 25 | AB6: =_xlfn.XLOOKUP($B6,'GP2 (2)'!$B$6:$B$100,'GP2 (2)'!$F$6:$F$100,"") -> 24 | AC6: =_xlfn.XLOOKUP($B6,'GP3 (1)'!$B$6:$B$100,'GP3 (1)'!$F$6:$F$100,"") -> 19 | AD6: =_xlfn.XLOOKUP($B6,'GP3 (2)'!$B$6:$B$100,'GP3 (2)'!$F$6:$F$100,"") -> 30 | AE6: =_xlfn.XLOOKUP($B6,'GP4 (1)'!$B$6:$B$66,'GP4 (1)'!$F$6:$F$66,"") -> 25 | AF6: =_xlfn.XLOOKUP($B6,'GP4 (2)'!$B$6:$B$100,'GP4 (2)'!$F$6:$F$100,"") -> 25 | AG6: =_xlfn.XLOOKUP($B6,'GP5 (1)'!$B$6:$B$99,'GP5 (1)'!$F$6:$F$99,"") -> 25 | AH6: =_xlfn.XLOOKUP($B6,'GP5 (2)'!$B$6:$B$99,'GP5 (2)'!$F$6:$F$99,"") -> 19 | AI6: =_xlfn.XLOOKUP($B6,'GP6 (1)'!$B$5:$B$99,'GP6 (1)'!$F$5:$F$99,"") -> 19 | AJ6: =_xlfn.XLOOKUP($B6,'GP6 (2)'!$B$5:$B$99,'GP6 (2)'!$F$5:$F$99,"") -> 16 | AK6: =_xlfn.XLOOKUP($B6,'GP7 (1)'!$B$6:$B$100,'GP7 (1)'!$F$6:$F$100,"") -> 20 | AL6: =_xlfn.XLOOKUP($B6,'GP7 (2)'!$B$6:$B$100,'GP7 (2)'!$F$6:$F$100,"") -> 25 | AM6: =_xlfn.XLOOKUP($B6,'GP8 (1)'!$B$6:$B$100,'GP8 (1)'!$F$6:$F$100,"") -> 16 | AN6: =_xlfn.XLOOKUP($B6,'GP8 (2)'!$B$6:$B$100,'GP8 (2)'!$F$6:$F$100,"") -> 25 | AO6: =SUM(AP6:BG6) -> 191 | AP6: =_xlfn.XLOOKUP($B6,'MP (1)'!$B$6:$B$99,'MP (1)'!$H$6:$H$99,"") -> 7 | AQ6: =_xlfn.XLOOKUP($B6,'MP (2)'!$B$6:$B$100,'MP (2)'!$H$6:$H$100,"") -> 15 | AR6: =_xlfn.XLOOKUP($B6,'GP1 (1)'!$B$6:$B$100,'GP1 (1)'!$H$6:$H$100,"") | AS6: =_xlfn.XLOOKUP($B6,'GP1 (2)'!$B$6:$B$100,'GP1 (2)'!$H$6:$H$100,"") | AT6: =_xlfn.XLOOKUP($B6,'GP2 (1)'!$B$6:$B$101,'GP2 (1)'!$H$6:$H$101,"") -> 18 | AU6: =_xlfn.XLOOKUP($B6,'GP2 (2)'!$B$6:$B$100,'GP2 (2)'!$H$6:$H$100,"") -> 15 | AV6: =_xlfn.XLOOKUP($B6,'GP3 (1)'!$B$6:$B$100,'GP3 (1)'!$H$6:$H$100,"") -> 8 | AW6: =_xlfn.XLOOKUP($B6,'GP3 (2)'!$B$6:$B$100,'GP3 (2)'!$H$6:$H$100,"") -> 18 | AX6: =_xlfn.XLOOKUP($B6,'GP4 (1)'!$B$6:$B$66,'GP4 (1)'!$H$6:$H$66,"") -> 14 | AY6: =_xlfn.XLOOKUP($B6,'GP4 (2)'!$B$6:$B$100,'GP4 (2)'!$H$6:$H$100,"") -> 17 | AZ6: =_xlfn.XLOOKUP($B6,'GP5 (1)'!$B$6:$B$99,'GP5 (1)'!$H$6:$H$99,"") -> 12 | BA6: =_xlfn.XLOOKUP($B6,'GP5 (2)'!$B$6:$B$99,'GP5 (2)'!$H$6:$H$99,"") -> 6 | BB6: =_xlfn.XLOOKUP($B6,'GP6 (1)'!$B$5:$B$99,'GP6 (1)'!$H$5:$H$99,"") -> 10 | BC6: =_xlfn.XLOOKUP($B6,'GP6 (2)'!$B$5:$B$99,'GP6 (2)'!$H$5:$H$99,"") -> 8 | BD6: =_xlfn.XLOOKUP($B6,'GP7 (1)'!$B$6:$B$100,'GP7 (1)'!$H$6:$H$100,"") -> 4 | BE6: =_xlfn.XLOOKUP($B6,'GP7 (2)'!$B$6:$B$100,'GP7 (2)'!$H$6:$H$100,"") -> 16 | BF6: =_xlfn.XLOOKUP($B6,'GP8 (1)'!$B$6:$B$100,'GP8 (1)'!$H$6:$H$100,"") -> 7 | BG6: =_xlfn.XLOOKUP($B6,'GP8 (2)'!$B$6:$B$100,'GP8 (2)'!$H$6:$H$100,"") -> 16
A7: =ROW()-4 -> 3 | B7: SZMIDT Grzegorz | C7: =SUM(D7:U7) -> 8.1 | D7: =_xlfn.XLOOKUP($B7,'MP (1)'!$B$6:$B$99,'MP (1)'!$E$6:$E$99,"") -> 1 | E7: =_xlfn.XLOOKUP($B7,'MP (2)'!$B$6:$B$100,'MP (2)'!$E$6:$E$100,"") -> 1 | F7: =_xlfn.XLOOKUP($B7,'GP1 (1)'!$B$6:$B$100,'GP1 (1)'!$E$6:$E$100,"") -> 1 | G7: =_xlfn.XLOOKUP($B7,'GP1 (2)'!$B$6:$B$100,'GP1 (2)'!$E$6:$E$100,"") -> 0.8 | H7: =_xlfn.XLOOKUP($B7,'GP2 (1)'!$B$6:$B$101,'GP2 (1)'!$E$6:$E$101,"") -> 1 | I7: =_xlfn.XLOOKUP($B7,'GP2 (2)'!$B$6:$B$100,'GP2 (2)'!$E$6:$E$100,"") -> 0.8 | J7: =_xlfn.XLOOKUP($B7,'GP3 (1)'!$B$6:$B$100,'GP3 (1)'!$E$6:$E$100,"") -> 0.83 | K7: =_xlfn.XLOOKUP($B7,'GP3 (2)'!$B$6:$B$100,'GP3 (2)'!$E$6:$E$100,"") -> 0.80 | L7: =_xlfn.XLOOKUP($B7,'GP4 (1)'!$B$6:$B$66,'GP4 (1)'!$E$6:$E$66,"") -> 1 | M7: =_xlfn.XLOOKUP($B7,'GP4 (2)'!$B$6:$B$100,'GP4 (2)'!$E$6:$E$100,"") -> 0.67 | N7: =_xlfn.XLOOKUP($B7,'GP5 (1)'!$B$6:$B$99,'GP5 (1)'!$E$6:$E$99,"") | O7: =_xlfn.XLOOKUP($B7,'GP5 (2)'!$B$6:$B$99,'GP5 (2)'!$E$6:$E$99,"") | P7: =_xlfn.XLOOKUP($B7,'GP6 (1)'!$B$5:$B$99,'GP6 (1)'!$E$5:$E$99,"") -> 0.80 | Q7: =_xlfn.XLOOKUP($B7,'GP6 (2)'!$B$5:$B$99,'GP6 (2)'!$E$5:$E$99,"") -> 1.00 | R7: =_xlfn.XLOOKUP($B7,'GP7 (1)'!$B$6:$B$100,'GP7 (1)'!$E$6:$E$100,"") | S7: =_xlfn.XLOOKUP($B7,'GP7 (2)'!$B$6:$B$100,'GP7 (2)'!$E$6:$E$100,"") | T7: =_xlfn.XLOOKUP($B7,'GP8 (1)'!$B$6:$B$100,'GP8 (1)'!$E$6:$E$100,"") | U7: =_xlfn.XLOOKUP($B7,'GP8 (2)'!$B$6:$B$100,'GP8 (2)'!$E$6:$E$100,"") | V7: =SUM(W7:AN7) -> 302 | W7: =_xlfn.XLOOKUP($B7,'MP (1)'!$B$6:$B$99,'MP (1)'!$F$6:$F$99,"") -> 29 | X7: =_xlfn.XLOOKUP($B7,'MP (2)'!$B$6:$B$100,'MP (2)'!$F$6:$F$100,"") -> 30 | Y7: =_xlfn.XLOOKUP($B7,'GP1 (1)'!$B$6:$B$100,'GP1 (1)'!$F$6:$F$100,"") -> 24 | Z7: =_xlfn.XLOOKUP($B7,'GP1 (2)'!$B$6:$B$100,'GP1 (2)'!$F$6:$F$100,"") -> 21 | AA7: =_xlfn.XLOOKUP($B7,'GP2 (1)'!$B$6:$B$101,'GP2 (1)'!$F$6:$F$101,"") -> 25 | AB7: =_xlfn.XLOOKUP($B7,'GP2 (2)'!$B$6:$B$100,'GP2 (2)'!$F$6:$F$100,"") -> 23 | AC7: =_xlfn.XLOOKUP($B7,'GP3 (1)'!$B$6:$B$100,'GP3 (1)'!$F$6:$F$100,"") -> 29 | AD7: =_xlfn.XLOOKUP($B7,'GP3 (2)'!$B$6:$B$100,'GP3 (2)'!$F$6:$F$100,"") -> 23 | AE7: =_xlfn.XLOOKUP($B7,'GP4 (1)'!$B$6:$B$66,'GP4 (1)'!$F$6:$F$66,"") -> 29 | AF7: =_xlfn.XLOOKUP($B7,'GP4 (2)'!$B$6:$B$100,'GP4 (2)'!$F$6:$F$100,"") -> 26 | AG7: =_xlfn.XLOOKUP($B7,'GP5 (1)'!$B$6:$B$99,'GP5 (1)'!$F$6:$F$99,"") | AH7: =_xlfn.XLOOKUP($B7,'GP5 (2)'!$B$6:$B$99,'GP5 (2)'!$F$6:$F$99,"") | AI7: =_xlfn.XLOOKUP($B7,'GP6 (1)'!$B$5:$B$99,'GP6 (1)'!$F$5:$F$99,"") -> 23 | AJ7: =_xlfn.XLOOKUP($B7,'GP6 (2)'!$B$5:$B$99,'GP6 (2)'!$F$5:$F$99,"") -> 20 | AK7: =_xlfn.XLOOKUP($B7,'GP7 (1)'!$B$6:$B$100,'GP7 (1)'!$F$6:$F$100,"") | AL7: =_xlfn.XLOOKUP($B7,'GP7 (2)'!$B$6:$B$100,'GP7 (2)'!$F$6:$F$100,"") | AM7: =_xlfn.XLOOKUP($B7,'GP8 (1)'!$B$6:$B$100,'GP8 (1)'!$F$6:$F$100,"") | AN7: =_xlfn.XLOOKUP($B7,'GP8 (2)'!$B$6:$B$100,'GP8 (2)'!$F$6:$F$100,"") | AO7: =SUM(AP7:BG7) -> 194 | AP7: =_xlfn.XLOOKUP($B7,'MP (1)'!$B$6:$B$99,'MP (1)'!$H$6:$H$99,"") -> 20 | AQ7: =_xlfn.XLOOKUP($B7,'MP (2)'!$B$6:$B$100,'MP (2)'!$H$6:$H$100,"") -> 25 | AR7: =_xlfn.XLOOKUP($B7,'GP1 (1)'!$B$6:$B$100,'GP1 (1)'!$H$6:$H$100,"") -> 17 | AS7: =_xlfn.XLOOKUP($B7,'GP1 (2)'!$B$6:$B$100,'GP1 (2)'!$H$6:$H$100,"") -> 13 | AT7: =_xlfn.XLOOKUP($B7,'GP2 (1)'!$B$6:$B$101,'GP2 (1)'!$H$6:$H$101,"") -> 18 | AU7: =_xlfn.XLOOKUP($B7,'GP2 (2)'!$B$6:$B$100,'GP2 (2)'!$H$6:$H$100,"") -> 7 | AV7: =_xlfn.XLOOKUP($B7,'GP3 (1)'!$B$6:$B$100,'GP3 (1)'!$H$6:$H$100,"") -> 18 | AW7: =_xlfn.XLOOKUP($B7,'GP3 (2)'!$B$6:$B$100,'GP3 (2)'!$H$6:$H$100,"") -> 15 | AX7: =_xlfn.XLOOKUP($B7,'GP4 (1)'!$B$6:$B$66,'GP4 (1)'!$H$6:$H$66,"") -> 18 | AY7: =_xlfn.XLOOKUP($B7,'GP4 (2)'!$B$6:$B$100,'GP4 (2)'!$H$6:$H$100,"") -> 13 | AZ7: =_xlfn.XLOOKUP($B7,'GP5 (1)'!$B$6:$B$99,'GP5 (1)'!$H$6:$H$99,"") | BA7: =_xlfn.XLOOKUP($B7,'GP5 (2)'!$B$6:$B$99,'GP5 (2)'!$H$6:$H$99,"") | BB7: =_xlfn.XLOOKUP($B7,'GP6 (1)'!$B$5:$B$99,'GP6 (1)'!$H$5:$H$99,"") -> 16 | BC7: =_xlfn.XLOOKUP($B7,'GP6 (2)'!$B$5:$B$99,'GP6 (2)'!$H$5:$H$99,"") -> 14 | BD7: =_xlfn.XLOOKUP($B7,'GP7 (1)'!$B$6:$B$100,'GP7 (1)'!$H$6:$H$100,"") | BE7: =_xlfn.XLOOKUP($B7,'GP7 (2)'!$B$6:$B$100,'GP7 (2)'!$H$6:$H$100,"") | BF7: =_xlfn.XLOOKUP($B7,'GP8 (1)'!$B$6:$B$100,'GP8 (1)'!$H$6:$H$100,"") | BG7: =_xlfn.XLOOKUP($B7,'GP8 (2)'!$B$6:$B$100,'GP8 (2)'!$H$6:$H$100,"")
A8: =ROW()-4 -> 4 | B8: HAŚKO Sergiusz | C8: =SUM(D8:U8) -> 7.81 | D8: =_xlfn.XLOOKUP($B8,'MP (1)'!$B$6:$B$99,'MP (1)'!$E$6:$E$99,"") -> 0.83 | E8: =_xlfn.XLOOKUP($B8,'MP (2)'!$B$6:$B$100,'MP (2)'!$E$6:$E$100,"") -> 0.8 | F8: =_xlfn.XLOOKUP($B8,'GP1 (1)'!$B$6:$B$100,'GP1 (1)'!$E$6:$E$100,"") | G8: =_xlfn.XLOOKUP($B8,'GP1 (2)'!$B$6:$B$100,'GP1 (2)'!$E$6:$E$100,"") | H8: =_xlfn.XLOOKUP($B8,'GP2 (1)'!$B$6:$B$101,'GP2 (1)'!$E$6:$E$101,"") -> 0.6 | I8: =_xlfn.XLOOKUP($B8,'GP2 (2)'!$B$6:$B$100,'GP2 (2)'!$E$6:$E$100,"") -> 1 | J8: =_xlfn.XLOOKUP($B8,'GP3 (1)'!$B$6:$B$100,'GP3 (1)'!$E$6:$E$100,"") -> 0.6 | K8: =_xlfn.XLOOKUP($B8,'GP3 (2)'!$B$6:$B$100,'GP3 (2)'!$E$6:$E$100,"") -> 0.80 | L8: =_xlfn.XLOOKUP($B8,'GP4 (1)'!$B$6:$B$66,'GP4 (1)'!$E$6:$E$66,"") -> 0.83 | M8: =_xlfn.XLOOKUP($B8,'GP4 (2)'!$B$6:$B$100,'GP4 (2)'!$E$6:$E$100,"") -> 0.8 | N8: =_xlfn.XLOOKUP($B8,'GP5 (1)'!$B$6:$B$99,'GP5 (1)'!$E$6:$E$99,"") -> 1 | O8: =_xlfn.XLOOKUP($B8,'GP5 (2)'!$B$6:$B$99,'GP5 (2)'!$E$6:$E$99,"") -> 0.75 | P8: =_xlfn.XLOOKUP($B8,'GP6 (1)'!$B$5:$B$99,'GP6 (1)'!$E$5:$E$99,"") -> 0.50 | Q8: =_xlfn.XLOOKUP($B8,'GP6 (2)'!$B$5:$B$99,'GP6 (2)'!$E$5:$E$99,"") -> 0.60 | R8: =_xlfn.XLOOKUP($B8,'GP7 (1)'!$B$6:$B$100,'GP7 (1)'!$E$6:$E$100,"") | S8: =_xlfn.XLOOKUP($B8,'GP7 (2)'!$B$6:$B$100,'GP7 (2)'!$E$6:$E$100,"") | T8: =_xlfn.XLOOKUP($B8,'GP8 (1)'!$B$6:$B$100,'GP8 (1)'!$E$6:$E$100,"") -> 1.00 | U8: =_xlfn.XLOOKUP($B8,'GP8 (2)'!$B$6:$B$100,'GP8 (2)'!$E$6:$E$100,"") -> 0.6 | V8: =SUM(W8:AN8) -> 300 | W8: =_xlfn.XLOOKUP($B8,'MP (1)'!$B$6:$B$99,'MP (1)'!$F$6:$F$99,"") -> 27 | X8: =_xlfn.XLOOKUP($B8,'MP (2)'!$B$6:$B$100,'MP (2)'!$F$6:$F$100,"") -> 21 | Y8: =_xlfn.XLOOKUP($B8,'GP1 (1)'!$B$6:$B$100,'GP1 (1)'!$F$6:$F$100,"") | Z8: =_xlfn.XLOOKUP($B8,'GP1 (2)'!$B$6:$B$100,'GP1 (2)'!$F$6:$F$100,"") | AA8: =_xlfn.XLOOKUP($B8,'GP2 (1)'!$B$6:$B$101,'GP2 (1)'!$F$6:$F$101,"") -> 17 | AB8: =_xlfn.XLOOKUP($B8,'GP2 (2)'!$B$6:$B$100,'GP2 (2)'!$F$6:$F$100,"") -> 25 | AC8: =_xlfn.XLOOKUP($B8,'GP3 (1)'!$B$6:$B$100,'GP3 (1)'!$F$6:$F$100,"") -> 19 | AD8: =_xlfn.XLOOKUP($B8,'GP3 (2)'!$B$6:$B$100,'GP3 (2)'!$F$6:$F$100,"") -> 23 | AE8: =_xlfn.XLOOKUP($B8,'GP4 (1)'!$B$6:$B$66,'GP4 (1)'!$F$6:$F$66,"") -> 29 | AF8: =_xlfn.XLOOKUP($B8,'GP4 (2)'!$B$6:$B$100,'GP4 (2)'!$F$6:$F$100,"") -> 22 | AG8: =_xlfn.XLOOKUP($B8,'GP5 (1)'!$B$6:$B$99,'GP5 (1)'!$F$6:$F$99,"") -> 20 | AH8: =_xlfn.XLOOKUP($B8,'GP5 (2)'!$B$6:$B$99,'GP5 (2)'!$F$6:$F$99,"") -> 16 | AI8: =_xlfn.XLOOKUP($B8,'GP6 (1)'!$B$5:$B$99,'GP6 (1)'!$F$5:$F$99,"") -> 17 | AJ8: =_xlfn.XLOOKUP($B8,'GP6 (2)'!$B$5:$B$99,'GP6 (2)'!$F$5:$F$99,"") -> 23 | AK8: =_xlfn.XLOOKUP($B8,'GP7 (1)'!$B$6:$B$100,'GP7 (1)'!$F$6:$F$100,"") | AL8: =_xlfn.XLOOKUP($B8,'GP7 (2)'!$B$6:$B$100,'GP7 (2)'!$F$6:$F$100,"") | AM8: =_xlfn.XLOOKUP($B8,'GP8 (1)'!$B$6:$B$100,'GP8 (1)'!$F$6:$F$100,"") -> 20 | AN8: =_xlfn.XLOOKUP($B8,'GP8 (2)'!$B$6:$B$100,'GP8 (2)'!$F$6:$F$100,"") -> 21 | AO8: =SUM(AP8:BG8) -> 128 | AP8: =_xlfn.XLOOKUP($B8,'MP (1)'!$B$6:$B$99,'MP (1)'!$H$6:$H$99,"") -> 15 | AQ8: =_xlfn.XLOOKUP($B8,'MP (2)'!$B$6:$B$100,'MP (2)'!$H$6:$H$100,"") -> 12 | AR8: =_xlfn.XLOOKUP($B8,'GP1 (1)'!$B$6:$B$100,'GP1 (1)'!$H$6:$H$100,"") | AS8: =_xlfn.XLOOKUP($B8,'GP1 (2)'!$B$6:$B$100,'GP1 (2)'!$H$6:$H$100,"") | AT8: =_xlfn.XLOOKUP($B8,'GP2 (1)'!$B$6:$B$101,'GP2 (1)'!$H$6:$H$101,"") -> 0 | AU8: =_xlfn.XLOOKUP($B8,'GP2 (2)'!$B$6:$B$100,'GP2 (2)'!$H$6:$H$100,"") -> 15 | AV8: =_xlfn.XLOOKUP($B8,'GP3 (1)'!$B$6:$B$100,'GP3 (1)'!$H$6:$H$100,"") -> 6 | AW8: =_xlfn.XLOOKUP($B8,'GP3 (2)'!$B$6:$B$100,'GP3 (2)'!$H$6:$H$100,"") -> 7 | AX8: =_xlfn.XLOOKUP($B8,'GP4 (1)'!$B$6:$B$66,'GP4 (1)'!$H$6:$H$66,"") -> 14 | AY8: =_xlfn.XLOOKUP($B8,'GP4 (2)'!$B$6:$B$100,'GP4 (2)'!$H$6:$H$100,"") -> 9 | AZ8: =_xlfn.XLOOKUP($B8,'GP5 (1)'!$B$6:$B$99,'GP5 (1)'!$H$6:$H$99,"") -> 12 | BA8: =_xlfn.XLOOKUP($B8,'GP5 (2)'!$B$6:$B$99,'GP5 (2)'!$H$6:$H$99,"") -> 3 | BB8: =_xlfn.XLOOKUP($B8,'GP6 (1)'!$B$5:$B$99,'GP6 (1)'!$H$5:$H$99,"") -> 1 | BC8: =_xlfn.XLOOKUP($B8,'GP6 (2)'!$B$5:$B$99,'GP6 (2)'!$H$5:$H$99,"") -> 9 | BD8: =_xlfn.XLOOKUP($B8,'GP7 (1)'!$B$6:$B$100,'GP7 (1)'!$H$6:$H$100,"") | BE8: =_xlfn.XLOOKUP($B8,'GP7 (2)'!$B$6:$B$100,'GP7 (2)'!$H$6:$H$100,"") | BF8: =_xlfn.XLOOKUP($B8,'GP8 (1)'!$B$6:$B$100,'GP8 (1)'!$H$6:$H$100,"") -> 17 | BG8: =_xlfn.XLOOKUP($B8,'GP8 (2)'!$B$6:$B$100,'GP8 (2)'!$H$6:$H$100,"") -> 8
A9: =ROW()-4 -> 5 | B9: LIPKOWSKA Dominika | C9: =SUM(D9:U9) -> 7.73 | D9: =_xlfn.XLOOKUP($B9,'MP (1)'!$B$6:$B$99,'MP (1)'!$E$6:$E$99,"") -> 0.8 | E9: =_xlfn.XLOOKUP($B9,'MP (2)'!$B$6:$B$100,'MP (2)'!$E$6:$E$100,"") -> 0.8 | F9: =_xlfn.XLOOKUP($B9,'GP1 (1)'!$B$6:$B$100,'GP1 (1)'!$E$6:$E$100,"") -> 0.33 | G9: =_xlfn.XLOOKUP($B9,'GP1 (2)'!$B$6:$B$100,'GP1 (2)'!$E$6:$E$100,"") -> 0.6 | H9: =_xlfn.XLOOKUP($B9,'GP2 (1)'!$B$6:$B$101,'GP2 (1)'!$E$6:$E$101,"") -> 1 | I9: =_xlfn.XLOOKUP($B9,'GP2 (2)'!$B$6:$B$100,'GP2 (2)'!$E$6:$E$100,"") -> 1 | J9: =_xlfn.XLOOKUP($B9,'GP3 (1)'!$B$6:$B$100,'GP3 (1)'!$E$6:$E$100,"") | K9: =_xlfn.XLOOKUP($B9,'GP3 (2)'!$B$6:$B$100,'GP3 (2)'!$E$6:$E$100,"") | L9: =_xlfn.XLOOKUP($B9,'GP4 (1)'!$B$6:$B$66,'GP4 (1)'!$E$6:$E$66,"") -> 0.6 | M9: =_xlfn.XLOOKUP($B9,'GP4 (2)'!$B$6:$B$100,'GP4 (2)'!$E$6:$E$100,"") -> 0.4 | N9: =_xlfn.XLOOKUP($B9,'GP5 (1)'!$B$6:$B$99,'GP5 (1)'!$E$6:$E$99,"") -> 1 | O9: =_xlfn.XLOOKUP($B9,'GP5 (2)'!$B$6:$B$99,'GP5 (2)'!$E$6:$E$99,"") -> 0.6 | P9: =_xlfn.XLOOKUP($B9,'GP6 (1)'!$B$5:$B$99,'GP6 (1)'!$E$5:$E$99,"") | Q9: =_xlfn.XLOOKUP($B9,'GP6 (2)'!$B$5:$B$99,'GP6 (2)'!$E$5:$E$99,"") | R9: =_xlfn.XLOOKUP($B9,'GP7 (1)'!$B$6:$B$100,'GP7 (1)'!$E$6:$E$100,"") -> 1.00 | S9: =_xlfn.XLOOKUP($B9,'GP7 (2)'!$B$6:$B$100,'GP7 (2)'!$E$6:$E$100,"") -> 0.6 | T9: =_xlfn.XLOOKUP($B9,'GP8 (1)'!$B$6:$B$100,'GP8 (1)'!$E$6:$E$100,"") | U9: =_xlfn.XLOOKUP($B9,'GP8 (2)'!$B$6:$B$100,'GP8 (2)'!$E$6:$E$100,"") | V9: =SUM(W9:AN9) -> 255 | W9: =_xlfn.XLOOKUP($B9,'MP (1)'!$B$6:$B$99,'MP (1)'!$F$6:$F$99,"") -> 23 | X9: =_xlfn.XLOOKUP($B9,'MP (2)'!$B$6:$B$100,'MP (2)'!$F$6:$F$100,"") -> 21 | Y9: =_xlfn.XLOOKUP($B9,'GP1 (1)'!$B$6:$B$100,'GP1 (1)'!$F$6:$F$100,"") -> 21 | Z9: =_xlfn.XLOOKUP($B9,'GP1 (2)'!$B$6:$B$100,'GP1 (2)'!$F$6:$F$100,"") -> 16 | AA9: =_xlfn.XLOOKUP($B9,'GP2 (1)'!$B$6:$B$101,'GP2 (1)'!$F$6:$F$101,"") -> 25 | AB9: =_xlfn.XLOOKUP($B9,'GP2 (2)'!$B$6:$B$100,'GP2 (2)'!$F$6:$F$100,"") -> 25 | AC9: =_xlfn.XLOOKUP($B9,'GP3 (1)'!$B$6:$B$100,'GP3 (1)'!$F$6:$F$100,"") | AD9: =_xlfn.XLOOKUP($B9,'GP3 (2)'!$B$6:$B$100,'GP3 (2)'!$F$6:$F$100,"") | AE9: =_xlfn.XLOOKUP($B9,'GP4 (1)'!$B$6:$B$66,'GP4 (1)'!$F$6:$F$66,"") -> 20 | AF9: =_xlfn.XLOOKUP($B9,'GP4 (2)'!$B$6:$B$100,'GP4 (2)'!$F$6:$F$100,"") -> 15 | AG9: =_xlfn.XLOOKUP($B9,'GP5 (1)'!$B$6:$B$99,'GP5 (1)'!$F$6:$F$99,"") -> 25 | AH9: =_xlfn.XLOOKUP($B9,'GP5 (2)'!$B$6:$B$99,'GP5 (2)'!$F$6:$F$99,"") -> 21 | AI9: =_xlfn.XLOOKUP($B9,'GP6 (1)'!$B$5:$B$99,'GP6 (1)'!$F$5:$F$99,"") | AJ9: =_xlfn.XLOOKUP($B9,'GP6 (2)'!$B$5:$B$99,'GP6 (2)'!$F$5:$F$99,"") | AK9: =_xlfn.XLOOKUP($B9,'GP7 (1)'!$B$6:$B$100,'GP7 (1)'!$F$6:$F$100,"") -> 20 | AL9: =_xlfn.XLOOKUP($B9,'GP7 (2)'!$B$6:$B$100,'GP7 (2)'!$F$6:$F$100,"") -> 23 | AM9: =_xlfn.XLOOKUP($B9,'GP8 (1)'!$B$6:$B$100,'GP8 (1)'!$F$6:$F$100,"") | AN9: =_xlfn.XLOOKUP($B9,'GP8 (2)'!$B$6:$B$100,'GP8 (2)'!$F$6:$F$100,"") | AO9: =SUM(AP9:BG9) -> 83 | AP9: =_xlfn.XLOOKUP($B9,'MP (1)'!$B$6:$B$99,'MP (1)'!$H$6:$H$99,"") -> 8 | AQ9: =_xlfn.XLOOKUP($B9,'MP (2)'!$B$6:$B$100,'MP (2)'!$H$6:$H$100,"") -> 9 | AR9: =_xlfn.XLOOKUP($B9,'GP1 (1)'!$B$6:$B$100,'GP1 (1)'!$H$6:$H$100,"") -> -3 | AS9: =_xlfn.XLOOKUP($B9,'GP1 (2)'!$B$6:$B$100,'GP1 (2)'!$H$6:$H$100,"") -> -2 | AT9: =_xlfn.XLOOKUP($B9,'GP2 (1)'!$B$6:$B$101,'GP2 (1)'!$H$6:$H$101,"") -> 12 | AU9: =_xlfn.XLOOKUP($B9,'GP2 (2)'!$B$6:$B$100,'GP2 (2)'!$H$6:$H$100,"") -> 14 | AV9: =_xlfn.XLOOKUP($B9,'GP3 (1)'!$B$6:$B$100,'GP3 (1)'!$H$6:$H$100,"") | AW9: =_xlfn.XLOOKUP($B9,'GP3 (2)'!$B$6:$B$100,'GP3 (2)'!$H$6:$H$100,"") | AX9: =_xlfn.XLOOKUP($B9,'GP4 (1)'!$B$6:$B$66,'GP4 (1)'!$H$6:$H$66,"") -> 3 | AY9: =_xlfn.XLOOKUP($B9,'GP4 (2)'!$B$6:$B$100,'GP4 (2)'!$H$6:$H$100,"") -> 0 | AZ9: =_xlfn.XLOOKUP($B9,'GP5 (1)'!$B$6:$B$99,'GP5 (1)'!$H$6:$H$99,"") -> 15 | BA9: =_xlfn.XLOOKUP($B9,'GP5 (2)'!$B$6:$B$99,'GP5 (2)'!$H$6:$H$99,"") -> 8 | BB9: =_xlfn.XLOOKUP($B9,'GP6 (1)'!$B$5:$B$99,'GP6 (1)'!$H$5:$H$99,"") | BC9: =_xlfn.XLOOKUP($B9,'GP6 (2)'!$B$5:$B$99,'GP6 (2)'!$H$5:$H$99,"") | BD9: =_xlfn.XLOOKUP($B9,'GP7 (1)'!$B$6:$B$100,'GP7 (1)'!$H$6:$H$100,"") -> 12 | BE9: =_xlfn.XLOOKUP($B9,'GP7 (2)'!$B$6:$B$100,'GP7 (2)'!$H$6:$H$100,"") -> 7 | BF9: =_xlfn.XLOOKUP($B9,'GP8 (1)'!$B$6:$B$100,'GP8 (1)'!$H$6:$H$100,"") | BG9: =_xlfn.XLOOKUP($B9,'GP8 (2)'!$B$6:$B$100,'GP8 (2)'!$H$6:$H$100,"")
A10: =ROW()-4 -> 6 | B10: JADCZUK Wojciech | C10: =SUM(D10:U10) -> 7.26 | D10: =_xlfn.XLOOKUP($B10,'MP (1)'!$B$6:$B$99,'MP (1)'!$E$6:$E$99,"") -> 0.83 | E10: =_xlfn.XLOOKUP($B10,'MP (2)'!$B$6:$B$100,'MP (2)'!$E$6:$E$100,"") -> 0.5 | F10: =_xlfn.XLOOKUP($B10,'GP1 (1)'!$B$6:$B$100,'GP1 (1)'!$E$6:$E$100,"") -> 0.83 | G10: =_xlfn.XLOOKUP($B10,'GP1 (2)'!$B$6:$B$100,'GP1 (2)'!$E$6:$E$100,"") -> 1 | H10: =_xlfn.XLOOKUP($B10,'GP2 (1)'!$B$6:$B$101,'GP2 (1)'!$E$6:$E$101,"") -> 1 | I10: =_xlfn.XLOOKUP($B10,'GP2 (2)'!$B$6:$B$100,'GP2 (2)'!$E$6:$E$100,"") -> 0.6 | J10: =_xlfn.XLOOKUP($B10,'GP3 (1)'!$B$6:$B$100,'GP3 (1)'!$E$6:$E$100,"") -> 1 | K10: =_xlfn.XLOOKUP($B10,'GP3 (2)'!$B$6:$B$100,'GP3 (2)'!$E$6:$E$100,"") -> 0.80 | L10: =_xlfn.XLOOKUP($B10,'GP4 (1)'!$B$6:$B$66,'GP4 (1)'!$E$6:$E$66,"") | M10: =_xlfn.XLOOKUP($B10,'GP4 (2)'!$B$6:$B$100,'GP4 (2)'!$E$6:$E$100,"") | N10: =_xlfn.XLOOKUP($B10,'GP5 (1)'!$B$6:$B$99,'GP5 (1)'!$E$6:$E$99,"") | O10: =_xlfn.XLOOKUP($B10,'GP5 (2)'!$B$6:$B$99,'GP5 (2)'!$E$6:$E$99,"") | P10: =_xlfn.XLOOKUP($B10,'GP6 (1)'!$B$5:$B$99,'GP6 (1)'!$E$5:$E$99,"") -> 0.75 | Q10: =_xlfn.XLOOKUP($B10,'GP6 (2)'!$B$5:$B$99,'GP6 (2)'!$E$5:$E$99,"") -> 1.00 | R10: =_xlfn.XLOOKUP($B10,'GP7 (1)'!$B$6:$B$100,'GP7 (1)'!$E$6:$E$100,"") -> 0.50 | S10: =_xlfn.XLOOKUP($B10,'GP7 (2)'!$B$6:$B$100,'GP7 (2)'!$E$6:$E$100,"") -> 0.5 | T10: =_xlfn.XLOOKUP($B10,'GP8 (1)'!$B$6:$B$100,'GP8 (1)'!$E$6:$E$100,"") -> 0.80 | U10: =_xlfn.XLOOKUP($B10,'GP8 (2)'!$B$6:$B$100,'GP8 (2)'!$E$6:$E$100,"") -> 1 | V10: =SUM(W10:AN10) -> 311 | W10: =_xlfn.XLOOKUP($B10,'MP (1)'!$B$6:$B$99,'MP (1)'!$F$6:$F$99,"") -> 29 | X10: =_xlfn.XLOOKUP($B10,'MP (2)'!$B$6:$B$100,'MP (2)'!$F$6:$F$100,"") -> 23 | Y10: =_xlfn.XLOOKUP($B10,'GP1 (1)'!$B$6:$B$100,'GP1 (1)'!$F$6:$F$100,"") -> 27 | Z10: =_xlfn.XLOOKUP($B10,'GP1 (2)'!$B$6:$B$100,'GP1 (2)'!$F$6:$F$100,"") -> 25 | AA10: =_xlfn.XLOOKUP($B10,'GP2 (1)'!$B$6:$B$101,'GP2 (1)'!$F$6:$F$101,"") -> 25 | AB10: =_xlfn.XLOOKUP($B10,'GP2 (2)'!$B$6:$B$100,'GP2 (2)'!$F$6:$F$100,"") -> 21 | AC10: =_xlfn.XLOOKUP($B10,'GP3 (1)'!$B$6:$B$100,'GP3 (1)'!$F$6:$F$100,"") -> 25 | AD10: =_xlfn.XLOOKUP($B10,'GP3 (2)'!$B$6:$B$100,'GP3 (2)'!$F$6:$F$100,"") -> 22 | AE10: =_xlfn.XLOOKUP($B10,'GP4 (1)'!$B$6:$B$66,'GP4 (1)'!$F$6:$F$66,"") | AF10: =_xlfn.XLOOKUP($B10,'GP4 (2)'!$B$6:$B$100,'GP4 (2)'!$F$6:$F$100,"") | AG10: =_xlfn.XLOOKUP($B10,'GP5 (1)'!$B$6:$B$99,'GP5 (1)'!$F$6:$F$99,"") | AH10: =_xlfn.XLOOKUP($B10,'GP5 (2)'!$B$6:$B$99,'GP5 (2)'!$F$6:$F$99,"") | AI10: =_xlfn.XLOOKUP($B10,'GP6 (1)'!$B$5:$B$99,'GP6 (1)'!$F$5:$F$99,"") -> 19 | AJ10: =_xlfn.XLOOKUP($B10,'GP6 (2)'!$B$5:$B$99,'GP6 (2)'!$F$5:$F$99,"") -> 20 | AK10: =_xlfn.XLOOKUP($B10,'GP7 (1)'!$B$6:$B$100,'GP7 (1)'!$F$6:$F$100,"") -> 15 | AL10: =_xlfn.XLOOKUP($B10,'GP7 (2)'!$B$6:$B$100,'GP7 (2)'!$F$6:$F$100,"") -> 17 | AM10: =_xlfn.XLOOKUP($B10,'GP8 (1)'!$B$6:$B$100,'GP8 (1)'!$F$6:$F$100,"") -> 23 | AN10: =_xlfn.XLOOKUP($B10,'GP8 (2)'!$B$6:$B$100,'GP8 (2)'!$F$6:$F$100,"") -> 20 | AO10: =SUM(AP10:BG10) -> 156 | AP10: =_xlfn.XLOOKUP($B10,'MP (1)'!$B$6:$B$99,'MP (1)'!$H$6:$H$99,"") -> 17 | AQ10: =_xlfn.XLOOKUP($B10,'MP (2)'!$B$6:$B$100,'MP (2)'!$H$6:$H$100,"") -> 5 | AR10: =_xlfn.XLOOKUP($B10,'GP1 (1)'!$B$6:$B$100,'GP1 (1)'!$H$6:$H$100,"") -> 13 | AS10: =_xlfn.XLOOKUP($B10,'GP1 (2)'!$B$6:$B$100,'GP1 (2)'!$H$6:$H$100,"") -> 21 | AT10: =_xlfn.XLOOKUP($B10,'GP2 (1)'!$B$6:$B$101,'GP2 (1)'!$H$6:$H$101,"") -> 14 | AU10: =_xlfn.XLOOKUP($B10,'GP2 (2)'!$B$6:$B$100,'GP2 (2)'!$H$6:$H$100,"") -> 7 | AV10: =_xlfn.XLOOKUP($B10,'GP3 (1)'!$B$6:$B$100,'GP3 (1)'!$H$6:$H$100,"") -> 15 | AW10: =_xlfn.XLOOKUP($B10,'GP3 (2)'!$B$6:$B$100,'GP3 (2)'!$H$6:$H$100,"") -> 10 | AX10: =_xlfn.XLOOKUP($B10,'GP4 (1)'!$B$6:$B$66,'GP4 (1)'!$H$6:$H$66,"") | AY10: =_xlfn.XLOOKUP($B10,'GP4 (2)'!$B$6:$B$100,'GP4 (2)'!$H$6:$H$100,"") | AZ10: =_xlfn.XLOOKUP($B10,'GP5 (1)'!$B$6:$B$99,'GP5 (1)'!$H$6:$H$99,"") | BA10: =_xlfn.XLOOKUP($B10,'GP5 (2)'!$B$6:$B$99,'GP5 (2)'!$H$6:$H$99,"") | BB10: =_xlfn.XLOOKUP($B10,'GP6 (1)'!$B$5:$B$99,'GP6 (1)'!$H$5:$H$99,"") -> 8 | BC10: =_xlfn.XLOOKUP($B10,'GP6 (2)'!$B$5:$B$99,'GP6 (2)'!$H$5:$H$99,"") -> 14 | BD10: =_xlfn.XLOOKUP($B10,'GP7 (1)'!$B$6:$B$100,'GP7 (1)'!$H$6:$H$100,"") -> -1 | BE10: =_xlfn.XLOOKUP($B10,'GP7 (2)'!$B$6:$B$100,'GP7 (2)'!$H$6:$H$100,"") -> 3 | BF10: =_xlfn.XLOOKUP($B10,'GP8 (1)'!$B$6:$B$100,'GP8 (1)'!$H$6:$H$100,"") -> 14 | BG10: =_xlfn.XLOOKUP($B10,'GP8 (2)'!$B$6:$B$100,'GP8 (2)'!$H$6:$H$100,"") -> 16
A11: =ROW()-4 -> 7 | B11: KORONA-TRZEBSKI Przemysław | C11: =SUM(D11:U11) -> 6.93 | D11: =_xlfn.XLOOKUP($B11,'MP (1)'!$B$6:$B$99,'MP (1)'!$E$6:$E$99,"") -> 0.67 | E11: =_xlfn.XLOOKUP($B11,'MP (2)'!$B$6:$B$100,'MP (2)'!$E$6:$E$100,"") -> 0.83 | F11: =_xlfn.XLOOKUP($B11,'GP1 (1)'!$B$6:$B$100,'GP1 (1)'!$E$6:$E$100,"") -> 0.6 | G11: =_xlfn.XLOOKUP($B11,'GP1 (2)'!$B$6:$B$100,'GP1 (2)'!$E$6:$E$100,"") -> 0.8 | H11: =_xlfn.XLOOKUP($B11,'GP2 (1)'!$B$6:$B$101,'GP2 (1)'!$E$6:$E$101,"") -> 0.8 | I11: =_xlfn.XLOOKUP($B11,'GP2 (2)'!$B$6:$B$100,'GP2 (2)'!$E$6:$E$100,"") -> 1 | J11: =_xlfn.XLOOKUP($B11,'GP3 (1)'!$B$6:$B$100,'GP3 (1)'!$E$6:$E$100,"") -> 0.83 | K11: =_xlfn.XLOOKUP($B11,'GP3 (2)'!$B$6:$B$100,'GP3 (2)'!$E$6:$E$100,"") -> 0.60 | L11: =_xlfn.XLOOKUP($B11,'GP4 (1)'!$B$6:$B$66,'GP4 (1)'!$E$6:$E$66,"") | M11: =_xlfn.XLOOKUP($B11,'GP4 (2)'!$B$6:$B$100,'GP4 (2)'!$E$6:$E$100,"") | N11: =_xlfn.XLOOKUP($B11,'GP5 (1)'!$B$6:$B$99,'GP5 (1)'!$E$6:$E$99,"") | O11: =_xlfn.XLOOKUP($B11,'GP5 (2)'!$B$6:$B$99,'GP5 (2)'!$E$6:$E$99,"") | P11: =_xlfn.XLOOKUP($B11,'GP6 (1)'!$B$5:$B$99,'GP6 (1)'!$E$5:$E$99,"") -> 0.50 | Q11: =_xlfn.XLOOKUP($B11,'GP6 (2)'!$B$5:$B$99,'GP6 (2)'!$E$5:$E$99,"") -> 0.50 | R11: =_xlfn.XLOOKUP($B11,'GP7 (1)'!$B$6:$B$100,'GP7 (1)'!$E$6:$E$100,"") -> 0.75 | S11: =_xlfn.XLOOKUP($B11,'GP7 (2)'!$B$6:$B$100,'GP7 (2)'!$E$6:$E$100,"") -> 0.6 | T11: =_xlfn.XLOOKUP($B11,'GP8 (1)'!$B$6:$B$100,'GP8 (1)'!$E$6:$E$100,"") -> 0.60 | U11: =_xlfn.XLOOKUP($B11,'GP8 (2)'!$B$6:$B$100,'GP8 (2)'!$E$6:$E$100,"") -> 0.8 | V11: =SUM(W11:AN11) -> 283 | W11: =_xlfn.XLOOKUP($B11,'MP (1)'!$B$6:$B$99,'MP (1)'!$F$6:$F$99,"") -> 22 | X11: =_xlfn.XLOOKUP($B11,'MP (2)'!$B$6:$B$100,'MP (2)'!$F$6:$F$100,"") -> 25 | Y11: =_xlfn.XLOOKUP($B11,'GP1 (1)'!$B$6:$B$100,'GP1 (1)'!$F$6:$F$100,"") -> 21 | Z11: =_xlfn.XLOOKUP($B11,'GP1 (2)'!$B$6:$B$100,'GP1 (2)'!$F$6:$F$100,"") -> 21 | AA11: =_xlfn.XLOOKUP($B11,'GP2 (1)'!$B$6:$B$101,'GP2 (1)'!$F$6:$F$101,"") -> 23 | AB11: =_xlfn.XLOOKUP($B11,'GP2 (2)'!$B$6:$B$100,'GP2 (2)'!$F$6:$F$100,"") -> 25 | AC11: =_xlfn.XLOOKUP($B11,'GP3 (1)'!$B$6:$B$100,'GP3 (1)'!$F$6:$F$100,"") -> 29 | AD11: =_xlfn.XLOOKUP($B11,'GP3 (2)'!$B$6:$B$100,'GP3 (2)'!$F$6:$F$100,"") -> 20 | AE11: =_xlfn.XLOOKUP($B11,'GP4 (1)'!$B$6:$B$66,'GP4 (1)'!$F$6:$F$66,"") | AF11: =_xlfn.XLOOKUP($B11,'GP4 (2)'!$B$6:$B$100,'GP4 (2)'!$F$6:$F$100,"") | AG11: =_xlfn.XLOOKUP($B11,'GP5 (1)'!$B$6:$B$99,'GP5 (1)'!$F$6:$F$99,"") | AH11: =_xlfn.XLOOKUP($B11,'GP5 (2)'!$B$6:$B$99,'GP5 (2)'!$F$6:$F$99,"") | AI11: =_xlfn.XLOOKUP($B11,'GP6 (1)'!$B$5:$B$99,'GP6 (1)'!$F$5:$F$99,"") -> 11 | AJ11: =_xlfn.XLOOKUP($B11,'GP6 (2)'!$B$5:$B$99,'GP6 (2)'!$F$5:$F$99,"") -> 12 | AK11: =_xlfn.XLOOKUP($B11,'GP7 (1)'!$B$6:$B$100,'GP7 (1)'!$F$6:$F$100,"") -> 18 | AL11: =_xlfn.XLOOKUP($B11,'GP7 (2)'!$B$6:$B$100,'GP7 (2)'!$F$6:$F$100,"") -> 17 | AM11: =_xlfn.XLOOKUP($B11,'GP8 (1)'!$B$6:$B$100,'GP8 (1)'!$F$6:$F$100,"") -> 19 | AN11: =_xlfn.XLOOKUP($B11,'GP8 (2)'!$B$6:$B$100,'GP8 (2)'!$F$6:$F$100,"") -> 20 | AO11: =SUM(AP11:BG11) -> 93 | AP11: =_xlfn.XLOOKUP($B11,'MP (1)'!$B$6:$B$99,'MP (1)'!$H$6:$H$99,"") -> 4 | AQ11: =_xlfn.XLOOKUP($B11,'MP (2)'!$B$6:$B$100,'MP (2)'!$H$6:$H$100,"") -> 12 | AR11: =_xlfn.XLOOKUP($B11,'GP1 (1)'!$B$6:$B$100,'GP1 (1)'!$H$6:$H$100,"") -> 7 | AS11: =_xlfn.XLOOKUP($B11,'GP1 (2)'!$B$6:$B$100,'GP1 (2)'!$H$6:$H$100,"") -> 11 | AT11: =_xlfn.XLOOKUP($B11,'GP2 (1)'!$B$6:$B$101,'GP2 (1)'!$H$6:$H$101,"") -> 12 | AU11: =_xlfn.XLOOKUP($B11,'GP2 (2)'!$B$6:$B$100,'GP2 (2)'!$H$6:$H$100,"") -> 16 | AV11: =_xlfn.XLOOKUP($B11,'GP3 (1)'!$B$6:$B$100,'GP3 (1)'!$H$6:$H$100,"") -> 11 | AW11: =_xlfn.XLOOKUP($B11,'GP3 (2)'!$B$6:$B$100,'GP3 (2)'!$H$6:$H$100,"") -> 6 | AX11: =_xlfn.XLOOKUP($B11,'GP4 (1)'!$B$6:$B$66,'GP4 (1)'!$H$6:$H$66,"") | AY11: =_xlfn.XLOOKUP($B11,'GP4 (2)'!$B$6:$B$100,'GP4 (2)'!$H$6:$H$100,"") | AZ11: =_xlfn.XLOOKUP($B11,'GP5 (1)'!$B$6:$B$99,'GP5 (1)'!$H$6:$H$99,"") | BA11: =_xlfn.XLOOKUP($B11,'GP5 (2)'!$B$6:$B$99,'GP5 (2)'!$H$6:$H$99,"") | BB11: =_xlfn.XLOOKUP($B11,'GP6 (1)'!$B$5:$B$99,'GP6 (1)'!$H$5:$H$99,"") -> -5 | BC11: =_xlfn.XLOOKUP($B11,'GP6 (2)'!$B$5:$B$99,'GP6 (2)'!$H$5:$H$99,"") -> 0 | BD11: =_xlfn.XLOOKUP($B11,'GP7 (1)'!$B$6:$B$100,'GP7 (1)'!$H$6:$H$100,"") -> 6 | BE11: =_xlfn.XLOOKUP($B11,'GP7 (2)'!$B$6:$B$100,'GP7 (2)'!$H$6:$H$100,"") -> 0 | BF11: =_xlfn.XLOOKUP($B11,'GP8 (1)'!$B$6:$B$100,'GP8 (1)'!$H$6:$H$100,"") -> 4 | BG11: =_xlfn.XLOOKUP($B11,'GP8 (2)'!$B$6:$B$100,'GP8 (2)'!$H$6:$H$100,"") -> 9
A12: =ROW()-4 -> 8 | B12: POŚPIESZNY Sławomir | C12: =SUM(D12:U12) -> 6.09 | D12: =_xlfn.XLOOKUP($B12,'MP (1)'!$B$6:$B$99,'MP (1)'!$E$6:$E$99,"") -> 0.67 | E12: =_xlfn.XLOOKUP($B12,'MP (2)'!$B$6:$B$100,'MP (2)'!$E$6:$E$100,"") -> 0.67 | F12: =_xlfn.XLOOKUP($B12,'GP1 (1)'!$B$6:$B$100,'GP1 (1)'!$E$6:$E$100,"") | G12: =_xlfn.XLOOKUP($B12,'GP1 (2)'!$B$6:$B$100,'GP1 (2)'!$E$6:$E$100,"") | H12: =_xlfn.XLOOKUP($B12,'GP2 (1)'!$B$6:$B$101,'GP2 (1)'!$E$6:$E$101,"") -> 0.6 | I12: =_xlfn.XLOOKUP($B12,'GP2 (2)'!$B$6:$B$100,'GP2 (2)'!$E$6:$E$100,"") -> 0.6 | J12: =_xlfn.XLOOKUP($B12,'GP3 (1)'!$B$6:$B$100,'GP3 (1)'!$E$6:$E$100,"") -> 0.4 | K12: =_xlfn.XLOOKUP($B12,'GP3 (2)'!$B$6:$B$100,'GP3 (2)'!$E$6:$E$100,"") -> 0.83 | L12: =_xlfn.XLOOKUP($B12,'GP4 (1)'!$B$6:$B$66,'GP4 (1)'!$E$6:$E$66,"") -> 0.8 | M12: =_xlfn.XLOOKUP($B12,'GP4 (2)'!$B$6:$B$100,'GP4 (2)'!$E$6:$E$100,"") -> 0.8 | N12: =_xlfn.XLOOKUP($B12,'GP5 (1)'!$B$6:$B$99,'GP5 (1)'!$E$6:$E$99,"") -> 0.8 | O12: =_xlfn.XLOOKUP($B12,'GP5 (2)'!$B$6:$B$99,'GP5 (2)'!$E$6:$E$99,"") -> 0.75 | P12: =_xlfn.XLOOKUP($B12,'GP6 (1)'!$B$5:$B$99,'GP6 (1)'!$E$5:$E$99,"") -> 1.00 | Q12: =_xlfn.XLOOKUP($B12,'GP6 (2)'!$B$5:$B$99,'GP6 (2)'!$E$5:$E$99,"") -> 0.50 | R12: =_xlfn.XLOOKUP($B12,'GP7 (1)'!$B$6:$B$100,'GP7 (1)'!$E$6:$E$100,"") | S12: =_xlfn.XLOOKUP($B12,'GP7 (2)'!$B$6:$B$100,'GP7 (2)'!$E$6:$E$100,"") | T12: =_xlfn.XLOOKUP($B12,'GP8 (1)'!$B$6:$B$100,'GP8 (1)'!$E$6:$E$100,"") | U12: =_xlfn.XLOOKUP($B12,'GP8 (2)'!$B$6:$B$100,'GP8 (2)'!$E$6:$E$100,"") | V12: =SUM(W12:AN12) -> 239 | W12: =_xlfn.XLOOKUP($B12,'MP (1)'!$B$6:$B$99,'MP (1)'!$F$6:$F$99,"") -> 24 | X12: =_xlfn.XLOOKUP($B12,'MP (2)'!$B$6:$B$100,'MP (2)'!$F$6:$F$100,"") -> 21 | Y12: =_xlfn.XLOOKUP($B12,'GP1 (1)'!$B$6:$B$100,'GP1 (1)'!$F$6:$F$100,"") | Z12: =_xlfn.XLOOKUP($B12,'GP1 (2)'!$B$6:$B$100,'GP1 (2)'!$F$6:$F$100,"") | AA12: =_xlfn.XLOOKUP($B12,'GP2 (1)'!$B$6:$B$101,'GP2 (1)'!$F$6:$F$101,"") -> 19 | AB12: =_xlfn.XLOOKUP($B12,'GP2 (2)'!$B$6:$B$100,'GP2 (2)'!$F$6:$F$100,"") -> 20 | AC12: =_xlfn.XLOOKUP($B12,'GP3 (1)'!$B$6:$B$100,'GP3 (1)'!$F$6:$F$100,"") -> 13 | AD12: =_xlfn.XLOOKUP($B12,'GP3 (2)'!$B$6:$B$100,'GP3 (2)'!$F$6:$F$100,"") -> 25 | AE12: =_xlfn.XLOOKUP($B12,'GP4 (1)'!$B$6:$B$66,'GP4 (1)'!$F$6:$F$66,"") -> 20 | AF12: =_xlfn.XLOOKUP($B12,'GP4 (2)'!$B$6:$B$100,'GP4 (2)'!$F$6:$F$100,"") -> 22 | AG12: =_xlfn.XLOOKUP($B12,'GP5 (1)'!$B$6:$B$99,'GP5 (1)'!$F$6:$F$99,"") -> 22 | AH12: =_xlfn.XLOOKUP($B12,'GP5 (2)'!$B$6:$B$99,'GP5 (2)'!$F$6:$F$99,"") -> 19 | AI12: =_xlfn.XLOOKUP($B12,'GP6 (1)'!$B$5:$B$99,'GP6 (1)'!$F$5:$F$99,"") -> 19 | AJ12: =_xlfn.XLOOKUP($B12,'GP6 (2)'!$B$5:$B$99,'GP6 (2)'!$F$5:$F$99,"") -> 15 | AK12: =_xlfn.XLOOKUP($B12,'GP7 (1)'!$B$6:$B$100,'GP7 (1)'!$F$6:$F$100,"") | AL12: =_xlfn.XLOOKUP($B12,'GP7 (2)'!$B$6:$B$100,'GP7 (2)'!$F$6:$F$100,"") | AM12: =_xlfn.XLOOKUP($B12,'GP8 (1)'!$B$6:$B$100,'GP8 (1)'!$F$6:$F$100,"") | AN12: =_xlfn.XLOOKUP($B12,'GP8 (2)'!$B$6:$B$100,'GP8 (2)'!$F$6:$F$100,"") | AO12: =SUM(AP12:BG12) -> 86 | AP12: =_xlfn.XLOOKUP($B12,'MP (1)'!$B$6:$B$99,'MP (1)'!$H$6:$H$99,"") -> 10 | AQ12: =_xlfn.XLOOKUP($B12,'MP (2)'!$B$6:$B$100,'MP (2)'!$H$6:$H$100,"") -> 6 | AR12: =_xlfn.XLOOKUP($B12,'GP1 (1)'!$B$6:$B$100,'GP1 (1)'!$H$6:$H$100,"") | AS12: =_xlfn.XLOOKUP($B12,'GP1 (2)'!$B$6:$B$100,'GP1 (2)'!$H$6:$H$100,"") | AT12: =_xlfn.XLOOKUP($B12,'GP2 (1)'!$B$6:$B$101,'GP2 (1)'!$H$6:$H$101,"") -> 6 | AU12: =_xlfn.XLOOKUP($B12,'GP2 (2)'!$B$6:$B$100,'GP2 (2)'!$H$6:$H$100,"") -> 4 | AV12: =_xlfn.XLOOKUP($B12,'GP3 (1)'!$B$6:$B$100,'GP3 (1)'!$H$6:$H$100,"") -> -5 | AW12: =_xlfn.XLOOKUP($B12,'GP3 (2)'!$B$6:$B$100,'GP3 (2)'!$H$6:$H$100,"") -> 11 | AX12: =_xlfn.XLOOKUP($B12,'GP4 (1)'!$B$6:$B$66,'GP4 (1)'!$H$6:$H$66,"") -> 11 | AY12: =_xlfn.XLOOKUP($B12,'GP4 (2)'!$B$6:$B$100,'GP4 (2)'!$H$6:$H$100,"") -> 11 | AZ12: =_xlfn.XLOOKUP($B12,'GP5 (1)'!$B$6:$B$99,'GP5 (1)'!$H$6:$H$99,"") -> 12 | BA12: =_xlfn.XLOOKUP($B12,'GP5 (2)'!$B$6:$B$99,'GP5 (2)'!$H$6:$H$99,"") -> 9 | BB12: =_xlfn.XLOOKUP($B12,'GP6 (1)'!$B$5:$B$99,'GP6 (1)'!$H$5:$H$99,"") -> 12 | BC12: =_xlfn.XLOOKUP($B12,'GP6 (2)'!$B$5:$B$99,'GP6 (2)'!$H$5:$H$99,"") -> -1 | BD12: =_xlfn.XLOOKUP($B12,'GP7 (1)'!$B$6:$B$100,'GP7 (1)'!$H$6:$H$100,"") | BE12: =_xlfn.XLOOKUP($B12,'GP7 (2)'!$B$6:$B$100,'GP7 (2)'!$H$6:$H$100,"") | BF12: =_xlfn.XLOOKUP($B12,'GP8 (1)'!$B$6:$B$100,'GP8 (1)'!$H$6:$H$100,"") | BG12: =_xlfn.XLOOKUP($B12,'GP8 (2)'!$B$6:$B$100,'GP8 (2)'!$H$6:$H$100,"")
A13: =ROW()-4 -> 9 | B13: NIKALAICHUK Aliaksandr | C13: =SUM(D13:U13) -> 5.97 | D13: =_xlfn.XLOOKUP($B13,'MP (1)'!$B$6:$B$99,'MP (1)'!$E$6:$E$99,"") | E13: =_xlfn.XLOOKUP($B13,'MP (2)'!$B$6:$B$100,'MP (2)'!$E$6:$E$100,"") | F13: =_xlfn.XLOOKUP($B13,'GP1 (1)'!$B$6:$B$100,'GP1 (1)'!$E$6:$E$100,"") -> 1 | G13: =_xlfn.XLOOKUP($B13,'GP1 (2)'!$B$6:$B$100,'GP1 (2)'!$E$6:$E$100,"") -> 0.8 | H13: =_xlfn.XLOOKUP($B13,'GP2 (1)'!$B$6:$B$101,'GP2 (1)'!$E$6:$E$101,"") -> 0.6 | I13: =_xlfn.XLOOKUP($B13,'GP2 (2)'!$B$6:$B$100,'GP2 (2)'!$E$6:$E$100,"") -> 0.6 | J13: =_xlfn.XLOOKUP($B13,'GP3 (1)'!$B$6:$B$100,'GP3 (1)'!$E$6:$E$100,"") -> 1 | K13: =_xlfn.XLOOKUP($B13,'GP3 (2)'!$B$6:$B$100,'GP3 (2)'!$E$6:$E$100,"") -> 0.50 | L13: =_xlfn.XLOOKUP($B13,'GP4 (1)'!$B$6:$B$66,'GP4 (1)'!$E$6:$E$66,"") -> 0.8 | M13: =_xlfn.XLOOKUP($B13,'GP4 (2)'!$B$6:$B$100,'GP4 (2)'!$E$6:$E$100,"") -> 0.67 | N13: =_xlfn.XLOOKUP($B13,'GP5 (1)'!$B$6:$B$99,'GP5 (1)'!$E$6:$E$99,"") -> 0.5 | O13: =_xlfn.XLOOKUP($B13,'GP5 (2)'!$B$6:$B$99,'GP5 (2)'!$E$6:$E$99,"") -> 0 | P13: =_xlfn.XLOOKUP($B13,'GP6 (1)'!$B$5:$B$99,'GP6 (1)'!$E$5:$E$99,"") -> 1.00 | Q13: =_xlfn.XLOOKUP($B13,'GP6 (2)'!$B$5:$B$99,'GP6 (2)'!$E$5:$E$99,"") -> 1.00 | R13: =_xlfn.XLOOKUP($B13,'GP7 (1)'!$B$6:$B$100,'GP7 (1)'!$E$6:$E$100,"") | S13: =_xlfn.XLOOKUP($B13,'GP7 (2)'!$B$6:$B$100,'GP7 (2)'!$E$6:$E$100,"") | T13: =_xlfn.XLOOKUP($B13,'GP8 (1)'!$B$6:$B$100,'GP8 (1)'!$E$6:$E$100,"") | U13: =_xlfn.XLOOKUP($B13,'GP8 (2)'!$B$6:$B$100,'GP8 (2)'!$E$6:$E$100,"") | V13: =SUM(W13:AN13) -> 255 | W13: =_xlfn.XLOOKUP($B13,'MP (1)'!$B$6:$B$99,'MP (1)'!$F$6:$F$99,"") | X13: =_xlfn.XLOOKUP($B13,'MP (2)'!$B$6:$B$100,'MP (2)'!$F$6:$F$100,"") | Y13: =_xlfn.XLOOKUP($B13,'GP1 (1)'!$B$6:$B$100,'GP1 (1)'!$F$6:$F$100,"") -> 25 | Z13: =_xlfn.XLOOKUP($B13,'GP1 (2)'!$B$6:$B$100,'GP1 (2)'!$F$6:$F$100,"") -> 23 | AA13: =_xlfn.XLOOKUP($B13,'GP2 (1)'!$B$6:$B$101,'GP2 (1)'!$F$6:$F$101,"") -> 16 | AB13: =_xlfn.XLOOKUP($B13,'GP2 (2)'!$B$6:$B$100,'GP2 (2)'!$F$6:$F$100,"") -> 20 | AC13: =_xlfn.XLOOKUP($B13,'GP3 (1)'!$B$6:$B$100,'GP3 (1)'!$F$6:$F$100,"") -> 25 | AD13: =_xlfn.XLOOKUP($B13,'GP3 (2)'!$B$6:$B$100,'GP3 (2)'!$F$6:$F$100,"") -> 23 | AE13: =_xlfn.XLOOKUP($B13,'GP4 (1)'!$B$6:$B$66,'GP4 (1)'!$F$6:$F$66,"") -> 20 | AF13: =_xlfn.XLOOKUP($B13,'GP4 (2)'!$B$6:$B$100,'GP4 (2)'!$F$6:$F$100,"") -> 25 | AG13: =_xlfn.XLOOKUP($B13,'GP5 (1)'!$B$6:$B$99,'GP5 (1)'!$F$6:$F$99,"") -> 17 | AH13: =_xlfn.XLOOKUP($B13,'GP5 (2)'!$B$6:$B$99,'GP5 (2)'!$F$6:$F$99,"") -> 11 | AI13: =_xlfn.XLOOKUP($B13,'GP6 (1)'!$B$5:$B$99,'GP6 (1)'!$F$5:$F$99,"") -> 25 | AJ13: =_xlfn.XLOOKUP($B13,'GP6 (2)'!$B$5:$B$99,'GP6 (2)'!$F$5:$F$99,"") -> 25 | AK13: =_xlfn.XLOOKUP($B13,'GP7 (1)'!$B$6:$B$100,'GP7 (1)'!$F$6:$F$100,"") | AL13: =_xlfn.XLOOKUP($B13,'GP7 (2)'!$B$6:$B$100,'GP7 (2)'!$F$6:$F$100,"") | AM13: =_xlfn.XLOOKUP($B13,'GP8 (1)'!$B$6:$B$100,'GP8 (1)'!$F$6:$F$100,"") | AN13: =_xlfn.XLOOKUP($B13,'GP8 (2)'!$B$6:$B$100,'GP8 (2)'!$F$6:$F$100,"") | AO13: =SUM(AP13:BG13) -> 103 | AP13: =_xlfn.XLOOKUP($B13,'MP (1)'!$B$6:$B$99,'MP (1)'!$H$6:$H$99,"") | AQ13: =_xlfn.XLOOKUP($B13,'MP (2)'!$B$6:$B$100,'MP (2)'!$H$6:$H$100,"") | AR13: =_xlfn.XLOOKUP($B13,'GP1 (1)'!$B$6:$B$100,'GP1 (1)'!$H$6:$H$100,"") -> 17 | AS13: =_xlfn.XLOOKUP($B13,'GP1 (2)'!$B$6:$B$100,'GP1 (2)'!$H$6:$H$100,"") -> 12 | AT13: =_xlfn.XLOOKUP($B13,'GP2 (1)'!$B$6:$B$101,'GP2 (1)'!$H$6:$H$101,"") -> -3 | AU13: =_xlfn.XLOOKUP($B13,'GP2 (2)'!$B$6:$B$100,'GP2 (2)'!$H$6:$H$100,"") -> 7 | AV13: =_xlfn.XLOOKUP($B13,'GP3 (1)'!$B$6:$B$100,'GP3 (1)'!$H$6:$H$100,"") -> 16 | AW13: =_xlfn.XLOOKUP($B13,'GP3 (2)'!$B$6:$B$100,'GP3 (2)'!$H$6:$H$100,"") -> 2 | AX13: =_xlfn.XLOOKUP($B13,'GP4 (1)'!$B$6:$B$66,'GP4 (1)'!$H$6:$H$66,"") -> 9 | AY13: =_xlfn.XLOOKUP($B13,'GP4 (2)'!$B$6:$B$100,'GP4 (2)'!$H$6:$H$100,"") -> 10 | AZ13: =_xlfn.XLOOKUP($B13,'GP5 (1)'!$B$6:$B$99,'GP5 (1)'!$H$6:$H$99,"") -> 6 | BA13: =_xlfn.XLOOKUP($B13,'GP5 (2)'!$B$6:$B$99,'GP5 (2)'!$H$6:$H$99,"") -> -9 | BB13: =_xlfn.XLOOKUP($B13,'GP6 (1)'!$B$5:$B$99,'GP6 (1)'!$H$5:$H$99,"") -> 15 | BC13: =_xlfn.XLOOKUP($B13,'GP6 (2)'!$B$5:$B$99,'GP6 (2)'!$H$5:$H$99,"") -> 21 | BD13: =_xlfn.XLOOKUP($B13,'GP7 (1)'!$B$6:$B$100,'GP7 (1)'!$H$6:$H$100,"") | BE13: =_xlfn.XLOOKUP($B13,'GP7 (2)'!$B$6:$B$100,'GP7 (2)'!$H$6:$H$100,"") | BF13: =_xlfn.XLOOKUP($B13,'GP8 (1)'!$B$6:$B$100,'GP8 (1)'!$H$6:$H$100,"") | BG13: =_xlfn.XLOOKUP($B13,'GP8 (2)'!$B$6:$B$100,'GP8 (2)'!$H$6:$H$100,"")
A14: =ROW()-4 -> 10 | B14: NOWAK Szymon | C14: =SUM(D14:U14) -> 5.72 | D14: =_xlfn.XLOOKUP($B14,'MP (1)'!$B$6:$B$99,'MP (1)'!$E$6:$E$99,"") -> 0.5 | E14: =_xlfn.XLOOKUP($B14,'MP (2)'!$B$6:$B$100,'MP (2)'!$E$6:$E$100,"") -> 0.67 | F14: =_xlfn.XLOOKUP($B14,'GP1 (1)'!$B$6:$B$100,'GP1 (1)'!$E$6:$E$100,"") | G14: =_xlfn.XLOOKUP($B14,'GP1 (2)'!$B$6:$B$100,'GP1 (2)'!$E$6:$E$100,"") | H14: =_xlfn.XLOOKUP($B14,'GP2 (1)'!$B$6:$B$101,'GP2 (1)'!$E$6:$E$101,"") -> 0.8 | I14: =_xlfn.XLOOKUP($B14,'GP2 (2)'!$B$6:$B$100,'GP2 (2)'!$E$6:$E$100,"") -> 0.8 | J14: =_xlfn.XLOOKUP($B14,'GP3 (1)'!$B$6:$B$100,'GP3 (1)'!$E$6:$E$100,"") -> 0.6 | K14: =_xlfn.XLOOKUP($B14,'GP3 (2)'!$B$6:$B$100,'GP3 (2)'!$E$6:$E$100,"") -> 0.40 | L14: =_xlfn.XLOOKUP($B14,'GP4 (1)'!$B$6:$B$66,'GP4 (1)'!$E$6:$E$66,"") | M14: =_xlfn.XLOOKUP($B14,'GP4 (2)'!$B$6:$B$100,'GP4 (2)'!$E$6:$E$100,"") | N14: =_xlfn.XLOOKUP($B14,'GP5 (1)'!$B$6:$B$99,'GP5 (1)'!$E$6:$E$99,"") -> 0.6 | O14: =_xlfn.XLOOKUP($B14,'GP5 (2)'!$B$6:$B$99,'GP5 (2)'!$E$6:$E$99,"") -> 1 | P14: =_xlfn.XLOOKUP($B14,'GP6 (1)'!$B$5:$B$99,'GP6 (1)'!$E$5:$E$99,"") | Q14: =_xlfn.XLOOKUP($B14,'GP6 (2)'!$B$5:$B$99,'GP6 (2)'!$E$5:$E$99,"") | R14: =_xlfn.XLOOKUP($B14,'GP7 (1)'!$B$6:$B$100,'GP7 (1)'!$E$6:$E$100,"") -> 0.80 | S14: =_xlfn.XLOOKUP($B14,'GP7 (2)'!$B$6:$B$100,'GP7 (2)'!$E$6:$E$100,"") -> 0.75 | T14: =_xlfn.XLOOKUP($B14,'GP8 (1)'!$B$6:$B$100,'GP8 (1)'!$E$6:$E$100,"") | U14: =_xlfn.XLOOKUP($B14,'GP8 (2)'!$B$6:$B$100,'GP8 (2)'!$E$6:$E$100,"") | V14: =SUM(W14:AN14) -> 206 | W14: =_xlfn.XLOOKUP($B14,'MP (1)'!$B$6:$B$99,'MP (1)'!$F$6:$F$99,"") -> 20 | X14: =_xlfn.XLOOKUP($B14,'MP (2)'!$B$6:$B$100,'MP (2)'!$F$6:$F$100,"") -> 24 | Y14: =_xlfn.XLOOKUP($B14,'GP1 (1)'!$B$6:$B$100,'GP1 (1)'!$F$6:$F$100,"") | Z14: =_xlfn.XLOOKUP($B14,'GP1 (2)'!$B$6:$B$100,'GP1 (2)'!$F$6:$F$100,"") | AA14: =_xlfn.XLOOKUP($B14,'GP2 (1)'!$B$6:$B$101,'GP2 (1)'!$F$6:$F$101,"") -> 21 | AB14: =_xlfn.XLOOKUP($B14,'GP2 (2)'!$B$6:$B$100,'GP2 (2)'!$F$6:$F$100,"") -> 24 | AC14: =_xlfn.XLOOKUP($B14,'GP3 (1)'!$B$6:$B$100,'GP3 (1)'!$F$6:$F$100,"") -> 17 | AD14: =_xlfn.XLOOKUP($B14,'GP3 (2)'!$B$6:$B$100,'GP3 (2)'!$F$6:$F$100,"") -> 18 | AE14: =_xlfn.XLOOKUP($B14,'GP4 (1)'!$B$6:$B$66,'GP4 (1)'!$F$6:$F$66,"") | AF14: =_xlfn.XLOOKUP($B14,'GP4 (2)'!$B$6:$B$100,'GP4 (2)'!$F$6:$F$100,"") | AG14: =_xlfn.XLOOKUP($B14,'GP5 (1)'!$B$6:$B$99,'GP5 (1)'!$F$6:$F$99,"") -> 15 | AH14: =_xlfn.XLOOKUP($B14,'GP5 (2)'!$B$6:$B$99,'GP5 (2)'!$F$6:$F$99,"") -> 25 | AI14: =_xlfn.XLOOKUP($B14,'GP6 (1)'!$B$5:$B$99,'GP6 (1)'!$F$5:$F$99,"") | AJ14: =_xlfn.XLOOKUP($B14,'GP6 (2)'!$B$5:$B$99,'GP6 (2)'!$F$5:$F$99,"") | AK14: =_xlfn.XLOOKUP($B14,'GP7 (1)'!$B$6:$B$100,'GP7 (1)'!$F$6:$F$100,"") -> 24 | AL14: =_xlfn.XLOOKUP($B14,'GP7 (2)'!$B$6:$B$100,'GP7 (2)'!$F$6:$F$100,"") -> 18 | AM14: =_xlfn.XLOOKUP($B14,'GP8 (1)'!$B$6:$B$100,'GP8 (1)'!$F$6:$F$100,"") | AN14: =_xlfn.XLOOKUP($B14,'GP8 (2)'!$B$6:$B$100,'GP8 (2)'!$F$6:$F$100,"") | AO14: =SUM(AP14:BG14) -> 73 | AP14: =_xlfn.XLOOKUP($B14,'MP (1)'!$B$6:$B$99,'MP (1)'!$H$6:$H$99,"") -> 3 | AQ14: =_xlfn.XLOOKUP($B14,'MP (2)'!$B$6:$B$100,'MP (2)'!$H$6:$H$100,"") -> 10 | AR14: =_xlfn.XLOOKUP($B14,'GP1 (1)'!$B$6:$B$100,'GP1 (1)'!$H$6:$H$100,"") | AS14: =_xlfn.XLOOKUP($B14,'GP1 (2)'!$B$6:$B$100,'GP1 (2)'!$H$6:$H$100,"") | AT14: =_xlfn.XLOOKUP($B14,'GP2 (1)'!$B$6:$B$101,'GP2 (1)'!$H$6:$H$101,"") -> 13 | AU14: =_xlfn.XLOOKUP($B14,'GP2 (2)'!$B$6:$B$100,'GP2 (2)'!$H$6:$H$100,"") -> 11 | AV14: =_xlfn.XLOOKUP($B14,'GP3 (1)'!$B$6:$B$100,'GP3 (1)'!$H$6:$H$100,"") -> 3 | AW14: =_xlfn.XLOOKUP($B14,'GP3 (2)'!$B$6:$B$100,'GP3 (2)'!$H$6:$H$100,"") -> 0 | AX14: =_xlfn.XLOOKUP($B14,'GP4 (1)'!$B$6:$B$66,'GP4 (1)'!$H$6:$H$66,"") | AY14: =_xlfn.XLOOKUP($B14,'GP4 (2)'!$B$6:$B$100,'GP4 (2)'!$H$6:$H$100,"") | AZ14: =_xlfn.XLOOKUP($B14,'GP5 (1)'!$B$6:$B$99,'GP5 (1)'!$H$6:$H$99,"") -> 2 | BA14: =_xlfn.XLOOKUP($B14,'GP5 (2)'!$B$6:$B$99,'GP5 (2)'!$H$6:$H$99,"") -> 17 | BB14: =_xlfn.XLOOKUP($B14,'GP6 (1)'!$B$5:$B$99,'GP6 (1)'!$H$5:$H$99,"") | BC14: =_xlfn.XLOOKUP($B14,'GP6 (2)'!$B$5:$B$99,'GP6 (2)'!$H$5:$H$99,"") | BD14: =_xlfn.XLOOKUP($B14,'GP7 (1)'!$B$6:$B$100,'GP7 (1)'!$H$6:$H$100,"") -> 7 | BE14: =_xlfn.XLOOKUP($B14,'GP7 (2)'!$B$6:$B$100,'GP7 (2)'!$H$6:$H$100,"") -> 7 | BF14: =_xlfn.XLOOKUP($B14,'GP8 (1)'!$B$6:$B$100,'GP8 (1)'!$H$6:$H$100,"") | BG14: =_xlfn.XLOOKUP($B14,'GP8 (2)'!$B$6:$B$100,'GP8 (2)'!$H$6:$H$100,"")
A15: =ROW()-4 -> 11 | B15: POKRZYWA Mariusz | C15: =SUM(D15:U15) -> 5.44 | D15: =_xlfn.XLOOKUP($B15,'MP (1)'!$B$6:$B$99,'MP (1)'!$E$6:$E$99,"") -> 0.67 | E15: =_xlfn.XLOOKUP($B15,'MP (2)'!$B$6:$B$100,'MP (2)'!$E$6:$E$100,"") -> 0.67 | F15: =_xlfn.XLOOKUP($B15,'GP1 (1)'!$B$6:$B$100,'GP1 (1)'!$E$6:$E$100,"") -> 0.8 | G15: =_xlfn.XLOOKUP($B15,'GP1 (2)'!$B$6:$B$100,'GP1 (2)'!$E$6:$E$100,"") -> 0.8 | H15: =_xlfn.XLOOKUP($B15,'GP2 (1)'!$B$6:$B$101,'GP2 (1)'!$E$6:$E$101,"") | I15: =_xlfn.XLOOKUP($B15,'GP2 (2)'!$B$6:$B$100,'GP2 (2)'!$E$6:$E$100,"") | J15: =_xlfn.XLOOKUP($B15,'GP3 (1)'!$B$6:$B$100,'GP3 (1)'!$E$6:$E$100,"") -> 0.6 | K15: =_xlfn.XLOOKUP($B15,'GP3 (2)'!$B$6:$B$100,'GP3 (2)'!$E$6:$E$100,"") -> 0.67 | L15: =_xlfn.XLOOKUP($B15,'GP4 (1)'!$B$6:$B$66,'GP4 (1)'!$E$6:$E$66,"") | M15: =_xlfn.XLOOKUP($B15,'GP4 (2)'!$B$6:$B$100,'GP4 (2)'!$E$6:$E$100,"") | N15: =_xlfn.XLOOKUP($B15,'GP5 (1)'!$B$6:$B$99,'GP5 (1)'!$E$6:$E$99,"") -> 0.6 | O15: =_xlfn.XLOOKUP($B15,'GP5 (2)'!$B$6:$B$99,'GP5 (2)'!$E$6:$E$99,"") -> 0.8 | P15: =_xlfn.XLOOKUP($B15,'GP6 (1)'!$B$5:$B$99,'GP6 (1)'!$E$5:$E$99,"") -> 0.50 | Q15: =_xlfn.XLOOKUP($B15,'GP6 (2)'!$B$5:$B$99,'GP6 (2)'!$E$5:$E$99,"") -> 0.75 | R15: =_xlfn.XLOOKUP($B15,'GP7 (1)'!$B$6:$B$100,'GP7 (1)'!$E$6:$E$100,"") | S15: =_xlfn.XLOOKUP($B15,'GP7 (2)'!$B$6:$B$100,'GP7 (2)'!$E$6:$E$100,"") | T15: =_xlfn.XLOOKUP($B15,'GP8 (1)'!$B$6:$B$100,'GP8 (1)'!$E$6:$E$100,"") -> 0.50 | U15: =_xlfn.XLOOKUP($B15,'GP8 (2)'!$B$6:$B$100,'GP8 (2)'!$E$6:$E$100,"") -> 0.5 | V15: =SUM(W15:AN15) -> 228 | W15: =_xlfn.XLOOKUP($B15,'MP (1)'!$B$6:$B$99,'MP (1)'!$F$6:$F$99,"") -> 23 | X15: =_xlfn.XLOOKUP($B15,'MP (2)'!$B$6:$B$100,'MP (2)'!$F$6:$F$100,"") -> 19 | Y15: =_xlfn.XLOOKUP($B15,'GP1 (1)'!$B$6:$B$100,'GP1 (1)'!$F$6:$F$100,"") -> 23 | Z15: =_xlfn.XLOOKUP($B15,'GP1 (2)'!$B$6:$B$100,'GP1 (2)'!$F$6:$F$100,"") -> 21 | AA15: =_xlfn.XLOOKUP($B15,'GP2 (1)'!$B$6:$B$101,'GP2 (1)'!$F$6:$F$101,"") | AB15: =_xlfn.XLOOKUP($B15,'GP2 (2)'!$B$6:$B$100,'GP2 (2)'!$F$6:$F$100,"") | AC15: =_xlfn.XLOOKUP($B15,'GP3 (1)'!$B$6:$B$100,'GP3 (1)'!$F$6:$F$100,"") -> 22 | AD15: =_xlfn.XLOOKUP($B15,'GP3 (2)'!$B$6:$B$100,'GP3 (2)'!$F$6:$F$100,"") -> 25 | AE15: =_xlfn.XLOOKUP($B15,'GP4 (1)'!$B$6:$B$66,'GP4 (1)'!$F$6:$F$66,"") | AF15: =_xlfn.XLOOKUP($B15,'GP4 (2)'!$B$6:$B$100,'GP4 (2)'!$F$6:$F$100,"") | AG15: =_xlfn.XLOOKUP($B15,'GP5 (1)'!$B$6:$B$99,'GP5 (1)'!$F$6:$F$99,"") -> 21 | AH15: =_xlfn.XLOOKUP($B15,'GP5 (2)'!$B$6:$B$99,'GP5 (2)'!$F$6:$F$99,"") -> 20 | AI15: =_xlfn.XLOOKUP($B15,'GP6 (1)'!$B$5:$B$99,'GP6 (1)'!$F$5:$F$99,"") -> 14 | AJ15: =_xlfn.XLOOKUP($B15,'GP6 (2)'!$B$5:$B$99,'GP6 (2)'!$F$5:$F$99,"") -> 16 | AK15: =_xlfn.XLOOKUP($B15,'GP7 (1)'!$B$6:$B$100,'GP7 (1)'!$F$6:$F$100,"") | AL15: =_xlfn.XLOOKUP($B15,'GP7 (2)'!$B$6:$B$100,'GP7 (2)'!$F$6:$F$100,"") | AM15: =_xlfn.XLOOKUP($B15,'GP8 (1)'!$B$6:$B$100,'GP8 (1)'!$F$6:$F$100,"") -> 12 | AN15: =_xlfn.XLOOKUP($B15,'GP8 (2)'!$B$6:$B$100,'GP8 (2)'!$F$6:$F$100,"") -> 12 | AO15: =SUM(AP15:BG15) -> 75 | AP15: =_xlfn.XLOOKUP($B15,'MP (1)'!$B$6:$B$99,'MP (1)'!$H$6:$H$99,"") -> 8 | AQ15: =_xlfn.XLOOKUP($B15,'MP (2)'!$B$6:$B$100,'MP (2)'!$H$6:$H$100,"") -> 3 | AR15: =_xlfn.XLOOKUP($B15,'GP1 (1)'!$B$6:$B$100,'GP1 (1)'!$H$6:$H$100,"") -> 11 | AS15: =_xlfn.XLOOKUP($B15,'GP1 (2)'!$B$6:$B$100,'GP1 (2)'!$H$6:$H$100,"") -> 11 | AT15: =_xlfn.XLOOKUP($B15,'GP2 (1)'!$B$6:$B$101,'GP2 (1)'!$H$6:$H$101,"") | AU15: =_xlfn.XLOOKUP($B15,'GP2 (2)'!$B$6:$B$100,'GP2 (2)'!$H$6:$H$100,"") | AV15: =_xlfn.XLOOKUP($B15,'GP3 (1)'!$B$6:$B$100,'GP3 (1)'!$H$6:$H$100,"") -> 7 | AW15: =_xlfn.XLOOKUP($B15,'GP3 (2)'!$B$6:$B$100,'GP3 (2)'!$H$6:$H$100,"") -> 8 | AX15: =_xlfn.XLOOKUP($B15,'GP4 (1)'!$B$6:$B$66,'GP4 (1)'!$H$6:$H$66,"") | AY15: =_xlfn.XLOOKUP($B15,'GP4 (2)'!$B$6:$B$100,'GP4 (2)'!$H$6:$H$100,"") | AZ15: =_xlfn.XLOOKUP($B15,'GP5 (1)'!$B$6:$B$99,'GP5 (1)'!$H$6:$H$99,"") -> 6 | BA15: =_xlfn.XLOOKUP($B15,'GP5 (2)'!$B$6:$B$99,'GP5 (2)'!$H$6:$H$99,"") -> 12 | BB15: =_xlfn.XLOOKUP($B15,'GP6 (1)'!$B$5:$B$99,'GP6 (1)'!$H$5:$H$99,"") -> 2 | BC15: =_xlfn.XLOOKUP($B15,'GP6 (2)'!$B$5:$B$99,'GP6 (2)'!$H$5:$H$99,"") -> 9 | BD15: =_xlfn.XLOOKUP($B15,'GP7 (1)'!$B$6:$B$100,'GP7 (1)'!$H$6:$H$100,"") | BE15: =_xlfn.XLOOKUP($B15,'GP7 (2)'!$B$6:$B$100,'GP7 (2)'!$H$6:$H$100,"") | BF15: =_xlfn.XLOOKUP($B15,'GP8 (1)'!$B$6:$B$100,'GP8 (1)'!$H$6:$H$100,"") -> -1 | BG15: =_xlfn.XLOOKUP($B15,'GP8 (2)'!$B$6:$B$100,'GP8 (2)'!$H$6:$H$100,"") -> -1
A16: =ROW()-4 -> 12 | B16: GWIAZDA Paweł | C16: =SUM(D16:U16) -> 5 | D16: =_xlfn.XLOOKUP($B16,'MP (1)'!$B$6:$B$99,'MP (1)'!$E$6:$E$99,"") | E16: =_xlfn.XLOOKUP($B16,'MP (2)'!$B$6:$B$100,'MP (2)'!$E$6:$E$100,"") | F16: =_xlfn.XLOOKUP($B16,'GP1 (1)'!$B$6:$B$100,'GP1 (1)'!$E$6:$E$100,"") -> 0.8 | G16: =_xlfn.XLOOKUP($B16,'GP1 (2)'!$B$6:$B$100,'GP1 (2)'!$E$6:$E$100,"") -> 1 | H16: =_xlfn.XLOOKUP($B16,'GP2 (1)'!$B$6:$B$101,'GP2 (1)'!$E$6:$E$101,"") -> 0.4 | I16: =_xlfn.XLOOKUP($B16,'GP2 (2)'!$B$6:$B$100,'GP2 (2)'!$E$6:$E$100,"") -> 0.6 | J16: =_xlfn.XLOOKUP($B16,'GP3 (1)'!$B$6:$B$100,'GP3 (1)'!$E$6:$E$100,"") -> 0.4 | K16: =_xlfn.XLOOKUP($B16,'GP3 (2)'!$B$6:$B$100,'GP3 (2)'!$E$6:$E$100,"") -> 0.33 | L16: =_xlfn.XLOOKUP($B16,'GP4 (1)'!$B$6:$B$66,'GP4 (1)'!$E$6:$E$66,"") -> 0.6 | M16: =_xlfn.XLOOKUP($B16,'GP4 (2)'!$B$6:$B$100,'GP4 (2)'!$E$6:$E$100,"") -> 0.6 | N16: =_xlfn.XLOOKUP($B16,'GP5 (1)'!$B$6:$B$99,'GP5 (1)'!$E$6:$E$99,"") | O16: =_xlfn.XLOOKUP($B16,'GP5 (2)'!$B$6:$B$99,'GP5 (2)'!$E$6:$E$99,"") | P16: =_xlfn.XLOOKUP($B16,'GP6 (1)'!$B$5:$B$99,'GP6 (1)'!$E$5:$E$99,"") -> 0.60 | Q16: =_xlfn.XLOOKUP($B16,'GP6 (2)'!$B$5:$B$99,'GP6 (2)'!$E$5:$E$99,"") -> 0.80 | R16: =_xlfn.XLOOKUP($B16,'GP7 (1)'!$B$6:$B$100,'GP7 (1)'!$E$6:$E$100,"") -> 0.40 | S16: =_xlfn.XLOOKUP($B16,'GP7 (2)'!$B$6:$B$100,'GP7 (2)'!$E$6:$E$100,"") -> 0.6 | T16: =_xlfn.XLOOKUP($B16,'GP8 (1)'!$B$6:$B$100,'GP8 (1)'!$E$6:$E$100,"") | U16: =_xlfn.XLOOKUP($B16,'GP8 (2)'!$B$6:$B$100,'GP8 (2)'!$E$6:$E$100,"") | V16: =SUM(W16:AN16) -> 235 | W16: =_xlfn.XLOOKUP($B16,'MP (1)'!$B$6:$B$99,'MP (1)'!$F$6:$F$99,"") | X16: =_xlfn.XLOOKUP($B16,'MP (2)'!$B$6:$B$100,'MP (2)'!$F$6:$F$100,"") | Y16: =_xlfn.XLOOKUP($B16,'GP1 (1)'!$B$6:$B$100,'GP1 (1)'!$F$6:$F$100,"") -> 21 | Z16: =_xlfn.XLOOKUP($B16,'GP1 (2)'!$B$6:$B$100,'GP1 (2)'!$F$6:$F$100,"") -> 22 | AA16: =_xlfn.XLOOKUP($B16,'GP2 (1)'!$B$6:$B$101,'GP2 (1)'!$F$6:$F$101,"") -> 17 | AB16: =_xlfn.XLOOKUP($B16,'GP2 (2)'!$B$6:$B$100,'GP2 (2)'!$F$6:$F$100,"") -> 21 | AC16: =_xlfn.XLOOKUP($B16,'GP3 (1)'!$B$6:$B$100,'GP3 (1)'!$F$6:$F$100,"") -> 15 | AD16: =_xlfn.XLOOKUP($B16,'GP3 (2)'!$B$6:$B$100,'GP3 (2)'!$F$6:$F$100,"") -> 21 | AE16: =_xlfn.XLOOKUP($B16,'GP4 (1)'!$B$6:$B$66,'GP4 (1)'!$F$6:$F$66,"") -> 21 | AF16: =_xlfn.XLOOKUP($B16,'GP4 (2)'!$B$6:$B$100,'GP4 (2)'!$F$6:$F$100,"") -> 18 | AG16: =_xlfn.XLOOKUP($B16,'GP5 (1)'!$B$6:$B$99,'GP5 (1)'!$F$6:$F$99,"") | AH16: =_xlfn.XLOOKUP($B16,'GP5 (2)'!$B$6:$B$99,'GP5 (2)'!$F$6:$F$99,"") | AI16: =_xlfn.XLOOKUP($B16,'GP6 (1)'!$B$5:$B$99,'GP6 (1)'!$F$5:$F$99,"") -> 19 | AJ16: =_xlfn.XLOOKUP($B16,'GP6 (2)'!$B$5:$B$99,'GP6 (2)'!$F$5:$F$99,"") -> 20 | AK16: =_xlfn.XLOOKUP($B16,'GP7 (1)'!$B$6:$B$100,'GP7 (1)'!$F$6:$F$100,"") -> 20 | AL16: =_xlfn.XLOOKUP($B16,'GP7 (2)'!$B$6:$B$100,'GP7 (2)'!$F$6:$F$100,"") -> 20 | AM16: =_xlfn.XLOOKUP($B16,'GP8 (1)'!$B$6:$B$100,'GP8 (1)'!$F$6:$F$100,"") | AN16: =_xlfn.XLOOKUP($B16,'GP8 (2)'!$B$6:$B$100,'GP8 (2)'!$F$6:$F$100,"") | AO16: =SUM(AP16:BG16) -> 59 | AP16: =_xlfn.XLOOKUP($B16,'MP (1)'!$B$6:$B$99,'MP (1)'!$H$6:$H$99,"") | AQ16: =_xlfn.XLOOKUP($B16,'MP (2)'!$B$6:$B$100,'MP (2)'!$H$6:$H$100,"") | AR16: =_xlfn.XLOOKUP($B16,'GP1 (1)'!$B$6:$B$100,'GP1 (1)'!$H$6:$H$100,"") -> 9 | AS16: =_xlfn.XLOOKUP($B16,'GP1 (2)'!$B$6:$B$100,'GP1 (2)'!$H$6:$H$100,"") -> 18 | AT16: =_xlfn.XLOOKUP($B16,'GP2 (1)'!$B$6:$B$101,'GP2 (1)'!$H$6:$H$101,"") -> -1 | AU16: =_xlfn.XLOOKUP($B16,'GP2 (2)'!$B$6:$B$100,'GP2 (2)'!$H$6:$H$100,"") -> 4 | AV16: =_xlfn.XLOOKUP($B16,'GP3 (1)'!$B$6:$B$100,'GP3 (1)'!$H$6:$H$100,"") -> -5 | AW16: =_xlfn.XLOOKUP($B16,'GP3 (2)'!$B$6:$B$100,'GP3 (2)'!$H$6:$H$100,"") -> 1 | AX16: =_xlfn.XLOOKUP($B16,'GP4 (1)'!$B$6:$B$66,'GP4 (1)'!$H$6:$H$66,"") -> 6 | AY16: =_xlfn.XLOOKUP($B16,'GP4 (2)'!$B$6:$B$100,'GP4 (2)'!$H$6:$H$100,"") -> 6 | AZ16: =_xlfn.XLOOKUP($B16,'GP5 (1)'!$B$6:$B$99,'GP5 (1)'!$H$6:$H$99,"") | BA16: =_xlfn.XLOOKUP($B16,'GP5 (2)'!$B$6:$B$99,'GP5 (2)'!$H$6:$H$99,"") | BB16: =_xlfn.XLOOKUP($B16,'GP6 (1)'!$B$5:$B$99,'GP6 (1)'!$H$5:$H$99,"") -> 5 | BC16: =_xlfn.XLOOKUP($B16,'GP6 (2)'!$B$5:$B$99,'GP6 (2)'!$H$5:$H$99,"") -> 9 | BD16: =_xlfn.XLOOKUP($B16,'GP7 (1)'!$B$6:$B$100,'GP7 (1)'!$H$6:$H$100,"") -> 1 | BE16: =_xlfn.XLOOKUP($B16,'GP7 (2)'!$B$6:$B$100,'GP7 (2)'!$H$6:$H$100,"") -> 6 | BF16: =_xlfn.XLOOKUP($B16,'GP8 (1)'!$B$6:$B$100,'GP8 (1)'!$H$6:$H$100,"") | BG16: =_xlfn.XLOOKUP($B16,'GP8 (2)'!$B$6:$B$100,'GP8 (2)'!$H$6:$H$100,"")
... A63: =ROW()-4 -> 59 | B63: WIŚNIEWSKI Bernard | C63: =SUM(D63:U63) -> 0 | D63: =_xlfn.XLOOKUP($B63,'MP (1)'!$B$6:$B$99,'MP (1)'!$E$6:$E$99,"") | E63: =_xlfn.XLOOKUP($B63,'MP (2)'!$B$6:$B$100,'MP (2)'!$E$6:$E$100,"") | F63: =_xlfn.XLOOKUP($B63,'GP1 (1)'!$B$6:$B$100,'GP1 (1)'!$E$6:$E$100,"") | G63: =_xlfn.XLOOKUP($B63,'GP1 (2)'!$B$6:$B$100,'GP1 (2)'!$E$6:$E$100,"") | H63: =_xlfn.XLOOKUP($B63,'GP2 (1)'!$B$6:$B$101,'GP2 (1)'!$E$6:$E$101,"") | I63: =_xlfn.XLOOKUP($B63,'GP2 (2)'!$B$6:$B$100,'GP2 (2)'!$E$6:$E$100,"") | J63: =_xlfn.XLOOKUP($B63,'GP3 (1)'!$B$6:$B$100,'GP3 (1)'!$E$6:$E$100,"") | K63: =_xlfn.XLOOKUP($B63,'GP3 (2)'!$B$6:$B$100,'GP3 (2)'!$E$6:$E$100,"") | L63: =_xlfn.XLOOKUP($B63,'GP4 (1)'!$B$6:$B$66,'GP4 (1)'!$E$6:$E$66,"") | M63: =_xlfn.XLOOKUP($B63,'GP4 (2)'!$B$6:$B$100,'GP4 (2)'!$E$6:$E$100,"") | N63: =_xlfn.XLOOKUP($B63,'GP5 (1)'!$B$6:$B$99,'GP5 (1)'!$E$6:$E$99,"") | O63: =_xlfn.XLOOKUP($B63,'GP5 (2)'!$B$6:$B$99,'GP5 (2)'!$E$6:$E$99,"") | P63: =_xlfn.XLOOKUP($B63,'GP6 (1)'!$B$5:$B$99,'GP6 (1)'!$E$5:$E$99,"") | Q63: =_xlfn.XLOOKUP($B63,'GP6 (2)'!$B$5:$B$99,'GP6 (2)'!$E$5:$E$99,"") | R63: =_xlfn.XLOOKUP($B63,'GP7 (1)'!$B$6:$B$100,'GP7 (1)'!$E$6:$E$100,"") | S63: =_xlfn.XLOOKUP($B63,'GP7 (2)'!$B$6:$B$100,'GP7 (2)'!$E$6:$E$100,"") | T63: =_xlfn.XLOOKUP($B63,'GP8 (1)'!$B$6:$B$100,'GP8 (1)'!$E$6:$E$100,"") | U63: =_xlfn.XLOOKUP($B63,'GP8 (2)'!$B$6:$B$100,'GP8 (2)'!$E$6:$E$100,"") | V63: =SUM(W63:AN63) -> 0 | W63: =_xlfn.XLOOKUP($B63,'MP (1)'!$B$6:$B$99,'MP (1)'!$F$6:$F$99,"") | X63: =_xlfn.XLOOKUP($B63,'MP (2)'!$B$6:$B$100,'MP (2)'!$F$6:$F$100,"") | Y63: =_xlfn.XLOOKUP($B63,'GP1 (1)'!$B$6:$B$100,'GP1 (1)'!$F$6:$F$100,"") | Z63: =_xlfn.XLOOKUP($B63,'GP1 (2)'!$B$6:$B$100,'GP1 (2)'!$F$6:$F$100,"") | AA63: =_xlfn.XLOOKUP($B63,'GP2 (1)'!$B$6:$B$101,'GP2 (1)'!$F$6:$F$101,"") | AB63: =_xlfn.XLOOKUP($B63,'GP2 (2)'!$B$6:$B$100,'GP2 (2)'!$F$6:$F$100,"") | AC63: =_xlfn.XLOOKUP($B63,'GP3 (1)'!$B$6:$B$100,'GP3 (1)'!$F$6:$F$100,"") | AD63: =_xlfn.XLOOKUP($B63,'GP3 (2)'!$B$6:$B$100,'GP3 (2)'!$F$6:$F$100,"") | AE63: =_xlfn.XLOOKUP($B63,'GP4 (1)'!$B$6:$B$66,'GP4 (1)'!$F$6:$F$66,"") | AF63: =_xlfn.XLOOKUP($B63,'GP4 (2)'!$B$6:$B$100,'GP4 (2)'!$F$6:$F$100,"") | AG63: =_xlfn.XLOOKUP($B63,'GP5 (1)'!$B$6:$B$99,'GP5 (1)'!$F$6:$F$99,"") | AH63: =_xlfn.XLOOKUP($B63,'GP5 (2)'!$B$6:$B$99,'GP5 (2)'!$F$6:$F$99,"") | AI63: =_xlfn.XLOOKUP($B63,'GP6 (1)'!$B$5:$B$99,'GP6 (1)'!$F$5:$F$99,"") | AJ63: =_xlfn.XLOOKUP($B63,'GP6 (2)'!$B$5:$B$99,'GP6 (2)'!$F$5:$F$99,"") | AK63: =_xlfn.XLOOKUP($B63,'GP7 (1)'!$B$6:$B$100,'GP7 (1)'!$F$6:$F$100,"") | AL63: =_xlfn.XLOOKUP($B63,'GP7 (2)'!$B$6:$B$100,'GP7 (2)'!$F$6:$F$100,"") | AM63: =_xlfn.XLOOKUP($B63,'GP8 (1)'!$B$6:$B$100,'GP8 (1)'!$F$6:$F$100,"") | AN63: =_xlfn.XLOOKUP($B63,'GP8 (2)'!$B$6:$B$100,'GP8 (2)'!$F$6:$F$100,"") | AO63: =SUM(AP63:BG63) -> 0 | AP63: =_xlfn.XLOOKUP($B63,'MP (1)'!$B$6:$B$99,'MP (1)'!$H$6:$H$99,"") | AQ63: =_xlfn.XLOOKUP($B63,'MP (2)'!$B$6:$B$100,'MP (2)'!$H$6:$H$100,"") | AR63: =_xlfn.XLOOKUP($B63,'GP1 (1)'!$B$6:$B$100,'GP1 (1)'!$H$6:$H$100,"") | AS63: =_xlfn.XLOOKUP($B63,'GP1 (2)'!$B$6:$B$100,'GP1 (2)'!$H$6:$H$100,"") | AT63: =_xlfn.XLOOKUP($B63,'GP2 (1)'!$B$6:$B$101,'GP2 (1)'!$H$6:$H$101,"") | AU63: =_xlfn.XLOOKUP($B63,'GP2 (2)'!$B$6:$B$100,'GP2 (2)'!$H$6:$H$100,"") | AV63: =_xlfn.XLOOKUP($B63,'GP3 (1)'!$B$6:$B$100,'GP3 (1)'!$H$6:$H$100,"") | AW63: =_xlfn.XLOOKUP($B63,'GP3 (2)'!$B$6:$B$100,'GP3 (2)'!$H$6:$H$100,"") | AX63: =_xlfn.XLOOKUP($B63,'GP4 (1)'!$B$6:$B$66,'GP4 (1)'!$H$6:$H$66,"") | AY63: =_xlfn.XLOOKUP($B63,'GP4 (2)'!$B$6:$B$100,'GP4 (2)'!$H$6:$H$100,"") | AZ63: =_xlfn.XLOOKUP($B63,'GP5 (1)'!$B$6:$B$99,'GP5 (1)'!$H$6:$H$99,"") | BA63: =_xlfn.XLOOKUP($B63,'GP5 (2)'!$B$6:$B$99,'GP5 (2)'!$H$6:$H$99,"") | BB63: =_xlfn.XLOOKUP($B63,'GP6 (1)'!$B$5:$B$99,'GP6 (1)'!$H$5:$H$99,"") | BC63: =_xlfn.XLOOKUP($B63,'GP6 (2)'!$B$5:$B$99,'GP6 (2)'!$H$5:$H$99,"") | BD63: =_xlfn.XLOOKUP($B63,'GP7 (1)'!$B$6:$B$100,'GP7 (1)'!$H$6:$H$100,"") | BE63: =_xlfn.XLOOKUP($B63,'GP7 (2)'!$B$6:$B$100,'GP7 (2)'!$H$6:$H$100,"") | BF63: =_xlfn.XLOOKUP($B63,'GP8 (1)'!$B$6:$B$100,'GP8 (1)'!$H$6:$H$100,"") | BG63: =_xlfn.XLOOKUP($B63,'GP8 (2)'!$B$6:$B$100,'GP8 (2)'!$H$6:$H$100,"")
