Workbook

Sheet Ranking
B2: Dołączył/a do kategorii w tym roku | D2: Ranking Pucharu Polski Weteranów (PP) sezon 2024-2025 | R2: Na sumę punktów w rankingu skłąda się 4 najlepszych wyników (z 5 możliwych) w turniejach PP Weteranów oraz wynik z Mistrzostw Polski Weteranów.
D3: Kat. 2
A4: L.P. | B4: NAZWISKO Imię | C4: KLUB | D4: PUNKTY | E4: I PP | G4: II PP | I4: III PP | K4: IV PP | M4: V PP | O4: MPW
E5: M | F5: P | G5: M | H5: P | I5: M | J5: P | K5: M | L5: P | M5: M | N5: P | O5: M | P5: P
A6: =ROW()-5 -> 1 | B6: TK | D6: =SUM(F6,H6,J6,L6,N6,P6)-MIN(F6,H6,J6,L6,N6) -> 497.7146 | E6: =_xlfn.XLOOKUP($B6,'PP1'!$C$6:$C$55,'PP1'!$B$6:$B$55,"") -> 1 | F6: =_xlfn.XLOOKUP(E6,'PP1'!$B$6:$B$55,'PP1'!$A$6:$A$55,0) -> 96.354085 | G6: =_xlfn.XLOOKUP($B6,'PP2'!$C$6:$C$55,'PP2'!$B$6:$B$55,"") -> 1 | H6: =_xlfn.XLOOKUP(G6,'PP2'!$B$6:$B$55,'PP2'!$A$6:$A$55,0) -> 107.21638 | I6: =_xlfn.XLOOKUP($B6,'PP3'!$C$6:$C$55,'PP3'!$B$6:$B$55,"") -> 1 | J6: =_xlfn.XLOOKUP(I6,'PP3'!$B$6:$B$55,'PP3'!$A$6:$A$55,0) -> 95.389784 | K6: =_xlfn.XLOOKUP($B6,'PP4'!$C$6:$C$55,'PP4'!$B$6:$B$55,"") -> 1 | L6: =_xlfn.XLOOKUP(K6,'PP4'!$B$6:$B$55,'PP4'!$A$6:$A$55,0) -> 82.980246 | M6: =_xlfn.XLOOKUP($B6,'PP5'!$C$6:$C$55,'PP5'!$B$6:$B$55,"") -> 1 | N6: =_xlfn.XLOOKUP(M6,'PP5'!$B$6:$B$55,'PP5'!$A$6:$A$55,0) -> 84.286609 | O6: =_xlfn.XLOOKUP(B6,MPW!C$6:C$55,MPW!B$6:B$55,"") -> 1 | P6: =_xlfn.XLOOKUP(O6,MPW!B$6:B$55,MPW!A$6:A$55,0) -> 114.46774
A7: =ROW()-5 -> 2 | B7: SZMIDT Grzegorz | D7: =SUM(F7,H7,J7,L7,N7,P7)-MIN(F7,H7,J7,L7,N7) -> 248.31424 | E7: =_xlfn.XLOOKUP($B7,'PP1'!$C$6:$C$55,'PP1'!$B$6:$B$55,"") -> 3 | F7: =_xlfn.XLOOKUP(E7,'PP1'!$B$6:$B$55,'PP1'!$A$6:$A$55,0) -> 35.407149 | G7: =_xlfn.XLOOKUP($B7,'PP2'!$C$6:$C$55,'PP2'!$B$6:$B$55,"") -> 4 | H7: =_xlfn.XLOOKUP(G7,'PP2'!$B$6:$B$55,'PP2'!$A$6:$A$55,0) -> 25.091696 | I7: =_xlfn.XLOOKUP($B7,'PP3'!$C$6:$C$55,'PP3'!$B$6:$B$55,"") -> 2 | J7: =_xlfn.XLOOKUP(I7,'PP3'!$B$6:$B$55,'PP3'!$A$6:$A$55,0) -> 59.156704 | K7: =_xlfn.XLOOKUP($B7,'PP4'!$C$6:$C$55,'PP4'!$B$6:$B$55,"") -> 2 | L7: =_xlfn.XLOOKUP(K7,'PP4'!$B$6:$B$55,'PP4'!$A$6:$A$55,0) -> 37.737939 | M7: =_xlfn.XLOOKUP($B7,'PP5'!$C$6:$C$55,'PP5'!$B$6:$B$55,"") -> 2 | N7: =_xlfn.XLOOKUP(M7,'PP5'!$B$6:$B$55,'PP5'!$A$6:$A$55,0) -> 45.024406 | O7: =_xlfn.XLOOKUP(B7,MPW!C$6:C$55,MPW!B$6:B$55,"") -> 2 | P7: =_xlfn.XLOOKUP(O7,MPW!B$6:B$55,MPW!A$6:A$55,0) -> 70.988045
A8: =ROW()-5 -> 3 | B8: BAZAK Jacek | D8: =SUM(F8,H8,J8,L8,N8,P8)-MIN(F8,H8,J8,L8,N8) -> 171.76454 | E8: =_xlfn.XLOOKUP($B8,'PP1'!$C$6:$C$55,'PP1'!$B$6:$B$55,"") -> 2 | F8: =_xlfn.XLOOKUP(E8,'PP1'!$B$6:$B$55,'PP1'!$A$6:$A$55,0) -> 61.946936 | G8: =_xlfn.XLOOKUP($B8,'PP2'!$C$6:$C$55,'PP2'!$B$6:$B$55,"") -> 3 | H8: =_xlfn.XLOOKUP(G8,'PP2'!$B$6:$B$55,'PP2'!$A$6:$A$55,0) -> 38.074617 | I8: =_xlfn.XLOOKUP($B8,'PP3'!$C$6:$C$55,'PP3'!$B$6:$B$55,"") -> 4 | J8: =_xlfn.XLOOKUP(I8,'PP3'!$B$6:$B$55,'PP3'!$A$6:$A$55,0) -> 17.793697 | K8: =_xlfn.XLOOKUP($B8,'PP4'!$C$6:$C$55,'PP4'!$B$6:$B$55,"") -> 3 | L8: =_xlfn.XLOOKUP(K8,'PP4'!$B$6:$B$55,'PP4'!$A$6:$A$55,0) -> 5.3267487 | M8: =_xlfn.XLOOKUP($B8,'PP5'!$C$6:$C$55,'PP5'!$B$6:$B$55,"") -> 3 | N8: =_xlfn.XLOOKUP(M8,'PP5'!$B$6:$B$55,'PP5'!$A$6:$A$55,0) -> 15.930622 | O8: =_xlfn.XLOOKUP(B8,MPW!C$6:C$55,MPW!B$6:B$55,"") -> 3 | P8: =_xlfn.XLOOKUP(O8,MPW!B$6:B$55,MPW!A$6:A$55,0) -> 38.018669
A9: =ROW()-5 -> 4 | B9: HAŚKO Sergiusz | D9: =SUM(F9,H9,J9,L9,N9,P9)-MIN(F9,H9,J9,L9,N9) -> 111.69168 | E9: =_xlfn.XLOOKUP($B9,'PP1'!$C$6:$C$55,'PP1'!$B$6:$B$55,"") -> 5 | F9: =_xlfn.XLOOKUP(E9,'PP1'!$B$6:$B$55,'PP1'!$A$6:$A$55,0) -> 5.9860243 | G9: =_xlfn.XLOOKUP($B9,'PP2'!$C$6:$C$55,'PP2'!$B$6:$B$55,"") -> 2 | H9: =_xlfn.XLOOKUP(G9,'PP2'!$B$6:$B$55,'PP2'!$A$6:$A$55,0) -> 74.023435 | I9: =_xlfn.XLOOKUP($B9,'PP3'!$C$6:$C$55,'PP3'!$B$6:$B$55,"") -> 3 | J9: =_xlfn.XLOOKUP(I9,'PP3'!$B$6:$B$55,'PP3'!$A$6:$A$55,0) -> 31.682224 | K9: =_xlfn.XLOOKUP($B9,'PP4'!$C$6:$C$55,'PP4'!$B$6:$B$55,"") | L9: =_xlfn.XLOOKUP(K9,'PP4'!$B$6:$B$55,'PP4'!$A$6:$A$55,0) -> 0 | M9: =_xlfn.XLOOKUP($B9,'PP5'!$C$6:$C$55,'PP5'!$B$6:$B$55,"") | N9: =_xlfn.XLOOKUP(M9,'PP5'!$B$6:$B$55,'PP5'!$A$6:$A$55,0) -> 0 | O9: =_xlfn.XLOOKUP(B9,MPW!C$6:C$55,MPW!B$6:B$55,"") | P9: =_xlfn.XLOOKUP(O9,MPW!B$6:B$55,MPW!A$6:A$55,0)
A10: =ROW()-5 -> 5 | B10: POŚPIESZNY Sławomir | D10: =SUM(F10,H10,J10,L10,N10,P10)-MIN(F10,H10,J10,L10,N10) -> 54.472714 | E10: =_xlfn.XLOOKUP($B10,'PP1'!$C$6:$C$55,'PP1'!$B$6:$B$55,"") -> 4 | F10: =_xlfn.XLOOKUP(E10,'PP1'!$B$6:$B$55,'PP1'!$A$6:$A$55,0) -> 35 | G10: =_xlfn.XLOOKUP($B10,'PP2'!$C$6:$C$55,'PP2'!$B$6:$B$55,"") -> 5 | H10: =_xlfn.XLOOKUP(G10,'PP2'!$B$6:$B$55,'PP2'!$A$6:$A$55,0) -> 19.472714 | I10: =_xlfn.XLOOKUP($B10,'PP3'!$C$6:$C$55,'PP3'!$B$6:$B$55,"") | J10: =_xlfn.XLOOKUP(I10,'PP3'!$B$6:$B$55,'PP3'!$A$6:$A$55,0) -> 0 | K10: =_xlfn.XLOOKUP($B10,'PP4'!$C$6:$C$55,'PP4'!$B$6:$B$55,"") | L10: =_xlfn.XLOOKUP(K10,'PP4'!$B$6:$B$55,'PP4'!$A$6:$A$55,0) -> 0 | M10: =_xlfn.XLOOKUP($B10,'PP5'!$C$6:$C$55,'PP5'!$B$6:$B$55,"") | N10: =_xlfn.XLOOKUP(M10,'PP5'!$B$6:$B$55,'PP5'!$A$6:$A$55,0) -> 0 | O10: =_xlfn.XLOOKUP(B10,MPW!C$6:C$55,MPW!B$6:B$55,"") | P10: =_xlfn.XLOOKUP(O10,MPW!B$6:B$55,MPW!A$6:A$55,0)
A11: =ROW()-5 -> 6 | B11: ŻUKOWSKI Wojciech | D11: =SUM(F11,H11,J11,L11,N11,P11)-MIN(F11,H11,J11,L11,N11) -> 25.352437 | E11: =_xlfn.XLOOKUP($B11,'PP1'!$C$6:$C$55,'PP1'!$B$6:$B$55,"") -> 6 | F11: =_xlfn.XLOOKUP(E11,'PP1'!$B$6:$B$55,'PP1'!$A$6:$A$55,0) -> 1 | G11: =_xlfn.XLOOKUP($B11,'PP2'!$C$6:$C$55,'PP2'!$B$6:$B$55,"") -> 7 | H11: =_xlfn.XLOOKUP(G11,'PP2'!$B$6:$B$55,'PP2'!$A$6:$A$55,0) -> 1 | I11: =_xlfn.XLOOKUP($B11,'PP3'!$C$6:$C$55,'PP3'!$B$6:$B$55,"") -> 5 | J11: =_xlfn.XLOOKUP(I11,'PP3'!$B$6:$B$55,'PP3'!$A$6:$A$55,0) -> 1 | K11: =_xlfn.XLOOKUP($B11,'PP4'!$C$6:$C$55,'PP4'!$B$6:$B$55,"") | L11: =_xlfn.XLOOKUP(K11,'PP4'!$B$6:$B$55,'PP4'!$A$6:$A$55,0) -> 0 | M11: =_xlfn.XLOOKUP($B11,'PP5'!$C$6:$C$55,'PP5'!$B$6:$B$55,"") -> 4 | N11: =_xlfn.XLOOKUP(M11,'PP5'!$B$6:$B$55,'PP5'!$A$6:$A$55,0) -> 1 | O11: =_xlfn.XLOOKUP(B11,MPW!C$6:C$55,MPW!B$6:B$55,"") -> 4 | P11: =_xlfn.XLOOKUP(O11,MPW!B$6:B$55,MPW!A$6:A$55,0) -> 21.352437
A12: =ROW()-5 -> 7 | B12: GWIAZDA Paweł | D12: =SUM(F12,H12,J12,L12,N12,P12)-MIN(F12,H12,J12,L12,N12) -> 14.881671 | E12: =_xlfn.XLOOKUP($B12,'PP1'!$C$6:$C$55,'PP1'!$B$6:$B$55,"") | F12: =_xlfn.XLOOKUP(E12,'PP1'!$B$6:$B$55,'PP1'!$A$6:$A$55,0) -> 0 | G12: =_xlfn.XLOOKUP($B12,'PP2'!$C$6:$C$55,'PP2'!$B$6:$B$55,"") -> 6 | H12: =_xlfn.XLOOKUP(G12,'PP2'!$B$6:$B$55,'PP2'!$A$6:$A$55,0) -> 14.881671 | I12: =_xlfn.XLOOKUP($B12,'PP3'!$C$6:$C$55,'PP3'!$B$6:$B$55,"") | J12: =_xlfn.XLOOKUP(I12,'PP3'!$B$6:$B$55,'PP3'!$A$6:$A$55,0) -> 0 | K12: =_xlfn.XLOOKUP($B12,'PP4'!$C$6:$C$55,'PP4'!$B$6:$B$55,"") | L12: =_xlfn.XLOOKUP(K12,'PP4'!$B$6:$B$55,'PP4'!$A$6:$A$55,0) -> 0 | M12: =_xlfn.XLOOKUP($B12,'PP5'!$C$6:$C$55,'PP5'!$B$6:$B$55,"") | N12: =_xlfn.XLOOKUP(M12,'PP5'!$B$6:$B$55,'PP5'!$A$6:$A$55,0) -> 0 | O12: =_xlfn.XLOOKUP(B12,MPW!C$6:C$55,MPW!B$6:B$55,"") | P12: =_xlfn.XLOOKUP(O12,MPW!B$6:B$55,MPW!A$6:A$55,0)
A13: =ROW()-5 -> 8 | B13: BOCHEŃSKI JACEK | D13: =SUM(F13,H13,J13,L13,N13,P13)-MIN(F13,H13,J13,L13,N13) -> 1.2 | E13: =_xlfn.XLOOKUP($B13,'PP1'!$C$6:$C$55,'PP1'!$B$6:$B$55,"") | F13: =_xlfn.XLOOKUP(E13,'PP1'!$B$6:$B$55,'PP1'!$A$6:$A$55,0) -> 0 | G13: =_xlfn.XLOOKUP($B13,'PP2'!$C$6:$C$55,'PP2'!$B$6:$B$55,"") | H13: =_xlfn.XLOOKUP(G13,'PP2'!$B$6:$B$55,'PP2'!$A$6:$A$55,0) -> 0 | I13: =_xlfn.XLOOKUP($B13,'PP3'!$C$6:$C$55,'PP3'!$B$6:$B$55,"") | J13: =_xlfn.XLOOKUP(I13,'PP3'!$B$6:$B$55,'PP3'!$A$6:$A$55,0) -> 0 | K13: =_xlfn.XLOOKUP($B13,'PP4'!$C$6:$C$55,'PP4'!$B$6:$B$55,"") | L13: =_xlfn.XLOOKUP(K13,'PP4'!$B$6:$B$55,'PP4'!$A$6:$A$55,0) -> 0 | M13: =_xlfn.XLOOKUP($B13,'PP5'!$C$6:$C$55,'PP5'!$B$6:$B$55,"") | N13: =_xlfn.XLOOKUP(M13,'PP5'!$B$6:$B$55,'PP5'!$A$6:$A$55,0) -> 0 | O13: =_xlfn.XLOOKUP(B13,MPW!C$6:C$55,MPW!B$6:B$55,"") -> 5 | P13: =_xlfn.XLOOKUP(O13,MPW!B$6:B$55,MPW!A$6:A$55,0) -> 1.2
A14: =ROW()-5 -> 9 | D14: =SUM(F14,H14,J14,L14,N14,P14)-MIN(F14,H14,J14,L14,N14) -> 0 | E14: =_xlfn.XLOOKUP($B14,'PP1'!$C$6:$C$55,'PP1'!$B$6:$B$55,"") | F14: =_xlfn.XLOOKUP(E14,'PP1'!$B$6:$B$55,'PP1'!$A$6:$A$55,0) -> 0 | G14: =_xlfn.XLOOKUP($B14,'PP2'!$C$6:$C$55,'PP2'!$B$6:$B$55,"") | H14: =_xlfn.XLOOKUP(G14,'PP2'!$B$6:$B$55,'PP2'!$A$6:$A$55,0) -> 0 | I14: =_xlfn.XLOOKUP($B14,'PP3'!$C$6:$C$55,'PP3'!$B$6:$B$55,"") | J14: =_xlfn.XLOOKUP(I14,'PP3'!$B$6:$B$55,'PP3'!$A$6:$A$55,0) -> 0 | K14: =_xlfn.XLOOKUP($B14,'PP4'!$C$6:$C$55,'PP4'!$B$6:$B$55,"") | L14: =_xlfn.XLOOKUP(K14,'PP4'!$B$6:$B$55,'PP4'!$A$6:$A$55,0) -> 0 | M14: =_xlfn.XLOOKUP($B14,'PP5'!$C$6:$C$55,'PP5'!$B$6:$B$55,"") | N14: =_xlfn.XLOOKUP(M14,'PP5'!$B$6:$B$55,'PP5'!$A$6:$A$55,0) -> 0 | O14: =_xlfn.XLOOKUP(B14,MPW!C$6:C$55,MPW!B$6:B$55,"") | P14: =_xlfn.XLOOKUP(O14,MPW!B$6:B$55,MPW!A$6:A$55,0)
A15: =ROW()-5 -> 10 | D15: =SUM(F15,H15,J15,L15,N15,P15)-MIN(F15,H15,J15,L15,N15) -> 0 | E15: =_xlfn.XLOOKUP($B15,'PP1'!$C$6:$C$55,'PP1'!$B$6:$B$55,"") | F15: =_xlfn.XLOOKUP(E15,'PP1'!$B$6:$B$55,'PP1'!$A$6:$A$55,0) -> 0 | G15: =_xlfn.XLOOKUP($B15,'PP2'!$C$6:$C$55,'PP2'!$B$6:$B$55,"") | H15: =_xlfn.XLOOKUP(G15,'PP2'!$B$6:$B$55,'PP2'!$A$6:$A$55,0) -> 0 | I15: =_xlfn.XLOOKUP($B15,'PP3'!$C$6:$C$55,'PP3'!$B$6:$B$55,"") | J15: =_xlfn.XLOOKUP(I15,'PP3'!$B$6:$B$55,'PP3'!$A$6:$A$55,0) -> 0 | K15: =_xlfn.XLOOKUP($B15,'PP4'!$C$6:$C$55,'PP4'!$B$6:$B$55,"") | L15: =_xlfn.XLOOKUP(K15,'PP4'!$B$6:$B$55,'PP4'!$A$6:$A$55,0) -> 0 | M15: =_xlfn.XLOOKUP($B15,'PP5'!$C$6:$C$55,'PP5'!$B$6:$B$55,"") | N15: =_xlfn.XLOOKUP(M15,'PP5'!$B$6:$B$55,'PP5'!$A$6:$A$55,0) -> 0 | O15: =_xlfn.XLOOKUP(B15,MPW!C$6:C$55,MPW!B$6:B$55,"") | P15: =_xlfn.XLOOKUP(O15,MPW!B$6:B$55,MPW!A$6:A$55,0)
A16: =ROW()-5 -> 11 | D16: =SUM(F16,H16,J16,L16,N16,P16)-MIN(F16,H16,J16,L16,N16) -> 0 | E16: =_xlfn.XLOOKUP($B16,'PP1'!$C$6:$C$55,'PP1'!$B$6:$B$55,"") | F16: =_xlfn.XLOOKUP(E16,'PP1'!$B$6:$B$55,'PP1'!$A$6:$A$55,0) -> 0 | G16: =_xlfn.XLOOKUP($B16,'PP2'!$C$6:$C$55,'PP2'!$B$6:$B$55,"") | H16: =_xlfn.XLOOKUP(G16,'PP2'!$B$6:$B$55,'PP2'!$A$6:$A$55,0) -> 0 | I16: =_xlfn.XLOOKUP($B16,'PP3'!$C$6:$C$55,'PP3'!$B$6:$B$55,"") | J16: =_xlfn.XLOOKUP(I16,'PP3'!$B$6:$B$55,'PP3'!$A$6:$A$55,0) -> 0 | K16: =_xlfn.XLOOKUP($B16,'PP4'!$C$6:$C$55,'PP4'!$B$6:$B$55,"") | L16: =_xlfn.XLOOKUP(K16,'PP4'!$B$6:$B$55,'PP4'!$A$6:$A$55,0) -> 0 | M16: =_xlfn.XLOOKUP($B16,'PP5'!$C$6:$C$55,'PP5'!$B$6:$B$55,"") | N16: =_xlfn.XLOOKUP(M16,'PP5'!$B$6:$B$55,'PP5'!$A$6:$A$55,0) -> 0 | O16: =_xlfn.XLOOKUP(B16,MPW!C$6:C$55,MPW!B$6:B$55,"") | P16: =_xlfn.XLOOKUP(O16,MPW!B$6:B$55,MPW!A$6:A$55,0)
A17: =ROW()-5 -> 12 | D17: =SUM(F17,H17,J17,L17,N17,P17)-MIN(F17,H17,J17,L17,N17) -> 0 | E17: =_xlfn.XLOOKUP($B17,'PP1'!$C$6:$C$55,'PP1'!$B$6:$B$55,"") | F17: =_xlfn.XLOOKUP(E17,'PP1'!$B$6:$B$55,'PP1'!$A$6:$A$55,0) -> 0 | G17: =_xlfn.XLOOKUP($B17,'PP2'!$C$6:$C$55,'PP2'!$B$6:$B$55,"") | H17: =_xlfn.XLOOKUP(G17,'PP2'!$B$6:$B$55,'PP2'!$A$6:$A$55,0) -> 0 | I17: =_xlfn.XLOOKUP($B17,'PP3'!$C$6:$C$55,'PP3'!$B$6:$B$55,"") | J17: =_xlfn.XLOOKUP(I17,'PP3'!$B$6:$B$55,'PP3'!$A$6:$A$55,0) -> 0 | K17: =_xlfn.XLOOKUP($B17,'PP4'!$C$6:$C$55,'PP4'!$B$6:$B$55,"") | L17: =_xlfn.XLOOKUP(K17,'PP4'!$B$6:$B$55,'PP4'!$A$6:$A$55,0) -> 0 | M17: =_xlfn.XLOOKUP($B17,'PP5'!$C$6:$C$55,'PP5'!$B$6:$B$55,"") | N17: =_xlfn.XLOOKUP(M17,'PP5'!$B$6:$B$55,'PP5'!$A$6:$A$55,0) -> 0 | O17: =_xlfn.XLOOKUP(B17,MPW!C$6:C$55,MPW!B$6:B$55,"") | P17: =_xlfn.XLOOKUP(O17,MPW!B$6:B$55,MPW!A$6:A$55,0)
A18: =ROW()-5 -> 13 | D18: =SUM(F18,H18,J18,L18,N18,P18)-MIN(F18,H18,J18,L18,N18) -> 0 | E18: =_xlfn.XLOOKUP($B18,'PP1'!$C$6:$C$55,'PP1'!$B$6:$B$55,"") | F18: =_xlfn.XLOOKUP(E18,'PP1'!$B$6:$B$55,'PP1'!$A$6:$A$55,0) -> 0 | G18: =_xlfn.XLOOKUP($B18,'PP2'!$C$6:$C$55,'PP2'!$B$6:$B$55,"") | H18: =_xlfn.XLOOKUP(G18,'PP2'!$B$6:$B$55,'PP2'!$A$6:$A$55,0) -> 0 | I18: =_xlfn.XLOOKUP($B18,'PP3'!$C$6:$C$55,'PP3'!$B$6:$B$55,"") | J18: =_xlfn.XLOOKUP(I18,'PP3'!$B$6:$B$55,'PP3'!$A$6:$A$55,0) -> 0 | K18: =_xlfn.XLOOKUP($B18,'PP4'!$C$6:$C$55,'PP4'!$B$6:$B$55,"") | L18: =_xlfn.XLOOKUP(K18,'PP4'!$B$6:$B$55,'PP4'!$A$6:$A$55,0) -> 0 | M18: =_xlfn.XLOOKUP($B18,'PP5'!$C$6:$C$55,'PP5'!$B$6:$B$55,"") | N18: =_xlfn.XLOOKUP(M18,'PP5'!$B$6:$B$55,'PP5'!$A$6:$A$55,0) -> 0 | O18: =_xlfn.XLOOKUP(B18,MPW!C$6:C$55,MPW!B$6:B$55,"") | P18: =_xlfn.XLOOKUP(O18,MPW!B$6:B$55,MPW!A$6:A$55,0)
A19: =ROW()-5 -> 14 | D19: =SUM(F19,H19,J19,L19,N19,P19)-MIN(F19,H19,J19,L19,N19) -> 0 | E19: =_xlfn.XLOOKUP($B19,'PP1'!$C$6:$C$55,'PP1'!$B$6:$B$55,"") | F19: =_xlfn.XLOOKUP(E19,'PP1'!$B$6:$B$55,'PP1'!$A$6:$A$55,0) -> 0 | G19: =_xlfn.XLOOKUP($B19,'PP2'!$C$6:$C$55,'PP2'!$B$6:$B$55,"") | H19: =_xlfn.XLOOKUP(G19,'PP2'!$B$6:$B$55,'PP2'!$A$6:$A$55,0) -> 0 | I19: =_xlfn.XLOOKUP($B19,'PP3'!$C$6:$C$55,'PP3'!$B$6:$B$55,"") | J19: =_xlfn.XLOOKUP(I19,'PP3'!$B$6:$B$55,'PP3'!$A$6:$A$55,0) -> 0 | K19: =_xlfn.XLOOKUP($B19,'PP4'!$C$6:$C$55,'PP4'!$B$6:$B$55,"") | L19: =_xlfn.XLOOKUP(K19,'PP4'!$B$6:$B$55,'PP4'!$A$6:$A$55,0) -> 0 | M19: =_xlfn.XLOOKUP($B19,'PP5'!$C$6:$C$55,'PP5'!$B$6:$B$55,"") | N19: =_xlfn.XLOOKUP(M19,'PP5'!$B$6:$B$55,'PP5'!$A$6:$A$55,0) -> 0 | O19: =_xlfn.XLOOKUP(B19,MPW!C$6:C$55,MPW!B$6:B$55,"") | P19: =_xlfn.XLOOKUP(O19,MPW!B$6:B$55,MPW!A$6:A$55,0)
A20: =ROW()-5 -> 15 | D20: =SUM(F20,H20,J20,L20,N20,P20)-MIN(F20,H20,J20,L20,N20) -> 0 | E20: =_xlfn.XLOOKUP($B20,'PP1'!$C$6:$C$55,'PP1'!$B$6:$B$55,"") | F20: =_xlfn.XLOOKUP(E20,'PP1'!$B$6:$B$55,'PP1'!$A$6:$A$55,0) -> 0 | G20: =_xlfn.XLOOKUP($B20,'PP2'!$C$6:$C$55,'PP2'!$B$6:$B$55,"") | H20: =_xlfn.XLOOKUP(G20,'PP2'!$B$6:$B$55,'PP2'!$A$6:$A$55,0) -> 0 | I20: =_xlfn.XLOOKUP($B20,'PP3'!$C$6:$C$55,'PP3'!$B$6:$B$55,"") | J20: =_xlfn.XLOOKUP(I20,'PP3'!$B$6:$B$55,'PP3'!$A$6:$A$55,0) -> 0 | K20: =_xlfn.XLOOKUP($B20,'PP4'!$C$6:$C$55,'PP4'!$B$6:$B$55,"") | L20: =_xlfn.XLOOKUP(K20,'PP4'!$B$6:$B$55,'PP4'!$A$6:$A$55,0) -> 0 | M20: =_xlfn.XLOOKUP($B20,'PP5'!$C$6:$C$55,'PP5'!$B$6:$B$55,"") | N20: =_xlfn.XLOOKUP(M20,'PP5'!$B$6:$B$55,'PP5'!$A$6:$A$55,0) -> 0 | O20: =_xlfn.XLOOKUP(B20,MPW!C$6:C$55,MPW!B$6:B$55,"") | P20: =_xlfn.XLOOKUP(O20,MPW!B$6:B$55,MPW!A$6:A$55,0)

Sheet PP1
H1: Liczba uczestników: | I1: GP Punkty | J1: Bonus za rundę | K1: Mnożnik za podium
B2: miejsce: | C2: KONIN | H2: 6 | I2: 50 | J2: 10 | K2: =3*H2^(1/3) -> 5.4513618
B3: data: | C3: 29.09.2024
A5: Punkty | B5: Miejsce Place | C5: Nazwisko Imię Name | D5: Klub Club(s) | E5: Okręg Division | F5: Państwo Country | H5: Miejsce | I5: Punkty za miejsce | J5: awans do kolejnej rundy pucharowej | K5: bonus za rundy pucharowe | L5: punkty za podium | M5: Suma
A6: =M6 -> 96.354085 | B6: =IF(H6>$H$2,"",(ROW()-5)) -> 1 | C6: TK | D6: KU AZS ASzWoj | F6: POL | H6: 1 | I6: =IF(H2=1,50,IF(H6<$H$2+1,($I$2-($I$2-1)*(LOG(H6)/LOG($H$2))),"")) -> 50 | J6: =INT(LOG($H$2,2))-ROUNDUP(LOG(H6,2),0)+IF(OR($H$2=1,$H$2=2,$H$2=4,$H$2=8,$H$2=16,$H$2=32,$H$2=64,$H$2=128,$H$2=256),0,1) -> 3 | K6: =J6*$J$2 -> 30 | L6: =3*K2 -> 16.354085 | M6: =IF(I6<>"",K6+I6+L6,0) -> 96.354085
A7: =M7 -> 61.946936 | B7: =IF(H7>$H$2,"",(ROW()-5)) -> 2 | C7: BAZAK Jacek | D7: UKS Floret Ruda Śląska | F7: POL | H7: 2 | I7: =IF(H7<$H$2+1,($I$2-($I$2-1)*(LOG(H7)/LOG($H$2))),"") -> 31.044212 | J7: =INT(LOG($H$2,2))-ROUNDUP(LOG(H7,2),0)+IF(OR($H$2=1,$H$2=2,$H$2=4,$H$2=8,$H$2=16,$H$2=32,$H$2=64,$H$2=128,$H$2=256),0,1) -> 2 | K7: =J7*$J$2 -> 20 | L7: =2*K2 -> 10.902724 | M7: =IF(I7<>"",K7+I7+L7,0) -> 61.946936
A8: =M8 -> 35.407149 | B8: =IF(H8>$H$2,"",(ROW()-5)) -> 3 | C8: SZMIDT Grzegorz | D8: Kolejarz Wrocław | F8: POL | H8: 3 | I8: =IF(H8<$H$2+1,($I$2-($I$2-1)*(LOG(H8)/LOG($H$2))),"") -> 19.955788 | J8: =INT(LOG($H$2,2))-ROUNDUP(LOG(H8,2),0)+IF(OR($H$2=1,$H$2=2,$H$2=4,$H$2=8,$H$2=16,$H$2=32,$H$2=64,$H$2=128,$H$2=256),0,1) -> 1 | K8: =J8*$J$2 -> 10 | L8: =K2 -> 5.4513618 | M8: =IF(I8<>"",K8+I8+L8,0) -> 35.407149
A9: 35 | B9: =IF(H9>$H$2,"",(ROW()-5)) -> 4 | C9: POŚPIESZNY Sławomir | D9: Kolejarz Wrocław | F9: POL | H9: 4 | I9: =IF(H9<$H$2+1,($I$2-($I$2-1)*(LOG(H9)/LOG($H$2))),"") -> 12.088425 | J9: =INT(LOG($H$2,2))-ROUNDUP(LOG(H9,2),0)+IF(OR($H$2=1,$H$2=2,$H$2=4,$H$2=8,$H$2=16,$H$2=32,$H$2=64,$H$2=128,$H$2=256),0,1) -> 1 | K9: =J9*$J$2 -> 10 | M9: =IF(I9<>"",K9+I9+L9,0) -> 22.088425 | AH9: x | AI9: 23
A10: =M10 -> 5.9860243 | B10: =IF(H10>$H$2,"",(ROW()-5)) -> 5 | C10: HAŚKO Sergiusz | D10: BTS Bytom | F10: POL | H10: 5 | I10: =IF(H10<$H$2+1,($I$2-($I$2-1)*(LOG(H10)/LOG($H$2))),"") -> 5.9860243 | J10: =INT(LOG($H$2,2))-ROUNDUP(LOG(H10,2),0)+IF(OR($H$2=1,$H$2=2,$H$2=4,$H$2=8,$H$2=16,$H$2=32,$H$2=64,$H$2=128,$H$2=256),0,1) -> 0 | K10: =J10*$J$2 -> 0 | M10: =IF(I10<>"",K10+I10+L10,0) -> 5.9860243 | AH10: N | AI10: 45
A11: =M11 -> 1 | B11: =IF(H11>$H$2,"",(ROW()-5)) -> 6 | C11: ŻUKOWSKI Wojciech | D11: Szczecińska Szkoła Szermiercza | F11: POL | H11: 6 | I11: =IF(H11<$H$2+1,($I$2-($I$2-1)*(LOG(H11)/LOG($H$2))),"") -> 1 | J11: =INT(LOG($H$2,2))-ROUNDUP(LOG(H11,2),0)+IF(OR($H$2=1,$H$2=2,$H$2=4,$H$2=8,$H$2=16,$H$2=32,$H$2=64,$H$2=128,$H$2=256),0,1) -> 0 | K11: =J11*$J$2 -> 0 | M11: =IF(I11<>"",K11+I11+L11,0) -> 1 | AH11: MP | AI11: 50
A12: =M12 -> 0 | B12: =IF(H12>$H$2,"",(ROW()-5)) | H12: 7 | I12: =IF(H12<$H$2+1,($I$2-($I$2-1)*(LOG(H12)/LOG($H$2))),"") | J12: =INT(LOG($H$2,2))-ROUNDUP(LOG(H12,2),0)+IF(OR($H$2=1,$H$2=2,$H$2=4,$H$2=8,$H$2=16,$H$2=32,$H$2=64,$H$2=128,$H$2=256),0,1) -> 0 | K12: =J12*$J$2 -> 0 | M12: =IF(I12<>"",K12+I12+L12,0) -> 0 | AH12: MP-1 | AI12: =AI11-1 -> 49
A13: =M13 -> 0 | B13: =IF(H13>$H$2,"",(ROW()-5)) | H13: 8 | I13: =IF(H13<$H$2+1,($I$2-($I$2-1)*(LOG(H13)/LOG($H$2))),"") | J13: =INT(LOG($H$2,2))-ROUNDUP(LOG(H13,2),0)+IF(OR($H$2=1,$H$2=2,$H$2=4,$H$2=8,$H$2=16,$H$2=32,$H$2=64,$H$2=128,$H$2=256),0,1) -> 0 | K13: =J13*$J$2 -> 0 | M13: =IF(I13<>"",K13+I13+L13,0) -> 0 | AH13: log(x) | AI13: =LOG(AI9) -> 1.3617278
A14: =M14 -> 0 | B14: =IF(H14>$H$2,"",(ROW()-5)) | H14: 9 | I14: =IF(H14<$H$2+1,($I$2-($I$2-1)*(LOG(H14)/LOG($H$2))),"") | J14: =INT(LOG($H$2,2))-ROUNDUP(LOG(H14,2),0)+IF(OR($H$2=1,$H$2=2,$H$2=4,$H$2=8,$H$2=16,$H$2=32,$H$2=64,$H$2=128,$H$2=256),0,1) -> -1 | K14: =J14*$J$2 -> -10 | M14: =IF(I14<>"",K14+I14+L14,0) -> 0 | AH14: Log(N) | AI14: =LOG(AI10) -> 1.6532125
A15: =M15 -> 0 | B15: =IF(H15>$H$2,"",(ROW()-5)) | H15: 10 | I15: =IF(H15<$H$2+1,($I$2-($I$2-1)*(LOG(H15)/LOG($H$2))),"") | J15: =INT(LOG($H$2,2))-ROUNDUP(LOG(H15,2),0)+IF(OR($H$2=1,$H$2=2,$H$2=4,$H$2=8,$H$2=16,$H$2=32,$H$2=64,$H$2=128,$H$2=256),0,1) -> -1 | K15: =J15*$J$2 -> -10 | M15: =IF(I15<>"",K15+I15+L15,0) -> 0
A16: =M16 -> 0 | B16: =IF(H16>$H$2,"",(ROW()-5)) | H16: 11 | I16: =IF(H16<$H$2+1,($I$2-($I$2-1)*(LOG(H16)/LOG($H$2))),"") | J16: =INT(LOG($H$2,2))-ROUNDUP(LOG(H16,2),0)+IF(OR($H$2=1,$H$2=2,$H$2=4,$H$2=8,$H$2=16,$H$2=32,$H$2=64,$H$2=128,$H$2=256),0,1) -> -1 | K16: =J16*$J$2 -> -10 | M16: =IF(I16<>"",K16+I16+L16,0) -> 0 | AH16: MP - (MP-1)*LOG(x)/LOG(N) | AI16: =AI11-AI12*AI13/AI14 -> 9.6393909 | AJ16: points
A17: =M17 -> 0 | B17: =IF(H17>$H$2,"",(ROW()-5)) | H17: 12 | I17: =IF(H17<$H$2+1,($I$2-($I$2-1)*(LOG(H17)/LOG($H$2))),"") | J17: =INT(LOG($H$2,2))-ROUNDUP(LOG(H17,2),0)+IF(OR($H$2=1,$H$2=2,$H$2=4,$H$2=8,$H$2=16,$H$2=32,$H$2=64,$H$2=128,$H$2=256),0,1) -> -1 | K17: =J17*$J$2 -> -10 | M17: =IF(I17<>"",K17+I17+L17,0) -> 0
A18: =M18 -> 0 | B18: =IF(H18>$H$2,"",(ROW()-5)) | H18: 13 | I18: =IF(H18<$H$2+1,($I$2-($I$2-1)*(LOG(H18)/LOG($H$2))),"") | J18: =INT(LOG($H$2,2))-ROUNDUP(LOG(H18,2),0)+IF(OR($H$2=1,$H$2=2,$H$2=4,$H$2=8,$H$2=16,$H$2=32,$H$2=64,$H$2=128,$H$2=256),0,1) -> -1 | K18: =J18*$J$2 -> -10 | M18: =IF(I18<>"",K18+I18+L18,0) -> 0
A19: =M19 -> 0 | B19: =IF(H19>$H$2,"",(ROW()-5)) | H19: 14 | I19: =IF(H19<$H$2+1,($I$2-($I$2-1)*(LOG(H19)/LOG($H$2))),"") | J19: =INT(LOG($H$2,2))-ROUNDUP(LOG(H19,2),0)+IF(OR($H$2=1,$H$2=2,$H$2=4,$H$2=8,$H$2=16,$H$2=32,$H$2=64,$H$2=128,$H$2=256),0,1) -> -1 | K19: =J19*$J$2 -> -10 | M19: =IF(I19<>"",K19+I19+L19,0) -> 0
A20: =M20 -> 0 | B20: =IF(H20>$H$2,"",(ROW()-5)) | H20: 15 | I20: =IF(H20<$H$2+1,($I$2-($I$2-1)*(LOG(H20)/LOG($H$2))),"") | J20: =INT(LOG($H$2,2))-ROUNDUP(LOG(H20,2),0)+IF(OR($H$2=1,$H$2=2,$H$2=4,$H$2=8,$H$2=16,$H$2=32,$H$2=64,$H$2=128,$H$2=256),0,1) -> -1 | K20: =J20*$J$2 -> -10 | M20: =IF(I20<>"",K20+I20+L20,0) -> 0
A21: =M21 -> 0 | B21: =IF(H21>$H$2,"",(ROW()-5)) | H21: 16 | I21: =IF(H21<$H$2+1,($I$2-($I$2-1)*(LOG(H21)/LOG($H$2))),"") | J21: =INT(LOG($H$2,2))-ROUNDUP(LOG(H21,2),0)+IF(OR($H$2=1,$H$2=2,$H$2=4,$H$2=8,$H$2=16,$H$2=32,$H$2=64,$H$2=128,$H$2=256),0,1) -> -1 | K21: =J21*$J$2 -> -10 | M21: =IF(I21<>"",K21+I21+L21,0) -> 0
A22: =M22 -> 0 | B22: =IF(H22>$H$2,"",(ROW()-5)) | H22: 17 | I22: =IF(H22<$H$2+1,($I$2-($I$2-1)*(LOG(H22)/LOG($H$2))),"") | J22: =INT(LOG($H$2,2))-ROUNDUP(LOG(H22,2),0)+IF(OR($H$2=1,$H$2=2,$H$2=4,$H$2=8,$H$2=16,$H$2=32,$H$2=64,$H$2=128,$H$2=256),0,1) -> -2 | K22: =J22*$J$2 -> -20 | M22: =IF(I22<>"",K22+I22+L22,0) -> 0
A23: =M23 -> 0 | B23: =IF(H23>$H$2,"",(ROW()-5)) | H23: 18 | I23: =IF(H23<$H$2+1,($I$2-($I$2-1)*(LOG(H23)/LOG($H$2))),"") | J23: =INT(LOG($H$2,2))-ROUNDUP(LOG(H23,2),0)+IF(OR($H$2=1,$H$2=2,$H$2=4,$H$2=8,$H$2=16,$H$2=32,$H$2=64,$H$2=128,$H$2=256),0,1) -> -2 | K23: =J23*$J$2 -> -20 | M23: =IF(I23<>"",K23+I23+L23,0) -> 0
A24: =M24 -> 0 | B24: =IF(H24>$H$2,"",(ROW()-5)) | H24: 19 | I24: =IF(H24<$H$2+1,($I$2-($I$2-1)*(LOG(H24)/LOG($H$2))),"") | J24: =INT(LOG($H$2,2))-ROUNDUP(LOG(H24,2),0)+IF(OR($H$2=1,$H$2=2,$H$2=4,$H$2=8,$H$2=16,$H$2=32,$H$2=64,$H$2=128,$H$2=256),0,1) -> -2 | K24: =J24*$J$2 -> -20 | M24: =IF(I24<>"",K24+I24+L24,0) -> 0
A25: =M25 -> 0 | B25: =IF(H25>$H$2,"",(ROW()-5)) | H25: 20 | I25: =IF(H25<$H$2+1,($I$2-($I$2-1)*(LOG(H25)/LOG($H$2))),"") | J25: =INT(LOG($H$2,2))-ROUNDUP(LOG(H25,2),0)+IF(OR($H$2=1,$H$2=2,$H$2=4,$H$2=8,$H$2=16,$H$2=32,$H$2=64,$H$2=128,$H$2=256),0,1) -> -2 | K25: =J25*$J$2 -> -20 | M25: =IF(I25<>"",K25+I25+L25,0) -> 0
A26: =M26 -> 0 | B26: =IF(H26>$H$2,"",(ROW()-5)) | H26: 21 | I26: =IF(H26<$H$2+1,($I$2-($I$2-1)*(LOG(H26)/LOG($H$2))),"") | J26: =INT(LOG($H$2,2))-ROUNDUP(LOG(H26,2),0)+IF(OR($H$2=1,$H$2=2,$H$2=4,$H$2=8,$H$2=16,$H$2=32,$H$2=64,$H$2=128,$H$2=256),0,1) -> -2 | K26: =J26*$J$2 -> -20 | M26: =IF(I26<>"",K26+I26+L26,0) -> 0
A27: =M27 -> 0 | B27: =IF(H27>$H$2,"",(ROW()-5)) | H27: 22 | I27: =IF(H27<$H$2+1,($I$2-($I$2-1)*(LOG(H27)/LOG($H$2))),"") | J27: =INT(LOG($H$2,2))-ROUNDUP(LOG(H27,2),0)+IF(OR($H$2=1,$H$2=2,$H$2=4,$H$2=8,$H$2=16,$H$2=32,$H$2=64,$H$2=128,$H$2=256),0,1) -> -2 | K27: =J27*$J$2 -> -20 | M27: =IF(I27<>"",K27+I27+L27,0) -> 0
A28: =M28 -> 0 | B28: =IF(H28>$H$2,"",(ROW()-5)) | H28: 23 | I28: =IF(H28<$H$2+1,($I$2-($I$2-1)*(LOG(H28)/LOG($H$2))),"") | J28: =INT(LOG($H$2,2))-ROUNDUP(LOG(H28,2),0)+IF(OR($H$2=1,$H$2=2,$H$2=4,$H$2=8,$H$2=16,$H$2=32,$H$2=64,$H$2=128,$H$2=256),0,1) -> -2 | K28: =J28*$J$2 -> -20 | M28: =IF(I28<>"",K28+I28+L28,0) -> 0
... A37: =M37 -> 0 | B37: =IF(H37>$H$2,"",(ROW()-5)) | H37: 32 | I37: =IF(H37<$H$2+1,($I$2-($I$2-1)*(LOG(H37)/LOG($H$2))),"") | J37: =INT(LOG($H$2,2))-ROUNDUP(LOG(H37,2),0)+IF(OR($H$2=1,$H$2=2,$H$2=4,$H$2=8,$H$2=16,$H$2=32,$H$2=64,$H$2=128,$H$2=256),0,1) -> -2 | K37: =J37*$J$2 -> -20 | M37: =IF(I37<>"",K37+I37+L37,0) -> 0
B38: =IF(H38>$H$2,"",(ROW()-5)) | H38: 33 | I38: =IF(H38<$H$2+1,($I$2-($I$2-1)*(LOG(H38)/LOG($H$2))),"") | J38: =INT(LOG($H$2,2))-ROUNDUP(LOG(H38,2),0)+IF(OR($H$2=1,$H$2=2,$H$2=4,$H$2=8,$H$2=16,$H$2=32,$H$2=64,$H$2=128,$H$2=256),0,1) -> -3 | K38: =J38*$J$2 -> -30 | M38: =IF(I38<>"",K38+I38+L38,0) -> 0
B39: =IF(H39>$H$2,"",(ROW()-5)) | H39: 34 | I39: =IF(H39<$H$2+1,($I$2-($I$2-1)*(LOG(H39)/LOG($H$2))),"") | J39: =INT(LOG($H$2,2))-ROUNDUP(LOG(H39,2),0)+IF(OR($H$2=1,$H$2=2,$H$2=4,$H$2=8,$H$2=16,$H$2=32,$H$2=64,$H$2=128,$H$2=256),0,1) -> -3 | K39: =J39*$J$2 -> -30 | M39: =IF(I39<>"",K39+I39+L39,0) -> 0
B40: =IF(H40>$H$2,"",(ROW()-5)) | H40: 35 | I40: =IF(H40<$H$2+1,($I$2-($I$2-1)*(LOG(H40)/LOG($H$2))),"") | J40: =INT(LOG($H$2,2))-ROUNDUP(LOG(H40,2),0)+IF(OR($H$2=1,$H$2=2,$H$2=4,$H$2=8,$H$2=16,$H$2=32,$H$2=64,$H$2=128,$H$2=256),0,1) -> -3 | K40: =J40*$J$2 -> -30 | M40: =IF(I40<>"",K40+I40+L40,0) -> 0
B41: =IF(H41>$H$2,"",(ROW()-5)) | H41: 36 | I41: =IF(H41<$H$2+1,($I$2-($I$2-1)*(LOG(H41)/LOG($H$2))),"") | J41: =INT(LOG($H$2,2))-ROUNDUP(LOG(H41,2),0)+IF(OR($H$2=1,$H$2=2,$H$2=4,$H$2=8,$H$2=16,$H$2=32,$H$2=64,$H$2=128,$H$2=256),0,1) -> -3 | K41: =J41*$J$2 -> -30 | M41: =IF(I41<>"",K41+I41+L41,0) -> 0
B42: =IF(H42>$H$2,"",(ROW()-5)) | H42: 37 | I42: =IF(H42<$H$2+1,($I$2-($I$2-1)*(LOG(H42)/LOG($H$2))),"") | J42: =INT(LOG($H$2,2))-ROUNDUP(LOG(H42,2),0)+IF(OR($H$2=1,$H$2=2,$H$2=4,$H$2=8,$H$2=16,$H$2=32,$H$2=64,$H$2=128,$H$2=256),0,1) -> -3 | K42: =J42*$J$2 -> -30 | M42: =IF(I42<>"",K42+I42+L42,0) -> 0
B43: =IF(H43>$H$2,"",(ROW()-5)) | H43: 38 | I43: =IF(H43<$H$2+1,($I$2-($I$2-1)*(LOG(H43)/LOG($H$2))),"") | J43: =INT(LOG($H$2,2))-ROUNDUP(LOG(H43,2),0)+IF(OR($H$2=1,$H$2=2,$H$2=4,$H$2=8,$H$2=16,$H$2=32,$H$2=64,$H$2=128,$H$2=256),0,1) -> -3 | K43: =J43*$J$2 -> -30 | M43: =IF(I43<>"",K43+I43+L43,0) -> 0
B44: =IF(H44>$H$2,"",(ROW()-5)) | H44: 39 | I44: =IF(H44<$H$2+1,($I$2-($I$2-1)*(LOG(H44)/LOG($H$2))),"") | J44: =INT(LOG($H$2,2))-ROUNDUP(LOG(H44,2),0)+IF(OR($H$2=1,$H$2=2,$H$2=4,$H$2=8,$H$2=16,$H$2=32,$H$2=64,$H$2=128,$H$2=256),0,1) -> -3 | K44: =J44*$J$2 -> -30 | M44: =IF(I44<>"",K44+I44+L44,0) -> 0
B45: =IF(H45>$H$2,"",(ROW()-5)) | H45: 40 | I45: =IF(H45<$H$2+1,($I$2-($I$2-1)*(LOG(H45)/LOG($H$2))),"") | J45: =INT(LOG($H$2,2))-ROUNDUP(LOG(H45,2),0)+IF(OR($H$2=1,$H$2=2,$H$2=4,$H$2=8,$H$2=16,$H$2=32,$H$2=64,$H$2=128,$H$2=256),0,1) -> -3 | K45: =J45*$J$2 -> -30 | M45: =IF(I45<>"",K45+I45+L45,0) -> 0
B46: =IF(H46>$H$2,"",(ROW()-5)) | H46: 41 | I46: =IF(H46<$H$2+1,($I$2-($I$2-1)*(LOG(H46)/LOG($H$2))),"") | J46: =INT(LOG($H$2,2))-ROUNDUP(LOG(H46,2),0)+IF(OR($H$2=1,$H$2=2,$H$2=4,$H$2=8,$H$2=16,$H$2=32,$H$2=64,$H$2=128,$H$2=256),0,1) -> -3 | K46: =J46*$J$2 -> -30 | M46: =IF(I46<>"",K46+I46+L46,0) -> 0 | R46: =LOG($H$2,2) -> 2.5849625 | T46: =LOG(H38,2) -> 5.0443941 | U46: =R46-T46 -> -2.4594316
B47: =IF(H47>$H$2,"",(ROW()-5)) | H47: 42 | I47: =IF(H47<$H$2+1,($I$2-($I$2-1)*(LOG(H47)/LOG($H$2))),"") | J47: =INT(LOG($H$2,2))-ROUNDUP(LOG(H47,2),0)+IF(OR($H$2=1,$H$2=2,$H$2=4,$H$2=8,$H$2=16,$H$2=32,$H$2=64,$H$2=128,$H$2=256),0,1) -> -3 | K47: =J47*$J$2 -> -30 | M47: =IF(I47<>"",K47+I47+L47,0) -> 0
B48: =IF(H48>$H$2,"",(ROW()-5)) | H48: 43 | I48: =IF(H48<$H$2+1,($I$2-($I$2-1)*(LOG(H48)/LOG($H$2))),"") | J48: =INT(LOG($H$2,2))-ROUNDUP(LOG(H48,2),0)+IF(OR($H$2=1,$H$2=2,$H$2=4,$H$2=8,$H$2=16,$H$2=32,$H$2=64,$H$2=128,$H$2=256),0,1) -> -3 | K48: =J48*$J$2 -> -30 | M48: =IF(I48<>"",K48+I48+L48,0) -> 0
B49: =IF(H49>$H$2,"",(ROW()-5)) | H49: 44 | I49: =IF(H49<$H$2+1,($I$2-($I$2-1)*(LOG(H49)/LOG($H$2))),"") | J49: =INT(LOG($H$2,2))-ROUNDUP(LOG(H49,2),0)+IF(OR($H$2=1,$H$2=2,$H$2=4,$H$2=8,$H$2=16,$H$2=32,$H$2=64,$H$2=128,$H$2=256),0,1) -> -3 | K49: =J49*$J$2 -> -30 | M49: =IF(I49<>"",K49+I49+L49,0) -> 0
...

Sheet PP2
H1: Liczba uczestników: | I1: GP Punkty | J1: Bonus za rundę | K1: Mnożnik za podium
B2: miejsce: | C2: BYTOM | H2: 7 | I2: 50 | J2: 10 | K2: =3*H2^(1/3) -> 5.7387935
B3: data: | C3: 27.10.2024
A5: Punkty | B5: Miejsce Place | C5: Nazwisko Imię Name | D5: Klub Club(s) | E5: Okręg Division | F5: Państwo Country | H5: Miejsce | I5: Punkty za miejsce | J5: awans do kolejnej rundy pucharowej | K5: bonus za rundy pucharowe | L5: punkty za podium | M5: Suma | O5: Miejsce Place | P5: Nazwisko Imię Name | Q5: awans do kolejnej rundy pucharowej | R5: bonus za rundy pucharowe
A6: =M6 -> 107.21638 | B6: =IF(H6>$H$2,"",(ROW()-5)) -> 1 | C6: TK | D6: KU AZS ASZWOJ | E6: POL | H6: 1 | I6: =IF(H2=1,50,IF(H6<$H$2+1,($I$2-($I$2-1)*(LOG(H6)/LOG($H$2))),"")) -> 50 | J6: 4 | K6: =J6*$J$2 -> 40 | L6: =3*K2 -> 17.216381 | M6: =IF(I6<>"",K6+I6+L6,0) -> 107.21638 | O6: 1 | P6: KOŃCZYŁO Tomasz (2) | Q6: 4 | R6: 40
A7: =M7 -> 74.023435 | B7: =IF(H7>$H$2,"",(ROW()-5)) -> 2 | C7: HAŚKO Sergiusz | D7: BYTOMSKIE TOWARZYSTWO SZERMIERCZE | E7: POL | H7: 2 | I7: =IF(H7<$H$2+1,($I$2-($I$2-1)*(LOG(H7)/LOG($H$2))),"") -> 32.545848 | J7: 3 | K7: =J7*$J$2 -> 30 | L7: =2*K2 -> 11.477587 | M7: =IF(I7<>"",K7+I7+L7,0) -> 74.023435 | O7: 2 | P7: HAŚKO Sergiusz (2) | Q7: 3 | R7: 30
A8: =M8 -> 38.074617 | B8: =IF(H8>$H$2,"",(ROW()-5)) -> 3 | C8: BAZAK Jacek | D8: AKS MIKOŁÓW | E8: POL | H8: 3 | I8: =IF(H8<$H$2+1,($I$2-($I$2-1)*(LOG(H8)/LOG($H$2))),"") -> 22.335823 | J8: =INT(LOG($H$2,2))-ROUNDUP(LOG(H8,2),0)+IF(OR($H$2=1,$H$2=2,$H$2=4,$H$2=8,$H$2=16,$H$2=32,$H$2=64,$H$2=128,$H$2=256),0,1) -> 1 | K8: =J8*$J$2 -> 10 | L8: =K2 -> 5.7387935 | M8: =IF(I8<>"",K8+I8+L8,0) -> 38.074617 | O8: 3 | P8: NIKALAICHUK Aliaksandr (3) | Q8: 2 | R8: 20
A9: =M9 -> 25.091696 | B9: =IF(H9>$H$2,"",(ROW()-5)) -> 4 | C9: SZMIDT Grzegorz | D9: WKS KOLEJARZ WROCŁAW | E9: POL | H9: 4 | I9: =IF(H9<$H$2+1,($I$2-($I$2-1)*(LOG(H9)/LOG($H$2))),"") -> 15.091696 | J9: =INT(LOG($H$2,2))-ROUNDUP(LOG(H9,2),0)+IF(OR($H$2=1,$H$2=2,$H$2=4,$H$2=8,$H$2=16,$H$2=32,$H$2=64,$H$2=128,$H$2=256),0,1) -> 1 | K9: =J9*$J$2 -> 10 | M9: =IF(I9<>"",K9+I9+L9,0) -> 25.091696 | O9: 4 | P9: POKRZYWA Mariusz (3) | Q9: 2 | R9: 20 | AH9: x | AI9: 23
A10: =M10 -> 19.472714 | B10: =IF(H10>$H$2,"",(ROW()-5)) -> 5 | C10: POŚPIESZNY Sławomir | D10: WKS KOLEJARZ WROCŁAW | E10: POL | H10: 5 | I10: =IF(H10<$H$2+1,($I$2-($I$2-1)*(LOG(H10)/LOG($H$2))),"") -> 9.4727137 | J10: 1 | K10: =J10*$J$2 -> 10 | M10: =IF(I10<>"",K10+I10+L10,0) -> 19.472714 | O10: 5 | P10: BAZAK Jacek (2) | Q10: 1 | R10: 10 | AH10: N | AI10: 45
A11: =M11 -> 14.881671 | B11: =IF(H11>$H$2,"",(ROW()-5)) -> 6 | C11: GWIAZDA Paweł | D11: PTG SOKÓŁ 1893 MIELEC | E11: POL | H11: 6 | I11: =IF(H11<$H$2+1,($I$2-($I$2-1)*(LOG(H11)/LOG($H$2))),"") -> 4.8816712 | J11: 1 | K11: =J11*$J$2 -> 10 | M11: =IF(I11<>"",K11+I11+L11,0) -> 14.881671 | O11: 6 | P11: SZMIDT Grzegorz (2) | Q11: 1 | R11: 10 | AH11: MP | AI11: 50
A12: =M12 -> 1 | B12: =IF(H12>$H$2,"",(ROW()-5)) -> 7 | C12: ŻUKOWSKI Wojciech | D12: Szczecińska Szkoła Szermierki | E12: POL | H12: 7 | I12: =IF(H12<$H$2+1,($I$2-($I$2-1)*(LOG(H12)/LOG($H$2))),"") -> 1 | J12: =INT(LOG($H$2,2))-ROUNDUP(LOG(H12,2),0)+IF(OR($H$2=1,$H$2=2,$H$2=4,$H$2=8,$H$2=16,$H$2=32,$H$2=64,$H$2=128,$H$2=256),0,1) -> 0 | K12: =J12*$J$2 -> 0 | M12: =IF(I12<>"",K12+I12+L12,0) -> 1 | O12: 7 | P12: POŚPIESZNY Sławomir (2) | Q12: 1 | R12: 10 | AH12: MP-1 | AI12: =AI11-1 -> 49
A13: =M13 -> 0 | B13: =IF(H13>$H$2,"",(ROW()-5)) | H13: 8 | I13: =IF(H13<$H$2+1,($I$2-($I$2-1)*(LOG(H13)/LOG($H$2))),"") | J13: =INT(LOG($H$2,2))-ROUNDUP(LOG(H13,2),0)+IF(OR($H$2=1,$H$2=2,$H$2=4,$H$2=8,$H$2=16,$H$2=32,$H$2=64,$H$2=128,$H$2=256),0,1) -> 0 | K13: =J13*$J$2 -> 0 | M13: =IF(I13<>"",K13+I13+L13,0) -> 0 | O13: 8 | P13: GWIAZDA Paweł (2) | Q13: 1 | R13: 10 | AH13: log(x) | AI13: =LOG(AI9) -> 1.3617278
A14: =M14 -> 0 | B14: =IF(H14>$H$2,"",(ROW()-5)) | H14: 9 | I14: =IF(H14<$H$2+1,($I$2-($I$2-1)*(LOG(H14)/LOG($H$2))),"") | J14: =INT(LOG($H$2,2))-ROUNDUP(LOG(H14,2),0)+IF(OR($H$2=1,$H$2=2,$H$2=4,$H$2=8,$H$2=16,$H$2=32,$H$2=64,$H$2=128,$H$2=256),0,1) -> -1 | K14: =J14*$J$2 -> -10 | M14: =IF(I14<>"",K14+I14+L14,0) -> 0 | O14: 9 | P14: ŻUKOWSKI Wojciech (2) | Q14: 0 | R14: 0 | AH14: Log(N) | AI14: =LOG(AI10) -> 1.6532125
A15: =M15 -> 0 | B15: =IF(H15>$H$2,"",(ROW()-5)) | H15: 10 | I15: =IF(H15<$H$2+1,($I$2-($I$2-1)*(LOG(H15)/LOG($H$2))),"") | J15: =INT(LOG($H$2,2))-ROUNDUP(LOG(H15,2),0)+IF(OR($H$2=1,$H$2=2,$H$2=4,$H$2=8,$H$2=16,$H$2=32,$H$2=64,$H$2=128,$H$2=256),0,1) -> -1 | K15: =J15*$J$2 -> -10 | M15: =IF(I15<>"",K15+I15+L15,0) -> 0
A16: =M16 -> 0 | B16: =IF(H16>$H$2,"",(ROW()-5)) | H16: 11 | I16: =IF(H16<$H$2+1,($I$2-($I$2-1)*(LOG(H16)/LOG($H$2))),"") | J16: =INT(LOG($H$2,2))-ROUNDUP(LOG(H16,2),0)+IF(OR($H$2=1,$H$2=2,$H$2=4,$H$2=8,$H$2=16,$H$2=32,$H$2=64,$H$2=128,$H$2=256),0,1) -> -1 | K16: =J16*$J$2 -> -10 | M16: =IF(I16<>"",K16+I16+L16,0) -> 0 | AH16: MP - (MP-1)*LOG(x)/LOG(N) | AI16: =AI11-AI12*AI13/AI14 -> 9.6393909 | AJ16: points
A17: =M17 -> 0 | B17: =IF(H17>$H$2,"",(ROW()-5)) | H17: 12 | I17: =IF(H17<$H$2+1,($I$2-($I$2-1)*(LOG(H17)/LOG($H$2))),"") | J17: =INT(LOG($H$2,2))-ROUNDUP(LOG(H17,2),0)+IF(OR($H$2=1,$H$2=2,$H$2=4,$H$2=8,$H$2=16,$H$2=32,$H$2=64,$H$2=128,$H$2=256),0,1) -> -1 | K17: =J17*$J$2 -> -10 | M17: =IF(I17<>"",K17+I17+L17,0) -> 0
A18: =M18 -> 0 | B18: =IF(H18>$H$2,"",(ROW()-5)) | H18: 13 | I18: =IF(H18<$H$2+1,($I$2-($I$2-1)*(LOG(H18)/LOG($H$2))),"") | J18: =INT(LOG($H$2,2))-ROUNDUP(LOG(H18,2),0)+IF(OR($H$2=1,$H$2=2,$H$2=4,$H$2=8,$H$2=16,$H$2=32,$H$2=64,$H$2=128,$H$2=256),0,1) -> -1 | K18: =J18*$J$2 -> -10 | M18: =IF(I18<>"",K18+I18+L18,0) -> 0
A19: =M19 -> 0 | B19: =IF(H19>$H$2,"",(ROW()-5)) | H19: 14 | I19: =IF(H19<$H$2+1,($I$2-($I$2-1)*(LOG(H19)/LOG($H$2))),"") | J19: =INT(LOG($H$2,2))-ROUNDUP(LOG(H19,2),0)+IF(OR($H$2=1,$H$2=2,$H$2=4,$H$2=8,$H$2=16,$H$2=32,$H$2=64,$H$2=128,$H$2=256),0,1) -> -1 | K19: =J19*$J$2 -> -10 | M19: =IF(I19<>"",K19+I19+L19,0) -> 0
A20: =M20 -> 0 | B20: =IF(H20>$H$2,"",(ROW()-5)) | H20: 15 | I20: =IF(H20<$H$2+1,($I$2-($I$2-1)*(LOG(H20)/LOG($H$2))),"") | J20: =INT(LOG($H$2,2))-ROUNDUP(LOG(H20,2),0)+IF(OR($H$2=1,$H$2=2,$H$2=4,$H$2=8,$H$2=16,$H$2=32,$H$2=64,$H$2=128,$H$2=256),0,1) -> -1 | K20: =J20*$J$2 -> -10 | M20: =IF(I20<>"",K20+I20+L20,0) -> 0
A21: =M21 -> 0 | B21: =IF(H21>$H$2,"",(ROW()-5)) | H21: 16 | I21: =IF(H21<$H$2+1,($I$2-($I$2-1)*(LOG(H21)/LOG($H$2))),"") | J21: =INT(LOG($H$2,2))-ROUNDUP(LOG(H21,2),0)+IF(OR($H$2=1,$H$2=2,$H$2=4,$H$2=8,$H$2=16,$H$2=32,$H$2=64,$H$2=128,$H$2=256),0,1) -> -1 | K21: =J21*$J$2 -> -10 | M21: =IF(I21<>"",K21+I21+L21,0) -> 0
A22: =M22 -> 0 | B22: =IF(H22>$H$2,"",(ROW()-5)) | H22: 17 | I22: =IF(H22<$H$2+1,($I$2-($I$2-1)*(LOG(H22)/LOG($H$2))),"") | J22: =INT(LOG($H$2,2))-ROUNDUP(LOG(H22,2),0)+IF(OR($H$2=1,$H$2=2,$H$2=4,$H$2=8,$H$2=16,$H$2=32,$H$2=64,$H$2=128,$H$2=256),0,1) -> -2 | K22: =J22*$J$2 -> -20 | M22: =IF(I22<>"",K22+I22+L22,0) -> 0
A23: =M23 -> 0 | B23: =IF(H23>$H$2,"",(ROW()-5)) | H23: 18 | I23: =IF(H23<$H$2+1,($I$2-($I$2-1)*(LOG(H23)/LOG($H$2))),"") | J23: =INT(LOG($H$2,2))-ROUNDUP(LOG(H23,2),0)+IF(OR($H$2=1,$H$2=2,$H$2=4,$H$2=8,$H$2=16,$H$2=32,$H$2=64,$H$2=128,$H$2=256),0,1) -> -2 | K23: =J23*$J$2 -> -20 | M23: =IF(I23<>"",K23+I23+L23,0) -> 0
A24: =M24 -> 0 | B24: =IF(H24>$H$2,"",(ROW()-5)) | H24: 19 | I24: =IF(H24<$H$2+1,($I$2-($I$2-1)*(LOG(H24)/LOG($H$2))),"") | J24: =INT(LOG($H$2,2))-ROUNDUP(LOG(H24,2),0)+IF(OR($H$2=1,$H$2=2,$H$2=4,$H$2=8,$H$2=16,$H$2=32,$H$2=64,$H$2=128,$H$2=256),0,1) -> -2 | K24: =J24*$J$2 -> -20 | M24: =IF(I24<>"",K24+I24+L24,0) -> 0
A25: =M25 -> 0 | B25: =IF(H25>$H$2,"",(ROW()-5)) | H25: 20 | I25: =IF(H25<$H$2+1,($I$2-($I$2-1)*(LOG(H25)/LOG($H$2))),"") | J25: =INT(LOG($H$2,2))-ROUNDUP(LOG(H25,2),0)+IF(OR($H$2=1,$H$2=2,$H$2=4,$H$2=8,$H$2=16,$H$2=32,$H$2=64,$H$2=128,$H$2=256),0,1) -> -2 | K25: =J25*$J$2 -> -20 | M25: =IF(I25<>"",K25+I25+L25,0) -> 0
A26: =M26 -> 0 | B26: =IF(H26>$H$2,"",(ROW()-5)) | H26: 21 | I26: =IF(H26<$H$2+1,($I$2-($I$2-1)*(LOG(H26)/LOG($H$2))),"") | J26: =INT(LOG($H$2,2))-ROUNDUP(LOG(H26,2),0)+IF(OR($H$2=1,$H$2=2,$H$2=4,$H$2=8,$H$2=16,$H$2=32,$H$2=64,$H$2=128,$H$2=256),0,1) -> -2 | K26: =J26*$J$2 -> -20 | M26: =IF(I26<>"",K26+I26+L26,0) -> 0
A27: =M27 -> 0 | B27: =IF(H27>$H$2,"",(ROW()-5)) | H27: 22 | I27: =IF(H27<$H$2+1,($I$2-($I$2-1)*(LOG(H27)/LOG($H$2))),"") | J27: =INT(LOG($H$2,2))-ROUNDUP(LOG(H27,2),0)+IF(OR($H$2=1,$H$2=2,$H$2=4,$H$2=8,$H$2=16,$H$2=32,$H$2=64,$H$2=128,$H$2=256),0,1) -> -2 | K27: =J27*$J$2 -> -20 | M27: =IF(I27<>"",K27+I27+L27,0) -> 0
A28: =M28 -> 0 | B28: =IF(H28>$H$2,"",(ROW()-5)) | H28: 23 | I28: =IF(H28<$H$2+1,($I$2-($I$2-1)*(LOG(H28)/LOG($H$2))),"") | J28: =INT(LOG($H$2,2))-ROUNDUP(LOG(H28,2),0)+IF(OR($H$2=1,$H$2=2,$H$2=4,$H$2=8,$H$2=16,$H$2=32,$H$2=64,$H$2=128,$H$2=256),0,1) -> -2 | K28: =J28*$J$2 -> -20 | M28: =IF(I28<>"",K28+I28+L28,0) -> 0
... A37: =M37 -> 0 | B37: =IF(H37>$H$2,"",(ROW()-5)) | H37: 32 | I37: =IF(H37<$H$2+1,($I$2-($I$2-1)*(LOG(H37)/LOG($H$2))),"") | J37: =INT(LOG($H$2,2))-ROUNDUP(LOG(H37,2),0)+IF(OR($H$2=1,$H$2=2,$H$2=4,$H$2=8,$H$2=16,$H$2=32,$H$2=64,$H$2=128,$H$2=256),0,1) -> -2 | K37: =J37*$J$2 -> -20 | M37: =IF(I37<>"",K37+I37+L37,0) -> 0
B38: =IF(H38>$H$2,"",(ROW()-5)) | H38: 33 | I38: =IF(H38<$H$2+1,($I$2-($I$2-1)*(LOG(H38)/LOG($H$2))),"") | J38: =INT(LOG($H$2,2))-ROUNDUP(LOG(H38,2),0)+IF(OR($H$2=1,$H$2=2,$H$2=4,$H$2=8,$H$2=16,$H$2=32,$H$2=64,$H$2=128,$H$2=256),0,1) -> -3 | K38: =J38*$J$2 -> -30 | M38: =IF(I38<>"",K38+I38+L38,0) -> 0
B39: =IF(H39>$H$2,"",(ROW()-5)) | H39: 34 | I39: =IF(H39<$H$2+1,($I$2-($I$2-1)*(LOG(H39)/LOG($H$2))),"") | J39: =INT(LOG($H$2,2))-ROUNDUP(LOG(H39,2),0)+IF(OR($H$2=1,$H$2=2,$H$2=4,$H$2=8,$H$2=16,$H$2=32,$H$2=64,$H$2=128,$H$2=256),0,1) -> -3 | K39: =J39*$J$2 -> -30 | M39: =IF(I39<>"",K39+I39+L39,0) -> 0
B40: =IF(H40>$H$2,"",(ROW()-5)) | H40: 35 | I40: =IF(H40<$H$2+1,($I$2-($I$2-1)*(LOG(H40)/LOG($H$2))),"") | J40: =INT(LOG($H$2,2))-ROUNDUP(LOG(H40,2),0)+IF(OR($H$2=1,$H$2=2,$H$2=4,$H$2=8,$H$2=16,$H$2=32,$H$2=64,$H$2=128,$H$2=256),0,1) -> -3 | K40: =J40*$J$2 -> -30 | M40: =IF(I40<>"",K40+I40+L40,0) -> 0
B41: =IF(H41>$H$2,"",(ROW()-5)) | H41: 36 | I41: =IF(H41<$H$2+1,($I$2-($I$2-1)*(LOG(H41)/LOG($H$2))),"") | J41: =INT(LOG($H$2,2))-ROUNDUP(LOG(H41,2),0)+IF(OR($H$2=1,$H$2=2,$H$2=4,$H$2=8,$H$2=16,$H$2=32,$H$2=64,$H$2=128,$H$2=256),0,1) -> -3 | K41: =J41*$J$2 -> -30 | M41: =IF(I41<>"",K41+I41+L41,0) -> 0
B42: =IF(H42>$H$2,"",(ROW()-5)) | H42: 37 | I42: =IF(H42<$H$2+1,($I$2-($I$2-1)*(LOG(H42)/LOG($H$2))),"") | J42: =INT(LOG($H$2,2))-ROUNDUP(LOG(H42,2),0)+IF(OR($H$2=1,$H$2=2,$H$2=4,$H$2=8,$H$2=16,$H$2=32,$H$2=64,$H$2=128,$H$2=256),0,1) -> -3 | K42: =J42*$J$2 -> -30 | M42: =IF(I42<>"",K42+I42+L42,0) -> 0
B43: =IF(H43>$H$2,"",(ROW()-5)) | H43: 38 | I43: =IF(H43<$H$2+1,($I$2-($I$2-1)*(LOG(H43)/LOG($H$2))),"") | J43: =INT(LOG($H$2,2))-ROUNDUP(LOG(H43,2),0)+IF(OR($H$2=1,$H$2=2,$H$2=4,$H$2=8,$H$2=16,$H$2=32,$H$2=64,$H$2=128,$H$2=256),0,1) -> -3 | K43: =J43*$J$2 -> -30 | M43: =IF(I43<>"",K43+I43+L43,0) -> 0
B44: =IF(H44>$H$2,"",(ROW()-5)) | H44: 39 | I44: =IF(H44<$H$2+1,($I$2-($I$2-1)*(LOG(H44)/LOG($H$2))),"") | J44: =INT(LOG($H$2,2))-ROUNDUP(LOG(H44,2),0)+IF(OR($H$2=1,$H$2=2,$H$2=4,$H$2=8,$H$2=16,$H$2=32,$H$2=64,$H$2=128,$H$2=256),0,1) -> -3 | K44: =J44*$J$2 -> -30 | M44: =IF(I44<>"",K44+I44+L44,0) -> 0
B45: =IF(H45>$H$2,"",(ROW()-5)) | H45: 40 | I45: =IF(H45<$H$2+1,($I$2-($I$2-1)*(LOG(H45)/LOG($H$2))),"") | J45: =INT(LOG($H$2,2))-ROUNDUP(LOG(H45,2),0)+IF(OR($H$2=1,$H$2=2,$H$2=4,$H$2=8,$H$2=16,$H$2=32,$H$2=64,$H$2=128,$H$2=256),0,1) -> -3 | K45: =J45*$J$2 -> -30 | M45: =IF(I45<>"",K45+I45+L45,0) -> 0
B46: =IF(H46>$H$2,"",(ROW()-5)) | H46: 41 | I46: =IF(H46<$H$2+1,($I$2-($I$2-1)*(LOG(H46)/LOG($H$2))),"") | J46: =INT(LOG($H$2,2))-ROUNDUP(LOG(H46,2),0)+IF(OR($H$2=1,$H$2=2,$H$2=4,$H$2=8,$H$2=16,$H$2=32,$H$2=64,$H$2=128,$H$2=256),0,1) -> -3 | K46: =J46*$J$2 -> -30 | M46: =IF(I46<>"",K46+I46+L46,0) -> 0 | Q46: =LOG($H$2,2) -> 2.8073549 | T46: =LOG(H38,2) -> 5.0443941 | U46: =R46-T46 -> -5.0443941
B47: =IF(H47>$H$2,"",(ROW()-5)) | H47: 42 | I47: =IF(H47<$H$2+1,($I$2-($I$2-1)*(LOG(H47)/LOG($H$2))),"") | J47: =INT(LOG($H$2,2))-ROUNDUP(LOG(H47,2),0)+IF(OR($H$2=1,$H$2=2,$H$2=4,$H$2=8,$H$2=16,$H$2=32,$H$2=64,$H$2=128,$H$2=256),0,1) -> -3 | K47: =J47*$J$2 -> -30 | M47: =IF(I47<>"",K47+I47+L47,0) -> 0
B48: =IF(H48>$H$2,"",(ROW()-5)) | H48: 43 | I48: =IF(H48<$H$2+1,($I$2-($I$2-1)*(LOG(H48)/LOG($H$2))),"") | J48: =INT(LOG($H$2,2))-ROUNDUP(LOG(H48,2),0)+IF(OR($H$2=1,$H$2=2,$H$2=4,$H$2=8,$H$2=16,$H$2=32,$H$2=64,$H$2=128,$H$2=256),0,1) -> -3 | K48: =J48*$J$2 -> -30 | M48: =IF(I48<>"",K48+I48+L48,0) -> 0
B49: =IF(H49>$H$2,"",(ROW()-5)) | H49: 44 | I49: =IF(H49<$H$2+1,($I$2-($I$2-1)*(LOG(H49)/LOG($H$2))),"") | J49: =INT(LOG($H$2,2))-ROUNDUP(LOG(H49,2),0)+IF(OR($H$2=1,$H$2=2,$H$2=4,$H$2=8,$H$2=16,$H$2=32,$H$2=64,$H$2=128,$H$2=256),0,1) -> -3 | K49: =J49*$J$2 -> -30 | M49: =IF(I49<>"",K49+I49+L49,0) -> 0
...

Sheet PP3
H1: Liczba uczestników: | I1: GP Punkty | J1: Bonus za rundę | K1: Mnożnik za podium
B2: miejsce: | C2: KRAKÓW | H2: 5 | I2: 50 | J2: 10 | K2: =3*H2^(1/3) -> 5.1299278
B3: data: | C3: 01.12.2024
A5: Punkty | B5: Miejsce Place | C5: Nazwisko Imię Name | D5: Klub Club(s) | E5: Okręg Division | F5: Państwo Country | H5: Miejsce | I5: Punkty za miejsce | J5: awans do kolejnej rundy pucharowej | K5: bonus za rundy pucharowe | L5: punkty za podium | M5: Suma
A6: =M6 -> 95.389784 | B6: =IF(H6>$H$2,"",(ROW()-5)) -> 1 | C6: TK | D6: KU AZS ASZWOJ WARSZAWA | E6: POL | H6: 1 | I6: =IF(H2=1,50,IF(H6<$H$2+1,($I$2-($I$2-1)*(LOG(H6)/LOG($H$2))),"")) -> 50 | J6: =INT(LOG($H$2,2))-ROUNDUP(LOG(H6,2),0)+IF(OR($H$2=1,$H$2=2,$H$2=4,$H$2=8,$H$2=16,$H$2=32,$H$2=64,$H$2=128,$H$2=256),0,1) -> 3 | K6: =J6*$J$2 -> 30 | L6: =3*K2 -> 15.389784 | M6: =IF(I6<>"",K6+I6+L6,0) -> 95.389784
A7: =M7 -> 59.156704 | B7: =IF(H7>$H$2,"",(ROW()-5)) -> 2 | C7: SZMIDT Grzegorz | D7: WKS KOLEJARZ WROCŁAW | E7: POL | H7: 2 | I7: =IF(H7<$H$2+1,($I$2-($I$2-1)*(LOG(H7)/LOG($H$2))),"") -> 28.896849 | J7: =INT(LOG($H$2,2))-ROUNDUP(LOG(H7,2),0)+IF(OR($H$2=1,$H$2=2,$H$2=4,$H$2=8,$H$2=16,$H$2=32,$H$2=64,$H$2=128,$H$2=256),0,1) -> 2 | K7: =J7*$J$2 -> 20 | L7: =2*K2 -> 10.259856 | M7: =IF(I7<>"",K7+I7+L7,0) -> 59.156704
A8: =M8 -> 31.682224 | B8: =IF(H8>$H$2,"",(ROW()-5)) -> 3 | C8: HAŚKO Sergiusz | D8: BTS BYTOM | E8: POL | H8: 3 | I8: =IF(H8<$H$2+1,($I$2-($I$2-1)*(LOG(H8)/LOG($H$2))),"") -> 16.552296 | J8: =INT(LOG($H$2,2))-ROUNDUP(LOG(H8,2),0)+IF(OR($H$2=1,$H$2=2,$H$2=4,$H$2=8,$H$2=16,$H$2=32,$H$2=64,$H$2=128,$H$2=256),0,1) -> 1 | K8: =J8*$J$2 -> 10 | L8: =K2 -> 5.1299278 | M8: =IF(I8<>"",K8+I8+L8,0) -> 31.682224
A9: =M9 -> 17.793697 | B9: =IF(H9>$H$2,"",(ROW()-5)) -> 4 | C9: BAZAK Jacek | D9: AKS MIKOŁÓW | E9: POL | H9: 4 | I9: =IF(H9<$H$2+1,($I$2-($I$2-1)*(LOG(H9)/LOG($H$2))),"") -> 7.7936973 | J9: =INT(LOG($H$2,2))-ROUNDUP(LOG(H9,2),0)+IF(OR($H$2=1,$H$2=2,$H$2=4,$H$2=8,$H$2=16,$H$2=32,$H$2=64,$H$2=128,$H$2=256),0,1) -> 1 | K9: =J9*$J$2 -> 10 | M9: =IF(I9<>"",K9+I9+L9,0) -> 17.793697 | AH9: x | AI9: 23
A10: =M10 -> 1 | B10: =IF(H10>$H$2,"",(ROW()-5)) -> 5 | C10: ŻUKOWSKI Wojciech | D10: SZCZECIŃSKA SZKOŁA SZERMIERCZA | E10: POL | H10: 5 | I10: =IF(H10<$H$2+1,($I$2-($I$2-1)*(LOG(H10)/LOG($H$2))),"") -> 1 | J10: =INT(LOG($H$2,2))-ROUNDUP(LOG(H10,2),0)+IF(OR($H$2=1,$H$2=2,$H$2=4,$H$2=8,$H$2=16,$H$2=32,$H$2=64,$H$2=128,$H$2=256),0,1) -> 0 | K10: =J10*$J$2 -> 0 | M10: =IF(I10<>"",K10+I10+L10,0) -> 1 | AH10: N | AI10: 45
A11: =M11 -> 0 | B11: =IF(H11>$H$2,"",(ROW()-5)) | H11: 6 | I11: =IF(H11<$H$2+1,($I$2-($I$2-1)*(LOG(H11)/LOG($H$2))),"") | J11: =INT(LOG($H$2,2))-ROUNDUP(LOG(H11,2),0)+IF(OR($H$2=1,$H$2=2,$H$2=4,$H$2=8,$H$2=16,$H$2=32,$H$2=64,$H$2=128,$H$2=256),0,1) -> 0 | K11: =J11*$J$2 -> 0 | M11: =IF(I11<>"",K11+I11+L11,0) -> 0 | AH11: MP | AI11: 50
A12: =M12 -> 0 | B12: =IF(H12>$H$2,"",(ROW()-5)) | H12: 7 | I12: =IF(H12<$H$2+1,($I$2-($I$2-1)*(LOG(H12)/LOG($H$2))),"") | J12: =INT(LOG($H$2,2))-ROUNDUP(LOG(H12,2),0)+IF(OR($H$2=1,$H$2=2,$H$2=4,$H$2=8,$H$2=16,$H$2=32,$H$2=64,$H$2=128,$H$2=256),0,1) -> 0 | K12: =J12*$J$2 -> 0 | M12: =IF(I12<>"",K12+I12+L12,0) -> 0 | AH12: MP-1 | AI12: =AI11-1 -> 49
A13: =M13 -> 0 | B13: =IF(H13>$H$2,"",(ROW()-5)) | H13: 8 | I13: =IF(H13<$H$2+1,($I$2-($I$2-1)*(LOG(H13)/LOG($H$2))),"") | J13: =INT(LOG($H$2,2))-ROUNDUP(LOG(H13,2),0)+IF(OR($H$2=1,$H$2=2,$H$2=4,$H$2=8,$H$2=16,$H$2=32,$H$2=64,$H$2=128,$H$2=256),0,1) -> 0 | K13: =J13*$J$2 -> 0 | M13: =IF(I13<>"",K13+I13+L13,0) -> 0 | AH13: log(x) | AI13: =LOG(AI9) -> 1.3617278
A14: =M14 -> 0 | B14: =IF(H14>$H$2,"",(ROW()-5)) | H14: 9 | I14: =IF(H14<$H$2+1,($I$2-($I$2-1)*(LOG(H14)/LOG($H$2))),"") | J14: =INT(LOG($H$2,2))-ROUNDUP(LOG(H14,2),0)+IF(OR($H$2=1,$H$2=2,$H$2=4,$H$2=8,$H$2=16,$H$2=32,$H$2=64,$H$2=128,$H$2=256),0,1) -> -1 | K14: =J14*$J$2 -> -10 | M14: =IF(I14<>"",K14+I14+L14,0) -> 0 | AH14: Log(N) | AI14: =LOG(AI10) -> 1.6532125
A15: =M15 -> 0 | B15: =IF(H15>$H$2,"",(ROW()-5)) | H15: 10 | I15: =IF(H15<$H$2+1,($I$2-($I$2-1)*(LOG(H15)/LOG($H$2))),"") | J15: =INT(LOG($H$2,2))-ROUNDUP(LOG(H15,2),0)+IF(OR($H$2=1,$H$2=2,$H$2=4,$H$2=8,$H$2=16,$H$2=32,$H$2=64,$H$2=128,$H$2=256),0,1) -> -1 | K15: =J15*$J$2 -> -10 | M15: =IF(I15<>"",K15+I15+L15,0) -> 0
A16: =M16 -> 0 | B16: =IF(H16>$H$2,"",(ROW()-5)) | H16: 11 | I16: =IF(H16<$H$2+1,($I$2-($I$2-1)*(LOG(H16)/LOG($H$2))),"") | J16: =INT(LOG($H$2,2))-ROUNDUP(LOG(H16,2),0)+IF(OR($H$2=1,$H$2=2,$H$2=4,$H$2=8,$H$2=16,$H$2=32,$H$2=64,$H$2=128,$H$2=256),0,1) -> -1 | K16: =J16*$J$2 -> -10 | M16: =IF(I16<>"",K16+I16+L16,0) -> 0 | AH16: MP - (MP-1)*LOG(x)/LOG(N) | AI16: =AI11-AI12*AI13/AI14 -> 9.6393909 | AJ16: points
A17: =M17 -> 0 | B17: =IF(H17>$H$2,"",(ROW()-5)) | H17: 12 | I17: =IF(H17<$H$2+1,($I$2-($I$2-1)*(LOG(H17)/LOG($H$2))),"") | J17: =INT(LOG($H$2,2))-ROUNDUP(LOG(H17,2),0)+IF(OR($H$2=1,$H$2=2,$H$2=4,$H$2=8,$H$2=16,$H$2=32,$H$2=64,$H$2=128,$H$2=256),0,1) -> -1 | K17: =J17*$J$2 -> -10 | M17: =IF(I17<>"",K17+I17+L17,0) -> 0
A18: =M18 -> 0 | B18: =IF(H18>$H$2,"",(ROW()-5)) | H18: 13 | I18: =IF(H18<$H$2+1,($I$2-($I$2-1)*(LOG(H18)/LOG($H$2))),"") | J18: =INT(LOG($H$2,2))-ROUNDUP(LOG(H18,2),0)+IF(OR($H$2=1,$H$2=2,$H$2=4,$H$2=8,$H$2=16,$H$2=32,$H$2=64,$H$2=128,$H$2=256),0,1) -> -1 | K18: =J18*$J$2 -> -10 | M18: =IF(I18<>"",K18+I18+L18,0) -> 0
A19: =M19 -> 0 | B19: =IF(H19>$H$2,"",(ROW()-5)) | H19: 14 | I19: =IF(H19<$H$2+1,($I$2-($I$2-1)*(LOG(H19)/LOG($H$2))),"") | J19: =INT(LOG($H$2,2))-ROUNDUP(LOG(H19,2),0)+IF(OR($H$2=1,$H$2=2,$H$2=4,$H$2=8,$H$2=16,$H$2=32,$H$2=64,$H$2=128,$H$2=256),0,1) -> -1 | K19: =J19*$J$2 -> -10 | M19: =IF(I19<>"",K19+I19+L19,0) -> 0
A20: =M20 -> 0 | B20: =IF(H20>$H$2,"",(ROW()-5)) | H20: 15 | I20: =IF(H20<$H$2+1,($I$2-($I$2-1)*(LOG(H20)/LOG($H$2))),"") | J20: =INT(LOG($H$2,2))-ROUNDUP(LOG(H20,2),0)+IF(OR($H$2=1,$H$2=2,$H$2=4,$H$2=8,$H$2=16,$H$2=32,$H$2=64,$H$2=128,$H$2=256),0,1) -> -1 | K20: =J20*$J$2 -> -10 | M20: =IF(I20<>"",K20+I20+L20,0) -> 0
A21: =M21 -> 0 | B21: =IF(H21>$H$2,"",(ROW()-5)) | H21: 16 | I21: =IF(H21<$H$2+1,($I$2-($I$2-1)*(LOG(H21)/LOG($H$2))),"") | J21: =INT(LOG($H$2,2))-ROUNDUP(LOG(H21,2),0)+IF(OR($H$2=1,$H$2=2,$H$2=4,$H$2=8,$H$2=16,$H$2=32,$H$2=64,$H$2=128,$H$2=256),0,1) -> -1 | K21: =J21*$J$2 -> -10 | M21: =IF(I21<>"",K21+I21+L21,0) -> 0
A22: =M22 -> 0 | B22: =IF(H22>$H$2,"",(ROW()-5)) | H22: 17 | I22: =IF(H22<$H$2+1,($I$2-($I$2-1)*(LOG(H22)/LOG($H$2))),"") | J22: =INT(LOG($H$2,2))-ROUNDUP(LOG(H22,2),0)+IF(OR($H$2=1,$H$2=2,$H$2=4,$H$2=8,$H$2=16,$H$2=32,$H$2=64,$H$2=128,$H$2=256),0,1) -> -2 | K22: =J22*$J$2 -> -20 | M22: =IF(I22<>"",K22+I22+L22,0) -> 0
A23: =M23 -> 0 | B23: =IF(H23>$H$2,"",(ROW()-5)) | H23: 18 | I23: =IF(H23<$H$2+1,($I$2-($I$2-1)*(LOG(H23)/LOG($H$2))),"") | J23: =INT(LOG($H$2,2))-ROUNDUP(LOG(H23,2),0)+IF(OR($H$2=1,$H$2=2,$H$2=4,$H$2=8,$H$2=16,$H$2=32,$H$2=64,$H$2=128,$H$2=256),0,1) -> -2 | K23: =J23*$J$2 -> -20 | M23: =IF(I23<>"",K23+I23+L23,0) -> 0
A24: =M24 -> 0 | B24: =IF(H24>$H$2,"",(ROW()-5)) | H24: 19 | I24: =IF(H24<$H$2+1,($I$2-($I$2-1)*(LOG(H24)/LOG($H$2))),"") | J24: =INT(LOG($H$2,2))-ROUNDUP(LOG(H24,2),0)+IF(OR($H$2=1,$H$2=2,$H$2=4,$H$2=8,$H$2=16,$H$2=32,$H$2=64,$H$2=128,$H$2=256),0,1) -> -2 | K24: =J24*$J$2 -> -20 | M24: =IF(I24<>"",K24+I24+L24,0) -> 0
A25: =M25 -> 0 | B25: =IF(H25>$H$2,"",(ROW()-5)) | H25: 20 | I25: =IF(H25<$H$2+1,($I$2-($I$2-1)*(LOG(H25)/LOG($H$2))),"") | J25: =INT(LOG($H$2,2))-ROUNDUP(LOG(H25,2),0)+IF(OR($H$2=1,$H$2=2,$H$2=4,$H$2=8,$H$2=16,$H$2=32,$H$2=64,$H$2=128,$H$2=256),0,1) -> -2 | K25: =J25*$J$2 -> -20 | M25: =IF(I25<>"",K25+I25+L25,0) -> 0
A26: =M26 -> 0 | B26: =IF(H26>$H$2,"",(ROW()-5)) | H26: 21 | I26: =IF(H26<$H$2+1,($I$2-($I$2-1)*(LOG(H26)/LOG($H$2))),"") | J26: =INT(LOG($H$2,2))-ROUNDUP(LOG(H26,2),0)+IF(OR($H$2=1,$H$2=2,$H$2=4,$H$2=8,$H$2=16,$H$2=32,$H$2=64,$H$2=128,$H$2=256),0,1) -> -2 | K26: =J26*$J$2 -> -20 | M26: =IF(I26<>"",K26+I26+L26,0) -> 0
A27: =M27 -> 0 | B27: =IF(H27>$H$2,"",(ROW()-5)) | H27: 22 | I27: =IF(H27<$H$2+1,($I$2-($I$2-1)*(LOG(H27)/LOG($H$2))),"") | J27: =INT(LOG($H$2,2))-ROUNDUP(LOG(H27,2),0)+IF(OR($H$2=1,$H$2=2,$H$2=4,$H$2=8,$H$2=16,$H$2=32,$H$2=64,$H$2=128,$H$2=256),0,1) -> -2 | K27: =J27*$J$2 -> -20 | M27: =IF(I27<>"",K27+I27+L27,0) -> 0
A28: =M28 -> 0 | B28: =IF(H28>$H$2,"",(ROW()-5)) | H28: 23 | I28: =IF(H28<$H$2+1,($I$2-($I$2-1)*(LOG(H28)/LOG($H$2))),"") | J28: =INT(LOG($H$2,2))-ROUNDUP(LOG(H28,2),0)+IF(OR($H$2=1,$H$2=2,$H$2=4,$H$2=8,$H$2=16,$H$2=32,$H$2=64,$H$2=128,$H$2=256),0,1) -> -2 | K28: =J28*$J$2 -> -20 | M28: =IF(I28<>"",K28+I28+L28,0) -> 0
... A37: =M37 -> 0 | B37: =IF(H37>$H$2,"",(ROW()-5)) | H37: 32 | I37: =IF(H37<$H$2+1,($I$2-($I$2-1)*(LOG(H37)/LOG($H$2))),"") | J37: =INT(LOG($H$2,2))-ROUNDUP(LOG(H37,2),0)+IF(OR($H$2=1,$H$2=2,$H$2=4,$H$2=8,$H$2=16,$H$2=32,$H$2=64,$H$2=128,$H$2=256),0,1) -> -2 | K37: =J37*$J$2 -> -20 | M37: =IF(I37<>"",K37+I37+L37,0) -> 0
B38: =IF(H38>$H$2,"",(ROW()-5)) | H38: 33 | I38: =IF(H38<$H$2+1,($I$2-($I$2-1)*(LOG(H38)/LOG($H$2))),"") | J38: =INT(LOG($H$2,2))-ROUNDUP(LOG(H38,2),0)+IF(OR($H$2=1,$H$2=2,$H$2=4,$H$2=8,$H$2=16,$H$2=32,$H$2=64,$H$2=128,$H$2=256),0,1) -> -3 | K38: =J38*$J$2 -> -30 | M38: =IF(I38<>"",K38+I38+L38,0) -> 0
B39: =IF(H39>$H$2,"",(ROW()-5)) | H39: 34 | I39: =IF(H39<$H$2+1,($I$2-($I$2-1)*(LOG(H39)/LOG($H$2))),"") | J39: =INT(LOG($H$2,2))-ROUNDUP(LOG(H39,2),0)+IF(OR($H$2=1,$H$2=2,$H$2=4,$H$2=8,$H$2=16,$H$2=32,$H$2=64,$H$2=128,$H$2=256),0,1) -> -3 | K39: =J39*$J$2 -> -30 | M39: =IF(I39<>"",K39+I39+L39,0) -> 0
B40: =IF(H40>$H$2,"",(ROW()-5)) | H40: 35 | I40: =IF(H40<$H$2+1,($I$2-($I$2-1)*(LOG(H40)/LOG($H$2))),"") | J40: =INT(LOG($H$2,2))-ROUNDUP(LOG(H40,2),0)+IF(OR($H$2=1,$H$2=2,$H$2=4,$H$2=8,$H$2=16,$H$2=32,$H$2=64,$H$2=128,$H$2=256),0,1) -> -3 | K40: =J40*$J$2 -> -30 | M40: =IF(I40<>"",K40+I40+L40,0) -> 0
B41: =IF(H41>$H$2,"",(ROW()-5)) | H41: 36 | I41: =IF(H41<$H$2+1,($I$2-($I$2-1)*(LOG(H41)/LOG($H$2))),"") | J41: =INT(LOG($H$2,2))-ROUNDUP(LOG(H41,2),0)+IF(OR($H$2=1,$H$2=2,$H$2=4,$H$2=8,$H$2=16,$H$2=32,$H$2=64,$H$2=128,$H$2=256),0,1) -> -3 | K41: =J41*$J$2 -> -30 | M41: =IF(I41<>"",K41+I41+L41,0) -> 0
B42: =IF(H42>$H$2,"",(ROW()-5)) | H42: 37 | I42: =IF(H42<$H$2+1,($I$2-($I$2-1)*(LOG(H42)/LOG($H$2))),"") | J42: =INT(LOG($H$2,2))-ROUNDUP(LOG(H42,2),0)+IF(OR($H$2=1,$H$2=2,$H$2=4,$H$2=8,$H$2=16,$H$2=32,$H$2=64,$H$2=128,$H$2=256),0,1) -> -3 | K42: =J42*$J$2 -> -30 | M42: =IF(I42<>"",K42+I42+L42,0) -> 0
B43: =IF(H43>$H$2,"",(ROW()-5)) | H43: 38 | I43: =IF(H43<$H$2+1,($I$2-($I$2-1)*(LOG(H43)/LOG($H$2))),"") | J43: =INT(LOG($H$2,2))-ROUNDUP(LOG(H43,2),0)+IF(OR($H$2=1,$H$2=2,$H$2=4,$H$2=8,$H$2=16,$H$2=32,$H$2=64,$H$2=128,$H$2=256),0,1) -> -3 | K43: =J43*$J$2 -> -30 | M43: =IF(I43<>"",K43+I43+L43,0) -> 0
B44: =IF(H44>$H$2,"",(ROW()-5)) | H44: 39 | I44: =IF(H44<$H$2+1,($I$2-($I$2-1)*(LOG(H44)/LOG($H$2))),"") | J44: =INT(LOG($H$2,2))-ROUNDUP(LOG(H44,2),0)+IF(OR($H$2=1,$H$2=2,$H$2=4,$H$2=8,$H$2=16,$H$2=32,$H$2=64,$H$2=128,$H$2=256),0,1) -> -3 | K44: =J44*$J$2 -> -30 | M44: =IF(I44<>"",K44+I44+L44,0) -> 0
B45: =IF(H45>$H$2,"",(ROW()-5)) | H45: 40 | I45: =IF(H45<$H$2+1,($I$2-($I$2-1)*(LOG(H45)/LOG($H$2))),"") | J45: =INT(LOG($H$2,2))-ROUNDUP(LOG(H45,2),0)+IF(OR($H$2=1,$H$2=2,$H$2=4,$H$2=8,$H$2=16,$H$2=32,$H$2=64,$H$2=128,$H$2=256),0,1) -> -3 | K45: =J45*$J$2 -> -30 | M45: =IF(I45<>"",K45+I45+L45,0) -> 0
B46: =IF(H46>$H$2,"",(ROW()-5)) | H46: 41 | I46: =IF(H46<$H$2+1,($I$2-($I$2-1)*(LOG(H46)/LOG($H$2))),"") | J46: =INT(LOG($H$2,2))-ROUNDUP(LOG(H46,2),0)+IF(OR($H$2=1,$H$2=2,$H$2=4,$H$2=8,$H$2=16,$H$2=32,$H$2=64,$H$2=128,$H$2=256),0,1) -> -3 | K46: =J46*$J$2 -> -30 | M46: =IF(I46<>"",K46+I46+L46,0) -> 0 | R46: =LOG($H$2,2) -> 2.3219281 | T46: =LOG(H38,2) -> 5.0443941 | U46: =R46-T46 -> -2.722466
B47: =IF(H47>$H$2,"",(ROW()-5)) | H47: 42 | I47: =IF(H47<$H$2+1,($I$2-($I$2-1)*(LOG(H47)/LOG($H$2))),"") | J47: =INT(LOG($H$2,2))-ROUNDUP(LOG(H47,2),0)+IF(OR($H$2=1,$H$2=2,$H$2=4,$H$2=8,$H$2=16,$H$2=32,$H$2=64,$H$2=128,$H$2=256),0,1) -> -3 | K47: =J47*$J$2 -> -30 | M47: =IF(I47<>"",K47+I47+L47,0) -> 0
B48: =IF(H48>$H$2,"",(ROW()-5)) | H48: 43 | I48: =IF(H48<$H$2+1,($I$2-($I$2-1)*(LOG(H48)/LOG($H$2))),"") | J48: =INT(LOG($H$2,2))-ROUNDUP(LOG(H48,2),0)+IF(OR($H$2=1,$H$2=2,$H$2=4,$H$2=8,$H$2=16,$H$2=32,$H$2=64,$H$2=128,$H$2=256),0,1) -> -3 | K48: =J48*$J$2 -> -30 | M48: =IF(I48<>"",K48+I48+L48,0) -> 0
B49: =IF(H49>$H$2,"",(ROW()-5)) | H49: 44 | I49: =IF(H49<$H$2+1,($I$2-($I$2-1)*(LOG(H49)/LOG($H$2))),"") | J49: =INT(LOG($H$2,2))-ROUNDUP(LOG(H49,2),0)+IF(OR($H$2=1,$H$2=2,$H$2=4,$H$2=8,$H$2=16,$H$2=32,$H$2=64,$H$2=128,$H$2=256),0,1) -> -3 | K49: =J49*$J$2 -> -30 | M49: =IF(I49<>"",K49+I49+L49,0) -> 0
...

Sheet PP4
H1: Liczba uczestników: | I1: GP Punkty | J1: Bonus za rundę | K1: Mnożnik za podium
B2: miejsce: | C2: WARSZAWA | H2: 3 | I2: 50 | J2: 10 | K2: =3*H2^(1/3) -> 4.3267487
B3: data: | C3: 23.02.2025
A5: Punkty | B5: Miejsce Place | C5: Nazwisko Imię Name | D5: Klub Club(s) | E5: Okręg Division | F5: Państwo Country | H5: Miejsce | I5: Punkty za miejsce | J5: awans do kolejnej rundy pucharowej | K5: bonus za rundy pucharowe | L5: punkty za podium | M5: Suma
A6: =M6 -> 82.980246 | B6: =IF(H6>$H$2,"",(ROW()-5)) -> 1 | C6: TK | D6: KU AZS ASZWOJ WARSZAWA | E6: POL | H6: 1 | I6: =IF(H2=1,50,IF(H6<$H$2+1,($I$2-($I$2-1)*(LOG(H6)/LOG($H$2))),"")) -> 50 | J6: 2 | K6: =J6*$J$2 -> 20 | L6: =3*K2 -> 12.980246 | M6: =IF(I6<>"",K6+I6+L6,0) -> 82.980246
A7: =M7 -> 37.737939 | B7: =IF(H7>$H$2,"",(ROW()-5)) -> 2 | C7: SZMIDT Grzegorz | D7: WKS KOLEJARZ WROCŁAW | E7: POL | H7: 2 | I7: =IF(H7<$H$2+1,($I$2-($I$2-1)*(LOG(H7)/LOG($H$2))),"") -> 19.084442 | J7: 1 | K7: =J7*$J$2 -> 10 | L7: =2*K2 -> 8.6534974 | M7: =IF(I7<>"",K7+I7+L7,0) -> 37.737939
A8: =M8 -> 5.3267487 | B8: =IF(H8>$H$2,"",(ROW()-5)) -> 3 | C8: BAZAK Jacek | D8: AKS MIKOŁÓW | E8: POL | H8: 3 | I8: =IF(H8<$H$2+1,($I$2-($I$2-1)*(LOG(H8)/LOG($H$2))),"") -> 1 | J8: =INT(LOG($H$2,2))-ROUNDUP(LOG(H8,2),0)+IF(OR($H$2=1,$H$2=2,$H$2=4,$H$2=8,$H$2=16,$H$2=32,$H$2=64,$H$2=128,$H$2=256),0,1) -> 0 | K8: =J8*$J$2 -> 0 | L8: =K2 -> 4.3267487 | M8: =IF(I8<>"",K8+I8+L8,0) -> 5.3267487
A9: =M9 -> 0 | B9: =IF(H9>$H$2,"",(ROW()-5)) | H9: 4 | I9: =IF(H9<$H$2+1,($I$2-($I$2-1)*(LOG(H9)/LOG($H$2))),"") | J9: =INT(LOG($H$2,2))-ROUNDUP(LOG(H9,2),0)+IF(OR($H$2=1,$H$2=2,$H$2=4,$H$2=8,$H$2=16,$H$2=32,$H$2=64,$H$2=128,$H$2=256),0,1) -> 0 | K9: =J9*$J$2 -> 0 | M9: =IF(I9<>"",K9+I9+L9,0) -> 0 | AH9: x | AI9: 23
A10: =M10 -> 0 | B10: =IF(H10>$H$2,"",(ROW()-5)) | H10: 5 | I10: =IF(H10<$H$2+1,($I$2-($I$2-1)*(LOG(H10)/LOG($H$2))),"") | J10: =INT(LOG($H$2,2))-ROUNDUP(LOG(H10,2),0)+IF(OR($H$2=1,$H$2=2,$H$2=4,$H$2=8,$H$2=16,$H$2=32,$H$2=64,$H$2=128,$H$2=256),0,1) -> -1 | K10: =J10*$J$2 -> -10 | M10: =IF(I10<>"",K10+I10+L10,0) -> 0 | AH10: N | AI10: 45
A11: =M11 -> 0 | B11: =IF(H11>$H$2,"",(ROW()-5)) | H11: 6 | I11: =IF(H11<$H$2+1,($I$2-($I$2-1)*(LOG(H11)/LOG($H$2))),"") | J11: =INT(LOG($H$2,2))-ROUNDUP(LOG(H11,2),0)+IF(OR($H$2=1,$H$2=2,$H$2=4,$H$2=8,$H$2=16,$H$2=32,$H$2=64,$H$2=128,$H$2=256),0,1) -> -1 | K11: =J11*$J$2 -> -10 | M11: =IF(I11<>"",K11+I11+L11,0) -> 0 | AH11: MP | AI11: 50
A12: =M12 -> 0 | B12: =IF(H12>$H$2,"",(ROW()-5)) | H12: 7 | I12: =IF(H12<$H$2+1,($I$2-($I$2-1)*(LOG(H12)/LOG($H$2))),"") | J12: =INT(LOG($H$2,2))-ROUNDUP(LOG(H12,2),0)+IF(OR($H$2=1,$H$2=2,$H$2=4,$H$2=8,$H$2=16,$H$2=32,$H$2=64,$H$2=128,$H$2=256),0,1) -> -1 | K12: =J12*$J$2 -> -10 | M12: =IF(I12<>"",K12+I12+L12,0) -> 0 | AH12: MP-1 | AI12: =AI11-1 -> 49
A13: =M13 -> 0 | B13: =IF(H13>$H$2,"",(ROW()-5)) | H13: 8 | I13: =IF(H13<$H$2+1,($I$2-($I$2-1)*(LOG(H13)/LOG($H$2))),"") | J13: =INT(LOG($H$2,2))-ROUNDUP(LOG(H13,2),0)+IF(OR($H$2=1,$H$2=2,$H$2=4,$H$2=8,$H$2=16,$H$2=32,$H$2=64,$H$2=128,$H$2=256),0,1) -> -1 | K13: =J13*$J$2 -> -10 | M13: =IF(I13<>"",K13+I13+L13,0) -> 0 | AH13: log(x) | AI13: =LOG(AI9) -> 1.3617278
A14: =M14 -> 0 | B14: =IF(H14>$H$2,"",(ROW()-5)) | H14: 9 | I14: =IF(H14<$H$2+1,($I$2-($I$2-1)*(LOG(H14)/LOG($H$2))),"") | J14: =INT(LOG($H$2,2))-ROUNDUP(LOG(H14,2),0)+IF(OR($H$2=1,$H$2=2,$H$2=4,$H$2=8,$H$2=16,$H$2=32,$H$2=64,$H$2=128,$H$2=256),0,1) -> -2 | K14: =J14*$J$2 -> -20 | M14: =IF(I14<>"",K14+I14+L14,0) -> 0 | AH14: Log(N) | AI14: =LOG(AI10) -> 1.6532125
A15: =M15 -> 0 | B15: =IF(H15>$H$2,"",(ROW()-5)) | H15: 10 | I15: =IF(H15<$H$2+1,($I$2-($I$2-1)*(LOG(H15)/LOG($H$2))),"") | J15: =INT(LOG($H$2,2))-ROUNDUP(LOG(H15,2),0)+IF(OR($H$2=1,$H$2=2,$H$2=4,$H$2=8,$H$2=16,$H$2=32,$H$2=64,$H$2=128,$H$2=256),0,1) -> -2 | K15: =J15*$J$2 -> -20 | M15: =IF(I15<>"",K15+I15+L15,0) -> 0
A16: =M16 -> 0 | B16: =IF(H16>$H$2,"",(ROW()-5)) | H16: 11 | I16: =IF(H16<$H$2+1,($I$2-($I$2-1)*(LOG(H16)/LOG($H$2))),"") | J16: =INT(LOG($H$2,2))-ROUNDUP(LOG(H16,2),0)+IF(OR($H$2=1,$H$2=2,$H$2=4,$H$2=8,$H$2=16,$H$2=32,$H$2=64,$H$2=128,$H$2=256),0,1) -> -2 | K16: =J16*$J$2 -> -20 | M16: =IF(I16<>"",K16+I16+L16,0) -> 0 | AH16: MP - (MP-1)*LOG(x)/LOG(N) | AI16: =AI11-AI12*AI13/AI14 -> 9.6393909 | AJ16: points
A17: =M17 -> 0 | B17: =IF(H17>$H$2,"",(ROW()-5)) | H17: 12 | I17: =IF(H17<$H$2+1,($I$2-($I$2-1)*(LOG(H17)/LOG($H$2))),"") | J17: =INT(LOG($H$2,2))-ROUNDUP(LOG(H17,2),0)+IF(OR($H$2=1,$H$2=2,$H$2=4,$H$2=8,$H$2=16,$H$2=32,$H$2=64,$H$2=128,$H$2=256),0,1) -> -2 | K17: =J17*$J$2 -> -20 | M17: =IF(I17<>"",K17+I17+L17,0) -> 0
A18: =M18 -> 0 | B18: =IF(H18>$H$2,"",(ROW()-5)) | H18: 13 | I18: =IF(H18<$H$2+1,($I$2-($I$2-1)*(LOG(H18)/LOG($H$2))),"") | J18: =INT(LOG($H$2,2))-ROUNDUP(LOG(H18,2),0)+IF(OR($H$2=1,$H$2=2,$H$2=4,$H$2=8,$H$2=16,$H$2=32,$H$2=64,$H$2=128,$H$2=256),0,1) -> -2 | K18: =J18*$J$2 -> -20 | M18: =IF(I18<>"",K18+I18+L18,0) -> 0
A19: =M19 -> 0 | B19: =IF(H19>$H$2,"",(ROW()-5)) | H19: 14 | I19: =IF(H19<$H$2+1,($I$2-($I$2-1)*(LOG(H19)/LOG($H$2))),"") | J19: =INT(LOG($H$2,2))-ROUNDUP(LOG(H19,2),0)+IF(OR($H$2=1,$H$2=2,$H$2=4,$H$2=8,$H$2=16,$H$2=32,$H$2=64,$H$2=128,$H$2=256),0,1) -> -2 | K19: =J19*$J$2 -> -20 | M19: =IF(I19<>"",K19+I19+L19,0) -> 0
A20: =M20 -> 0 | B20: =IF(H20>$H$2,"",(ROW()-5)) | H20: 15 | I20: =IF(H20<$H$2+1,($I$2-($I$2-1)*(LOG(H20)/LOG($H$2))),"") | J20: =INT(LOG($H$2,2))-ROUNDUP(LOG(H20,2),0)+IF(OR($H$2=1,$H$2=2,$H$2=4,$H$2=8,$H$2=16,$H$2=32,$H$2=64,$H$2=128,$H$2=256),0,1) -> -2 | K20: =J20*$J$2 -> -20 | M20: =IF(I20<>"",K20+I20+L20,0) -> 0
A21: =M21 -> 0 | B21: =IF(H21>$H$2,"",(ROW()-5)) | H21: 16 | I21: =IF(H21<$H$2+1,($I$2-($I$2-1)*(LOG(H21)/LOG($H$2))),"") | J21: =INT(LOG($H$2,2))-ROUNDUP(LOG(H21,2),0)+IF(OR($H$2=1,$H$2=2,$H$2=4,$H$2=8,$H$2=16,$H$2=32,$H$2=64,$H$2=128,$H$2=256),0,1) -> -2 | K21: =J21*$J$2 -> -20 | M21: =IF(I21<>"",K21+I21+L21,0) -> 0
A22: =M22 -> 0 | B22: =IF(H22>$H$2,"",(ROW()-5)) | H22: 17 | I22: =IF(H22<$H$2+1,($I$2-($I$2-1)*(LOG(H22)/LOG($H$2))),"") | J22: =INT(LOG($H$2,2))-ROUNDUP(LOG(H22,2),0)+IF(OR($H$2=1,$H$2=2,$H$2=4,$H$2=8,$H$2=16,$H$2=32,$H$2=64,$H$2=128,$H$2=256),0,1) -> -3 | K22: =J22*$J$2 -> -30 | M22: =IF(I22<>"",K22+I22+L22,0) -> 0
A23: =M23 -> 0 | B23: =IF(H23>$H$2,"",(ROW()-5)) | H23: 18 | I23: =IF(H23<$H$2+1,($I$2-($I$2-1)*(LOG(H23)/LOG($H$2))),"") | J23: =INT(LOG($H$2,2))-ROUNDUP(LOG(H23,2),0)+IF(OR($H$2=1,$H$2=2,$H$2=4,$H$2=8,$H$2=16,$H$2=32,$H$2=64,$H$2=128,$H$2=256),0,1) -> -3 | K23: =J23*$J$2 -> -30 | M23: =IF(I23<>"",K23+I23+L23,0) -> 0
A24: =M24 -> 0 | B24: =IF(H24>$H$2,"",(ROW()-5)) | H24: 19 | I24: =IF(H24<$H$2+1,($I$2-($I$2-1)*(LOG(H24)/LOG($H$2))),"") | J24: =INT(LOG($H$2,2))-ROUNDUP(LOG(H24,2),0)+IF(OR($H$2=1,$H$2=2,$H$2=4,$H$2=8,$H$2=16,$H$2=32,$H$2=64,$H$2=128,$H$2=256),0,1) -> -3 | K24: =J24*$J$2 -> -30 | M24: =IF(I24<>"",K24+I24+L24,0) -> 0
A25: =M25 -> 0 | B25: =IF(H25>$H$2,"",(ROW()-5)) | H25: 20 | I25: =IF(H25<$H$2+1,($I$2-($I$2-1)*(LOG(H25)/LOG($H$2))),"") | J25: =INT(LOG($H$2,2))-ROUNDUP(LOG(H25,2),0)+IF(OR($H$2=1,$H$2=2,$H$2=4,$H$2=8,$H$2=16,$H$2=32,$H$2=64,$H$2=128,$H$2=256),0,1) -> -3 | K25: =J25*$J$2 -> -30 | M25: =IF(I25<>"",K25+I25+L25,0) -> 0
A26: =M26 -> 0 | B26: =IF(H26>$H$2,"",(ROW()-5)) | H26: 21 | I26: =IF(H26<$H$2+1,($I$2-($I$2-1)*(LOG(H26)/LOG($H$2))),"") | J26: =INT(LOG($H$2,2))-ROUNDUP(LOG(H26,2),0)+IF(OR($H$2=1,$H$2=2,$H$2=4,$H$2=8,$H$2=16,$H$2=32,$H$2=64,$H$2=128,$H$2=256),0,1) -> -3 | K26: =J26*$J$2 -> -30 | M26: =IF(I26<>"",K26+I26+L26,0) -> 0
A27: =M27 -> 0 | B27: =IF(H27>$H$2,"",(ROW()-5)) | H27: 22 | I27: =IF(H27<$H$2+1,($I$2-($I$2-1)*(LOG(H27)/LOG($H$2))),"") | J27: =INT(LOG($H$2,2))-ROUNDUP(LOG(H27,2),0)+IF(OR($H$2=1,$H$2=2,$H$2=4,$H$2=8,$H$2=16,$H$2=32,$H$2=64,$H$2=128,$H$2=256),0,1) -> -3 | K27: =J27*$J$2 -> -30 | M27: =IF(I27<>"",K27+I27+L27,0) -> 0
