Workbook

Sheet All
A2: L.P. | B2: kat | C2: IMIĘ NAZWISKO | D2: V/M | E2: V/M | Q2: TS | R2: TS | AD2: Ind | AE2: Ind
E3: MP | G3: PP1 | I3: PP2 | K3: PP3 | M3: PP4 | O3: PP5 | R3: MP | T3: PP1 | V3: PP2 | X3: PP3 | Z3: PP4 | AB3: PP5 | AE3: MP | AG3: PP1 | AI3: PP2 | AK3: PP3 | AM3: PP4 | AO3: PP5
E4: 1 | F4: 2 | G4: 1 | H4: 2 | I4: 1 | J4: 2 | K4: 1 | L4: 2 | M4: 1 | N4: 2 | O4: 1 | P4: 2 | R4: 1 | S4: 2 | T4: 1 | U4: 2 | V4: 1 | W4: 2 | X4: 1 | Y4: 2 | Z4: 1 | AA4: 2 | AB4: 1 | AC4: 2 | AE4: 1 | AF4: 2 | AG4: 1 | AH4: 2 | AI4: 1 | AJ4: 2 | AK4: 1 | AL4: 2 | AM4: 1 | AN4: 2 | AO4: 1 | AP4: 2
A5: =ROW()-4 -> 1 | B5: 2 | C5: ZAWROTNIAK Przemysław | D5: =SUM(E5:P5) -> 10.25 | E5: =_xlfn.XLOOKUP($C5,'MP (1)'!$B$6:$B$100,'MP (1)'!$E$6:$E$100,"") -> 0.75 | F5: =_xlfn.XLOOKUP($C5,'MP (2)'!$B$6:$B$100,'MP (2)'!$E$6:$E$100,"") -> 0.8 | G5: =_xlfn.XLOOKUP($C5,'PP1 (1)'!$B$6:$B$66,'PP1 (1)'!$E$6:$E$66,"") -> 0.8 | H5: =_xlfn.XLOOKUP($C5,'PP1 (2)'!$B$6:$B$100,'PP1 (2)'!$E$6:$E$100,"") -> 0.8 | I5: =_xlfn.XLOOKUP($C5,'PP2 (1)'!$B$6:$B$99,'PP2 (1)'!$E$6:$E$99,"") -> 0.67 | J5: =_xlfn.XLOOKUP($C5,'PP2 (2)'!$B$6:$B$100,'PP2 (2)'!$E$6:$E$100,"") -> 0.83 | K5: =_xlfn.XLOOKUP($C5,'PP3 (1)'!$B$5:$B$113,'PP3 (1)'!$E$5:$E$113,"") -> 1 | L5: =_xlfn.XLOOKUP($C5,'PP3 (2)'!$B$5:$B$112,'PP3 (2)'!$E$5:$E$112,"") -> 1 | M5: =_xlfn.XLOOKUP($C5,'PP4 (1)'!$B$6:$B$100,'PP4 (1)'!$E$6:$E$100,"") -> 0.8 | N5: =_xlfn.XLOOKUP($C5,'PP4 (2)'!$B$6:$B$100,'PP4 (2)'!$E$6:$E$100,"") -> 0.8 | O5: =_xlfn.XLOOKUP($C5,'PP5 (1)'!$B$6:$B$100,'PP5 (1)'!$E$6:$E$100,"") -> 1 | P5: =_xlfn.XLOOKUP($C5,'PP5(2)'!$B$6:$B$100,'PP5(2)'!$E$6:$E$100,"") -> 1 | Q5: =SUM(R5:AC5) -> 290 | R5: =_xlfn.XLOOKUP($C5,'MP (1)'!$B$6:$B$100,'MP (1)'!$F$6:$F$100,"") -> 19 | S5: =_xlfn.XLOOKUP($C5,'MP (2)'!$B$6:$B$100,'MP (2)'!$F$6:$F$100,"") -> 23 | T5: =_xlfn.XLOOKUP($C5,'PP1 (1)'!$B$6:$B$66,'PP1 (1)'!$F$6:$F$66,"") -> 24 | U5: =_xlfn.XLOOKUP($C5,'PP1 (2)'!$B$6:$B$100,'PP1 (2)'!$F$6:$F$100,"") -> 22 | V5: =_xlfn.XLOOKUP($C5,'PP2 (1)'!$B$6:$B$99,'PP2 (1)'!$F$6:$F$99,"") -> 25 | W5: =_xlfn.XLOOKUP($C5,'PP2 (2)'!$B$6:$B$100,'PP2 (2)'!$F$6:$F$100,"") -> 29 | X5: =_xlfn.XLOOKUP($C5,'PP3 (1)'!$B$5:$B$113,'PP3 (1)'!$F$5:$F$113,"") -> 30 | Y5: =_xlfn.XLOOKUP($C5,'PP3 (2)'!$B$5:$B$112,'PP3 (2)'!$F$5:$F$112,"") -> 25 | Z5: =_xlfn.XLOOKUP($C5,'PP4 (1)'!$B$6:$B$100,'PP4 (1)'!$F$6:$F$100,"") -> 20 | AA5: =_xlfn.XLOOKUP($C5,'PP4 (2)'!$B$6:$B$100,'PP4 (2)'!$F$6:$F$100,"") -> 23 | AB5: =_xlfn.XLOOKUP($C5,'PP5 (1)'!$B$6:$B$100,'PP5 (1)'!$F$6:$F$100,"") -> 25 | AC5: =_xlfn.XLOOKUP($C5,'PP5(2)'!$B$6:$B$100,'PP5(2)'!$F$6:$F$100,"") -> 25 | AD5: =SUM(AE5:AP5) -> 166 | AE5: =_xlfn.XLOOKUP($C5,'MP (1)'!$B$6:$B$100,'MP (1)'!$H$6:$H$100,"") -> 8 | AF5: =_xlfn.XLOOKUP($C5,'MP (2)'!$B$6:$B$100,'MP (2)'!$H$6:$H$100,"") -> 14 | AG5: =_xlfn.XLOOKUP($C5,'PP1 (1)'!$B$6:$B$66,'PP1 (1)'!$H$6:$H$66,"") -> 14 | AH5: =_xlfn.XLOOKUP($C5,'PP1 (2)'!$B$6:$B$100,'PP1 (2)'!$H$6:$H$100,"") -> 16 | AI5: =_xlfn.XLOOKUP($C5,'PP2 (1)'!$B$6:$B$99,'PP2 (1)'!$H$6:$H$99,"") -> 8 | AJ5: =_xlfn.XLOOKUP($C5,'PP2 (2)'!$B$6:$B$100,'PP2 (2)'!$H$6:$H$100,"") -> 16 | AK5: =_xlfn.XLOOKUP($C5,'PP3 (1)'!$B$5:$B$113,'PP3 (1)'!$H$5:$H$113,"") -> 22 | AL5: =_xlfn.XLOOKUP($C5,'PP3 (2)'!$B$5:$B$112,'PP3 (2)'!$H$5:$H$112,"") -> 14 | AM5: =_xlfn.XLOOKUP($C5,'PP4 (1)'!$B$6:$B$100,'PP4 (1)'!$H$6:$H$100,"") -> 8 | AN5: =_xlfn.XLOOKUP($C5,'PP4 (2)'!$B$6:$B$100,'PP4 (2)'!$H$6:$H$100,"") -> 13 | AO5: =_xlfn.XLOOKUP($C5,'PP5 (1)'!$B$6:$B$100,'PP5 (1)'!$H$6:$H$100,"") -> 13 | AP5: =_xlfn.XLOOKUP($C5,'PP5(2)'!$B$6:$B$100,'PP5(2)'!$H$6:$H$100,"") -> 20
A6: =ROW()-4 -> 2 | B6: 2 | C6: NOWICKI Robert | D6: =SUM(E6:P6) -> 10.19 | E6: =_xlfn.XLOOKUP($C6,'MP (1)'!$B$6:$B$100,'MP (1)'!$E$6:$E$100,"") -> 0.83 | F6: =_xlfn.XLOOKUP($C6,'MP (2)'!$B$6:$B$100,'MP (2)'!$E$6:$E$100,"") -> 0.8 | G6: =_xlfn.XLOOKUP($C6,'PP1 (1)'!$B$6:$B$66,'PP1 (1)'!$E$6:$E$66,"") -> 0.8 | H6: =_xlfn.XLOOKUP($C6,'PP1 (2)'!$B$6:$B$100,'PP1 (2)'!$E$6:$E$100,"") -> 0.5 | I6: =_xlfn.XLOOKUP($C6,'PP2 (1)'!$B$6:$B$99,'PP2 (1)'!$E$6:$E$99,"") -> 1 | J6: =_xlfn.XLOOKUP($C6,'PP2 (2)'!$B$6:$B$100,'PP2 (2)'!$E$6:$E$100,"") -> 0.8 | K6: =_xlfn.XLOOKUP($C6,'PP3 (1)'!$B$5:$B$113,'PP3 (1)'!$E$5:$E$113,"") -> 0.83 | L6: =_xlfn.XLOOKUP($C6,'PP3 (2)'!$B$5:$B$112,'PP3 (2)'!$E$5:$E$112,"") -> 0.83 | M6: =_xlfn.XLOOKUP($C6,'PP4 (1)'!$B$6:$B$100,'PP4 (1)'!$E$6:$E$100,"") -> 1 | N6: =_xlfn.XLOOKUP($C6,'PP4 (2)'!$B$6:$B$100,'PP4 (2)'!$E$6:$E$100,"") -> 1 | O6: =_xlfn.XLOOKUP($C6,'PP5 (1)'!$B$6:$B$100,'PP5 (1)'!$E$6:$E$100,"") -> 1 | P6: =_xlfn.XLOOKUP($C6,'PP5(2)'!$B$6:$B$100,'PP5(2)'!$E$6:$E$100,"") -> 0.8 | Q6: =SUM(R6:AC6) -> 277 | R6: =_xlfn.XLOOKUP($C6,'MP (1)'!$B$6:$B$100,'MP (1)'!$F$6:$F$100,"") -> 28 | S6: =_xlfn.XLOOKUP($C6,'MP (2)'!$B$6:$B$100,'MP (2)'!$F$6:$F$100,"") -> 22 | T6: =_xlfn.XLOOKUP($C6,'PP1 (1)'!$B$6:$B$66,'PP1 (1)'!$F$6:$F$66,"") -> 20 | U6: =_xlfn.XLOOKUP($C6,'PP1 (2)'!$B$6:$B$100,'PP1 (2)'!$F$6:$F$100,"") -> 15 | V6: =_xlfn.XLOOKUP($C6,'PP2 (1)'!$B$6:$B$99,'PP2 (1)'!$F$6:$F$99,"") -> 25 | W6: =_xlfn.XLOOKUP($C6,'PP2 (2)'!$B$6:$B$100,'PP2 (2)'!$F$6:$F$100,"") -> 22 | X6: =_xlfn.XLOOKUP($C6,'PP3 (1)'!$B$5:$B$113,'PP3 (1)'!$F$5:$F$113,"") -> 26 | Y6: =_xlfn.XLOOKUP($C6,'PP3 (2)'!$B$5:$B$112,'PP3 (2)'!$F$5:$F$112,"") -> 28 | Z6: =_xlfn.XLOOKUP($C6,'PP4 (1)'!$B$6:$B$100,'PP4 (1)'!$F$6:$F$100,"") -> 20 | AA6: =_xlfn.XLOOKUP($C6,'PP4 (2)'!$B$6:$B$100,'PP4 (2)'!$F$6:$F$100,"") -> 25 | AB6: =_xlfn.XLOOKUP($C6,'PP5 (1)'!$B$6:$B$100,'PP5 (1)'!$F$6:$F$100,"") -> 25 | AC6: =_xlfn.XLOOKUP($C6,'PP5(2)'!$B$6:$B$100,'PP5(2)'!$F$6:$F$100,"") -> 21 | AD6: =SUM(AE6:AP6) -> 139 | AE6: =_xlfn.XLOOKUP($C6,'MP (1)'!$B$6:$B$100,'MP (1)'!$H$6:$H$100,"") -> 12 | AF6: =_xlfn.XLOOKUP($C6,'MP (2)'!$B$6:$B$100,'MP (2)'!$H$6:$H$100,"") -> 9 | AG6: =_xlfn.XLOOKUP($C6,'PP1 (1)'!$B$6:$B$66,'PP1 (1)'!$H$6:$H$66,"") -> 7 | AH6: =_xlfn.XLOOKUP($C6,'PP1 (2)'!$B$6:$B$100,'PP1 (2)'!$H$6:$H$100,"") -> 5 | AI6: =_xlfn.XLOOKUP($C6,'PP2 (1)'!$B$6:$B$99,'PP2 (1)'!$H$6:$H$99,"") -> 17 | AJ6: =_xlfn.XLOOKUP($C6,'PP2 (2)'!$B$6:$B$100,'PP2 (2)'!$H$6:$H$100,"") -> 6 | AK6: =_xlfn.XLOOKUP($C6,'PP3 (1)'!$B$5:$B$113,'PP3 (1)'!$H$5:$H$113,"") -> 13 | AL6: =_xlfn.XLOOKUP($C6,'PP3 (2)'!$B$5:$B$112,'PP3 (2)'!$H$5:$H$112,"") -> 19 | AM6: =_xlfn.XLOOKUP($C6,'PP4 (1)'!$B$6:$B$100,'PP4 (1)'!$H$6:$H$100,"") -> 11 | AN6: =_xlfn.XLOOKUP($C6,'PP4 (2)'!$B$6:$B$100,'PP4 (2)'!$H$6:$H$100,"") -> 17 | AO6: =_xlfn.XLOOKUP($C6,'PP5 (1)'!$B$6:$B$100,'PP5 (1)'!$H$6:$H$100,"") -> 17 | AP6: =_xlfn.XLOOKUP($C6,'PP5(2)'!$B$6:$B$100,'PP5(2)'!$H$6:$H$100,"") -> 6
A7: =ROW()-4 -> 3 | B7: 2 | C7: GANSZCZYK Marcin | D7: =SUM(E7:P7) -> 8.56 | E7: =_xlfn.XLOOKUP($C7,'MP (1)'!$B$6:$B$100,'MP (1)'!$E$6:$E$100,"") | F7: =_xlfn.XLOOKUP($C7,'MP (2)'!$B$6:$B$100,'MP (2)'!$E$6:$E$100,"") | G7: =_xlfn.XLOOKUP($C7,'PP1 (1)'!$B$6:$B$66,'PP1 (1)'!$E$6:$E$66,"") -> 1 | H7: =_xlfn.XLOOKUP($C7,'PP1 (2)'!$B$6:$B$100,'PP1 (2)'!$E$6:$E$100,"") -> 0.83 | I7: =_xlfn.XLOOKUP($C7,'PP2 (1)'!$B$6:$B$99,'PP2 (1)'!$E$6:$E$99,"") -> 1 | J7: =_xlfn.XLOOKUP($C7,'PP2 (2)'!$B$6:$B$100,'PP2 (2)'!$E$6:$E$100,"") -> 0.5 | K7: =_xlfn.XLOOKUP($C7,'PP3 (1)'!$B$5:$B$113,'PP3 (1)'!$E$5:$E$113,"") -> 0.83 | L7: =_xlfn.XLOOKUP($C7,'PP3 (2)'!$B$5:$B$112,'PP3 (2)'!$E$5:$E$112,"") -> 1 | M7: =_xlfn.XLOOKUP($C7,'PP4 (1)'!$B$6:$B$100,'PP4 (1)'!$E$6:$E$100,"") -> 0.8 | N7: =_xlfn.XLOOKUP($C7,'PP4 (2)'!$B$6:$B$100,'PP4 (2)'!$E$6:$E$100,"") -> 0.8 | O7: =_xlfn.XLOOKUP($C7,'PP5 (1)'!$B$6:$B$100,'PP5 (1)'!$E$6:$E$100,"") -> 0.8 | P7: =_xlfn.XLOOKUP($C7,'PP5(2)'!$B$6:$B$100,'PP5(2)'!$E$6:$E$100,"") -> 1 | Q7: =SUM(R7:AC7) -> 255 | R7: =_xlfn.XLOOKUP($C7,'MP (1)'!$B$6:$B$100,'MP (1)'!$F$6:$F$100,"") | S7: =_xlfn.XLOOKUP($C7,'MP (2)'!$B$6:$B$100,'MP (2)'!$F$6:$F$100,"") | T7: =_xlfn.XLOOKUP($C7,'PP1 (1)'!$B$6:$B$66,'PP1 (1)'!$F$6:$F$66,"") -> 30 | U7: =_xlfn.XLOOKUP($C7,'PP1 (2)'!$B$6:$B$100,'PP1 (2)'!$F$6:$F$100,"") -> 29 | V7: =_xlfn.XLOOKUP($C7,'PP2 (1)'!$B$6:$B$99,'PP2 (1)'!$F$6:$F$99,"") -> 25 | W7: =_xlfn.XLOOKUP($C7,'PP2 (2)'!$B$6:$B$100,'PP2 (2)'!$F$6:$F$100,"") -> 24 | X7: =_xlfn.XLOOKUP($C7,'PP3 (1)'!$B$5:$B$113,'PP3 (1)'!$F$5:$F$113,"") -> 28 | Y7: =_xlfn.XLOOKUP($C7,'PP3 (2)'!$B$5:$B$112,'PP3 (2)'!$F$5:$F$112,"") -> 30 | Z7: =_xlfn.XLOOKUP($C7,'PP4 (1)'!$B$6:$B$100,'PP4 (1)'!$F$6:$F$100,"") -> 24 | AA7: =_xlfn.XLOOKUP($C7,'PP4 (2)'!$B$6:$B$100,'PP4 (2)'!$F$6:$F$100,"") -> 21 | AB7: =_xlfn.XLOOKUP($C7,'PP5 (1)'!$B$6:$B$100,'PP5 (1)'!$F$6:$F$100,"") -> 24 | AC7: =_xlfn.XLOOKUP($C7,'PP5(2)'!$B$6:$B$100,'PP5(2)'!$F$6:$F$100,"") -> 20 | AD7: =SUM(AE7:AP7) -> 157 | AE7: =_xlfn.XLOOKUP($C7,'MP (1)'!$B$6:$B$100,'MP (1)'!$H$6:$H$100,"") | AF7: =_xlfn.XLOOKUP($C7,'MP (2)'!$B$6:$B$100,'MP (2)'!$H$6:$H$100,"") | AG7: =_xlfn.XLOOKUP($C7,'PP1 (1)'!$B$6:$B$66,'PP1 (1)'!$H$6:$H$66,"") -> 20 | AH7: =_xlfn.XLOOKUP($C7,'PP1 (2)'!$B$6:$B$100,'PP1 (2)'!$H$6:$H$100,"") -> 22 | AI7: =_xlfn.XLOOKUP($C7,'PP2 (1)'!$B$6:$B$99,'PP2 (1)'!$H$6:$H$99,"") -> 20 | AJ7: =_xlfn.XLOOKUP($C7,'PP2 (2)'!$B$6:$B$100,'PP2 (2)'!$H$6:$H$100,"") -> 5 | AK7: =_xlfn.XLOOKUP($C7,'PP3 (1)'!$B$5:$B$113,'PP3 (1)'!$H$5:$H$113,"") -> 18 | AL7: =_xlfn.XLOOKUP($C7,'PP3 (2)'!$B$5:$B$112,'PP3 (2)'!$H$5:$H$112,"") -> 18 | AM7: =_xlfn.XLOOKUP($C7,'PP4 (1)'!$B$6:$B$100,'PP4 (1)'!$H$6:$H$100,"") -> 16 | AN7: =_xlfn.XLOOKUP($C7,'PP4 (2)'!$B$6:$B$100,'PP4 (2)'!$H$6:$H$100,"") -> 11 | AO7: =_xlfn.XLOOKUP($C7,'PP5 (1)'!$B$6:$B$100,'PP5 (1)'!$H$6:$H$100,"") -> 11 | AP7: =_xlfn.XLOOKUP($C7,'PP5(2)'!$B$6:$B$100,'PP5(2)'!$H$6:$H$100,"") -> 16
A8: =ROW()-4 -> 4 | B8: 2 | C8: TK | D8: =SUM(E8:P8) -> 8.17 | E8: =_xlfn.XLOOKUP($C8,'MP (1)'!$B$6:$B$100,'MP (1)'!$E$6:$E$100,"") -> 1 | F8: =_xlfn.XLOOKUP($C8,'MP (2)'!$B$6:$B$100,'MP (2)'!$E$6:$E$100,"") -> 1 | G8: =_xlfn.XLOOKUP($C8,'PP1 (1)'!$B$6:$B$66,'PP1 (1)'!$E$6:$E$66,"") -> 0.6 | H8: =_xlfn.XLOOKUP($C8,'PP1 (2)'!$B$6:$B$100,'PP1 (2)'!$E$6:$E$100,"") -> 1 | I8: =_xlfn.XLOOKUP($C8,'PP2 (1)'!$B$6:$B$99,'PP2 (1)'!$E$6:$E$99,"") -> 0.2 | J8: =_xlfn.XLOOKUP($C8,'PP2 (2)'!$B$6:$B$100,'PP2 (2)'!$E$6:$E$100,"") -> 0.6 | K8: =_xlfn.XLOOKUP($C8,'PP3 (1)'!$B$5:$B$113,'PP3 (1)'!$E$5:$E$113,"") -> 0.67 | L8: =_xlfn.XLOOKUP($C8,'PP3 (2)'!$B$5:$B$112,'PP3 (2)'!$E$5:$E$112,"") | M8: =_xlfn.XLOOKUP($C8,'PP4 (1)'!$B$6:$B$100,'PP4 (1)'!$E$6:$E$100,"") -> 0.8 | N8: =_xlfn.XLOOKUP($C8,'PP4 (2)'!$B$6:$B$100,'PP4 (2)'!$E$6:$E$100,"") -> 0.75 | O8: =_xlfn.XLOOKUP($C8,'PP5 (1)'!$B$6:$B$100,'PP5 (1)'!$E$6:$E$100,"") -> 0.8 | P8: =_xlfn.XLOOKUP($C8,'PP5(2)'!$B$6:$B$100,'PP5(2)'!$E$6:$E$100,"") -> 0.75 | Q8: =SUM(R8:AC8) -> 233 | R8: =_xlfn.XLOOKUP($C8,'MP (1)'!$B$6:$B$100,'MP (1)'!$F$6:$F$100,"") -> 20 | S8: =_xlfn.XLOOKUP($C8,'MP (2)'!$B$6:$B$100,'MP (2)'!$F$6:$F$100,"") -> 25 | T8: =_xlfn.XLOOKUP($C8,'PP1 (1)'!$B$6:$B$66,'PP1 (1)'!$F$6:$F$66,"") -> 20 | U8: =_xlfn.XLOOKUP($C8,'PP1 (2)'!$B$6:$B$100,'PP1 (2)'!$F$6:$F$100,"") -> 20 | V8: =_xlfn.XLOOKUP($C8,'PP2 (1)'!$B$6:$B$99,'PP2 (1)'!$F$6:$F$99,"") -> 15 | W8: =_xlfn.XLOOKUP($C8,'PP2 (2)'!$B$6:$B$100,'PP2 (2)'!$F$6:$F$100,"") -> 21 | X8: =_xlfn.XLOOKUP($C8,'PP3 (1)'!$B$5:$B$113,'PP3 (1)'!$F$5:$F$113,"") -> 28 | Y8: =_xlfn.XLOOKUP($C8,'PP3 (2)'!$B$5:$B$112,'PP3 (2)'!$F$5:$F$112,"") | Z8: =_xlfn.XLOOKUP($C8,'PP4 (1)'!$B$6:$B$100,'PP4 (1)'!$F$6:$F$100,"") -> 24 | AA8: =_xlfn.XLOOKUP($C8,'PP4 (2)'!$B$6:$B$100,'PP4 (2)'!$F$6:$F$100,"") -> 18 | AB8: =_xlfn.XLOOKUP($C8,'PP5 (1)'!$B$6:$B$100,'PP5 (1)'!$F$6:$F$100,"") -> 24 | AC8: =_xlfn.XLOOKUP($C8,'PP5(2)'!$B$6:$B$100,'PP5(2)'!$F$6:$F$100,"") -> 18 | AD8: =SUM(AE8:AP8) -> 90 | AE8: =_xlfn.XLOOKUP($C8,'MP (1)'!$B$6:$B$100,'MP (1)'!$H$6:$H$100,"") -> 14 | AF8: =_xlfn.XLOOKUP($C8,'MP (2)'!$B$6:$B$100,'MP (2)'!$H$6:$H$100,"") -> 14 | AG8: =_xlfn.XLOOKUP($C8,'PP1 (1)'!$B$6:$B$66,'PP1 (1)'!$H$6:$H$66,"") -> 5 | AH8: =_xlfn.XLOOKUP($C8,'PP1 (2)'!$B$6:$B$100,'PP1 (2)'!$H$6:$H$100,"") -> 15 | AI8: =_xlfn.XLOOKUP($C8,'PP2 (1)'!$B$6:$B$99,'PP2 (1)'!$H$6:$H$99,"") -> -8 | AJ8: =_xlfn.XLOOKUP($C8,'PP2 (2)'!$B$6:$B$100,'PP2 (2)'!$H$6:$H$100,"") -> 3 | AK8: =_xlfn.XLOOKUP($C8,'PP3 (1)'!$B$5:$B$113,'PP3 (1)'!$H$5:$H$113,"") -> 10 | AL8: =_xlfn.XLOOKUP($C8,'PP3 (2)'!$B$5:$B$112,'PP3 (2)'!$H$5:$H$112,"") | AM8: =_xlfn.XLOOKUP($C8,'PP4 (1)'!$B$6:$B$100,'PP4 (1)'!$H$6:$H$100,"") -> 7 | AN8: =_xlfn.XLOOKUP($C8,'PP4 (2)'!$B$6:$B$100,'PP4 (2)'!$H$6:$H$100,"") -> 8 | AO8: =_xlfn.XLOOKUP($C8,'PP5 (1)'!$B$6:$B$100,'PP5 (1)'!$H$6:$H$100,"") -> 13 | AP8: =_xlfn.XLOOKUP($C8,'PP5(2)'!$B$6:$B$100,'PP5(2)'!$H$6:$H$100,"") -> 9
A9: =ROW()-4 -> 5 | B9: 1 | C9: KUCIĘBA Piotr | D9: =SUM(E9:P9) -> 7.67 | E9: =_xlfn.XLOOKUP($C9,'MP (1)'!$B$6:$B$100,'MP (1)'!$E$6:$E$100,"") -> 1 | F9: =_xlfn.XLOOKUP($C9,'MP (2)'!$B$6:$B$100,'MP (2)'!$E$6:$E$100,"") -> 1 | G9: =_xlfn.XLOOKUP($C9,'PP1 (1)'!$B$6:$B$66,'PP1 (1)'!$E$6:$E$66,"") | H9: =_xlfn.XLOOKUP($C9,'PP1 (2)'!$B$6:$B$100,'PP1 (2)'!$E$6:$E$100,"") | I9: =_xlfn.XLOOKUP($C9,'PP2 (1)'!$B$6:$B$99,'PP2 (1)'!$E$6:$E$99,"") -> 0.67 | J9: =_xlfn.XLOOKUP($C9,'PP2 (2)'!$B$6:$B$100,'PP2 (2)'!$E$6:$E$100,"") -> 1 | K9: =_xlfn.XLOOKUP($C9,'PP3 (1)'!$B$5:$B$113,'PP3 (1)'!$E$5:$E$113,"") -> 1 | L9: =_xlfn.XLOOKUP($C9,'PP3 (2)'!$B$5:$B$112,'PP3 (2)'!$E$5:$E$112,"") -> 1 | M9: =_xlfn.XLOOKUP($C9,'PP4 (1)'!$B$6:$B$100,'PP4 (1)'!$E$6:$E$100,"") -> 1 | N9: =_xlfn.XLOOKUP($C9,'PP4 (2)'!$B$6:$B$100,'PP4 (2)'!$E$6:$E$100,"") -> 1 | O9: =_xlfn.XLOOKUP($C9,'PP5 (1)'!$B$6:$B$100,'PP5 (1)'!$E$6:$E$100,"") | P9: =_xlfn.XLOOKUP($C9,'PP5(2)'!$B$6:$B$100,'PP5(2)'!$E$6:$E$100,"") | Q9: =SUM(R9:AC9) -> 223 | R9: =_xlfn.XLOOKUP($C9,'MP (1)'!$B$6:$B$100,'MP (1)'!$F$6:$F$100,"") -> 30 | S9: =_xlfn.XLOOKUP($C9,'MP (2)'!$B$6:$B$100,'MP (2)'!$F$6:$F$100,"") -> 25 | T9: =_xlfn.XLOOKUP($C9,'PP1 (1)'!$B$6:$B$66,'PP1 (1)'!$F$6:$F$66,"") | U9: =_xlfn.XLOOKUP($C9,'PP1 (2)'!$B$6:$B$100,'PP1 (2)'!$F$6:$F$100,"") | V9: =_xlfn.XLOOKUP($C9,'PP2 (1)'!$B$6:$B$99,'PP2 (1)'!$F$6:$F$99,"") -> 28 | W9: =_xlfn.XLOOKUP($C9,'PP2 (2)'!$B$6:$B$100,'PP2 (2)'!$F$6:$F$100,"") -> 30 | X9: =_xlfn.XLOOKUP($C9,'PP3 (1)'!$B$5:$B$113,'PP3 (1)'!$F$5:$F$113,"") -> 30 | Y9: =_xlfn.XLOOKUP($C9,'PP3 (2)'!$B$5:$B$112,'PP3 (2)'!$F$5:$F$112,"") -> 30 | Z9: =_xlfn.XLOOKUP($C9,'PP4 (1)'!$B$6:$B$100,'PP4 (1)'!$F$6:$F$100,"") -> 25 | AA9: =_xlfn.XLOOKUP($C9,'PP4 (2)'!$B$6:$B$100,'PP4 (2)'!$F$6:$F$100,"") -> 25 | AB9: =_xlfn.XLOOKUP($C9,'PP5 (1)'!$B$6:$B$100,'PP5 (1)'!$F$6:$F$100,"") | AC9: =_xlfn.XLOOKUP($C9,'PP5(2)'!$B$6:$B$100,'PP5(2)'!$F$6:$F$100,"") | AD9: =SUM(AE9:AP9) -> 153 | AE9: =_xlfn.XLOOKUP($C9,'MP (1)'!$B$6:$B$100,'MP (1)'!$H$6:$H$100,"") -> 21 | AF9: =_xlfn.XLOOKUP($C9,'MP (2)'!$B$6:$B$100,'MP (2)'!$H$6:$H$100,"") -> 16 | AG9: =_xlfn.XLOOKUP($C9,'PP1 (1)'!$B$6:$B$66,'PP1 (1)'!$H$6:$H$66,"") | AH9: =_xlfn.XLOOKUP($C9,'PP1 (2)'!$B$6:$B$100,'PP1 (2)'!$H$6:$H$100,"") | AI9: =_xlfn.XLOOKUP($C9,'PP2 (1)'!$B$6:$B$99,'PP2 (1)'!$H$6:$H$99,"") -> 12 | AJ9: =_xlfn.XLOOKUP($C9,'PP2 (2)'!$B$6:$B$100,'PP2 (2)'!$H$6:$H$100,"") -> 17 | AK9: =_xlfn.XLOOKUP($C9,'PP3 (1)'!$B$5:$B$113,'PP3 (1)'!$H$5:$H$113,"") -> 25 | AL9: =_xlfn.XLOOKUP($C9,'PP3 (2)'!$B$5:$B$112,'PP3 (2)'!$H$5:$H$112,"") -> 21 | AM9: =_xlfn.XLOOKUP($C9,'PP4 (1)'!$B$6:$B$100,'PP4 (1)'!$H$6:$H$100,"") -> 21 | AN9: =_xlfn.XLOOKUP($C9,'PP4 (2)'!$B$6:$B$100,'PP4 (2)'!$H$6:$H$100,"") -> 20 | AO9: =_xlfn.XLOOKUP($C9,'PP5 (1)'!$B$6:$B$100,'PP5 (1)'!$H$6:$H$100,"") | AP9: =_xlfn.XLOOKUP($C9,'PP5(2)'!$B$6:$B$100,'PP5(2)'!$H$6:$H$100,"")
A10: =ROW()-4 -> 6 | B10: 1 | C10: KOSIŃSKI Łukasz | D10: =SUM(E10:P10) -> 7.4 | E10: =_xlfn.XLOOKUP($C10,'MP (1)'!$B$6:$B$100,'MP (1)'!$E$6:$E$100,"") -> 0.8 | F10: =_xlfn.XLOOKUP($C10,'MP (2)'!$B$6:$B$100,'MP (2)'!$E$6:$E$100,"") -> 0.8 | G10: =_xlfn.XLOOKUP($C10,'PP1 (1)'!$B$6:$B$66,'PP1 (1)'!$E$6:$E$66,"") -> 0.8 | H10: =_xlfn.XLOOKUP($C10,'PP1 (2)'!$B$6:$B$100,'PP1 (2)'!$E$6:$E$100,"") -> 1 | I10: =_xlfn.XLOOKUP($C10,'PP2 (1)'!$B$6:$B$99,'PP2 (1)'!$E$6:$E$99,"") -> 1 | J10: =_xlfn.XLOOKUP($C10,'PP2 (2)'!$B$6:$B$100,'PP2 (2)'!$E$6:$E$100,"") -> 1 | K10: =_xlfn.XLOOKUP($C10,'PP3 (1)'!$B$5:$B$113,'PP3 (1)'!$E$5:$E$113,"") | L10: =_xlfn.XLOOKUP($C10,'PP3 (2)'!$B$5:$B$112,'PP3 (2)'!$E$5:$E$112,"") | M10: =_xlfn.XLOOKUP($C10,'PP4 (1)'!$B$6:$B$100,'PP4 (1)'!$E$6:$E$100,"") -> 1 | N10: =_xlfn.XLOOKUP($C10,'PP4 (2)'!$B$6:$B$100,'PP4 (2)'!$E$6:$E$100,"") -> 1 | O10: =_xlfn.XLOOKUP($C10,'PP5 (1)'!$B$6:$B$100,'PP5 (1)'!$E$6:$E$100,"") | P10: =_xlfn.XLOOKUP($C10,'PP5(2)'!$B$6:$B$100,'PP5(2)'!$E$6:$E$100,"") | Q10: =SUM(R10:AC10) -> 191 | R10: =_xlfn.XLOOKUP($C10,'MP (1)'!$B$6:$B$100,'MP (1)'!$F$6:$F$100,"") -> 23 | S10: =_xlfn.XLOOKUP($C10,'MP (2)'!$B$6:$B$100,'MP (2)'!$F$6:$F$100,"") -> 22 | T10: =_xlfn.XLOOKUP($C10,'PP1 (1)'!$B$6:$B$66,'PP1 (1)'!$F$6:$F$66,"") -> 21 | U10: =_xlfn.XLOOKUP($C10,'PP1 (2)'!$B$6:$B$100,'PP1 (2)'!$F$6:$F$100,"") -> 25 | V10: =_xlfn.XLOOKUP($C10,'PP2 (1)'!$B$6:$B$99,'PP2 (1)'!$F$6:$F$99,"") -> 25 | W10: =_xlfn.XLOOKUP($C10,'PP2 (2)'!$B$6:$B$100,'PP2 (2)'!$F$6:$F$100,"") -> 25 | X10: =_xlfn.XLOOKUP($C10,'PP3 (1)'!$B$5:$B$113,'PP3 (1)'!$F$5:$F$113,"") | Y10: =_xlfn.XLOOKUP($C10,'PP3 (2)'!$B$5:$B$112,'PP3 (2)'!$F$5:$F$112,"") | Z10: =_xlfn.XLOOKUP($C10,'PP4 (1)'!$B$6:$B$100,'PP4 (1)'!$F$6:$F$100,"") -> 25 | AA10: =_xlfn.XLOOKUP($C10,'PP4 (2)'!$B$6:$B$100,'PP4 (2)'!$F$6:$F$100,"") -> 25 | AB10: =_xlfn.XLOOKUP($C10,'PP5 (1)'!$B$6:$B$100,'PP5 (1)'!$F$6:$F$100,"") | AC10: =_xlfn.XLOOKUP($C10,'PP5(2)'!$B$6:$B$100,'PP5(2)'!$F$6:$F$100,"") | AD10: =SUM(AE10:AP10) -> 116 | AE10: =_xlfn.XLOOKUP($C10,'MP (1)'!$B$6:$B$100,'MP (1)'!$H$6:$H$100,"") -> 11 | AF10: =_xlfn.XLOOKUP($C10,'MP (2)'!$B$6:$B$100,'MP (2)'!$H$6:$H$100,"") -> 10 | AG10: =_xlfn.XLOOKUP($C10,'PP1 (1)'!$B$6:$B$66,'PP1 (1)'!$H$6:$H$66,"") -> 11 | AH10: =_xlfn.XLOOKUP($C10,'PP1 (2)'!$B$6:$B$100,'PP1 (2)'!$H$6:$H$100,"") -> 16 | AI10: =_xlfn.XLOOKUP($C10,'PP2 (1)'!$B$6:$B$99,'PP2 (1)'!$H$6:$H$99,"") -> 16 | AJ10: =_xlfn.XLOOKUP($C10,'PP2 (2)'!$B$6:$B$100,'PP2 (2)'!$H$6:$H$100,"") -> 16 | AK10: =_xlfn.XLOOKUP($C10,'PP3 (1)'!$B$5:$B$113,'PP3 (1)'!$H$5:$H$113,"") | AL10: =_xlfn.XLOOKUP($C10,'PP3 (2)'!$B$5:$B$112,'PP3 (2)'!$H$5:$H$112,"") | AM10: =_xlfn.XLOOKUP($C10,'PP4 (1)'!$B$6:$B$100,'PP4 (1)'!$H$6:$H$100,"") -> 16 | AN10: =_xlfn.XLOOKUP($C10,'PP4 (2)'!$B$6:$B$100,'PP4 (2)'!$H$6:$H$100,"") -> 20 | AO10: =_xlfn.XLOOKUP($C10,'PP5 (1)'!$B$6:$B$100,'PP5 (1)'!$H$6:$H$100,"") | AP10: =_xlfn.XLOOKUP($C10,'PP5(2)'!$B$6:$B$100,'PP5(2)'!$H$6:$H$100,"")
A11: =ROW()-4 -> 7 | B11: 1 | C11: KROCHMALSKI Jakub | D11: =SUM(E11:P11) -> 7.18 | E11: =_xlfn.XLOOKUP($C11,'MP (1)'!$B$6:$B$100,'MP (1)'!$E$6:$E$100,"") -> 0.83 | F11: =_xlfn.XLOOKUP($C11,'MP (2)'!$B$6:$B$100,'MP (2)'!$E$6:$E$100,"") -> 1 | G11: =_xlfn.XLOOKUP($C11,'PP1 (1)'!$B$6:$B$66,'PP1 (1)'!$E$6:$E$66,"") -> 1 | H11: =_xlfn.XLOOKUP($C11,'PP1 (2)'!$B$6:$B$100,'PP1 (2)'!$E$6:$E$100,"") -> 0.75 | I11: =_xlfn.XLOOKUP($C11,'PP2 (1)'!$B$6:$B$99,'PP2 (1)'!$E$6:$E$99,"") -> 0.8 | J11: =_xlfn.XLOOKUP($C11,'PP2 (2)'!$B$6:$B$100,'PP2 (2)'!$E$6:$E$100,"") -> 0.8 | K11: =_xlfn.XLOOKUP($C11,'PP3 (1)'!$B$5:$B$113,'PP3 (1)'!$E$5:$E$113,"") -> 1 | L11: =_xlfn.XLOOKUP($C11,'PP3 (2)'!$B$5:$B$112,'PP3 (2)'!$E$5:$E$112,"") -> 1 | M11: =_xlfn.XLOOKUP($C11,'PP4 (1)'!$B$6:$B$100,'PP4 (1)'!$E$6:$E$100,"") | N11: =_xlfn.XLOOKUP($C11,'PP4 (2)'!$B$6:$B$100,'PP4 (2)'!$E$6:$E$100,"") | O11: =_xlfn.XLOOKUP($C11,'PP5 (1)'!$B$6:$B$100,'PP5 (1)'!$E$6:$E$100,"") | P11: =_xlfn.XLOOKUP($C11,'PP5(2)'!$B$6:$B$100,'PP5(2)'!$E$6:$E$100,"") | Q11: =SUM(R11:AC11) -> 200 | R11: =_xlfn.XLOOKUP($C11,'MP (1)'!$B$6:$B$100,'MP (1)'!$F$6:$F$100,"") -> 26 | S11: =_xlfn.XLOOKUP($C11,'MP (2)'!$B$6:$B$100,'MP (2)'!$F$6:$F$100,"") -> 25 | T11: =_xlfn.XLOOKUP($C11,'PP1 (1)'!$B$6:$B$66,'PP1 (1)'!$F$6:$F$66,"") -> 25 | U11: =_xlfn.XLOOKUP($C11,'PP1 (2)'!$B$6:$B$100,'PP1 (2)'!$F$6:$F$100,"") -> 18 | V11: =_xlfn.XLOOKUP($C11,'PP2 (1)'!$B$6:$B$99,'PP2 (1)'!$F$6:$F$99,"") -> 24 | W11: =_xlfn.XLOOKUP($C11,'PP2 (2)'!$B$6:$B$100,'PP2 (2)'!$F$6:$F$100,"") -> 22 | X11: =_xlfn.XLOOKUP($C11,'PP3 (1)'!$B$5:$B$113,'PP3 (1)'!$F$5:$F$113,"") -> 30 | Y11: =_xlfn.XLOOKUP($C11,'PP3 (2)'!$B$5:$B$112,'PP3 (2)'!$F$5:$F$112,"") -> 30 | Z11: =_xlfn.XLOOKUP($C11,'PP4 (1)'!$B$6:$B$100,'PP4 (1)'!$F$6:$F$100,"") | AA11: =_xlfn.XLOOKUP($C11,'PP4 (2)'!$B$6:$B$100,'PP4 (2)'!$F$6:$F$100,"") | AB11: =_xlfn.XLOOKUP($C11,'PP5 (1)'!$B$6:$B$100,'PP5 (1)'!$F$6:$F$100,"") | AC11: =_xlfn.XLOOKUP($C11,'PP5(2)'!$B$6:$B$100,'PP5(2)'!$F$6:$F$100,"") | AD11: =SUM(AE11:AP11) -> 128 | AE11: =_xlfn.XLOOKUP($C11,'MP (1)'!$B$6:$B$100,'MP (1)'!$H$6:$H$100,"") -> 14 | AF11: =_xlfn.XLOOKUP($C11,'MP (2)'!$B$6:$B$100,'MP (2)'!$H$6:$H$100,"") -> 21 | AG11: =_xlfn.XLOOKUP($C11,'PP1 (1)'!$B$6:$B$66,'PP1 (1)'!$H$6:$H$66,"") -> 16 | AH11: =_xlfn.XLOOKUP($C11,'PP1 (2)'!$B$6:$B$100,'PP1 (2)'!$H$6:$H$100,"") -> 6 | AI11: =_xlfn.XLOOKUP($C11,'PP2 (1)'!$B$6:$B$99,'PP2 (1)'!$H$6:$H$99,"") -> 18 | AJ11: =_xlfn.XLOOKUP($C11,'PP2 (2)'!$B$6:$B$100,'PP2 (2)'!$H$6:$H$100,"") -> 14 | AK11: =_xlfn.XLOOKUP($C11,'PP3 (1)'!$B$5:$B$113,'PP3 (1)'!$H$5:$H$113,"") -> 15 | AL11: =_xlfn.XLOOKUP($C11,'PP3 (2)'!$B$5:$B$112,'PP3 (2)'!$H$5:$H$112,"") -> 24 | AM11: =_xlfn.XLOOKUP($C11,'PP4 (1)'!$B$6:$B$100,'PP4 (1)'!$H$6:$H$100,"") | AN11: =_xlfn.XLOOKUP($C11,'PP4 (2)'!$B$6:$B$100,'PP4 (2)'!$H$6:$H$100,"") | AO11: =_xlfn.XLOOKUP($C11,'PP5 (1)'!$B$6:$B$100,'PP5 (1)'!$H$6:$H$100,"") | AP11: =_xlfn.XLOOKUP($C11,'PP5(2)'!$B$6:$B$100,'PP5(2)'!$H$6:$H$100,"")
A12: =ROW()-4 -> 8 | B12: 3 | C12: GAJDA Leszek | D12: =SUM(E12:P12) -> 6.69 | E12: =_xlfn.XLOOKUP($C12,'MP (1)'!$B$6:$B$100,'MP (1)'!$E$6:$E$100,"") -> 0.6 | F12: =_xlfn.XLOOKUP($C12,'MP (2)'!$B$6:$B$100,'MP (2)'!$E$6:$E$100,"") -> 1 | G12: =_xlfn.XLOOKUP($C12,'PP1 (1)'!$B$6:$B$66,'PP1 (1)'!$E$6:$E$66,"") | H12: =_xlfn.XLOOKUP($C12,'PP1 (2)'!$B$6:$B$100,'PP1 (2)'!$E$6:$E$100,"") | I12: =_xlfn.XLOOKUP($C12,'PP2 (1)'!$B$6:$B$99,'PP2 (1)'!$E$6:$E$99,"") -> 0.8 | J12: =_xlfn.XLOOKUP($C12,'PP2 (2)'!$B$6:$B$100,'PP2 (2)'!$E$6:$E$100,"") -> 1 | K12: =_xlfn.XLOOKUP($C12,'PP3 (1)'!$B$5:$B$113,'PP3 (1)'!$E$5:$E$113,"") -> 0.67 | L12: =_xlfn.XLOOKUP($C12,'PP3 (2)'!$B$5:$B$112,'PP3 (2)'!$E$5:$E$112,"") -> 0.67 | M12: =_xlfn.XLOOKUP($C12,'PP4 (1)'!$B$6:$B$100,'PP4 (1)'!$E$6:$E$100,"") -> 0.4 | N12: =_xlfn.XLOOKUP($C12,'PP4 (2)'!$B$6:$B$100,'PP4 (2)'!$E$6:$E$100,"") -> 0.4 | O12: =_xlfn.XLOOKUP($C12,'PP5 (1)'!$B$6:$B$100,'PP5 (1)'!$E$6:$E$100,"") -> 0.75 | P12: =_xlfn.XLOOKUP($C12,'PP5(2)'!$B$6:$B$100,'PP5(2)'!$E$6:$E$100,"") -> 0.4 | Q12: =SUM(R12:AC12) -> 218 | R12: =_xlfn.XLOOKUP($C12,'MP (1)'!$B$6:$B$100,'MP (1)'!$F$6:$F$100,"") -> 20 | S12: =_xlfn.XLOOKUP($C12,'MP (2)'!$B$6:$B$100,'MP (2)'!$F$6:$F$100,"") -> 25 | T12: =_xlfn.XLOOKUP($C12,'PP1 (1)'!$B$6:$B$66,'PP1 (1)'!$F$6:$F$66,"") | U12: =_xlfn.XLOOKUP($C12,'PP1 (2)'!$B$6:$B$100,'PP1 (2)'!$F$6:$F$100,"") | V12: =_xlfn.XLOOKUP($C12,'PP2 (1)'!$B$6:$B$99,'PP2 (1)'!$F$6:$F$99,"") -> 23 | W12: =_xlfn.XLOOKUP($C12,'PP2 (2)'!$B$6:$B$100,'PP2 (2)'!$F$6:$F$100,"") -> 25 | X12: =_xlfn.XLOOKUP($C12,'PP3 (1)'!$B$5:$B$113,'PP3 (1)'!$F$5:$F$113,"") -> 27 | Y12: =_xlfn.XLOOKUP($C12,'PP3 (2)'!$B$5:$B$112,'PP3 (2)'!$F$5:$F$112,"") -> 23 | Z12: =_xlfn.XLOOKUP($C12,'PP4 (1)'!$B$6:$B$100,'PP4 (1)'!$F$6:$F$100,"") -> 18 | AA12: =_xlfn.XLOOKUP($C12,'PP4 (2)'!$B$6:$B$100,'PP4 (2)'!$F$6:$F$100,"") -> 20 | AB12: =_xlfn.XLOOKUP($C12,'PP5 (1)'!$B$6:$B$100,'PP5 (1)'!$F$6:$F$100,"") -> 19 | AC12: =_xlfn.XLOOKUP($C12,'PP5(2)'!$B$6:$B$100,'PP5(2)'!$F$6:$F$100,"") -> 18 | AD12: =SUM(AE12:AP12) -> 70 | AE12: =_xlfn.XLOOKUP($C12,'MP (1)'!$B$6:$B$100,'MP (1)'!$H$6:$H$100,"") -> 4 | AF12: =_xlfn.XLOOKUP($C12,'MP (2)'!$B$6:$B$100,'MP (2)'!$H$6:$H$100,"") -> 17 | AG12: =_xlfn.XLOOKUP($C12,'PP1 (1)'!$B$6:$B$66,'PP1 (1)'!$H$6:$H$66,"") | AH12: =_xlfn.XLOOKUP($C12,'PP1 (2)'!$B$6:$B$100,'PP1 (2)'!$H$6:$H$100,"") | AI12: =_xlfn.XLOOKUP($C12,'PP2 (1)'!$B$6:$B$99,'PP2 (1)'!$H$6:$H$99,"") -> 12 | AJ12: =_xlfn.XLOOKUP($C12,'PP2 (2)'!$B$6:$B$100,'PP2 (2)'!$H$6:$H$100,"") -> 15 | AK12: =_xlfn.XLOOKUP($C12,'PP3 (1)'!$B$5:$B$113,'PP3 (1)'!$H$5:$H$113,"") -> 12 | AL12: =_xlfn.XLOOKUP($C12,'PP3 (2)'!$B$5:$B$112,'PP3 (2)'!$H$5:$H$112,"") -> 3 | AM12: =_xlfn.XLOOKUP($C12,'PP4 (1)'!$B$6:$B$100,'PP4 (1)'!$H$6:$H$100,"") -> -2 | AN12: =_xlfn.XLOOKUP($C12,'PP4 (2)'!$B$6:$B$100,'PP4 (2)'!$H$6:$H$100,"") -> 0 | AO12: =_xlfn.XLOOKUP($C12,'PP5 (1)'!$B$6:$B$100,'PP5 (1)'!$H$6:$H$100,"") -> 8 | AP12: =_xlfn.XLOOKUP($C12,'PP5(2)'!$B$6:$B$100,'PP5(2)'!$H$6:$H$100,"") -> 1
A13: =ROW()-4 -> 9 | B13: 2 | C13: MAZIK Aleksander | D13: =SUM(E13:P13) -> 6.69 | E13: =_xlfn.XLOOKUP($C13,'MP (1)'!$B$6:$B$100,'MP (1)'!$E$6:$E$100,"") -> 0.75 | F13: =_xlfn.XLOOKUP($C13,'MP (2)'!$B$6:$B$100,'MP (2)'!$E$6:$E$100,"") -> 0.4 | G13: =_xlfn.XLOOKUP($C13,'PP1 (1)'!$B$6:$B$66,'PP1 (1)'!$E$6:$E$66,"") -> 0.2 | H13: =_xlfn.XLOOKUP($C13,'PP1 (2)'!$B$6:$B$100,'PP1 (2)'!$E$6:$E$100,"") -> 0.2 | I13: =_xlfn.XLOOKUP($C13,'PP2 (1)'!$B$6:$B$99,'PP2 (1)'!$E$6:$E$99,"") -> 0.4 | J13: =_xlfn.XLOOKUP($C13,'PP2 (2)'!$B$6:$B$100,'PP2 (2)'!$E$6:$E$100,"") -> 0.6 | K13: =_xlfn.XLOOKUP($C13,'PP3 (1)'!$B$5:$B$113,'PP3 (1)'!$E$5:$E$113,"") -> 0.67 | L13: =_xlfn.XLOOKUP($C13,'PP3 (2)'!$B$5:$B$112,'PP3 (2)'!$E$5:$E$112,"") -> 0.67 | M13: =_xlfn.XLOOKUP($C13,'PP4 (1)'!$B$6:$B$100,'PP4 (1)'!$E$6:$E$100,"") -> 0.6 | N13: =_xlfn.XLOOKUP($C13,'PP4 (2)'!$B$6:$B$100,'PP4 (2)'!$E$6:$E$100,"") -> 0.6 | O13: =_xlfn.XLOOKUP($C13,'PP5 (1)'!$B$6:$B$100,'PP5 (1)'!$E$6:$E$100,"") -> 1 | P13: =_xlfn.XLOOKUP($C13,'PP5(2)'!$B$6:$B$100,'PP5(2)'!$E$6:$E$100,"") -> 0.6 | Q13: =SUM(R13:AC13) -> 221 | R13: =_xlfn.XLOOKUP($C13,'MP (1)'!$B$6:$B$100,'MP (1)'!$F$6:$F$100,"") -> 19 | S13: =_xlfn.XLOOKUP($C13,'MP (2)'!$B$6:$B$100,'MP (2)'!$F$6:$F$100,"") -> 17 | T13: =_xlfn.XLOOKUP($C13,'PP1 (1)'!$B$6:$B$66,'PP1 (1)'!$F$6:$F$66,"") -> 7 | U13: =_xlfn.XLOOKUP($C13,'PP1 (2)'!$B$6:$B$100,'PP1 (2)'!$F$6:$F$100,"") -> 14 | V13: =_xlfn.XLOOKUP($C13,'PP2 (1)'!$B$6:$B$99,'PP2 (1)'!$F$6:$F$99,"") -> 14 | W13: =_xlfn.XLOOKUP($C13,'PP2 (2)'!$B$6:$B$100,'PP2 (2)'!$F$6:$F$100,"") -> 21 | X13: =_xlfn.XLOOKUP($C13,'PP3 (1)'!$B$5:$B$113,'PP3 (1)'!$F$5:$F$113,"") -> 24 | Y13: =_xlfn.XLOOKUP($C13,'PP3 (2)'!$B$5:$B$112,'PP3 (2)'!$F$5:$F$112,"") -> 22 | Z13: =_xlfn.XLOOKUP($C13,'PP4 (1)'!$B$6:$B$100,'PP4 (1)'!$F$6:$F$100,"") -> 23 | AA13: =_xlfn.XLOOKUP($C13,'PP4 (2)'!$B$6:$B$100,'PP4 (2)'!$F$6:$F$100,"") -> 19 | AB13: =_xlfn.XLOOKUP($C13,'PP5 (1)'!$B$6:$B$100,'PP5 (1)'!$F$6:$F$100,"") -> 20 | AC13: =_xlfn.XLOOKUP($C13,'PP5(2)'!$B$6:$B$100,'PP5(2)'!$F$6:$F$100,"") -> 21 | AD13: =SUM(AE13:AP13) -> 13 | AE13: =_xlfn.XLOOKUP($C13,'MP (1)'!$B$6:$B$100,'MP (1)'!$H$6:$H$100,"") -> 9 | AF13: =_xlfn.XLOOKUP($C13,'MP (2)'!$B$6:$B$100,'MP (2)'!$H$6:$H$100,"") -> -1 | AG13: =_xlfn.XLOOKUP($C13,'PP1 (1)'!$B$6:$B$66,'PP1 (1)'!$H$6:$H$66,"") -> -13 | AH13: =_xlfn.XLOOKUP($C13,'PP1 (2)'!$B$6:$B$100,'PP1 (2)'!$H$6:$H$100,"") -> -9 | AI13: =_xlfn.XLOOKUP($C13,'PP2 (1)'!$B$6:$B$99,'PP2 (1)'!$H$6:$H$99,"") -> -5 | AJ13: =_xlfn.XLOOKUP($C13,'PP2 (2)'!$B$6:$B$100,'PP2 (2)'!$H$6:$H$100,"") -> 4 | AK13: =_xlfn.XLOOKUP($C13,'PP3 (1)'!$B$5:$B$113,'PP3 (1)'!$H$5:$H$113,"") -> 4 | AL13: =_xlfn.XLOOKUP($C13,'PP3 (2)'!$B$5:$B$112,'PP3 (2)'!$H$5:$H$112,"") -> 2 | AM13: =_xlfn.XLOOKUP($C13,'PP4 (1)'!$B$6:$B$100,'PP4 (1)'!$H$6:$H$100,"") -> 8 | AN13: =_xlfn.XLOOKUP($C13,'PP4 (2)'!$B$6:$B$100,'PP4 (2)'!$H$6:$H$100,"") -> 1 | AO13: =_xlfn.XLOOKUP($C13,'PP5 (1)'!$B$6:$B$100,'PP5 (1)'!$H$6:$H$100,"") -> 9 | AP13: =_xlfn.XLOOKUP($C13,'PP5(2)'!$B$6:$B$100,'PP5(2)'!$H$6:$H$100,"") -> 4
A14: =ROW()-4 -> 10 | B14: 0k | C14: OWCZAREK Ewelina | D14: =SUM(E14:P14) -> 6.67 | E14: =_xlfn.XLOOKUP($C14,'MP (1)'!$B$6:$B$100,'MP (1)'!$E$6:$E$100,"") -> 0.6 | F14: =_xlfn.XLOOKUP($C14,'MP (2)'!$B$6:$B$100,'MP (2)'!$E$6:$E$100,"") -> 0.6 | G14: =_xlfn.XLOOKUP($C14,'PP1 (1)'!$B$6:$B$66,'PP1 (1)'!$E$6:$E$66,"") -> 0.8 | H14: =_xlfn.XLOOKUP($C14,'PP1 (2)'!$B$6:$B$100,'PP1 (2)'!$E$6:$E$100,"") -> 0.4 | I14: =_xlfn.XLOOKUP($C14,'PP2 (1)'!$B$6:$B$99,'PP2 (1)'!$E$6:$E$99,"") -> 0.4 | J14: =_xlfn.XLOOKUP($C14,'PP2 (2)'!$B$6:$B$100,'PP2 (2)'!$E$6:$E$100,"") -> 0.4 | K14: =_xlfn.XLOOKUP($C14,'PP3 (1)'!$B$5:$B$113,'PP3 (1)'!$E$5:$E$113,"") -> 0.67 | L14: =_xlfn.XLOOKUP($C14,'PP3 (2)'!$B$5:$B$112,'PP3 (2)'!$E$5:$E$112,"") -> 0.4 | M14: =_xlfn.XLOOKUP($C14,'PP4 (1)'!$B$6:$B$100,'PP4 (1)'!$E$6:$E$100,"") -> 0.6 | N14: =_xlfn.XLOOKUP($C14,'PP4 (2)'!$B$6:$B$100,'PP4 (2)'!$E$6:$E$100,"") -> 0.8 | O14: =_xlfn.XLOOKUP($C14,'PP5 (1)'!$B$6:$B$100,'PP5 (1)'!$E$6:$E$100,"") -> 0.2 | P14: =_xlfn.XLOOKUP($C14,'PP5(2)'!$B$6:$B$100,'PP5(2)'!$E$6:$E$100,"") -> 0.8 | Q14: =SUM(R14:AC14) -> 232 | R14: =_xlfn.XLOOKUP($C14,'MP (1)'!$B$6:$B$100,'MP (1)'!$F$6:$F$100,"") -> 21 | S14: =_xlfn.XLOOKUP($C14,'MP (2)'!$B$6:$B$100,'MP (2)'!$F$6:$F$100,"") -> 20 | T14: =_xlfn.XLOOKUP($C14,'PP1 (1)'!$B$6:$B$66,'PP1 (1)'!$F$6:$F$66,"") -> 21 | U14: =_xlfn.XLOOKUP($C14,'PP1 (2)'!$B$6:$B$100,'PP1 (2)'!$F$6:$F$100,"") -> 19 | V14: =_xlfn.XLOOKUP($C14,'PP2 (1)'!$B$6:$B$99,'PP2 (1)'!$F$6:$F$99,"") -> 18 | W14: =_xlfn.XLOOKUP($C14,'PP2 (2)'!$B$6:$B$100,'PP2 (2)'!$F$6:$F$100,"") -> 12 | X14: =_xlfn.XLOOKUP($C14,'PP3 (1)'!$B$5:$B$113,'PP3 (1)'!$F$5:$F$113,"") -> 27 | Y14: =_xlfn.XLOOKUP($C14,'PP3 (2)'!$B$5:$B$112,'PP3 (2)'!$F$5:$F$112,"") -> 17 | Z14: =_xlfn.XLOOKUP($C14,'PP4 (1)'!$B$6:$B$100,'PP4 (1)'!$F$6:$F$100,"") -> 18 | AA14: =_xlfn.XLOOKUP($C14,'PP4 (2)'!$B$6:$B$100,'PP4 (2)'!$F$6:$F$100,"") -> 20 | AB14: =_xlfn.XLOOKUP($C14,'PP5 (1)'!$B$6:$B$100,'PP5 (1)'!$F$6:$F$100,"") -> 17 | AC14: =_xlfn.XLOOKUP($C14,'PP5(2)'!$B$6:$B$100,'PP5(2)'!$F$6:$F$100,"") -> 22 | AD14: =SUM(AE14:AP14) -> 36 | AE14: =_xlfn.XLOOKUP($C14,'MP (1)'!$B$6:$B$100,'MP (1)'!$H$6:$H$100,"") -> 6 | AF14: =_xlfn.XLOOKUP($C14,'MP (2)'!$B$6:$B$100,'MP (2)'!$H$6:$H$100,"") -> 6 | AG14: =_xlfn.XLOOKUP($C14,'PP1 (1)'!$B$6:$B$66,'PP1 (1)'!$H$6:$H$66,"") -> 8 | AH14: =_xlfn.XLOOKUP($C14,'PP1 (2)'!$B$6:$B$100,'PP1 (2)'!$H$6:$H$100,"") -> 2 | AI14: =_xlfn.XLOOKUP($C14,'PP2 (1)'!$B$6:$B$99,'PP2 (1)'!$H$6:$H$99,"") -> -1 | AJ14: =_xlfn.XLOOKUP($C14,'PP2 (2)'!$B$6:$B$100,'PP2 (2)'!$H$6:$H$100,"") -> -6 | AK14: =_xlfn.XLOOKUP($C14,'PP3 (1)'!$B$5:$B$113,'PP3 (1)'!$H$5:$H$113,"") -> 8 | AL14: =_xlfn.XLOOKUP($C14,'PP3 (2)'!$B$5:$B$112,'PP3 (2)'!$H$5:$H$112,"") -> -2 | AM14: =_xlfn.XLOOKUP($C14,'PP4 (1)'!$B$6:$B$100,'PP4 (1)'!$H$6:$H$100,"") -> 2 | AN14: =_xlfn.XLOOKUP($C14,'PP4 (2)'!$B$6:$B$100,'PP4 (2)'!$H$6:$H$100,"") -> 3 | AO14: =_xlfn.XLOOKUP($C14,'PP5 (1)'!$B$6:$B$100,'PP5 (1)'!$H$6:$H$100,"") -> -3 | AP14: =_xlfn.XLOOKUP($C14,'PP5(2)'!$B$6:$B$100,'PP5(2)'!$H$6:$H$100,"") -> 13
A15: =ROW()-4 -> 11 | B15: 1 | C15: PRZYSTAJKO Daniel | D15: =SUM(E15:P15) -> 6.47 | E15: =_xlfn.XLOOKUP($C15,'MP (1)'!$B$6:$B$100,'MP (1)'!$E$6:$E$100,"") | F15: =_xlfn.XLOOKUP($C15,'MP (2)'!$B$6:$B$100,'MP (2)'!$E$6:$E$100,"") | G15: =_xlfn.XLOOKUP($C15,'PP1 (1)'!$B$6:$B$66,'PP1 (1)'!$E$6:$E$66,"") -> 0.6 | H15: =_xlfn.XLOOKUP($C15,'PP1 (2)'!$B$6:$B$100,'PP1 (2)'!$E$6:$E$100,"") -> 0.8 | I15: =_xlfn.XLOOKUP($C15,'PP2 (1)'!$B$6:$B$99,'PP2 (1)'!$E$6:$E$99,"") -> 0.67 | J15: =_xlfn.XLOOKUP($C15,'PP2 (2)'!$B$6:$B$100,'PP2 (2)'!$E$6:$E$100,"") -> 0.6 | K15: =_xlfn.XLOOKUP($C15,'PP3 (1)'!$B$5:$B$113,'PP3 (1)'!$E$5:$E$113,"") | L15: =_xlfn.XLOOKUP($C15,'PP3 (2)'!$B$5:$B$112,'PP3 (2)'!$E$5:$E$112,"") | M15: =_xlfn.XLOOKUP($C15,'PP4 (1)'!$B$6:$B$100,'PP4 (1)'!$E$6:$E$100,"") -> 1 | N15: =_xlfn.XLOOKUP($C15,'PP4 (2)'!$B$6:$B$100,'PP4 (2)'!$E$6:$E$100,"") -> 1 | O15: =_xlfn.XLOOKUP($C15,'PP5 (1)'!$B$6:$B$100,'PP5 (1)'!$E$6:$E$100,"") -> 0.8 | P15: =_xlfn.XLOOKUP($C15,'PP5(2)'!$B$6:$B$100,'PP5(2)'!$E$6:$E$100,"") -> 1 | Q15: =SUM(R15:AC15) -> 178 | R15: =_xlfn.XLOOKUP($C15,'MP (1)'!$B$6:$B$100,'MP (1)'!$F$6:$F$100,"") | S15: =_xlfn.XLOOKUP($C15,'MP (2)'!$B$6:$B$100,'MP (2)'!$F$6:$F$100,"") | T15: =_xlfn.XLOOKUP($C15,'PP1 (1)'!$B$6:$B$66,'PP1 (1)'!$F$6:$F$66,"") -> 19 | U15: =_xlfn.XLOOKUP($C15,'PP1 (2)'!$B$6:$B$100,'PP1 (2)'!$F$6:$F$100,"") -> 21 | V15: =_xlfn.XLOOKUP($C15,'PP2 (1)'!$B$6:$B$99,'PP2 (1)'!$F$6:$F$99,"") -> 23 | W15: =_xlfn.XLOOKUP($C15,'PP2 (2)'!$B$6:$B$100,'PP2 (2)'!$F$6:$F$100,"") -> 18 | X15: =_xlfn.XLOOKUP($C15,'PP3 (1)'!$B$5:$B$113,'PP3 (1)'!$F$5:$F$113,"") | Y15: =_xlfn.XLOOKUP($C15,'PP3 (2)'!$B$5:$B$112,'PP3 (2)'!$F$5:$F$112,"") | Z15: =_xlfn.XLOOKUP($C15,'PP4 (1)'!$B$6:$B$100,'PP4 (1)'!$F$6:$F$100,"") -> 25 | AA15: =_xlfn.XLOOKUP($C15,'PP4 (2)'!$B$6:$B$100,'PP4 (2)'!$F$6:$F$100,"") -> 25 | AB15: =_xlfn.XLOOKUP($C15,'PP5 (1)'!$B$6:$B$100,'PP5 (1)'!$F$6:$F$100,"") -> 22 | AC15: =_xlfn.XLOOKUP($C15,'PP5(2)'!$B$6:$B$100,'PP5(2)'!$F$6:$F$100,"") -> 25 | AD15: =SUM(AE15:AP15) -> 80 | AE15: =_xlfn.XLOOKUP($C15,'MP (1)'!$B$6:$B$100,'MP (1)'!$H$6:$H$100,"") | AF15: =_xlfn.XLOOKUP($C15,'MP (2)'!$B$6:$B$100,'MP (2)'!$H$6:$H$100,"") | AG15: =_xlfn.XLOOKUP($C15,'PP1 (1)'!$B$6:$B$66,'PP1 (1)'!$H$6:$H$66,"") -> 5 | AH15: =_xlfn.XLOOKUP($C15,'PP1 (2)'!$B$6:$B$100,'PP1 (2)'!$H$6:$H$100,"") -> 7 | AI15: =_xlfn.XLOOKUP($C15,'PP2 (1)'!$B$6:$B$99,'PP2 (1)'!$H$6:$H$99,"") -> 3 | AJ15: =_xlfn.XLOOKUP($C15,'PP2 (2)'!$B$6:$B$100,'PP2 (2)'!$H$6:$H$100,"") -> 3 | AK15: =_xlfn.XLOOKUP($C15,'PP3 (1)'!$B$5:$B$113,'PP3 (1)'!$H$5:$H$113,"") | AL15: =_xlfn.XLOOKUP($C15,'PP3 (2)'!$B$5:$B$112,'PP3 (2)'!$H$5:$H$112,"") | AM15: =_xlfn.XLOOKUP($C15,'PP4 (1)'!$B$6:$B$100,'PP4 (1)'!$H$6:$H$100,"") -> 14 | AN15: =_xlfn.XLOOKUP($C15,'PP4 (2)'!$B$6:$B$100,'PP4 (2)'!$H$6:$H$100,"") -> 21 | AO15: =_xlfn.XLOOKUP($C15,'PP5 (1)'!$B$6:$B$100,'PP5 (1)'!$H$6:$H$100,"") -> 9 | AP15: =_xlfn.XLOOKUP($C15,'PP5(2)'!$B$6:$B$100,'PP5(2)'!$H$6:$H$100,"") -> 18
A16: =ROW()-4 -> 12 | B16: 2 | C16: KACZMAREK Paweł | D16: =SUM(E16:P16) -> 6.4 | E16: =_xlfn.XLOOKUP($C16,'MP (1)'!$B$6:$B$100,'MP (1)'!$E$6:$E$100,"") -> 0.4 | F16: =_xlfn.XLOOKUP($C16,'MP (2)'!$B$6:$B$100,'MP (2)'!$E$6:$E$100,"") -> 0.8 | G16: =_xlfn.XLOOKUP($C16,'PP1 (1)'!$B$6:$B$66,'PP1 (1)'!$E$6:$E$66,"") -> 0.8 | H16: =_xlfn.XLOOKUP($C16,'PP1 (2)'!$B$6:$B$100,'PP1 (2)'!$E$6:$E$100,"") -> 0.6 | I16: =_xlfn.XLOOKUP($C16,'PP2 (1)'!$B$6:$B$99,'PP2 (1)'!$E$6:$E$99,"") | J16: =_xlfn.XLOOKUP($C16,'PP2 (2)'!$B$6:$B$100,'PP2 (2)'!$E$6:$E$100,"") | K16: =_xlfn.XLOOKUP($C16,'PP3 (1)'!$B$5:$B$113,'PP3 (1)'!$E$5:$E$113,"") -> 0.67 | L16: =_xlfn.XLOOKUP($C16,'PP3 (2)'!$B$5:$B$112,'PP3 (2)'!$E$5:$E$112,"") -> 0.83 | M16: =_xlfn.XLOOKUP($C16,'PP4 (1)'!$B$6:$B$100,'PP4 (1)'!$E$6:$E$100,"") -> 0.2 | N16: =_xlfn.XLOOKUP($C16,'PP4 (2)'!$B$6:$B$100,'PP4 (2)'!$E$6:$E$100,"") -> 0.5 | O16: =_xlfn.XLOOKUP($C16,'PP5 (1)'!$B$6:$B$100,'PP5 (1)'!$E$6:$E$100,"") -> 0.8 | P16: =_xlfn.XLOOKUP($C16,'PP5(2)'!$B$6:$B$100,'PP5(2)'!$E$6:$E$100,"") -> 0.8 | Q16: =SUM(R16:AC16) -> 201 | R16: =_xlfn.XLOOKUP($C16,'MP (1)'!$B$6:$B$100,'MP (1)'!$F$6:$F$100,"") -> 16 | S16: =_xlfn.XLOOKUP($C16,'MP (2)'!$B$6:$B$100,'MP (2)'!$F$6:$F$100,"") -> 20 | T16: =_xlfn.XLOOKUP($C16,'PP1 (1)'!$B$6:$B$66,'PP1 (1)'!$F$6:$F$66,"") -> 23 | U16: =_xlfn.XLOOKUP($C16,'PP1 (2)'!$B$6:$B$100,'PP1 (2)'!$F$6:$F$100,"") -> 17 | V16: =_xlfn.XLOOKUP($C16,'PP2 (1)'!$B$6:$B$99,'PP2 (1)'!$F$6:$F$99,"") | W16: =_xlfn.XLOOKUP($C16,'PP2 (2)'!$B$6:$B$100,'PP2 (2)'!$F$6:$F$100,"") | X16: =_xlfn.XLOOKUP($C16,'PP3 (1)'!$B$5:$B$113,'PP3 (1)'!$F$5:$F$113,"") -> 23 | Y16: =_xlfn.XLOOKUP($C16,'PP3 (2)'!$B$5:$B$112,'PP3 (2)'!$F$5:$F$112,"") -> 28 | Z16: =_xlfn.XLOOKUP($C16,'PP4 (1)'!$B$6:$B$100,'PP4 (1)'!$F$6:$F$100,"") -> 16 | AA16: =_xlfn.XLOOKUP($C16,'PP4 (2)'!$B$6:$B$100,'PP4 (2)'!$F$6:$F$100,"") -> 12 | AB16: =_xlfn.XLOOKUP($C16,'PP5 (1)'!$B$6:$B$100,'PP5 (1)'!$F$6:$F$100,"") -> 22 | AC16: =_xlfn.XLOOKUP($C16,'PP5(2)'!$B$6:$B$100,'PP5(2)'!$F$6:$F$100,"") -> 24 | AD16: =SUM(AE16:AP16) -> 41 | AE16: =_xlfn.XLOOKUP($C16,'MP (1)'!$B$6:$B$100,'MP (1)'!$H$6:$H$100,"") -> -5 | AF16: =_xlfn.XLOOKUP($C16,'MP (2)'!$B$6:$B$100,'MP (2)'!$H$6:$H$100,"") -> 6 | AG16: =_xlfn.XLOOKUP($C16,'PP1 (1)'!$B$6:$B$66,'PP1 (1)'!$H$6:$H$66,"") -> 7 | AH16: =_xlfn.XLOOKUP($C16,'PP1 (2)'!$B$6:$B$100,'PP1 (2)'!$H$6:$H$100,"") -> 0 | AI16: =_xlfn.XLOOKUP($C16,'PP2 (1)'!$B$6:$B$99,'PP2 (1)'!$H$6:$H$99,"") | AJ16: =_xlfn.XLOOKUP($C16,'PP2 (2)'!$B$6:$B$100,'PP2 (2)'!$H$6:$H$100,"") | AK16: =_xlfn.XLOOKUP($C16,'PP3 (1)'!$B$5:$B$113,'PP3 (1)'!$H$5:$H$113,"") -> 6 | AL16: =_xlfn.XLOOKUP($C16,'PP3 (2)'!$B$5:$B$112,'PP3 (2)'!$H$5:$H$112,"") -> 18 | AM16: =_xlfn.XLOOKUP($C16,'PP4 (1)'!$B$6:$B$100,'PP4 (1)'!$H$6:$H$100,"") -> -8 | AN16: =_xlfn.XLOOKUP($C16,'PP4 (2)'!$B$6:$B$100,'PP4 (2)'!$H$6:$H$100,"") -> 0 | AO16: =_xlfn.XLOOKUP($C16,'PP5 (1)'!$B$6:$B$100,'PP5 (1)'!$H$6:$H$100,"") -> 7 | AP16: =_xlfn.XLOOKUP($C16,'PP5(2)'!$B$6:$B$100,'PP5(2)'!$H$6:$H$100,"") -> 10
A17: =ROW()-4 -> 13 | B17: 2 | C17: GAJDA Zbigniew | D17: =SUM(E17:P17) -> 5.87 | E17: =_xlfn.XLOOKUP($C17,'MP (1)'!$B$6:$B$100,'MP (1)'!$E$6:$E$100,"") -> 0.5 | F17: =_xlfn.XLOOKUP($C17,'MP (2)'!$B$6:$B$100,'MP (2)'!$E$6:$E$100,"") -> 0.4 | G17: =_xlfn.XLOOKUP($C17,'PP1 (1)'!$B$6:$B$66,'PP1 (1)'!$E$6:$E$66,"") | H17: =_xlfn.XLOOKUP($C17,'PP1 (2)'!$B$6:$B$100,'PP1 (2)'!$E$6:$E$100,"") | I17: =_xlfn.XLOOKUP($C17,'PP2 (1)'!$B$6:$B$99,'PP2 (1)'!$E$6:$E$99,"") -> 0.6 | J17: =_xlfn.XLOOKUP($C17,'PP2 (2)'!$B$6:$B$100,'PP2 (2)'!$E$6:$E$100,"") -> 0.4 | K17: =_xlfn.XLOOKUP($C17,'PP3 (1)'!$B$5:$B$113,'PP3 (1)'!$E$5:$E$113,"") -> 0.5 | L17: =_xlfn.XLOOKUP($C17,'PP3 (2)'!$B$5:$B$112,'PP3 (2)'!$E$5:$E$112,"") -> 0.67 | M17: =_xlfn.XLOOKUP($C17,'PP4 (1)'!$B$6:$B$100,'PP4 (1)'!$E$6:$E$100,"") -> 0.6 | N17: =_xlfn.XLOOKUP($C17,'PP4 (2)'!$B$6:$B$100,'PP4 (2)'!$E$6:$E$100,"") -> 0.8 | O17: =_xlfn.XLOOKUP($C17,'PP5 (1)'!$B$6:$B$100,'PP5 (1)'!$E$6:$E$100,"") -> 0.6 | P17: =_xlfn.XLOOKUP($C17,'PP5(2)'!$B$6:$B$100,'PP5(2)'!$E$6:$E$100,"") -> 0.8 | Q17: =SUM(R17:AC17) -> 182 | R17: =_xlfn.XLOOKUP($C17,'MP (1)'!$B$6:$B$100,'MP (1)'!$F$6:$F$100,"") -> 12 | S17: =_xlfn.XLOOKUP($C17,'MP (2)'!$B$6:$B$100,'MP (2)'!$F$6:$F$100,"") -> 15 | T17: =_xlfn.XLOOKUP($C17,'PP1 (1)'!$B$6:$B$66,'PP1 (1)'!$F$6:$F$66,"") | U17: =_xlfn.XLOOKUP($C17,'PP1 (2)'!$B$6:$B$100,'PP1 (2)'!$F$6:$F$100,"") | V17: =_xlfn.XLOOKUP($C17,'PP2 (1)'!$B$6:$B$99,'PP2 (1)'!$F$6:$F$99,"") -> 15 | W17: =_xlfn.XLOOKUP($C17,'PP2 (2)'!$B$6:$B$100,'PP2 (2)'!$F$6:$F$100,"") -> 13 | X17: =_xlfn.XLOOKUP($C17,'PP3 (1)'!$B$5:$B$113,'PP3 (1)'!$F$5:$F$113,"") -> 21 | Y17: =_xlfn.XLOOKUP($C17,'PP3 (2)'!$B$5:$B$112,'PP3 (2)'!$F$5:$F$112,"") -> 24 | Z17: =_xlfn.XLOOKUP($C17,'PP4 (1)'!$B$6:$B$100,'PP4 (1)'!$F$6:$F$100,"") -> 21 | AA17: =_xlfn.XLOOKUP($C17,'PP4 (2)'!$B$6:$B$100,'PP4 (2)'!$F$6:$F$100,"") -> 21 | AB17: =_xlfn.XLOOKUP($C17,'PP5 (1)'!$B$6:$B$100,'PP5 (1)'!$F$6:$F$100,"") -> 19 | AC17: =_xlfn.XLOOKUP($C17,'PP5(2)'!$B$6:$B$100,'PP5(2)'!$F$6:$F$100,"") -> 21 | AD17: =SUM(AE17:AP17) -> 25 | AE17: =_xlfn.XLOOKUP($C17,'MP (1)'!$B$6:$B$100,'MP (1)'!$H$6:$H$100,"") -> -3 | AF17: =_xlfn.XLOOKUP($C17,'MP (2)'!$B$6:$B$100,'MP (2)'!$H$6:$H$100,"") -> -4 | AG17: =_xlfn.XLOOKUP($C17,'PP1 (1)'!$B$6:$B$66,'PP1 (1)'!$H$6:$H$66,"") | AH17: =_xlfn.XLOOKUP($C17,'PP1 (2)'!$B$6:$B$100,'PP1 (2)'!$H$6:$H$100,"") | AI17: =_xlfn.XLOOKUP($C17,'PP2 (1)'!$B$6:$B$99,'PP2 (1)'!$H$6:$H$99,"") -> -3 | AJ17: =_xlfn.XLOOKUP($C17,'PP2 (2)'!$B$6:$B$100,'PP2 (2)'!$H$6:$H$100,"") -> -3 | AK17: =_xlfn.XLOOKUP($C17,'PP3 (1)'!$B$5:$B$113,'PP3 (1)'!$H$5:$H$113,"") -> -3 | AL17: =_xlfn.XLOOKUP($C17,'PP3 (2)'!$B$5:$B$112,'PP3 (2)'!$H$5:$H$112,"") -> 10 | AM17: =_xlfn.XLOOKUP($C17,'PP4 (1)'!$B$6:$B$100,'PP4 (1)'!$H$6:$H$100,"") -> 8 | AN17: =_xlfn.XLOOKUP($C17,'PP4 (2)'!$B$6:$B$100,'PP4 (2)'!$H$6:$H$100,"") -> 10 | AO17: =_xlfn.XLOOKUP($C17,'PP5 (1)'!$B$6:$B$100,'PP5 (1)'!$H$6:$H$100,"") -> 2 | AP17: =_xlfn.XLOOKUP($C17,'PP5(2)'!$B$6:$B$100,'PP5(2)'!$H$6:$H$100,"") -> 11
A18: =ROW()-4 -> 14 | B18: 0 | C18: REDZIŃSKI Michał | D18: =SUM(E18:P18) -> 5.57 | E18: =_xlfn.XLOOKUP($C18,'MP (1)'!$B$6:$B$100,'MP (1)'!$E$6:$E$100,"") -> 0.5 | F18: =_xlfn.XLOOKUP($C18,'MP (2)'!$B$6:$B$100,'MP (2)'!$E$6:$E$100,"") -> 0.6 | G18: =_xlfn.XLOOKUP($C18,'PP1 (1)'!$B$6:$B$66,'PP1 (1)'!$E$6:$E$66,"") -> 0.4 | H18: =_xlfn.XLOOKUP($C18,'PP1 (2)'!$B$6:$B$100,'PP1 (2)'!$E$6:$E$100,"") -> 0.8 | I18: =_xlfn.XLOOKUP($C18,'PP2 (1)'!$B$6:$B$99,'PP2 (1)'!$E$6:$E$99,"") -> 0.4 | J18: =_xlfn.XLOOKUP($C18,'PP2 (2)'!$B$6:$B$100,'PP2 (2)'!$E$6:$E$100,"") -> 0.6 | K18: =_xlfn.XLOOKUP($C18,'PP3 (1)'!$B$5:$B$113,'PP3 (1)'!$E$5:$E$113,"") -> 0.5 | L18: =_xlfn.XLOOKUP($C18,'PP3 (2)'!$B$5:$B$112,'PP3 (2)'!$E$5:$E$112,"") -> 0.67 | M18: =_xlfn.XLOOKUP($C18,'PP4 (1)'!$B$6:$B$100,'PP4 (1)'!$E$6:$E$100,"") -> 0.25 | N18: =_xlfn.XLOOKUP($C18,'PP4 (2)'!$B$6:$B$100,'PP4 (2)'!$E$6:$E$100,"") -> 0.4 | O18: =_xlfn.XLOOKUP($C18,'PP5 (1)'!$B$6:$B$100,'PP5 (1)'!$E$6:$E$100,"") -> 0.25 | P18: =_xlfn.XLOOKUP($C18,'PP5(2)'!$B$6:$B$100,'PP5(2)'!$E$6:$E$100,"") -> 0.2 | Q18: =SUM(R18:AC18) -> 228 | R18: =_xlfn.XLOOKUP($C18,'MP (1)'!$B$6:$B$100,'MP (1)'!$F$6:$F$100,"") -> 24 | S18: =_xlfn.XLOOKUP($C18,'MP (2)'!$B$6:$B$100,'MP (2)'!$F$6:$F$100,"") -> 21 | T18: =_xlfn.XLOOKUP($C18,'PP1 (1)'!$B$6:$B$66,'PP1 (1)'!$F$6:$F$66,"") -> 19 | U18: =_xlfn.XLOOKUP($C18,'PP1 (2)'!$B$6:$B$100,'PP1 (2)'!$F$6:$F$100,"") -> 22 | V18: =_xlfn.XLOOKUP($C18,'PP2 (1)'!$B$6:$B$99,'PP2 (1)'!$F$6:$F$99,"") -> 14 | W18: =_xlfn.XLOOKUP($C18,'PP2 (2)'!$B$6:$B$100,'PP2 (2)'!$F$6:$F$100,"") -> 22 | X18: =_xlfn.XLOOKUP($C18,'PP3 (1)'!$B$5:$B$113,'PP3 (1)'!$F$5:$F$113,"") -> 25 | Y18: =_xlfn.XLOOKUP($C18,'PP3 (2)'!$B$5:$B$112,'PP3 (2)'!$F$5:$F$112,"") -> 23 | Z18: =_xlfn.XLOOKUP($C18,'PP4 (1)'!$B$6:$B$100,'PP4 (1)'!$F$6:$F$100,"") -> 14 | AA18: =_xlfn.XLOOKUP($C18,'PP4 (2)'!$B$6:$B$100,'PP4 (2)'!$F$6:$F$100,"") -> 17 | AB18: =_xlfn.XLOOKUP($C18,'PP5 (1)'!$B$6:$B$100,'PP5 (1)'!$F$6:$F$100,"") -> 17 | AC18: =_xlfn.XLOOKUP($C18,'PP5(2)'!$B$6:$B$100,'PP5(2)'!$F$6:$F$100,"") -> 10 | AD18: =SUM(AE18:AP18) -> 7 | AE18: =_xlfn.XLOOKUP($C18,'MP (1)'!$B$6:$B$100,'MP (1)'!$H$6:$H$100,"") -> -1 | AF18: =_xlfn.XLOOKUP($C18,'MP (2)'!$B$6:$B$100,'MP (2)'!$H$6:$H$100,"") -> 7 | AG18: =_xlfn.XLOOKUP($C18,'PP1 (1)'!$B$6:$B$66,'PP1 (1)'!$H$6:$H$66,"") -> 1 | AH18: =_xlfn.XLOOKUP($C18,'PP1 (2)'!$B$6:$B$100,'PP1 (2)'!$H$6:$H$100,"") -> 8 | AI18: =_xlfn.XLOOKUP($C18,'PP2 (1)'!$B$6:$B$99,'PP2 (1)'!$H$6:$H$99,"") -> -4 | AJ18: =_xlfn.XLOOKUP($C18,'PP2 (2)'!$B$6:$B$100,'PP2 (2)'!$H$6:$H$100,"") -> 6 | AK18: =_xlfn.XLOOKUP($C18,'PP3 (1)'!$B$5:$B$113,'PP3 (1)'!$H$5:$H$113,"") -> 2 | AL18: =_xlfn.XLOOKUP($C18,'PP3 (2)'!$B$5:$B$112,'PP3 (2)'!$H$5:$H$112,"") -> 6 | AM18: =_xlfn.XLOOKUP($C18,'PP4 (1)'!$B$6:$B$100,'PP4 (1)'!$H$6:$H$100,"") -> -4 | AN18: =_xlfn.XLOOKUP($C18,'PP4 (2)'!$B$6:$B$100,'PP4 (2)'!$H$6:$H$100,"") -> -3 | AO18: =_xlfn.XLOOKUP($C18,'PP5 (1)'!$B$6:$B$100,'PP5 (1)'!$H$6:$H$100,"") -> 0 | AP18: =_xlfn.XLOOKUP($C18,'PP5(2)'!$B$6:$B$100,'PP5(2)'!$H$6:$H$100,"") -> -11
A19: =ROW()-4 -> 15 | B19: 1 | C19: TECŁAW Robert | D19: =SUM(E19:P19) -> 5.43 | E19: =_xlfn.XLOOKUP($C19,'MP (1)'!$B$6:$B$100,'MP (1)'!$E$6:$E$100,"") -> 1 | F19: =_xlfn.XLOOKUP($C19,'MP (2)'!$B$6:$B$100,'MP (2)'!$E$6:$E$100,"") -> 0.6 | G19: =_xlfn.XLOOKUP($C19,'PP1 (1)'!$B$6:$B$66,'PP1 (1)'!$E$6:$E$66,"") -> 0.33 | H19: =_xlfn.XLOOKUP($C19,'PP1 (2)'!$B$6:$B$100,'PP1 (2)'!$E$6:$E$100,"") -> 0.2 | I19: =_xlfn.XLOOKUP($C19,'PP2 (1)'!$B$6:$B$99,'PP2 (1)'!$E$6:$E$99,"") -> 0.17 | J19: =_xlfn.XLOOKUP($C19,'PP2 (2)'!$B$6:$B$100,'PP2 (2)'!$E$6:$E$100,"") -> 0 | K19: =_xlfn.XLOOKUP($C19,'PP3 (1)'!$B$5:$B$113,'PP3 (1)'!$E$5:$E$113,"") -> 0.33 | L19: =_xlfn.XLOOKUP($C19,'PP3 (2)'!$B$5:$B$112,'PP3 (2)'!$E$5:$E$112,"") -> 0.5 | M19: =_xlfn.XLOOKUP($C19,'PP4 (1)'!$B$6:$B$100,'PP4 (1)'!$E$6:$E$100,"") -> 0.5 | N19: =_xlfn.XLOOKUP($C19,'PP4 (2)'!$B$6:$B$100,'PP4 (2)'!$E$6:$E$100,"") -> 0.4 | O19: =_xlfn.XLOOKUP($C19,'PP5 (1)'!$B$6:$B$100,'PP5 (1)'!$E$6:$E$100,"") -> 0.8 | P19: =_xlfn.XLOOKUP($C19,'PP5(2)'!$B$6:$B$100,'PP5(2)'!$E$6:$E$100,"") -> 0.6 | Q19: =SUM(R19:AC19) -> 210 | R19: =_xlfn.XLOOKUP($C19,'MP (1)'!$B$6:$B$100,'MP (1)'!$F$6:$F$100,"") -> 25 | S19: =_xlfn.XLOOKUP($C19,'MP (2)'!$B$6:$B$100,'MP (2)'!$F$6:$F$100,"") -> 16 | T19: =_xlfn.XLOOKUP($C19,'PP1 (1)'!$B$6:$B$66,'PP1 (1)'!$F$6:$F$66,"") -> 21 | U19: =_xlfn.XLOOKUP($C19,'PP1 (2)'!$B$6:$B$100,'PP1 (2)'!$F$6:$F$100,"") -> 15 | V19: =_xlfn.XLOOKUP($C19,'PP2 (1)'!$B$6:$B$99,'PP2 (1)'!$F$6:$F$99,"") -> 10 | W19: =_xlfn.XLOOKUP($C19,'PP2 (2)'!$B$6:$B$100,'PP2 (2)'!$F$6:$F$100,"") -> 12 | X19: =_xlfn.XLOOKUP($C19,'PP3 (1)'!$B$5:$B$113,'PP3 (1)'!$F$5:$F$113,"") -> 18 | Y19: =_xlfn.XLOOKUP($C19,'PP3 (2)'!$B$5:$B$112,'PP3 (2)'!$F$5:$F$112,"") -> 21 | Z19: =_xlfn.XLOOKUP($C19,'PP4 (1)'!$B$6:$B$100,'PP4 (1)'!$F$6:$F$100,"") -> 16 | AA19: =_xlfn.XLOOKUP($C19,'PP4 (2)'!$B$6:$B$100,'PP4 (2)'!$F$6:$F$100,"") -> 14 | AB19: =_xlfn.XLOOKUP($C19,'PP5 (1)'!$B$6:$B$100,'PP5 (1)'!$F$6:$F$100,"") -> 23 | AC19: =_xlfn.XLOOKUP($C19,'PP5(2)'!$B$6:$B$100,'PP5(2)'!$F$6:$F$100,"") -> 19 | AD19: =SUM(AE19:AP19) -> -22 | AE19: =_xlfn.XLOOKUP($C19,'MP (1)'!$B$6:$B$100,'MP (1)'!$H$6:$H$100,"") -> 15 | AF19: =_xlfn.XLOOKUP($C19,'MP (2)'!$B$6:$B$100,'MP (2)'!$H$6:$H$100,"") -> 0 | AG19: =_xlfn.XLOOKUP($C19,'PP1 (1)'!$B$6:$B$66,'PP1 (1)'!$H$6:$H$66,"") -> -3 | AH19: =_xlfn.XLOOKUP($C19,'PP1 (2)'!$B$6:$B$100,'PP1 (2)'!$H$6:$H$100,"") -> -5 | AI19: =_xlfn.XLOOKUP($C19,'PP2 (1)'!$B$6:$B$99,'PP2 (1)'!$H$6:$H$99,"") -> -18 | AJ19: =_xlfn.XLOOKUP($C19,'PP2 (2)'!$B$6:$B$100,'PP2 (2)'!$H$6:$H$100,"") -> -13 | AK19: =_xlfn.XLOOKUP($C19,'PP3 (1)'!$B$5:$B$113,'PP3 (1)'!$H$5:$H$113,"") -> -6 | AL19: =_xlfn.XLOOKUP($C19,'PP3 (2)'!$B$5:$B$112,'PP3 (2)'!$H$5:$H$112,"") -> 0 | AM19: =_xlfn.XLOOKUP($C19,'PP4 (1)'!$B$6:$B$100,'PP4 (1)'!$H$6:$H$100,"") -> 1 | AN19: =_xlfn.XLOOKUP($C19,'PP4 (2)'!$B$6:$B$100,'PP4 (2)'!$H$6:$H$100,"") -> -3 | AO19: =_xlfn.XLOOKUP($C19,'PP5 (1)'!$B$6:$B$100,'PP5 (1)'!$H$6:$H$100,"") -> 7 | AP19: =_xlfn.XLOOKUP($C19,'PP5(2)'!$B$6:$B$100,'PP5(2)'!$H$6:$H$100,"") -> 3
A20: =ROW()-4 -> 16 | B20: 0 | C20: ROMANOWICZ Aleksiej | D20: =SUM(E20:P20) -> 5.3 | E20: =_xlfn.XLOOKUP($C20,'MP (1)'!$B$6:$B$100,'MP (1)'!$E$6:$E$100,"") | F20: =_xlfn.XLOOKUP($C20,'MP (2)'!$B$6:$B$100,'MP (2)'!$E$6:$E$100,"") | G20: =_xlfn.XLOOKUP($C20,'PP1 (1)'!$B$6:$B$66,'PP1 (1)'!$E$6:$E$66,"") | H20: =_xlfn.XLOOKUP($C20,'PP1 (2)'!$B$6:$B$100,'PP1 (2)'!$E$6:$E$100,"") | I20: =_xlfn.XLOOKUP($C20,'PP2 (1)'!$B$6:$B$99,'PP2 (1)'!$E$6:$E$99,"") -> 0.83 | J20: =_xlfn.XLOOKUP($C20,'PP2 (2)'!$B$6:$B$100,'PP2 (2)'!$E$6:$E$100,"") -> 1 | K20: =_xlfn.XLOOKUP($C20,'PP3 (1)'!$B$5:$B$113,'PP3 (1)'!$E$5:$E$113,"") -> 0.67 | L20: =_xlfn.XLOOKUP($C20,'PP3 (2)'!$B$5:$B$112,'PP3 (2)'!$E$5:$E$112,"") -> 0.5 | M20: =_xlfn.XLOOKUP($C20,'PP4 (1)'!$B$6:$B$100,'PP4 (1)'!$E$6:$E$100,"") -> 0.6 | N20: =_xlfn.XLOOKUP($C20,'PP4 (2)'!$B$6:$B$100,'PP4 (2)'!$E$6:$E$100,"") -> 0.8 | O20: =_xlfn.XLOOKUP($C20,'PP5 (1)'!$B$6:$B$100,'PP5 (1)'!$E$6:$E$100,"") -> 0.4 | P20: =_xlfn.XLOOKUP($C20,'PP5(2)'!$B$6:$B$100,'PP5(2)'!$E$6:$E$100,"") -> 0.5 | Q20: =SUM(R20:AC20) -> 178 | R20: =_xlfn.XLOOKUP($C20,'MP (1)'!$B$6:$B$100,'MP (1)'!$F$6:$F$100,"") | S20: =_xlfn.XLOOKUP($C20,'MP (2)'!$B$6:$B$100,'MP (2)'!$F$6:$F$100,"") | T20: =_xlfn.XLOOKUP($C20,'PP1 (1)'!$B$6:$B$66,'PP1 (1)'!$F$6:$F$66,"") | U20: =_xlfn.XLOOKUP($C20,'PP1 (2)'!$B$6:$B$100,'PP1 (2)'!$F$6:$F$100,"") | V20: =_xlfn.XLOOKUP($C20,'PP2 (1)'!$B$6:$B$99,'PP2 (1)'!$F$6:$F$99,"") -> 29 | W20: =_xlfn.XLOOKUP($C20,'PP2 (2)'!$B$6:$B$100,'PP2 (2)'!$F$6:$F$100,"") -> 25 | X20: =_xlfn.XLOOKUP($C20,'PP3 (1)'!$B$5:$B$113,'PP3 (1)'!$F$5:$F$113,"") -> 25 | Y20: =_xlfn.XLOOKUP($C20,'PP3 (2)'!$B$5:$B$112,'PP3 (2)'!$F$5:$F$112,"") -> 22 | Z20: =_xlfn.XLOOKUP($C20,'PP4 (1)'!$B$6:$B$100,'PP4 (1)'!$F$6:$F$100,"") -> 21 | AA20: =_xlfn.XLOOKUP($C20,'PP4 (2)'!$B$6:$B$100,'PP4 (2)'!$F$6:$F$100,"") -> 22 | AB20: =_xlfn.XLOOKUP($C20,'PP5 (1)'!$B$6:$B$100,'PP5 (1)'!$F$6:$F$100,"") -> 21 | AC20: =_xlfn.XLOOKUP($C20,'PP5(2)'!$B$6:$B$100,'PP5(2)'!$F$6:$F$100,"") -> 13 | AD20: =SUM(AE20:AP20) -> 57 | AE20: =_xlfn.XLOOKUP($C20,'MP (1)'!$B$6:$B$100,'MP (1)'!$H$6:$H$100,"") | AF20: =_xlfn.XLOOKUP($C20,'MP (2)'!$B$6:$B$100,'MP (2)'!$H$6:$H$100,"") | AG20: =_xlfn.XLOOKUP($C20,'PP1 (1)'!$B$6:$B$66,'PP1 (1)'!$H$6:$H$66,"") | AH20: =_xlfn.XLOOKUP($C20,'PP1 (2)'!$B$6:$B$100,'PP1 (2)'!$H$6:$H$100,"") | AI20: =_xlfn.XLOOKUP($C20,'PP2 (1)'!$B$6:$B$99,'PP2 (1)'!$H$6:$H$99,"") -> 15 | AJ20: =_xlfn.XLOOKUP($C20,'PP2 (2)'!$B$6:$B$100,'PP2 (2)'!$H$6:$H$100,"") -> 21 | AK20: =_xlfn.XLOOKUP($C20,'PP3 (1)'!$B$5:$B$113,'PP3 (1)'!$H$5:$H$113,"") -> 4 | AL20: =_xlfn.XLOOKUP($C20,'PP3 (2)'!$B$5:$B$112,'PP3 (2)'!$H$5:$H$112,"") -> 3 | AM20: =_xlfn.XLOOKUP($C20,'PP4 (1)'!$B$6:$B$100,'PP4 (1)'!$H$6:$H$100,"") -> 1 | AN20: =_xlfn.XLOOKUP($C20,'PP4 (2)'!$B$6:$B$100,'PP4 (2)'!$H$6:$H$100,"") -> 9 | AO20: =_xlfn.XLOOKUP($C20,'PP5 (1)'!$B$6:$B$100,'PP5 (1)'!$H$6:$H$100,"") -> 6 | AP20: =_xlfn.XLOOKUP($C20,'PP5(2)'!$B$6:$B$100,'PP5(2)'!$H$6:$H$100,"") -> -2
A21: =ROW()-4 -> 17 | B21: 3 | C21: ZABŁOCKI Michał | D21: =SUM(E21:P21) -> 5.18 | E21: =_xlfn.XLOOKUP($C21,'MP (1)'!$B$6:$B$100,'MP (1)'!$E$6:$E$100,"") | F21: =_xlfn.XLOOKUP($C21,'MP (2)'!$B$6:$B$100,'MP (2)'!$E$6:$E$100,"") | G21: =_xlfn.XLOOKUP($C21,'PP1 (1)'!$B$6:$B$66,'PP1 (1)'!$E$6:$E$66,"") -> 0.8 | H21: =_xlfn.XLOOKUP($C21,'PP1 (2)'!$B$6:$B$100,'PP1 (2)'!$E$6:$E$100,"") -> 1 | I21: =_xlfn.XLOOKUP($C21,'PP2 (1)'!$B$6:$B$99,'PP2 (1)'!$E$6:$E$99,"") | J21: =_xlfn.XLOOKUP($C21,'PP2 (2)'!$B$6:$B$100,'PP2 (2)'!$E$6:$E$100,"") | K21: =_xlfn.XLOOKUP($C21,'PP3 (1)'!$B$5:$B$113,'PP3 (1)'!$E$5:$E$113,"") -> 1 | L21: =_xlfn.XLOOKUP($C21,'PP3 (2)'!$B$5:$B$112,'PP3 (2)'!$E$5:$E$112,"") -> 0.83 | M21: =_xlfn.XLOOKUP($C21,'PP4 (1)'!$B$6:$B$100,'PP4 (1)'!$E$6:$E$100,"") -> 0.8 | N21: =_xlfn.XLOOKUP($C21,'PP4 (2)'!$B$6:$B$100,'PP4 (2)'!$E$6:$E$100,"") -> 0.75 | O21: =_xlfn.XLOOKUP($C21,'PP5 (1)'!$B$6:$B$100,'PP5 (1)'!$E$6:$E$100,"") | P21: =_xlfn.XLOOKUP($C21,'PP5(2)'!$B$6:$B$100,'PP5(2)'!$E$6:$E$100,"") | Q21: =SUM(R21:AC21) -> 151 | R21: =_xlfn.XLOOKUP($C21,'MP (1)'!$B$6:$B$100,'MP (1)'!$F$6:$F$100,"") | S21: =_xlfn.XLOOKUP($C21,'MP (2)'!$B$6:$B$100,'MP (2)'!$F$6:$F$100,"") | T21: =_xlfn.XLOOKUP($C21,'PP1 (1)'!$B$6:$B$66,'PP1 (1)'!$F$6:$F$66,"") -> 24 | U21: =_xlfn.XLOOKUP($C21,'PP1 (2)'!$B$6:$B$100,'PP1 (2)'!$F$6:$F$100,"") -> 25 | V21: =_xlfn.XLOOKUP($C21,'PP2 (1)'!$B$6:$B$99,'PP2 (1)'!$F$6:$F$99,"") | W21: =_xlfn.XLOOKUP($C21,'PP2 (2)'!$B$6:$B$100,'PP2 (2)'!$F$6:$F$100,"") | X21: =_xlfn.XLOOKUP($C21,'PP3 (1)'!$B$5:$B$113,'PP3 (1)'!$F$5:$F$113,"") -> 30 | Y21: =_xlfn.XLOOKUP($C21,'PP3 (2)'!$B$5:$B$112,'PP3 (2)'!$F$5:$F$112,"") -> 29 | Z21: =_xlfn.XLOOKUP($C21,'PP4 (1)'!$B$6:$B$100,'PP4 (1)'!$F$6:$F$100,"") -> 24 | AA21: =_xlfn.XLOOKUP($C21,'PP4 (2)'!$B$6:$B$100,'PP4 (2)'!$F$6:$F$100,"") -> 19 | AB21: =_xlfn.XLOOKUP($C21,'PP5 (1)'!$B$6:$B$100,'PP5 (1)'!$F$6:$F$100,"") | AC21: =_xlfn.XLOOKUP($C21,'PP5(2)'!$B$6:$B$100,'PP5(2)'!$F$6:$F$100,"") | AD21: =SUM(AE21:AP21) -> 83 | AE21: =_xlfn.XLOOKUP($C21,'MP (1)'!$B$6:$B$100,'MP (1)'!$H$6:$H$100,"") | AF21: =_xlfn.XLOOKUP($C21,'MP (2)'!$B$6:$B$100,'MP (2)'!$H$6:$H$100,"") | AG21: =_xlfn.XLOOKUP($C21,'PP1 (1)'!$B$6:$B$66,'PP1 (1)'!$H$6:$H$66,"") -> 14 | AH21: =_xlfn.XLOOKUP($C21,'PP1 (2)'!$B$6:$B$100,'PP1 (2)'!$H$6:$H$100,"") -> 17 | AI21: =_xlfn.XLOOKUP($C21,'PP2 (1)'!$B$6:$B$99,'PP2 (1)'!$H$6:$H$99,"") | AJ21: =_xlfn.XLOOKUP($C21,'PP2 (2)'!$B$6:$B$100,'PP2 (2)'!$H$6:$H$100,"") | AK21: =_xlfn.XLOOKUP($C21,'PP3 (1)'!$B$5:$B$113,'PP3 (1)'!$H$5:$H$113,"") -> 15 | AL21: =_xlfn.XLOOKUP($C21,'PP3 (2)'!$B$5:$B$112,'PP3 (2)'!$H$5:$H$112,"") -> 16 | AM21: =_xlfn.XLOOKUP($C21,'PP4 (1)'!$B$6:$B$100,'PP4 (1)'!$H$6:$H$100,"") -> 13 | AN21: =_xlfn.XLOOKUP($C21,'PP4 (2)'!$B$6:$B$100,'PP4 (2)'!$H$6:$H$100,"") -> 8 | AO21: =_xlfn.XLOOKUP($C21,'PP5 (1)'!$B$6:$B$100,'PP5 (1)'!$H$6:$H$100,"") | AP21: =_xlfn.XLOOKUP($C21,'PP5(2)'!$B$6:$B$100,'PP5(2)'!$H$6:$H$100,"")
A22: =ROW()-4 -> 18 | B22: 2 | C22: WINGROWICZ Mariusz | D22: =SUM(E22:P22) -> 5 | E22: =_xlfn.XLOOKUP($C22,'MP (1)'!$B$6:$B$100,'MP (1)'!$E$6:$E$100,"") -> 0.67 | F22: =_xlfn.XLOOKUP($C22,'MP (2)'!$B$6:$B$100,'MP (2)'!$E$6:$E$100,"") -> 0.6 | G22: =_xlfn.XLOOKUP($C22,'PP1 (1)'!$B$6:$B$66,'PP1 (1)'!$E$6:$E$66,"") | H22: =_xlfn.XLOOKUP($C22,'PP1 (2)'!$B$6:$B$100,'PP1 (2)'!$E$6:$E$100,"") | I22: =_xlfn.XLOOKUP($C22,'PP2 (1)'!$B$6:$B$99,'PP2 (1)'!$E$6:$E$99,"") -> 1 | J22: =_xlfn.XLOOKUP($C22,'PP2 (2)'!$B$6:$B$100,'PP2 (2)'!$E$6:$E$100,"") -> 0.4 | K22: =_xlfn.XLOOKUP($C22,'PP3 (1)'!$B$5:$B$113,'PP3 (1)'!$E$5:$E$113,"") -> 0.33 | L22: =_xlfn.XLOOKUP($C22,'PP3 (2)'!$B$5:$B$112,'PP3 (2)'!$E$5:$E$112,"") -> 0.8 | M22: =_xlfn.XLOOKUP($C22,'PP4 (1)'!$B$6:$B$100,'PP4 (1)'!$E$6:$E$100,"") -> 0.6 | N22: =_xlfn.XLOOKUP($C22,'PP4 (2)'!$B$6:$B$100,'PP4 (2)'!$E$6:$E$100,"") -> 0.6 | O22: =_xlfn.XLOOKUP($C22,'PP5 (1)'!$B$6:$B$100,'PP5 (1)'!$E$6:$E$100,"") | P22: =_xlfn.XLOOKUP($C22,'PP5(2)'!$B$6:$B$100,'PP5(2)'!$E$6:$E$100,"") | Q22: =SUM(R22:AC22) -> 182 | R22: =_xlfn.XLOOKUP($C22,'MP (1)'!$B$6:$B$100,'MP (1)'!$F$6:$F$100,"") -> 27 | S22: =_xlfn.XLOOKUP($C22,'MP (2)'!$B$6:$B$100,'MP (2)'!$F$6:$F$100,"") -> 22 | T22: =_xlfn.XLOOKUP($C22,'PP1 (1)'!$B$6:$B$66,'PP1 (1)'!$F$6:$F$66,"") | U22: =_xlfn.XLOOKUP($C22,'PP1 (2)'!$B$6:$B$100,'PP1 (2)'!$F$6:$F$100,"") | V22: =_xlfn.XLOOKUP($C22,'PP2 (1)'!$B$6:$B$99,'PP2 (1)'!$F$6:$F$99,"") -> 25 | W22: =_xlfn.XLOOKUP($C22,'PP2 (2)'!$B$6:$B$100,'PP2 (2)'!$F$6:$F$100,"") -> 21 | X22: =_xlfn.XLOOKUP($C22,'PP3 (1)'!$B$5:$B$113,'PP3 (1)'!$F$5:$F$113,"") -> 25 | Y22: =_xlfn.XLOOKUP($C22,'PP3 (2)'!$B$5:$B$112,'PP3 (2)'!$F$5:$F$112,"") -> 22 | Z22: =_xlfn.XLOOKUP($C22,'PP4 (1)'!$B$6:$B$100,'PP4 (1)'!$F$6:$F$100,"") -> 20 | AA22: =_xlfn.XLOOKUP($C22,'PP4 (2)'!$B$6:$B$100,'PP4 (2)'!$F$6:$F$100,"") -> 20 | AB22: =_xlfn.XLOOKUP($C22,'PP5 (1)'!$B$6:$B$100,'PP5 (1)'!$F$6:$F$100,"") | AC22: =_xlfn.XLOOKUP($C22,'PP5(2)'!$B$6:$B$100,'PP5(2)'!$F$6:$F$100,"") | AD22: =SUM(AE22:AP22) -> 52 | AE22: =_xlfn.XLOOKUP($C22,'MP (1)'!$B$6:$B$100,'MP (1)'!$H$6:$H$100,"") -> 7 | AF22: =_xlfn.XLOOKUP($C22,'MP (2)'!$B$6:$B$100,'MP (2)'!$H$6:$H$100,"") -> 5 | AG22: =_xlfn.XLOOKUP($C22,'PP1 (1)'!$B$6:$B$66,'PP1 (1)'!$H$6:$H$66,"") | AH22: =_xlfn.XLOOKUP($C22,'PP1 (2)'!$B$6:$B$100,'PP1 (2)'!$H$6:$H$100,"") | AI22: =_xlfn.XLOOKUP($C22,'PP2 (1)'!$B$6:$B$99,'PP2 (1)'!$H$6:$H$99,"") -> 14 | AJ22: =_xlfn.XLOOKUP($C22,'PP2 (2)'!$B$6:$B$100,'PP2 (2)'!$H$6:$H$100,"") -> 2 | AK22: =_xlfn.XLOOKUP($C22,'PP3 (1)'!$B$5:$B$113,'PP3 (1)'!$H$5:$H$113,"") -> 1 | AL22: =_xlfn.XLOOKUP($C22,'PP3 (2)'!$B$5:$B$112,'PP3 (2)'!$H$5:$H$112,"") -> 12 | AM22: =_xlfn.XLOOKUP($C22,'PP4 (1)'!$B$6:$B$100,'PP4 (1)'!$H$6:$H$100,"") -> 4 | AN22: =_xlfn.XLOOKUP($C22,'PP4 (2)'!$B$6:$B$100,'PP4 (2)'!$H$6:$H$100,"") -> 7 | AO22: =_xlfn.XLOOKUP($C22,'PP5 (1)'!$B$6:$B$100,'PP5 (1)'!$H$6:$H$100,"") | AP22: =_xlfn.XLOOKUP($C22,'PP5(2)'!$B$6:$B$100,'PP5(2)'!$H$6:$H$100,"")
A23: =ROW()-4 -> 19 | B23: 1 | C23: GRACZYK Bogdan | D23: =SUM(E23:P23) -> 4.94 | E23: =_xlfn.XLOOKUP($C23,'MP (1)'!$B$6:$B$100,'MP (1)'!$E$6:$E$100,"") -> 1 | F23: =_xlfn.XLOOKUP($C23,'MP (2)'!$B$6:$B$100,'MP (2)'!$E$6:$E$100,"") -> 1 | G23: =_xlfn.XLOOKUP($C23,'PP1 (1)'!$B$6:$B$66,'PP1 (1)'!$E$6:$E$66,"") | H23: =_xlfn.XLOOKUP($C23,'PP1 (2)'!$B$6:$B$100,'PP1 (2)'!$E$6:$E$100,"") | I23: =_xlfn.XLOOKUP($C23,'PP2 (1)'!$B$6:$B$99,'PP2 (1)'!$E$6:$E$99,"") -> 0.8 | J23: =_xlfn.XLOOKUP($C23,'PP2 (2)'!$B$6:$B$100,'PP2 (2)'!$E$6:$E$100,"") -> 0.8 | K23: =_xlfn.XLOOKUP($C23,'PP3 (1)'!$B$5:$B$113,'PP3 (1)'!$E$5:$E$113,"") -> 0.67 | L23: =_xlfn.XLOOKUP($C23,'PP3 (2)'!$B$5:$B$112,'PP3 (2)'!$E$5:$E$112,"") -> 0.67 | M23: =_xlfn.XLOOKUP($C23,'PP4 (1)'!$B$6:$B$100,'PP4 (1)'!$E$6:$E$100,"") | N23: =_xlfn.XLOOKUP($C23,'PP4 (2)'!$B$6:$B$100,'PP4 (2)'!$E$6:$E$100,"") | O23: =_xlfn.XLOOKUP($C23,'PP5 (1)'!$B$6:$B$100,'PP5 (1)'!$E$6:$E$100,"") | P23: =_xlfn.XLOOKUP($C23,'PP5(2)'!$B$6:$B$100,'PP5(2)'!$E$6:$E$100,"") | Q23: =SUM(R23:AC23) -> 147 | R23: =_xlfn.XLOOKUP($C23,'MP (1)'!$B$6:$B$100,'MP (1)'!$F$6:$F$100,"") -> 25 | S23: =_xlfn.XLOOKUP($C23,'MP (2)'!$B$6:$B$100,'MP (2)'!$F$6:$F$100,"") -> 25 | T23: =_xlfn.XLOOKUP($C23,'PP1 (1)'!$B$6:$B$66,'PP1 (1)'!$F$6:$F$66,"") | U23: =_xlfn.XLOOKUP($C23,'PP1 (2)'!$B$6:$B$100,'PP1 (2)'!$F$6:$F$100,"") | V23: =_xlfn.XLOOKUP($C23,'PP2 (1)'!$B$6:$B$99,'PP2 (1)'!$F$6:$F$99,"") -> 21 | W23: =_xlfn.XLOOKUP($C23,'PP2 (2)'!$B$6:$B$100,'PP2 (2)'!$F$6:$F$100,"") -> 24 | X23: =_xlfn.XLOOKUP($C23,'PP3 (1)'!$B$5:$B$113,'PP3 (1)'!$F$5:$F$113,"") -> 27 | Y23: =_xlfn.XLOOKUP($C23,'PP3 (2)'!$B$5:$B$112,'PP3 (2)'!$F$5:$F$112,"") -> 25 | Z23: =_xlfn.XLOOKUP($C23,'PP4 (1)'!$B$6:$B$100,'PP4 (1)'!$F$6:$F$100,"") | AA23: =_xlfn.XLOOKUP($C23,'PP4 (2)'!$B$6:$B$100,'PP4 (2)'!$F$6:$F$100,"") | AB23: =_xlfn.XLOOKUP($C23,'PP5 (1)'!$B$6:$B$100,'PP5 (1)'!$F$6:$F$100,"") | AC23: =_xlfn.XLOOKUP($C23,'PP5(2)'!$B$6:$B$100,'PP5(2)'!$F$6:$F$100,"") | AD23: =SUM(AE23:AP23) -> 73 | AE23: =_xlfn.XLOOKUP($C23,'MP (1)'!$B$6:$B$100,'MP (1)'!$H$6:$H$100,"") -> 16 | AF23: =_xlfn.XLOOKUP($C23,'MP (2)'!$B$6:$B$100,'MP (2)'!$H$6:$H$100,"") -> 21 | AG23: =_xlfn.XLOOKUP($C23,'PP1 (1)'!$B$6:$B$66,'PP1 (1)'!$H$6:$H$66,"") | AH23: =_xlfn.XLOOKUP($C23,'PP1 (2)'!$B$6:$B$100,'PP1 (2)'!$H$6:$H$100,"") | AI23: =_xlfn.XLOOKUP($C23,'PP2 (1)'!$B$6:$B$99,'PP2 (1)'!$H$6:$H$99,"") -> 11 | AJ23: =_xlfn.XLOOKUP($C23,'PP2 (2)'!$B$6:$B$100,'PP2 (2)'!$H$6:$H$100,"") -> 14 | AK23: =_xlfn.XLOOKUP($C23,'PP3 (1)'!$B$5:$B$113,'PP3 (1)'!$H$5:$H$113,"") -> 4 | AL23: =_xlfn.XLOOKUP($C23,'PP3 (2)'!$B$5:$B$112,'PP3 (2)'!$H$5:$H$112,"") -> 7 | AM23: =_xlfn.XLOOKUP($C23,'PP4 (1)'!$B$6:$B$100,'PP4 (1)'!$H$6:$H$100,"") | AN23: =_xlfn.XLOOKUP($C23,'PP4 (2)'!$B$6:$B$100,'PP4 (2)'!$H$6:$H$100,"") | AO23: =_xlfn.XLOOKUP($C23,'PP5 (1)'!$B$6:$B$100,'PP5 (1)'!$H$6:$H$100,"") | AP23: =_xlfn.XLOOKUP($C23,'PP5(2)'!$B$6:$B$100,'PP5(2)'!$H$6:$H$100,"")
