Workbook

Sheet Ranking
B2: Dołączył/a do kategorii w tym roku | D2: Ranking Pucharu Polski Weteranów (PP) sezon 2024-2025 | R2: Na sumę punktów w rankingu skłąda się 4 najlepszych wyników (z 5 możliwych) w turniejach PP Weteranów oraz wynik z Mistrzostw Polski Weteranów.
D3: Kat. 3
A4: L.P. | B4: NAZWISKO Imię | C4: KLUB | D4: PUNKTY | E4: I PP | G4: II PP | I4: III PP | K4: IV PP | M4: V PP | O4: MPW
E5: M | F5: P | G5: M | H5: P | I5: M | J5: P | K5: M | L5: P | M5: M | N5: P | O5: M | P5: P
A6: =ROW()-5 -> 1 | B6: KRZEMIŃSKI Mariusz | D6: =SUM(F6,H6,J6,L6,N6,P6)-MIN(F6,H6,J6,L6,N6) -> 512.59257 | E6: =_xlfn.XLOOKUP($B6,'PP1'!$C$6:$C$101,'PP1'!$B$6:$B$101,"") -> 1 | F6: =_xlfn.XLOOKUP(E6,'PP1'!$B$6:$B$55,'PP1'!$A$6:$A$55,0) -> 109.38991 | G6: =_xlfn.XLOOKUP($B6,'PP2'!$C$6:$C$101,'PP2'!$B$6:$B$101,"") -> 3 | H6: =_xlfn.XLOOKUP(G6,'PP2'!$B$6:$B$55,'PP2'!$A$6:$A$55,0) -> 51.740251 | I6: =_xlfn.XLOOKUP($B6,'PP3'!$C$6:$C$101,'PP3'!$B$6:$B$101,"") -> 1 | J6: =_xlfn.XLOOKUP(I6,'PP3'!$B$6:$B$55,'PP3'!$A$6:$A$55,0) -> 110.01582 | K6: =_xlfn.XLOOKUP($B6,'PP4'!$C$6:$C$101,'PP4'!$B$6:$B$101,"") -> 1 | L6: =_xlfn.XLOOKUP(K6,'PP4'!$B$6:$B$55,'PP4'!$A$6:$A$55,0) -> 108.72075 | M6: =_xlfn.XLOOKUP($B6,'PP5'!$C$6:$C$101,'PP5'!$B$6:$B$101,"") | N6: =_xlfn.XLOOKUP(M6,'PP5'!$B$6:$B$55,'PP5'!$A$6:$A$55,0) -> 0 | O6: =_xlfn.XLOOKUP(B6,MPW!C$6:C$101,MPW!B$6:B$101,"") -> 1 | P6: =_xlfn.XLOOKUP(O6,MPW!B$6:B$55,MPW!A$6:A$55,0) -> 132.72583
A7: =ROW()-5 -> 2 | B7: KOSTRZEWA Ireneusz | D7: =SUM(F7,H7,J7,L7,N7,P7)-MIN(F7,H7,J7,L7,N7) -> 379.21984 | E7: =_xlfn.XLOOKUP($B7,'PP1'!$C$6:$C$101,'PP1'!$B$6:$B$101,"") -> 2 | F7: =_xlfn.XLOOKUP(E7,'PP1'!$B$6:$B$55,'PP1'!$A$6:$A$55,0) -> 78.176138 | G7: =_xlfn.XLOOKUP($B7,'PP2'!$C$6:$C$101,'PP2'!$B$6:$B$101,"") -> 1 | H7: =_xlfn.XLOOKUP(G7,'PP2'!$B$6:$B$55,'PP2'!$A$6:$A$55,0) -> 108.72075 | I7: =_xlfn.XLOOKUP($B7,'PP3'!$C$6:$C$101,'PP3'!$B$6:$B$101,"") -> 2 | J7: =_xlfn.XLOOKUP(I7,'PP3'!$B$6:$B$55,'PP3'!$A$6:$A$55,0) -> 79.179704 | K7: =_xlfn.XLOOKUP($B7,'PP4'!$C$6:$C$101,'PP4'!$B$6:$B$101,"") | L7: =_xlfn.XLOOKUP(K7,'PP4'!$B$6:$B$55,'PP4'!$A$6:$A$55,0) -> 0 | M7: =_xlfn.XLOOKUP($B7,'PP5'!$C$6:$C$101,'PP5'!$B$6:$B$101,"") -> 2 | N7: =_xlfn.XLOOKUP(M7,'PP5'!$B$6:$B$55,'PP5'!$A$6:$A$55,0) -> 61.946936 | O7: =_xlfn.XLOOKUP(B7,MPW!C$6:C$101,MPW!B$6:B$101,"") -> 4 | P7: =_xlfn.XLOOKUP(O7,MPW!B$6:B$55,MPW!A$6:A$55,0) -> 51.19631
A8: =ROW()-5 -> 3 | B8: AUGUSTOWSKI Waldemar | D8: =SUM(F8,H8,J8,L8,N8,P8)-MIN(F8,H8,J8,L8,N8) -> 312.43489 | E8: =_xlfn.XLOOKUP($B8,'PP1'!$C$6:$C$101,'PP1'!$B$6:$B$101,"") -> 7 | F8: =_xlfn.XLOOKUP(E8,'PP1'!$B$6:$B$55,'PP1'!$A$6:$A$55,0) -> 18.590196 | G8: =_xlfn.XLOOKUP($B8,'PP2'!$C$6:$C$101,'PP2'!$B$6:$B$101,"") -> 7 | H8: =_xlfn.XLOOKUP(G8,'PP2'!$B$6:$B$55,'PP2'!$A$6:$A$55,0) -> 16.604528 | I8: =_xlfn.XLOOKUP($B8,'PP3'!$C$6:$C$101,'PP3'!$B$6:$B$101,"") -> 3 | J8: =_xlfn.XLOOKUP(I8,'PP3'!$B$6:$B$55,'PP3'!$A$6:$A$55,0) -> 54.222252 | K8: =_xlfn.XLOOKUP($B8,'PP4'!$C$6:$C$101,'PP4'!$B$6:$B$101,"") -> 2 | L8: =_xlfn.XLOOKUP(K8,'PP4'!$B$6:$B$55,'PP4'!$A$6:$A$55,0) -> 77.022724 | M8: =_xlfn.XLOOKUP($B8,'PP5'!$C$6:$C$101,'PP5'!$B$6:$B$101,"") -> 1 | N8: =_xlfn.XLOOKUP(M8,'PP5'!$B$6:$B$55,'PP5'!$A$6:$A$55,0) -> 96.354085 | O8: =_xlfn.XLOOKUP(B8,MPW!C$6:C$101,MPW!B$6:B$101,"") -> 3 | P8: =_xlfn.XLOOKUP(O8,MPW!B$6:B$55,MPW!A$6:A$55,0) -> 66.245633
A9: =ROW()-5 -> 4 | B9: DRAPELLA Maciej | D9: =SUM(F9,H9,J9,L9,N9,P9)-MIN(F9,H9,J9,L9,N9) -> 242.87523 | E9: =_xlfn.XLOOKUP($B9,'PP1'!$C$6:$C$101,'PP1'!$B$6:$B$101,"") -> 3 | F9: =_xlfn.XLOOKUP(E9,'PP1'!$B$6:$B$55,'PP1'!$A$6:$A$55,0) -> 53.084363 | G9: =_xlfn.XLOOKUP($B9,'PP2'!$C$6:$C$101,'PP2'!$B$6:$B$101,"") -> 2 | H9: =_xlfn.XLOOKUP(G9,'PP2'!$B$6:$B$55,'PP2'!$A$6:$A$55,0) -> 77.022724 | I9: =_xlfn.XLOOKUP($B9,'PP3'!$C$6:$C$101,'PP3'!$B$6:$B$101,"") -> 5 | J9: =_xlfn.XLOOKUP(I9,'PP3'!$B$6:$B$55,'PP3'!$A$6:$A$55,0) -> 27.111801 | K9: =_xlfn.XLOOKUP($B9,'PP4'!$C$6:$C$101,'PP4'!$B$6:$B$101,"") -> 3 | L9: =_xlfn.XLOOKUP(K9,'PP4'!$B$6:$B$55,'PP4'!$A$6:$A$55,0) -> 51.740251 | M9: =_xlfn.XLOOKUP($B9,'PP5'!$C$6:$C$101,'PP5'!$B$6:$B$101,"") | N9: =_xlfn.XLOOKUP(M9,'PP5'!$B$6:$B$55,'PP5'!$A$6:$A$55,0) -> 0 | O9: =_xlfn.XLOOKUP(B9,MPW!C$6:C$101,MPW!B$6:B$101,"") -> 5 | P9: =_xlfn.XLOOKUP(O9,MPW!B$6:B$55,MPW!A$6:A$55,0) -> 33.916095
A10: =ROW()-5 -> 5 | B10: HERONIMEK Leszek | D10: =SUM(F10,H10,J10,L10,N10,P10)-MIN(F10,H10,J10,L10,N10) -> 170.01414 | E10: =_xlfn.XLOOKUP($B10,'PP1'!$C$6:$C$101,'PP1'!$B$6:$B$101,"") -> 4 | F10: =_xlfn.XLOOKUP(E10,'PP1'!$B$6:$B$55,'PP1'!$A$6:$A$55,0) -> 46.962364 | G10: =_xlfn.XLOOKUP($B10,'PP2'!$C$6:$C$101,'PP2'!$B$6:$B$101,"") -> 4 | H10: =_xlfn.XLOOKUP(G10,'PP2'!$B$6:$B$55,'PP2'!$A$6:$A$55,0) -> 39.084442 | I10: =_xlfn.XLOOKUP($B10,'PP3'!$C$6:$C$101,'PP3'!$B$6:$B$101,"") | J10: =_xlfn.XLOOKUP(I10,'PP3'!$B$6:$B$55,'PP3'!$A$6:$A$55,0) -> 0 | K10: =_xlfn.XLOOKUP($B10,'PP4'!$C$6:$C$101,'PP4'!$B$6:$B$101,"") -> 4 | L10: =_xlfn.XLOOKUP(K10,'PP4'!$B$6:$B$55,'PP4'!$A$6:$A$55,0) -> 39.084442 | M10: =_xlfn.XLOOKUP($B10,'PP5'!$C$6:$C$101,'PP5'!$B$6:$B$101,"") -> 4 | N10: =_xlfn.XLOOKUP(M10,'PP5'!$B$6:$B$55,'PP5'!$A$6:$A$55,0) -> 22.088425 | O10: =_xlfn.XLOOKUP(B10,MPW!C$6:C$101,MPW!B$6:B$101,"") -> 8 | P10: =_xlfn.XLOOKUP(O10,MPW!B$6:B$55,MPW!A$6:A$55,0) -> 22.794464
A11: =ROW()-5 -> 6 | B11: SZYMKOWIAK Krzysztof | D11: =SUM(F11,H11,J11,L11,N11,P11)-MIN(F11,H11,J11,L11,N11) -> 131.48919 | E11: =_xlfn.XLOOKUP($B11,'PP1'!$C$6:$C$101,'PP1'!$B$6:$B$101,"") | F11: =_xlfn.XLOOKUP(E11,'PP1'!$B$6:$B$55,'PP1'!$A$6:$A$55,0) -> 0 | G11: =_xlfn.XLOOKUP($B11,'PP2'!$C$6:$C$101,'PP2'!$B$6:$B$101,"") | H11: =_xlfn.XLOOKUP(G11,'PP2'!$B$6:$B$55,'PP2'!$A$6:$A$55,0) -> 0 | I11: =_xlfn.XLOOKUP($B11,'PP3'!$C$6:$C$101,'PP3'!$B$6:$B$101,"") | J11: =_xlfn.XLOOKUP(I11,'PP3'!$B$6:$B$55,'PP3'!$A$6:$A$55,0) -> 0 | K11: =_xlfn.XLOOKUP($B11,'PP4'!$C$6:$C$101,'PP4'!$B$6:$B$101,"") | L11: =_xlfn.XLOOKUP(K11,'PP4'!$B$6:$B$55,'PP4'!$A$6:$A$55,0) -> 0 | M11: =_xlfn.XLOOKUP($B11,'PP5'!$C$6:$C$101,'PP5'!$B$6:$B$101,"") -> 3 | N11: =_xlfn.XLOOKUP(M11,'PP5'!$B$6:$B$55,'PP5'!$A$6:$A$55,0) -> 35.407149 | O11: =_xlfn.XLOOKUP(B11,MPW!C$6:C$101,MPW!B$6:B$101,"") -> 2 | P11: =_xlfn.XLOOKUP(O11,MPW!B$6:B$55,MPW!A$6:A$55,0) -> 96.08204
A12: =ROW()-5 -> 7 | B12: POKRZYWA Mariusz | D12: =SUM(F12,H12,J12,L12,N12,P12)-MIN(F12,H12,J12,L12,N12) -> 82.683148 | E12: =_xlfn.XLOOKUP($B12,'PP1'!$C$6:$C$101,'PP1'!$B$6:$B$101,"") -> 6 | F12: =_xlfn.XLOOKUP(E12,'PP1'!$B$6:$B$55,'PP1'!$A$6:$A$55,0) -> 21.870589 | G12: =_xlfn.XLOOKUP($B12,'PP2'!$C$6:$C$101,'PP2'!$B$6:$B$101,"") -> 8 | H12: =_xlfn.XLOOKUP(G12,'PP2'!$B$6:$B$55,'PP2'!$A$6:$A$55,0) -> 13.626663 | I12: =_xlfn.XLOOKUP($B12,'PP3'!$C$6:$C$101,'PP3'!$B$6:$B$101,"") -> 4 | J12: =_xlfn.XLOOKUP(I12,'PP3'!$B$6:$B$55,'PP3'!$A$6:$A$55,0) -> 41.671647 | K12: =_xlfn.XLOOKUP($B12,'PP4'!$C$6:$C$101,'PP4'!$B$6:$B$101,"") | L12: =_xlfn.XLOOKUP(K12,'PP4'!$B$6:$B$55,'PP4'!$A$6:$A$55,0) -> 0 | M12: =_xlfn.XLOOKUP($B12,'PP5'!$C$6:$C$101,'PP5'!$B$6:$B$101,"") | N12: =_xlfn.XLOOKUP(M12,'PP5'!$B$6:$B$55,'PP5'!$A$6:$A$55,0) -> 0 | O12: =_xlfn.XLOOKUP(B12,MPW!C$6:C$101,MPW!B$6:B$101,"") -> 10 | P12: =_xlfn.XLOOKUP(O12,MPW!B$6:B$55,MPW!A$6:A$55,0) -> 5.5142496
A13: =ROW()-5 -> 8 | B13: POPRAWA Mariusz | D13: =SUM(F13,H13,J13,L13,N13,P13)-MIN(F13,H13,J13,L13,N13) -> 68.040265 | E13: =_xlfn.XLOOKUP($B13,'PP1'!$C$6:$C$101,'PP1'!$B$6:$B$101,"") | F13: =_xlfn.XLOOKUP(E13,'PP1'!$B$6:$B$55,'PP1'!$A$6:$A$55,0) -> 0 | G13: =_xlfn.XLOOKUP($B13,'PP2'!$C$6:$C$101,'PP2'!$B$6:$B$101,"") -> 6 | H13: =_xlfn.XLOOKUP(G13,'PP2'!$B$6:$B$55,'PP2'!$A$6:$A$55,0) -> 20.042221 | I13: =_xlfn.XLOOKUP($B13,'PP3'!$C$6:$C$101,'PP3'!$B$6:$B$101,"") -> 6 | J13: =_xlfn.XLOOKUP(I13,'PP3'!$B$6:$B$55,'PP3'!$A$6:$A$55,0) -> 23.386135 | K13: =_xlfn.XLOOKUP($B13,'PP4'!$C$6:$C$101,'PP4'!$B$6:$B$101,"") -> 7 | L13: =_xlfn.XLOOKUP(K13,'PP4'!$B$6:$B$55,'PP4'!$A$6:$A$55,0) -> 16.604528 | M13: =_xlfn.XLOOKUP($B13,'PP5'!$C$6:$C$101,'PP5'!$B$6:$B$101,"") | N13: =_xlfn.XLOOKUP(M13,'PP5'!$B$6:$B$55,'PP5'!$A$6:$A$55,0) -> 0 | O13: =_xlfn.XLOOKUP(B13,MPW!C$6:C$101,MPW!B$6:B$101,"") -> 9 | P13: =_xlfn.XLOOKUP(O13,MPW!B$6:B$55,MPW!A$6:A$55,0) -> 8.0073808
A14: =ROW()-5 -> 9 | B14: MAŁASIŃSKI Adam | D14: =SUM(F14,H14,J14,L14,N14,P14)-MIN(F14,H14,J14,L14,N14) -> 63.503891 | E14: =_xlfn.XLOOKUP($B14,'PP1'!$C$6:$C$101,'PP1'!$B$6:$B$101,"") | F14: =_xlfn.XLOOKUP(E14,'PP1'!$B$6:$B$55,'PP1'!$A$6:$A$55,0) -> 0 | G14: =_xlfn.XLOOKUP($B14,'PP2'!$C$6:$C$101,'PP2'!$B$6:$B$101,"") | H14: =_xlfn.XLOOKUP(G14,'PP2'!$B$6:$B$55,'PP2'!$A$6:$A$55,0) -> 0 | I14: =_xlfn.XLOOKUP($B14,'PP3'!$C$6:$C$101,'PP3'!$B$6:$B$101,"") -> 8 | J14: =_xlfn.XLOOKUP(I14,'PP3'!$B$6:$B$55,'PP3'!$A$6:$A$55,0) -> 17.507471 | K14: =_xlfn.XLOOKUP($B14,'PP4'!$C$6:$C$101,'PP4'!$B$6:$B$101,"") -> 6 | L14: =_xlfn.XLOOKUP(K14,'PP4'!$B$6:$B$55,'PP4'!$A$6:$A$55,0) -> 20.042221 | M14: =_xlfn.XLOOKUP($B14,'PP5'!$C$6:$C$101,'PP5'!$B$6:$B$101,"") | N14: =_xlfn.XLOOKUP(M14,'PP5'!$B$6:$B$55,'PP5'!$A$6:$A$55,0) -> 0 | O14: =_xlfn.XLOOKUP(B14,MPW!C$6:C$101,MPW!B$6:B$101,"") -> 7 | P14: =_xlfn.XLOOKUP(O14,MPW!B$6:B$55,MPW!A$6:A$55,0) -> 25.954199
A15: =ROW()-5 -> 10 | B15: NIKALAICHUK Aliaksandr | D15: =SUM(F15,H15,J15,L15,N15,P15)-MIN(F15,H15,J15,L15,N15) -> 54.959241 | E15: =_xlfn.XLOOKUP($B15,'PP1'!$C$6:$C$101,'PP1'!$B$6:$B$101,"") -> 5 | F15: =_xlfn.XLOOKUP(E15,'PP1'!$B$6:$B$55,'PP1'!$A$6:$A$55,0) -> 25.75047 | G15: =_xlfn.XLOOKUP($B15,'PP2'!$C$6:$C$101,'PP2'!$B$6:$B$101,"") -> 5 | H15: =_xlfn.XLOOKUP(G15,'PP2'!$B$6:$B$55,'PP2'!$A$6:$A$55,0) -> 24.108149 | I15: =_xlfn.XLOOKUP($B15,'PP3'!$C$6:$C$101,'PP3'!$B$6:$B$101,"") -> 9 | J15: =_xlfn.XLOOKUP(I15,'PP3'!$B$6:$B$55,'PP3'!$A$6:$A$55,0) -> 5.1006228 | K15: =_xlfn.XLOOKUP($B15,'PP4'!$C$6:$C$101,'PP4'!$B$6:$B$101,"") | L15: =_xlfn.XLOOKUP(K15,'PP4'!$B$6:$B$55,'PP4'!$A$6:$A$55,0) -> 0 | M15: =_xlfn.XLOOKUP($B15,'PP5'!$C$6:$C$101,'PP5'!$B$6:$B$101,"") | N15: =_xlfn.XLOOKUP(M15,'PP5'!$B$6:$B$55,'PP5'!$A$6:$A$55,0) -> 0 | O15: =_xlfn.XLOOKUP(B15,MPW!C$6:C$101,MPW!B$6:B$101,"") | P15: =_xlfn.XLOOKUP(O15,MPW!B$6:B$55,MPW!A$6:A$55,0)
A16: =ROW()-5 -> 11 | B16: SZCZĘSNY Jacek | D16: =SUM(F16,H16,J16,L16,N16,P16)-MIN(F16,H16,J16,L16,N16) -> 53.709994 | E16: =_xlfn.XLOOKUP($B16,'PP1'!$C$6:$C$101,'PP1'!$B$6:$B$101,"") | F16: =_xlfn.XLOOKUP(E16,'PP1'!$B$6:$B$55,'PP1'!$A$6:$A$55,0) -> 0 | G16: =_xlfn.XLOOKUP($B16,'PP2'!$C$6:$C$101,'PP2'!$B$6:$B$101,"") | H16: =_xlfn.XLOOKUP(G16,'PP2'!$B$6:$B$55,'PP2'!$A$6:$A$55,0) -> 0 | I16: =_xlfn.XLOOKUP($B16,'PP3'!$C$6:$C$101,'PP3'!$B$6:$B$101,"") | J16: =_xlfn.XLOOKUP(I16,'PP3'!$B$6:$B$55,'PP3'!$A$6:$A$55,0) -> 0 | K16: =_xlfn.XLOOKUP($B16,'PP4'!$C$6:$C$101,'PP4'!$B$6:$B$101,"") -> 5 | L16: =_xlfn.XLOOKUP(K16,'PP4'!$B$6:$B$55,'PP4'!$A$6:$A$55,0) -> 24.108149 | M16: =_xlfn.XLOOKUP($B16,'PP5'!$C$6:$C$101,'PP5'!$B$6:$B$101,"") | N16: =_xlfn.XLOOKUP(M16,'PP5'!$B$6:$B$55,'PP5'!$A$6:$A$55,0) -> 0 | O16: =_xlfn.XLOOKUP(B16,MPW!C$6:C$101,MPW!B$6:B$101,"") -> 6 | P16: =_xlfn.XLOOKUP(O16,MPW!B$6:B$55,MPW!A$6:A$55,0) -> 29.601845
A17: =ROW()-5 -> 12 | B17: CHUDYCKI Artur | D17: =SUM(F17,H17,J17,L17,N17,P17)-MIN(F17,H17,J17,L17,N17) -> 38.121731 | E17: =_xlfn.XLOOKUP($B17,'PP1'!$C$6:$C$101,'PP1'!$B$6:$B$101,"") -> 10 | F17: =_xlfn.XLOOKUP(E17,'PP1'!$B$6:$B$55,'PP1'!$A$6:$A$55,0) -> 1 | G17: =_xlfn.XLOOKUP($B17,'PP2'!$C$6:$C$101,'PP2'!$B$6:$B$101,"") | H17: =_xlfn.XLOOKUP(G17,'PP2'!$B$6:$B$55,'PP2'!$A$6:$A$55,0) -> 0 | I17: =_xlfn.XLOOKUP($B17,'PP3'!$C$6:$C$101,'PP3'!$B$6:$B$101,"") -> 7 | J17: =_xlfn.XLOOKUP(I17,'PP3'!$B$6:$B$55,'PP3'!$A$6:$A$55,0) -> 20.236129 | K17: =_xlfn.XLOOKUP($B17,'PP4'!$C$6:$C$101,'PP4'!$B$6:$B$101,"") -> 8 | L17: =_xlfn.XLOOKUP(K17,'PP4'!$B$6:$B$55,'PP4'!$A$6:$A$55,0) -> 13.626663 | M17: =_xlfn.XLOOKUP($B17,'PP5'!$C$6:$C$101,'PP5'!$B$6:$B$101,"") | N17: =_xlfn.XLOOKUP(M17,'PP5'!$B$6:$B$55,'PP5'!$A$6:$A$55,0) -> 0 | O17: =_xlfn.XLOOKUP(B17,MPW!C$6:C$101,MPW!B$6:B$101,"") -> 11 | P17: =_xlfn.XLOOKUP(O17,MPW!B$6:B$55,MPW!A$6:A$55,0) -> 3.2589381
... A22: =ROW()-5 -> 17 | B22: STOŁOWSKI Mariusz | D22: =SUM(F22,H22,J22,L22,N22,P22)-MIN(F22,H22,J22,L22,N22) -> 1 | E22: =_xlfn.XLOOKUP($B22,'PP1'!$C$6:$C$101,'PP1'!$B$6:$B$101,"") | F22: =_xlfn.XLOOKUP(E22,'PP1'!$B$6:$B$55,'PP1'!$A$6:$A$55,0) -> 0 | G22: =_xlfn.XLOOKUP($B22,'PP2'!$C$6:$C$101,'PP2'!$B$6:$B$101,"") | H22: =_xlfn.XLOOKUP(G22,'PP2'!$B$6:$B$55,'PP2'!$A$6:$A$55,0) -> 0 | I22: =_xlfn.XLOOKUP($B22,'PP3'!$C$6:$C$101,'PP3'!$B$6:$B$101,"") | J22: =_xlfn.XLOOKUP(I22,'PP3'!$B$6:$B$55,'PP3'!$A$6:$A$55,0) -> 0 | K22: =_xlfn.XLOOKUP($B22,'PP4'!$C$6:$C$101,'PP4'!$B$6:$B$101,"") | L22: =_xlfn.XLOOKUP(K22,'PP4'!$B$6:$B$55,'PP4'!$A$6:$A$55,0) -> 0 | M22: =_xlfn.XLOOKUP($B22,'PP5'!$C$6:$C$101,'PP5'!$B$6:$B$101,"") -> 6 | N22: =_xlfn.XLOOKUP(M22,'PP5'!$B$6:$B$55,'PP5'!$A$6:$A$55,0) -> 1 | O22: =_xlfn.XLOOKUP(B22,MPW!C$6:C$101,MPW!B$6:B$101,"") | P22: =_xlfn.XLOOKUP(O22,MPW!B$6:B$55,MPW!A$6:A$55,0)
A23: =ROW()-5 -> 18 | D23: =SUM(F23,H23,J23,L23,N23,P23)-MIN(F23,H23,J23,L23,N23) -> 0 | E23: =_xlfn.XLOOKUP($B23,'PP1'!$C$6:$C$101,'PP1'!$B$6:$B$101,"") | F23: =_xlfn.XLOOKUP(E23,'PP1'!$B$6:$B$55,'PP1'!$A$6:$A$55,0) -> 0 | G23: =_xlfn.XLOOKUP($B23,'PP2'!$C$6:$C$101,'PP2'!$B$6:$B$101,"") | H23: =_xlfn.XLOOKUP(G23,'PP2'!$B$6:$B$55,'PP2'!$A$6:$A$55,0) -> 0 | I23: =_xlfn.XLOOKUP($B23,'PP3'!$C$6:$C$101,'PP3'!$B$6:$B$101,"") | J23: =_xlfn.XLOOKUP(I23,'PP3'!$B$6:$B$55,'PP3'!$A$6:$A$55,0) -> 0 | K23: =_xlfn.XLOOKUP($B23,'PP4'!$C$6:$C$101,'PP4'!$B$6:$B$101,"") | L23: =_xlfn.XLOOKUP(K23,'PP4'!$B$6:$B$55,'PP4'!$A$6:$A$55,0) -> 0 | M23: =_xlfn.XLOOKUP($B23,'PP5'!$C$6:$C$101,'PP5'!$B$6:$B$101,"") | N23: =_xlfn.XLOOKUP(M23,'PP5'!$B$6:$B$55,'PP5'!$A$6:$A$55,0) -> 0 | O23: =_xlfn.XLOOKUP(B23,MPW!C$6:C$101,MPW!B$6:B$101,"") | P23: =_xlfn.XLOOKUP(O23,MPW!B$6:B$55,MPW!A$6:A$55,0)
A24: =ROW()-5 -> 19 | D24: =SUM(F24,H24,J24,L24,N24,P24)-MIN(F24,H24,J24,L24,N24) -> 0 | E24: =_xlfn.XLOOKUP($B24,'PP1'!$C$6:$C$101,'PP1'!$B$6:$B$101,"") | F24: =_xlfn.XLOOKUP(E24,'PP1'!$B$6:$B$55,'PP1'!$A$6:$A$55,0) -> 0 | G24: =_xlfn.XLOOKUP($B24,'PP2'!$C$6:$C$101,'PP2'!$B$6:$B$101,"") | H24: =_xlfn.XLOOKUP(G24,'PP2'!$B$6:$B$55,'PP2'!$A$6:$A$55,0) -> 0 | I24: =_xlfn.XLOOKUP($B24,'PP3'!$C$6:$C$101,'PP3'!$B$6:$B$101,"") | J24: =_xlfn.XLOOKUP(I24,'PP3'!$B$6:$B$55,'PP3'!$A$6:$A$55,0) -> 0 | K24: =_xlfn.XLOOKUP($B24,'PP4'!$C$6:$C$101,'PP4'!$B$6:$B$101,"") | L24: =_xlfn.XLOOKUP(K24,'PP4'!$B$6:$B$55,'PP4'!$A$6:$A$55,0) -> 0 | M24: =_xlfn.XLOOKUP($B24,'PP5'!$C$6:$C$101,'PP5'!$B$6:$B$101,"") | N24: =_xlfn.XLOOKUP(M24,'PP5'!$B$6:$B$55,'PP5'!$A$6:$A$55,0) -> 0 | O24: =_xlfn.XLOOKUP(B24,MPW!C$6:C$101,MPW!B$6:B$101,"") | P24: =_xlfn.XLOOKUP(O24,MPW!B$6:B$55,MPW!A$6:A$55,0)
A25: =ROW()-5 -> 20 | D25: =SUM(F25,H25,J25,L25,N25,P25)-MIN(F25,H25,J25,L25,N25) -> 0 | E25: =_xlfn.XLOOKUP($B25,'PP1'!$C$6:$C$101,'PP1'!$B$6:$B$101,"") | F25: =_xlfn.XLOOKUP(E25,'PP1'!$B$6:$B$55,'PP1'!$A$6:$A$55,0) -> 0 | G25: =_xlfn.XLOOKUP($B25,'PP2'!$C$6:$C$101,'PP2'!$B$6:$B$101,"") | H25: =_xlfn.XLOOKUP(G25,'PP2'!$B$6:$B$55,'PP2'!$A$6:$A$55,0) -> 0 | I25: =_xlfn.XLOOKUP($B25,'PP3'!$C$6:$C$101,'PP3'!$B$6:$B$101,"") | J25: =_xlfn.XLOOKUP(I25,'PP3'!$B$6:$B$55,'PP3'!$A$6:$A$55,0) -> 0 | K25: =_xlfn.XLOOKUP($B25,'PP4'!$C$6:$C$101,'PP4'!$B$6:$B$101,"") | L25: =_xlfn.XLOOKUP(K25,'PP4'!$B$6:$B$55,'PP4'!$A$6:$A$55,0) -> 0 | M25: =_xlfn.XLOOKUP($B25,'PP5'!$C$6:$C$101,'PP5'!$B$6:$B$101,"") | N25: =_xlfn.XLOOKUP(M25,'PP5'!$B$6:$B$55,'PP5'!$A$6:$A$55,0) -> 0 | O25: =_xlfn.XLOOKUP(B25,MPW!C$6:C$101,MPW!B$6:B$101,"") | P25: =_xlfn.XLOOKUP(O25,MPW!B$6:B$55,MPW!A$6:A$55,0)
A26: =ROW()-5 -> 21 | D26: =SUM(F26,H26,J26,L26,N26,P26)-MIN(F26,H26,J26,L26,N26) -> 0 | E26: =_xlfn.XLOOKUP($B26,'PP1'!$C$6:$C$101,'PP1'!$B$6:$B$101,"") | F26: =_xlfn.XLOOKUP(E26,'PP1'!$B$6:$B$55,'PP1'!$A$6:$A$55,0) -> 0 | G26: =_xlfn.XLOOKUP($B26,'PP2'!$C$6:$C$101,'PP2'!$B$6:$B$101,"") | H26: =_xlfn.XLOOKUP(G26,'PP2'!$B$6:$B$55,'PP2'!$A$6:$A$55,0) -> 0 | I26: =_xlfn.XLOOKUP($B26,'PP3'!$C$6:$C$101,'PP3'!$B$6:$B$101,"") | J26: =_xlfn.XLOOKUP(I26,'PP3'!$B$6:$B$55,'PP3'!$A$6:$A$55,0) -> 0 | K26: =_xlfn.XLOOKUP($B26,'PP4'!$C$6:$C$101,'PP4'!$B$6:$B$101,"") | L26: =_xlfn.XLOOKUP(K26,'PP4'!$B$6:$B$55,'PP4'!$A$6:$A$55,0) -> 0 | M26: =_xlfn.XLOOKUP($B26,'PP5'!$C$6:$C$101,'PP5'!$B$6:$B$101,"") | N26: =_xlfn.XLOOKUP(M26,'PP5'!$B$6:$B$55,'PP5'!$A$6:$A$55,0) -> 0 | O26: =_xlfn.XLOOKUP(B26,MPW!C$6:C$101,MPW!B$6:B$101,"") | P26: =_xlfn.XLOOKUP(O26,MPW!B$6:B$55,MPW!A$6:A$55,0)
A27: =ROW()-5 -> 22 | D27: =SUM(F27,H27,J27,L27,N27,P27)-MIN(F27,H27,J27,L27,N27) -> 0 | E27: =_xlfn.XLOOKUP($B27,'PP1'!$C$6:$C$101,'PP1'!$B$6:$B$101,"") | F27: =_xlfn.XLOOKUP(E27,'PP1'!$B$6:$B$55,'PP1'!$A$6:$A$55,0) -> 0 | G27: =_xlfn.XLOOKUP($B27,'PP2'!$C$6:$C$101,'PP2'!$B$6:$B$101,"") | H27: =_xlfn.XLOOKUP(G27,'PP2'!$B$6:$B$55,'PP2'!$A$6:$A$55,0) -> 0 | I27: =_xlfn.XLOOKUP($B27,'PP3'!$C$6:$C$101,'PP3'!$B$6:$B$101,"") | J27: =_xlfn.XLOOKUP(I27,'PP3'!$B$6:$B$55,'PP3'!$A$6:$A$55,0) -> 0 | K27: =_xlfn.XLOOKUP($B27,'PP4'!$C$6:$C$101,'PP4'!$B$6:$B$101,"") | L27: =_xlfn.XLOOKUP(K27,'PP4'!$B$6:$B$55,'PP4'!$A$6:$A$55,0) -> 0 | M27: =_xlfn.XLOOKUP($B27,'PP5'!$C$6:$C$101,'PP5'!$B$6:$B$101,"") | N27: =_xlfn.XLOOKUP(M27,'PP5'!$B$6:$B$55,'PP5'!$A$6:$A$55,0) -> 0 | O27: =_xlfn.XLOOKUP(B27,MPW!C$6:C$101,MPW!B$6:B$101,"") | P27: =_xlfn.XLOOKUP(O27,MPW!B$6:B$55,MPW!A$6:A$55,0)
A28: =ROW()-5 -> 23 | D28: =SUM(F28,H28,J28,L28,N28,P28)-MIN(F28,H28,J28,L28,N28) -> 0 | E28: =_xlfn.XLOOKUP($B28,'PP1'!$C$6:$C$101,'PP1'!$B$6:$B$101,"") | F28: =_xlfn.XLOOKUP(E28,'PP1'!$B$6:$B$55,'PP1'!$A$6:$A$55,0) -> 0 | G28: =_xlfn.XLOOKUP($B28,'PP2'!$C$6:$C$101,'PP2'!$B$6:$B$101,"") | H28: =_xlfn.XLOOKUP(G28,'PP2'!$B$6:$B$55,'PP2'!$A$6:$A$55,0) -> 0 | I28: =_xlfn.XLOOKUP($B28,'PP3'!$C$6:$C$101,'PP3'!$B$6:$B$101,"") | J28: =_xlfn.XLOOKUP(I28,'PP3'!$B$6:$B$55,'PP3'!$A$6:$A$55,0) -> 0 | K28: =_xlfn.XLOOKUP($B28,'PP4'!$C$6:$C$101,'PP4'!$B$6:$B$101,"") | L28: =_xlfn.XLOOKUP(K28,'PP4'!$B$6:$B$55,'PP4'!$A$6:$A$55,0) -> 0 | M28: =_xlfn.XLOOKUP($B28,'PP5'!$C$6:$C$101,'PP5'!$B$6:$B$101,"") | N28: =_xlfn.XLOOKUP(M28,'PP5'!$B$6:$B$55,'PP5'!$A$6:$A$55,0) -> 0 | O28: =_xlfn.XLOOKUP(B28,MPW!C$6:C$101,MPW!B$6:B$101,"") | P28: =_xlfn.XLOOKUP(O28,MPW!B$6:B$55,MPW!A$6:A$55,0)
A29: =ROW()-5 -> 24 | D29: =SUM(F29,H29,J29,L29,N29,P29)-MIN(F29,H29,J29,L29,N29) -> 0 | E29: =_xlfn.XLOOKUP($B29,'PP1'!$C$6:$C$101,'PP1'!$B$6:$B$101,"") | F29: =_xlfn.XLOOKUP(E29,'PP1'!$B$6:$B$55,'PP1'!$A$6:$A$55,0) -> 0 | G29: =_xlfn.XLOOKUP($B29,'PP2'!$C$6:$C$101,'PP2'!$B$6:$B$101,"") | H29: =_xlfn.XLOOKUP(G29,'PP2'!$B$6:$B$55,'PP2'!$A$6:$A$55,0) -> 0 | I29: =_xlfn.XLOOKUP($B29,'PP3'!$C$6:$C$101,'PP3'!$B$6:$B$101,"") | J29: =_xlfn.XLOOKUP(I29,'PP3'!$B$6:$B$55,'PP3'!$A$6:$A$55,0) -> 0 | K29: =_xlfn.XLOOKUP($B29,'PP4'!$C$6:$C$101,'PP4'!$B$6:$B$101,"") | L29: =_xlfn.XLOOKUP(K29,'PP4'!$B$6:$B$55,'PP4'!$A$6:$A$55,0) -> 0 | M29: =_xlfn.XLOOKUP($B29,'PP5'!$C$6:$C$101,'PP5'!$B$6:$B$101,"") | N29: =_xlfn.XLOOKUP(M29,'PP5'!$B$6:$B$55,'PP5'!$A$6:$A$55,0) -> 0 | O29: =_xlfn.XLOOKUP(B29,MPW!C$6:C$101,MPW!B$6:B$101,"") | P29: =_xlfn.XLOOKUP(O29,MPW!B$6:B$55,MPW!A$6:A$55,0)
A30: =ROW()-5 -> 25 | D30: =SUM(F30,H30,J30,L30,N30,P30)-MIN(F30,H30,J30,L30,N30) -> 0 | E30: =_xlfn.XLOOKUP($B30,'PP1'!$C$6:$C$101,'PP1'!$B$6:$B$101,"") | F30: =_xlfn.XLOOKUP(E30,'PP1'!$B$6:$B$55,'PP1'!$A$6:$A$55,0) -> 0 | G30: =_xlfn.XLOOKUP($B30,'PP2'!$C$6:$C$101,'PP2'!$B$6:$B$101,"") | H30: =_xlfn.XLOOKUP(G30,'PP2'!$B$6:$B$55,'PP2'!$A$6:$A$55,0) -> 0 | I30: =_xlfn.XLOOKUP($B30,'PP3'!$C$6:$C$101,'PP3'!$B$6:$B$101,"") | J30: =_xlfn.XLOOKUP(I30,'PP3'!$B$6:$B$55,'PP3'!$A$6:$A$55,0) -> 0 | K30: =_xlfn.XLOOKUP($B30,'PP4'!$C$6:$C$101,'PP4'!$B$6:$B$101,"") | L30: =_xlfn.XLOOKUP(K30,'PP4'!$B$6:$B$55,'PP4'!$A$6:$A$55,0) -> 0 | M30: =_xlfn.XLOOKUP($B30,'PP5'!$C$6:$C$101,'PP5'!$B$6:$B$101,"") | N30: =_xlfn.XLOOKUP(M30,'PP5'!$B$6:$B$55,'PP5'!$A$6:$A$55,0) -> 0 | O30: =_xlfn.XLOOKUP(B30,MPW!C$6:C$101,MPW!B$6:B$101,"") | P30: =_xlfn.XLOOKUP(O30,MPW!B$6:B$55,MPW!A$6:A$55,0)

Sheet PP1
H1: Liczba uczestników: | I1: GP Punkty | J1: Bonus za rundę | K1: Mnożnik za podium
B2: miejsce: | C2: KONIN | H2: 10 | I2: 50 | J2: 10 | K2: =3*H2^(1/3) -> 6.4633041
B3: data: | C3: 28.09.2024
A5: Punkty | B5: Miejsce Place | C5: Nazwisko Imię Name | D5: Klub Club(s) | E5: Okręg Division | F5: Państwo Country | H5: Miejsce | I5: Punkty za miejsce | J5: awans do kolejnej rundy pucharowej | K5: bonus za rundy pucharowe | L5: punkty za podium | M5: Suma
A6: =M6 -> 109.38991 | B6: =IF(H6>$H$2,"",(ROW()-5)) -> 1 | C6: KRZEMIŃSKI Mariusz | D6: AZS AWF Gdańsk | F6: POL | H6: 1 | I6: =IF(H2=1,50,IF(H6<$H$2+1,($I$2-($I$2-1)*(LOG(H6)/LOG($H$2))),"")) -> 50 | J6: =INT(LOG($H$2,2))-ROUNDUP(LOG(H6,2),0)+IF(OR($H$2=1,$H$2=2,$H$2=4,$H$2=8,$H$2=16,$H$2=32,$H$2=64,$H$2=128,$H$2=256),0,1) -> 4 | K6: =J6*$J$2 -> 40 | L6: =3*K2 -> 19.389912 | M6: =IF(I6<>"",K6+I6+L6,0) -> 109.38991
A7: =M7 -> 78.176138 | B7: =IF(H7>$H$2,"",(ROW()-5)) -> 2 | C7: KOSTRZEWA Ireneusz | D7: Ksz Warszawianka | F7: POL | H7: 2 | I7: =IF(H7<$H$2+1,($I$2-($I$2-1)*(LOG(H7)/LOG($H$2))),"") -> 35.24953 | J7: =INT(LOG($H$2,2))-ROUNDUP(LOG(H7,2),0)+IF(OR($H$2=1,$H$2=2,$H$2=4,$H$2=8,$H$2=16,$H$2=32,$H$2=64,$H$2=128,$H$2=256),0,1) -> 3 | K7: =J7*$J$2 -> 30 | L7: =2*K2 -> 12.926608 | M7: =IF(I7<>"",K7+I7+L7,0) -> 78.176138
A8: =M8 -> 53.084363 | B8: =IF(H8>$H$2,"",(ROW()-5)) -> 3 | C8: DRAPELLA Maciej | D8: SPWS | F8: POL | H8: 3 | I8: =IF(H8<$H$2+1,($I$2-($I$2-1)*(LOG(H8)/LOG($H$2))),"") -> 26.621059 | J8: =INT(LOG($H$2,2))-ROUNDUP(LOG(H8,2),0)+IF(OR($H$2=1,$H$2=2,$H$2=4,$H$2=8,$H$2=16,$H$2=32,$H$2=64,$H$2=128,$H$2=256),0,1) -> 2 | K8: =J8*$J$2 -> 20 | L8: =K2 -> 6.4633041 | M8: =IF(I8<>"",K8+I8+L8,0) -> 53.084363
A9: =M9 -> 46.962364 | B9: =IF(H9>$H$2,"",(ROW()-5)) -> 4 | C9: HERONIMEK Leszek | D9: Polski Klub Szermierczy Warszawa | F9: POL | H9: 4 | I9: =IF(H9<$H$2+1,($I$2-($I$2-1)*(LOG(H9)/LOG($H$2))),"") -> 20.49906 | J9: =INT(LOG($H$2,2))-ROUNDUP(LOG(H9,2),0)+IF(OR($H$2=1,$H$2=2,$H$2=4,$H$2=8,$H$2=16,$H$2=32,$H$2=64,$H$2=128,$H$2=256),0,1) -> 2 | K9: =J9*$J$2 -> 20 | L9: =K2 -> 6.4633041 | M9: =IF(I9<>"",K9+I9+L9,0) -> 46.962364 | AH9: x | AI9: 23
A10: =M10 -> 25.75047 | B10: =IF(H10>$H$2,"",(ROW()-5)) -> 5 | C10: NIKALAICHUK Aliaksandr | D10: AZS AWF Kraków | F10: POL | H10: 5 | I10: =IF(H10<$H$2+1,($I$2-($I$2-1)*(LOG(H10)/LOG($H$2))),"") -> 15.75047 | J10: =INT(LOG($H$2,2))-ROUNDUP(LOG(H10,2),0)+IF(OR($H$2=1,$H$2=2,$H$2=4,$H$2=8,$H$2=16,$H$2=32,$H$2=64,$H$2=128,$H$2=256),0,1) -> 1 | K10: =J10*$J$2 -> 10 | M10: =IF(I10<>"",K10+I10+L10,0) -> 25.75047 | AH10: N | AI10: 45
A11: =M11 -> 21.870589 | B11: =IF(H11>$H$2,"",(ROW()-5)) -> 6 | C11: POKRZYWA Mariusz | D11: AZS AWF Kraków | F11: POL | H11: 6 | I11: =IF(H11<$H$2+1,($I$2-($I$2-1)*(LOG(H11)/LOG($H$2))),"") -> 11.870589 | J11: =INT(LOG($H$2,2))-ROUNDUP(LOG(H11,2),0)+IF(OR($H$2=1,$H$2=2,$H$2=4,$H$2=8,$H$2=16,$H$2=32,$H$2=64,$H$2=128,$H$2=256),0,1) -> 1 | K11: =J11*$J$2 -> 10 | M11: =IF(I11<>"",K11+I11+L11,0) -> 21.870589 | AH11: MP | AI11: 50
A12: =M12 -> 18.590196 | B12: =IF(H12>$H$2,"",(ROW()-5)) -> 7 | C12: AUGUSTOWSKI Waldemar | D12: AZS AWF Wrocław | F12: POL | H12: 7 | I12: =IF(H12<$H$2+1,($I$2-($I$2-1)*(LOG(H12)/LOG($H$2))),"") -> 8.590196 | J12: =INT(LOG($H$2,2))-ROUNDUP(LOG(H12,2),0)+IF(OR($H$2=1,$H$2=2,$H$2=4,$H$2=8,$H$2=16,$H$2=32,$H$2=64,$H$2=128,$H$2=256),0,1) -> 1 | K12: =J12*$J$2 -> 10 | M12: =IF(I12<>"",K12+I12+L12,0) -> 18.590196 | AH12: MP-1 | AI12: =AI11-1 -> 49
A13: =M13 -> 15.748591 | B13: =IF(H13>$H$2,"",(ROW()-5)) -> 8 | C13: ĆWIORO Krzysztof | D13: BTS Bytom | F13: POL | H13: 8 | I13: =IF(H13<$H$2+1,($I$2-($I$2-1)*(LOG(H13)/LOG($H$2))),"") -> 5.7485906 | J13: =INT(LOG($H$2,2))-ROUNDUP(LOG(H13,2),0)+IF(OR($H$2=1,$H$2=2,$H$2=4,$H$2=8,$H$2=16,$H$2=32,$H$2=64,$H$2=128,$H$2=256),0,1) -> 1 | K13: =J13*$J$2 -> 10 | M13: =IF(I13<>"",K13+I13+L13,0) -> 15.748591 | AH13: log(x) | AI13: =LOG(AI9) -> 1.3617278
A14: =M14 -> 3.242117 | B14: =IF(H14>$H$2,"",(ROW()-5)) -> 9 | C14: WHITLEY Gary | D14: AZS Wratislavia | F14: POL | H14: 9 | I14: =IF(H14<$H$2+1,($I$2-($I$2-1)*(LOG(H14)/LOG($H$2))),"") -> 3.242117 | J14: =INT(LOG($H$2,2))-ROUNDUP(LOG(H14,2),0)+IF(OR($H$2=1,$H$2=2,$H$2=4,$H$2=8,$H$2=16,$H$2=32,$H$2=64,$H$2=128,$H$2=256),0,1) -> 0 | K14: =J14*$J$2 -> 0 | M14: =IF(I14<>"",K14+I14+L14,0) -> 3.242117 | AH14: Log(N) | AI14: =LOG(AI10) -> 1.6532125
A15: =M15 -> 1 | B15: =IF(H15>$H$2,"",(ROW()-5)) -> 10 | C15: CHUDYCKI Artur | D15: MKS KUSY SZCZECIN | F15: POL | H15: 10 | I15: =IF(H15<$H$2+1,($I$2-($I$2-1)*(LOG(H15)/LOG($H$2))),"") -> 1 | J15: =INT(LOG($H$2,2))-ROUNDUP(LOG(H15,2),0)+IF(OR($H$2=1,$H$2=2,$H$2=4,$H$2=8,$H$2=16,$H$2=32,$H$2=64,$H$2=128,$H$2=256),0,1) -> 0 | K15: =J15*$J$2 -> 0 | M15: =IF(I15<>"",K15+I15+L15,0) -> 1
A16: =M16 -> 0 | B16: =IF(H16>$H$2,"",(ROW()-5)) | H16: 11 | I16: =IF(H16<$H$2+1,($I$2-($I$2-1)*(LOG(H16)/LOG($H$2))),"") | J16: =INT(LOG($H$2,2))-ROUNDUP(LOG(H16,2),0)+IF(OR($H$2=1,$H$2=2,$H$2=4,$H$2=8,$H$2=16,$H$2=32,$H$2=64,$H$2=128,$H$2=256),0,1) -> 0 | K16: =J16*$J$2 -> 0 | M16: =IF(I16<>"",K16+I16+L16,0) -> 0 | AH16: MP - (MP-1)*LOG(x)/LOG(N) | AI16: =AI11-AI12*AI13/AI14 -> 9.6393909 | AJ16: points
A17: =M17 -> 0 | B17: =IF(H17>$H$2,"",(ROW()-5)) | H17: 12 | I17: =IF(H17<$H$2+1,($I$2-($I$2-1)*(LOG(H17)/LOG($H$2))),"") | J17: =INT(LOG($H$2,2))-ROUNDUP(LOG(H17,2),0)+IF(OR($H$2=1,$H$2=2,$H$2=4,$H$2=8,$H$2=16,$H$2=32,$H$2=64,$H$2=128,$H$2=256),0,1) -> 0 | K17: =J17*$J$2 -> 0 | M17: =IF(I17<>"",K17+I17+L17,0) -> 0
A18: =M18 -> 0 | B18: =IF(H18>$H$2,"",(ROW()-5)) | H18: 13 | I18: =IF(H18<$H$2+1,($I$2-($I$2-1)*(LOG(H18)/LOG($H$2))),"") | J18: =INT(LOG($H$2,2))-ROUNDUP(LOG(H18,2),0)+IF(OR($H$2=1,$H$2=2,$H$2=4,$H$2=8,$H$2=16,$H$2=32,$H$2=64,$H$2=128,$H$2=256),0,1) -> 0 | K18: =J18*$J$2 -> 0 | M18: =IF(I18<>"",K18+I18+L18,0) -> 0
A19: =M19 -> 0 | B19: =IF(H19>$H$2,"",(ROW()-5)) | H19: 14 | I19: =IF(H19<$H$2+1,($I$2-($I$2-1)*(LOG(H19)/LOG($H$2))),"") | J19: =INT(LOG($H$2,2))-ROUNDUP(LOG(H19,2),0)+IF(OR($H$2=1,$H$2=2,$H$2=4,$H$2=8,$H$2=16,$H$2=32,$H$2=64,$H$2=128,$H$2=256),0,1) -> 0 | K19: =J19*$J$2 -> 0 | M19: =IF(I19<>"",K19+I19+L19,0) -> 0
A20: =M20 -> 0 | B20: =IF(H20>$H$2,"",(ROW()-5)) | H20: 15 | I20: =IF(H20<$H$2+1,($I$2-($I$2-1)*(LOG(H20)/LOG($H$2))),"") | J20: =INT(LOG($H$2,2))-ROUNDUP(LOG(H20,2),0)+IF(OR($H$2=1,$H$2=2,$H$2=4,$H$2=8,$H$2=16,$H$2=32,$H$2=64,$H$2=128,$H$2=256),0,1) -> 0 | K20: =J20*$J$2 -> 0 | M20: =IF(I20<>"",K20+I20+L20,0) -> 0
A21: =M21 -> 0 | B21: =IF(H21>$H$2,"",(ROW()-5)) | H21: 16 | I21: =IF(H21<$H$2+1,($I$2-($I$2-1)*(LOG(H21)/LOG($H$2))),"") | J21: =INT(LOG($H$2,2))-ROUNDUP(LOG(H21,2),0)+IF(OR($H$2=1,$H$2=2,$H$2=4,$H$2=8,$H$2=16,$H$2=32,$H$2=64,$H$2=128,$H$2=256),0,1) -> 0 | K21: =J21*$J$2 -> 0 | M21: =IF(I21<>"",K21+I21+L21,0) -> 0
A22: =M22 -> 0 | B22: =IF(H22>$H$2,"",(ROW()-5)) | H22: 17 | I22: =IF(H22<$H$2+1,($I$2-($I$2-1)*(LOG(H22)/LOG($H$2))),"") | J22: =INT(LOG($H$2,2))-ROUNDUP(LOG(H22,2),0)+IF(OR($H$2=1,$H$2=2,$H$2=4,$H$2=8,$H$2=16,$H$2=32,$H$2=64,$H$2=128,$H$2=256),0,1) -> -1 | K22: =J22*$J$2 -> -10 | M22: =IF(I22<>"",K22+I22+L22,0) -> 0
A23: =M23 -> 0 | B23: =IF(H23>$H$2,"",(ROW()-5)) | H23: 18 | I23: =IF(H23<$H$2+1,($I$2-($I$2-1)*(LOG(H23)/LOG($H$2))),"") | J23: =INT(LOG($H$2,2))-ROUNDUP(LOG(H23,2),0)+IF(OR($H$2=1,$H$2=2,$H$2=4,$H$2=8,$H$2=16,$H$2=32,$H$2=64,$H$2=128,$H$2=256),0,1) -> -1 | K23: =J23*$J$2 -> -10 | M23: =IF(I23<>"",K23+I23+L23,0) -> 0
A24: =M24 -> 0 | B24: =IF(H24>$H$2,"",(ROW()-5)) | H24: 19 | I24: =IF(H24<$H$2+1,($I$2-($I$2-1)*(LOG(H24)/LOG($H$2))),"") | J24: =INT(LOG($H$2,2))-ROUNDUP(LOG(H24,2),0)+IF(OR($H$2=1,$H$2=2,$H$2=4,$H$2=8,$H$2=16,$H$2=32,$H$2=64,$H$2=128,$H$2=256),0,1) -> -1 | K24: =J24*$J$2 -> -10 | M24: =IF(I24<>"",K24+I24+L24,0) -> 0
A25: =M25 -> 0 | B25: =IF(H25>$H$2,"",(ROW()-5)) | H25: 20 | I25: =IF(H25<$H$2+1,($I$2-($I$2-1)*(LOG(H25)/LOG($H$2))),"") | J25: =INT(LOG($H$2,2))-ROUNDUP(LOG(H25,2),0)+IF(OR($H$2=1,$H$2=2,$H$2=4,$H$2=8,$H$2=16,$H$2=32,$H$2=64,$H$2=128,$H$2=256),0,1) -> -1 | K25: =J25*$J$2 -> -10 | M25: =IF(I25<>"",K25+I25+L25,0) -> 0
A26: =M26 -> 0 | B26: =IF(H26>$H$2,"",(ROW()-5)) | H26: 21 | I26: =IF(H26<$H$2+1,($I$2-($I$2-1)*(LOG(H26)/LOG($H$2))),"") | J26: =INT(LOG($H$2,2))-ROUNDUP(LOG(H26,2),0)+IF(OR($H$2=1,$H$2=2,$H$2=4,$H$2=8,$H$2=16,$H$2=32,$H$2=64,$H$2=128,$H$2=256),0,1) -> -1 | K26: =J26*$J$2 -> -10 | M26: =IF(I26<>"",K26+I26+L26,0) -> 0
A27: =M27 -> 0 | B27: =IF(H27>$H$2,"",(ROW()-5)) | H27: 22 | I27: =IF(H27<$H$2+1,($I$2-($I$2-1)*(LOG(H27)/LOG($H$2))),"") | J27: =INT(LOG($H$2,2))-ROUNDUP(LOG(H27,2),0)+IF(OR($H$2=1,$H$2=2,$H$2=4,$H$2=8,$H$2=16,$H$2=32,$H$2=64,$H$2=128,$H$2=256),0,1) -> -1 | K27: =J27*$J$2 -> -10 | M27: =IF(I27<>"",K27+I27+L27,0) -> 0
A28: =M28 -> 0 | B28: =IF(H28>$H$2,"",(ROW()-5)) | H28: 23 | I28: =IF(H28<$H$2+1,($I$2-($I$2-1)*(LOG(H28)/LOG($H$2))),"") | J28: =INT(LOG($H$2,2))-ROUNDUP(LOG(H28,2),0)+IF(OR($H$2=1,$H$2=2,$H$2=4,$H$2=8,$H$2=16,$H$2=32,$H$2=64,$H$2=128,$H$2=256),0,1) -> -1 | K28: =J28*$J$2 -> -10 | M28: =IF(I28<>"",K28+I28+L28,0) -> 0
... A37: =M37 -> 0 | B37: =IF(H37>$H$2,"",(ROW()-5)) | H37: 32 | I37: =IF(H37<$H$2+1,($I$2-($I$2-1)*(LOG(H37)/LOG($H$2))),"") | J37: =INT(LOG($H$2,2))-ROUNDUP(LOG(H37,2),0)+IF(OR($H$2=1,$H$2=2,$H$2=4,$H$2=8,$H$2=16,$H$2=32,$H$2=64,$H$2=128,$H$2=256),0,1) -> -1 | K37: =J37*$J$2 -> -10 | M37: =IF(I37<>"",K37+I37+L37,0) -> 0
B38: =IF(H38>$H$2,"",(ROW()-5)) | H38: 33 | I38: =IF(H38<$H$2+1,($I$2-($I$2-1)*(LOG(H38)/LOG($H$2))),"") | J38: =INT(LOG($H$2,2))-ROUNDUP(LOG(H38,2),0)+IF(OR($H$2=1,$H$2=2,$H$2=4,$H$2=8,$H$2=16,$H$2=32,$H$2=64,$H$2=128,$H$2=256),0,1) -> -2 | K38: =J38*$J$2 -> -20 | M38: =IF(I38<>"",K38+I38+L38,0) -> 0
B39: =IF(H39>$H$2,"",(ROW()-5)) | H39: 34 | I39: =IF(H39<$H$2+1,($I$2-($I$2-1)*(LOG(H39)/LOG($H$2))),"") | J39: =INT(LOG($H$2,2))-ROUNDUP(LOG(H39,2),0)+IF(OR($H$2=1,$H$2=2,$H$2=4,$H$2=8,$H$2=16,$H$2=32,$H$2=64,$H$2=128,$H$2=256),0,1) -> -2 | K39: =J39*$J$2 -> -20 | M39: =IF(I39<>"",K39+I39+L39,0) -> 0
B40: =IF(H40>$H$2,"",(ROW()-5)) | H40: 35 | I40: =IF(H40<$H$2+1,($I$2-($I$2-1)*(LOG(H40)/LOG($H$2))),"") | J40: =INT(LOG($H$2,2))-ROUNDUP(LOG(H40,2),0)+IF(OR($H$2=1,$H$2=2,$H$2=4,$H$2=8,$H$2=16,$H$2=32,$H$2=64,$H$2=128,$H$2=256),0,1) -> -2 | K40: =J40*$J$2 -> -20 | M40: =IF(I40<>"",K40+I40+L40,0) -> 0
B41: =IF(H41>$H$2,"",(ROW()-5)) | H41: 36 | I41: =IF(H41<$H$2+1,($I$2-($I$2-1)*(LOG(H41)/LOG($H$2))),"") | J41: =INT(LOG($H$2,2))-ROUNDUP(LOG(H41,2),0)+IF(OR($H$2=1,$H$2=2,$H$2=4,$H$2=8,$H$2=16,$H$2=32,$H$2=64,$H$2=128,$H$2=256),0,1) -> -2 | K41: =J41*$J$2 -> -20 | M41: =IF(I41<>"",K41+I41+L41,0) -> 0
B42: =IF(H42>$H$2,"",(ROW()-5)) | H42: 37 | I42: =IF(H42<$H$2+1,($I$2-($I$2-1)*(LOG(H42)/LOG($H$2))),"") | J42: =INT(LOG($H$2,2))-ROUNDUP(LOG(H42,2),0)+IF(OR($H$2=1,$H$2=2,$H$2=4,$H$2=8,$H$2=16,$H$2=32,$H$2=64,$H$2=128,$H$2=256),0,1) -> -2 | K42: =J42*$J$2 -> -20 | M42: =IF(I42<>"",K42+I42+L42,0) -> 0
B43: =IF(H43>$H$2,"",(ROW()-5)) | H43: 38 | I43: =IF(H43<$H$2+1,($I$2-($I$2-1)*(LOG(H43)/LOG($H$2))),"") | J43: =INT(LOG($H$2,2))-ROUNDUP(LOG(H43,2),0)+IF(OR($H$2=1,$H$2=2,$H$2=4,$H$2=8,$H$2=16,$H$2=32,$H$2=64,$H$2=128,$H$2=256),0,1) -> -2 | K43: =J43*$J$2 -> -20 | M43: =IF(I43<>"",K43+I43+L43,0) -> 0
B44: =IF(H44>$H$2,"",(ROW()-5)) | H44: 39 | I44: =IF(H44<$H$2+1,($I$2-($I$2-1)*(LOG(H44)/LOG($H$2))),"") | J44: =INT(LOG($H$2,2))-ROUNDUP(LOG(H44,2),0)+IF(OR($H$2=1,$H$2=2,$H$2=4,$H$2=8,$H$2=16,$H$2=32,$H$2=64,$H$2=128,$H$2=256),0,1) -> -2 | K44: =J44*$J$2 -> -20 | M44: =IF(I44<>"",K44+I44+L44,0) -> 0
B45: =IF(H45>$H$2,"",(ROW()-5)) | H45: 40 | I45: =IF(H45<$H$2+1,($I$2-($I$2-1)*(LOG(H45)/LOG($H$2))),"") | J45: =INT(LOG($H$2,2))-ROUNDUP(LOG(H45,2),0)+IF(OR($H$2=1,$H$2=2,$H$2=4,$H$2=8,$H$2=16,$H$2=32,$H$2=64,$H$2=128,$H$2=256),0,1) -> -2 | K45: =J45*$J$2 -> -20 | M45: =IF(I45<>"",K45+I45+L45,0) -> 0
B46: =IF(H46>$H$2,"",(ROW()-5)) | H46: 41 | I46: =IF(H46<$H$2+1,($I$2-($I$2-1)*(LOG(H46)/LOG($H$2))),"") | J46: =INT(LOG($H$2,2))-ROUNDUP(LOG(H46,2),0)+IF(OR($H$2=1,$H$2=2,$H$2=4,$H$2=8,$H$2=16,$H$2=32,$H$2=64,$H$2=128,$H$2=256),0,1) -> -2 | K46: =J46*$J$2 -> -20 | M46: =IF(I46<>"",K46+I46+L46,0) -> 0 | R46: =LOG($H$2,2) -> 3.3219281 | T46: =LOG(H38,2) -> 5.0443941 | U46: =R46-T46 -> -1.722466
B47: =IF(H47>$H$2,"",(ROW()-5)) | H47: 42 | I47: =IF(H47<$H$2+1,($I$2-($I$2-1)*(LOG(H47)/LOG($H$2))),"") | J47: =INT(LOG($H$2,2))-ROUNDUP(LOG(H47,2),0)+IF(OR($H$2=1,$H$2=2,$H$2=4,$H$2=8,$H$2=16,$H$2=32,$H$2=64,$H$2=128,$H$2=256),0,1) -> -2 | K47: =J47*$J$2 -> -20 | M47: =IF(I47<>"",K47+I47+L47,0) -> 0
B48: =IF(H48>$H$2,"",(ROW()-5)) | H48: 43 | I48: =IF(H48<$H$2+1,($I$2-($I$2-1)*(LOG(H48)/LOG($H$2))),"") | J48: =INT(LOG($H$2,2))-ROUNDUP(LOG(H48,2),0)+IF(OR($H$2=1,$H$2=2,$H$2=4,$H$2=8,$H$2=16,$H$2=32,$H$2=64,$H$2=128,$H$2=256),0,1) -> -2 | K48: =J48*$J$2 -> -20 | M48: =IF(I48<>"",K48+I48+L48,0) -> 0
B49: =IF(H49>$H$2,"",(ROW()-5)) | H49: 44 | I49: =IF(H49<$H$2+1,($I$2-($I$2-1)*(LOG(H49)/LOG($H$2))),"") | J49: =INT(LOG($H$2,2))-ROUNDUP(LOG(H49,2),0)+IF(OR($H$2=1,$H$2=2,$H$2=4,$H$2=8,$H$2=16,$H$2=32,$H$2=64,$H$2=128,$H$2=256),0,1) -> -2 | K49: =J49*$J$2 -> -20 | M49: =IF(I49<>"",K49+I49+L49,0) -> 0
...

Sheet PP2
H1: Liczba uczestników: | I1: GP Punkty | J1: Bonus za rundę | K1: Mnożnik za podium
B2: miejsce: | C2: BYTOM | H2: 9 | I2: 50 | J2: 10 | K2: =3*H2^(1/3) -> 6.2402515
B3: data: | C3: 26.10.2024
A5: Punkty | B5: Miejsce Place | C5: Nazwisko Imię Name | D5: Klub Club(s) | E5: Okręg Division | F5: Państwo Country | H5: Miejsce | I5: Punkty za miejsce | J5: awans do kolejnej rundy pucharowej | K5: bonus za rundy pucharowe | L5: punkty za podium | M5: Suma
A6: =M6 -> 108.72075 | B6: =IF(H6>$H$2,"",(ROW()-5)) -> 1 | C6: KOSTRZEWA Ireneusz | D6: KSz WARSZAWIANKA | E6: POL | F6: POL | H6: 1 | I6: =IF(H2=1,50,IF(H6<$H$2+1,($I$2-($I$2-1)*(LOG(H6)/LOG($H$2))),"")) -> 50 | J6: =INT(LOG($H$2,2))-ROUNDUP(LOG(H6,2),0)+IF(OR($H$2=1,$H$2=2,$H$2=4,$H$2=8,$H$2=16,$H$2=32,$H$2=64,$H$2=128,$H$2=256),0,1) -> 4 | K6: =J6*$J$2 -> 40 | L6: =3*K2 -> 18.720754 | M6: =IF(I6<>"",K6+I6+L6,0) -> 108.72075
A7: =M7 -> 77.022724 | B7: =IF(H7>$H$2,"",(ROW()-5)) -> 2 | C7: DRAPELLA Maciej | D7: SPWS | E7: POL | F7: POL | H7: 2 | I7: =IF(H7<$H$2+1,($I$2-($I$2-1)*(LOG(H7)/LOG($H$2))),"") -> 34.542221 | J7: =INT(LOG($H$2,2))-ROUNDUP(LOG(H7,2),0)+IF(OR($H$2=1,$H$2=2,$H$2=4,$H$2=8,$H$2=16,$H$2=32,$H$2=64,$H$2=128,$H$2=256),0,1) -> 3 | K7: =J7*$J$2 -> 30 | L7: =2*K2 -> 12.480503 | M7: =IF(I7<>"",K7+I7+L7,0) -> 77.022724
A8: =M8 -> 51.740251 | B8: =IF(H8>$H$2,"",(ROW()-5)) -> 3 | C8: KRZEMIŃSKI Mariusz | D8: KS AZS AWFIS GDAŃSK | E8: POL | F8: POL | H8: 3 | I8: =IF(H8<$H$2+1,($I$2-($I$2-1)*(LOG(H8)/LOG($H$2))),"") -> 25.5 | J8: =INT(LOG($H$2,2))-ROUNDUP(LOG(H8,2),0)+IF(OR($H$2=1,$H$2=2,$H$2=4,$H$2=8,$H$2=16,$H$2=32,$H$2=64,$H$2=128,$H$2=256),0,1) -> 2 | K8: =J8*$J$2 -> 20 | L8: =K2 -> 6.2402515 | M8: =IF(I8<>"",K8+I8+L8,0) -> 51.740251
A9: =M9 -> 39.084442 | B9: =IF(H9>$H$2,"",(ROW()-5)) -> 4 | C9: HERONIMEK Leszek | D9: PKSzerm WARSZAWA | E9: POL | F9: POL | H9: 4 | I9: =IF(H9<$H$2+1,($I$2-($I$2-1)*(LOG(H9)/LOG($H$2))),"") -> 19.084442 | J9: =INT(LOG($H$2,2))-ROUNDUP(LOG(H9,2),0)+IF(OR($H$2=1,$H$2=2,$H$2=4,$H$2=8,$H$2=16,$H$2=32,$H$2=64,$H$2=128,$H$2=256),0,1) -> 2 | K9: =J9*$J$2 -> 20 | M9: =IF(I9<>"",K9+I9+L9,0) -> 39.084442 | AH9: x | AI9: 23
A10: =M10 -> 24.108149 | B10: =IF(H10>$H$2,"",(ROW()-5)) -> 5 | C10: NIKALAICHUK Aliaksandr | D10: AZS AWF KRAKÓW | E10: POL | F10: POL | H10: 5 | I10: =IF(H10<$H$2+1,($I$2-($I$2-1)*(LOG(H10)/LOG($H$2))),"") -> 14.108149 | J10: =INT(LOG($H$2,2))-ROUNDUP(LOG(H10,2),0)+IF(OR($H$2=1,$H$2=2,$H$2=4,$H$2=8,$H$2=16,$H$2=32,$H$2=64,$H$2=128,$H$2=256),0,1) -> 1 | K10: =J10*$J$2 -> 10 | M10: =IF(I10<>"",K10+I10+L10,0) -> 24.108149 | AH10: N | AI10: 45
A11: =M11 -> 20.042221 | B11: =IF(H11>$H$2,"",(ROW()-5)) -> 6 | C11: POPRAWA Mariusz | D11: UKS SOKOLIK MOSiR KROSNO | E11: POL | F11: POL | H11: 6 | I11: =IF(H11<$H$2+1,($I$2-($I$2-1)*(LOG(H11)/LOG($H$2))),"") -> 10.042221 | J11: =INT(LOG($H$2,2))-ROUNDUP(LOG(H11,2),0)+IF(OR($H$2=1,$H$2=2,$H$2=4,$H$2=8,$H$2=16,$H$2=32,$H$2=64,$H$2=128,$H$2=256),0,1) -> 1 | K11: =J11*$J$2 -> 10 | M11: =IF(I11<>"",K11+I11+L11,0) -> 20.042221 | AH11: MP | AI11: 50
A12: =M12 -> 16.604528 | B12: =IF(H12>$H$2,"",(ROW()-5)) -> 7 | C12: AUGUSTOWSKI Waldemar | D12: AZS AWF WROCŁAW | E12: POL | H12: 7 | I12: =IF(H12<$H$2+1,($I$2-($I$2-1)*(LOG(H12)/LOG($H$2))),"") -> 6.6045281 | J12: =INT(LOG($H$2,2))-ROUNDUP(LOG(H12,2),0)+IF(OR($H$2=1,$H$2=2,$H$2=4,$H$2=8,$H$2=16,$H$2=32,$H$2=64,$H$2=128,$H$2=256),0,1) -> 1 | K12: =J12*$J$2 -> 10 | M12: =IF(I12<>"",K12+I12+L12,0) -> 16.604528 | AH12: MP-1 | AI12: =AI11-1 -> 49
A13: =M13 -> 13.626663 | B13: =IF(H13>$H$2,"",(ROW()-5)) -> 8 | C13: POKRZYWA Mariusz | D13: AZS AWF KRAKÓW | E13: POL | H13: 8 | I13: =IF(H13<$H$2+1,($I$2-($I$2-1)*(LOG(H13)/LOG($H$2))),"") -> 3.6266631 | J13: =INT(LOG($H$2,2))-ROUNDUP(LOG(H13,2),0)+IF(OR($H$2=1,$H$2=2,$H$2=4,$H$2=8,$H$2=16,$H$2=32,$H$2=64,$H$2=128,$H$2=256),0,1) -> 1 | K13: =J13*$J$2 -> 10 | M13: =IF(I13<>"",K13+I13+L13,0) -> 13.626663 | AH13: log(x) | AI13: =LOG(AI9) -> 1.3617278
A14: =M14 -> 1 | B14: =IF(H14>$H$2,"",(ROW()-5)) -> 9 | C14: WHITLEY Gary | D14: AZS WRATISLAVIA WROCŁAW | E14: USA | F14: USA | H14: 9 | I14: =IF(H14<$H$2+1,($I$2-($I$2-1)*(LOG(H14)/LOG($H$2))),"") -> 1 | J14: =INT(LOG($H$2,2))-ROUNDUP(LOG(H14,2),0)+IF(OR($H$2=1,$H$2=2,$H$2=4,$H$2=8,$H$2=16,$H$2=32,$H$2=64,$H$2=128,$H$2=256),0,1) -> 0 | K14: =J14*$J$2 -> 0 | M14: =IF(I14<>"",K14+I14+L14,0) -> 1 | AH14: Log(N) | AI14: =LOG(AI10) -> 1.6532125
A15: =M15 -> 0 | B15: =IF(H15>$H$2,"",(ROW()-5)) | H15: 10 | I15: =IF(H15<$H$2+1,($I$2-($I$2-1)*(LOG(H15)/LOG($H$2))),"") | J15: =INT(LOG($H$2,2))-ROUNDUP(LOG(H15,2),0)+IF(OR($H$2=1,$H$2=2,$H$2=4,$H$2=8,$H$2=16,$H$2=32,$H$2=64,$H$2=128,$H$2=256),0,1) -> 0 | K15: =J15*$J$2 -> 0 | M15: =IF(I15<>"",K15+I15+L15,0) -> 0
A16: =M16 -> 0 | B16: =IF(H16>$H$2,"",(ROW()-5)) | H16: 11 | I16: =IF(H16<$H$2+1,($I$2-($I$2-1)*(LOG(H16)/LOG($H$2))),"") | J16: =INT(LOG($H$2,2))-ROUNDUP(LOG(H16,2),0)+IF(OR($H$2=1,$H$2=2,$H$2=4,$H$2=8,$H$2=16,$H$2=32,$H$2=64,$H$2=128,$H$2=256),0,1) -> 0 | K16: =J16*$J$2 -> 0 | M16: =IF(I16<>"",K16+I16+L16,0) -> 0 | AH16: MP - (MP-1)*LOG(x)/LOG(N) | AI16: =AI11-AI12*AI13/AI14 -> 9.6393909 | AJ16: points
A17: =M17 -> 0 | B17: =IF(H17>$H$2,"",(ROW()-5)) | H17: 12 | I17: =IF(H17<$H$2+1,($I$2-($I$2-1)*(LOG(H17)/LOG($H$2))),"") | J17: =INT(LOG($H$2,2))-ROUNDUP(LOG(H17,2),0)+IF(OR($H$2=1,$H$2=2,$H$2=4,$H$2=8,$H$2=16,$H$2=32,$H$2=64,$H$2=128,$H$2=256),0,1) -> 0 | K17: =J17*$J$2 -> 0 | M17: =IF(I17<>"",K17+I17+L17,0) -> 0
A18: =M18 -> 0 | B18: =IF(H18>$H$2,"",(ROW()-5)) | H18: 13 | I18: =IF(H18<$H$2+1,($I$2-($I$2-1)*(LOG(H18)/LOG($H$2))),"") | J18: =INT(LOG($H$2,2))-ROUNDUP(LOG(H18,2),0)+IF(OR($H$2=1,$H$2=2,$H$2=4,$H$2=8,$H$2=16,$H$2=32,$H$2=64,$H$2=128,$H$2=256),0,1) -> 0 | K18: =J18*$J$2 -> 0 | M18: =IF(I18<>"",K18+I18+L18,0) -> 0
A19: =M19 -> 0 | B19: =IF(H19>$H$2,"",(ROW()-5)) | H19: 14 | I19: =IF(H19<$H$2+1,($I$2-($I$2-1)*(LOG(H19)/LOG($H$2))),"") | J19: =INT(LOG($H$2,2))-ROUNDUP(LOG(H19,2),0)+IF(OR($H$2=1,$H$2=2,$H$2=4,$H$2=8,$H$2=16,$H$2=32,$H$2=64,$H$2=128,$H$2=256),0,1) -> 0 | K19: =J19*$J$2 -> 0 | M19: =IF(I19<>"",K19+I19+L19,0) -> 0
A20: =M20 -> 0 | B20: =IF(H20>$H$2,"",(ROW()-5)) | H20: 15 | I20: =IF(H20<$H$2+1,($I$2-($I$2-1)*(LOG(H20)/LOG($H$2))),"") | J20: =INT(LOG($H$2,2))-ROUNDUP(LOG(H20,2),0)+IF(OR($H$2=1,$H$2=2,$H$2=4,$H$2=8,$H$2=16,$H$2=32,$H$2=64,$H$2=128,$H$2=256),0,1) -> 0 | K20: =J20*$J$2 -> 0 | M20: =IF(I20<>"",K20+I20+L20,0) -> 0
A21: =M21 -> 0 | B21: =IF(H21>$H$2,"",(ROW()-5)) | H21: 16 | I21: =IF(H21<$H$2+1,($I$2-($I$2-1)*(LOG(H21)/LOG($H$2))),"") | J21: =INT(LOG($H$2,2))-ROUNDUP(LOG(H21,2),0)+IF(OR($H$2=1,$H$2=2,$H$2=4,$H$2=8,$H$2=16,$H$2=32,$H$2=64,$H$2=128,$H$2=256),0,1) -> 0 | K21: =J21*$J$2 -> 0 | M21: =IF(I21<>"",K21+I21+L21,0) -> 0
A22: =M22 -> 0 | B22: =IF(H22>$H$2,"",(ROW()-5)) | H22: 17 | I22: =IF(H22<$H$2+1,($I$2-($I$2-1)*(LOG(H22)/LOG($H$2))),"") | J22: =INT(LOG($H$2,2))-ROUNDUP(LOG(H22,2),0)+IF(OR($H$2=1,$H$2=2,$H$2=4,$H$2=8,$H$2=16,$H$2=32,$H$2=64,$H$2=128,$H$2=256),0,1) -> -1 | K22: =J22*$J$2 -> -10 | M22: =IF(I22<>"",K22+I22+L22,0) -> 0
A23: =M23 -> 0 | B23: =IF(H23>$H$2,"",(ROW()-5)) | H23: 18 | I23: =IF(H23<$H$2+1,($I$2-($I$2-1)*(LOG(H23)/LOG($H$2))),"") | J23: =INT(LOG($H$2,2))-ROUNDUP(LOG(H23,2),0)+IF(OR($H$2=1,$H$2=2,$H$2=4,$H$2=8,$H$2=16,$H$2=32,$H$2=64,$H$2=128,$H$2=256),0,1) -> -1 | K23: =J23*$J$2 -> -10 | M23: =IF(I23<>"",K23+I23+L23,0) -> 0
A24: =M24 -> 0 | B24: =IF(H24>$H$2,"",(ROW()-5)) | H24: 19 | I24: =IF(H24<$H$2+1,($I$2-($I$2-1)*(LOG(H24)/LOG($H$2))),"") | J24: =INT(LOG($H$2,2))-ROUNDUP(LOG(H24,2),0)+IF(OR($H$2=1,$H$2=2,$H$2=4,$H$2=8,$H$2=16,$H$2=32,$H$2=64,$H$2=128,$H$2=256),0,1) -> -1 | K24: =J24*$J$2 -> -10 | M24: =IF(I24<>"",K24+I24+L24,0) -> 0
A25: =M25 -> 0 | B25: =IF(H25>$H$2,"",(ROW()-5)) | H25: 20 | I25: =IF(H25<$H$2+1,($I$2-($I$2-1)*(LOG(H25)/LOG($H$2))),"") | J25: =INT(LOG($H$2,2))-ROUNDUP(LOG(H25,2),0)+IF(OR($H$2=1,$H$2=2,$H$2=4,$H$2=8,$H$2=16,$H$2=32,$H$2=64,$H$2=128,$H$2=256),0,1) -> -1 | K25: =J25*$J$2 -> -10 | M25: =IF(I25<>"",K25+I25+L25,0) -> 0
A26: =M26 -> 0 | B26: =IF(H26>$H$2,"",(ROW()-5)) | H26: 21 | I26: =IF(H26<$H$2+1,($I$2-($I$2-1)*(LOG(H26)/LOG($H$2))),"") | J26: =INT(LOG($H$2,2))-ROUNDUP(LOG(H26,2),0)+IF(OR($H$2=1,$H$2=2,$H$2=4,$H$2=8,$H$2=16,$H$2=32,$H$2=64,$H$2=128,$H$2=256),0,1) -> -1 | K26: =J26*$J$2 -> -10 | M26: =IF(I26<>"",K26+I26+L26,0) -> 0
A27: =M27 -> 0 | B27: =IF(H27>$H$2,"",(ROW()-5)) | H27: 22 | I27: =IF(H27<$H$2+1,($I$2-($I$2-1)*(LOG(H27)/LOG($H$2))),"") | J27: =INT(LOG($H$2,2))-ROUNDUP(LOG(H27,2),0)+IF(OR($H$2=1,$H$2=2,$H$2=4,$H$2=8,$H$2=16,$H$2=32,$H$2=64,$H$2=128,$H$2=256),0,1) -> -1 | K27: =J27*$J$2 -> -10 | M27: =IF(I27<>"",K27+I27+L27,0) -> 0
A28: =M28 -> 0 | B28: =IF(H28>$H$2,"",(ROW()-5)) | H28: 23 | I28: =IF(H28<$H$2+1,($I$2-($I$2-1)*(LOG(H28)/LOG($H$2))),"") | J28: =INT(LOG($H$2,2))-ROUNDUP(LOG(H28,2),0)+IF(OR($H$2=1,$H$2=2,$H$2=4,$H$2=8,$H$2=16,$H$2=32,$H$2=64,$H$2=128,$H$2=256),0,1) -> -1 | K28: =J28*$J$2 -> -10 | M28: =IF(I28<>"",K28+I28+L28,0) -> 0
... A37: =M37 -> 0 | B37: =IF(H37>$H$2,"",(ROW()-5)) | H37: 32 | I37: =IF(H37<$H$2+1,($I$2-($I$2-1)*(LOG(H37)/LOG($H$2))),"") | J37: =INT(LOG($H$2,2))-ROUNDUP(LOG(H37,2),0)+IF(OR($H$2=1,$H$2=2,$H$2=4,$H$2=8,$H$2=16,$H$2=32,$H$2=64,$H$2=128,$H$2=256),0,1) -> -1 | K37: =J37*$J$2 -> -10 | M37: =IF(I37<>"",K37+I37+L37,0) -> 0
B38: =IF(H38>$H$2,"",(ROW()-5)) | H38: 33 | I38: =IF(H38<$H$2+1,($I$2-($I$2-1)*(LOG(H38)/LOG($H$2))),"") | J38: =INT(LOG($H$2,2))-ROUNDUP(LOG(H38,2),0)+IF(OR($H$2=1,$H$2=2,$H$2=4,$H$2=8,$H$2=16,$H$2=32,$H$2=64,$H$2=128,$H$2=256),0,1) -> -2 | K38: =J38*$J$2 -> -20 | M38: =IF(I38<>"",K38+I38+L38,0) -> 0
B39: =IF(H39>$H$2,"",(ROW()-5)) | H39: 34 | I39: =IF(H39<$H$2+1,($I$2-($I$2-1)*(LOG(H39)/LOG($H$2))),"") | J39: =INT(LOG($H$2,2))-ROUNDUP(LOG(H39,2),0)+IF(OR($H$2=1,$H$2=2,$H$2=4,$H$2=8,$H$2=16,$H$2=32,$H$2=64,$H$2=128,$H$2=256),0,1) -> -2 | K39: =J39*$J$2 -> -20 | M39: =IF(I39<>"",K39+I39+L39,0) -> 0
B40: =IF(H40>$H$2,"",(ROW()-5)) | H40: 35 | I40: =IF(H40<$H$2+1,($I$2-($I$2-1)*(LOG(H40)/LOG($H$2))),"") | J40: =INT(LOG($H$2,2))-ROUNDUP(LOG(H40,2),0)+IF(OR($H$2=1,$H$2=2,$H$2=4,$H$2=8,$H$2=16,$H$2=32,$H$2=64,$H$2=128,$H$2=256),0,1) -> -2 | K40: =J40*$J$2 -> -20 | M40: =IF(I40<>"",K40+I40+L40,0) -> 0
B41: =IF(H41>$H$2,"",(ROW()-5)) | H41: 36 | I41: =IF(H41<$H$2+1,($I$2-($I$2-1)*(LOG(H41)/LOG($H$2))),"") | J41: =INT(LOG($H$2,2))-ROUNDUP(LOG(H41,2),0)+IF(OR($H$2=1,$H$2=2,$H$2=4,$H$2=8,$H$2=16,$H$2=32,$H$2=64,$H$2=128,$H$2=256),0,1) -> -2 | K41: =J41*$J$2 -> -20 | M41: =IF(I41<>"",K41+I41+L41,0) -> 0
B42: =IF(H42>$H$2,"",(ROW()-5)) | H42: 37 | I42: =IF(H42<$H$2+1,($I$2-($I$2-1)*(LOG(H42)/LOG($H$2))),"") | J42: =INT(LOG($H$2,2))-ROUNDUP(LOG(H42,2),0)+IF(OR($H$2=1,$H$2=2,$H$2=4,$H$2=8,$H$2=16,$H$2=32,$H$2=64,$H$2=128,$H$2=256),0,1) -> -2 | K42: =J42*$J$2 -> -20 | M42: =IF(I42<>"",K42+I42+L42,0) -> 0
B43: =IF(H43>$H$2,"",(ROW()-5)) | H43: 38 | I43: =IF(H43<$H$2+1,($I$2-($I$2-1)*(LOG(H43)/LOG($H$2))),"") | J43: =INT(LOG($H$2,2))-ROUNDUP(LOG(H43,2),0)+IF(OR($H$2=1,$H$2=2,$H$2=4,$H$2=8,$H$2=16,$H$2=32,$H$2=64,$H$2=128,$H$2=256),0,1) -> -2 | K43: =J43*$J$2 -> -20 | M43: =IF(I43<>"",K43+I43+L43,0) -> 0
B44: =IF(H44>$H$2,"",(ROW()-5)) | H44: 39 | I44: =IF(H44<$H$2+1,($I$2-($I$2-1)*(LOG(H44)/LOG($H$2))),"") | J44: =INT(LOG($H$2,2))-ROUNDUP(LOG(H44,2),0)+IF(OR($H$2=1,$H$2=2,$H$2=4,$H$2=8,$H$2=16,$H$2=32,$H$2=64,$H$2=128,$H$2=256),0,1) -> -2 | K44: =J44*$J$2 -> -20 | M44: =IF(I44<>"",K44+I44+L44,0) -> 0
B45: =IF(H45>$H$2,"",(ROW()-5)) | H45: 40 | I45: =IF(H45<$H$2+1,($I$2-($I$2-1)*(LOG(H45)/LOG($H$2))),"") | J45: =INT(LOG($H$2,2))-ROUNDUP(LOG(H45,2),0)+IF(OR($H$2=1,$H$2=2,$H$2=4,$H$2=8,$H$2=16,$H$2=32,$H$2=64,$H$2=128,$H$2=256),0,1) -> -2 | K45: =J45*$J$2 -> -20 | M45: =IF(I45<>"",K45+I45+L45,0) -> 0
B46: =IF(H46>$H$2,"",(ROW()-5)) | H46: 41 | I46: =IF(H46<$H$2+1,($I$2-($I$2-1)*(LOG(H46)/LOG($H$2))),"") | J46: =INT(LOG($H$2,2))-ROUNDUP(LOG(H46,2),0)+IF(OR($H$2=1,$H$2=2,$H$2=4,$H$2=8,$H$2=16,$H$2=32,$H$2=64,$H$2=128,$H$2=256),0,1) -> -2 | K46: =J46*$J$2 -> -20 | M46: =IF(I46<>"",K46+I46+L46,0) -> 0 | R46: =LOG($H$2,2) -> 3.169925 | T46: =LOG(H38,2) -> 5.0443941 | U46: =R46-T46 -> -1.8744691
B47: =IF(H47>$H$2,"",(ROW()-5)) | H47: 42 | I47: =IF(H47<$H$2+1,($I$2-($I$2-1)*(LOG(H47)/LOG($H$2))),"") | J47: =INT(LOG($H$2,2))-ROUNDUP(LOG(H47,2),0)+IF(OR($H$2=1,$H$2=2,$H$2=4,$H$2=8,$H$2=16,$H$2=32,$H$2=64,$H$2=128,$H$2=256),0,1) -> -2 | K47: =J47*$J$2 -> -20 | M47: =IF(I47<>"",K47+I47+L47,0) -> 0
B48: =IF(H48>$H$2,"",(ROW()-5)) | H48: 43 | I48: =IF(H48<$H$2+1,($I$2-($I$2-1)*(LOG(H48)/LOG($H$2))),"") | J48: =INT(LOG($H$2,2))-ROUNDUP(LOG(H48,2),0)+IF(OR($H$2=1,$H$2=2,$H$2=4,$H$2=8,$H$2=16,$H$2=32,$H$2=64,$H$2=128,$H$2=256),0,1) -> -2 | K48: =J48*$J$2 -> -20 | M48: =IF(I48<>"",K48+I48+L48,0) -> 0
B49: =IF(H49>$H$2,"",(ROW()-5)) | H49: 44 | I49: =IF(H49<$H$2+1,($I$2-($I$2-1)*(LOG(H49)/LOG($H$2))),"") | J49: =INT(LOG($H$2,2))-ROUNDUP(LOG(H49,2),0)+IF(OR($H$2=1,$H$2=2,$H$2=4,$H$2=8,$H$2=16,$H$2=32,$H$2=64,$H$2=128,$H$2=256),0,1) -> -2 | K49: =J49*$J$2 -> -20 | M49: =IF(I49<>"",K49+I49+L49,0) -> 0
...

Sheet PP3
H1: Liczba uczestników: | I1: GP Punkty | J1: Bonus za rundę | K1: Mnożnik za podium
B2: miejsce: | C2: KRAKÓW | H2: 11 | I2: 50 | J2: 10 | K2: =3*H2^(1/3) -> 6.6719403
B3: data: | C3: 30.11.2024
A5: Punkty | B5: Miejsce Place | C5: Nazwisko Imię Name | D5: Klub Club(s) | E5: Okręg Division | F5: Państwo Country | H5: Miejsce | I5: Punkty za miejsce | J5: awans do kolejnej rundy pucharowej | K5: bonus za rundy pucharowe | L5: punkty za podium | M5: Suma
A6: =M6 -> 110.01582 | B6: =IF(H6>$H$2,"",(ROW()-5)) -> 1 | C6: KRZEMIŃSKI Mariusz | D6: KS AZS AWFIS GDAŃSK | E6: POL | H6: 1 | I6: =IF(H2=1,50,IF(H6<$H$2+1,($I$2-($I$2-1)*(LOG(H6)/LOG($H$2))),"")) -> 50 | J6: =INT(LOG($H$2,2))-ROUNDUP(LOG(H6,2),0)+IF(OR($H$2=1,$H$2=2,$H$2=4,$H$2=8,$H$2=16,$H$2=32,$H$2=64,$H$2=128,$H$2=256),0,1) -> 4 | K6: =J6*$J$2 -> 40 | L6: =3*K2 -> 20.015821 | M6: =IF(I6<>"",K6+I6+L6,0) -> 110.01582
A7: =M7 -> 79.179704 | B7: =IF(H7>$H$2,"",(ROW()-5)) -> 2 | C7: KOSTRZEWA Ireneusz | D7: KSz WARSZAWIANKA | E7: POL | H7: 2 | I7: =IF(H7<$H$2+1,($I$2-($I$2-1)*(LOG(H7)/LOG($H$2))),"") -> 35.835824 | J7: =INT(LOG($H$2,2))-ROUNDUP(LOG(H7,2),0)+IF(OR($H$2=1,$H$2=2,$H$2=4,$H$2=8,$H$2=16,$H$2=32,$H$2=64,$H$2=128,$H$2=256),0,1) -> 3 | K7: =J7*$J$2 -> 30 | L7: =2*K2 -> 13.343881 | M7: =IF(I7<>"",K7+I7+L7,0) -> 79.179704
A8: =M8 -> 54.222252 | B8: =IF(H8>$H$2,"",(ROW()-5)) -> 3 | C8: AUGUSTOWSKI Waldemar | D8: AZS AWF WROCŁAW | E8: POL | H8: 3 | I8: =IF(H8<$H$2+1,($I$2-($I$2-1)*(LOG(H8)/LOG($H$2))),"") -> 27.550311 | J8: =INT(LOG($H$2,2))-ROUNDUP(LOG(H8,2),0)+IF(OR($H$2=1,$H$2=2,$H$2=4,$H$2=8,$H$2=16,$H$2=32,$H$2=64,$H$2=128,$H$2=256),0,1) -> 2 | K8: =J8*$J$2 -> 20 | L8: =K2 -> 6.6719403 | M8: =IF(I8<>"",K8+I8+L8,0) -> 54.222252
A9: =M9 -> 41.671647 | B9: =IF(H9>$H$2,"",(ROW()-5)) -> 4 | C9: POKRZYWA MARIUSZ | D9: AZS AWF KRAKÓW | E9: POL | H9: 4 | I9: =IF(H9<$H$2+1,($I$2-($I$2-1)*(LOG(H9)/LOG($H$2))),"") -> 21.671647 | J9: =INT(LOG($H$2,2))-ROUNDUP(LOG(H9,2),0)+IF(OR($H$2=1,$H$2=2,$H$2=4,$H$2=8,$H$2=16,$H$2=32,$H$2=64,$H$2=128,$H$2=256),0,1) -> 2 | K9: =J9*$J$2 -> 20 | M9: =IF(I9<>"",K9+I9+L9,0) -> 41.671647 | AH9: x | AI9: 23
A10: =M10 -> 27.111801 | B10: =IF(H10>$H$2,"",(ROW()-5)) -> 5 | C10: DRAPELLA Maciej | D10: ST. POLSKICH WETERANÓW SZERMIERKI | E10: POL | H10: 5 | I10: =IF(H10<$H$2+1,($I$2-($I$2-1)*(LOG(H10)/LOG($H$2))),"") -> 17.111801 | J10: =INT(LOG($H$2,2))-ROUNDUP(LOG(H10,2),0)+IF(OR($H$2=1,$H$2=2,$H$2=4,$H$2=8,$H$2=16,$H$2=32,$H$2=64,$H$2=128,$H$2=256),0,1) -> 1 | K10: =J10*$J$2 -> 10 | M10: =IF(I10<>"",K10+I10+L10,0) -> 27.111801 | AH10: N | AI10: 45
A11: =M11 -> 23.386135 | B11: =IF(H11>$H$2,"",(ROW()-5)) -> 6 | C11: POPRAWA Mariusz | D11: UKS SOKOLIK MOSiR KROSNO | E11: POL | H11: 6 | I11: =IF(H11<$H$2+1,($I$2-($I$2-1)*(LOG(H11)/LOG($H$2))),"") -> 13.386135 | J11: =INT(LOG($H$2,2))-ROUNDUP(LOG(H11,2),0)+IF(OR($H$2=1,$H$2=2,$H$2=4,$H$2=8,$H$2=16,$H$2=32,$H$2=64,$H$2=128,$H$2=256),0,1) -> 1 | K11: =J11*$J$2 -> 10 | M11: =IF(I11<>"",K11+I11+L11,0) -> 23.386135 | AH11: MP | AI11: 50
A12: =M12 -> 20.236129 | B12: =IF(H12>$H$2,"",(ROW()-5)) -> 7 | C12: CHUDYCKI Artur | D12: MKS KUSY SZCZECIN | E12: POL | H12: 7 | I12: =IF(H12<$H$2+1,($I$2-($I$2-1)*(LOG(H12)/LOG($H$2))),"") -> 10.236129 | J12: =INT(LOG($H$2,2))-ROUNDUP(LOG(H12,2),0)+IF(OR($H$2=1,$H$2=2,$H$2=4,$H$2=8,$H$2=16,$H$2=32,$H$2=64,$H$2=128,$H$2=256),0,1) -> 1 | K12: =J12*$J$2 -> 10 | M12: =IF(I12<>"",K12+I12+L12,0) -> 20.236129 | AH12: MP-1 | AI12: =AI11-1 -> 49
A13: =M13 -> 17.507471 | B13: =IF(H13>$H$2,"",(ROW()-5)) -> 8 | C13: MAŁASIŃSKI Adam | D13: AZS AWF KRAKÓW | E13: POL | H13: 8 | I13: =IF(H13<$H$2+1,($I$2-($I$2-1)*(LOG(H13)/LOG($H$2))),"") -> 7.5074705 | J13: =INT(LOG($H$2,2))-ROUNDUP(LOG(H13,2),0)+IF(OR($H$2=1,$H$2=2,$H$2=4,$H$2=8,$H$2=16,$H$2=32,$H$2=64,$H$2=128,$H$2=256),0,1) -> 1 | K13: =J13*$J$2 -> 10 | M13: =IF(I13<>"",K13+I13+L13,0) -> 17.507471 | AH13: log(x) | AI13: =LOG(AI9) -> 1.3617278
A14: =M14 -> 5.1006228 | B14: =IF(H14>$H$2,"",(ROW()-5)) -> 9 | C14: NIKALAICHUK Aliaksandr | D14: AZS AWF KRAKÓW | E14: POL | H14: 9 | I14: =IF(H14<$H$2+1,($I$2-($I$2-1)*(LOG(H14)/LOG($H$2))),"") -> 5.1006228 | J14: =INT(LOG($H$2,2))-ROUNDUP(LOG(H14,2),0)+IF(OR($H$2=1,$H$2=2,$H$2=4,$H$2=8,$H$2=16,$H$2=32,$H$2=64,$H$2=128,$H$2=256),0,1) -> 0 | K14: =J14*$J$2 -> 0 | M14: =IF(I14<>"",K14+I14+L14,0) -> 5.1006228 | AH14: Log(N) | AI14: =LOG(AI10) -> 1.6532125
A15: =M15 -> 2.9476242 | B15: =IF(H15>$H$2,"",(ROW()-5)) -> 10 | C15: WRONA Grzegorz | D15: KKS KRAKÓW | E15: POL | H15: 10 | I15: =IF(H15<$H$2+1,($I$2-($I$2-1)*(LOG(H15)/LOG($H$2))),"") -> 2.9476242 | J15: =INT(LOG($H$2,2))-ROUNDUP(LOG(H15,2),0)+IF(OR($H$2=1,$H$2=2,$H$2=4,$H$2=8,$H$2=16,$H$2=32,$H$2=64,$H$2=128,$H$2=256),0,1) -> 0 | K15: =J15*$J$2 -> 0 | M15: =IF(I15<>"",K15+I15+L15,0) -> 2.9476242
A16: =M16 -> 1 | B16: =IF(H16>$H$2,"",(ROW()-5)) -> 11 | C16: PYZIK Zdzisław | D16: KSz WARSZAWIANKA | E16: POL | H16: 11 | I16: =IF(H16<$H$2+1,($I$2-($I$2-1)*(LOG(H16)/LOG($H$2))),"") -> 1 | J16: =INT(LOG($H$2,2))-ROUNDUP(LOG(H16,2),0)+IF(OR($H$2=1,$H$2=2,$H$2=4,$H$2=8,$H$2=16,$H$2=32,$H$2=64,$H$2=128,$H$2=256),0,1) -> 0 | K16: =J16*$J$2 -> 0 | M16: =IF(I16<>"",K16+I16+L16,0) -> 1 | AH16: MP - (MP-1)*LOG(x)/LOG(N) | AI16: =AI11-AI12*AI13/AI14 -> 9.6393909 | AJ16: points
A17: =M17 -> 0 | B17: =IF(H17>$H$2,"",(ROW()-5)) | H17: 12 | I17: =IF(H17<$H$2+1,($I$2-($I$2-1)*(LOG(H17)/LOG($H$2))),"") | J17: =INT(LOG($H$2,2))-ROUNDUP(LOG(H17,2),0)+IF(OR($H$2=1,$H$2=2,$H$2=4,$H$2=8,$H$2=16,$H$2=32,$H$2=64,$H$2=128,$H$2=256),0,1) -> 0 | K17: =J17*$J$2 -> 0 | M17: =IF(I17<>"",K17+I17+L17,0) -> 0
A18: =M18 -> 0 | B18: =IF(H18>$H$2,"",(ROW()-5)) | H18: 13 | I18: =IF(H18<$H$2+1,($I$2-($I$2-1)*(LOG(H18)/LOG($H$2))),"") | J18: =INT(LOG($H$2,2))-ROUNDUP(LOG(H18,2),0)+IF(OR($H$2=1,$H$2=2,$H$2=4,$H$2=8,$H$2=16,$H$2=32,$H$2=64,$H$2=128,$H$2=256),0,1) -> 0 | K18: =J18*$J$2 -> 0 | M18: =IF(I18<>"",K18+I18+L18,0) -> 0
A19: =M19 -> 0 | B19: =IF(H19>$H$2,"",(ROW()-5)) | H19: 14 | I19: =IF(H19<$H$2+1,($I$2-($I$2-1)*(LOG(H19)/LOG($H$2))),"") | J19: =INT(LOG($H$2,2))-ROUNDUP(LOG(H19,2),0)+IF(OR($H$2=1,$H$2=2,$H$2=4,$H$2=8,$H$2=16,$H$2=32,$H$2=64,$H$2=128,$H$2=256),0,1) -> 0 | K19: =J19*$J$2 -> 0 | M19: =IF(I19<>"",K19+I19+L19,0) -> 0
A20: =M20 -> 0 | B20: =IF(H20>$H$2,"",(ROW()-5)) | H20: 15 | I20: =IF(H20<$H$2+1,($I$2-($I$2-1)*(LOG(H20)/LOG($H$2))),"") | J20: =INT(LOG($H$2,2))-ROUNDUP(LOG(H20,2),0)+IF(OR($H$2=1,$H$2=2,$H$2=4,$H$2=8,$H$2=16,$H$2=32,$H$2=64,$H$2=128,$H$2=256),0,1) -> 0 | K20: =J20*$J$2 -> 0 | M20: =IF(I20<>"",K20+I20+L20,0) -> 0
A21: =M21 -> 0 | B21: =IF(H21>$H$2,"",(ROW()-5)) | H21: 16 | I21: =IF(H21<$H$2+1,($I$2-($I$2-1)*(LOG(H21)/LOG($H$2))),"") | J21: =INT(LOG($H$2,2))-ROUNDUP(LOG(H21,2),0)+IF(OR($H$2=1,$H$2=2,$H$2=4,$H$2=8,$H$2=16,$H$2=32,$H$2=64,$H$2=128,$H$2=256),0,1) -> 0 | K21: =J21*$J$2 -> 0 | M21: =IF(I21<>"",K21+I21+L21,0) -> 0
A22: =M22 -> 0 | B22: =IF(H22>$H$2,"",(ROW()-5)) | H22: 17 | I22: =IF(H22<$H$2+1,($I$2-($I$2-1)*(LOG(H22)/LOG($H$2))),"") | J22: =INT(LOG($H$2,2))-ROUNDUP(LOG(H22,2),0)+IF(OR($H$2=1,$H$2=2,$H$2=4,$H$2=8,$H$2=16,$H$2=32,$H$2=64,$H$2=128,$H$2=256),0,1) -> -1 | K22: =J22*$J$2 -> -10 | M22: =IF(I22<>"",K22+I22+L22,0) -> 0
A23: =M23 -> 0 | B23: =IF(H23>$H$2,"",(ROW()-5)) | H23: 18 | I23: =IF(H23<$H$2+1,($I$2-($I$2-1)*(LOG(H23)/LOG($H$2))),"") | J23: =INT(LOG($H$2,2))-ROUNDUP(LOG(H23,2),0)+IF(OR($H$2=1,$H$2=2,$H$2=4,$H$2=8,$H$2=16,$H$2=32,$H$2=64,$H$2=128,$H$2=256),0,1) -> -1 | K23: =J23*$J$2 -> -10 | M23: =IF(I23<>"",K23+I23+L23,0) -> 0
A24: =M24 -> 0 | B24: =IF(H24>$H$2,"",(ROW()-5)) | H24: 19 | I24: =IF(H24<$H$2+1,($I$2-($I$2-1)*(LOG(H24)/LOG($H$2))),"") | J24: =INT(LOG($H$2,2))-ROUNDUP(LOG(H24,2),0)+IF(OR($H$2=1,$H$2=2,$H$2=4,$H$2=8,$H$2=16,$H$2=32,$H$2=64,$H$2=128,$H$2=256),0,1) -> -1 | K24: =J24*$J$2 -> -10 | M24: =IF(I24<>"",K24+I24+L24,0) -> 0
A25: =M25 -> 0 | B25: =IF(H25>$H$2,"",(ROW()-5)) | H25: 20 | I25: =IF(H25<$H$2+1,($I$2-($I$2-1)*(LOG(H25)/LOG($H$2))),"") | J25: =INT(LOG($H$2,2))-ROUNDUP(LOG(H25,2),0)+IF(OR($H$2=1,$H$2=2,$H$2=4,$H$2=8,$H$2=16,$H$2=32,$H$2=64,$H$2=128,$H$2=256),0,1) -> -1 | K25: =J25*$J$2 -> -10 | M25: =IF(I25<>"",K25+I25+L25,0) -> 0
A26: =M26 -> 0 | B26: =IF(H26>$H$2,"",(ROW()-5)) | H26: 21 | I26: =IF(H26<$H$2+1,($I$2-($I$2-1)*(LOG(H26)/LOG($H$2))),"") | J26: =INT(LOG($H$2,2))-ROUNDUP(LOG(H26,2),0)+IF(OR($H$2=1,$H$2=2,$H$2=4,$H$2=8,$H$2=16,$H$2=32,$H$2=64,$H$2=128,$H$2=256),0,1) -> -1 | K26: =J26*$J$2 -> -10 | M26: =IF(I26<>"",K26+I26+L26,0) -> 0
A27: =M27 -> 0 | B27: =IF(H27>$H$2,"",(ROW()-5)) | H27: 22 | I27: =IF(H27<$H$2+1,($I$2-($I$2-1)*(LOG(H27)/LOG($H$2))),"") | J27: =INT(LOG($H$2,2))-ROUNDUP(LOG(H27,2),0)+IF(OR($H$2=1,$H$2=2,$H$2=4,$H$2=8,$H$2=16,$H$2=32,$H$2=64,$H$2=128,$H$2=256),0,1) -> -1 | K27: =J27*$J$2 -> -10 | M27: =IF(I27<>"",K27+I27+L27,0) -> 0
A28: =M28 -> 0 | B28: =IF(H28>$H$2,"",(ROW()-5)) | H28: 23 | I28: =IF(H28<$H$2+1,($I$2-($I$2-1)*(LOG(H28)/LOG($H$2))),"") | J28: =INT(LOG($H$2,2))-ROUNDUP(LOG(H28,2),0)+IF(OR($H$2=1,$H$2=2,$H$2=4,$H$2=8,$H$2=16,$H$2=32,$H$2=64,$H$2=128,$H$2=256),0,1) -> -1 | K28: =J28*$J$2 -> -10 | M28: =IF(I28<>"",K28+I28+L28,0) -> 0
... A37: =M37 -> 0 | B37: =IF(H37>$H$2,"",(ROW()-5)) | H37: 32 | I37: =IF(H37<$H$2+1,($I$2-($I$2-1)*(LOG(H37)/LOG($H$2))),"") | J37: =INT(LOG($H$2,2))-ROUNDUP(LOG(H37,2),0)+IF(OR($H$2=1,$H$2=2,$H$2=4,$H$2=8,$H$2=16,$H$2=32,$H$2=64,$H$2=128,$H$2=256),0,1) -> -1 | K37: =J37*$J$2 -> -10 | M37: =IF(I37<>"",K37+I37+L37,0) -> 0
B38: =IF(H38>$H$2,"",(ROW()-5)) | H38: 33 | I38: =IF(H38<$H$2+1,($I$2-($I$2-1)*(LOG(H38)/LOG($H$2))),"") | J38: =INT(LOG($H$2,2))-ROUNDUP(LOG(H38,2),0)+IF(OR($H$2=1,$H$2=2,$H$2=4,$H$2=8,$H$2=16,$H$2=32,$H$2=64,$H$2=128,$H$2=256),0,1) -> -2 | K38: =J38*$J$2 -> -20 | M38: =IF(I38<>"",K38+I38+L38,0) -> 0
B39: =IF(H39>$H$2,"",(ROW()-5)) | H39: 34 | I39: =IF(H39<$H$2+1,($I$2-($I$2-1)*(LOG(H39)/LOG($H$2))),"") | J39: =INT(LOG($H$2,2))-ROUNDUP(LOG(H39,2),0)+IF(OR($H$2=1,$H$2=2,$H$2=4,$H$2=8,$H$2=16,$H$2=32,$H$2=64,$H$2=128,$H$2=256),0,1) -> -2 | K39: =J39*$J$2 -> -20 | M39: =IF(I39<>"",K39+I39+L39,0) -> 0
B40: =IF(H40>$H$2,"",(ROW()-5)) | H40: 35 | I40: =IF(H40<$H$2+1,($I$2-($I$2-1)*(LOG(H40)/LOG($H$2))),"") | J40: =INT(LOG($H$2,2))-ROUNDUP(LOG(H40,2),0)+IF(OR($H$2=1,$H$2=2,$H$2=4,$H$2=8,$H$2=16,$H$2=32,$H$2=64,$H$2=128,$H$2=256),0,1) -> -2 | K40: =J40*$J$2 -> -20 | M40: =IF(I40<>"",K40+I40+L40,0) -> 0
B41: =IF(H41>$H$2,"",(ROW()-5)) | H41: 36 | I41: =IF(H41<$H$2+1,($I$2-($I$2-1)*(LOG(H41)/LOG($H$2))),"") | J41: =INT(LOG($H$2,2))-ROUNDUP(LOG(H41,2),0)+IF(OR($H$2=1,$H$2=2,$H$2=4,$H$2=8,$H$2=16,$H$2=32,$H$2=64,$H$2=128,$H$2=256),0,1) -> -2 | K41: =J41*$J$2 -> -20 | M41: =IF(I41<>"",K41+I41+L41,0) -> 0
B42: =IF(H42>$H$2,"",(ROW()-5)) | H42: 37 | I42: =IF(H42<$H$2+1,($I$2-($I$2-1)*(LOG(H42)/LOG($H$2))),"") | J42: =INT(LOG($H$2,2))-ROUNDUP(LOG(H42,2),0)+IF(OR($H$2=1,$H$2=2,$H$2=4,$H$2=8,$H$2=16,$H$2=32,$H$2=64,$H$2=128,$H$2=256),0,1) -> -2 | K42: =J42*$J$2 -> -20 | M42: =IF(I42<>"",K42+I42+L42,0) -> 0
B43: =IF(H43>$H$2,"",(ROW()-5)) | H43: 38 | I43: =IF(H43<$H$2+1,($I$2-($I$2-1)*(LOG(H43)/LOG($H$2))),"") | J43: =INT(LOG($H$2,2))-ROUNDUP(LOG(H43,2),0)+IF(OR($H$2=1,$H$2=2,$H$2=4,$H$2=8,$H$2=16,$H$2=32,$H$2=64,$H$2=128,$H$2=256),0,1) -> -2 | K43: =J43*$J$2 -> -20 | M43: =IF(I43<>"",K43+I43+L43,0) -> 0
B44: =IF(H44>$H$2,"",(ROW()-5)) | H44: 39 | I44: =IF(H44<$H$2+1,($I$2-($I$2-1)*(LOG(H44)/LOG($H$2))),"") | J44: =INT(LOG($H$2,2))-ROUNDUP(LOG(H44,2),0)+IF(OR($H$2=1,$H$2=2,$H$2=4,$H$2=8,$H$2=16,$H$2=32,$H$2=64,$H$2=128,$H$2=256),0,1) -> -2 | K44: =J44*$J$2 -> -20 | M44: =IF(I44<>"",K44+I44+L44,0) -> 0
B45: =IF(H45>$H$2,"",(ROW()-5)) | H45: 40 | I45: =IF(H45<$H$2+1,($I$2-($I$2-1)*(LOG(H45)/LOG($H$2))),"") | J45: =INT(LOG($H$2,2))-ROUNDUP(LOG(H45,2),0)+IF(OR($H$2=1,$H$2=2,$H$2=4,$H$2=8,$H$2=16,$H$2=32,$H$2=64,$H$2=128,$H$2=256),0,1) -> -2 | K45: =J45*$J$2 -> -20 | M45: =IF(I45<>"",K45+I45+L45,0) -> 0
B46: =IF(H46>$H$2,"",(ROW()-5)) | H46: 41 | I46: =IF(H46<$H$2+1,($I$2-($I$2-1)*(LOG(H46)/LOG($H$2))),"") | J46: =INT(LOG($H$2,2))-ROUNDUP(LOG(H46,2),0)+IF(OR($H$2=1,$H$2=2,$H$2=4,$H$2=8,$H$2=16,$H$2=32,$H$2=64,$H$2=128,$H$2=256),0,1) -> -2 | K46: =J46*$J$2 -> -20 | M46: =IF(I46<>"",K46+I46+L46,0) -> 0 | R46: =LOG($H$2,2) -> 3.4594316 | T46: =LOG(H38,2) -> 5.0443941 | U46: =R46-T46 -> -1.5849625
B47: =IF(H47>$H$2,"",(ROW()-5)) | H47: 42 | I47: =IF(H47<$H$2+1,($I$2-($I$2-1)*(LOG(H47)/LOG($H$2))),"") | J47: =INT(LOG($H$2,2))-ROUNDUP(LOG(H47,2),0)+IF(OR($H$2=1,$H$2=2,$H$2=4,$H$2=8,$H$2=16,$H$2=32,$H$2=64,$H$2=128,$H$2=256),0,1) -> -2 | K47: =J47*$J$2 -> -20 | M47: =IF(I47<>"",K47+I47+L47,0) -> 0
B48: =IF(H48>$H$2,"",(ROW()-5)) | H48: 43 | I48: =IF(H48<$H$2+1,($I$2-($I$2-1)*(LOG(H48)/LOG($H$2))),"") | J48: =INT(LOG($H$2,2))-ROUNDUP(LOG(H48,2),0)+IF(OR($H$2=1,$H$2=2,$H$2=4,$H$2=8,$H$2=16,$H$2=32,$H$2=64,$H$2=128,$H$2=256),0,1) -> -2 | K48: =J48*$J$2 -> -20 | M48: =IF(I48<>"",K48+I48+L48,0) -> 0
B49: =IF(H49>$H$2,"",(ROW()-5)) | H49: 44 | I49: =IF(H49<$H$2+1,($I$2-($I$2-1)*(LOG(H49)/LOG($H$2))),"") | J49: =INT(LOG($H$2,2))-ROUNDUP(LOG(H49,2),0)+IF(OR($H$2=1,$H$2=2,$H$2=4,$H$2=8,$H$2=16,$H$2=32,$H$2=64,$H$2=128,$H$2=256),0,1) -> -2 | K49: =J49*$J$2 -> -20 | M49: =IF(I49<>"",K49+I49+L49,0) -> 0
...

Sheet PP4
H1: Liczba uczestników: | I1: GP Punkty | J1: Bonus za rundę | K1: Mnożnik za podium
B2: miejsce: | C2: WARSZAWA | H2: 9 | I2: 50 | J2: 10 | K2: =3*H2^(1/3) -> 6.2402515
B3: data: | C3: 22.02.2025
A5: Punkty | B5: Miejsce Place | C5: Nazwisko Imię Name | D5: Klub Club(s) | E5: Okręg Division | F5: Państwo Country | H5: Miejsce | I5: Punkty za miejsce | J5: awans do kolejnej rundy pucharowej | K5: bonus za rundy pucharowe | L5: punkty za podium | M5: Suma
A6: =M6 -> 108.72075 | B6: =IF(H6>$H$2,"",(ROW()-5)) -> 1 | C6: KRZEMIŃSKI Mariusz | D6: KS AZS AWFIS GDAŃSK | E6: POL | H6: 1 | I6: =IF(H2=1,50,IF(H6<$H$2+1,($I$2-($I$2-1)*(LOG(H6)/LOG($H$2))),"")) -> 50 | J6: =INT(LOG($H$2,2))-ROUNDUP(LOG(H6,2),0)+IF(OR($H$2=1,$H$2=2,$H$2=4,$H$2=8,$H$2=16,$H$2=32,$H$2=64,$H$2=128,$H$2=256),0,1) -> 4 | K6: =J6*$J$2 -> 40 | L6: =3*K2 -> 18.720754 | M6: =IF(I6<>"",K6+I6+L6,0) -> 108.72075
