Workbook

Sheet Ranking
B2: Dołączył/a do kategorii w tym roku | D2: Ranking Grand Prix Pucharu Polski Weteranów (PPW) za 2023 rok | R2: Na sumę punktów w rankingu skłądają się 4 najlepsze wyniki (z 5 możliwych) w turniejach GP PPW oraz wynik z Mistrzostw Polski Weteranów.
D3: KOBIETY Kat.2
A4: L.P. | B4: NAZWISKO Imię | C4: KLUB | D4: PUNKTY | E4: I GP | G4: II GP | I4: III GP | K4: IV GP | M4: V GP | O4: MPW
E5: M | F5: P | G5: M | H5: P | I5: M | J5: P | K5: M | L5: P | M5: M | N5: P | O5: M | P5: P
A6: =ROW()-5 -> 1 | B6: GANSZCZYK Anna | D6: =SUM(F6,H6,J6,L6,N6,P6)-MIN(F6,H6,J6,L6,N6) -> 366.6001 | E6: =_xlfn.XLOOKUP($B6,'GP1'!$C$6:$C$101,'GP1'!$B$6:$B$101,"") -> 1 | F6: =_xlfn.XLOOKUP(E6,'GP1'!$B$6:$B$55,'GP1'!$A$6:$A$55,0) -> 82.980246 | G6: =_xlfn.XLOOKUP($B6,'GP2'!$C$6:$C$101,'GP2'!$B$6:$B$101,"") -> 1 | H6: =_xlfn.XLOOKUP(G6,'GP2'!$B$6:$B$55,'GP2'!$A$6:$A$55,0) -> 82.980246 | I6: =_xlfn.XLOOKUP($B6,'GP3'!$C$6:$C$101,'GP3'!$B$6:$B$101,"") -> 1 | J6: =_xlfn.XLOOKUP(I6,'GP3'!$B$6:$B$55,'GP3'!$A$6:$A$55,0) -> 96.354085 | K6: =_xlfn.XLOOKUP($B6,'GP4'!$C$6:$C$101,'GP4'!$B$6:$B$101,"") -> 2 | L6: =_xlfn.XLOOKUP(K6,'GP4'!$B$6:$B$55,'GP4'!$A$6:$A$55,0) -> 37.737939 | M6: =_xlfn.XLOOKUP($B6,'GP5'!$C$6:$C$101,'GP5'!$B$6:$B$101,"") -> 1 | N6: =_xlfn.XLOOKUP(M6,'GP5'!$B$6:$B$55,'GP5'!$A$6:$A$55,0) -> 59 | O6: =_xlfn.XLOOKUP(B6,MPW!C$6:C$101,MPW!B$6:B$101,"") -> 2 | P6: =_xlfn.XLOOKUP(O6,MPW!$B$6:$B$55,MPW!$A$6:$A$55,0) -> 45.285527
A7: =ROW()-5 -> 2 | B7: WASILCZUK Beata | D7: =SUM(F7,H7,J7,L7,N7,P7)-MIN(F7,H7,J7,L7,N7) -> 282.24142 | E7: =_xlfn.XLOOKUP($B7,'GP1'!$C$6:$C$101,'GP1'!$B$6:$B$101,"") | F7: =_xlfn.XLOOKUP(E7,'GP1'!$B$6:$B$55,'GP1'!$A$6:$A$55,0) -> 0 | G7: =_xlfn.XLOOKUP($B7,'GP2'!$C$6:$C$101,'GP2'!$B$6:$B$101,"") -> 2 | H7: =_xlfn.XLOOKUP(G7,'GP2'!$B$6:$B$55,'GP2'!$A$6:$A$55,0) -> 37.737939 | I7: =_xlfn.XLOOKUP($B7,'GP3'!$C$6:$C$101,'GP3'!$B$6:$B$101,"") -> 2 | J7: =_xlfn.XLOOKUP(I7,'GP3'!$B$6:$B$55,'GP3'!$A$6:$A$55,0) -> 61.946936 | K7: =_xlfn.XLOOKUP($B7,'GP4'!$C$6:$C$101,'GP4'!$B$6:$B$101,"") -> 1 | L7: =_xlfn.XLOOKUP(K7,'GP4'!$B$6:$B$55,'GP4'!$A$6:$A$55,0) -> 82.980246 | M7: =_xlfn.XLOOKUP($B7,'GP5'!$C$6:$C$101,'GP5'!$B$6:$B$101,"") | N7: =_xlfn.XLOOKUP(M7,'GP5'!$B$6:$B$55,'GP5'!$A$6:$A$55,0) -> 0 | O7: =_xlfn.XLOOKUP(B7,MPW!C$6:C$101,MPW!B$6:B$101,"") -> 1 | P7: =_xlfn.XLOOKUP(O7,MPW!$B$6:$B$55,MPW!$A$6:$A$55,0) -> 99.576295
A8: =ROW()-5 -> 3 | B8: POJMAŃSKA Katarzyna | D8: =SUM(F8,H8,J8,L8,N8,P8)-MIN(F8,H8,J8,L8,N8) -> 37.737939 | E8: =_xlfn.XLOOKUP($B8,'GP1'!$C$6:$C$101,'GP1'!$B$6:$B$101,"") -> 2 | F8: =_xlfn.XLOOKUP(E8,'GP1'!$B$6:$B$55,'GP1'!$A$6:$A$55,0) -> 37.737939 | G8: =_xlfn.XLOOKUP($B8,'GP2'!$C$6:$C$101,'GP2'!$B$6:$B$101,"") | H8: =_xlfn.XLOOKUP(G8,'GP2'!$B$6:$B$55,'GP2'!$A$6:$A$55,0) -> 0 | I8: =_xlfn.XLOOKUP($B8,'GP3'!$C$6:$C$101,'GP3'!$B$6:$B$101,"") | J8: =_xlfn.XLOOKUP(I8,'GP3'!$B$6:$B$55,'GP3'!$A$6:$A$55,0) -> 0 | K8: =_xlfn.XLOOKUP($B8,'GP4'!$C$6:$C$101,'GP4'!$B$6:$B$101,"") | L8: =_xlfn.XLOOKUP(K8,'GP4'!$B$6:$B$55,'GP4'!$A$6:$A$55,0) -> 0 | M8: =_xlfn.XLOOKUP($B8,'GP5'!$C$6:$C$101,'GP5'!$B$6:$B$101,"") | N8: =_xlfn.XLOOKUP(M8,'GP5'!$B$6:$B$55,'GP5'!$A$6:$A$55,0) -> 0 | O8: =_xlfn.XLOOKUP(B8,MPW!C$6:C$101,MPW!B$6:B$101,"") | P8: =_xlfn.XLOOKUP(O8,MPW!$B$6:$B$55,MPW!$A$6:$A$55,0) -> 0
A9: =ROW()-5 -> 4 | B9: MILOVA Tatiana | D9: =SUM(F9,H9,J9,L9,N9,P9)-MIN(F9,H9,J9,L9,N9) -> 35.407149 | E9: =_xlfn.XLOOKUP($B9,'GP1'!$C$6:$C$101,'GP1'!$B$6:$B$101,"") | F9: =_xlfn.XLOOKUP(E9,'GP1'!$B$6:$B$55,'GP1'!$A$6:$A$55,0) -> 0 | G9: =_xlfn.XLOOKUP($B9,'GP2'!$C$6:$C$101,'GP2'!$B$6:$B$101,"") | H9: =_xlfn.XLOOKUP(G9,'GP2'!$B$6:$B$55,'GP2'!$A$6:$A$55,0) -> 0 | I9: =_xlfn.XLOOKUP($B9,'GP3'!$C$6:$C$101,'GP3'!$B$6:$B$101,"") -> 3 | J9: =_xlfn.XLOOKUP(I9,'GP3'!$B$6:$B$55,'GP3'!$A$6:$A$55,0) -> 35.407149 | K9: =_xlfn.XLOOKUP($B9,'GP4'!$C$6:$C$101,'GP4'!$B$6:$B$101,"") | L9: =_xlfn.XLOOKUP(K9,'GP4'!$B$6:$B$55,'GP4'!$A$6:$A$55,0) -> 0 | M9: =_xlfn.XLOOKUP($B9,'GP5'!$C$6:$C$101,'GP5'!$B$6:$B$101,"") | N9: =_xlfn.XLOOKUP(M9,'GP5'!$B$6:$B$55,'GP5'!$A$6:$A$55,0) -> 0 | O9: =_xlfn.XLOOKUP(B9,MPW!C$6:C$101,MPW!B$6:B$101,"") | P9: =_xlfn.XLOOKUP(O9,MPW!$B$6:$B$55,MPW!$A$6:$A$55,0) -> 0
A10: =ROW()-5 -> 5 | B10: SADOWIŃSKA Adriana | D10: =SUM(F10,H10,J10,L10,N10,P10)-MIN(F10,H10,J10,L10,N10) -> 33.807272 | E10: =_xlfn.XLOOKUP($B10,'GP1'!$C$6:$C$101,'GP1'!$B$6:$B$101,"") | F10: =_xlfn.XLOOKUP(E10,'GP1'!$B$6:$B$55,'GP1'!$A$6:$A$55,0) -> 0 | G10: =_xlfn.XLOOKUP($B10,'GP2'!$C$6:$C$101,'GP2'!$B$6:$B$101,"") | H10: =_xlfn.XLOOKUP(G10,'GP2'!$B$6:$B$55,'GP2'!$A$6:$A$55,0) -> 0 | I10: =_xlfn.XLOOKUP($B10,'GP3'!$C$6:$C$101,'GP3'!$B$6:$B$101,"") -> 4 | J10: =_xlfn.XLOOKUP(I10,'GP3'!$B$6:$B$55,'GP3'!$A$6:$A$55,0) -> 22.088425 | K10: =_xlfn.XLOOKUP($B10,'GP4'!$C$6:$C$101,'GP4'!$B$6:$B$101,"") -> 3 | L10: =_xlfn.XLOOKUP(K10,'GP4'!$B$6:$B$55,'GP4'!$A$6:$A$55,0) -> 5.3267487 | M10: =_xlfn.XLOOKUP($B10,'GP5'!$C$6:$C$101,'GP5'!$B$6:$B$101,"") | N10: =_xlfn.XLOOKUP(M10,'GP5'!$B$6:$B$55,'GP5'!$A$6:$A$55,0) -> 0 | O10: =_xlfn.XLOOKUP(B10,MPW!C$6:C$101,MPW!B$6:B$101,"") -> 3 | P10: =_xlfn.XLOOKUP(O10,MPW!$B$6:$B$55,MPW!$A$6:$A$55,0) -> 6.3920985
A11: =ROW()-5 -> 6 | B11: WALECKA Wanda | D11: =SUM(F11,H11,J11,L11,N11,P11)-MIN(F11,H11,J11,L11,N11) -> 33.110868 | E11: =_xlfn.XLOOKUP($B11,'GP1'!$C$6:$C$101,'GP1'!$B$6:$B$101,"") -> 3 | F11: =_xlfn.XLOOKUP(E11,'GP1'!$B$6:$B$55,'GP1'!$A$6:$A$55,0) -> 5.3267487 | G11: =_xlfn.XLOOKUP($B11,'GP2'!$C$6:$C$101,'GP2'!$B$6:$B$101,"") -> 3 | H11: =_xlfn.XLOOKUP(G11,'GP2'!$B$6:$B$55,'GP2'!$A$6:$A$55,0) -> 5.3267487 | I11: =_xlfn.XLOOKUP($B11,'GP3'!$C$6:$C$101,'GP3'!$B$6:$B$101,"") -> 5 | J11: =_xlfn.XLOOKUP(I11,'GP3'!$B$6:$B$55,'GP3'!$A$6:$A$55,0) -> 1 | K11: =_xlfn.XLOOKUP($B11,'GP4'!$C$6:$C$101,'GP4'!$B$6:$B$101,"") -> 3k1 | L11: =_xlfn.XLOOKUP(K11,'GP4'!$B$6:$B$55,'GP4'!$A$6:$A$55,0) -> 5.3267487 | M11: =_xlfn.XLOOKUP($B11,'GP5'!$C$6:$C$101,'GP5'!$B$6:$B$101,"") -> 3k1 | N11: =_xlfn.XLOOKUP(M11,'GP5'!$B$6:$B$55,'GP5'!$A$6:$A$55,0) -> 15.930622 | O11: =_xlfn.XLOOKUP(B11,MPW!C$6:C$101,MPW!B$6:B$101,"") -> 6k1 | P11: =_xlfn.XLOOKUP(O11,MPW!$B$6:$B$55,MPW!$A$6:$A$55,0) -> 1.2
A12: =ROW()-5 -> 7 | B12: FITKEVICIENE Audrone | D12: =SUM(F12,H12,J12,L12,N12,P12)-MIN(F12,H12,J12,L12,N12) -> 0 | E12: =_xlfn.XLOOKUP($B12,'GP1'!$C$6:$C$101,'GP1'!$B$6:$B$101,"") | F12: =_xlfn.XLOOKUP(E12,'GP1'!$B$6:$B$55,'GP1'!$A$6:$A$55,0) -> 0 | G12: =_xlfn.XLOOKUP($B12,'GP2'!$C$6:$C$101,'GP2'!$B$6:$B$101,"") | H12: =_xlfn.XLOOKUP(G12,'GP2'!$B$6:$B$55,'GP2'!$A$6:$A$55,0) -> 0 | I12: =_xlfn.XLOOKUP($B12,'GP3'!$C$6:$C$101,'GP3'!$B$6:$B$101,"") | J12: =_xlfn.XLOOKUP(I12,'GP3'!$B$6:$B$55,'GP3'!$A$6:$A$55,0) -> 0 | K12: =_xlfn.XLOOKUP($B12,'GP4'!$C$6:$C$101,'GP4'!$B$6:$B$101,"") | L12: =_xlfn.XLOOKUP(K12,'GP4'!$B$6:$B$55,'GP4'!$A$6:$A$55,0) -> 0 | M12: =_xlfn.XLOOKUP($B12,'GP5'!$C$6:$C$101,'GP5'!$B$6:$B$101,"") | N12: =_xlfn.XLOOKUP(M12,'GP5'!$B$6:$B$55,'GP5'!$A$6:$A$55,0) -> 0 | O12: =_xlfn.XLOOKUP(B12,MPW!C$6:C$101,MPW!B$6:B$101,"") | P12: =_xlfn.XLOOKUP(O12,MPW!$B$6:$B$55,MPW!$A$6:$A$55,0) -> 0
A13: =ROW()-5 -> 8 | B13: KARMAN Irene | D13: =SUM(F13,H13,J13,L13,N13,P13)-MIN(F13,H13,J13,L13,N13) -> 0 | E13: =_xlfn.XLOOKUP($B13,'GP1'!$C$6:$C$101,'GP1'!$B$6:$B$101,"") | F13: =_xlfn.XLOOKUP(E13,'GP1'!$B$6:$B$55,'GP1'!$A$6:$A$55,0) -> 0 | G13: =_xlfn.XLOOKUP($B13,'GP2'!$C$6:$C$101,'GP2'!$B$6:$B$101,"") | H13: =_xlfn.XLOOKUP(G13,'GP2'!$B$6:$B$55,'GP2'!$A$6:$A$55,0) -> 0 | I13: =_xlfn.XLOOKUP($B13,'GP3'!$C$6:$C$101,'GP3'!$B$6:$B$101,"") | J13: =_xlfn.XLOOKUP(I13,'GP3'!$B$6:$B$55,'GP3'!$A$6:$A$55,0) -> 0 | K13: =_xlfn.XLOOKUP($B13,'GP4'!$C$6:$C$101,'GP4'!$B$6:$B$101,"") | L13: =_xlfn.XLOOKUP(K13,'GP4'!$B$6:$B$55,'GP4'!$A$6:$A$55,0) -> 0 | M13: =_xlfn.XLOOKUP($B13,'GP5'!$C$6:$C$101,'GP5'!$B$6:$B$101,"") | N13: =_xlfn.XLOOKUP(M13,'GP5'!$B$6:$B$55,'GP5'!$A$6:$A$55,0) -> 0 | O13: =_xlfn.XLOOKUP(B13,MPW!C$6:C$101,MPW!B$6:B$101,"") | P13: =_xlfn.XLOOKUP(O13,MPW!$B$6:$B$55,MPW!$A$6:$A$55,0) -> 0
A14: =ROW()-5 -> 9 | B14: BEDNARSKA Halina | D14: =SUM(F14,H14,J14,L14,N14,P14)-MIN(F14,H14,J14,L14,N14) -> 0 | E14: =_xlfn.XLOOKUP($B14,'GP1'!$C$6:$C$101,'GP1'!$B$6:$B$101,"") | F14: =_xlfn.XLOOKUP(E14,'GP1'!$B$6:$B$55,'GP1'!$A$6:$A$55,0) -> 0 | G14: =_xlfn.XLOOKUP($B14,'GP2'!$C$6:$C$101,'GP2'!$B$6:$B$101,"") | H14: =_xlfn.XLOOKUP(G14,'GP2'!$B$6:$B$55,'GP2'!$A$6:$A$55,0) -> 0 | I14: =_xlfn.XLOOKUP($B14,'GP3'!$C$6:$C$101,'GP3'!$B$6:$B$101,"") | J14: =_xlfn.XLOOKUP(I14,'GP3'!$B$6:$B$55,'GP3'!$A$6:$A$55,0) -> 0 | K14: =_xlfn.XLOOKUP($B14,'GP4'!$C$6:$C$101,'GP4'!$B$6:$B$101,"") | L14: =_xlfn.XLOOKUP(K14,'GP4'!$B$6:$B$55,'GP4'!$A$6:$A$55,0) -> 0 | M14: =_xlfn.XLOOKUP($B14,'GP5'!$C$6:$C$101,'GP5'!$B$6:$B$101,"") | N14: =_xlfn.XLOOKUP(M14,'GP5'!$B$6:$B$55,'GP5'!$A$6:$A$55,0) -> 0 | O14: =_xlfn.XLOOKUP(B14,MPW!C$6:C$101,MPW!B$6:B$101,"") | P14: =_xlfn.XLOOKUP(O14,MPW!$B$6:$B$55,MPW!$A$6:$A$55,0) -> 0
A15: =ROW()-5 -> 10 | D15: =SUM(F15,H15,J15,L15,N15,P15)-MIN(F15,H15,J15,L15,N15) -> 0 | E15: =_xlfn.XLOOKUP($B15,'GP1'!$C$6:$C$101,'GP1'!$B$6:$B$101,"") -> 0 | F15: =_xlfn.XLOOKUP(E15,'GP1'!$B$6:$B$55,'GP1'!$A$6:$A$55,0) -> 0 | G15: =_xlfn.XLOOKUP($B15,'GP2'!$C$6:$C$101,'GP2'!$B$6:$B$101,"") -> 0 | H15: =_xlfn.XLOOKUP(G15,'GP2'!$B$6:$B$55,'GP2'!$A$6:$A$55,0) -> 0 | I15: =_xlfn.XLOOKUP($B15,'GP3'!$C$6:$C$101,'GP3'!$B$6:$B$101,"") | J15: =_xlfn.XLOOKUP(I15,'GP3'!$B$6:$B$55,'GP3'!$A$6:$A$55,0) -> 0 | K15: =_xlfn.XLOOKUP($B15,'GP4'!$C$6:$C$101,'GP4'!$B$6:$B$101,"") | L15: =_xlfn.XLOOKUP(K15,'GP4'!$B$6:$B$55,'GP4'!$A$6:$A$55,0) -> 0 | M15: =_xlfn.XLOOKUP($B15,'GP5'!$C$6:$C$101,'GP5'!$B$6:$B$101,"") | N15: =_xlfn.XLOOKUP(M15,'GP5'!$B$6:$B$55,'GP5'!$A$6:$A$55,0) -> 0 | O15: =_xlfn.XLOOKUP(B15,MPW!C$6:C$101,MPW!B$6:B$101,"") | P15: =_xlfn.XLOOKUP(O15,MPW!$B$6:$B$55,MPW!$A$6:$A$55,0) -> 0
A16: =ROW()-5 -> 11 | D16: =SUM(F16,H16,J16,L16,N16,P16)-MIN(F16,H16,J16,L16,N16) -> 0 | E16: =_xlfn.XLOOKUP($B16,'GP1'!$C$6:$C$101,'GP1'!$B$6:$B$101,"") -> 0 | F16: =_xlfn.XLOOKUP(E16,'GP1'!$B$6:$B$55,'GP1'!$A$6:$A$55,0) -> 0 | G16: =_xlfn.XLOOKUP($B16,'GP2'!$C$6:$C$101,'GP2'!$B$6:$B$101,"") -> 0 | H16: =_xlfn.XLOOKUP(G16,'GP2'!$B$6:$B$55,'GP2'!$A$6:$A$55,0) -> 0 | I16: =_xlfn.XLOOKUP($B16,'GP3'!$C$6:$C$101,'GP3'!$B$6:$B$101,"") | J16: =_xlfn.XLOOKUP(I16,'GP3'!$B$6:$B$55,'GP3'!$A$6:$A$55,0) -> 0 | K16: =_xlfn.XLOOKUP($B16,'GP4'!$C$6:$C$101,'GP4'!$B$6:$B$101,"") | L16: =_xlfn.XLOOKUP(K16,'GP4'!$B$6:$B$55,'GP4'!$A$6:$A$55,0) -> 0 | M16: =_xlfn.XLOOKUP($B16,'GP5'!$C$6:$C$101,'GP5'!$B$6:$B$101,"") | N16: =_xlfn.XLOOKUP(M16,'GP5'!$B$6:$B$55,'GP5'!$A$6:$A$55,0) -> 0 | O16: =_xlfn.XLOOKUP(B16,MPW!C$6:C$101,MPW!B$6:B$101,"") | P16: =_xlfn.XLOOKUP(O16,MPW!$B$6:$B$55,MPW!$A$6:$A$55,0) -> 0
A17: =ROW()-5 -> 12 | D17: =SUM(F17,H17,J17,L17,N17,P17)-MIN(F17,H17,J17,L17,N17) -> 0 | E17: =_xlfn.XLOOKUP($B17,'GP1'!$C$6:$C$101,'GP1'!$B$6:$B$101,"") -> 0 | F17: =_xlfn.XLOOKUP(E17,'GP1'!$B$6:$B$55,'GP1'!$A$6:$A$55,0) -> 0 | G17: =_xlfn.XLOOKUP($B17,'GP2'!$C$6:$C$101,'GP2'!$B$6:$B$101,"") -> 0 | H17: =_xlfn.XLOOKUP(G17,'GP2'!$B$6:$B$55,'GP2'!$A$6:$A$55,0) -> 0 | I17: =_xlfn.XLOOKUP($B17,'GP3'!$C$6:$C$101,'GP3'!$B$6:$B$101,"") | J17: =_xlfn.XLOOKUP(I17,'GP3'!$B$6:$B$55,'GP3'!$A$6:$A$55,0) -> 0 | K17: =_xlfn.XLOOKUP($B17,'GP4'!$C$6:$C$101,'GP4'!$B$6:$B$101,"") | L17: =_xlfn.XLOOKUP(K17,'GP4'!$B$6:$B$55,'GP4'!$A$6:$A$55,0) -> 0 | M17: =_xlfn.XLOOKUP($B17,'GP5'!$C$6:$C$101,'GP5'!$B$6:$B$101,"") | N17: =_xlfn.XLOOKUP(M17,'GP5'!$B$6:$B$55,'GP5'!$A$6:$A$55,0) -> 0 | O17: =_xlfn.XLOOKUP(B17,MPW!C$6:C$101,MPW!B$6:B$101,"") | P17: =_xlfn.XLOOKUP(O17,MPW!$B$6:$B$55,MPW!$A$6:$A$55,0) -> 0
A18: =ROW()-5 -> 13 | D18: =SUM(F18,H18,J18,L18,N18,P18)-MIN(F18,H18,J18,L18,N18) -> 0 | E18: =_xlfn.XLOOKUP($B18,'GP1'!$C$6:$C$101,'GP1'!$B$6:$B$101,"") | F18: =_xlfn.XLOOKUP(E18,'GP1'!$B$6:$B$55,'GP1'!$A$6:$A$55,0) -> 0 | G18: =_xlfn.XLOOKUP($B18,'GP2'!$C$6:$C$101,'GP2'!$B$6:$B$101,"") | H18: =_xlfn.XLOOKUP(G18,'GP2'!$B$6:$B$55,'GP2'!$A$6:$A$55,0) -> 0 | I18: =_xlfn.XLOOKUP($B18,'GP3'!$C$6:$C$101,'GP3'!$B$6:$B$101,"") | J18: =_xlfn.XLOOKUP(I18,'GP3'!$B$6:$B$55,'GP3'!$A$6:$A$55,0) -> 0 | K18: =_xlfn.XLOOKUP($B18,'GP4'!$C$6:$C$101,'GP4'!$B$6:$B$101,"") | L18: =_xlfn.XLOOKUP(K18,'GP4'!$B$6:$B$55,'GP4'!$A$6:$A$55,0) -> 0 | M18: =_xlfn.XLOOKUP($B18,'GP5'!$C$6:$C$101,'GP5'!$B$6:$B$101,"") | N18: =_xlfn.XLOOKUP(M18,'GP5'!$B$6:$B$55,'GP5'!$A$6:$A$55,0) -> 0 | O18: =_xlfn.XLOOKUP(B18,MPW!C$6:C$101,MPW!B$6:B$101,"") | P18: =_xlfn.XLOOKUP(O18,MPW!$B$6:$B$55,MPW!$A$6:$A$55,0) -> 0
A19: =ROW()-5 -> 14 | D19: =SUM(F19,H19,J19,L19,N19,P19)-MIN(F19,H19,J19,L19,N19) -> 0 | E19: =_xlfn.XLOOKUP($B19,'GP1'!$C$6:$C$101,'GP1'!$B$6:$B$101,"") | F19: =_xlfn.XLOOKUP(E19,'GP1'!$B$6:$B$55,'GP1'!$A$6:$A$55,0) -> 0 | G19: =_xlfn.XLOOKUP($B19,'GP2'!$C$6:$C$101,'GP2'!$B$6:$B$101,"") | H19: =_xlfn.XLOOKUP(G19,'GP2'!$B$6:$B$55,'GP2'!$A$6:$A$55,0) -> 0 | I19: =_xlfn.XLOOKUP($B19,'GP3'!$C$6:$C$101,'GP3'!$B$6:$B$101,"") | J19: =_xlfn.XLOOKUP(I19,'GP3'!$B$6:$B$55,'GP3'!$A$6:$A$55,0) -> 0 | K19: =_xlfn.XLOOKUP($B19,'GP4'!$C$6:$C$101,'GP4'!$B$6:$B$101,"") | L19: =_xlfn.XLOOKUP(K19,'GP4'!$B$6:$B$55,'GP4'!$A$6:$A$55,0) -> 0 | M19: =_xlfn.XLOOKUP($B19,'GP5'!$C$6:$C$101,'GP5'!$B$6:$B$101,"") | N19: =_xlfn.XLOOKUP(M19,'GP5'!$B$6:$B$55,'GP5'!$A$6:$A$55,0) -> 0 | O19: =_xlfn.XLOOKUP(B19,MPW!C$6:C$101,MPW!B$6:B$101,"") | P19: =_xlfn.XLOOKUP(O19,MPW!$B$6:$B$55,MPW!$A$6:$A$55,0) -> 0
A20: =ROW()-5 -> 15 | D20: =SUM(F20,H20,J20,L20,N20,P20)-MIN(F20,H20,J20,L20,N20) -> 0 | E20: =_xlfn.XLOOKUP($B20,'GP1'!$C$6:$C$101,'GP1'!$B$6:$B$101,"") | F20: =_xlfn.XLOOKUP(E20,'GP1'!$B$6:$B$55,'GP1'!$A$6:$A$55,0) -> 0 | G20: =_xlfn.XLOOKUP($B20,'GP2'!$C$6:$C$101,'GP2'!$B$6:$B$101,"") | H20: =_xlfn.XLOOKUP(G20,'GP2'!$B$6:$B$55,'GP2'!$A$6:$A$55,0) -> 0 | I20: =_xlfn.XLOOKUP($B20,'GP3'!$C$6:$C$101,'GP3'!$B$6:$B$101,"") | J20: =_xlfn.XLOOKUP(I20,'GP3'!$B$6:$B$55,'GP3'!$A$6:$A$55,0) -> 0 | K20: =_xlfn.XLOOKUP($B20,'GP4'!$C$6:$C$101,'GP4'!$B$6:$B$101,"") | L20: =_xlfn.XLOOKUP(K20,'GP4'!$B$6:$B$55,'GP4'!$A$6:$A$55,0) -> 0 | M20: =_xlfn.XLOOKUP($B20,'GP5'!$C$6:$C$101,'GP5'!$B$6:$B$101,"") | N20: =_xlfn.XLOOKUP(M20,'GP5'!$B$6:$B$55,'GP5'!$A$6:$A$55,0) -> 0 | O20: =_xlfn.XLOOKUP(B20,MPW!C$6:C$101,MPW!B$6:B$101,"") | P20: =_xlfn.XLOOKUP(O20,MPW!$B$6:$B$55,MPW!$A$6:$A$55,0) -> 0
A21: =ROW()-5 -> 16 | D21: =SUM(F21,H21,J21,L21,N21,P21)-MIN(F21,H21,J21,L21,N21) -> 0 | E21: =_xlfn.XLOOKUP($B21,'GP1'!$C$6:$C$101,'GP1'!$B$6:$B$101,"") | F21: =_xlfn.XLOOKUP(E21,'GP1'!$B$6:$B$55,'GP1'!$A$6:$A$55,0) -> 0 | G21: =_xlfn.XLOOKUP($B21,'GP2'!$C$6:$C$101,'GP2'!$B$6:$B$101,"") | H21: =_xlfn.XLOOKUP(G21,'GP2'!$B$6:$B$55,'GP2'!$A$6:$A$55,0) -> 0 | I21: =_xlfn.XLOOKUP($B21,'GP3'!$C$6:$C$101,'GP3'!$B$6:$B$101,"") | J21: =_xlfn.XLOOKUP(I21,'GP3'!$B$6:$B$55,'GP3'!$A$6:$A$55,0) -> 0 | K21: =_xlfn.XLOOKUP($B21,'GP4'!$C$6:$C$101,'GP4'!$B$6:$B$101,"") | L21: =_xlfn.XLOOKUP(K21,'GP4'!$B$6:$B$55,'GP4'!$A$6:$A$55,0) -> 0 | M21: =_xlfn.XLOOKUP($B21,'GP5'!$C$6:$C$101,'GP5'!$B$6:$B$101,"") | N21: =_xlfn.XLOOKUP(M21,'GP5'!$B$6:$B$55,'GP5'!$A$6:$A$55,0) -> 0 | O21: =_xlfn.XLOOKUP(B21,MPW!C$6:C$101,MPW!B$6:B$101,"") | P21: =_xlfn.XLOOKUP(O21,MPW!$B$6:$B$55,MPW!$A$6:$A$55,0) -> 0
A22: =ROW()-5 -> 17 | D22: =SUM(F22,H22,J22,L22,N22,P22)-MIN(F22,H22,J22,L22,N22) -> 0 | E22: =_xlfn.XLOOKUP($B22,'GP1'!$C$6:$C$101,'GP1'!$B$6:$B$101,"") | F22: =_xlfn.XLOOKUP(E22,'GP1'!$B$6:$B$55,'GP1'!$A$6:$A$55,0) -> 0 | G22: =_xlfn.XLOOKUP($B22,'GP2'!$C$6:$C$101,'GP2'!$B$6:$B$101,"") | H22: =_xlfn.XLOOKUP(G22,'GP2'!$B$6:$B$55,'GP2'!$A$6:$A$55,0) -> 0 | I22: =_xlfn.XLOOKUP($B22,'GP3'!$C$6:$C$101,'GP3'!$B$6:$B$101,"") | J22: =_xlfn.XLOOKUP(I22,'GP3'!$B$6:$B$55,'GP3'!$A$6:$A$55,0) -> 0 | K22: =_xlfn.XLOOKUP($B22,'GP4'!$C$6:$C$101,'GP4'!$B$6:$B$101,"") | L22: =_xlfn.XLOOKUP(K22,'GP4'!$B$6:$B$55,'GP4'!$A$6:$A$55,0) -> 0 | M22: =_xlfn.XLOOKUP($B22,'GP5'!$C$6:$C$101,'GP5'!$B$6:$B$101,"") | N22: =_xlfn.XLOOKUP(M22,'GP5'!$B$6:$B$55,'GP5'!$A$6:$A$55,0) -> 0 | O22: =_xlfn.XLOOKUP(B22,MPW!C$6:C$101,MPW!B$6:B$101,"") | P22: =_xlfn.XLOOKUP(O22,MPW!$B$6:$B$55,MPW!$A$6:$A$55,0) -> 0
A23: =ROW()-5 -> 18 | D23: =SUM(F23,H23,J23,L23,N23,P23)-MIN(F23,H23,J23,L23,N23) -> 0 | E23: =_xlfn.XLOOKUP($B23,'GP1'!$C$6:$C$101,'GP1'!$B$6:$B$101,"") | F23: =_xlfn.XLOOKUP(E23,'GP1'!$B$6:$B$55,'GP1'!$A$6:$A$55,0) -> 0 | G23: =_xlfn.XLOOKUP($B23,'GP2'!$C$6:$C$101,'GP2'!$B$6:$B$101,"") | H23: =_xlfn.XLOOKUP(G23,'GP2'!$B$6:$B$55,'GP2'!$A$6:$A$55,0) -> 0 | I23: =_xlfn.XLOOKUP($B23,'GP3'!$C$6:$C$101,'GP3'!$B$6:$B$101,"") | J23: =_xlfn.XLOOKUP(I23,'GP3'!$B$6:$B$55,'GP3'!$A$6:$A$55,0) -> 0 | K23: =_xlfn.XLOOKUP($B23,'GP4'!$C$6:$C$101,'GP4'!$B$6:$B$101,"") | L23: =_xlfn.XLOOKUP(K23,'GP4'!$B$6:$B$55,'GP4'!$A$6:$A$55,0) -> 0 | M23: =_xlfn.XLOOKUP($B23,'GP5'!$C$6:$C$101,'GP5'!$B$6:$B$101,"") | N23: =_xlfn.XLOOKUP(M23,'GP5'!$B$6:$B$55,'GP5'!$A$6:$A$55,0) -> 0 | O23: =_xlfn.XLOOKUP(B23,MPW!C$6:C$101,MPW!B$6:B$101,"") | P23: =_xlfn.XLOOKUP(O23,MPW!$B$6:$B$55,MPW!$A$6:$A$55,0) -> 0

Sheet GP1
H1: Liczba uczestników: | I1: GP Punkty | J1: Bonus za rundę | K1: Bonus za podium | O1: Liczba uczestników połączonych kategorii: | T1: Mnożnik za podium
B2: miejsce: | C2: PABIANICE | H2: 3 | I2: 50 | J2: 10 | K2: =3*H2^(1/3) -> 4.3267487 | O2: 4 | T2: =3*O2^(1/3) -> 4.7622032
B3: data: | C3: 44940
O4: WYNIKI ŁĄCZONYCH KATEGORII
A5: Punkty | B5: Miejsce Place | C5: Nazwisko Imię Name | D5: Klub Club(s) | E5: Okręg Division | F5: Państwo Country | H5: Miejsce | I5: Punkty za miejsce | J5: awans do kolejnej rundy pucharowej | K5: bonus za rundy pucharowe | L5: punkty za podium | M5: Suma | O5: Miejsce | P5: NAZWISKO | R5: Punkty za miejsce | S5: awans do kolejnej rundy pucharowej | T5: bonus za rundy pucharowe | U5: punkty za podium | V5: Suma
A6: =M6 -> 82.980246 | B6: =IF(H6>$H$2,"",(ROW()-5)) -> 1 | C6: GANSZCZYK Anna | D6: BYTOMSKIE TOWARZYSTWO SZERMIERCZE | F6: POL | H6: 1 | I6: =IF(H2=1,50,IF(H6<$H$2+1,($I$2-($I$2-1)*(LOG(H6)/LOG($H$2))),"")) -> 50 | J6: =INT(LOG($H$2,2))-ROUNDUP(LOG(H6,2),0)+IF(OR($H$2=1,$H$2=2,$H$2=4,$H$2=8,$H$2=16,$H$2=32,$H$2=64,$H$2=128,$H$2=256),0,1) -> 2 | K6: =J6*$J$2 -> 20 | L6: =3*K2 -> 12.980246 | M6: =IF(I6<>"",K6+I6+L6,0) -> 82.980246 | O6: 1 | P6: GANSZCZYK Anna | R6: =IF(O2=1,50,IF(O6<$O$2+1,($I$2-($I$2-1)*(LOG(O6)/LOG($O$2))),"")) -> 50 | S6: =INT(LOG($O$2,2))-ROUNDUP(LOG(O6,2),0)+IF(OR($O$2=1,$O$2=2,$O$2=4,$O$2=8,$O$2=16,$O$2=32,$O$2=64,$O$2=128,$O$2=256),0,1) -> 2 | T6: =S6*$J$2 -> 20 | U6: =3*T2 -> 14.286609 | V6: =IF(R6<>"",T6+R6+U6,0) -> 84.286609
A7: =M7 -> 37.737939 | B7: =IF(H7>$H$2,"",(ROW()-5)) -> 2 | C7: POJMAŃSKA Katarzyna | D7: AKADEMIA SZERMIERKI W-WA | F7: POL | H7: 2 | I7: =IF(H7<$H$2+1,($I$2-($I$2-1)*(LOG(H7)/LOG($H$2))),"") -> 19.084442 | J7: =INT(LOG($H$2,2))-ROUNDUP(LOG(H7,2),0)+IF(OR($H$2=1,$H$2=2,$H$2=4,$H$2=8,$H$2=16,$H$2=32,$H$2=64,$H$2=128,$H$2=256),0,1) -> 1 | K7: =J7*$J$2 -> 10 | L7: =2*K2 -> 8.6534974 | M7: =IF(I7<>"",K7+I7+L7,0) -> 37.737939 | O7: 2 | P7: BORKOWSKA Halina | R7: =IF(O7<$O$2+1,($I$2-($I$2-1)*(LOG(O7)/LOG($O$2))),"") -> 25.5 | S7: =INT(LOG($O$2,2))-ROUNDUP(LOG(O7,2),0)+IF(OR($O$2=1,$O$2=2,$O$2=4,$O$2=8,$O$2=16,$O$2=32,$O$2=64,$O$2=128,$O$2=256),0,1) -> 1 | T7: =S7*$J$2 -> 10 | U7: =2*T2 -> 9.5244063 | V7: =IF(R7<>"",T7+R7+U7,0) -> 45.024406
A8: 5.3267487 | B8: =IF(H8>$H$2,"",(ROW()-5)) -> 3 | C8: WALECKA Wanda | D8: Feniks Nowy Dwór Mazowiecki | F8: POL | H8: 3 | I8: =IF(H8<$H$2+1,($I$2-($I$2-1)*(LOG(H8)/LOG($H$2))),"") -> 1 | J8: =INT(LOG($H$2,2))-ROUNDUP(LOG(H8,2),0)+IF(OR($H$2=1,$H$2=2,$H$2=4,$H$2=8,$H$2=16,$H$2=32,$H$2=64,$H$2=128,$H$2=256),0,1) -> 0 | K8: =J8*$J$2 -> 0 | L8: =K2 -> 4.3267487 | M8: =IF(I8<>"",K8+I8+L8,0) -> 5.3267487 | O8: 3 | P8: POJMAŃSKA Katarzyna | R8: =IF(O8<$O$2+1,($I$2-($I$2-1)*(LOG(O8)/LOG($O$2))),"") -> 11.168419 | S8: =INT(LOG($O$2,2))-ROUNDUP(LOG(O8,2),0)+IF(OR($O$2=1,$O$2=2,$O$2=4,$O$2=8,$O$2=16,$O$2=32,$O$2=64,$O$2=128,$O$2=256),0,1) -> 0 | T8: =S8*$J$2 -> 0 | U8: =T2 -> 4.7622032 | V8: =IF(R8<>"",T8+R8+U8,0) -> 15.930622
A9: =M9 -> 0 | H9: 4 | I9: =IF(H9<$H$2+1,($I$2-($I$2-1)*(LOG(H9)/LOG($H$2))),"") | J9: =INT(LOG($H$2,2))-ROUNDUP(LOG(H9,2),0)+IF(OR($H$2=1,$H$2=2,$H$2=4,$H$2=8,$H$2=16,$H$2=32,$H$2=64,$H$2=128,$H$2=256),0,1) -> 0 | K9: =J9*$J$2 -> 0 | M9: =IF(I9<>"",K9+I9+L9,0) -> 0 | O9: 4 | P9: WALECKA Wanda | R9: =IF(O9<$O$2+1,($I$2-($I$2-1)*(LOG(O9)/LOG($O$2))),"") -> 1 | S9: =INT(LOG($O$2,2))-ROUNDUP(LOG(O9,2),0)+IF(OR($O$2=1,$O$2=2,$O$2=4,$O$2=8,$O$2=16,$O$2=32,$O$2=64,$O$2=128,$O$2=256),0,1) -> 0 | T9: =S9*$J$2 -> 0 | V9: =IF(R9<>"",T9+R9+U9,0) -> 1 | AH9: x | AI9: 23
A10: =M10 -> 0 | B10: =IF(H10>$H$2,"",(ROW()-5)) | H10: 5 | I10: =IF(H10<$H$2+1,($I$2-($I$2-1)*(LOG(H10)/LOG($H$2))),"") | J10: =INT(LOG($H$2,2))-ROUNDUP(LOG(H10,2),0)+IF(OR($H$2=1,$H$2=2,$H$2=4,$H$2=8,$H$2=16,$H$2=32,$H$2=64,$H$2=128,$H$2=256),0,1) -> -1 | K10: =J10*$J$2 -> -10 | M10: =IF(I10<>"",K10+I10+L10,0) -> 0 | O10: 5 | R10: =IF(O10<$O$2+1,($I$2-($I$2-1)*(LOG(O10)/LOG($O$2))),"") | S10: =INT(LOG($O$2,2))-ROUNDUP(LOG(O10,2),0)+IF(OR($O$2=1,$O$2=2,$O$2=4,$O$2=8,$O$2=16,$O$2=32,$O$2=64,$O$2=128,$O$2=256),0,1) -> -1 | T10: =S10*$J$2 -> -10 | V10: =IF(R10<>"",T10+R10+U10,0) -> 0 | AH10: N | AI10: 45
A11: =M11 -> 0 | B11: =IF(H11>$H$2,"",(ROW()-5)) | H11: 6 | I11: =IF(H11<$H$2+1,($I$2-($I$2-1)*(LOG(H11)/LOG($H$2))),"") | J11: =INT(LOG($H$2,2))-ROUNDUP(LOG(H11,2),0)+IF(OR($H$2=1,$H$2=2,$H$2=4,$H$2=8,$H$2=16,$H$2=32,$H$2=64,$H$2=128,$H$2=256),0,1) -> -1 | K11: =J11*$J$2 -> -10 | M11: =IF(I11<>"",K11+I11+L11,0) -> 0 | O11: 6 | R11: =IF(O11<$O$2+1,($I$2-($I$2-1)*(LOG(O11)/LOG($O$2))),"") | S11: =INT(LOG($O$2,2))-ROUNDUP(LOG(O11,2),0)+IF(OR($O$2=1,$O$2=2,$O$2=4,$O$2=8,$O$2=16,$O$2=32,$O$2=64,$O$2=128,$O$2=256),0,1) -> -1 | T11: =S11*$J$2 -> -10 | V11: =IF(R11<>"",T11+R11+U11,0) -> 0 | AH11: MP | AI11: 50
A12: =M12 -> 0 | B12: =IF(H12>$H$2,"",(ROW()-5)) | H12: 7 | I12: =IF(H12<$H$2+1,($I$2-($I$2-1)*(LOG(H12)/LOG($H$2))),"") | J12: =INT(LOG($H$2,2))-ROUNDUP(LOG(H12,2),0)+IF(OR($H$2=1,$H$2=2,$H$2=4,$H$2=8,$H$2=16,$H$2=32,$H$2=64,$H$2=128,$H$2=256),0,1) -> -1 | K12: =J12*$J$2 -> -10 | M12: =IF(I12<>"",K12+I12+L12,0) -> 0 | O12: 7 | R12: =IF(O12<$O$2+1,($I$2-($I$2-1)*(LOG(O12)/LOG($O$2))),"") | S12: =INT(LOG($O$2,2))-ROUNDUP(LOG(O12,2),0)+IF(OR($O$2=1,$O$2=2,$O$2=4,$O$2=8,$O$2=16,$O$2=32,$O$2=64,$O$2=128,$O$2=256),0,1) -> -1 | T12: =S12*$J$2 -> -10 | V12: =IF(R12<>"",T12+R12+U12,0) -> 0 | AH12: MP-1 | AI12: =AI11-1 -> 49
A13: =M13 -> 0 | B13: =IF(H13>$H$2,"",(ROW()-5)) | H13: 8 | I13: =IF(H13<$H$2+1,($I$2-($I$2-1)*(LOG(H13)/LOG($H$2))),"") | J13: =INT(LOG($H$2,2))-ROUNDUP(LOG(H13,2),0)+IF(OR($H$2=1,$H$2=2,$H$2=4,$H$2=8,$H$2=16,$H$2=32,$H$2=64,$H$2=128,$H$2=256),0,1) -> -1 | K13: =J13*$J$2 -> -10 | M13: =IF(I13<>"",K13+I13+L13,0) -> 0 | O13: 8 | R13: =IF(O13<$O$2+1,($I$2-($I$2-1)*(LOG(O13)/LOG($O$2))),"") | S13: =INT(LOG($O$2,2))-ROUNDUP(LOG(O13,2),0)+IF(OR($O$2=1,$O$2=2,$O$2=4,$O$2=8,$O$2=16,$O$2=32,$O$2=64,$O$2=128,$O$2=256),0,1) -> -1 | T13: =S13*$J$2 -> -10 | V13: =IF(R13<>"",T13+R13+U13,0) -> 0 | AH13: log(x) | AI13: =LOG(AI9) -> 1.3617278
A14: =M14 -> 0 | B14: =IF(H14>$H$2,"",(ROW()-5)) | H14: 9 | I14: =IF(H14<$H$2+1,($I$2-($I$2-1)*(LOG(H14)/LOG($H$2))),"") | J14: =INT(LOG($H$2,2))-ROUNDUP(LOG(H14,2),0)+IF(OR($H$2=1,$H$2=2,$H$2=4,$H$2=8,$H$2=16,$H$2=32,$H$2=64,$H$2=128,$H$2=256),0,1) -> -2 | K14: =J14*$J$2 -> -20 | M14: =IF(I14<>"",K14+I14+L14,0) -> 0 | O14: 9 | R14: =IF(O14<$O$2+1,($I$2-($I$2-1)*(LOG(O14)/LOG($O$2))),"") | S14: =INT(LOG($O$2,2))-ROUNDUP(LOG(O14,2),0)+IF(OR($O$2=1,$O$2=2,$O$2=4,$O$2=8,$O$2=16,$O$2=32,$O$2=64,$O$2=128,$O$2=256),0,1) -> -2 | T14: =S14*$J$2 -> -20 | V14: =IF(R14<>"",T14+R14+U14,0) -> 0 | AH14: Log(N) | AI14: =LOG(AI10) -> 1.6532125
A15: =M15 -> 0 | B15: =IF(H15>$H$2,"",(ROW()-5)) | H15: 10 | I15: =IF(H15<$H$2+1,($I$2-($I$2-1)*(LOG(H15)/LOG($H$2))),"") | J15: =INT(LOG($H$2,2))-ROUNDUP(LOG(H15,2),0)+IF(OR($H$2=1,$H$2=2,$H$2=4,$H$2=8,$H$2=16,$H$2=32,$H$2=64,$H$2=128,$H$2=256),0,1) -> -2 | K15: =J15*$J$2 -> -20 | M15: =IF(I15<>"",K15+I15+L15,0) -> 0 | O15: 10 | R15: =IF(O15<$O$2+1,($I$2-($I$2-1)*(LOG(O15)/LOG($O$2))),"") | S15: =INT(LOG($O$2,2))-ROUNDUP(LOG(O15,2),0)+IF(OR($O$2=1,$O$2=2,$O$2=4,$O$2=8,$O$2=16,$O$2=32,$O$2=64,$O$2=128,$O$2=256),0,1) -> -2 | T15: =S15*$J$2 -> -20 | V15: =IF(R15<>"",T15+R15+U15,0) -> 0
A16: =M16 -> 0 | B16: =IF(H16>$H$2,"",(ROW()-5)) | H16: 11 | I16: =IF(H16<$H$2+1,($I$2-($I$2-1)*(LOG(H16)/LOG($H$2))),"") | J16: =INT(LOG($H$2,2))-ROUNDUP(LOG(H16,2),0)+IF(OR($H$2=1,$H$2=2,$H$2=4,$H$2=8,$H$2=16,$H$2=32,$H$2=64,$H$2=128,$H$2=256),0,1) -> -2 | K16: =J16*$J$2 -> -20 | M16: =IF(I16<>"",K16+I16+L16,0) -> 0 | O16: 11 | R16: =IF(O16<$O$2+1,($I$2-($I$2-1)*(LOG(O16)/LOG($O$2))),"") | S16: =INT(LOG($O$2,2))-ROUNDUP(LOG(O16,2),0)+IF(OR($O$2=1,$O$2=2,$O$2=4,$O$2=8,$O$2=16,$O$2=32,$O$2=64,$O$2=128,$O$2=256),0,1) -> -2 | T16: =S16*$J$2 -> -20 | V16: =IF(R16<>"",T16+R16+U16,0) -> 0 | AH16: MP - (MP-1)*LOG(x)/LOG(N) | AI16: =AI11-AI12*AI13/AI14 -> 9.6393909 | AJ16: points
A17: =M17 -> 0 | B17: =IF(H17>$H$2,"",(ROW()-5)) | H17: 12 | I17: =IF(H17<$H$2+1,($I$2-($I$2-1)*(LOG(H17)/LOG($H$2))),"") | J17: =INT(LOG($H$2,2))-ROUNDUP(LOG(H17,2),0)+IF(OR($H$2=1,$H$2=2,$H$2=4,$H$2=8,$H$2=16,$H$2=32,$H$2=64,$H$2=128,$H$2=256),0,1) -> -2 | K17: =J17*$J$2 -> -20 | M17: =IF(I17<>"",K17+I17+L17,0) -> 0 | O17: 12 | R17: =IF(O17<$O$2+1,($I$2-($I$2-1)*(LOG(O17)/LOG($O$2))),"") | S17: =INT(LOG($O$2,2))-ROUNDUP(LOG(O17,2),0)+IF(OR($O$2=1,$O$2=2,$O$2=4,$O$2=8,$O$2=16,$O$2=32,$O$2=64,$O$2=128,$O$2=256),0,1) -> -2 | T17: =S17*$J$2 -> -20 | V17: =IF(R17<>"",T17+R17+U17,0) -> 0
A18: =M18 -> 0 | B18: =IF(H18>$H$2,"",(ROW()-5)) | H18: 13 | I18: =IF(H18<$H$2+1,($I$2-($I$2-1)*(LOG(H18)/LOG($H$2))),"") | J18: =INT(LOG($H$2,2))-ROUNDUP(LOG(H18,2),0)+IF(OR($H$2=1,$H$2=2,$H$2=4,$H$2=8,$H$2=16,$H$2=32,$H$2=64,$H$2=128,$H$2=256),0,1) -> -2 | K18: =J18*$J$2 -> -20 | M18: =IF(I18<>"",K18+I18+L18,0) -> 0 | O18: 13 | R18: =IF(O18<$O$2+1,($I$2-($I$2-1)*(LOG(O18)/LOG($O$2))),"") | S18: =INT(LOG($O$2,2))-ROUNDUP(LOG(O18,2),0)+IF(OR($O$2=1,$O$2=2,$O$2=4,$O$2=8,$O$2=16,$O$2=32,$O$2=64,$O$2=128,$O$2=256),0,1) -> -2 | T18: =S18*$J$2 -> -20 | V18: =IF(R18<>"",T18+R18+U18,0) -> 0
A19: =M19 -> 0 | B19: =IF(H19>$H$2,"",(ROW()-5)) | H19: 14 | I19: =IF(H19<$H$2+1,($I$2-($I$2-1)*(LOG(H19)/LOG($H$2))),"") | J19: =INT(LOG($H$2,2))-ROUNDUP(LOG(H19,2),0)+IF(OR($H$2=1,$H$2=2,$H$2=4,$H$2=8,$H$2=16,$H$2=32,$H$2=64,$H$2=128,$H$2=256),0,1) -> -2 | K19: =J19*$J$2 -> -20 | M19: =IF(I19<>"",K19+I19+L19,0) -> 0 | O19: 14 | R19: =IF(O19<$O$2+1,($I$2-($I$2-1)*(LOG(O19)/LOG($O$2))),"") | S19: =INT(LOG($O$2,2))-ROUNDUP(LOG(O19,2),0)+IF(OR($O$2=1,$O$2=2,$O$2=4,$O$2=8,$O$2=16,$O$2=32,$O$2=64,$O$2=128,$O$2=256),0,1) -> -2 | T19: =S19*$J$2 -> -20 | V19: =IF(R19<>"",T19+R19+U19,0) -> 0
A20: =M20 -> 0 | B20: =IF(H20>$H$2,"",(ROW()-5)) | H20: 15 | I20: =IF(H20<$H$2+1,($I$2-($I$2-1)*(LOG(H20)/LOG($H$2))),"") | J20: =INT(LOG($H$2,2))-ROUNDUP(LOG(H20,2),0)+IF(OR($H$2=1,$H$2=2,$H$2=4,$H$2=8,$H$2=16,$H$2=32,$H$2=64,$H$2=128,$H$2=256),0,1) -> -2 | K20: =J20*$J$2 -> -20 | M20: =IF(I20<>"",K20+I20+L20,0) -> 0 | O20: 15 | R20: =IF(O20<$O$2+1,($I$2-($I$2-1)*(LOG(O20)/LOG($O$2))),"") | S20: =INT(LOG($O$2,2))-ROUNDUP(LOG(O20,2),0)+IF(OR($O$2=1,$O$2=2,$O$2=4,$O$2=8,$O$2=16,$O$2=32,$O$2=64,$O$2=128,$O$2=256),0,1) -> -2 | T20: =S20*$J$2 -> -20 | V20: =IF(R20<>"",T20+R20+U20,0) -> 0
A21: =M21 -> 0 | B21: =IF(H21>$H$2,"",(ROW()-5)) | H21: 16 | I21: =IF(H21<$H$2+1,($I$2-($I$2-1)*(LOG(H21)/LOG($H$2))),"") | J21: =INT(LOG($H$2,2))-ROUNDUP(LOG(H21,2),0)+IF(OR($H$2=1,$H$2=2,$H$2=4,$H$2=8,$H$2=16,$H$2=32,$H$2=64,$H$2=128,$H$2=256),0,1) -> -2 | K21: =J21*$J$2 -> -20 | M21: =IF(I21<>"",K21+I21+L21,0) -> 0 | O21: 16 | R21: =IF(O21<$O$2+1,($I$2-($I$2-1)*(LOG(O21)/LOG($O$2))),"") | S21: =INT(LOG($O$2,2))-ROUNDUP(LOG(O21,2),0)+IF(OR($O$2=1,$O$2=2,$O$2=4,$O$2=8,$O$2=16,$O$2=32,$O$2=64,$O$2=128,$O$2=256),0,1) -> -2 | T21: =S21*$J$2 -> -20 | V21: =IF(R21<>"",T21+R21+U21,0) -> 0
A22: =M22 -> 0 | B22: =IF(H22>$H$2,"",(ROW()-5)) | H22: 17 | I22: =IF(H22<$H$2+1,($I$2-($I$2-1)*(LOG(H22)/LOG($H$2))),"") | J22: =INT(LOG($H$2,2))-ROUNDUP(LOG(H22,2),0)+IF(OR($H$2=1,$H$2=2,$H$2=4,$H$2=8,$H$2=16,$H$2=32,$H$2=64,$H$2=128,$H$2=256),0,1) -> -3 | K22: =J22*$J$2 -> -30 | M22: =IF(I22<>"",K22+I22+L22,0) -> 0 | O22: 17 | R22: =IF(O22<$O$2+1,($I$2-($I$2-1)*(LOG(O22)/LOG($O$2))),"") | S22: =INT(LOG($O$2,2))-ROUNDUP(LOG(O22,2),0)+IF(OR($O$2=1,$O$2=2,$O$2=4,$O$2=8,$O$2=16,$O$2=32,$O$2=64,$O$2=128,$O$2=256),0,1) -> -3 | T22: =S22*$J$2 -> -30 | V22: =IF(R22<>"",T22+R22+U22,0) -> 0
A23: =M23 -> 0 | B23: =IF(H23>$H$2,"",(ROW()-5)) | H23: 18 | I23: =IF(H23<$H$2+1,($I$2-($I$2-1)*(LOG(H23)/LOG($H$2))),"") | J23: =INT(LOG($H$2,2))-ROUNDUP(LOG(H23,2),0)+IF(OR($H$2=1,$H$2=2,$H$2=4,$H$2=8,$H$2=16,$H$2=32,$H$2=64,$H$2=128,$H$2=256),0,1) -> -3 | K23: =J23*$J$2 -> -30 | M23: =IF(I23<>"",K23+I23+L23,0) -> 0 | O23: 18 | R23: =IF(O23<$O$2+1,($I$2-($I$2-1)*(LOG(O23)/LOG($O$2))),"") | S23: =INT(LOG($O$2,2))-ROUNDUP(LOG(O23,2),0)+IF(OR($O$2=1,$O$2=2,$O$2=4,$O$2=8,$O$2=16,$O$2=32,$O$2=64,$O$2=128,$O$2=256),0,1) -> -3 | T23: =S23*$J$2 -> -30 | V23: =IF(R23<>"",T23+R23+U23,0) -> 0
A24: =M24 -> 0 | B24: =IF(H24>$H$2,"",(ROW()-5)) | H24: 19 | I24: =IF(H24<$H$2+1,($I$2-($I$2-1)*(LOG(H24)/LOG($H$2))),"") | J24: =INT(LOG($H$2,2))-ROUNDUP(LOG(H24,2),0)+IF(OR($H$2=1,$H$2=2,$H$2=4,$H$2=8,$H$2=16,$H$2=32,$H$2=64,$H$2=128,$H$2=256),0,1) -> -3 | K24: =J24*$J$2 -> -30 | M24: =IF(I24<>"",K24+I24+L24,0) -> 0 | O24: 19 | R24: =IF(O24<$O$2+1,($I$2-($I$2-1)*(LOG(O24)/LOG($O$2))),"") | S24: =INT(LOG($O$2,2))-ROUNDUP(LOG(O24,2),0)+IF(OR($O$2=1,$O$2=2,$O$2=4,$O$2=8,$O$2=16,$O$2=32,$O$2=64,$O$2=128,$O$2=256),0,1) -> -3 | T24: =S24*$J$2 -> -30 | V24: =IF(R24<>"",T24+R24+U24,0) -> 0
A25: =M25 -> 0 | B25: =IF(H25>$H$2,"",(ROW()-5)) | H25: 20 | I25: =IF(H25<$H$2+1,($I$2-($I$2-1)*(LOG(H25)/LOG($H$2))),"") | J25: =INT(LOG($H$2,2))-ROUNDUP(LOG(H25,2),0)+IF(OR($H$2=1,$H$2=2,$H$2=4,$H$2=8,$H$2=16,$H$2=32,$H$2=64,$H$2=128,$H$2=256),0,1) -> -3 | K25: =J25*$J$2 -> -30 | M25: =IF(I25<>"",K25+I25+L25,0) -> 0 | O25: 20 | R25: =IF(O25<$O$2+1,($I$2-($I$2-1)*(LOG(O25)/LOG($O$2))),"") | S25: =INT(LOG($O$2,2))-ROUNDUP(LOG(O25,2),0)+IF(OR($O$2=1,$O$2=2,$O$2=4,$O$2=8,$O$2=16,$O$2=32,$O$2=64,$O$2=128,$O$2=256),0,1) -> -3 | T25: =S25*$J$2 -> -30 | V25: =IF(R25<>"",T25+R25+U25,0) -> 0
A26: =M26 -> 0 | B26: =IF(H26>$H$2,"",(ROW()-5)) | H26: 21 | I26: =IF(H26<$H$2+1,($I$2-($I$2-1)*(LOG(H26)/LOG($H$2))),"") | J26: =INT(LOG($H$2,2))-ROUNDUP(LOG(H26,2),0)+IF(OR($H$2=1,$H$2=2,$H$2=4,$H$2=8,$H$2=16,$H$2=32,$H$2=64,$H$2=128,$H$2=256),0,1) -> -3 | K26: =J26*$J$2 -> -30 | M26: =IF(I26<>"",K26+I26+L26,0) -> 0 | O26: 21 | R26: =IF(O26<$O$2+1,($I$2-($I$2-1)*(LOG(O26)/LOG($O$2))),"") | S26: =INT(LOG($O$2,2))-ROUNDUP(LOG(O26,2),0)+IF(OR($O$2=1,$O$2=2,$O$2=4,$O$2=8,$O$2=16,$O$2=32,$O$2=64,$O$2=128,$O$2=256),0,1) -> -3 | T26: =S26*$J$2 -> -30 | V26: =IF(R26<>"",T26+R26+U26,0) -> 0
A27: =M27 -> 0 | B27: =IF(H27>$H$2,"",(ROW()-5)) | H27: 22 | I27: =IF(H27<$H$2+1,($I$2-($I$2-1)*(LOG(H27)/LOG($H$2))),"") | J27: =INT(LOG($H$2,2))-ROUNDUP(LOG(H27,2),0)+IF(OR($H$2=1,$H$2=2,$H$2=4,$H$2=8,$H$2=16,$H$2=32,$H$2=64,$H$2=128,$H$2=256),0,1) -> -3 | K27: =J27*$J$2 -> -30 | M27: =IF(I27<>"",K27+I27+L27,0) -> 0 | O27: 22 | R27: =IF(O27<$O$2+1,($I$2-($I$2-1)*(LOG(O27)/LOG($O$2))),"") | S27: =INT(LOG($O$2,2))-ROUNDUP(LOG(O27,2),0)+IF(OR($O$2=1,$O$2=2,$O$2=4,$O$2=8,$O$2=16,$O$2=32,$O$2=64,$O$2=128,$O$2=256),0,1) -> -3 | T27: =S27*$J$2 -> -30 | V27: =IF(R27<>"",T27+R27+U27,0) -> 0
A28: =M28 -> 0 | B28: =IF(H28>$H$2,"",(ROW()-5)) | H28: 23 | I28: =IF(H28<$H$2+1,($I$2-($I$2-1)*(LOG(H28)/LOG($H$2))),"") | J28: =INT(LOG($H$2,2))-ROUNDUP(LOG(H28,2),0)+IF(OR($H$2=1,$H$2=2,$H$2=4,$H$2=8,$H$2=16,$H$2=32,$H$2=64,$H$2=128,$H$2=256),0,1) -> -3 | K28: =J28*$J$2 -> -30 | M28: =IF(I28<>"",K28+I28+L28,0) -> 0 | O28: 23 | R28: =IF(O28<$O$2+1,($I$2-($I$2-1)*(LOG(O28)/LOG($O$2))),"") | S28: =INT(LOG($O$2,2))-ROUNDUP(LOG(O28,2),0)+IF(OR($O$2=1,$O$2=2,$O$2=4,$O$2=8,$O$2=16,$O$2=32,$O$2=64,$O$2=128,$O$2=256),0,1) -> -3 | T28: =S28*$J$2 -> -30 | V28: =IF(R28<>"",T28+R28+U28,0) -> 0
... A37: =M37 -> 0 | B37: =IF(H37>$H$2,"",(ROW()-5)) | H37: 32 | I37: =IF(H37<$H$2+1,($I$2-($I$2-1)*(LOG(H37)/LOG($H$2))),"") | J37: =INT(LOG($H$2,2))-ROUNDUP(LOG(H37,2),0)+IF(OR($H$2=1,$H$2=2,$H$2=4,$H$2=8,$H$2=16,$H$2=32,$H$2=64,$H$2=128,$H$2=256),0,1) -> -3 | K37: =J37*$J$2 -> -30 | M37: =IF(I37<>"",K37+I37+L37,0) -> 0 | O37: 32 | R37: =IF(O37<$O$2+1,($I$2-($I$2-1)*(LOG(O37)/LOG($O$2))),"") | S37: =INT(LOG($O$2,2))-ROUNDUP(LOG(O37,2),0)+IF(OR($O$2=1,$O$2=2,$O$2=4,$O$2=8,$O$2=16,$O$2=32,$O$2=64,$O$2=128,$O$2=256),0,1) -> -3 | T37: =S37*$J$2 -> -30 | V37: =IF(R37<>"",T37+R37+U37,0) -> 0
B38: =IF(H38>$H$2,"",(ROW()-5)) | H38: 33 | I38: =IF(H38<$H$2+1,($I$2-($I$2-1)*(LOG(H38)/LOG($H$2))),"") | J38: =INT(LOG($H$2,2))-ROUNDUP(LOG(H38,2),0)+IF(OR($H$2=1,$H$2=2,$H$2=4,$H$2=8,$H$2=16,$H$2=32,$H$2=64,$H$2=128,$H$2=256),0,1) -> -4 | K38: =J38*$J$2 -> -40 | M38: =IF(I38<>"",K38+I38+L38,0) -> 0 | O38: 33 | R38: =IF(O38<$O$2+1,($I$2-($I$2-1)*(LOG(O38)/LOG($O$2))),"") | S38: =INT(LOG($O$2,2))-ROUNDUP(LOG(O38,2),0)+IF(OR($O$2=1,$O$2=2,$O$2=4,$O$2=8,$O$2=16,$O$2=32,$O$2=64,$O$2=128,$O$2=256),0,1) -> -4 | T38: =S38*$J$2 -> -40 | V38: =IF(R38<>"",T38+R38+U38,0) -> 0
B39: =IF(H39>$H$2,"",(ROW()-5)) | H39: 34 | I39: =IF(H39<$H$2+1,($I$2-($I$2-1)*(LOG(H39)/LOG($H$2))),"") | J39: =INT(LOG($H$2,2))-ROUNDUP(LOG(H39,2),0)+IF(OR($H$2=1,$H$2=2,$H$2=4,$H$2=8,$H$2=16,$H$2=32,$H$2=64,$H$2=128,$H$2=256),0,1) -> -4 | K39: =J39*$J$2 -> -40 | M39: =IF(I39<>"",K39+I39+L39,0) -> 0 | O39: 34 | R39: =IF(O39<$O$2+1,($I$2-($I$2-1)*(LOG(O39)/LOG($O$2))),"") | S39: =INT(LOG($O$2,2))-ROUNDUP(LOG(O39,2),0)+IF(OR($O$2=1,$O$2=2,$O$2=4,$O$2=8,$O$2=16,$O$2=32,$O$2=64,$O$2=128,$O$2=256),0,1) -> -4 | T39: =S39*$J$2 -> -40 | V39: =IF(R39<>"",T39+R39+U39,0) -> 0
B40: =IF(H40>$H$2,"",(ROW()-5)) | H40: 35 | I40: =IF(H40<$H$2+1,($I$2-($I$2-1)*(LOG(H40)/LOG($H$2))),"") | J40: =INT(LOG($H$2,2))-ROUNDUP(LOG(H40,2),0)+IF(OR($H$2=1,$H$2=2,$H$2=4,$H$2=8,$H$2=16,$H$2=32,$H$2=64,$H$2=128,$H$2=256),0,1) -> -4 | K40: =J40*$J$2 -> -40 | M40: =IF(I40<>"",K40+I40+L40,0) -> 0 | O40: 35 | R40: =IF(O40<$O$2+1,($I$2-($I$2-1)*(LOG(O40)/LOG($O$2))),"") | S40: =INT(LOG($O$2,2))-ROUNDUP(LOG(O40,2),0)+IF(OR($O$2=1,$O$2=2,$O$2=4,$O$2=8,$O$2=16,$O$2=32,$O$2=64,$O$2=128,$O$2=256),0,1) -> -4 | T40: =S40*$J$2 -> -40 | V40: =IF(R40<>"",T40+R40+U40,0) -> 0
B41: =IF(H41>$H$2,"",(ROW()-5)) | H41: 36 | I41: =IF(H41<$H$2+1,($I$2-($I$2-1)*(LOG(H41)/LOG($H$2))),"") | J41: =INT(LOG($H$2,2))-ROUNDUP(LOG(H41,2),0)+IF(OR($H$2=1,$H$2=2,$H$2=4,$H$2=8,$H$2=16,$H$2=32,$H$2=64,$H$2=128,$H$2=256),0,1) -> -4 | K41: =J41*$J$2 -> -40 | M41: =IF(I41<>"",K41+I41+L41,0) -> 0 | O41: 36 | R41: =IF(O41<$O$2+1,($I$2-($I$2-1)*(LOG(O41)/LOG($O$2))),"") | S41: =INT(LOG($O$2,2))-ROUNDUP(LOG(O41,2),0)+IF(OR($O$2=1,$O$2=2,$O$2=4,$O$2=8,$O$2=16,$O$2=32,$O$2=64,$O$2=128,$O$2=256),0,1) -> -4 | T41: =S41*$J$2 -> -40 | V41: =IF(R41<>"",T41+R41+U41,0) -> 0
B42: =IF(H42>$H$2,"",(ROW()-5)) | H42: 37 | I42: =IF(H42<$H$2+1,($I$2-($I$2-1)*(LOG(H42)/LOG($H$2))),"") | J42: =INT(LOG($H$2,2))-ROUNDUP(LOG(H42,2),0)+IF(OR($H$2=1,$H$2=2,$H$2=4,$H$2=8,$H$2=16,$H$2=32,$H$2=64,$H$2=128,$H$2=256),0,1) -> -4 | K42: =J42*$J$2 -> -40 | M42: =IF(I42<>"",K42+I42+L42,0) -> 0 | O42: 37 | R42: =IF(O42<$O$2+1,($I$2-($I$2-1)*(LOG(O42)/LOG($O$2))),"") | S42: =INT(LOG($O$2,2))-ROUNDUP(LOG(O42,2),0)+IF(OR($O$2=1,$O$2=2,$O$2=4,$O$2=8,$O$2=16,$O$2=32,$O$2=64,$O$2=128,$O$2=256),0,1) -> -4 | T42: =S42*$J$2 -> -40 | V42: =IF(R42<>"",T42+R42+U42,0) -> 0
B43: =IF(H43>$H$2,"",(ROW()-5)) | H43: 38 | I43: =IF(H43<$H$2+1,($I$2-($I$2-1)*(LOG(H43)/LOG($H$2))),"") | J43: =INT(LOG($H$2,2))-ROUNDUP(LOG(H43,2),0)+IF(OR($H$2=1,$H$2=2,$H$2=4,$H$2=8,$H$2=16,$H$2=32,$H$2=64,$H$2=128,$H$2=256),0,1) -> -4 | K43: =J43*$J$2 -> -40 | M43: =IF(I43<>"",K43+I43+L43,0) -> 0 | O43: 38 | R43: =IF(O43<$O$2+1,($I$2-($I$2-1)*(LOG(O43)/LOG($O$2))),"") | S43: =INT(LOG($O$2,2))-ROUNDUP(LOG(O43,2),0)+IF(OR($O$2=1,$O$2=2,$O$2=4,$O$2=8,$O$2=16,$O$2=32,$O$2=64,$O$2=128,$O$2=256),0,1) -> -4 | T43: =S43*$J$2 -> -40 | V43: =IF(R43<>"",T43+R43+U43,0) -> 0
B44: =IF(H44>$H$2,"",(ROW()-5)) | H44: 39 | I44: =IF(H44<$H$2+1,($I$2-($I$2-1)*(LOG(H44)/LOG($H$2))),"") | J44: =INT(LOG($H$2,2))-ROUNDUP(LOG(H44,2),0)+IF(OR($H$2=1,$H$2=2,$H$2=4,$H$2=8,$H$2=16,$H$2=32,$H$2=64,$H$2=128,$H$2=256),0,1) -> -4 | K44: =J44*$J$2 -> -40 | M44: =IF(I44<>"",K44+I44+L44,0) -> 0 | O44: 39 | R44: =IF(O44<$O$2+1,($I$2-($I$2-1)*(LOG(O44)/LOG($O$2))),"") | S44: =INT(LOG($O$2,2))-ROUNDUP(LOG(O44,2),0)+IF(OR($O$2=1,$O$2=2,$O$2=4,$O$2=8,$O$2=16,$O$2=32,$O$2=64,$O$2=128,$O$2=256),0,1) -> -4 | T44: =S44*$J$2 -> -40 | V44: =IF(R44<>"",T44+R44+U44,0) -> 0
B45: =IF(H45>$H$2,"",(ROW()-5)) | H45: 40 | I45: =IF(H45<$H$2+1,($I$2-($I$2-1)*(LOG(H45)/LOG($H$2))),"") | J45: =INT(LOG($H$2,2))-ROUNDUP(LOG(H45,2),0)+IF(OR($H$2=1,$H$2=2,$H$2=4,$H$2=8,$H$2=16,$H$2=32,$H$2=64,$H$2=128,$H$2=256),0,1) -> -4 | K45: =J45*$J$2 -> -40 | M45: =IF(I45<>"",K45+I45+L45,0) -> 0 | O45: 40 | R45: =IF(O45<$O$2+1,($I$2-($I$2-1)*(LOG(O45)/LOG($O$2))),"") | S45: =INT(LOG($O$2,2))-ROUNDUP(LOG(O45,2),0)+IF(OR($O$2=1,$O$2=2,$O$2=4,$O$2=8,$O$2=16,$O$2=32,$O$2=64,$O$2=128,$O$2=256),0,1) -> -4 | T45: =S45*$J$2 -> -40 | V45: =IF(R45<>"",T45+R45+U45,0) -> 0
B46: =IF(H46>$H$2,"",(ROW()-5)) | H46: 41 | I46: =IF(H46<$H$2+1,($I$2-($I$2-1)*(LOG(H46)/LOG($H$2))),"") | J46: =INT(LOG($H$2,2))-ROUNDUP(LOG(H46,2),0)+IF(OR($H$2=1,$H$2=2,$H$2=4,$H$2=8,$H$2=16,$H$2=32,$H$2=64,$H$2=128,$H$2=256),0,1) -> -4 | K46: =J46*$J$2 -> -40 | M46: =IF(I46<>"",K46+I46+L46,0) -> 0 | O46: 41 | R46: =IF(O46<$O$2+1,($I$2-($I$2-1)*(LOG(O46)/LOG($O$2))),"") | S46: =INT(LOG($O$2,2))-ROUNDUP(LOG(O46,2),0)+IF(OR($O$2=1,$O$2=2,$O$2=4,$O$2=8,$O$2=16,$O$2=32,$O$2=64,$O$2=128,$O$2=256),0,1) -> -4 | T46: =S46*$J$2 -> -40 | V46: =IF(R46<>"",T46+R46+U46,0) -> 0
B47: =IF(H47>$H$2,"",(ROW()-5)) | H47: 42 | I47: =IF(H47<$H$2+1,($I$2-($I$2-1)*(LOG(H47)/LOG($H$2))),"") | J47: =INT(LOG($H$2,2))-ROUNDUP(LOG(H47,2),0)+IF(OR($H$2=1,$H$2=2,$H$2=4,$H$2=8,$H$2=16,$H$2=32,$H$2=64,$H$2=128,$H$2=256),0,1) -> -4 | K47: =J47*$J$2 -> -40 | M47: =IF(I47<>"",K47+I47+L47,0) -> 0 | O47: 42 | R47: =IF(O47<$O$2+1,($I$2-($I$2-1)*(LOG(O47)/LOG($O$2))),"") | S47: =INT(LOG($O$2,2))-ROUNDUP(LOG(O47,2),0)+IF(OR($O$2=1,$O$2=2,$O$2=4,$O$2=8,$O$2=16,$O$2=32,$O$2=64,$O$2=128,$O$2=256),0,1) -> -4 | T47: =S47*$J$2 -> -40 | V47: =IF(R47<>"",T47+R47+U47,0) -> 0
B48: =IF(H48>$H$2,"",(ROW()-5)) | H48: 43 | I48: =IF(H48<$H$2+1,($I$2-($I$2-1)*(LOG(H48)/LOG($H$2))),"") | J48: =INT(LOG($H$2,2))-ROUNDUP(LOG(H48,2),0)+IF(OR($H$2=1,$H$2=2,$H$2=4,$H$2=8,$H$2=16,$H$2=32,$H$2=64,$H$2=128,$H$2=256),0,1) -> -4 | K48: =J48*$J$2 -> -40 | M48: =IF(I48<>"",K48+I48+L48,0) -> 0 | O48: 43 | R48: =IF(O48<$O$2+1,($I$2-($I$2-1)*(LOG(O48)/LOG($O$2))),"") | S48: =INT(LOG($O$2,2))-ROUNDUP(LOG(O48,2),0)+IF(OR($O$2=1,$O$2=2,$O$2=4,$O$2=8,$O$2=16,$O$2=32,$O$2=64,$O$2=128,$O$2=256),0,1) -> -4 | T48: =S48*$J$2 -> -40 | V48: =IF(R48<>"",T48+R48+U48,0) -> 0
...

Sheet GP2
H1: Liczba uczestników: | I1: GP Punkty | J1: Bonus za rundę | K1: Bonus za podium | O1: Liczba uczestników połączonych kategorii: | T1: Mnożnik za podium
B2: miejsce: | C2: TORUŃ | H2: 3 | I2: 50 | J2: 10 | K2: =3*H2^(1/3) -> 4.3267487 | O2: 4 | T2: =3*O2^(1/3) -> 4.7622032
B3: data: | C3: 45019
O4: WYNIKI ŁĄCZONYCH KATEGORII
A5: Punkty | B5: Miejsce Place | C5: Nazwisko Imię Name | D5: Klub Club(s) | E5: Okręg Division | F5: Państwo Country | H5: Miejsce | I5: Punkty za miejsce | J5: awans do kolejnej rundy pucharowej | K5: bonus za rundy pucharowe | L5: punkty za podium | M5: Suma | O5: Miejsce | P5: NAZWISKO | R5: Punkty za miejsce | S5: awans do kolejnej rundy pucharowej | T5: bonus za rundy pucharowe | U5: punkty za podium | V5: Suma
A6: =M6 -> 82.980246 | B6: 1 | C6: GANSZCZYK Anna | D6: BYTOMSKIE TOWARZYSTWO SZERMIERCZE | H6: 1 | I6: =IF(H2=1,50,IF(H6<$H$2+1,($I$2-($I$2-1)*(LOG(H6)/LOG($H$2))),"")) -> 50 | J6: =INT(LOG($H$2,2))-ROUNDUP(LOG(H6,2),0)+IF(OR($H$2=1,$H$2=2,$H$2=4,$H$2=8,$H$2=16,$H$2=32,$H$2=64,$H$2=128,$H$2=256),0,1) -> 2 | K6: =J6*$J$2 -> 20 | L6: =3*K2 -> 12.980246 | M6: =IF(I6<>"",K6+I6+L6,0) -> 82.980246 | O6: 1 | P6: GANSZCZYK Anna | R6: =IF(O2=1,50,IF(O6<$O$2+1,($I$2-($I$2-1)*(LOG(O6)/LOG($O$2))),"")) -> 50 | S6: =INT(LOG($O$2,2))-ROUNDUP(LOG(O6,2),0)+IF(OR($O$2=1,$O$2=2,$O$2=4,$O$2=8,$O$2=16,$O$2=32,$O$2=64,$O$2=128,$O$2=256),0,1) -> 2 | T6: =S6*$J$2 -> 20 | U6: =3*T2 -> 14.286609 | V6: =IF(R6<>"",T6+R6+U6,0) -> 84.286609
A7: =M7 -> 37.737939 | B7: 2 | C7: WASILCZUK Beata | D7: IKS AWF WARSZAWA | H7: 2 | I7: =IF(H7<$H$2+1,($I$2-($I$2-1)*(LOG(H7)/LOG($H$2))),"") -> 19.084442 | J7: =INT(LOG($H$2,2))-ROUNDUP(LOG(H7,2),0)+IF(OR($H$2=1,$H$2=2,$H$2=4,$H$2=8,$H$2=16,$H$2=32,$H$2=64,$H$2=128,$H$2=256),0,1) -> 1 | K7: =J7*$J$2 -> 10 | L7: =2*K2 -> 8.6534974 | M7: =IF(I7<>"",K7+I7+L7,0) -> 37.737939 | O7: 2 | P7: WASILCZUK Beata | R7: =IF(O7<$O$2+1,($I$2-($I$2-1)*(LOG(O7)/LOG($O$2))),"") -> 25.5 | S7: =INT(LOG($O$2,2))-ROUNDUP(LOG(O7,2),0)+IF(OR($O$2=1,$O$2=2,$O$2=4,$O$2=8,$O$2=16,$O$2=32,$O$2=64,$O$2=128,$O$2=256),0,1) -> 1 | T7: =S7*$J$2 -> 10 | U7: =2*T2 -> 9.5244063 | V7: =IF(R7<>"",T7+R7+U7,0) -> 45.024406
A8: =M8 -> 5.3267487 | B8: 3 | C8: WALECKA Wanda | D8: Feniks Nowy Dwór Mazowiecki | H8: 3 | I8: =IF(H8<$H$2+1,($I$2-($I$2-1)*(LOG(H8)/LOG($H$2))),"") -> 1 | J8: =INT(LOG($H$2,2))-ROUNDUP(LOG(H8,2),0)+IF(OR($H$2=1,$H$2=2,$H$2=4,$H$2=8,$H$2=16,$H$2=32,$H$2=64,$H$2=128,$H$2=256),0,1) -> 0 | K8: =J8*$J$2 -> 0 | L8: =K2 -> 4.3267487 | M8: =IF(I8<>"",K8+I8+L8,0) -> 5.3267487 | O8: 3 | P8: WALECKA Wanda | R8: =IF(O8<$O$2+1,($I$2-($I$2-1)*(LOG(O8)/LOG($O$2))),"") -> 11.168419 | S8: =INT(LOG($O$2,2))-ROUNDUP(LOG(O8,2),0)+IF(OR($O$2=1,$O$2=2,$O$2=4,$O$2=8,$O$2=16,$O$2=32,$O$2=64,$O$2=128,$O$2=256),0,1) -> 0 | T8: =S8*$J$2 -> 0 | U8: =T2 -> 4.7622032 | V8: =IF(R8<>"",T8+R8+U8,0) -> 15.930622
A9: =M9 -> 0 | H9: 4 | I9: =IF(H9<$H$2+1,($I$2-($I$2-1)*(LOG(H9)/LOG($H$2))),"") | J9: =INT(LOG($H$2,2))-ROUNDUP(LOG(H9,2),0)+IF(OR($H$2=1,$H$2=2,$H$2=4,$H$2=8,$H$2=16,$H$2=32,$H$2=64,$H$2=128,$H$2=256),0,1) -> 0 | K9: =J9*$J$2 -> 0 | M9: =IF(I9<>"",K9+I9+L9,0) -> 0 | O9: 4 | P9: BORKOWSKA Halina | R9: =IF(O9<$O$2+1,($I$2-($I$2-1)*(LOG(O9)/LOG($O$2))),"") -> 1 | S9: =INT(LOG($O$2,2))-ROUNDUP(LOG(O9,2),0)+IF(OR($O$2=1,$O$2=2,$O$2=4,$O$2=8,$O$2=16,$O$2=32,$O$2=64,$O$2=128,$O$2=256),0,1) -> 0 | T9: =S9*$J$2 -> 0 | V9: =IF(R9<>"",T9+R9+U9,0) -> 1 | AH9: x | AI9: 23
A10: =M10 -> 0 | B10: =IF(H10>$H$2,"",(ROW()-5)) | H10: 5 | I10: =IF(H10<$H$2+1,($I$2-($I$2-1)*(LOG(H10)/LOG($H$2))),"") | J10: =INT(LOG($H$2,2))-ROUNDUP(LOG(H10,2),0)+IF(OR($H$2=1,$H$2=2,$H$2=4,$H$2=8,$H$2=16,$H$2=32,$H$2=64,$H$2=128,$H$2=256),0,1) -> -1 | K10: =J10*$J$2 -> -10 | M10: =IF(I10<>"",K10+I10+L10,0) -> 0 | O10: 5 | R10: =IF(O10<$O$2+1,($I$2-($I$2-1)*(LOG(O10)/LOG($O$2))),"") | S10: =INT(LOG($O$2,2))-ROUNDUP(LOG(O10,2),0)+IF(OR($O$2=1,$O$2=2,$O$2=4,$O$2=8,$O$2=16,$O$2=32,$O$2=64,$O$2=128,$O$2=256),0,1) -> -1 | T10: =S10*$J$2 -> -10 | V10: =IF(R10<>"",T10+R10+U10,0) -> 0 | AH10: N | AI10: 45
A11: =M11 -> 0 | B11: =IF(H11>$H$2,"",(ROW()-5)) | H11: 6 | I11: =IF(H11<$H$2+1,($I$2-($I$2-1)*(LOG(H11)/LOG($H$2))),"") | J11: =INT(LOG($H$2,2))-ROUNDUP(LOG(H11,2),0)+IF(OR($H$2=1,$H$2=2,$H$2=4,$H$2=8,$H$2=16,$H$2=32,$H$2=64,$H$2=128,$H$2=256),0,1) -> -1 | K11: =J11*$J$2 -> -10 | M11: =IF(I11<>"",K11+I11+L11,0) -> 0 | O11: 6 | R11: =IF(O11<$O$2+1,($I$2-($I$2-1)*(LOG(O11)/LOG($O$2))),"") | S11: =INT(LOG($O$2,2))-ROUNDUP(LOG(O11,2),0)+IF(OR($O$2=1,$O$2=2,$O$2=4,$O$2=8,$O$2=16,$O$2=32,$O$2=64,$O$2=128,$O$2=256),0,1) -> -1 | T11: =S11*$J$2 -> -10 | V11: =IF(R11<>"",T11+R11+U11,0) -> 0 | AH11: MP | AI11: 50
A12: =M12 -> 0 | B12: =IF(H12>$H$2,"",(ROW()-5)) | H12: 7 | I12: =IF(H12<$H$2+1,($I$2-($I$2-1)*(LOG(H12)/LOG($H$2))),"") | J12: =INT(LOG($H$2,2))-ROUNDUP(LOG(H12,2),0)+IF(OR($H$2=1,$H$2=2,$H$2=4,$H$2=8,$H$2=16,$H$2=32,$H$2=64,$H$2=128,$H$2=256),0,1) -> -1 | K12: =J12*$J$2 -> -10 | M12: =IF(I12<>"",K12+I12+L12,0) -> 0 | O12: 7 | R12: =IF(O12<$O$2+1,($I$2-($I$2-1)*(LOG(O12)/LOG($O$2))),"") | S12: =INT(LOG($O$2,2))-ROUNDUP(LOG(O12,2),0)+IF(OR($O$2=1,$O$2=2,$O$2=4,$O$2=8,$O$2=16,$O$2=32,$O$2=64,$O$2=128,$O$2=256),0,1) -> -1 | T12: =S12*$J$2 -> -10 | V12: =IF(R12<>"",T12+R12+U12,0) -> 0 | AH12: MP-1 | AI12: =AI11-1 -> 49
A13: =M13 -> 0 | B13: =IF(H13>$H$2,"",(ROW()-5)) | H13: 8 | I13: =IF(H13<$H$2+1,($I$2-($I$2-1)*(LOG(H13)/LOG($H$2))),"") | J13: =INT(LOG($H$2,2))-ROUNDUP(LOG(H13,2),0)+IF(OR($H$2=1,$H$2=2,$H$2=4,$H$2=8,$H$2=16,$H$2=32,$H$2=64,$H$2=128,$H$2=256),0,1) -> -1 | K13: =J13*$J$2 -> -10 | M13: =IF(I13<>"",K13+I13+L13,0) -> 0 | O13: 8 | R13: =IF(O13<$O$2+1,($I$2-($I$2-1)*(LOG(O13)/LOG($O$2))),"") | S13: =INT(LOG($O$2,2))-ROUNDUP(LOG(O13,2),0)+IF(OR($O$2=1,$O$2=2,$O$2=4,$O$2=8,$O$2=16,$O$2=32,$O$2=64,$O$2=128,$O$2=256),0,1) -> -1 | T13: =S13*$J$2 -> -10 | V13: =IF(R13<>"",T13+R13+U13,0) -> 0 | AH13: log(x) | AI13: =LOG(AI9) -> 1.3617278
A14: =M14 -> 0 | B14: =IF(H14>$H$2,"",(ROW()-5)) | H14: 9 | I14: =IF(H14<$H$2+1,($I$2-($I$2-1)*(LOG(H14)/LOG($H$2))),"") | J14: =INT(LOG($H$2,2))-ROUNDUP(LOG(H14,2),0)+IF(OR($H$2=1,$H$2=2,$H$2=4,$H$2=8,$H$2=16,$H$2=32,$H$2=64,$H$2=128,$H$2=256),0,1) -> -2 | K14: =J14*$J$2 -> -20 | M14: =IF(I14<>"",K14+I14+L14,0) -> 0 | O14: 9 | R14: =IF(O14<$O$2+1,($I$2-($I$2-1)*(LOG(O14)/LOG($O$2))),"") | S14: =INT(LOG($O$2,2))-ROUNDUP(LOG(O14,2),0)+IF(OR($O$2=1,$O$2=2,$O$2=4,$O$2=8,$O$2=16,$O$2=32,$O$2=64,$O$2=128,$O$2=256),0,1) -> -2 | T14: =S14*$J$2 -> -20 | V14: =IF(R14<>"",T14+R14+U14,0) -> 0 | AH14: Log(N) | AI14: =LOG(AI10) -> 1.6532125
A15: =M15 -> 0 | B15: =IF(H15>$H$2,"",(ROW()-5)) | H15: 10 | I15: =IF(H15<$H$2+1,($I$2-($I$2-1)*(LOG(H15)/LOG($H$2))),"") | J15: =INT(LOG($H$2,2))-ROUNDUP(LOG(H15,2),0)+IF(OR($H$2=1,$H$2=2,$H$2=4,$H$2=8,$H$2=16,$H$2=32,$H$2=64,$H$2=128,$H$2=256),0,1) -> -2 | K15: =J15*$J$2 -> -20 | M15: =IF(I15<>"",K15+I15+L15,0) -> 0 | O15: 10 | R15: =IF(O15<$O$2+1,($I$2-($I$2-1)*(LOG(O15)/LOG($O$2))),"") | S15: =INT(LOG($O$2,2))-ROUNDUP(LOG(O15,2),0)+IF(OR($O$2=1,$O$2=2,$O$2=4,$O$2=8,$O$2=16,$O$2=32,$O$2=64,$O$2=128,$O$2=256),0,1) -> -2 | T15: =S15*$J$2 -> -20 | V15: =IF(R15<>"",T15+R15+U15,0) -> 0
A16: =M16 -> 0 | B16: =IF(H16>$H$2,"",(ROW()-5)) | H16: 11 | I16: =IF(H16<$H$2+1,($I$2-($I$2-1)*(LOG(H16)/LOG($H$2))),"") | J16: =INT(LOG($H$2,2))-ROUNDUP(LOG(H16,2),0)+IF(OR($H$2=1,$H$2=2,$H$2=4,$H$2=8,$H$2=16,$H$2=32,$H$2=64,$H$2=128,$H$2=256),0,1) -> -2 | K16: =J16*$J$2 -> -20 | M16: =IF(I16<>"",K16+I16+L16,0) -> 0 | O16: 11 | R16: =IF(O16<$O$2+1,($I$2-($I$2-1)*(LOG(O16)/LOG($O$2))),"") | S16: =INT(LOG($O$2,2))-ROUNDUP(LOG(O16,2),0)+IF(OR($O$2=1,$O$2=2,$O$2=4,$O$2=8,$O$2=16,$O$2=32,$O$2=64,$O$2=128,$O$2=256),0,1) -> -2 | T16: =S16*$J$2 -> -20 | V16: =IF(R16<>"",T16+R16+U16,0) -> 0 | AH16: MP - (MP-1)*LOG(x)/LOG(N) | AI16: =AI11-AI12*AI13/AI14 -> 9.6393909 | AJ16: points
A17: =M17 -> 0 | B17: =IF(H17>$H$2,"",(ROW()-5)) | H17: 12 | I17: =IF(H17<$H$2+1,($I$2-($I$2-1)*(LOG(H17)/LOG($H$2))),"") | J17: =INT(LOG($H$2,2))-ROUNDUP(LOG(H17,2),0)+IF(OR($H$2=1,$H$2=2,$H$2=4,$H$2=8,$H$2=16,$H$2=32,$H$2=64,$H$2=128,$H$2=256),0,1) -> -2 | K17: =J17*$J$2 -> -20 | M17: =IF(I17<>"",K17+I17+L17,0) -> 0 | O17: 12 | R17: =IF(O17<$O$2+1,($I$2-($I$2-1)*(LOG(O17)/LOG($O$2))),"") | S17: =INT(LOG($O$2,2))-ROUNDUP(LOG(O17,2),0)+IF(OR($O$2=1,$O$2=2,$O$2=4,$O$2=8,$O$2=16,$O$2=32,$O$2=64,$O$2=128,$O$2=256),0,1) -> -2 | T17: =S17*$J$2 -> -20 | V17: =IF(R17<>"",T17+R17+U17,0) -> 0
A18: =M18 -> 0 | B18: =IF(H18>$H$2,"",(ROW()-5)) | H18: 13 | I18: =IF(H18<$H$2+1,($I$2-($I$2-1)*(LOG(H18)/LOG($H$2))),"") | J18: =INT(LOG($H$2,2))-ROUNDUP(LOG(H18,2),0)+IF(OR($H$2=1,$H$2=2,$H$2=4,$H$2=8,$H$2=16,$H$2=32,$H$2=64,$H$2=128,$H$2=256),0,1) -> -2 | K18: =J18*$J$2 -> -20 | M18: =IF(I18<>"",K18+I18+L18,0) -> 0 | O18: 13 | R18: =IF(O18<$O$2+1,($I$2-($I$2-1)*(LOG(O18)/LOG($O$2))),"") | S18: =INT(LOG($O$2,2))-ROUNDUP(LOG(O18,2),0)+IF(OR($O$2=1,$O$2=2,$O$2=4,$O$2=8,$O$2=16,$O$2=32,$O$2=64,$O$2=128,$O$2=256),0,1) -> -2 | T18: =S18*$J$2 -> -20 | V18: =IF(R18<>"",T18+R18+U18,0) -> 0
A19: =M19 -> 0 | B19: =IF(H19>$H$2,"",(ROW()-5)) | H19: 14 | I19: =IF(H19<$H$2+1,($I$2-($I$2-1)*(LOG(H19)/LOG($H$2))),"") | J19: =INT(LOG($H$2,2))-ROUNDUP(LOG(H19,2),0)+IF(OR($H$2=1,$H$2=2,$H$2=4,$H$2=8,$H$2=16,$H$2=32,$H$2=64,$H$2=128,$H$2=256),0,1) -> -2 | K19: =J19*$J$2 -> -20 | M19: =IF(I19<>"",K19+I19+L19,0) -> 0 | O19: 14 | R19: =IF(O19<$O$2+1,($I$2-($I$2-1)*(LOG(O19)/LOG($O$2))),"") | S19: =INT(LOG($O$2,2))-ROUNDUP(LOG(O19,2),0)+IF(OR($O$2=1,$O$2=2,$O$2=4,$O$2=8,$O$2=16,$O$2=32,$O$2=64,$O$2=128,$O$2=256),0,1) -> -2 | T19: =S19*$J$2 -> -20 | V19: =IF(R19<>"",T19+R19+U19,0) -> 0
A20: =M20 -> 0 | B20: =IF(H20>$H$2,"",(ROW()-5)) | H20: 15 | I20: =IF(H20<$H$2+1,($I$2-($I$2-1)*(LOG(H20)/LOG($H$2))),"") | J20: =INT(LOG($H$2,2))-ROUNDUP(LOG(H20,2),0)+IF(OR($H$2=1,$H$2=2,$H$2=4,$H$2=8,$H$2=16,$H$2=32,$H$2=64,$H$2=128,$H$2=256),0,1) -> -2 | K20: =J20*$J$2 -> -20 | M20: =IF(I20<>"",K20+I20+L20,0) -> 0 | O20: 15 | R20: =IF(O20<$O$2+1,($I$2-($I$2-1)*(LOG(O20)/LOG($O$2))),"") | S20: =INT(LOG($O$2,2))-ROUNDUP(LOG(O20,2),0)+IF(OR($O$2=1,$O$2=2,$O$2=4,$O$2=8,$O$2=16,$O$2=32,$O$2=64,$O$2=128,$O$2=256),0,1) -> -2 | T20: =S20*$J$2 -> -20 | V20: =IF(R20<>"",T20+R20+U20,0) -> 0
A21: =M21 -> 0 | B21: =IF(H21>$H$2,"",(ROW()-5)) | H21: 16 | I21: =IF(H21<$H$2+1,($I$2-($I$2-1)*(LOG(H21)/LOG($H$2))),"") | J21: =INT(LOG($H$2,2))-ROUNDUP(LOG(H21,2),0)+IF(OR($H$2=1,$H$2=2,$H$2=4,$H$2=8,$H$2=16,$H$2=32,$H$2=64,$H$2=128,$H$2=256),0,1) -> -2 | K21: =J21*$J$2 -> -20 | M21: =IF(I21<>"",K21+I21+L21,0) -> 0 | O21: 16 | R21: =IF(O21<$O$2+1,($I$2-($I$2-1)*(LOG(O21)/LOG($O$2))),"") | S21: =INT(LOG($O$2,2))-ROUNDUP(LOG(O21,2),0)+IF(OR($O$2=1,$O$2=2,$O$2=4,$O$2=8,$O$2=16,$O$2=32,$O$2=64,$O$2=128,$O$2=256),0,1) -> -2 | T21: =S21*$J$2 -> -20 | V21: =IF(R21<>"",T21+R21+U21,0) -> 0
A22: =M22 -> 0 | B22: =IF(H22>$H$2,"",(ROW()-5)) | H22: 17 | I22: =IF(H22<$H$2+1,($I$2-($I$2-1)*(LOG(H22)/LOG($H$2))),"") | J22: =INT(LOG($H$2,2))-ROUNDUP(LOG(H22,2),0)+IF(OR($H$2=1,$H$2=2,$H$2=4,$H$2=8,$H$2=16,$H$2=32,$H$2=64,$H$2=128,$H$2=256),0,1) -> -3 | K22: =J22*$J$2 -> -30 | M22: =IF(I22<>"",K22+I22+L22,0) -> 0 | O22: 17 | R22: =IF(O22<$O$2+1,($I$2-($I$2-1)*(LOG(O22)/LOG($O$2))),"") | S22: =INT(LOG($O$2,2))-ROUNDUP(LOG(O22,2),0)+IF(OR($O$2=1,$O$2=2,$O$2=4,$O$2=8,$O$2=16,$O$2=32,$O$2=64,$O$2=128,$O$2=256),0,1) -> -3 | T22: =S22*$J$2 -> -30 | V22: =IF(R22<>"",T22+R22+U22,0) -> 0
A23: =M23 -> 0 | B23: =IF(H23>$H$2,"",(ROW()-5)) | H23: 18 | I23: =IF(H23<$H$2+1,($I$2-($I$2-1)*(LOG(H23)/LOG($H$2))),"") | J23: =INT(LOG($H$2,2))-ROUNDUP(LOG(H23,2),0)+IF(OR($H$2=1,$H$2=2,$H$2=4,$H$2=8,$H$2=16,$H$2=32,$H$2=64,$H$2=128,$H$2=256),0,1) -> -3 | K23: =J23*$J$2 -> -30 | M23: =IF(I23<>"",K23+I23+L23,0) -> 0 | O23: 18 | R23: =IF(O23<$O$2+1,($I$2-($I$2-1)*(LOG(O23)/LOG($O$2))),"") | S23: =INT(LOG($O$2,2))-ROUNDUP(LOG(O23,2),0)+IF(OR($O$2=1,$O$2=2,$O$2=4,$O$2=8,$O$2=16,$O$2=32,$O$2=64,$O$2=128,$O$2=256),0,1) -> -3 | T23: =S23*$J$2 -> -30 | V23: =IF(R23<>"",T23+R23+U23,0) -> 0
A24: =M24 -> 0 | B24: =IF(H24>$H$2,"",(ROW()-5)) | H24: 19 | I24: =IF(H24<$H$2+1,($I$2-($I$2-1)*(LOG(H24)/LOG($H$2))),"") | J24: =INT(LOG($H$2,2))-ROUNDUP(LOG(H24,2),0)+IF(OR($H$2=1,$H$2=2,$H$2=4,$H$2=8,$H$2=16,$H$2=32,$H$2=64,$H$2=128,$H$2=256),0,1) -> -3 | K24: =J24*$J$2 -> -30 | M24: =IF(I24<>"",K24+I24+L24,0) -> 0 | O24: 19 | R24: =IF(O24<$O$2+1,($I$2-($I$2-1)*(LOG(O24)/LOG($O$2))),"") | S24: =INT(LOG($O$2,2))-ROUNDUP(LOG(O24,2),0)+IF(OR($O$2=1,$O$2=2,$O$2=4,$O$2=8,$O$2=16,$O$2=32,$O$2=64,$O$2=128,$O$2=256),0,1) -> -3 | T24: =S24*$J$2 -> -30 | V24: =IF(R24<>"",T24+R24+U24,0) -> 0
A25: =M25 -> 0 | B25: =IF(H25>$H$2,"",(ROW()-5)) | H25: 20 | I25: =IF(H25<$H$2+1,($I$2-($I$2-1)*(LOG(H25)/LOG($H$2))),"") | J25: =INT(LOG($H$2,2))-ROUNDUP(LOG(H25,2),0)+IF(OR($H$2=1,$H$2=2,$H$2=4,$H$2=8,$H$2=16,$H$2=32,$H$2=64,$H$2=128,$H$2=256),0,1) -> -3 | K25: =J25*$J$2 -> -30 | M25: =IF(I25<>"",K25+I25+L25,0) -> 0 | O25: 20 | R25: =IF(O25<$O$2+1,($I$2-($I$2-1)*(LOG(O25)/LOG($O$2))),"") | S25: =INT(LOG($O$2,2))-ROUNDUP(LOG(O25,2),0)+IF(OR($O$2=1,$O$2=2,$O$2=4,$O$2=8,$O$2=16,$O$2=32,$O$2=64,$O$2=128,$O$2=256),0,1) -> -3 | T25: =S25*$J$2 -> -30 | V25: =IF(R25<>"",T25+R25+U25,0) -> 0
A26: =M26 -> 0 | B26: =IF(H26>$H$2,"",(ROW()-5)) | H26: 21 | I26: =IF(H26<$H$2+1,($I$2-($I$2-1)*(LOG(H26)/LOG($H$2))),"") | J26: =INT(LOG($H$2,2))-ROUNDUP(LOG(H26,2),0)+IF(OR($H$2=1,$H$2=2,$H$2=4,$H$2=8,$H$2=16,$H$2=32,$H$2=64,$H$2=128,$H$2=256),0,1) -> -3 | K26: =J26*$J$2 -> -30 | M26: =IF(I26<>"",K26+I26+L26,0) -> 0 | O26: 21 | R26: =IF(O26<$O$2+1,($I$2-($I$2-1)*(LOG(O26)/LOG($O$2))),"") | S26: =INT(LOG($O$2,2))-ROUNDUP(LOG(O26,2),0)+IF(OR($O$2=1,$O$2=2,$O$2=4,$O$2=8,$O$2=16,$O$2=32,$O$2=64,$O$2=128,$O$2=256),0,1) -> -3 | T26: =S26*$J$2 -> -30 | V26: =IF(R26<>"",T26+R26+U26,0) -> 0
A27: =M27 -> 0 | B27: =IF(H27>$H$2,"",(ROW()-5)) | H27: 22 | I27: =IF(H27<$H$2+1,($I$2-($I$2-1)*(LOG(H27)/LOG($H$2))),"") | J27: =INT(LOG($H$2,2))-ROUNDUP(LOG(H27,2),0)+IF(OR($H$2=1,$H$2=2,$H$2=4,$H$2=8,$H$2=16,$H$2=32,$H$2=64,$H$2=128,$H$2=256),0,1) -> -3 | K27: =J27*$J$2 -> -30 | M27: =IF(I27<>"",K27+I27+L27,0) -> 0 | O27: 22 | R27: =IF(O27<$O$2+1,($I$2-($I$2-1)*(LOG(O27)/LOG($O$2))),"") | S27: =INT(LOG($O$2,2))-ROUNDUP(LOG(O27,2),0)+IF(OR($O$2=1,$O$2=2,$O$2=4,$O$2=8,$O$2=16,$O$2=32,$O$2=64,$O$2=128,$O$2=256),0,1) -> -3 | T27: =S27*$J$2 -> -30 | V27: =IF(R27<>"",T27+R27+U27,0) -> 0
A28: =M28 -> 0 | B28: =IF(H28>$H$2,"",(ROW()-5)) | H28: 23 | I28: =IF(H28<$H$2+1,($I$2-($I$2-1)*(LOG(H28)/LOG($H$2))),"") | J28: =INT(LOG($H$2,2))-ROUNDUP(LOG(H28,2),0)+IF(OR($H$2=1,$H$2=2,$H$2=4,$H$2=8,$H$2=16,$H$2=32,$H$2=64,$H$2=128,$H$2=256),0,1) -> -3 | K28: =J28*$J$2 -> -30 | M28: =IF(I28<>"",K28+I28+L28,0) -> 0 | O28: 23 | R28: =IF(O28<$O$2+1,($I$2-($I$2-1)*(LOG(O28)/LOG($O$2))),"") | S28: =INT(LOG($O$2,2))-ROUNDUP(LOG(O28,2),0)+IF(OR($O$2=1,$O$2=2,$O$2=4,$O$2=8,$O$2=16,$O$2=32,$O$2=64,$O$2=128,$O$2=256),0,1) -> -3 | T28: =S28*$J$2 -> -30 | V28: =IF(R28<>"",T28+R28+U28,0) -> 0
... A37: =M37 -> 0 | B37: =IF(H37>$H$2,"",(ROW()-5)) | H37: 32 | I37: =IF(H37<$H$2+1,($I$2-($I$2-1)*(LOG(H37)/LOG($H$2))),"") | J37: =INT(LOG($H$2,2))-ROUNDUP(LOG(H37,2),0)+IF(OR($H$2=1,$H$2=2,$H$2=4,$H$2=8,$H$2=16,$H$2=32,$H$2=64,$H$2=128,$H$2=256),0,1) -> -3 | K37: =J37*$J$2 -> -30 | M37: =IF(I37<>"",K37+I37+L37,0) -> 0 | O37: 32 | R37: =IF(O37<$O$2+1,($I$2-($I$2-1)*(LOG(O37)/LOG($O$2))),"") | S37: =INT(LOG($O$2,2))-ROUNDUP(LOG(O37,2),0)+IF(OR($O$2=1,$O$2=2,$O$2=4,$O$2=8,$O$2=16,$O$2=32,$O$2=64,$O$2=128,$O$2=256),0,1) -> -3 | T37: =S37*$J$2 -> -30 | V37: =IF(R37<>"",T37+R37+U37,0) -> 0
B38: =IF(H38>$H$2,"",(ROW()-5)) | H38: 33 | I38: =IF(H38<$H$2+1,($I$2-($I$2-1)*(LOG(H38)/LOG($H$2))),"") | J38: =INT(LOG($H$2,2))-ROUNDUP(LOG(H38,2),0)+IF(OR($H$2=1,$H$2=2,$H$2=4,$H$2=8,$H$2=16,$H$2=32,$H$2=64,$H$2=128,$H$2=256),0,1) -> -4 | K38: =J38*$J$2 -> -40 | M38: =IF(I38<>"",K38+I38+L38,0) -> 0 | O38: 33 | R38: =IF(O38<$O$2+1,($I$2-($I$2-1)*(LOG(O38)/LOG($O$2))),"") | S38: =INT(LOG($O$2,2))-ROUNDUP(LOG(O38,2),0)+IF(OR($O$2=1,$O$2=2,$O$2=4,$O$2=8,$O$2=16,$O$2=32,$O$2=64,$O$2=128,$O$2=256),0,1) -> -4 | T38: =S38*$J$2 -> -40 | V38: =IF(R38<>"",T38+R38+U38,0) -> 0
B39: =IF(H39>$H$2,"",(ROW()-5)) | H39: 34 | I39: =IF(H39<$H$2+1,($I$2-($I$2-1)*(LOG(H39)/LOG($H$2))),"") | J39: =INT(LOG($H$2,2))-ROUNDUP(LOG(H39,2),0)+IF(OR($H$2=1,$H$2=2,$H$2=4,$H$2=8,$H$2=16,$H$2=32,$H$2=64,$H$2=128,$H$2=256),0,1) -> -4 | K39: =J39*$J$2 -> -40 | M39: =IF(I39<>"",K39+I39+L39,0) -> 0 | O39: 34 | R39: =IF(O39<$O$2+1,($I$2-($I$2-1)*(LOG(O39)/LOG($O$2))),"") | S39: =INT(LOG($O$2,2))-ROUNDUP(LOG(O39,2),0)+IF(OR($O$2=1,$O$2=2,$O$2=4,$O$2=8,$O$2=16,$O$2=32,$O$2=64,$O$2=128,$O$2=256),0,1) -> -4 | T39: =S39*$J$2 -> -40 | V39: =IF(R39<>"",T39+R39+U39,0) -> 0
B40: =IF(H40>$H$2,"",(ROW()-5)) | H40: 35 | I40: =IF(H40<$H$2+1,($I$2-($I$2-1)*(LOG(H40)/LOG($H$2))),"") | J40: =INT(LOG($H$2,2))-ROUNDUP(LOG(H40,2),0)+IF(OR($H$2=1,$H$2=2,$H$2=4,$H$2=8,$H$2=16,$H$2=32,$H$2=64,$H$2=128,$H$2=256),0,1) -> -4 | K40: =J40*$J$2 -> -40 | M40: =IF(I40<>"",K40+I40+L40,0) -> 0 | O40: 35 | R40: =IF(O40<$O$2+1,($I$2-($I$2-1)*(LOG(O40)/LOG($O$2))),"") | S40: =INT(LOG($O$2,2))-ROUNDUP(LOG(O40,2),0)+IF(OR($O$2=1,$O$2=2,$O$2=4,$O$2=8,$O$2=16,$O$2=32,$O$2=64,$O$2=128,$O$2=256),0,1) -> -4 | T40: =S40*$J$2 -> -40 | V40: =IF(R40<>"",T40+R40+U40,0) -> 0
B41: =IF(H41>$H$2,"",(ROW()-5)) | H41: 36 | I41: =IF(H41<$H$2+1,($I$2-($I$2-1)*(LOG(H41)/LOG($H$2))),"") | J41: =INT(LOG($H$2,2))-ROUNDUP(LOG(H41,2),0)+IF(OR($H$2=1,$H$2=2,$H$2=4,$H$2=8,$H$2=16,$H$2=32,$H$2=64,$H$2=128,$H$2=256),0,1) -> -4 | K41: =J41*$J$2 -> -40 | M41: =IF(I41<>"",K41+I41+L41,0) -> 0 | O41: 36 | R41: =IF(O41<$O$2+1,($I$2-($I$2-1)*(LOG(O41)/LOG($O$2))),"") | S41: =INT(LOG($O$2,2))-ROUNDUP(LOG(O41,2),0)+IF(OR($O$2=1,$O$2=2,$O$2=4,$O$2=8,$O$2=16,$O$2=32,$O$2=64,$O$2=128,$O$2=256),0,1) -> -4 | T41: =S41*$J$2 -> -40 | V41: =IF(R41<>"",T41+R41+U41,0) -> 0
B42: =IF(H42>$H$2,"",(ROW()-5)) | H42: 37 | I42: =IF(H42<$H$2+1,($I$2-($I$2-1)*(LOG(H42)/LOG($H$2))),"") | J42: =INT(LOG($H$2,2))-ROUNDUP(LOG(H42,2),0)+IF(OR($H$2=1,$H$2=2,$H$2=4,$H$2=8,$H$2=16,$H$2=32,$H$2=64,$H$2=128,$H$2=256),0,1) -> -4 | K42: =J42*$J$2 -> -40 | M42: =IF(I42<>"",K42+I42+L42,0) -> 0 | O42: 37 | R42: =IF(O42<$O$2+1,($I$2-($I$2-1)*(LOG(O42)/LOG($O$2))),"") | S42: =INT(LOG($O$2,2))-ROUNDUP(LOG(O42,2),0)+IF(OR($O$2=1,$O$2=2,$O$2=4,$O$2=8,$O$2=16,$O$2=32,$O$2=64,$O$2=128,$O$2=256),0,1) -> -4 | T42: =S42*$J$2 -> -40 | V42: =IF(R42<>"",T42+R42+U42,0) -> 0
B43: =IF(H43>$H$2,"",(ROW()-5)) | H43: 38 | I43: =IF(H43<$H$2+1,($I$2-($I$2-1)*(LOG(H43)/LOG($H$2))),"") | J43: =INT(LOG($H$2,2))-ROUNDUP(LOG(H43,2),0)+IF(OR($H$2=1,$H$2=2,$H$2=4,$H$2=8,$H$2=16,$H$2=32,$H$2=64,$H$2=128,$H$2=256),0,1) -> -4 | K43: =J43*$J$2 -> -40 | M43: =IF(I43<>"",K43+I43+L43,0) -> 0 | O43: 38 | R43: =IF(O43<$O$2+1,($I$2-($I$2-1)*(LOG(O43)/LOG($O$2))),"") | S43: =INT(LOG($O$2,2))-ROUNDUP(LOG(O43,2),0)+IF(OR($O$2=1,$O$2=2,$O$2=4,$O$2=8,$O$2=16,$O$2=32,$O$2=64,$O$2=128,$O$2=256),0,1) -> -4 | T43: =S43*$J$2 -> -40 | V43: =IF(R43<>"",T43+R43+U43,0) -> 0
B44: =IF(H44>$H$2,"",(ROW()-5)) | H44: 39 | I44: =IF(H44<$H$2+1,($I$2-($I$2-1)*(LOG(H44)/LOG($H$2))),"") | J44: =INT(LOG($H$2,2))-ROUNDUP(LOG(H44,2),0)+IF(OR($H$2=1,$H$2=2,$H$2=4,$H$2=8,$H$2=16,$H$2=32,$H$2=64,$H$2=128,$H$2=256),0,1) -> -4 | K44: =J44*$J$2 -> -40 | M44: =IF(I44<>"",K44+I44+L44,0) -> 0 | O44: 39 | R44: =IF(O44<$O$2+1,($I$2-($I$2-1)*(LOG(O44)/LOG($O$2))),"") | S44: =INT(LOG($O$2,2))-ROUNDUP(LOG(O44,2),0)+IF(OR($O$2=1,$O$2=2,$O$2=4,$O$2=8,$O$2=16,$O$2=32,$O$2=64,$O$2=128,$O$2=256),0,1) -> -4 | T44: =S44*$J$2 -> -40 | V44: =IF(R44<>"",T44+R44+U44,0) -> 0
B45: =IF(H45>$H$2,"",(ROW()-5)) | H45: 40 | I45: =IF(H45<$H$2+1,($I$2-($I$2-1)*(LOG(H45)/LOG($H$2))),"") | J45: =INT(LOG($H$2,2))-ROUNDUP(LOG(H45,2),0)+IF(OR($H$2=1,$H$2=2,$H$2=4,$H$2=8,$H$2=16,$H$2=32,$H$2=64,$H$2=128,$H$2=256),0,1) -> -4 | K45: =J45*$J$2 -> -40 | M45: =IF(I45<>"",K45+I45+L45,0) -> 0 | O45: 40 | R45: =IF(O45<$O$2+1,($I$2-($I$2-1)*(LOG(O45)/LOG($O$2))),"") | S45: =INT(LOG($O$2,2))-ROUNDUP(LOG(O45,2),0)+IF(OR($O$2=1,$O$2=2,$O$2=4,$O$2=8,$O$2=16,$O$2=32,$O$2=64,$O$2=128,$O$2=256),0,1) -> -4 | T45: =S45*$J$2 -> -40 | V45: =IF(R45<>"",T45+R45+U45,0) -> 0
B46: =IF(H46>$H$2,"",(ROW()-5)) | H46: 41 | I46: =IF(H46<$H$2+1,($I$2-($I$2-1)*(LOG(H46)/LOG($H$2))),"") | J46: =INT(LOG($H$2,2))-ROUNDUP(LOG(H46,2),0)+IF(OR($H$2=1,$H$2=2,$H$2=4,$H$2=8,$H$2=16,$H$2=32,$H$2=64,$H$2=128,$H$2=256),0,1) -> -4 | K46: =J46*$J$2 -> -40 | M46: =IF(I46<>"",K46+I46+L46,0) -> 0 | O46: 41 | R46: =IF(O46<$O$2+1,($I$2-($I$2-1)*(LOG(O46)/LOG($O$2))),"") | S46: =INT(LOG($O$2,2))-ROUNDUP(LOG(O46,2),0)+IF(OR($O$2=1,$O$2=2,$O$2=4,$O$2=8,$O$2=16,$O$2=32,$O$2=64,$O$2=128,$O$2=256),0,1) -> -4 | T46: =S46*$J$2 -> -40 | V46: =IF(R46<>"",T46+R46+U46,0) -> 0
