Workbook

Sheet Lista osób
E1: DEKLARACJA CZŁONKOWSKA
A2: LP | B2: NAZWISKO I IMIĘ | C2: ADRES EMAIL | D2: TELEFON | E2: DEKLARACJA | F2: PDF | G2: RODO | H2: Komentarz
A3: =ROW()-2 -> 1 | B3: Adamczewski Wojciech | C3: wojtekadamczewski52@gmail.com | D3: 501064047 | E3: TAK | F3: TAK | G3: =IF(E3="TAK","TAK","?") -> TAK
A4: =ROW()-2 -> 2 | B4: Adamczyk Grzegorz | E4: ? | F4: ? | G4: =IF(E4="TAK","TAK","?") -> ?
A5: =ROW()-2 -> 3 | B5: Adamska Maria | C5: komormaria@gmail.com | E5: ? | F5: ? | G5: =IF(E5="TAK","TAK","?") -> ?
A6: =ROW()-2 -> 4 | B6: Andersch Robert | E6: ? | F6: ? | G6: =IF(E6="TAK","TAK","?") -> ?
A7: =ROW()-2 -> 5 | B7: Atanassow Aleksander | C7: a.atanassow@gmail.com a.atanassow@protonmail.com | D7: 501488111 | E7: TAK | F7: TAK | G7: =IF(E7="TAK","TAK","?") -> TAK
A8: =ROW()-2 -> 6 | B8: Augustowski Waldemar | C8: waldemar.augustowski@ins.com.pl | D8: 505195111 | E8: TAK | F8: TAK | G8: =IF(E8="TAK","TAK","?") -> TAK
A9: =ROW()-2 -> 7 | B9: Augustyn Kajetan | E9: ? | F9: ? | G9: =IF(E9="TAK","TAK","?") -> ?
A10: =ROW()-2 -> 8 | B10: Baran Agata | C10: agata.baran@poczta.onet.pl | D10: 604425269 | E10: TAK | F10: TAK | G10: =IF(E10="TAK","TAK","?") -> TAK
A11: =ROW()-2 -> 9 | B11: Barański Wacław | C11: wbaranski@horn-poland.pl | D11: 501457669 | E11: NIE | F11: TAK | G11: =IF(E11="TAK","TAK","?") -> ? | H11: Rezygnacja
A12: =ROW()-2 -> 10 | B12: Bartusik Grzegorz | C12: r.bartusik@gmail.com | D12: 799891797 | E12: TAK | F12: TAK | G12: =IF(E12="TAK","TAK","?") -> TAK
A13: =ROW()-2 -> 11 | B13: Bazak Jacek | C13: jacek.bazak@myhs.eu | D13: 505061114 | E13: TAK | F13: TAK | G13: =IF(E13="TAK","TAK","?") -> TAK
A14: =ROW()-2 -> 12 | B14: Bednarska Halina | C14: halinatrzensiok@gmail.com | D14: 604559134 | E14: TAK | F14: TAK | G14: =IF(E14="TAK","TAK","?") -> TAK
A15: =ROW()-2 -> 13 | B15: Bednarz Przemysław | C15: przemekbednarz007@gmail.com | D15: 507286690 | E15: TAK | F15: TAK | G15: =IF(E15="TAK","TAK","?") -> TAK
A16: =ROW()-2 -> 14 | B16: Betlej Daniel | C16: daniel.betlej@wp.pl | D16: 691130100 | E16: TAK | F16: TAK | G16: =IF(E16="TAK","TAK","?") -> TAK
A17: =ROW()-2 -> 15 | B17: Betleja Artur | C17: art_bee@onet.eu | E17: ? | F17: ? | G17: =IF(E17="TAK","TAK","?") -> ?
A18: =ROW()-2 -> 16 | B18: Bobusia Dariusz | C18: dareo.krosno@mail.com | D18: 447511102501 | E18: TAK | F18: TAK | G18: =IF(E18="TAK","TAK","?") -> TAK
A19: =ROW()-2 -> 17 | B19: Bobusia Jarosław | C19: urliczko@interia.pl | D19: 517954679 | E19: TAK | F19: TAK | G19: =IF(E19="TAK","TAK","?") -> TAK
A20: =ROW()-2 -> 18 | B20: Bonik-Ninard Agata | E20: ? | F20: ? | G20: =IF(E20="TAK","TAK","?") -> ?
A21: =ROW()-2 -> 19 | B21: Borkowska Halina | C21: borkowska-halina@wp.pl | D21: 605651010 | E21: TAK | F21: TAK | G21: =IF(E21="TAK","TAK","?") -> TAK
A22: =ROW()-2 -> 20 | B22: Borkowski Andrzej | C22: andrzej-rajmund@wp.pl | D22: 666640656 | E22: TAK | F22: TAK | G22: =IF(E22="TAK","TAK","?") -> TAK
A23: =ROW()-2 -> 21 | B23: Borysiuk Zbigniew | C23: z.borysiuk@po.edu.pl | D23: 606327299 | E23: TAK | F23: TAK | G23: =IF(E23="TAK","TAK","?") -> TAK
A24: =ROW()-2 -> 22 | B24: Bromberek Angelika | E24: ? | F24: ? | G24: =IF(E24="TAK","TAK","?") -> ?
A25: =ROW()-2 -> 23 | B25: Brosch Artur | E25: ? | F25: ? | G25: =IF(E25="TAK","TAK","?") -> ?
A26: =ROW()-2 -> 24 | B26: Bujko Jacek | E26: ? | F26: ? | G26: =IF(E26="TAK","TAK","?") -> ?
A27: =ROW()-2 -> 25 | B27: Bujko Paulina | E27: ? | F27: ? | G27: =IF(E27="TAK","TAK","?") -> ?
A28: =ROW()-2 -> 26 | B28: Burlikowski Bartosz | C28: bburlikowski@gmail.com | D28: 500051007 | E28: TAK | F28: TAK | G28: =IF(E28="TAK","TAK","?") -> TAK
A29: =ROW()-2 -> 27 | B29: Caniard Henry | E29: ? | F29: ? | G29: =IF(E29="TAK","TAK","?") -> ?
A30: =ROW()-2 -> 28 | B30: Chmielewska Emilia | C30: chmielewska.emilia@gmail.com | D30: 696063845 | E30: TAK | F30: TAK | G30: =IF(E30="TAK","TAK","?") -> TAK
A31: =ROW()-2 -> 29 | B31: Chojnacki Tomasz | C31: chojna877@o2.pl | E31: ? | F31: ? | G31: =IF(E31="TAK","TAK","?") -> ?
A32: =ROW()-2 -> 30 | B32: Chojnecki Mateusz | C32: mateuszchojnecki@gmail.com | D32: 608294480 | E32: TAK | F32: TAK | G32: =IF(E32="TAK","TAK","?") -> TAK
A33: =ROW()-2 -> 31 | B33: Chudycki Artur | C33: chudycki@poczta.onet.pl | D33: 603204624 | E33: TAK | F33: TAK | G33: =IF(E33="TAK","TAK","?") -> TAK
A34: =ROW()-2 -> 32 | B34: Ciepły Tomasz | C34: cieplytom@gmail.com | D34: 502560769 | E34: TAK | F34: TAK | G34: =IF(E34="TAK","TAK","?") -> TAK
A35: =ROW()-2 -> 33 | B35: Cygański Tomasz | C35: cygan160@op.pl | D35: 603868477 | E35: TAK | F35: TAK | G35: =IF(E35="TAK","TAK","?") -> TAK
A36: =ROW()-2 -> 34 | B36: Czajkowski Marcin | C36: marcin@videotesty.pl | D36: 513006604 | E36: TAK | F36: TAK | G36: =IF(E36="TAK","TAK","?") -> TAK
A37: =ROW()-2 -> 35 | B37: Ćwioro Krzysztof | C37: kcwioro@grupa-logo.pl | D37: 600316820 | E37: TAK | F37: TAK | G37: =IF(E37="TAK","TAK","?") -> TAK
A38: =ROW()-2 -> 36 | B38: Ćwioro Tomasz | C38: tomekcwioro@gmail.com | D38: 733547733 | E38: TAK | F38: TAK | G38: =IF(E38="TAK","TAK","?") -> TAK
A39: =ROW()-2 -> 37 | B39: Damian Mateusz | C39: dziubek2_88@o2.pl | D39: 51333213 | E39: TAK | F39: TAK | G39: =IF(E39="TAK","TAK","?") -> TAK
A40: =ROW()-2 -> 38 | B40: Darul Tomasz | E40: ? | F40: ? | G40: =IF(E40="TAK","TAK","?") -> ?
...

Sheet Kategorie wiekowe
A1: LP | B1: NAZWISKO I IMIĘ | C1: DATA URODZENIA | E1: KATEGORIA
C2: DD/MM | D2: ROK
A3: =ROW()-2 -> 1 | B3: Adamczewski Wojciech | C3: 27/03 | D3: 1952 | E3: =IF(ISBLANK(D3),"?",IF(D3<=Slowniki!F$7,4,IF(D3<=Slowniki!F$6,3,IF(D3<=Slowniki!F$5,2,IF(D3<=Slowniki!F$4,1,0))))) -> 4
A4: =ROW()-2 -> 2 | B4: Adamczyk Grzegorz | E4: =IF(ISBLANK(D4),"?",IF(D4<=Slowniki!F$7,4,IF(D4<=Slowniki!F$6,3,IF(D4<=Slowniki!F$5,2,IF(D4<=Slowniki!F$4,1,0))))) -> ?
A5: =ROW()-2 -> 3 | B5: Adamska Maria | C5: 23/07 | D5: 1979 | E5: =IF(ISBLANK(D5),"?",IF(D5<=Slowniki!F$7,4,IF(D5<=Slowniki!F$6,3,IF(D5<=Slowniki!F$5,2,IF(D5<=Slowniki!F$4,1,0))))) -> 1
A6: =ROW()-2 -> 4 | B6: Andersch Robert | E6: =IF(ISBLANK(D6),"?",IF(D6<=Slowniki!F$7,4,IF(D6<=Slowniki!F$6,3,IF(D6<=Slowniki!F$5,2,IF(D6<=Slowniki!F$4,1,0))))) -> ?
A7: =ROW()-2 -> 5 | B7: Atanassow Aleksander | C7: 13/02 | D7: 1969 | E7: =IF(ISBLANK(D7),"?",IF(D7<=Slowniki!F$7,4,IF(D7<=Slowniki!F$6,3,IF(D7<=Slowniki!F$5,2,IF(D7<=Slowniki!F$4,1,0))))) -> 2
A8: =ROW()-2 -> 6 | B8: Augustowski Waldemar | C8: 15/03 | D8: 1959 | E8: =IF(ISBLANK(D8),"?",IF(D8<=Slowniki!F$7,4,IF(D8<=Slowniki!F$6,3,IF(D8<=Slowniki!F$5,2,IF(D8<=Slowniki!F$4,1,0))))) -> 3
A9: =ROW()-2 -> 7 | B9: Augustyn Kajetan | E9: =IF(ISBLANK(D9),"?",IF(D9<=Slowniki!F$7,4,IF(D9<=Slowniki!F$6,3,IF(D9<=Slowniki!F$5,2,IF(D9<=Slowniki!F$4,1,0))))) -> ?
A10: =ROW()-2 -> 8 | B10: Baran Agata | C10: 05/03 | D10: 1986 | E10: =IF(ISBLANK(D10),"?",IF(D10<=Slowniki!F$7,4,IF(D10<=Slowniki!F$6,3,IF(D10<=Slowniki!F$5,2,IF(D10<=Slowniki!F$4,1,0))))) -> 1
A11: =ROW()-2 -> 9 | B11: Barański Wacław | C11: 16/12 | D11: 1964 | E11: =IF(ISBLANK(D11),"?",IF(D11<=Slowniki!F$7,4,IF(D11<=Slowniki!F$6,3,IF(D11<=Slowniki!F$5,2,IF(D11<=Slowniki!F$4,1,0))))) -> 3
A12: =ROW()-2 -> 10 | B12: Bartusik Grzegorz | C12: 23/05 | D12: 1990 | E12: =IF(ISBLANK(D12),"?",IF(D12<=Slowniki!F$7,4,IF(D12<=Slowniki!F$6,3,IF(D12<=Slowniki!F$5,2,IF(D12<=Slowniki!F$4,1,0))))) -> 0
A13: =ROW()-2 -> 11 | B13: Bazak Jacek | C13: 10/03 | D13: 1974 | E13: =IF(ISBLANK(D13),"?",IF(D13<=Slowniki!F$7,4,IF(D13<=Slowniki!F$6,3,IF(D13<=Slowniki!F$5,2,IF(D13<=Slowniki!F$4,1,0))))) -> 2
A14: =ROW()-2 -> 12 | B14: Bednarska Halina | C14: 29/04 | D14: 1968 | E14: =IF(ISBLANK(D14),"?",IF(D14<=Slowniki!F$7,4,IF(D14<=Slowniki!F$6,3,IF(D14<=Slowniki!F$5,2,IF(D14<=Slowniki!F$4,1,0))))) -> 2
A15: =ROW()-2 -> 13 | B15: Bednarz Przemysław | C15: 14/10 | D15: 1984 | E15: =IF(ISBLANK(D15),"?",IF(D15<=Slowniki!F$7,4,IF(D15<=Slowniki!F$6,3,IF(D15<=Slowniki!F$5,2,IF(D15<=Slowniki!F$4,1,0))))) -> 1
A16: =ROW()-2 -> 14 | B16: Betlej Daniel | C16: 12/02 | D16: 1977 | E16: =IF(ISBLANK(D16),"?",IF(D16<=Slowniki!F$7,4,IF(D16<=Slowniki!F$6,3,IF(D16<=Slowniki!F$5,2,IF(D16<=Slowniki!F$4,1,0))))) -> 1
A17: =ROW()-2 -> 15 | B17: Betleja Artur | C17: 15/07 | D17: 1984 | E17: =IF(ISBLANK(D17),"?",IF(D17<=Slowniki!F$7,4,IF(D17<=Slowniki!F$6,3,IF(D17<=Slowniki!F$5,2,IF(D17<=Slowniki!F$4,1,0))))) -> 1
A18: =ROW()-2 -> 16 | B18: Bobusia Dariusz | C18: 22/06 | D18: 1984 | E18: =IF(ISBLANK(D18),"?",IF(D18<=Slowniki!F$7,4,IF(D18<=Slowniki!F$6,3,IF(D18<=Slowniki!F$5,2,IF(D18<=Slowniki!F$4,1,0))))) -> 1
A19: =ROW()-2 -> 17 | B19: Bobusia Jarosław | C19: 10/06 | D19: 1985 | E19: =IF(ISBLANK(D19),"?",IF(D19<=Slowniki!F$7,4,IF(D19<=Slowniki!F$6,3,IF(D19<=Slowniki!F$5,2,IF(D19<=Slowniki!F$4,1,0))))) -> 1
A20: =ROW()-2 -> 18 | B20: Bonik-Ninard Agata | E20: =IF(ISBLANK(D20),"?",IF(D20<=Slowniki!F$7,4,IF(D20<=Slowniki!F$6,3,IF(D20<=Slowniki!F$5,2,IF(D20<=Slowniki!F$4,1,0))))) -> ?
A21: =ROW()-2 -> 19 | B21: Borkowska Halina | C21: 27/02 | D21: 1956 | E21: =IF(ISBLANK(D21),"?",IF(D21<=Slowniki!F$7,4,IF(D21<=Slowniki!F$6,3,IF(D21<=Slowniki!F$5,2,IF(D21<=Slowniki!F$4,1,0))))) -> 4
A22: =ROW()-2 -> 20 | B22: Borkowski Andrzej | C22: 10/11 | D22: 1950 | E22: =IF(ISBLANK(D22),"?",IF(D22<=Slowniki!F$7,4,IF(D22<=Slowniki!F$6,3,IF(D22<=Slowniki!F$5,2,IF(D22<=Slowniki!F$4,1,0))))) -> 4
A23: =ROW()-2 -> 21 | B23: Borysiuk Zbigniew | C23: 10/11 | D23: 1953 | E23: =IF(ISBLANK(D23),"?",IF(D23<=Slowniki!F$7,4,IF(D23<=Slowniki!F$6,3,IF(D23<=Slowniki!F$5,2,IF(D23<=Slowniki!F$4,1,0))))) -> 4
A24: =ROW()-2 -> 22 | B24: Bromberek Angelika | C24: 28/11 | D24: 1988 | E24: =IF(ISBLANK(D24),"?",IF(D24<=Slowniki!F$7,4,IF(D24<=Slowniki!F$6,3,IF(D24<=Slowniki!F$5,2,IF(D24<=Slowniki!F$4,1,0))))) -> 0
A25: =ROW()-2 -> 23 | B25: Brosch Artur | E25: =IF(ISBLANK(D25),"?",IF(D25<=Slowniki!F$7,4,IF(D25<=Slowniki!F$6,3,IF(D25<=Slowniki!F$5,2,IF(D25<=Slowniki!F$4,1,0))))) -> ?
A26: =ROW()-2 -> 24 | B26: Bujko Jacek | E26: =IF(ISBLANK(D26),"?",IF(D26<=Slowniki!F$7,4,IF(D26<=Slowniki!F$6,3,IF(D26<=Slowniki!F$5,2,IF(D26<=Slowniki!F$4,1,0))))) -> ?
A27: =ROW()-2 -> 25 | B27: Bujko Paulina | E27: =IF(ISBLANK(D27),"?",IF(D27<=Slowniki!F$7,4,IF(D27<=Slowniki!F$6,3,IF(D27<=Slowniki!F$5,2,IF(D27<=Slowniki!F$4,1,0))))) -> ?
A28: =ROW()-2 -> 26 | B28: Burlikowski Bartosz | C28: 20/11 | D28: 1972 | E28: =IF(ISBLANK(D28),"?",IF(D28<=Slowniki!F$7,4,IF(D28<=Slowniki!F$6,3,IF(D28<=Slowniki!F$5,2,IF(D28<=Slowniki!F$4,1,0))))) -> 2
A29: =ROW()-2 -> 27 | B29: Caniard Henry | E29: =IF(ISBLANK(D29),"?",IF(D29<=Slowniki!F$7,4,IF(D29<=Slowniki!F$6,3,IF(D29<=Slowniki!F$5,2,IF(D29<=Slowniki!F$4,1,0))))) -> ?
A30: =ROW()-2 -> 28 | B30: Chmielewska Emilia | C30: 26/07 | D30: 1986 | E30: =IF(ISBLANK(D30),"?",IF(D30<=Slowniki!F$7,4,IF(D30<=Slowniki!F$6,3,IF(D30<=Slowniki!F$5,2,IF(D30<=Slowniki!F$4,1,0))))) -> 1
A31: =ROW()-2 -> 29 | B31: Chojnacki Tomasz | C31: 15/12 | D31: 1987 | E31: =IF(ISBLANK(D31),"?",IF(D31<=Slowniki!F$7,4,IF(D31<=Slowniki!F$6,3,IF(D31<=Slowniki!F$5,2,IF(D31<=Slowniki!F$4,1,0))))) -> 0
A32: =ROW()-2 -> 30 | B32: Chojnecki Mateusz | C32: 29/01 | D32: 1988 | E32: =IF(ISBLANK(D32),"?",IF(D32<=Slowniki!F$7,4,IF(D32<=Slowniki!F$6,3,IF(D32<=Slowniki!F$5,2,IF(D32<=Slowniki!F$4,1,0))))) -> 0
A33: =ROW()-2 -> 31 | B33: Chudycki Artur | C33: 24/11 | D33: 1960 | E33: =IF(ISBLANK(D33),"?",IF(D33<=Slowniki!F$7,4,IF(D33<=Slowniki!F$6,3,IF(D33<=Slowniki!F$5,2,IF(D33<=Slowniki!F$4,1,0))))) -> 3
A34: =ROW()-2 -> 32 | B34: Ciepły Tomasz | C34: 07/04 | D34: 1980 | E34: =IF(ISBLANK(D34),"?",IF(D34<=Slowniki!F$7,4,IF(D34<=Slowniki!F$6,3,IF(D34<=Slowniki!F$5,2,IF(D34<=Slowniki!F$4,1,0))))) -> 1
A35: =ROW()-2 -> 33 | B35: Cygański Tomasz | C35: 03/03 | D35: 1973 | E35: =IF(ISBLANK(D35),"?",IF(D35<=Slowniki!F$7,4,IF(D35<=Slowniki!F$6,3,IF(D35<=Slowniki!F$5,2,IF(D35<=Slowniki!F$4,1,0))))) -> 2
A36: =ROW()-2 -> 34 | B36: Czajkowski Marcin | C36: 02/08 | D36: 1979 | E36: =IF(ISBLANK(D36),"?",IF(D36<=Slowniki!F$7,4,IF(D36<=Slowniki!F$6,3,IF(D36<=Slowniki!F$5,2,IF(D36<=Slowniki!F$4,1,0))))) -> 1
A37: =ROW()-2 -> 35 | B37: Ćwioro Krzysztof | C37: 20/08 | D37: 1960 | E37: =IF(ISBLANK(D37),"?",IF(D37<=Slowniki!F$7,4,IF(D37<=Slowniki!F$6,3,IF(D37<=Slowniki!F$5,2,IF(D37<=Slowniki!F$4,1,0))))) -> 3
A38: =ROW()-2 -> 36 | B38: Ćwioro Tomasz | C38: 20/03 | D38: 1985 | E38: =IF(ISBLANK(D38),"?",IF(D38<=Slowniki!F$7,4,IF(D38<=Slowniki!F$6,3,IF(D38<=Slowniki!F$5,2,IF(D38<=Slowniki!F$4,1,0))))) -> 1
A39: =ROW()-2 -> 37 | B39: Damian Mateusz | C39: 20/04 | D39: 1988 | E39: =IF(ISBLANK(D39),"?",IF(D39<=Slowniki!F$7,4,IF(D39<=Slowniki!F$6,3,IF(D39<=Slowniki!F$5,2,IF(D39<=Slowniki!F$4,1,0))))) -> 0
A40: =ROW()-2 -> 38 | B40: Darul Tomasz | C40: 27/07 | D40: 1978 | E40: =IF(ISBLANK(D40),"?",IF(D40<=Slowniki!F$7,4,IF(D40<=Slowniki!F$6,3,IF(D40<=Slowniki!F$5,2,IF(D40<=Slowniki!F$4,1,0))))) -> 1
...

Sheet skladka
A1: LP | B1: NAZWISKO I IMIĘ | C1: SKŁADKA | D1: SKŁADK | E1: CZŁONEK
C2: 2026 | D2: 2025 | E2: SPWS
A3: =ROW()-2 -> 1 | B3: Adamczewski Wojciech | C3: 1 | D3: 1 | E3: =_xlfn.XLOOKUP($B3,'Lista osób'!$B$3:$B$305,'Lista osób'!$E$3:$E$305,"") -> TAK
A4: =ROW()-2 -> 2 | B4: Adamczyk Grzegorz | E4: =_xlfn.XLOOKUP($B4,'Lista osób'!$B$3:$B$305,'Lista osób'!$E$3:$E$305,"") -> ?
A5: =ROW()-2 -> 3 | B5: Adamska Maria | E5: =_xlfn.XLOOKUP($B5,'Lista osób'!$B$3:$B$305,'Lista osób'!$E$3:$E$305,"") -> ?
A6: =ROW()-2 -> 4 | B6: Andersch Robert | E6: =_xlfn.XLOOKUP($B6,'Lista osób'!$B$3:$B$305,'Lista osób'!$E$3:$E$305,"") -> ?
A7: =ROW()-2 -> 5 | B7: Atanassow Aleksander | C7: 1 | D7: 1 | E7: =_xlfn.XLOOKUP($B7,'Lista osób'!$B$3:$B$305,'Lista osób'!$E$3:$E$305,"") -> TAK
A8: =ROW()-2 -> 6 | B8: Augustowski Waldemar | C8: 1 | D8: 1 | E8: =_xlfn.XLOOKUP($B8,'Lista osób'!$B$3:$B$305,'Lista osób'!$E$3:$E$305,"") -> TAK
A9: =ROW()-2 -> 7 | B9: Augustyn Kajetan | E9: =_xlfn.XLOOKUP($B9,'Lista osób'!$B$3:$B$305,'Lista osób'!$E$3:$E$305,"") -> ?
A10: =ROW()-2 -> 8 | B10: Baran Agata | E10: =_xlfn.XLOOKUP($B10,'Lista osób'!$B$3:$B$305,'Lista osób'!$E$3:$E$305,"") -> TAK
A11: =ROW()-2 -> 9 | B11: Barański Wacław | E11: =_xlfn.XLOOKUP($B11,'Lista osób'!$B$3:$B$305,'Lista osób'!$E$3:$E$305,"") -> NIE
A12: =ROW()-2 -> 10 | B12: Bartusik Grzegorz | E12: =_xlfn.XLOOKUP($B12,'Lista osób'!$B$3:$B$305,'Lista osób'!$E$3:$E$305,"") -> TAK
A13: =ROW()-2 -> 11 | B13: Bazak Jacek | D13: 1 | E13: =_xlfn.XLOOKUP($B13,'Lista osób'!$B$3:$B$305,'Lista osób'!$E$3:$E$305,"") -> TAK
A14: =ROW()-2 -> 12 | B14: Bednarska Halina | E14: =_xlfn.XLOOKUP($B14,'Lista osób'!$B$3:$B$305,'Lista osób'!$E$3:$E$305,"") -> TAK
A15: =ROW()-2 -> 13 | B15: Bednarz Przemysław | D15: 1 | E15: TAK
A16: =ROW()-2 -> 14 | B16: Betlej Daniel | E16: =_xlfn.XLOOKUP($B16,'Lista osób'!$B$3:$B$305,'Lista osób'!$E$3:$E$305,"") -> TAK
A17: =ROW()-2 -> 15 | B17: Betleja Artur | E17: =_xlfn.XLOOKUP($B17,'Lista osób'!$B$3:$B$305,'Lista osób'!$E$3:$E$305,"") -> ?
A18: =ROW()-2 -> 16 | B18: Bobusia Dariusz | E18: =_xlfn.XLOOKUP($B18,'Lista osób'!$B$3:$B$305,'Lista osób'!$E$3:$E$305,"") -> TAK
A19: =ROW()-2 -> 17 | B19: Bobusia Jarosław | C19: 1 | D19: 1 | E19: TAK
A20: =ROW()-2 -> 18 | B20: Bonik-Ninard Agata | E20: =_xlfn.XLOOKUP($B20,'Lista osób'!$B$3:$B$305,'Lista osób'!$E$3:$E$305,"") -> ?
A21: =ROW()-2 -> 19 | B21: Borkowska Halina | C21: 1 | D21: 1 | E21: =_xlfn.XLOOKUP($B21,'Lista osób'!$B$3:$B$305,'Lista osób'!$E$3:$E$305,"") -> TAK
A22: =ROW()-2 -> 20 | B22: Borkowski Andrzej | C22: 1 | D22: 1 | E22: =_xlfn.XLOOKUP($B22,'Lista osób'!$B$3:$B$305,'Lista osób'!$E$3:$E$305,"") -> TAK
A23: =ROW()-2 -> 21 | B23: Borysiuk Zbigniew | D23: 1 | E23: =_xlfn.XLOOKUP($B23,'Lista osób'!$B$3:$B$305,'Lista osób'!$E$3:$E$305,"") -> TAK
A24: =ROW()-2 -> 22 | B24: Bromberek Angelika | E24: =_xlfn.XLOOKUP($B24,'Lista osób'!$B$3:$B$305,'Lista osób'!$E$3:$E$305,"") -> ?
A25: =ROW()-2 -> 23 | B25: Brosch Artur | E25: =_xlfn.XLOOKUP($B25,'Lista osób'!$B$3:$B$305,'Lista osób'!$E$3:$E$305,"") -> ?
A26: =ROW()-2 -> 24 | B26: Bujko Paulina | E26: =_xlfn.XLOOKUP($B26,'Lista osób'!$B$3:$B$305,'Lista osób'!$E$3:$E$305,"") -> ?
A27: =ROW()-2 -> 25 | B27: Bujko Jacek | E27: =_xlfn.XLOOKUP($B27,'Lista osób'!$B$3:$B$305,'Lista osób'!$E$3:$E$305,"") -> ?
A28: =ROW()-2 -> 26 | B28: Burlikowski Bartosz | E28: =_xlfn.XLOOKUP($B28,'Lista osób'!$B$3:$B$305,'Lista osób'!$E$3:$E$305,"") -> TAK
A29: =ROW()-2 -> 27 | B29: Caniard Henry | E29: =_xlfn.XLOOKUP($B29,'Lista osób'!$B$3:$B$305,'Lista osób'!$E$3:$E$305,"") -> ?
A30: =ROW()-2 -> 28 | B30: Chmielewska Emilia | D30: 1 | E30: TAK
A31: =ROW()-2 -> 29 | B31: Chojnacki Tomasz | E31: =_xlfn.XLOOKUP($B31,'Lista osób'!$B$3:$B$305,'Lista osób'!$E$3:$E$305,"") -> ?
A32: =ROW()-2 -> 30 | B32: Chojnecki Mateusz | E32: =_xlfn.XLOOKUP($B32,'Lista osób'!$B$3:$B$305,'Lista osób'!$E$3:$E$305,"") -> TAK
A33: =ROW()-2 -> 31 | B33: Chudycki Artur | C33: 1 | D33: 1 | E33: =_xlfn.XLOOKUP($B33,'Lista osób'!$B$3:$B$305,'Lista osób'!$E$3:$E$305,"") -> TAK
A34: =ROW()-2 -> 32 | B34: Ciepły Tomasz | E34: =_xlfn.XLOOKUP($B34,'Lista osób'!$B$3:$B$305,'Lista osób'!$E$3:$E$305,"") -> TAK
A35: =ROW()-2 -> 33 | B35: Cygański Tomasz | E35: =_xlfn.XLOOKUP($B35,'Lista osób'!$B$3:$B$305,'Lista osób'!$E$3:$E$305,"") -> TAK
A36: =ROW()-2 -> 34 | B36: Czajkowski Marcin | E36: =_xlfn.XLOOKUP($B36,'Lista osób'!$B$3:$B$305,'Lista osób'!$E$3:$E$305,"") -> TAK
A37: =ROW()-2 -> 35 | B37: Ćwioro Krzysztof | D37: 1 | E37: =_xlfn.XLOOKUP($B37,'Lista osób'!$B$3:$B$305,'Lista osób'!$E$3:$E$305,"") -> TAK
A38: =ROW()-2 -> 36 | B38: Ćwioro Tomasz | E38: =_xlfn.XLOOKUP($B38,'Lista osób'!$B$3:$B$305,'Lista osób'!$E$3:$E$305,"") -> TAK
A39: =ROW()-2 -> 37 | B39: Damian Mateusz | E39: =_xlfn.XLOOKUP($B39,'Lista osób'!$B$3:$B$305,'Lista osób'!$E$3:$E$305,"") -> TAK
A40: =ROW()-2 -> 38 | B40: Darul Tomasz | E40: =_xlfn.XLOOKUP($B40,'Lista osób'!$B$3:$B$305,'Lista osób'!$E$3:$E$305,"") -> ?
...

Sheet Podsumowanie
A2: Liczba deklaracji członkowskich
A4: #VALUE!
A10: Lista opłaconych składek

Sheet Slowniki
A1: DEKLARACJA | C1: SKŁADKA | E1: KATEGORIE WIEKOWE
A2: TAK | C2: X | E2: KAT | F2: DATA
A3: NIE | E3: 0 | F3: 1996
A4: ? | E4: 1 | F4: 1986
E5: 2 | F5: 1976
E6: 3 | F6: 1966
E7: 4 | F7: 1956
